File: data/TGA/archived/ExpDat_2024_01_13_SL_005K.csv
#EXPORTTYPE:                 ,DATA ALL
#FILE:                       ,2024_01_13_SL_005K.ngb-ss5
#FORMAT:                     ,NETZSCH5
#FTYPE:                      ,ASCII
#IDENTITY:                   ,SCF3-PS
#DECIMAL:                    ,POINT
#SEPARATOR:                  ,COMMA
#MTYPE:                      ,DSC
#INSTRUMENT:                 ,NETZSCH STA 449F5
#PROJECT:                    ,2024_01_08_SL_007B
#DATE/TIME:                  ,1/13/2024 11:38:44 AM (UTC-5)
#CORR. FILE:                 ,
#TEMPCAL:                    ,28-06-2023 13:26
#SENSITIVITY:                ,28-06-2023 13:53
#LABORATORY:                 ,Tran/AAG
#OPERATOR:                   ,Stanley
#REMARK:                     ,
#SAMPLE:                     ,005K
#SAMPLE MASS /mg:            ,15.25
#MATERIAL:                   ,
#REFERENCE:                  ,
#REFERENCE MASS /mg:         ,0
#TYPE OF CRUCIBLE:           ,Al2O3 85 ‘l, open
#SAMPLE CRUCIBLE MASS /mg:   ,0
#REFERENCE CRUCIBLE MASS /mg:,0
#DSC RANGE /‘V:              ,5000
#TG RANGE /mg:               ,35000
#TAU-R:                      ,---
#CORR. CODE:                 ,000
#EXO:                        ,-1
#RANGE:                      ,20›C....800›C/0.0....10.0K/min
#SEGMENT:                    ,S1-5/5
#SEG. 1:                     ,20›C/10.0(K/min)/100›C
#SEG. 2:                     ,100›C/00:10/100›C
#SEG. 3:                     ,100›C/10.0(K/min)/350›C
#SEG. 4:                     ,350›C/04:00/350›C
#SEG. 5:                     ,350›C/10.0(K/min)/800›C

##Temp./›C,Time/min,DSC/(mW/mg),Mass/%,Gas Flow(purge2)/(ml/min),Gas Flow(protective)/(ml/min),TIC(scan:1)/A,Sensit./(uV/mW),Segment
 26.57800,  0.00000,      0.20469,100.00000,50.00000,20.00000,1.785115e-07,0.92288,1
 28.21900,  0.75000,      0.15878, 99.90800,50.00000,20.00000,1.811256e-07,0.92321,1
 30.55100,  1.50000,      0.21173,100.06970,50.00000,20.00000,1.905754e-07,0.92366,1
 33.56800,  2.25000,      0.27922, 98.44662,50.00000,20.00000,2.093855e-07,0.92417,1
 37.12900,  3.00000,      0.35377, 98.55193,50.00000,20.00000,2.319447e-07,0.92471,1
 41.62300,  3.75000,      0.46273, 98.76334,50.00000,20.00000,2.341207e-07,0.92527,1
 47.26800,  4.50000,      0.60362, 98.96439,50.00000,20.00000,2.341572e-07,0.92578,1
 53.99100,  5.25000,      0.75173, 99.10531,50.00000,20.00000,2.322559e-07,0.92613,1
 61.59300,  6.00000,      0.89008, 99.16911,50.00000,20.00000,2.296962e-07,0.92618,1
 69.85900,  6.75000,      1.01736, 99.12466,50.00000,20.00000,2.272828e-07,0.92582,1
 78.65100,  7.50000,      1.13214, 98.96957,50.00000,20.00000,2.241704e-07,0.92498,1
 87.74212,  8.25000,      1.21592, 98.62016,50.00000,20.00000,2.205201e-07,0.92362,2
 95.49656,  9.00000,      1.07039, 97.81096,50.00000,20.00000,2.168376e-07,0.92208,2
100.80093,  9.75000,      0.78420, 96.85037,50.00000,20.00000,2.142341e-07,0.92083,2
104.33048, 10.50000,      0.54688, 96.06944,50.00000,20.00000,2.124985e-07,0.91991,2
106.97564, 11.25000,      0.40100, 95.49499,50.00000,20.00000,2.110159e-07,0.91917,2
108.83985, 12.00000,      0.28000, 95.03055,50.00000,20.00000,2.095174e-07,0.91863,2
109.88596, 12.75000,      0.15785, 94.61235,50.00000,20.00000,2.071468e-07,0.91831,2
110.25461, 13.50000, 5.356312e-02, 94.27586,50.00000,20.00000,2.057033e-07,0.91820,2
110.13583, 14.25000,-2.340774e-02, 94.01019,50.00000,20.00000,2.042061e-07,0.91824,2
109.66919, 15.00000,-7.770329e-02, 93.78935,50.00000,20.00000,2.035429e-07,0.91838,2
108.97010, 15.75000,     -0.11568, 93.62116,50.00000,20.00000,2.021417e-07,0.91859,2
108.13498, 16.50000,     -0.14180, 93.47344,50.00000,20.00000,2.010562e-07,0.91883,2
107.19784, 17.25000,     -0.15588, 93.35260,50.00000,20.00000,1.996188e-07,0.91911,2
106.25561, 18.00000,     -0.16123, 93.23718,50.00000,20.00000,1.985030e-07,0.91937,3
105.95305, 18.75000,-5.760345e-02, 93.31540,50.00000,20.00000,1.972648e-07,0.91946,3
108.07994, 19.50000,      0.26426, 93.69070,50.00000,20.00000,1.961954e-07,0.91885,3
112.06320, 20.25000,      0.54447, 93.95262,50.00000,20.00000,1.947031e-07,0.91764,3
117.04868, 21.00000,      0.73516, 94.09133,50.00000,20.00000,1.938593e-07,0.91601,3
123.11777, 21.75000,      0.93095, 94.23889,50.00000,20.00000,1.924658e-07,0.91385,3
130.37083, 22.50000,      1.13486, 94.36520,50.00000,20.00000,1.914357e-07,0.91101,3
138.48431, 23.25000,      1.29922, 94.46367,50.00000,20.00000,1.903694e-07,0.90751,3
147.11146, 24.00000,      1.42210, 94.55272,50.00000,20.00000,1.894341e-07,0.90344,3
156.04850, 24.75000,      1.50834, 94.61502,50.00000,20.00000,1.885731e-07,0.89886,3
165.11917, 25.50000,      1.56535, 94.66249,50.00000,20.00000,1.877869e-07,0.89384,3
174.17860, 26.25000,      1.59336, 94.67141,50.00000,20.00000,1.872437e-07,0.88847,3
183.13747, 27.00000,      1.59005, 94.68249,50.00000,20.00000,1.863371e-07,0.88282,3
191.99603, 27.75000,      1.54405, 94.67369,50.00000,20.00000,1.856198e-07,0.87694,3
200.64389, 28.50000,      1.47361, 94.66400,50.00000,20.00000,1.852202e-07,0.87091,3
209.09920, 29.25000,      1.40698, 94.61952,50.00000,20.00000,1.844181e-07,0.86477,3
217.35995, 30.00000,      1.35228, 94.58216,50.00000,20.00000,1.835450e-07,0.85855,3
225.43932, 30.75000,      1.30892, 94.54085,50.00000,20.00000,1.833953e-07,0.85226,3
233.37666, 31.50000,      1.27261, 94.48669,50.00000,20.00000,1.826357e-07,0.84590,3
241.18837, 32.25000,      1.23785, 94.43320,50.00000,20.00000,1.817884e-07,0.83948,3
248.88776, 33.00000,      1.20631, 94.36872,50.00000,20.00000,1.814722e-07,0.83301,3
256.51676, 33.75000,      1.17815, 94.28859,50.00000,20.00000,1.808763e-07,0.82647,3
264.07390, 34.50000,      1.15597, 94.23370,50.00000,20.00000,1.802920e-07,0.81987,3
271.59533, 35.25000,      1.13770, 94.13356,50.00000,20.00000,1.795630e-07,0.81319,3
279.06001, 36.00000,      1.12789, 94.03266,50.00000,20.00000,1.789142e-07,0.80647,3
286.51591, 36.75000,      1.13839, 93.92361,50.00000,20.00000,1.786347e-07,0.79967,3
293.94119, 37.50000,      1.13888, 93.81696,50.00000,20.00000,1.778382e-07,0.79283,3
301.36363, 38.25000,      1.12976, 93.66695,50.00000,20.00000,1.775428e-07,0.78593,3
308.77245, 39.00000,      1.11614, 93.46825,50.00000,20.00000,1.771330e-07,0.77899,3
316.18852, 39.75000,      1.10474, 93.22850,50.00000,20.00000,1.765330e-07,0.77200,3
323.60591, 40.50000,      1.09479, 92.89775,50.00000,20.00000,1.763480e-07,0.76497,3
331.01095, 41.25000,      1.08270, 92.47565,50.00000,20.00000,1.758647e-07,0.75793,3
338.42955, 42.00000,      1.07386, 91.89732,50.00000,20.00000,1.756772e-07,0.75086,3
345.82693, 42.75000,      1.06611, 91.14362,50.00000,20.00000,1.752244e-07,0.74380,3
352.10302, 43.50000,      0.76131, 90.15813,50.00000,20.00000,1.752266e-07,0.73781,4
353.38481, 44.25000,     -0.13267, 88.84412,50.00000,20.00000,1.751860e-07,0.73658,4
353.86657, 45.00000,     -0.28914, 87.60700,50.00000,20.00000,1.753766e-07,0.73612,4
354.68000, 45.75000,     -0.29757, 86.41353,50.00000,20.00000,1.754923e-07,0.73535,4
354.73161, 46.50000,     -0.44580, 85.18460,50.00000,20.00000,1.752905e-07,0.73530,4
354.37540, 47.25000,     -0.52736, 83.97968,50.00000,20.00000,1.751449e-07,0.73564,4
354.03755, 48.00000,     -0.54566, 82.80045,50.00000,20.00000,1.751646e-07,0.73596,4
353.61911, 48.75000,     -0.56694, 81.65871,50.00000,20.00000,1.745082e-07,0.73636,4
353.18433, 49.50000,     -0.58207, 80.56076,50.00000,20.00000,1.740008e-07,0.73677,4
352.77124, 50.25000,     -0.58439, 79.49175,50.00000,20.00000,1.738518e-07,0.73717,4
352.40164, 51.00000,     -0.58399, 78.45983,50.00000,20.00000,1.734840e-07,0.73752,4
352.06166, 51.75000,     -0.58312, 77.45368,50.00000,20.00000,1.735485e-07,0.73784,4
351.77031, 52.50000,     -0.58040, 76.46725,50.00000,20.00000,1.734191e-07,0.73812,4
351.51375, 53.25000,     -0.57771, 75.51490,50.00000,20.00000,1.735810e-07,0.73837,4
351.29552, 54.00000,     -0.57551, 74.58125,50.00000,20.00000,1.732512e-07,0.73858,4
351.10561, 54.75000,     -0.57410, 73.67250,50.00000,20.00000,1.732255e-07,0.73876,4
350.94625, 55.50000,     -0.57253, 72.75450,50.00000,20.00000,1.728125e-07,0.73891,4
350.79705, 56.25000,     -0.57085, 71.87502,50.00000,20.00000,1.730278e-07,0.73905,4
350.67876, 57.00000,     -0.57034, 71.01014,50.00000,20.00000,1.727483e-07,0.73916,4
350.57069, 57.75000,     -0.56864, 70.13718,50.00000,20.00000,1.723974e-07,0.73927,4
350.49668, 58.50000,     -0.56859, 69.31197,50.00000,20.00000,1.725103e-07,0.73934,4
350.41722, 59.25000,     -0.56869, 68.47700,50.00000,20.00000,1.724913e-07,0.73941,4
350.34984, 60.00000,     -0.56857, 67.65331,50.00000,20.00000,1.720777e-07,0.73948,4
350.29911, 60.75000,     -0.56875, 66.86349,50.00000,20.00000,1.724418e-07,0.73953,4
350.26658, 61.50000,     -0.56913, 66.05396,50.00000,20.00000,1.722770e-07,0.73956,4
350.22583, 62.25000,     -0.57004, 65.25636,50.00000,20.00000,1.719882e-07,0.73960,4
350.18924, 63.00000,     -0.57167, 64.47183,50.00000,20.00000,1.716712e-07,0.73963,4
350.16282, 63.75000,     -0.57215, 63.71508,50.00000,20.00000,1.715002e-07,0.73966,4
350.14495, 64.50000,     -0.57316, 62.95766,50.00000,20.00000,1.715927e-07,0.73967,4
350.12658, 65.25000,     -0.57428, 62.19683,50.00000,20.00000,1.715986e-07,0.73969,4
350.11051, 66.00000,     -0.57507, 61.46576,50.00000,20.00000,1.714548e-07,0.73971,4
350.10082, 66.75000,     -0.57634, 60.71795,50.00000,20.00000,1.715265e-07,0.73972,4
350.08723, 67.50000,     -0.57834, 59.98825,50.00000,20.00000,1.712939e-07,0.73973,4
350.07699, 68.25000,     -0.57902, 59.28513,50.00000,20.00000,1.713031e-07,0.73974,4
350.06695, 69.00000,     -0.57917, 58.56419,50.00000,20.00000,1.711860e-07,0.73975,4
350.05915, 69.75000,     -0.58086, 57.86359,50.00000,20.00000,1.712207e-07,0.73976,4
350.05809, 70.50000,     -0.58300, 57.15815,50.00000,20.00000,1.705661e-07,0.73976,4
350.04829, 71.25000,     -0.58450, 56.48505,50.00000,20.00000,1.709630e-07,0.73977,4
350.04703, 72.00000,     -0.58456, 55.80251,50.00000,20.00000,1.704906e-07,0.73977,4
350.04778, 72.75000,     -0.58642, 55.12626,50.00000,20.00000,1.706599e-07,0.73977,4
350.03580, 73.50000,     -0.58807, 54.47267,50.00000,20.00000,1.706536e-07,0.73978,4
350.04692, 74.25000,     -0.58841, 53.81311,50.00000,20.00000,1.703457e-07,0.73977,4
350.03653, 75.00000,     -0.58948, 53.15994,50.00000,20.00000,1.703478e-07,0.73978,4
350.03338, 75.75000,     -0.59065, 52.51882,50.00000,20.00000,1.705197e-07,0.73978,4
350.03597, 76.50000,     -0.59282, 51.89278,50.00000,20.00000,1.704111e-07,0.73978,4
350.03157, 77.25000,     -0.59422, 51.27160,50.00000,20.00000,1.702935e-07,0.73978,4
350.03995, 78.00000,     -0.59508, 50.65683,50.00000,20.00000,1.702389e-07,0.73977,4
350.03094, 78.75000,     -0.59571, 50.04559,50.00000,20.00000,1.701218e-07,0.73978,4
350.03667, 79.50000,     -0.59545, 49.43703,50.00000,20.00000,1.697100e-07,0.73978,4
350.03952, 80.25000,     -0.59789, 48.84805,50.00000,20.00000,1.698003e-07,0.73977,4
350.03450, 81.00000,     -0.60132, 48.28056,50.00000,20.00000,1.697762e-07,0.73978,4
350.02872, 81.75000,     -0.60138, 47.68725,50.00000,20.00000,1.698751e-07,0.73979,4
350.01406, 82.50000,     -0.60231, 47.11613,50.00000,20.00000,1.693193e-07,0.73980,4
350.02275, 83.25000,     -0.60253, 46.54475,50.00000,20.00000,1.694054e-07,0.73979,4
350.02641, 84.00000,     -0.60322, 46.00173,50.00000,20.00000,1.697601e-07,0.73979,4
350.01871, 84.75000,     -0.60431, 45.44452,50.00000,20.00000,1.692864e-07,0.73979,4
350.02402, 85.50000,     -0.60668, 44.90508,50.00000,20.00000,1.693520e-07,0.73979,4
350.02433, 86.25000,     -0.60776, 44.36801,50.00000,20.00000,1.690606e-07,0.73979,4
350.02543, 87.00000,     -0.60824, 43.84608,50.00000,20.00000,1.692961e-07,0.73979,4
350.02355, 87.75000,     -0.60925, 43.32216,50.00000,20.00000,1.690038e-07,0.73979,4
350.02822, 88.50000,     -0.61147, 42.80211,50.00000,20.00000,1.688383e-07,0.73979,4
350.02132, 89.25000,     -0.61244, 42.29399,50.00000,20.00000,1.688051e-07,0.73979,4
350.02227, 90.00000,     -0.61423, 41.78904,50.00000,20.00000,1.688140e-07,0.73979,4
350.02449, 90.75000,     -0.61478, 41.30202,50.00000,20.00000,1.687325e-07,0.73979,4
350.03007, 91.50000,     -0.61474, 40.81380,50.00000,20.00000,1.686993e-07,0.73978,4
350.03139, 92.25000,     -0.61571, 40.32219,50.00000,20.00000,1.685958e-07,0.73978,4
350.01672, 93.00000,     -0.61808, 39.85027,50.00000,20.00000,1.684699e-07,0.73980,4
350.02221, 93.75000,     -0.61824, 39.39349,50.00000,20.00000,1.686000e-07,0.73979,4
350.03460, 94.50000,     -0.61943, 38.93362,50.00000,20.00000,1.683953e-07,0.73978,4
350.02177, 95.25000,     -0.62140, 38.46538,50.00000,20.00000,1.684913e-07,0.73979,4
350.02400, 96.00000,     -0.62101, 38.01898,50.00000,20.00000,1.683232e-07,0.73979,4
350.02871, 96.75000,     -0.62182, 37.57122,50.00000,20.00000,1.682610e-07,0.73979,4
350.02556, 97.50000,     -0.62353, 37.13097,50.00000,20.00000,1.680424e-07,0.73979,4
350.02776, 98.25000,     -0.62459, 36.69821,50.00000,20.00000,1.680350e-07,0.73979,4
350.03420, 99.00000,     -0.62554, 36.28286,50.00000,20.00000,1.678200e-07,0.73978,4
350.02673, 99.75000,     -0.62655, 35.84165,50.00000,20.00000,1.680427e-07,0.73979,4
350.02368,100.50000,     -0.62775, 35.43198,50.00000,20.00000,1.678738e-07,0.73979,4
350.03223,101.25000,     -0.62893, 35.01675,50.00000,20.00000,1.676304e-07,0.73978,4
350.03145,102.00000,     -0.62929, 34.61218,50.00000,20.00000,1.674160e-07,0.73978,4
350.02682,102.75000,     -0.63020, 34.20800,50.00000,20.00000,1.674660e-07,0.73979,4
350.02243,103.50000,     -0.63142, 33.81259,50.00000,20.00000,1.674152e-07,0.73979,4
350.03005,104.25000,     -0.63135, 33.41786,50.00000,20.00000,1.672952e-07,0.73978,4
350.03844,105.00000,     -0.63197, 33.05512,50.00000,20.00000,1.673996e-07,0.73978,4
350.02870,105.75000,     -0.63431, 32.65703,50.00000,20.00000,1.672205e-07,0.73979,4
350.03470,106.50000,     -0.63466, 32.27395,50.00000,20.00000,1.671385e-07,0.73978,4
350.02770,107.25000,     -0.63570, 31.90176,50.00000,20.00000,1.670755e-07,0.73979,4
350.02519,108.00000,     -0.63680, 31.54621,50.00000,20.00000,1.670556e-07,0.73979,4
350.02509,108.75000,     -0.63710, 31.17758,50.00000,20.00000,1.667963e-07,0.73979,4
350.01810,109.50000,     -0.63875, 30.82747,50.00000,20.00000,1.668325e-07,0.73980,4
350.02730,110.25000,     -0.63966, 30.46321,50.00000,20.00000,1.672057e-07,0.73979,4
350.02640,111.00000,     -0.63948, 30.11297,50.00000,20.00000,1.667566e-07,0.73979,4
350.02711,111.75000,     -0.63970, 29.76690,50.00000,20.00000,1.668657e-07,0.73979,4
350.01744,112.50000,     -0.64167, 29.41552,50.00000,20.00000,1.664274e-07,0.73980,4
350.02876,113.25000,     -0.64255, 29.09392,50.00000,20.00000,1.662689e-07,0.73979,4
350.01963,114.00000,     -0.64152, 28.75629,50.00000,20.00000,1.663580e-07,0.73979,4
350.02934,114.75000,     -0.64187, 28.43777,50.00000,20.00000,1.665493e-07,0.73978,4
350.04214,115.50000,     -0.64414, 28.10735,50.00000,20.00000,1.661506e-07,0.73977,4
350.02486,116.25000,     -0.64588, 27.80238,50.00000,20.00000,1.663140e-07,0.73979,4
350.02325,117.00000,     -0.64481, 27.47359,50.00000,20.00000,1.659591e-07,0.73979,4
350.01323,117.75000,     -0.64631, 27.16944,50.00000,20.00000,1.659184e-07,0.73980,4
350.03540,118.50000,     -0.64691, 26.84085,50.00000,20.00000,1.659277e-07,0.73978,4
350.03371,119.25000,     -0.64761, 26.55762,50.00000,20.00000,1.661592e-07,0.73978,4
350.03674,120.00000,     -0.64876, 26.24368,50.00000,20.00000,1.659328e-07,0.73978,4
350.02669,120.75000,     -0.64917, 25.93417,50.00000,20.00000,1.659461e-07,0.73979,4
350.02574,121.50000,     -0.64998, 25.65758,50.00000,20.00000,1.657314e-07,0.73979,4
350.02363,122.25000,     -0.65089, 25.35690,50.00000,20.00000,1.659006e-07,0.73979,4
350.02456,123.00000,     -0.65111, 25.06465,50.00000,20.00000,1.657838e-07,0.73979,4
350.02772,123.75000,     -0.65081, 24.79636,50.00000,20.00000,1.655788e-07,0.73979,4
350.02240,124.50000,     -0.65154, 24.50621,50.00000,20.00000,1.653556e-07,0.73979,4
350.02173,125.25000,     -0.65251, 24.23245,50.00000,20.00000,1.654613e-07,0.73979,4
350.02262,126.00000,     -0.65365, 23.94990,50.00000,20.00000,1.651446e-07,0.73979,4
350.03661,126.75000,     -0.65416, 23.68800,50.00000,20.00000,1.652297e-07,0.73978,4
350.03421,127.50000,     -0.65465, 23.42171,50.00000,20.00000,1.652386e-07,0.73978,4
350.02973,128.25000,     -0.65587, 23.14354,50.00000,20.00000,1.651086e-07,0.73978,4
350.03140,129.00000,     -0.65656, 22.87868,50.00000,20.00000,1.650336e-07,0.73978,4
350.03337,129.75000,     -0.65720, 22.62559,50.00000,20.00000,1.650849e-07,0.73978,4
350.03122,130.50000,     -0.65718, 22.37153,50.00000,20.00000,1.648946e-07,0.73978,4
350.03616,131.25000,     -0.65755, 22.11879,50.00000,20.00000,1.645882e-07,0.73978,4
350.03048,132.00000,     -0.65774, 21.86832,50.00000,20.00000,1.644476e-07,0.73978,4
350.04328,132.75000,     -0.65958, 21.62047,50.00000,20.00000,1.643906e-07,0.73977,4
350.04231,133.50000,     -0.66037, 21.37573,50.00000,20.00000,1.641778e-07,0.73977,4
350.02780,134.25000,     -0.66137, 21.13378,50.00000,20.00000,1.642888e-07,0.73979,4
350.03815,135.00000,     -0.66058, 20.88462,50.00000,20.00000,1.639213e-07,0.73978,4
350.02749,135.75000,     -0.66251, 20.65238,50.00000,20.00000,1.642398e-07,0.73979,4
350.02649,136.50000,     -0.66242, 20.41791,50.00000,20.00000,1.639066e-07,0.73979,4
350.01948,137.25000,     -0.66307, 20.17447,50.00000,20.00000,1.640318e-07,0.73979,4
350.03289,138.00000,     -0.66285, 19.95587,50.00000,20.00000,1.639340e-07,0.73978,4
350.03161,138.75000,     -0.66383, 19.74072,50.00000,20.00000,1.639617e-07,0.73978,4
350.04205,139.50000,     -0.66433, 19.51092,50.00000,20.00000,1.639487e-07,0.73977,4
350.04210,140.25000,     -0.66553, 19.28369,50.00000,20.00000,1.636851e-07,0.73977,4
350.03627,141.00000,     -0.66620, 19.06714,50.00000,20.00000,1.633404e-07,0.73978,4
350.03488,141.75000,     -0.66651, 18.84603,50.00000,20.00000,1.633277e-07,0.73978,4
350.03652,142.50000,     -0.66724, 18.63613,50.00000,20.00000,1.635224e-07,0.73978,4
350.02956,143.25000,     -0.66834, 18.43136,50.00000,20.00000,1.632061e-07,0.73978,4
350.02876,144.00000,     -0.66823, 18.20512,50.00000,20.00000,1.634974e-07,0.73979,4
350.03265,144.75000,     -0.66875, 18.00574,50.00000,20.00000,1.632852e-07,0.73978,4
350.02957,145.50000,     -0.66918, 17.79578,50.00000,20.00000,1.632225e-07,0.73978,4
350.02796,146.25000,     -0.66982, 17.58850,50.00000,20.00000,1.634237e-07,0.73979,4
350.03777,147.00000,     -0.67043, 17.38541,50.00000,20.00000,1.633066e-07,0.73978,4
350.03879,147.75000,     -0.67120, 17.18418,50.00000,20.00000,1.628523e-07,0.73978,4
350.02524,148.50000,     -0.67097, 16.99070,50.00000,20.00000,1.628190e-07,0.73979,4
350.03059,149.25000,     -0.67135, 16.79934,50.00000,20.00000,1.630102e-07,0.73978,4
350.02242,150.00000,     -0.67236, 16.61167,50.00000,20.00000,1.632474e-07,0.73979,4
350.02675,150.75000,     -0.67294, 16.42318,50.00000,20.00000,1.629140e-07,0.73979,4
350.02355,151.50000,     -0.67233, 16.23995,50.00000,20.00000,1.629845e-07,0.73979,4
350.02842,152.25000,     -0.67315, 16.03810,50.00000,20.00000,1.631089e-07,0.73979,4
350.02558,153.00000,     -0.67375, 15.85718,50.00000,20.00000,1.628119e-07,0.73979,4
350.02918,153.75000,     -0.67347, 15.67965,50.00000,20.00000,1.629345e-07,0.73978,4
350.03366,154.50000,     -0.67471, 15.48551,50.00000,20.00000,1.625554e-07,0.73978,4
350.02326,155.25000,     -0.67513, 15.30603,50.00000,20.00000,1.625361e-07,0.73979,4
350.02520,156.00000,     -0.67531, 15.13257,50.00000,20.00000,1.624129e-07,0.73979,4
350.03349,156.75000,     -0.67642, 14.95281,50.00000,20.00000,1.626563e-07,0.73978,4
350.03023,157.50000,     -0.67759, 14.78453,50.00000,20.00000,1.625049e-07,0.73978,4
350.02475,158.25000,     -0.67795, 14.61608,50.00000,20.00000,1.627375e-07,0.73979,4
350.03506,159.00000,     -0.67826, 14.44624,50.00000,20.00000,1.625231e-07,0.73978,4
350.02725,159.75000,     -0.67849, 14.26897,50.00000,20.00000,1.625741e-07,0.73979,4
350.03309,160.50000,     -0.67883, 14.11239,50.00000,20.00000,1.626672e-07,0.73978,4
350.03945,161.25000,     -0.67890, 13.94029,50.00000,20.00000,1.626080e-07,0.73977,4
350.04712,162.00000,     -0.67933, 13.77556,50.00000,20.00000,1.625223e-07,0.73977,4
350.04255,162.75000,     -0.68032, 13.62210,50.00000,20.00000,1.621814e-07,0.73977,4
350.03213,163.50000,     -0.68091, 13.45644,50.00000,20.00000,1.622775e-07,0.73978,4
350.04074,164.25000,     -0.68202, 13.28822,50.00000,20.00000,1.622727e-07,0.73977,4
350.02806,165.00000,     -0.68228, 13.15169,50.00000,20.00000,1.625316e-07,0.73979,4
350.02831,165.75000,     -0.68269, 12.97737,50.00000,20.00000,1.623196e-07,0.73979,4
350.03420,166.50000,     -0.68228, 12.83425,50.00000,20.00000,1.623207e-07,0.73978,4
350.02253,167.25000,     -0.68331, 12.68359,50.00000,20.00000,1.622709e-07,0.73979,4
350.02668,168.00000,     -0.68416, 12.53220,50.00000,20.00000,1.625828e-07,0.73979,4
350.04007,168.75000,     -0.68453, 12.37652,50.00000,20.00000,1.625702e-07,0.73977,4
350.04074,169.50000,     -0.68397, 12.24151,50.00000,20.00000,1.622937e-07,0.73977,4
350.04093,170.25000,     -0.68539, 12.08035,50.00000,20.00000,1.622403e-07,0.73977,4
350.02895,171.00000,     -0.68653, 11.94476,50.00000,20.00000,1.624588e-07,0.73978,4
350.03937,171.75000,     -0.68573, 11.79639,50.00000,20.00000,1.621470e-07,0.73977,4
350.04915,172.50000,     -0.68656, 11.65610,50.00000,20.00000,1.622097e-07,0.73977,4
350.03450,173.25000,     -0.68823, 11.51521,50.00000,20.00000,1.622126e-07,0.73978,4
350.03070,174.00000,     -0.68887, 11.38913,50.00000,20.00000,1.621883e-07,0.73978,4
350.02714,174.75000,     -0.68911, 11.24597,50.00000,20.00000,1.622062e-07,0.73979,4
350.01913,175.50000,     -0.68780, 11.10347,50.00000,20.00000,1.621004e-07,0.73979,4
350.02460,176.25000,     -0.68837, 10.96702,50.00000,20.00000,1.618323e-07,0.73979,4
350.03202,177.00000,     -0.68937, 10.83790,50.00000,20.00000,1.620850e-07,0.73978,4
350.02441,177.75000,     -0.68972, 10.70144,50.00000,20.00000,1.619690e-07,0.73979,4
350.03306,178.50000,     -0.68982, 10.57897,50.00000,20.00000,1.619231e-07,0.73978,4
350.03319,179.25000,     -0.68913, 10.44992,50.00000,20.00000,1.618287e-07,0.73978,4
350.03350,180.00000,     -0.69008, 10.32164,50.00000,20.00000,1.619991e-07,0.73978,4
350.03077,180.75000,     -0.69092, 10.19342,50.00000,20.00000,1.619769e-07,0.73978,4
350.02217,181.50000,     -0.69182, 10.06046,50.00000,20.00000,1.619694e-07,0.73979,4
350.02152,182.25000,     -0.69250,  9.94105,50.00000,20.00000,1.620670e-07,0.73979,4
350.01913,183.00000,     -0.69246,  9.80311,50.00000,20.00000,1.620926e-07,0.73979,4
350.01684,183.75000,     -0.69220,  9.69180,50.00000,20.00000,1.622818e-07,0.73980,4
350.00381,184.50000,     -0.69126,  9.57456,50.00000,20.00000,1.617092e-07,0.73981,4
350.00960,185.25000,     -0.69147,  9.45443,50.00000,20.00000,1.618079e-07,0.73980,4
350.01206,186.00000,     -0.69196,  9.33646,50.00000,20.00000,1.617268e-07,0.73980,4
350.00889,186.75000,     -0.69160,  9.22367,50.00000,20.00000,1.618968e-07,0.73980,4
350.01555,187.50000,     -0.69148,  9.09833,50.00000,20.00000,1.618419e-07,0.73980,4
350.00231,188.25000,     -0.69174,  8.99672,50.00000,20.00000,1.618413e-07,0.73981,4
350.01380,189.00000,     -0.69083,  8.88689,50.00000,20.00000,1.619543e-07,0.73980,4
350.03738,189.75000,     -0.69088,  8.77635,50.00000,20.00000,1.617559e-07,0.73978,4
350.02395,190.50000,     -0.69173,  8.65987,50.00000,20.00000,1.618849e-07,0.73979,4
350.01914,191.25000,     -0.69221,  8.55517,50.00000,20.00000,1.613385e-07,0.73979,4
350.02161,192.00000,     -0.69019,  8.42981,50.00000,20.00000,1.616740e-07,0.73979,4
350.03071,192.75000,     -0.68573,  8.32754,50.00000,20.00000,1.619753e-07,0.73978,4
350.04228,193.50000,     -0.66910,  8.23187,50.00000,20.00000,1.620280e-07,0.73977,4
350.04602,194.25000,     -0.66728,  8.13161,50.00000,20.00000,1.618455e-07,0.73977,4
350.04413,195.00000,     -0.66703,  8.02702,50.00000,20.00000,1.618748e-07,0.73977,4
350.04391,195.75000,     -0.66729,  7.91954,50.00000,20.00000,1.618972e-07,0.73977,4
350.03913,196.50000,     -0.66943,  7.82308,50.00000,20.00000,1.616457e-07,0.73978,4
350.02055,197.25000,     -0.66825,  7.72000,50.00000,20.00000,1.615788e-07,0.73979,4
350.02601,198.00000,     -0.66734,  7.61987,50.00000,20.00000,1.616981e-07,0.73979,4
350.03457,198.75000,     -0.66811,  7.51894,50.00000,20.00000,1.613459e-07,0.73978,4
350.03380,199.50000,     -0.66754,  7.43515,50.00000,20.00000,1.617583e-07,0.73978,4
350.03313,200.25000,     -0.66829,  7.32452,50.00000,20.00000,1.614627e-07,0.73978,4
350.03102,201.00000,     -0.66972,  7.22517,50.00000,20.00000,1.615342e-07,0.73978,4
350.03797,201.75000,     -0.66884,  7.13318,50.00000,20.00000,1.612327e-07,0.73978,4
350.02652,202.50000,     -0.67002,  7.04046,50.00000,20.00000,1.615148e-07,0.73979,4
350.03753,203.25000,     -0.66656,  6.94774,50.00000,20.00000,1.614973e-07,0.73978,4
350.03710,204.00000,     -0.66962,  6.86009,50.00000,20.00000,1.615005e-07,0.73978,4
350.03203,204.75000,     -0.67012,  6.76596,50.00000,20.00000,1.611876e-07,0.73978,4
350.04441,205.50000,     -0.67027,  6.67547,50.00000,20.00000,1.616605e-07,0.73977,4
350.04309,206.25000,     -0.67098,  6.59462,50.00000,20.00000,1.611479e-07,0.73977,4
350.04786,207.00000,     -0.67228,  6.50258,50.00000,20.00000,1.611763e-07,0.73977,4
350.03718,207.75000,     -0.67284,  6.41213,50.00000,20.00000,1.614100e-07,0.73978,4
350.04579,208.50000,     -0.67298,  6.32164,50.00000,20.00000,1.611515e-07,0.73977,4
350.03218,209.25000,     -0.67442,  6.23780,50.00000,20.00000,1.610989e-07,0.73978,4
350.03605,210.00000,     -0.67424,  6.16360,50.00000,20.00000,1.613534e-07,0.73978,4
350.02557,210.75000,     -0.67380,  6.06199,50.00000,20.00000,1.610778e-07,0.73979,4
350.02251,211.50000,     -0.67475,  5.98992,50.00000,20.00000,1.605653e-07,0.73979,4
350.03140,212.25000,     -0.67301,  5.91213,50.00000,20.00000,1.611510e-07,0.73978,4
350.02722,213.00000,     -0.67363,  5.83201,50.00000,20.00000,1.608511e-07,0.73979,4
350.03320,213.75000,     -0.67397,  5.74226,50.00000,20.00000,1.610835e-07,0.73978,4
350.04786,214.50000,     -0.66415,  5.65616,50.00000,20.00000,1.612745e-07,0.73977,4
350.04514,215.25000,     -0.66399,  5.59536,50.00000,20.00000,1.611499e-07,0.73977,4
350.10648,216.00000,     -0.66388,  5.52269,50.00000,20.00000,1.611077e-07,0.73971,4
350.03836,216.75000,     -0.66211,  5.44033,50.00000,20.00000,1.613076e-07,0.73978,4
350.02029,217.50000,     -0.65956,  5.34943,50.00000,20.00000,1.607154e-07,0.73979,4
350.03759,218.25000,     -0.65844,  5.28675,50.00000,20.00000,1.611719e-07,0.73978,4
350.03946,219.00000,     -0.66479,  5.21204,50.00000,20.00000,1.608132e-07,0.73977,4
350.01959,219.75000,     -0.66655,  5.12134,50.00000,20.00000,1.608962e-07,0.73979,4
350.01651,220.50000,     -0.66729,  5.05607,50.00000,20.00000,1.607923e-07,0.73980,4
350.01143,221.25000,     -0.66604,  4.98190,50.00000,20.00000,1.609239e-07,0.73980,4
350.01551,222.00000,     -0.66684,  4.91882,50.00000,20.00000,1.608570e-07,0.73980,4
350.01389,222.75000,     -0.66874,  4.85502,50.00000,20.00000,1.604808e-07,0.73980,4
350.02018,223.50000,     -0.66669,  4.77489,50.00000,20.00000,1.608951e-07,0.73979,4
350.00636,224.25000,     -0.66998,  4.70964,50.00000,20.00000,1.606268e-07,0.73981,4
350.02710,225.00000,     -0.65883,  4.64656,50.00000,20.00000,1.609498e-07,0.73979,4
350.03607,225.75000,     -0.66008,  4.57462,50.00000,20.00000,1.607578e-07,0.73978,4
350.03360,226.50000,     -0.66177,  4.51222,50.00000,20.00000,1.607206e-07,0.73978,4
350.04286,227.25000,     -0.66234,  4.44105,50.00000,20.00000,1.607511e-07,0.73977,4
350.04414,228.00000,     -0.66397,  4.37875,50.00000,20.00000,1.609271e-07,0.73977,4
350.03359,228.75000,     -0.66376,  4.30275,50.00000,20.00000,1.604861e-07,0.73978,4
350.03281,229.50000,     -0.66313,  4.24007,50.00000,20.00000,1.606770e-07,0.73978,4
350.03527,230.25000,     -0.66409,  4.18662,50.00000,20.00000,1.608180e-07,0.73978,4
350.02800,231.00000,     -0.66383,  4.12354,50.00000,20.00000,1.608390e-07,0.73979,4
350.03503,231.75000,     -0.66373,  4.05902,50.00000,20.00000,1.610591e-07,0.73978,4
350.02802,232.50000,     -0.66408,  4.00999,50.00000,20.00000,1.605772e-07,0.73979,4
350.03364,233.25000,     -0.66491,  3.94774,50.00000,20.00000,1.606178e-07,0.73978,4
350.04133,234.00000,     -0.66533,  3.88393,50.00000,20.00000,1.606779e-07,0.73977,4
350.03472,234.75000,     -0.66729,  3.82236,50.00000,20.00000,1.608380e-07,0.73978,4
350.04833,235.50000,     -0.64159,  3.77081,50.00000,20.00000,1.608061e-07,0.73977,4
350.04318,236.25000,     -0.64976,  3.71705,50.00000,20.00000,1.605079e-07,0.73977,4
350.04297,237.00000,     -0.65262,  3.66289,50.00000,20.00000,1.604578e-07,0.73977,4
350.03689,237.75000,     -0.63559,  3.59390,50.00000,20.00000,1.602668e-07,0.73978,4
350.03338,238.50000,     -0.63535,  3.55091,50.00000,20.00000,1.604241e-07,0.73978,4
350.03678,239.25000,     -0.63675,  3.50341,50.00000,20.00000,1.603674e-07,0.73978,4
350.02025,240.00000,     -0.63783,  3.42143,50.00000,20.00000,1.602068e-07,0.73979,4
350.01481,240.75000,     -0.63682,  3.38320,50.00000,20.00000,1.605979e-07,0.73980,4
350.02256,241.50000,     -0.63649,  3.33869,50.00000,20.00000,1.604659e-07,0.73979,4
350.02430,242.25000,     -0.63791,  3.27491,50.00000,20.00000,1.602761e-07,0.73979,4
350.01651,243.00000,     -0.63753,  3.23705,50.00000,20.00000,1.601002e-07,0.73980,4
350.02380,243.75000,     -0.63826,  3.17325,50.00000,20.00000,1.600248e-07,0.73979,4
350.03747,244.50000,     -0.63903,  3.12879,50.00000,20.00000,1.603209e-07,0.73978,4
350.02843,245.25000,     -0.63831,  3.06721,50.00000,20.00000,1.603962e-07,0.73979,4
350.02206,246.00000,     -0.64131,  3.02256,50.00000,20.00000,1.603593e-07,0.73979,4
350.01155,246.75000,     -0.64062,  2.98334,50.00000,20.00000,1.604073e-07,0.73980,4
350.01944,247.50000,     -0.64725,  2.92105,50.00000,20.00000,1.603294e-07,0.73979,4
350.02258,248.25000,     -0.64418,  2.87727,50.00000,20.00000,1.601044e-07,0.73979,4
350.02449,249.00000,     -0.64495,  2.83123,50.00000,20.00000,1.603035e-07,0.73979,4
350.02207,249.75000,     -0.64515,  2.79567,50.00000,20.00000,1.602420e-07,0.73979,4
350.02467,250.50000,     -0.64482,  2.73328,50.00000,20.00000,1.599837e-07,0.73979,4
350.04021,251.25000,     -0.64575,  2.68885,50.00000,20.00000,1.599824e-07,0.73977,4
350.03299,252.00000,     -0.64725,  2.65325,50.00000,20.00000,1.600644e-07,0.73978,4
350.03148,252.75000,     -0.64781,  2.60728,50.00000,20.00000,1.598929e-07,0.73978,4
350.03164,253.50000,     -0.64749,  2.56275,50.00000,20.00000,1.599043e-07,0.73978,4
350.02430,254.25000,     -0.64736,  2.51750,50.00000,20.00000,1.598144e-07,0.73979,4
350.02857,255.00000,     -0.64764,  2.47593,50.00000,20.00000,1.600415e-07,0.73979,4
350.02719,255.75000,     -0.64840,  2.44479,50.00000,20.00000,1.598036e-07,0.73979,4
350.03225,256.50000,     -0.64747,  2.40026,50.00000,20.00000,1.598639e-07,0.73978,4
350.03894,257.25000,     -0.64746,  2.36243,50.00000,20.00000,1.601285e-07,0.73978,4
350.03337,258.00000,     -0.64866,  2.32610,50.00000,20.00000,1.601319e-07,0.73978,4
350.02783,258.75000,     -0.65003,  2.28826,50.00000,20.00000,1.600858e-07,0.73979,4
350.05263,259.50000,     -0.64923,  2.25416,50.00000,20.00000,1.598443e-07,0.73976,4
350.05241,260.25000,     -0.64905,  2.21856,50.00000,20.00000,1.599383e-07,0.73976,4
350.05886,261.00000,     -0.64915,  2.16795,50.00000,20.00000,1.598692e-07,0.73976,4
350.06881,261.75000,     -0.65064,  2.13102,50.00000,20.00000,1.597690e-07,0.73975,4
350.06904,262.50000,     -0.65234,  2.09541,50.00000,20.00000,1.597041e-07,0.73975,4
350.06815,263.25000,     -0.65457,  2.05089,50.00000,20.00000,1.599543e-07,0.73975,4
350.05975,264.00000,     -0.65549,  2.02420,50.00000,20.00000,1.598219e-07,0.73976,4
350.06968,264.75000,     -0.65709,  1.98859,50.00000,20.00000,1.597506e-07,0.73975,4
350.06694,265.50000,     -0.65684,  1.94407,50.00000,20.00000,1.599031e-07,0.73975,4
350.07136,266.25000,     -0.65649,  1.90846,50.00000,20.00000,1.597252e-07,0.73974,4
350.06090,267.00000,     -0.65884,  1.87285,50.00000,20.00000,1.596868e-07,0.73975,4
350.05508,267.75000,     -0.65943,  1.83574,50.00000,20.00000,1.596166e-07,0.73976,4
350.05780,268.50000,     -0.65958,  1.79829,50.00000,20.00000,1.591826e-07,0.73976,4
350.04383,269.25000,     -0.65971,  1.78014,50.00000,20.00000,1.596670e-07,0.73977,4
350.05176,270.00000,     -0.65706,  1.73783,50.00000,20.00000,1.596711e-07,0.73976,4
350.04493,270.75000,     -0.65829,  1.70000,50.00000,20.00000,1.592500e-07,0.73977,4
350.02960,271.50000,     -0.65944,  1.67331,50.00000,20.00000,1.596831e-07,0.73978,4
350.02789,272.25000,     -0.65876,  1.64665,50.00000,20.00000,1.594820e-07,0.73979,4
350.00166,273.00000,     -0.65913,  1.61023,50.00000,20.00000,1.595689e-07,0.73981,4
350.00613,273.75000,     -0.65831,  1.58638,50.00000,20.00000,1.593513e-07,0.73981,4
350.00950,274.50000,     -0.65785,  1.55456,50.00000,20.00000,1.595050e-07,0.73980,4
350.01172,275.25000,     -0.65751,  1.52787,50.00000,20.00000,1.595346e-07,0.73980,4
350.00363,276.00000,     -0.65791,  1.49672,50.00000,20.00000,1.593691e-07,0.73981,4
350.00264,276.75000,     -0.65780,  1.45889,50.00000,20.00000,1.594564e-07,0.73981,4
350.01105,277.50000,     -0.65510,  1.42551,50.00000,20.00000,1.594408e-07,0.73980,4
350.00576,278.25000,     -0.65625,  1.40327,50.00000,20.00000,1.594524e-07,0.73981,4
350.00671,279.00000,     -0.65469,  1.37875,50.00000,20.00000,1.592220e-07,0.73981,4
350.02038,279.75000,     -0.65341,  1.35207,50.00000,20.00000,1.593784e-07,0.73979,4
350.01219,280.50000,     -0.65638,  1.32459,50.00000,20.00000,1.592032e-07,0.73980,4
350.01733,281.25000,     -0.65583,  1.29790,50.00000,20.00000,1.593379e-07,0.73980,4
350.02145,282.00000,     -0.65529,  1.28013,50.00000,20.00000,1.596052e-07,0.73979,4
350.01873,282.75000,     -0.65588,  1.25338,50.00000,20.00000,1.590647e-07,0.73979,4
351.19900,283.50000,     -0.31485,  1.28533,50.00000,20.00000,1.595680e-07,0.73867,5
357.56869,284.25000,      0.66530,  1.43796,50.00000,20.00000,1.594050e-07,0.73259,5
364.23403,285.00000,      0.70596,  1.44906,50.00000,20.00000,1.590647e-07,0.72624,5
370.63776,285.75000,      0.70434,  1.45228,50.00000,20.00000,1.594218e-07,0.72016,5
378.06847,286.50000,      0.88084,  1.46349,50.00000,20.00000,1.593253e-07,0.71312,5
385.85261,287.25000,      0.92692,  1.44178,50.00000,20.00000,1.590356e-07,0.70578,5
393.66844,288.00000,      0.91453,  1.38244,50.00000,20.00000,1.592856e-07,0.69846,5
401.58721,288.75000,      0.90256,  1.29902,50.00000,20.00000,1.591870e-07,0.69109,5
409.50356,289.50000,      0.86871,  1.18206,50.00000,20.00000,1.595238e-07,0.68379,5
417.38907,290.25000,      0.82003,  1.03788,50.00000,20.00000,1.593972e-07,0.67658,5
425.21357,291.00000,      0.76658,  0.89267,50.00000,20.00000,1.590604e-07,0.66950,5
433.01163,291.75000,      0.70758,  0.79299,50.00000,20.00000,1.592006e-07,0.66252,5
440.74485,292.50000,      0.64090,  0.74286,50.00000,20.00000,1.593046e-07,0.65568,5
448.43252,293.25000,      0.57473,  0.73605,50.00000,20.00000,1.595791e-07,0.64897,5
456.08946,294.00000,      0.51080,  0.74392,50.00000,20.00000,1.595843e-07,0.64237,5
463.71799,294.75000,      0.44860,  0.75926,50.00000,20.00000,1.593083e-07,0.63590,5
471.33209,295.50000,      0.38438,  0.77830,50.00000,20.00000,1.592286e-07,0.62953,5
478.92621,296.25000,      0.32137,  0.80909,50.00000,20.00000,1.593384e-07,0.62327,5
486.48808,297.00000,      0.25407,  0.83165,50.00000,20.00000,1.595529e-07,0.61715,5
494.04900,297.75000,      0.18651,  0.84861,50.00000,20.00000,1.595901e-07,0.61112,5
501.57982,298.50000,      0.12096,  0.88458,50.00000,20.00000,1.595614e-07,0.60523,5
509.08322,299.25000, 5.511440e-02,  0.90366,50.00000,20.00000,1.595594e-07,0.59946,5
516.62229,300.00000,-1.168255e-02,  0.92971,50.00000,20.00000,1.594726e-07,0.59377,5
524.13684,300.75000,-8.412333e-02,  0.95776,50.00000,20.00000,1.592367e-07,0.58821,5
531.64993,301.50000,     -0.15840,  0.98875,50.00000,20.00000,1.597068e-07,0.58276,5
539.14964,302.25000,     -0.21216,  1.01563,50.00000,20.00000,1.595561e-07,0.57743,5
546.65326,303.00000,     -0.27313,  1.04950,50.00000,20.00000,1.596452e-07,0.57220,5
554.15792,303.75000,     -0.33564,  1.06524,50.00000,20.00000,1.595463e-07,0.56708,5
561.68215,304.50000,     -0.39865,  1.08291,50.00000,20.00000,1.593648e-07,0.56206,5
569.19887,305.25000,     -0.46057,  1.11379,50.00000,20.00000,1.593222e-07,0.55715,5
576.70689,306.00000,     -0.52502,  1.12739,50.00000,20.00000,1.596998e-07,0.55235,5
584.20898,306.75000,     -0.58375,  1.14498,50.00000,20.00000,1.594616e-07,0.54765,5
591.71491,307.50000,     -0.64153,  1.16141,50.00000,20.00000,1.596872e-07,0.54306,5
599.23409,308.25000,     -0.69589,  1.18059,50.00000,20.00000,1.596835e-07,0.53856,5
606.73416,309.00000,     -0.75107,  1.19098,50.00000,20.00000,1.597261e-07,0.53417,5
614.24236,309.75000,     -0.80257,  1.21477,50.00000,20.00000,1.596171e-07,0.52988,5
621.76554,310.50000,     -0.85176,  1.22465,50.00000,20.00000,1.595849e-07,0.52567,5
629.27881,311.25000,     -0.90197,  1.23077,50.00000,20.00000,1.597176e-07,0.52155,5
636.79567,312.00000,     -0.95506,  1.25357,50.00000,20.00000,1.597161e-07,0.51752,5
644.29814,312.75000,     -1.00393,  1.26315,50.00000,20.00000,1.595371e-07,0.51359,5
651.80863,313.50000,     -1.05242,  1.27968,50.00000,20.00000,1.596159e-07,0.50973,5
659.32960,314.25000,     -1.10414,  1.28705,50.00000,20.00000,1.599285e-07,0.50595,5
666.83100,315.00000,     -1.16096,  1.29647,50.00000,20.00000,1.598170e-07,0.50225,5
674.35322,315.75000,     -1.21733,  1.31039,50.00000,20.00000,1.596723e-07,0.49862,5
681.86193,316.50000,     -1.27591,  1.32248,50.00000,20.00000,1.595839e-07,0.49505,5
689.37908,317.25000,     -1.33736,  1.32440,50.00000,20.00000,1.597836e-07,0.49155,5
696.90011,318.00000,     -1.40662,  1.32994,50.00000,20.00000,1.598958e-07,0.48811,5
704.42460,318.75000,     -1.48680,  1.33743,50.00000,20.00000,1.599198e-07,0.48472,5
711.94465,319.50000,     -1.57285,  1.34886,50.00000,20.00000,1.598449e-07,0.48139,5
719.45205,320.25000,     -1.66641,  1.35237,50.00000,20.00000,1.600854e-07,0.47811,5
726.98597,321.00000,     -1.76153,  1.35686,50.00000,20.00000,1.598338e-07,0.47486,5
734.50619,321.75000,     -1.86264,  1.36654,50.00000,20.00000,1.601897e-07,0.47166,5
742.02063,322.50000,     -1.96673,  1.36790,50.00000,20.00000,1.604533e-07,0.46850,5
749.54860,323.25000,     -2.07370,  1.38305,50.00000,20.00000,1.597703e-07,0.46536,5
757.06081,324.00000,     -2.17977,  1.39305,50.00000,20.00000,1.594276e-07,0.46226,5
764.57299,324.75000,     -2.28771,  1.39617,50.00000,20.00000,1.602848e-07,0.45918,5
772.09236,325.50000,     -2.39526,  1.40644,50.00000,20.00000,1.601779e-07,0.45613,5
779.59959,326.25000,     -2.50153,  1.41516,50.00000,20.00000,1.605313e-07,0.45309,5
787.12231,327.00000,     -2.60821,  1.41367,50.00000,20.00000,1.604224e-07,0.45006,5
794.63124,327.75000,     -2.71485,  1.43135,50.00000,20.00000,1.597668e-07,0.44704,5