File: data/TGA/archived/ExpDat_2024_01_12_SL_001G.csv
#EXPORTTYPE:                 ,DATA ALL
#FILE:                       ,2024_01_12_SL_001G.ngb-ss5
#FORMAT:                     ,NETZSCH5
#FTYPE:                      ,ASCII
#IDENTITY:                   ,polystyrene
#DECIMAL:                    ,POINT
#SEPARATOR:                  ,COMMA
#MTYPE:                      ,DSC
#INSTRUMENT:                 ,NETZSCH STA 449F5
#PROJECT:                    ,2024_01_08_SL_007B
#DATE/TIME:                  ,1/12/2024 5:46:24 PM (UTC-5)
#CORR. FILE:                 ,
#TEMPCAL:                    ,28-06-2023 13:26
#SENSITIVITY:                ,28-06-2023 13:53
#LABORATORY:                 ,Tran/AAG
#OPERATOR:                   ,Stanley
#REMARK:                     ,
#SAMPLE:                     ,001G
#SAMPLE MASS /mg:            ,15.20
#MATERIAL:                   ,
#REFERENCE:                  ,
#REFERENCE MASS /mg:         ,0
#TYPE OF CRUCIBLE:           ,Al2O3 85 ‘l, open
#SAMPLE CRUCIBLE MASS /mg:   ,0
#REFERENCE CRUCIBLE MASS /mg:,0
#DSC RANGE /‘V:              ,5000
#TG RANGE /mg:               ,35000
#TAU-R:                      ,---
#CORR. CODE:                 ,000
#EXO:                        ,-1
#RANGE:                      ,20›C....800›C/0.0....10.0K/min
#SEGMENT:                    ,S1-5/5
#SEG. 1:                     ,20›C/10.0(K/min)/100›C
#SEG. 2:                     ,100›C/00:10/100›C
#SEG. 3:                     ,100›C/10.0(K/min)/350›C
#SEG. 4:                     ,350›C/04:00/350›C
#SEG. 5:                     ,350›C/10.0(K/min)/800›C

##Temp./›C,Time/min,DSC/(mW/mg),Mass/%,Gas Flow(purge2)/(ml/min),Gas Flow(protective)/(ml/min),TIC(scan:1)/A,Sensit./(uV/mW),Segment
 41.11100,  0.00000,      0.47665,    100.00000,50.00000,20.00000,1.886318e-07,0.92521,1
 43.78100,  0.60000,      0.31207,     99.70158,50.00000,20.00000,1.925519e-07,0.92549,1
 45.85900,  1.20000,      0.22438,     99.51921,50.00000,20.00000,2.052092e-07,0.92567,1
 47.37300,  1.80000,      0.15907,     97.73592,50.00000,20.00000,2.265005e-07,0.92579,1
 48.37200,  2.40000,      0.10452,     97.32211,50.00000,20.00000,2.427952e-07,0.92586,1
 49.06700,  3.00000, 6.944331e-02,     97.26625,50.00000,20.00000,2.439657e-07,0.92590,1
 49.92200,  3.60000, 8.385868e-02,     97.28638,50.00000,20.00000,2.430746e-07,0.92595,1
 51.54700,  4.20000,      0.15892,     97.45829,50.00000,20.00000,2.414695e-07,0.92604,1
 54.13400,  4.80000,      0.27472,     97.67638,50.00000,20.00000,2.391720e-07,0.92613,1
 57.72000,  5.40000,      0.39951,     97.90263,50.00000,20.00000,2.357794e-07,0.92620,1
 62.12400,  6.00000,      0.51854,     98.12441,50.00000,20.00000,2.316407e-07,0.92617,1
 67.24900,  6.60000,      0.63128,     98.31717,50.00000,20.00000,2.273557e-07,0.92598,1
 73.05000,  7.20000,      0.74186,     98.49882,50.00000,20.00000,2.233776e-07,0.92557,1
 79.39300,  7.80000,      0.84813,     98.66776,50.00000,20.00000,2.205292e-07,0.92489,1
 86.04331,  8.40000,      0.90818,     98.75995,50.00000,20.00000,2.181111e-07,0.92391,2
 91.73948,  9.00000,      0.81016,     98.61965,50.00000,20.00000,2.156740e-07,0.92287,2
 95.98955,  9.60000,      0.64031,     98.39798,50.00000,20.00000,2.140471e-07,0.92197,2
 99.16464, 10.20000,      0.49912,     98.20872,50.00000,20.00000,2.123301e-07,0.92123,2
101.78819, 10.80000,      0.42760,     98.08872,50.00000,20.00000,2.103419e-07,0.92058,2
103.99997, 11.40000,      0.36232,     97.98867,50.00000,20.00000,2.100006e-07,0.92000,2
105.76037, 12.00000,      0.27904,     97.87630,50.00000,20.00000,2.087347e-07,0.91951,2
106.99783, 12.60000,      0.19518,     97.73112,50.00000,20.00000,2.075252e-07,0.91916,2
107.77567, 13.20000,      0.12060,     97.60990,50.00000,20.00000,2.066496e-07,0.91894,2
108.17500, 13.80000, 5.922658e-02,     97.48453,50.00000,20.00000,2.054831e-07,0.91882,2
108.30142, 14.40000, 1.200692e-02,     97.38925,50.00000,20.00000,2.043495e-07,0.91879,2
108.21565, 15.00000,-2.513910e-02,     97.28162,50.00000,20.00000,2.032011e-07,0.91881,2
107.94173, 15.60000,-5.530915e-02,     97.21460,50.00000,20.00000,2.019999e-07,0.91889,2
107.53430, 16.20000,-7.821862e-02,     97.13626,50.00000,20.00000,2.012242e-07,0.91901,2
107.02379, 16.80000,-9.550149e-02,     97.09136,50.00000,20.00000,2.000865e-07,0.91916,2
106.45836, 17.40000,     -0.10620,     97.02915,50.00000,20.00000,1.992163e-07,0.91932,2
105.85099, 18.00000,     -0.11342,     96.97454,50.00000,20.00000,1.980846e-07,0.91949,3
105.59001, 18.60000,-5.917647e-02,     97.03710,50.00000,20.00000,1.972749e-07,0.91956,3
106.80712, 19.20000,      0.14564,     97.34824,50.00000,20.00000,1.960682e-07,0.91922,3
109.47476, 19.80000,      0.37659,     97.65474,50.00000,20.00000,1.952204e-07,0.91844,3
112.98036, 20.40000,      0.54183,     97.86024,50.00000,20.00000,1.945428e-07,0.91735,3
117.06710, 21.00000,      0.66911,     98.01887,50.00000,20.00000,1.933953e-07,0.91601,3
121.85675, 21.60000,      0.80694,     98.17872,50.00000,20.00000,1.925282e-07,0.91431,3
127.42579, 22.20000,      0.95720,     98.33890,50.00000,20.00000,1.920262e-07,0.91219,3
133.62564, 22.80000,      1.09513,     98.47500,50.00000,20.00000,1.908745e-07,0.90964,3
140.27075, 23.40000,      1.20911,     98.59855,50.00000,20.00000,1.901777e-07,0.90670,3
147.22499, 24.00000,      1.29847,     98.67892,50.00000,20.00000,1.893769e-07,0.90339,3
154.35011, 24.60000,      1.36983,     98.75112,50.00000,20.00000,1.888232e-07,0.89976,3
161.58120, 25.20000,      1.42247,     98.80546,50.00000,20.00000,1.882299e-07,0.89584,3
168.85835, 25.80000,      1.45833,     98.85013,50.00000,20.00000,1.881237e-07,0.89166,3
176.09126, 26.40000,      1.47652,     98.89474,50.00000,20.00000,1.870006e-07,0.88729,3
183.25979, 27.00000,      1.45596,     98.90368,50.00000,20.00000,1.867139e-07,0.88274,3
190.34537, 27.60000,      1.42413,     98.91263,50.00000,20.00000,1.863979e-07,0.87806,3
197.33795, 28.20000,      1.39912,     98.91934,50.00000,20.00000,1.857100e-07,0.87325,3
204.17645, 28.80000,      1.37567,     98.91935,50.00000,20.00000,1.856628e-07,0.86838,3
210.88316, 29.40000,      1.35221,     98.91435,50.00000,20.00000,1.851243e-07,0.86345,3
217.48017, 30.00000,      1.32784,     98.91049,50.00000,20.00000,1.845140e-07,0.85846,3
223.94777, 30.60000,      1.30475,     98.91817,50.00000,20.00000,1.842179e-07,0.85344,3
230.32510, 31.20000,      1.28476,     98.90072,50.00000,20.00000,1.839735e-07,0.84837,3
236.61023, 31.80000,      1.26561,     98.90967,50.00000,20.00000,1.836793e-07,0.84326,3
242.83656, 32.40000,      1.24733,     98.90705,50.00000,20.00000,1.832002e-07,0.83811,3
248.97280, 33.00000,      1.23113,     98.89849,50.00000,20.00000,1.828502e-07,0.83294,3
255.07632, 33.60000,      1.21657,     98.88730,50.00000,20.00000,1.824334e-07,0.82771,3
261.14444, 34.20000,      1.20387,     98.88059,50.00000,20.00000,1.819833e-07,0.82244,3
267.16692, 34.80000,      1.19292,     98.83203,50.00000,20.00000,1.817012e-07,0.81713,3
273.17006, 35.40000,      1.18326,     98.76454,50.00000,20.00000,1.816214e-07,0.81178,3
279.15858, 36.00000,      1.17664,     98.67537,50.00000,20.00000,1.812143e-07,0.80638,3
285.12198, 36.60000,      1.17306,     98.52711,50.00000,20.00000,1.810138e-07,0.80095,3
291.06673, 37.20000,      1.16927,     98.33578,50.00000,20.00000,1.808998e-07,0.79549,3
297.00341, 37.80000,      1.16532,     98.09316,50.00000,20.00000,1.802872e-07,0.78999,3
302.92788, 38.40000,      1.16004,     97.77923,50.00000,20.00000,1.803142e-07,0.78447,3
308.85822, 39.00000,      1.15294,     97.44279,50.00000,20.00000,1.801394e-07,0.77891,3
314.78367, 39.60000,      1.14878,     97.03316,50.00000,20.00000,1.802615e-07,0.77333,3
320.71778, 40.20000,      1.14841,     96.54807,50.00000,20.00000,1.804143e-07,0.76771,3
326.63102, 40.80000,      1.15132,     95.97480,50.00000,20.00000,1.797693e-07,0.76210,3
332.56946, 41.40000,      1.15651,     95.26563,50.00000,20.00000,1.801197e-07,0.75645,3
338.48073, 42.00000,      1.16548,     94.38592,50.00000,20.00000,1.800680e-07,0.75081,3
344.41197, 42.60000,      1.17480,     93.36015,50.00000,20.00000,1.802495e-07,0.74515,3
350.21961, 43.20000,      1.14739,     92.17390,50.00000,20.00000,1.802505e-07,0.73960,4
353.06907, 43.80000,      0.47576,     90.79118,50.00000,20.00000,1.803206e-07,0.73688,4
353.45386, 44.40000,-8.427720e-02,     89.39179,50.00000,20.00000,1.803713e-07,0.73652,4
353.91145, 45.00000,     -0.17003,     88.17628,50.00000,20.00000,1.808880e-07,0.73608,4
354.60447, 45.60000,     -0.18206,     86.99565,50.00000,20.00000,1.808168e-07,0.73542,4
354.83322, 46.20000,     -0.30043,     85.83057,50.00000,20.00000,1.804484e-07,0.73520,4
354.63922, 46.80000,     -0.41310,     84.70619,50.00000,20.00000,1.801709e-07,0.73539,4
354.33303, 47.40000,     -0.46166,     83.60748,50.00000,20.00000,1.800024e-07,0.73568,4
354.05559, 48.00000,     -0.48324,     82.59198,50.00000,20.00000,1.802521e-07,0.73594,4
353.74055, 48.60000,     -0.50587,     81.59913,50.00000,20.00000,1.802413e-07,0.73624,4
353.39411, 49.20000,     -0.52635,     80.63661,50.00000,20.00000,1.807939e-07,0.73657,4
353.05199, 49.80000,     -0.53858,     79.72528,50.00000,20.00000,1.806151e-07,0.73690,4
352.73205, 50.40000,     -0.54381,     78.84373,50.00000,20.00000,1.802609e-07,0.73720,4
352.42529, 51.00000,     -0.54649,     78.02032,50.00000,20.00000,1.805524e-07,0.73750,4
352.15595, 51.60000,     -0.54944,     77.19893,50.00000,20.00000,1.807005e-07,0.73775,4
351.90678, 52.20000,     -0.55110,     76.40310,50.00000,20.00000,1.808344e-07,0.73799,4
351.69681, 52.80000,     -0.55120,     75.65880,50.00000,20.00000,1.806696e-07,0.73819,4
351.48135, 53.40000,     -0.55191,     74.90337,50.00000,20.00000,1.801491e-07,0.73840,4
351.31324, 54.00000,     -0.55287,     74.19655,50.00000,20.00000,1.805872e-07,0.73856,4
351.15506, 54.60000,     -0.55322,     73.49131,50.00000,20.00000,1.804866e-07,0.73871,4
351.02358, 55.20000,     -0.55231,     72.78873,50.00000,20.00000,1.802780e-07,0.73884,4
350.90434, 55.80000,     -0.55320,     72.12325,50.00000,20.00000,1.795868e-07,0.73895,4
350.79890, 56.40000,     -0.55417,     71.47673,50.00000,20.00000,1.800727e-07,0.73905,4
350.69413, 57.00000,     -0.55475,     70.83953,50.00000,20.00000,1.800829e-07,0.73915,4
350.60949, 57.60000,     -0.55610,     70.20843,50.00000,20.00000,1.799521e-07,0.73923,4
350.52836, 58.20000,     -0.55612,     69.58220,50.00000,20.00000,1.800294e-07,0.73931,4
350.47334, 58.80000,     -0.55689,     69.00521,50.00000,20.00000,1.793019e-07,0.73936,4
350.50886, 59.40000,     -0.55744,     68.40609,50.00000,20.00000,1.798561e-07,0.73933,4
350.37041, 60.00000,     -0.55773,     67.82821,50.00000,20.00000,1.795958e-07,0.73946,4
350.33036, 60.60000,     -0.56041,     67.23901,50.00000,20.00000,1.796251e-07,0.73950,4
350.28102, 61.20000,     -0.56144,     66.68870,50.00000,20.00000,1.798424e-07,0.73954,4
350.25912, 61.80000,     -0.56209,     66.14271,50.00000,20.00000,1.795355e-07,0.73957,4
350.22358, 62.40000,     -0.56390,     65.59749,50.00000,20.00000,1.798391e-07,0.73960,4
350.19884, 63.00000,     -0.56570,     65.06233,50.00000,20.00000,1.795917e-07,0.73962,4
350.17987, 63.60000,     -0.56629,     64.53693,50.00000,20.00000,1.796934e-07,0.73964,4
350.15297, 64.20000,     -0.56696,     64.02040,50.00000,20.00000,1.796000e-07,0.73967,4
350.13999, 64.80000,     -0.56785,     63.49867,50.00000,20.00000,1.794239e-07,0.73968,4
350.13426, 65.40000,     -0.57008,     62.98654,50.00000,20.00000,1.794416e-07,0.73968,4
350.11770, 66.00000,     -0.57218,     62.47425,50.00000,20.00000,1.794511e-07,0.73970,4
350.10018, 66.60000,     -0.57276,     61.99200,50.00000,20.00000,1.795092e-07,0.73972,4
350.09104, 67.20000,     -0.57376,     61.49569,50.00000,20.00000,1.794689e-07,0.73973,4
350.07933, 67.80000,     -0.57470,     61.01782,50.00000,20.00000,1.798366e-07,0.73974,4
350.08353, 68.40000,     -0.57607,     60.54584,50.00000,20.00000,1.795812e-07,0.73973,4
350.08803, 69.00000,     -0.57805,     60.07766,50.00000,20.00000,1.791932e-07,0.73973,4
350.07738, 69.60000,     -0.57911,     59.62235,50.00000,20.00000,1.794416e-07,0.73974,4
350.07341, 70.20000,     -0.58026,     59.16774,50.00000,20.00000,1.792500e-07,0.73974,4
350.07048, 70.80000,     -0.58170,     58.71052,50.00000,20.00000,1.791987e-07,0.73975,4
350.05712, 71.40000,     -0.58407,     58.24711,50.00000,20.00000,1.793389e-07,0.73976,4
350.04750, 72.00000,     -0.58584,     57.82054,50.00000,20.00000,1.795324e-07,0.73977,4
350.04670, 72.60000,     -0.58568,     57.37397,50.00000,20.00000,1.790187e-07,0.73977,4
350.04403, 73.20000,     -0.58609,     56.94077,50.00000,20.00000,1.788890e-07,0.73977,4
350.05002, 73.80000,     -0.58792,     56.50004,50.00000,20.00000,1.789202e-07,0.73976,4
350.04282, 74.40000,     -0.58954,     56.08612,50.00000,20.00000,1.790636e-07,0.73977,4
350.03435, 75.00000,     -0.59082,     55.66883,50.00000,20.00000,1.786792e-07,0.73978,4
350.03864, 75.60000,     -0.59190,     55.26447,50.00000,20.00000,1.786175e-07,0.73978,4
350.02833, 76.20000,     -0.59281,     54.83791,50.00000,20.00000,1.786135e-07,0.73979,4
350.03873, 76.80000,     -0.59450,     54.44390,50.00000,20.00000,1.786768e-07,0.73978,4
350.03037, 77.40000,     -0.59579,     54.04904,50.00000,20.00000,1.783264e-07,0.73978,4
350.03656, 78.00000,     -0.59636,     53.65553,50.00000,20.00000,1.788761e-07,0.73978,4
350.03593, 78.60000,     -0.59775,     53.25513,50.00000,20.00000,1.784121e-07,0.73978,4
350.01894, 79.20000,     -0.59875,     52.85603,50.00000,20.00000,1.780298e-07,0.73979,4
350.02542, 79.80000,     -0.59965,     52.46825,50.00000,20.00000,1.784189e-07,0.73979,4
350.02472, 80.40000,     -0.60033,     52.08479,50.00000,20.00000,1.780058e-07,0.73979,4
350.02351, 81.00000,     -0.60046,     51.70217,50.00000,20.00000,1.780432e-07,0.73979,4
350.02909, 81.60000,     -0.60189,     51.34127,50.00000,20.00000,1.780349e-07,0.73978,4
350.03206, 82.20000,     -0.60427,     50.98418,50.00000,20.00000,1.779081e-07,0.73978,4
350.03017, 82.80000,     -0.60527,     50.62780,50.00000,20.00000,1.777902e-07,0.73978,4
350.03304, 83.40000,     -0.60567,     50.25018,50.00000,20.00000,1.776714e-07,0.73978,4
350.04133, 84.00000,     -0.60612,     49.91182,50.00000,20.00000,1.775657e-07,0.73977,4
350.02982, 84.60000,     -0.60785,     49.55287,50.00000,20.00000,1.778406e-07,0.73978,4
350.03424, 85.20000,     -0.60914,     49.19630,50.00000,20.00000,1.777831e-07,0.73978,4
350.02649, 85.80000,     -0.60959,     48.86254,50.00000,20.00000,1.774456e-07,0.73979,4
350.03243, 86.40000,     -0.61066,     48.50787,50.00000,20.00000,1.775355e-07,0.73978,4
350.03508, 87.00000,     -0.61147,     48.16085,50.00000,20.00000,1.778339e-07,0.73978,4
350.03284, 87.60000,     -0.61273,     47.81936,50.00000,20.00000,1.774087e-07,0.73978,4
350.02655, 88.20000,     -0.61472,     47.49226,50.00000,20.00000,1.774730e-07,0.73979,4
350.00888, 88.80000,     -0.61574,     47.17355,50.00000,20.00000,1.773494e-07,0.73980,4
350.01584, 89.40000,     -0.61577,     46.83200,50.00000,20.00000,1.773915e-07,0.73980,4
350.00860, 90.00000,     -0.61523,     46.51090,50.00000,20.00000,1.770754e-07,0.73980,4
350.02644, 90.60000,     -0.61619,     46.20372,50.00000,20.00000,1.769124e-07,0.73979,4
350.02084, 91.20000,     -0.61738,     45.86824,50.00000,20.00000,1.771403e-07,0.73979,4
350.03152, 91.80000,     -0.61836,     45.55411,50.00000,20.00000,1.772804e-07,0.73978,4
350.02431, 92.40000,     -0.61930,     45.23466,50.00000,20.00000,1.768370e-07,0.73979,4
350.03180, 93.00000,     -0.62020,     44.93788,50.00000,20.00000,1.766696e-07,0.73978,4
350.03826, 93.60000,     -0.62020,     44.62523,50.00000,20.00000,1.766948e-07,0.73978,4
350.03615, 94.20000,     -0.62182,     44.31827,50.00000,20.00000,1.765469e-07,0.73978,4
350.03692, 94.80000,     -0.62233,     44.00263,50.00000,20.00000,1.768002e-07,0.73978,4
350.03237, 95.40000,     -0.62360,     43.71100,50.00000,20.00000,1.767109e-07,0.73978,4
350.02764, 96.00000,     -0.62364,     43.41189,50.00000,20.00000,1.762752e-07,0.73979,4
350.03398, 96.60000,     -0.62441,     43.11957,50.00000,20.00000,1.761104e-07,0.73978,4
350.03442, 97.20000,     -0.62638,     42.82746,50.00000,20.00000,1.761423e-07,0.73978,4
350.01802, 97.80000,     -0.62664,     42.54762,50.00000,20.00000,1.759364e-07,0.73980,4
350.02003, 98.40000,     -0.62685,     42.26141,50.00000,20.00000,1.761134e-07,0.73979,4
350.01979, 99.00000,     -0.62750,     41.98382,50.00000,20.00000,1.761551e-07,0.73979,4
350.03478, 99.60000,     -0.62800,     41.71492,50.00000,20.00000,1.761865e-07,0.73978,4
350.03296,100.20000,     -0.62822,     41.43169,50.00000,20.00000,1.763591e-07,0.73978,4
350.02859,100.80000,     -0.62925,     41.16135,50.00000,20.00000,1.760064e-07,0.73979,4
350.03464,101.40000,     -0.63079,     40.88825,50.00000,20.00000,1.759586e-07,0.73978,4
350.02239,102.00000,     -0.63107,     40.62012,50.00000,20.00000,1.759489e-07,0.73979,4
350.02650,102.60000,     -0.63162,     40.35512,50.00000,20.00000,1.757532e-07,0.73979,4
350.03110,103.20000,     -0.63202,     40.07600,50.00000,20.00000,1.759853e-07,0.73978,4
350.02996,103.80000,     -0.63269,     39.81932,50.00000,20.00000,1.758501e-07,0.73978,4
350.02478,104.40000,     -0.63421,     39.55137,50.00000,20.00000,1.760340e-07,0.73979,4
350.03329,105.00000,     -0.63549,     39.28637,50.00000,20.00000,1.760722e-07,0.73978,4
350.03027,105.60000,     -0.63581,     39.03854,50.00000,20.00000,1.757692e-07,0.73978,4
350.03058,106.20000,     -0.63563,     38.78057,50.00000,20.00000,1.761276e-07,0.73978,4
350.03292,106.80000,     -0.63606,     38.52500,50.00000,20.00000,1.758588e-07,0.73978,4
350.03483,107.40000,     -0.63684,     38.27257,50.00000,20.00000,1.758759e-07,0.73978,4
350.03580,108.00000,     -0.63791,     38.03822,50.00000,20.00000,1.757868e-07,0.73978,4
350.03423,108.60000,     -0.63869,     37.78160,50.00000,20.00000,1.759042e-07,0.73978,4
350.02836,109.20000,     -0.63906,     37.54117,50.00000,20.00000,1.757175e-07,0.73979,4
350.02025,109.80000,     -0.63913,     37.32672,50.00000,20.00000,1.756562e-07,0.73979,4
350.02059,110.40000,     -0.63959,     37.08408,50.00000,20.00000,1.756521e-07,0.73979,4
350.02930,111.00000,     -0.64032,     36.83537,50.00000,20.00000,1.754158e-07,0.73978,4
350.02865,111.60000,     -0.63975,     36.60715,50.00000,20.00000,1.754731e-07,0.73979,4
350.02519,112.20000,     -0.64064,     36.37400,50.00000,20.00000,1.749911e-07,0.73979,4
350.02160,112.80000,     -0.64190,     36.13382,50.00000,20.00000,1.747955e-07,0.73979,4
350.01878,113.40000,     -0.64249,     35.92370,50.00000,20.00000,1.744606e-07,0.73979,4
350.02468,114.00000,     -0.64218,     35.67972,50.00000,20.00000,1.745514e-07,0.73979,4
350.01741,114.60000,     -0.64228,     35.46129,50.00000,20.00000,1.738541e-07,0.73980,4
350.03093,115.20000,     -0.64288,     35.24510,50.00000,20.00000,1.738377e-07,0.73978,4
350.02330,115.80000,     -0.64319,     35.01276,50.00000,20.00000,1.735522e-07,0.73979,4
350.02584,116.40000,     -0.64455,     34.80007,50.00000,20.00000,1.731642e-07,0.73979,4
350.02243,117.00000,     -0.64547,     34.58324,50.00000,20.00000,1.727631e-07,0.73979,4
350.02816,117.60000,     -0.64544,     34.37195,50.00000,20.00000,1.722303e-07,0.73979,4
350.02994,118.20000,     -0.64537,     34.15536,50.00000,20.00000,1.721914e-07,0.73978,4
350.02760,118.80000,     -0.64608,     33.94300,50.00000,20.00000,1.719094e-07,0.73979,4
350.02566,119.40000,     -0.64734,     33.73323,50.00000,20.00000,1.714663e-07,0.73979,4
350.02462,120.00000,     -0.64670,     33.52049,50.00000,20.00000,1.708853e-07,0.73979,4
350.02942,120.60000,     -0.64755,     33.31870,50.00000,20.00000,1.707759e-07,0.73978,4
350.02513,121.20000,     -0.64827,     33.11398,50.00000,20.00000,1.700019e-07,0.73979,4
350.02334,121.80000,     -0.64851,     32.91684,50.00000,20.00000,1.694711e-07,0.73979,4
350.02719,122.40000,     -0.64814,     32.71202,50.00000,20.00000,1.686133e-07,0.73979,4
350.03683,123.00000,     -0.64892,     32.50297,50.00000,20.00000,1.682463e-07,0.73978,4
350.03299,123.60000,     -0.64876,     32.30598,50.00000,20.00000,1.679029e-07,0.73978,4
350.02715,124.20000,     -0.64939,     32.11800,50.00000,20.00000,1.670308e-07,0.73979,4
350.03804,124.80000,     -0.65036,     31.92339,50.00000,20.00000,1.668245e-07,0.73978,4
350.02156,125.40000,     -0.65026,     31.72821,50.00000,20.00000,1.664115e-07,0.73979,4
350.04179,126.00000,     -0.64958,     31.55107,50.00000,20.00000,1.661380e-07,0.73977,4
350.04046,126.60000,     -0.64966,     31.35159,50.00000,20.00000,1.656171e-07,0.73977,4
350.03837,127.20000,     -0.65101,     31.16113,50.00000,20.00000,1.655022e-07,0.73978,4
350.03413,127.80000,     -0.65106,     30.97653,50.00000,20.00000,1.649884e-07,0.73978,4
350.03688,128.40000,     -0.65193,     30.78435,50.00000,20.00000,1.648382e-07,0.73978,4
350.03737,129.00000,     -0.65204,     30.59682,50.00000,20.00000,1.646917e-07,0.73978,4
350.02923,129.60000,     -0.65251,     30.41671,50.00000,20.00000,1.643432e-07,0.73978,4
350.03168,130.20000,     -0.65223,     30.23451,50.00000,20.00000,1.637994e-07,0.73978,4
350.03570,130.80000,     -0.65196,     30.06025,50.00000,20.00000,1.634822e-07,0.73978,4
350.02659,131.40000,     -0.65250,     29.88388,50.00000,20.00000,1.635616e-07,0.73979,4
350.03399,132.00000,     -0.65299,     29.70370,50.00000,20.00000,1.636458e-07,0.73978,4
350.03873,132.60000,     -0.65323,     29.51973,50.00000,20.00000,1.633346e-07,0.73978,4
350.02535,133.20000,     -0.65431,     29.35850,50.00000,20.00000,1.634670e-07,0.73979,4
350.02653,133.80000,     -0.65437,     29.17965,50.00000,20.00000,1.636772e-07,0.73979,4
350.03057,134.40000,     -0.65403,     28.99889,50.00000,20.00000,1.632610e-07,0.73978,4
350.03299,135.00000,     -0.65415,     28.82244,50.00000,20.00000,1.632682e-07,0.73978,4
350.03256,135.60000,     -0.65525,     28.65340,50.00000,20.00000,1.631249e-07,0.73978,4
350.02702,136.20000,     -0.65561,     28.50028,50.00000,20.00000,1.630689e-07,0.73979,4
350.02154,136.80000,     -0.65504,     28.33782,50.00000,20.00000,1.632618e-07,0.73979,4
350.02785,137.40000,     -0.65458,     28.17523,50.00000,20.00000,1.632764e-07,0.73979,4
350.02500,138.00000,     -0.65448,     28.00455,50.00000,20.00000,1.634960e-07,0.73979,4
350.02867,138.60000,     -0.65194,     27.84473,50.00000,20.00000,1.639657e-07,0.73979,4
350.02706,139.20000,     -0.65325,     27.68287,50.00000,20.00000,1.652652e-07,0.73979,4
350.03628,139.80000,     -0.65359,     27.52386,50.00000,20.00000,1.712770e-07,0.73978,4
350.02946,140.40000,     -0.65312,     27.37487,50.00000,20.00000,1.796645e-07,0.73978,4
350.03039,141.00000,     -0.65345,     27.20810,50.00000,20.00000,1.810098e-07,0.73978,4
350.03793,141.60000,     -0.65467,     27.04683,50.00000,20.00000,1.813966e-07,0.73978,4
350.03472,142.20000,     -0.65387,     26.90528,50.00000,20.00000,1.818754e-07,0.73978,4
350.04428,142.80000,     -0.65353,     26.73629,50.00000,20.00000,1.818137e-07,0.73977,4
350.04476,143.40000,     -0.65346,     26.58360,50.00000,20.00000,1.804949e-07,0.73977,4
350.03822,144.00000,     -0.65463,     26.43183,50.00000,20.00000,1.754208e-07,0.73978,4
350.04407,144.60000,     -0.65551,     26.29875,50.00000,20.00000,1.713096e-07,0.73977,4
350.03818,145.20000,     -0.65496,     26.14098,50.00000,20.00000,1.700435e-07,0.73978,4
350.04374,145.80000,     -0.65477,     26.00112,50.00000,20.00000,1.702263e-07,0.73977,4
350.04916,146.40000,     -0.65482,     25.84971,50.00000,20.00000,1.700911e-07,0.73977,4
350.03901,147.00000,     -0.65584,     25.71298,50.00000,20.00000,1.705255e-07,0.73978,4
350.04228,147.60000,     -0.65521,     25.55782,50.00000,20.00000,1.705318e-07,0.73977,4
350.03578,148.20000,     -0.65568,     25.41136,50.00000,20.00000,1.703691e-07,0.73978,4
350.02847,148.80000,     -0.65582,     25.27530,50.00000,20.00000,1.703858e-07,0.73979,4
350.02590,149.40000,     -0.65549,     25.14499,50.00000,20.00000,1.707437e-07,0.73979,4
350.02706,150.00000,     -0.65575,     25.00609,50.00000,20.00000,1.707204e-07,0.73979,4
350.03079,150.60000,     -0.65615,     24.85403,50.00000,20.00000,1.705281e-07,0.73978,4
350.02828,151.20000,     -0.65591,     24.72846,50.00000,20.00000,1.706531e-07,0.73979,4
350.03390,151.80000,     -0.65610,     24.58020,50.00000,20.00000,1.701432e-07,0.73978,4
350.01993,152.40000,     -0.65498,     24.44625,50.00000,20.00000,1.701424e-07,0.73979,4
350.02233,153.00000,     -0.65537,     24.30926,50.00000,20.00000,1.703207e-07,0.73979,4
350.04462,153.60000,     -0.65597,     24.16342,50.00000,20.00000,1.702418e-07,0.73977,4
350.04355,154.20000,     -0.65671,     24.04362,50.00000,20.00000,1.703104e-07,0.73977,4
350.04427,154.80000,     -0.65630,     23.91175,50.00000,20.00000,1.701754e-07,0.73977,4
350.03650,155.40000,     -0.65611,     23.77320,50.00000,20.00000,1.704735e-07,0.73978,4
350.03855,156.00000,     -0.65612,     23.64741,50.00000,20.00000,1.706746e-07,0.73978,4
350.04132,156.60000,     -0.65637,     23.52397,50.00000,20.00000,1.702201e-07,0.73977,4
350.03361,157.20000,     -0.65686,     23.38780,50.00000,20.00000,1.703157e-07,0.73978,4
350.03266,157.80000,     -0.65711,     23.27249,50.00000,20.00000,1.703391e-07,0.73978,4
350.02560,158.40000,     -0.65576,     23.13931,50.00000,20.00000,1.705781e-07,0.73979,4
350.03009,159.00000,     -0.65573,     23.01428,50.00000,20.00000,1.709447e-07,0.73978,4
350.02661,159.60000,     -0.65589,     22.89287,50.00000,20.00000,1.704617e-07,0.73979,4
350.03043,160.20000,     -0.65550,     22.76862,50.00000,20.00000,1.704274e-07,0.73978,4
350.03012,160.80000,     -0.65516,     22.65004,50.00000,20.00000,1.705947e-07,0.73978,4
350.03067,161.40000,     -0.65543,     22.52966,50.00000,20.00000,1.702905e-07,0.73978,4
350.02669,162.00000,     -0.65555,     22.40621,50.00000,20.00000,1.708078e-07,0.73979,4
350.03216,162.60000,     -0.65537,     22.29320,50.00000,20.00000,1.707018e-07,0.73978,4
350.03290,163.20000,     -0.65583,     22.17026,50.00000,20.00000,1.706381e-07,0.73978,4
350.03126,163.80000,     -0.65679,     22.05641,50.00000,20.00000,1.704959e-07,0.73978,4
350.03257,164.40000,     -0.65532,     21.94323,50.00000,20.00000,1.706722e-07,0.73978,4
350.03273,165.00000,     -0.65534,     21.81895,50.00000,20.00000,1.706693e-07,0.73978,4
350.03760,165.60000,     -0.65541,     21.70658,50.00000,20.00000,1.708748e-07,0.73978,4
350.02999,166.20000,     -0.65664,     21.58565,50.00000,20.00000,1.707113e-07,0.73978,4
350.03143,166.80000,     -0.65632,     21.48250,50.00000,20.00000,1.706329e-07,0.73978,4
350.02430,167.40000,     -0.65618,     21.36197,50.00000,20.00000,1.705260e-07,0.73979,4
350.02789,168.00000,     -0.65610,     21.25928,50.00000,20.00000,1.706506e-07,0.73979,4
350.02489,168.60000,     -0.65624,     21.13814,50.00000,20.00000,1.706904e-07,0.73979,4
350.02353,169.20000,     -0.65611,     21.02408,50.00000,20.00000,1.705908e-07,0.73979,4
350.01733,169.80000,     -0.65525,     20.92132,50.00000,20.00000,1.706812e-07,0.73980,4
350.03079,170.40000,     -0.65378,     20.80912,50.00000,20.00000,1.710565e-07,0.73978,4
350.03013,171.00000,     -0.65504,     20.68681,50.00000,20.00000,1.707534e-07,0.73978,4
350.02189,171.60000,     -0.65576,     20.58345,50.00000,20.00000,1.702582e-07,0.73979,4
350.02665,172.20000,     -0.65499,     20.49135,50.00000,20.00000,1.705363e-07,0.73979,4
350.03755,172.80000,     -0.65461,     20.37875,50.00000,20.00000,1.708630e-07,0.73978,4
350.03377,173.40000,     -0.65488,     20.27605,50.00000,20.00000,1.705346e-07,0.73978,4
350.02747,174.00000,     -0.65637,     20.17704,50.00000,20.00000,1.702922e-07,0.73979,4
350.01841,174.60000,     -0.65562,     20.08642,50.00000,20.00000,1.706210e-07,0.73979,4
350.02875,175.20000,     -0.65441,     19.98120,50.00000,20.00000,1.705271e-07,0.73979,4
350.03883,175.80000,     -0.65434,     19.87453,50.00000,20.00000,1.703441e-07,0.73978,4
350.03189,176.40000,     -0.65519,     19.78185,50.00000,20.00000,1.706907e-07,0.73978,4
350.03183,177.00000,     -0.65467,     19.67767,50.00000,20.00000,1.703742e-07,0.73978,4
350.04531,177.60000,     -0.65440,     19.57493,50.00000,20.00000,1.705619e-07,0.73977,4
350.03574,178.20000,     -0.65500,     19.47520,50.00000,20.00000,1.707933e-07,0.73978,4
350.03578,178.80000,     -0.65456,     19.37546,50.00000,20.00000,1.701661e-07,0.73978,4
350.03215,179.40000,     -0.65502,     19.28541,50.00000,20.00000,1.702852e-07,0.73978,4
350.03891,180.00000,     -0.65502,     19.18568,50.00000,20.00000,1.704288e-07,0.73978,4
350.03379,180.60000,     -0.65481,     19.08599,50.00000,20.00000,1.705153e-07,0.73978,4
350.03790,181.20000,     -0.65440,     18.99458,50.00000,20.00000,1.700447e-07,0.73978,4
350.03647,181.80000,     -0.65435,     18.89395,50.00000,20.00000,1.705861e-07,0.73978,4
350.01761,182.40000,     -0.65425,     18.81127,50.00000,20.00000,1.706178e-07,0.73980,4
350.03405,183.00000,     -0.65260,     18.70934,50.00000,20.00000,1.703195e-07,0.73978,4
350.03369,183.60000,     -0.65336,     18.60961,50.00000,20.00000,1.701210e-07,0.73978,4
350.03266,184.20000,     -0.65490,     18.52849,50.00000,20.00000,1.698986e-07,0.73978,4
350.04356,184.80000,     -0.65345,     18.42805,50.00000,20.00000,1.700654e-07,0.73977,4
350.04718,185.40000,     -0.65337,     18.32733,50.00000,20.00000,1.701458e-07,0.73977,4
350.04431,186.00000,     -0.65421,     18.24566,50.00000,20.00000,1.704532e-07,0.73977,4
350.03190,186.60000,     -0.65420,     18.15914,50.00000,20.00000,1.701612e-07,0.73978,4
350.02870,187.20000,     -0.65325,     18.06407,50.00000,20.00000,1.702560e-07,0.73979,4
350.03427,187.80000,     -0.65216,     17.98313,50.00000,20.00000,1.699960e-07,0.73978,4
350.03185,188.40000,     -0.65252,     17.89138,50.00000,20.00000,1.698913e-07,0.73978,4
350.03299,189.00000,     -0.65293,     17.80059,50.00000,20.00000,1.703382e-07,0.73978,4
350.03660,189.60000,     -0.65203,     17.71572,50.00000,20.00000,1.700411e-07,0.73978,4
350.04050,190.20000,     -0.65224,     17.62350,50.00000,20.00000,1.699990e-07,0.73977,4
350.03686,190.80000,     -0.65109,     17.54533,50.00000,20.00000,1.698097e-07,0.73978,4
350.03752,191.40000,     -0.65192,     17.45230,50.00000,20.00000,1.700652e-07,0.73978,4
350.03860,192.00000,     -0.65274,     17.37728,50.00000,20.00000,1.701747e-07,0.73978,4
350.03598,192.60000,     -0.65236,     17.28632,50.00000,20.00000,1.701400e-07,0.73978,4
350.03642,193.20000,     -0.65175,     17.21179,50.00000,20.00000,1.696840e-07,0.73978,4
350.03835,193.80000,     -0.65123,     17.12033,50.00000,20.00000,1.698096e-07,0.73978,4
350.03541,194.40000,     -0.65061,     17.03772,50.00000,20.00000,1.699588e-07,0.73978,4
350.03237,195.00000,     -0.65165,     16.95506,50.00000,20.00000,1.698349e-07,0.73978,4
350.03627,195.60000,     -0.65191,     16.87250,50.00000,20.00000,1.698907e-07,0.73978,4
350.03006,196.20000,     -0.65110,     16.78354,50.00000,20.00000,1.701944e-07,0.73978,4
350.03225,196.80000,     -0.65194,     16.71171,50.00000,20.00000,1.698577e-07,0.73978,4
350.02806,197.40000,     -0.65082,     16.62664,50.00000,20.00000,1.695632e-07,0.73979,4
350.03359,198.00000,     -0.65011,     16.55684,50.00000,20.00000,1.699320e-07,0.73978,4
350.03650,198.60000,     -0.65012,     16.47579,50.00000,20.00000,1.698817e-07,0.73978,4
350.04579,199.20000,     -0.65055,     16.39243,50.00000,20.00000,1.696718e-07,0.73977,4
350.03221,199.80000,     -0.65053,     16.32020,50.00000,20.00000,1.698777e-07,0.73978,4
350.03503,200.40000,     -0.64987,     16.23835,50.00000,20.00000,1.697448e-07,0.73978,4
350.03240,201.00000,     -0.65082,     16.16691,50.00000,20.00000,1.699235e-07,0.73978,4
350.03330,201.60000,     -0.65079,     16.09395,50.00000,20.00000,1.695728e-07,0.73978,4
350.02770,202.20000,     -0.64987,     16.01201,50.00000,20.00000,1.694294e-07,0.73979,4
350.02853,202.80000,     -0.64940,     15.94066,50.00000,20.00000,1.698156e-07,0.73979,4
350.02570,203.40000,     -0.64945,     15.86842,50.00000,20.00000,1.696034e-07,0.73979,4
350.02972,204.00000,     -0.64957,     15.78576,50.00000,20.00000,1.699644e-07,0.73978,4
350.02902,204.60000,     -0.64890,     15.71204,50.00000,20.00000,1.694152e-07,0.73978,4
350.02856,205.20000,     -0.64930,     15.64068,50.00000,20.00000,1.694512e-07,0.73979,4
350.03119,205.80000,     -0.64925,     15.56778,50.00000,20.00000,1.694469e-07,0.73978,4
350.03519,206.40000,     -0.64935,     15.50887,50.00000,20.00000,1.693007e-07,0.73978,4
350.02887,207.00000,     -0.64870,     15.42315,50.00000,20.00000,1.692282e-07,0.73979,4
350.02381,207.60000,     -0.64737,     15.35270,50.00000,20.00000,1.690533e-07,0.73979,4
350.02614,208.20000,     -0.64818,     15.27813,50.00000,20.00000,1.690824e-07,0.73979,4
350.02885,208.80000,     -0.64772,     15.21413,50.00000,20.00000,1.694194e-07,0.73979,4
350.01489,209.40000,     -0.64741,     15.13818,50.00000,20.00000,1.691095e-07,0.73980,4
350.01922,210.00000,     -0.64748,     15.07059,50.00000,20.00000,1.689829e-07,0.73979,4
350.02025,210.60000,     -0.64702,     15.00333,50.00000,20.00000,1.692017e-07,0.73979,4
350.02638,211.20000,     -0.64611,     14.93138,50.00000,20.00000,1.694762e-07,0.73979,4
350.02985,211.80000,     -0.64654,     14.85921,50.00000,20.00000,1.692810e-07,0.73978,4
350.03269,212.40000,     -0.64655,     14.78776,50.00000,20.00000,1.690762e-07,0.73978,4
350.02363,213.00000,     -0.64721,     14.71559,50.00000,20.00000,1.691280e-07,0.73979,4
350.02847,213.60000,     -0.64673,     14.66125,50.00000,20.00000,1.690417e-07,0.73979,4
350.03589,214.20000,     -0.64639,     14.58897,50.00000,20.00000,1.691672e-07,0.73978,4
350.03530,214.80000,     -0.64712,     14.52651,50.00000,20.00000,1.693984e-07,0.73978,4
350.02328,215.40000,     -0.64729,     14.45640,50.00000,20.00000,1.689905e-07,0.73979,4
350.02776,216.00000,     -0.64630,     14.38710,50.00000,20.00000,1.688835e-07,0.73979,4
350.02053,216.60000,     -0.64598,     14.32855,50.00000,20.00000,1.692190e-07,0.73979,4
350.01990,217.20000,     -0.64543,     14.26454,50.00000,20.00000,1.690529e-07,0.73979,4
350.02911,217.80000,     -0.64430,     14.18934,50.00000,20.00000,1.690241e-07,0.73978,4
350.02397,218.40000,     -0.64519,     14.13278,50.00000,20.00000,1.688778e-07,0.73979,4
350.01889,219.00000,     -0.64625,     14.07026,50.00000,20.00000,1.691537e-07,0.73979,4
350.02238,219.60000,     -0.64475,     14.00704,50.00000,20.00000,1.687902e-07,0.73979,4
350.00867,220.20000,     -0.64426,     13.94375,50.00000,20.00000,1.686374e-07,0.73980,4
350.02095,220.80000,     -0.64347,     13.87974,50.00000,20.00000,1.687391e-07,0.73979,4
350.03025,221.40000,     -0.64308,     13.81645,50.00000,20.00000,1.688347e-07,0.73978,4
350.02530,222.00000,     -0.64331,     13.76066,50.00000,20.00000,1.691724e-07,0.73979,4
350.02981,222.60000,     -0.64389,     13.69816,50.00000,20.00000,1.688565e-07,0.73978,4
350.02913,223.20000,     -0.64441,     13.63772,50.00000,20.00000,1.686956e-07,0.73978,4
350.03028,223.80000,     -0.64470,     13.58149,50.00000,20.00000,1.687559e-07,0.73978,4
350.02712,224.40000,     -0.64352,     13.51730,50.00000,20.00000,1.688858e-07,0.73979,4
350.03042,225.00000,     -0.64281,     13.45474,50.00000,20.00000,1.688407e-07,0.73978,4
350.03025,225.60000,     -0.64305,     13.38928,50.00000,20.00000,1.690755e-07,0.73978,4
350.02279,226.20000,     -0.64355,     13.33941,50.00000,20.00000,1.689896e-07,0.73979,4
350.02811,226.80000,     -0.64270,     13.28579,50.00000,20.00000,1.687626e-07,0.73979,4
350.03084,227.40000,     -0.64246,     13.22257,50.00000,20.00000,1.689440e-07,0.73978,4
350.03747,228.00000,     -0.64321,     13.16285,50.00000,20.00000,1.687356e-07,0.73978,4
350.03340,228.60000,     -0.64252,     13.10422,50.00000,20.00000,1.685918e-07,0.73978,4
350.03466,229.20000,     -0.64373,     13.04171,50.00000,20.00000,1.687748e-07,0.73978,4
350.02658,229.80000,     -0.64264,     12.99632,50.00000,20.00000,1.686978e-07,0.73979,4
350.02222,230.40000,     -0.64411,     12.93302,50.00000,20.00000,1.686917e-07,0.73979,4
350.02290,231.00000,     -0.64568,     12.87796,50.00000,20.00000,1.686668e-07,0.73979,4
350.03092,231.60000,     -0.64678,     12.82430,50.00000,20.00000,1.685672e-07,0.73978,4
350.02623,232.20000,     -0.64721,     12.76085,50.00000,20.00000,1.684727e-07,0.73979,4
350.02945,232.80000,     -0.64608,     12.70526,50.00000,20.00000,1.686242e-07,0.73978,4
350.03119,233.40000,     -0.64816,     12.65914,50.00000,20.00000,1.686820e-07,0.73978,4
350.02401,234.00000,     -0.64782,     12.60481,50.00000,20.00000,1.685592e-07,0.73979,4
350.02691,234.60000,     -0.64788,     12.54151,50.00000,20.00000,1.684246e-07,0.73979,4
350.01939,235.20000,     -0.64604,     12.49708,50.00000,20.00000,1.682272e-07,0.73979,4
350.03366,235.80000,     -0.64632,     12.43362,50.00000,20.00000,1.684001e-07,0.73978,4
350.02608,236.40000,     -0.64612,     12.38894,50.00000,20.00000,1.685627e-07,0.73979,4
350.02962,237.00000,     -0.64499,     12.33539,50.00000,20.00000,1.686735e-07,0.73978,4
350.02038,237.60000,     -0.64474,     12.28026,50.00000,20.00000,1.683049e-07,0.73979,4
350.02944,238.20000,     -0.64509,     12.23338,50.00000,20.00000,1.684454e-07,0.73978,4
350.01885,238.80000,     -0.64700,     12.17980,50.00000,20.00000,1.683995e-07,0.73979,4
350.01808,239.40000,     -0.64612,     12.11730,50.00000,20.00000,1.688375e-07,0.73980,4
350.03323,240.00000,     -0.64380,     12.07191,50.00000,20.00000,1.684180e-07,0.73978,4
350.02876,240.60000,     -0.64365,     12.01757,50.00000,20.00000,1.682644e-07,0.73979,4
350.02697,241.20000,     -0.65058,     11.96395,50.00000,20.00000,1.685595e-07,0.73979,4
350.02662,241.80000,     -0.65141,     11.91952,50.00000,20.00000,1.682772e-07,0.73979,4
350.01513,242.40000,     -0.65160,     11.86573,50.00000,20.00000,1.681144e-07,0.73980,4
350.03514,243.00000,     -0.65093,     11.81205,50.00000,20.00000,1.683014e-07,0.73978,4
350.03628,243.60000,     -0.65137,     11.76073,50.00000,20.00000,1.684125e-07,0.73978,4
350.03489,244.20000,     -0.65168,     11.71388,50.00000,20.00000,1.679807e-07,0.73978,4
350.03360,244.80000,     -0.65229,     11.65954,50.00000,20.00000,1.681674e-07,0.73978,4
350.03190,245.40000,     -0.65161,     11.61414,50.00000,20.00000,1.680864e-07,0.73978,4
350.03005,246.00000,     -0.65058,     11.55980,50.00000,20.00000,1.680336e-07,0.73978,4
350.03136,246.60000,     -0.65082,     11.51558,50.00000,20.00000,1.679431e-07,0.73978,4
350.02643,247.20000,     -0.64932,     11.47864,50.00000,20.00000,1.679395e-07,0.73979,4
350.03371,247.80000,     -0.64850,     11.42434,50.00000,20.00000,1.679672e-07,0.73978,4
350.02478,248.40000,     -0.65067,     11.37081,50.00000,20.00000,1.680740e-07,0.73979,4
350.02432,249.00000,     -0.64992,     11.32539,50.00000,20.00000,1.679985e-07,0.73979,4
350.02826,249.60000,     -0.64904,     11.28017,50.00000,20.00000,1.682625e-07,0.73979,4
350.02482,250.20000,     -0.65006,     11.22641,50.00000,20.00000,1.678638e-07,0.73979,4
350.02635,250.80000,     -0.64853,     11.18099,50.00000,20.00000,1.683367e-07,0.73979,4
350.03045,251.40000,     -0.64799,     11.12743,50.00000,20.00000,1.682356e-07,0.73978,4
350.02911,252.00000,     -0.64844,     11.08267,50.00000,20.00000,1.678439e-07,0.73978,4
350.03264,252.60000,     -0.64727,     11.03737,50.00000,20.00000,1.677570e-07,0.73978,4
350.03463,253.20000,     -0.64701,     11.00013,50.00000,20.00000,1.679932e-07,0.73978,4
350.04059,253.80000,     -0.64705,     10.95546,50.00000,20.00000,1.679713e-07,0.73977,4
350.03580,254.40000,     -0.64857,     10.90191,50.00000,20.00000,1.681951e-07,0.73978,4
350.02495,255.00000,     -0.64884,     10.86618,50.00000,20.00000,1.676835e-07,0.73979,4
350.02934,255.60000,     -0.64729,     10.81257,50.00000,20.00000,1.679297e-07,0.73978,4
350.02088,256.20000,     -0.64680,     10.77685,50.00000,20.00000,1.677328e-07,0.73979,4
350.03176,256.80000,     -0.64692,     10.73217,50.00000,20.00000,1.681299e-07,0.73978,4
350.02787,257.40000,     -0.64538,     10.67789,50.00000,20.00000,1.679431e-07,0.73979,4
350.04290,258.00000,     -0.64498,     10.64586,50.00000,20.00000,1.679499e-07,0.73977,4
350.02751,258.60000,     -0.64715,     10.59230,50.00000,20.00000,1.679364e-07,0.73979,4
350.02640,259.20000,     -0.64519,     10.55658,50.00000,20.00000,1.675901e-07,0.73979,4
350.04474,259.80000,     -0.64490,     10.50335,50.00000,20.00000,1.674697e-07,0.73977,4
350.04189,260.40000,     -0.64611,     10.46177,50.00000,20.00000,1.678154e-07,0.73977,4
350.02282,261.00000,     -0.64438,     10.42112,50.00000,20.00000,1.674523e-07,0.73979,4
350.02471,261.60000,     -0.64441,     10.37566,50.00000,20.00000,1.675492e-07,0.73979,4
350.03598,262.20000,     -0.64429,     10.32115,50.00000,20.00000,1.677558e-07,0.73978,4
350.02448,262.80000,     -0.64392,     10.28487,50.00000,20.00000,1.677521e-07,0.73979,4
350.02576,263.40000,     -0.64485,     10.24842,50.00000,20.00000,1.676022e-07,0.73979,4
350.03265,264.00000,     -0.64316,     10.20217,50.00000,20.00000,1.677431e-07,0.73978,4
350.01885,264.60000,     -0.64417,     10.16132,50.00000,20.00000,1.674603e-07,0.73979,4
350.02679,265.20000,     -0.64450,     10.11299,50.00000,20.00000,1.674106e-07,0.73979,4
350.02678,265.80000,     -0.64294,     10.08237,50.00000,20.00000,1.676085e-07,0.73979,4
350.02097,266.40000,     -0.64342,     10.03032,50.00000,20.00000,1.673811e-07,0.73979,4
350.02438,267.00000,     -0.64238,      9.99013,50.00000,20.00000,1.675026e-07,0.73979,4
350.02227,267.60000,     -0.64326,      9.95726,50.00000,20.00000,1.676837e-07,0.73979,4
350.01487,268.20000,     -0.64241,      9.91724,50.00000,20.00000,1.673557e-07,0.73980,4
350.02396,268.80000,     -0.64316,      9.88151,50.00000,20.00000,1.672807e-07,0.73979,4
350.02958,269.40000,     -0.64069,      9.83675,50.00000,20.00000,1.672563e-07,0.73978,4
350.02239,270.00000,     -0.64124,      9.80112,50.00000,20.00000,1.673297e-07,0.73979,4
350.02337,270.60000,     -0.64032,      9.76539,50.00000,20.00000,1.671964e-07,0.73979,4
350.02961,271.20000,     -0.64149,      9.72074,50.00000,20.00000,1.673333e-07,0.73978,4
350.02827,271.80000,     -0.64071,      9.67596,50.00000,20.00000,1.672941e-07,0.73979,4
350.02935,272.40000,     -0.64116,      9.64927,50.00000,20.00000,1.670147e-07,0.73978,4
350.01377,273.00000,     -0.64211,      9.60684,50.00000,20.00000,1.671010e-07,0.73980,4
350.02262,273.60000,     -0.64188,      9.57649,50.00000,20.00000,1.672169e-07,0.73979,4
350.02868,274.20000,     -0.63797,      9.53171,50.00000,20.00000,1.671738e-07,0.73979,4
350.02616,274.80000,     -0.63987,      9.49592,50.00000,20.00000,1.670373e-07,0.73979,4
350.03119,275.40000,     -0.64030,      9.45867,50.00000,20.00000,1.674224e-07,0.73978,4
350.02369,276.00000,     -0.64026,      9.41480,50.00000,20.00000,1.667838e-07,0.73979,4
350.03266,276.60000,     -0.63861,      9.38059,50.00000,20.00000,1.670334e-07,0.73978,4
350.02758,277.20000,     -0.63832,      9.34263,50.00000,20.00000,1.667540e-07,0.73979,4
350.02518,277.80000,     -0.63869,      9.30691,50.00000,20.00000,1.670154e-07,0.73979,4
350.03478,278.40000,     -0.63804,      9.26375,50.00000,20.00000,1.670672e-07,0.73978,4
350.02901,279.00000,     -0.63831,      9.23474,50.00000,20.00000,1.668577e-07,0.73978,4
350.02685,279.60000,     -0.63837,      9.19695,50.00000,20.00000,1.669775e-07,0.73979,4
350.01558,280.20000,     -0.63825,      9.15954,50.00000,20.00000,1.667763e-07,0.73980,4
350.02351,280.80000,     -0.63702,      9.11487,50.00000,20.00000,1.670642e-07,0.73979,4
350.02467,281.40000,     -0.63895,      9.07910,50.00000,20.00000,1.670224e-07,0.73979,4
350.03066,282.00000,     -0.63737,      9.05232,50.00000,20.00000,1.665874e-07,0.73978,4
350.03634,282.60000,     -0.63566,      9.00760,50.00000,20.00000,1.667494e-07,0.73978,4
350.13890,283.20000,     -0.59927,      8.97527,50.00000,20.00000,1.667432e-07,0.73968,5
353.35456,283.80000,      0.10377,      9.06197,50.00000,20.00000,1.664585e-07,0.73661,5
359.03708,284.40000,      0.57985,      9.12845,50.00000,20.00000,1.670799e-07,0.73119,5
364.26259,285.00000,      0.52423,      9.11884,50.00000,20.00000,1.667086e-07,0.72622,5
369.33149,285.60000,      0.50729,      9.07410,50.00000,20.00000,1.666571e-07,0.72140,5
375.04100,286.20000,      0.63672,      9.01034,50.00000,20.00000,1.668199e-07,0.71598,5
381.21379,286.80000,      0.72596,      8.90717,50.00000,20.00000,1.664814e-07,0.71015,5
387.44186,287.40000,      0.73959,      8.71491,50.00000,20.00000,1.671602e-07,0.70429,5
393.68889,288.00000,      0.74235,      8.39462,50.00000,20.00000,1.668532e-07,0.69844,5
400.00970,288.60000,      0.75224,      7.95321,50.00000,20.00000,1.668994e-07,0.69256,5
406.34818,289.20000,      0.75828,      7.32408,50.00000,20.00000,1.671373e-07,0.68669,5
412.65439,289.80000,      0.73493,      6.48798,50.00000,20.00000,1.669116e-07,0.68090,5
418.93689,290.40000,      0.68667,      5.45115,50.00000,20.00000,1.675333e-07,0.67517,5
425.20420,291.00000,      0.61079,      4.29919,50.00000,20.00000,1.679304e-07,0.66951,5
431.43306,291.60000,      0.51355,      3.15587,50.00000,20.00000,1.684881e-07,0.66393,5
437.63835,292.20000,      0.40386,      2.15497,50.00000,20.00000,1.692327e-07,0.65842,5
443.82826,292.80000,      0.29269,      1.36201,50.00000,20.00000,1.695641e-07,0.65298,5
449.97768,293.40000,      0.18205,      0.80136,50.00000,20.00000,1.695513e-07,0.64763,5
456.11774,294.00000, 8.425704e-02,      0.42045,50.00000,20.00000,1.698079e-07,0.64235,5
462.22320,294.60000,-3.393544e-03,      0.14600,50.00000,20.00000,1.697798e-07,0.63716,5
468.33113,295.20000,-8.839834e-02,-5.622258e-02,50.00000,20.00000,1.696410e-07,0.63203,5
474.39571,295.80000,     -0.17863,     -0.17126,50.00000,20.00000,1.697743e-07,0.62699,5
480.46893,296.40000,     -0.26527,     -0.22144,50.00000,20.00000,1.690995e-07,0.62201,5
486.51360,297.00000,     -0.34168,     -0.20272,50.00000,20.00000,1.689204e-07,0.61713,5
492.56196,297.60000,     -0.41192,     -0.17624,50.00000,20.00000,1.690351e-07,0.61230,5
498.59760,298.20000,     -0.48217,     -0.14946,50.00000,20.00000,1.682597e-07,0.60755,5
504.61762,298.80000,     -0.55345,     -0.12268,50.00000,20.00000,1.679259e-07,0.60288,5
510.62780,299.40000,     -0.62815,-9.590730e-02,50.00000,20.00000,1.677715e-07,0.59829,5
516.64617,300.00000,     -0.69762,-6.907262e-02,50.00000,20.00000,1.675356e-07,0.59376,5
522.65895,300.60000,     -0.77357,-4.448070e-02,50.00000,20.00000,1.673574e-07,0.58930,5
528.65977,301.20000,     -0.85194,-1.083292e-02,50.00000,20.00000,1.671482e-07,0.58492,5
534.67298,301.80000,     -0.92752, 4.676604e-03,50.00000,20.00000,1.673422e-07,0.58060,5
540.66863,302.40000,     -1.00450, 3.129408e-02,50.00000,20.00000,1.671261e-07,0.57636,5
546.67644,303.00000,     -1.08389, 4.866199e-02,50.00000,20.00000,1.672452e-07,0.57219,5
552.67778,303.60000,     -1.16103, 6.911840e-02,50.00000,20.00000,1.671320e-07,0.56808,5
558.70201,304.20000,     -1.24078, 9.401100e-02,50.00000,20.00000,1.667187e-07,0.56404,5
564.68473,304.80000,     -1.32214,      0.12104,50.00000,20.00000,1.664780e-07,0.56008,5
570.68904,305.40000,     -1.40140,      0.13853,50.00000,20.00000,1.661304e-07,0.55619,5
576.71106,306.00000,     -1.48087,      0.14737,50.00000,20.00000,1.662910e-07,0.55234,5
582.71853,306.60000,     -1.56215,      0.16719,50.00000,20.00000,1.660449e-07,0.54858,5
588.71056,307.20000,     -1.64299,      0.18514,50.00000,20.00000,1.660703e-07,0.54489,5
594.71985,307.80000,     -1.71912,      0.20304,50.00000,20.00000,1.660798e-07,0.54125,5
600.73850,308.40000,     -1.79821,      0.22138,50.00000,20.00000,1.660510e-07,0.53767,5
606.75394,309.00000,     -1.87527,      0.24119,50.00000,20.00000,1.658925e-07,0.53416,5
612.76062,309.60000,     -1.95622,      0.26108,50.00000,20.00000,1.661120e-07,0.53072,5
618.77284,310.20000,     -2.03245,      0.27927,50.00000,20.00000,1.662512e-07,0.52733,5
624.78039,310.80000,     -2.10816,      0.29049,50.00000,20.00000,1.664825e-07,0.52400,5
630.78278,311.40000,     -2.17998,      0.30827,50.00000,20.00000,1.665464e-07,0.52074,5
636.79560,312.00000,     -2.25164,      0.31662,50.00000,20.00000,1.663927e-07,0.51752,5
642.81279,312.60000,     -2.32303,      0.32564,50.00000,20.00000,1.663225e-07,0.51436,5
648.81938,313.20000,     -2.39090,      0.33779,50.00000,20.00000,1.667063e-07,0.51126,5
654.81963,313.80000,     -2.45457,      0.35103,50.00000,20.00000,1.669501e-07,0.50821,5
660.82973,314.40000,     -2.51754,      0.37134,50.00000,20.00000,1.663459e-07,0.50520,5
666.83401,315.00000,     -2.57849,      0.38690,50.00000,20.00000,1.667003e-07,0.50225,5
672.84607,315.60000,     -2.63501,      0.38922,50.00000,20.00000,1.662991e-07,0.49934,5
678.86078,316.20000,     -2.69088,      0.40738,50.00000,20.00000,1.666651e-07,0.49647,5
684.86673,316.80000,     -2.74579,      0.41594,50.00000,20.00000,1.665594e-07,0.49365,5
690.87993,317.40000,     -2.79401,      0.42049,50.00000,20.00000,1.664801e-07,0.49086,5
696.90183,318.00000,     -2.83863,      0.44243,50.00000,20.00000,1.669386e-07,0.48811,5
702.91707,318.60000,     -2.88047,      0.45151,50.00000,20.00000,1.666766e-07,0.48540,5
708.91930,319.20000,     -2.92187,      0.45661,50.00000,20.00000,1.667687e-07,0.48272,5
714.94987,319.80000,     -2.96044,      0.47423,50.00000,20.00000,1.671895e-07,0.48007,5
720.96966,320.40000,     -2.99517,      0.47655,50.00000,20.00000,1.670550e-07,0.47745,5
726.98580,321.00000,     -3.03114,      0.48270,50.00000,20.00000,1.670969e-07,0.47486,5
733.00031,321.60000,     -3.06085,      0.49159,50.00000,20.00000,1.669392e-07,0.47230,5
739.01822,322.20000,     -3.09321,      0.50974,50.00000,20.00000,1.668340e-07,0.46976,5
745.02862,322.80000,     -3.12378,      0.51844,50.00000,20.00000,1.668792e-07,0.46724,5
751.04589,323.40000,     -3.15493,      0.52063,50.00000,20.00000,1.670192e-07,0.46474,5
757.06381,324.00000,     -3.18637,      0.53214,50.00000,20.00000,1.669633e-07,0.46226,5
763.07560,324.60000,     -3.21741,      0.54538,50.00000,20.00000,1.672409e-07,0.45980,5
769.08876,325.20000,     -3.25069,      0.55890,50.00000,20.00000,1.668120e-07,0.45735,5
775.11521,325.80000,     -3.28554,      0.56083,50.00000,20.00000,1.674981e-07,0.45490,5
781.11450,326.40000,     -3.31930,      0.56749,50.00000,20.00000,1.671672e-07,0.45248,5
787.11941,327.00000,     -3.35658,      0.57647,50.00000,20.00000,1.670082e-07,0.45006,5
793.13171,327.60000,     -3.39186,      0.57430,50.00000,20.00000,1.671457e-07,0.44764,5
794.13231,327.70000,     -3.39823,      0.57436,50.00000,20.00000,1.671457e-07,0.44724,5