File: pc_x_polymers/ExpDat_2024_01_19_SL_005P.csv
#EXPORTTYPE:                 ,DATA ALL
#FILE:                       ,2024_01_19_SL_005P.ngb-ss5
#FORMAT:                     ,NETZSCH5
#FTYPE:                      ,ASCII
#IDENTITY:                   ,PS-SCF3
#DECIMAL:                    ,POINT
#SEPARATOR:                  ,COMMA
#MTYPE:                      ,DSC
#INSTRUMENT:                 ,NETZSCH STA 449F5
#PROJECT:                    ,2024_01_08_SL_007B
#DATE/TIME:                  ,1/20/2024 2:10:19 PM (UTC-5)
#CORR. FILE:                 ,
#TEMPCAL:                    ,28-06-2023 13:26
#SENSITIVITY:                ,28-06-2023 13:53
#LABORATORY:                 ,Tran/AAG
#OPERATOR:                   ,Stanley
#REMARK:                     ,
#SAMPLE:                     ,005P
#SAMPLE MASS /mg:            ,10.05
#MATERIAL:                   ,
#REFERENCE:                  ,Empty Al2O3
#REFERENCE MASS /mg:         ,0
#TYPE OF CRUCIBLE:           ,Al2O3 85 ‘l, open
#SAMPLE CRUCIBLE MASS /mg:   ,0
#REFERENCE CRUCIBLE MASS /mg:,136.57
#DSC RANGE /‘V:              ,5000
#TG RANGE /mg:               ,35000
#TAU-R:                      ,---
#CORR. CODE:                 ,000
#EXO:                        ,-1
#RANGE:                      ,20›C....800›C/0.0....10.0K/min
#SEGMENT:                    ,S1-5/5
#SEG. 1:                     ,20›C/10.0(K/min)/100›C
#SEG. 2:                     ,100›C/00:10/100›C
#SEG. 3:                     ,100›C/10.0(K/min)/350›C
#SEG. 4:                     ,350›C/04:00/350›C
#SEG. 5:                     ,350›C/10.0(K/min)/800›C

##Temp./›C,Time/min,DSC/(mW/mg),Mass/%,Gas Flow(purge2)/(ml/min),Gas Flow(protective)/(ml/min),TIC(scan:1)/A,Sensit./(uV/mW),Segment
 32.01800,  0.00000,-3.845371e-02,100.00000,50.00000,20.00000,1.216010e-07,0.92391,1
 32.15700,  0.60000,-1.339272e-02,100.16995,50.00000,20.00000,1.214885e-07,0.92394,1
 32.89000,  1.20000, 8.034556e-02,100.62587,50.00000,20.00000,1.215406e-07,0.92406,1
 34.23700,  1.80000,      0.19088,101.06935,50.00000,20.00000,1.215795e-07,0.92428,1
 36.04400,  2.40000,      0.29026,101.44876,50.00000,20.00000,1.211718e-07,0.92455,1
 38.36900,  3.00000,      0.39858,101.85960,50.00000,20.00000,1.211312e-07,0.92488,1
 41.38200,  3.60000,      0.53848,102.34358,50.00000,20.00000,1.208524e-07,0.92524,1
 45.21500,  4.20000,      0.71230,102.86259,50.00000,20.00000,1.211590e-07,0.92562,1
 49.85400,  4.80000,      0.90094,103.36796,50.00000,20.00000,1.208133e-07,0.92595,1
 55.21300,  5.40000,      1.08262,103.80020,50.00000,20.00000,1.203984e-07,0.92616,1
 61.16400,  6.00000,      1.24988,104.18070,50.00000,20.00000,1.203408e-07,0.92618,1
 67.65700,  6.60000,      1.40612,104.49254,50.00000,20.00000,1.197364e-07,0.92596,1
 74.54400,  7.20000,      1.55081,104.75144,50.00000,20.00000,1.193636e-07,0.92543,1
 81.76800,  7.80000,      1.68050,104.95970,50.00000,20.00000,1.197382e-07,0.92457,1
 88.96136,  8.40000,      1.71444,105.08042,50.00000,20.00000,1.195988e-07,0.92340,2
 94.83819,  9.00000,      1.46801,104.82248,50.00000,20.00000,1.198247e-07,0.92223,2
 99.22017,  9.60000,      1.15186,104.42657,50.00000,20.00000,1.192809e-07,0.92122,2
102.50236, 10.20000,      0.89850,104.10838,50.00000,20.00000,1.191640e-07,0.92039,2
105.17531, 10.80000,      0.71683,103.90830,50.00000,20.00000,1.191622e-07,0.91968,2
107.34854, 11.40000,      0.57260,103.74653,50.00000,20.00000,1.192790e-07,0.91906,2
108.95781, 12.00000,      0.42680,103.57550,50.00000,20.00000,1.189309e-07,0.91859,2
110.00385, 12.60000,      0.28190,103.38540,50.00000,20.00000,1.190554e-07,0.91828,2
110.56763, 13.20000,      0.15348,103.19115,50.00000,20.00000,1.188112e-07,0.91811,2
110.77210, 13.80000, 5.065006e-02,103.03091,50.00000,20.00000,1.183955e-07,0.91804,2
110.65713, 14.40000,-2.981335e-02,102.88928,50.00000,20.00000,1.184460e-07,0.91808,2
110.33115, 15.00000,-9.243227e-02,102.75434,50.00000,20.00000,1.186349e-07,0.91818,2
109.82099, 15.60000,     -0.14183,102.65991,50.00000,20.00000,1.182365e-07,0.91833,2
109.19517, 16.20000,     -0.17738,102.56090,50.00000,20.00000,1.185698e-07,0.91852,2
108.46667, 16.80000,     -0.20178,102.46422,50.00000,20.00000,1.181777e-07,0.91874,2
107.68980, 17.40000,     -0.21680,102.40361,50.00000,20.00000,1.180621e-07,0.91896,2
106.90140, 18.00000,     -0.22397,102.34139,50.00000,20.00000,1.176022e-07,0.91919,3
106.51851, 18.60000,     -0.11693,102.46519,50.00000,20.00000,1.182821e-07,0.91930,3
107.71879, 19.20000,      0.24131,102.99882,50.00000,20.00000,1.174054e-07,0.91896,3
110.31603, 19.80000,      0.61322,103.52850,50.00000,20.00000,1.177825e-07,0.91818,3
113.66112, 20.40000,      0.86738,103.83859,50.00000,20.00000,1.177427e-07,0.91714,3
117.62928, 21.00000,      1.07855,104.13623,50.00000,20.00000,1.170571e-07,0.91581,3
122.38589, 21.60000,      1.31944,104.41205,50.00000,20.00000,1.173735e-07,0.91412,3
127.93224, 22.20000,      1.57623,104.69292,50.00000,20.00000,1.167703e-07,0.91199,3
134.10389, 22.80000,      1.80042,104.92366,50.00000,20.00000,1.170579e-07,0.90944,3
140.72231, 23.40000,      1.98388,105.11729,50.00000,20.00000,1.167093e-07,0.90649,3
147.63241, 24.00000,      2.13726,105.25801,50.00000,20.00000,1.173380e-07,0.90319,3
154.76308, 24.60000,      2.27162,105.38179,50.00000,20.00000,1.172764e-07,0.89954,3
161.99926, 25.20000,      2.37802,105.48985,50.00000,20.00000,1.170444e-07,0.89561,3
169.25401, 25.80000,      2.45130,105.55741,50.00000,20.00000,1.165244e-07,0.89143,3
176.48876, 26.40000,      2.49946,105.60358,50.00000,20.00000,1.168174e-07,0.88704,3
183.65102, 27.00000,      2.50750,105.64408,50.00000,20.00000,1.169367e-07,0.88249,3
190.73985, 27.60000,      2.47356,105.68796,50.00000,20.00000,1.167397e-07,0.87779,3
197.71567, 28.20000,      2.42279,105.70149,50.00000,20.00000,1.162256e-07,0.87298,3
204.56334, 28.80000,      2.37471,105.72179,50.00000,20.00000,1.165363e-07,0.86810,3
211.28044, 29.40000,      2.33041,105.73522,50.00000,20.00000,1.167537e-07,0.86315,3
217.87269, 30.00000,      2.28427,105.73194,50.00000,20.00000,1.163926e-07,0.85815,3
224.34526, 30.60000,      2.24878,105.75135,50.00000,20.00000,1.165630e-07,0.85312,3
230.73407, 31.20000,      2.22348,105.75891,50.00000,20.00000,1.163802e-07,0.84804,3
237.01298, 31.80000,      2.20587,105.77244,50.00000,20.00000,1.165225e-07,0.84293,3
243.22844, 32.40000,      2.19442,105.76229,50.00000,20.00000,1.165037e-07,0.83778,3
249.38394, 33.00000,      2.18678,105.75552,50.00000,20.00000,1.162009e-07,0.83259,3
255.49818, 33.60000,      2.18222,105.75552,50.00000,20.00000,1.162758e-07,0.82735,3
261.55823, 34.20000,      2.17810,105.74876,50.00000,20.00000,1.164414e-07,0.82208,3
267.59313, 34.80000,      2.17814,105.73522,50.00000,20.00000,1.159680e-07,0.81675,3
273.60160, 35.40000,      2.17848,105.70826,50.00000,20.00000,1.163871e-07,0.81139,3
279.57794, 36.00000,      2.18327,105.69473,50.00000,20.00000,1.161709e-07,0.80600,3
285.52948, 36.60000,      2.18953,105.65423,50.00000,20.00000,1.165764e-07,0.80058,3
291.48438, 37.20000,      2.20231,105.59682,50.00000,20.00000,1.164224e-07,0.79511,3
297.42363, 37.80000,      2.20958,105.55293,50.00000,20.00000,1.157919e-07,0.78960,3
303.36063, 38.40000,      2.21819,105.45721,50.00000,20.00000,1.162126e-07,0.78407,3
309.26577, 39.00000,      2.22564,105.37024,50.00000,20.00000,1.159214e-07,0.77853,3
315.19176, 39.60000,      2.23323,105.25463,50.00000,20.00000,1.160943e-07,0.77294,3
321.10995, 40.20000,      2.24075,105.11393,50.00000,20.00000,1.161584e-07,0.76734,3
327.04211, 40.80000,      2.24803,104.94248,50.00000,20.00000,1.162356e-07,0.76171,3
332.94479, 41.40000,      2.25874,104.74001,50.00000,20.00000,1.157708e-07,0.75609,3
338.87283, 42.00000,      2.26799,104.49701,50.00000,20.00000,1.155468e-07,0.75043,3
344.80861, 42.60000,      2.28026,104.20016,50.00000,20.00000,1.159498e-07,0.74477,3
350.48085, 43.20000,      2.19657,103.77511,50.00000,20.00000,1.160248e-07,0.73935,4
352.51079, 43.80000,      0.88886,103.17420,50.00000,20.00000,1.158815e-07,0.73742,4
352.97010, 44.40000,      0.18146,102.53161,50.00000,20.00000,1.160727e-07,0.73698,4
353.73516, 45.00000,      0.16903,101.93882,50.00000,20.00000,1.158855e-07,0.73625,4
354.36543, 45.60000,      0.11236,101.33261,50.00000,20.00000,1.154685e-07,0.73565,4
354.51337, 46.20000,-7.353224e-02,100.72821,50.00000,20.00000,1.157007e-07,0.73551,4
354.35488, 46.80000,     -0.20394,100.08666,50.00000,20.00000,1.159750e-07,0.73566,4
354.13334, 47.40000,     -0.25725, 99.46079,50.00000,20.00000,1.160104e-07,0.73587,4
353.86721, 48.00000,     -0.28246, 98.83277,50.00000,20.00000,1.157954e-07,0.73612,4
353.54785, 48.60000,     -0.30883, 98.22913,50.00000,20.00000,1.155670e-07,0.73643,4
353.22529, 49.20000,     -0.32809, 97.63469,50.00000,20.00000,1.157868e-07,0.73673,4
352.90713, 49.80000,     -0.33781, 97.05225,50.00000,20.00000,1.158704e-07,0.73704,4
352.59823, 50.40000,     -0.32799, 96.48213,50.00000,20.00000,1.162128e-07,0.73733,4
352.30547, 51.00000,     -0.32741, 95.94450,50.00000,20.00000,1.161328e-07,0.73761,4
352.05505, 51.60000,     -0.31861, 95.40069,50.00000,20.00000,1.159532e-07,0.73785,4
351.81586, 52.20000,     -0.31942, 94.85485,50.00000,20.00000,1.162469e-07,0.73808,4
351.60086, 52.80000,     -0.31812, 94.26565,50.00000,20.00000,1.161836e-07,0.73828,4
351.42317, 53.40000,     -0.30263, 93.70675,50.00000,20.00000,1.160322e-07,0.73845,4
351.23933, 54.00000,     -0.30145, 93.23039,50.00000,20.00000,1.159267e-07,0.73863,4
351.08865, 54.60000,     -0.29657, 92.70565,50.00000,20.00000,1.161125e-07,0.73877,4
350.96590, 55.20000,     -0.29644, 92.16044,50.00000,20.00000,1.157727e-07,0.73889,4
350.85607, 55.80000,     -0.28519, 91.62808,50.00000,20.00000,1.159683e-07,0.73900,4
350.76103, 56.40000,     -0.28774, 91.11832,50.00000,20.00000,1.160737e-07,0.73909,4
350.66996, 57.00000,     -0.28908, 90.60397,50.00000,20.00000,1.158559e-07,0.73917,4
350.59202, 57.60000,     -0.29327, 90.06279,50.00000,20.00000,1.159577e-07,0.73925,4
350.51598, 58.20000,     -0.29747, 89.53804,50.00000,20.00000,1.158850e-07,0.73932,4
350.45532, 58.80000,     -0.27238, 89.01444,50.00000,20.00000,1.160214e-07,0.73938,4
350.39754, 59.40000,     -0.27494, 88.55750,50.00000,20.00000,1.156273e-07,0.73943,4
350.35918, 60.00000,     -0.27155, 88.05667,50.00000,20.00000,1.159932e-07,0.73947,4
350.31242, 60.60000,     -0.27399, 87.56683,50.00000,20.00000,1.159067e-07,0.73951,4
350.26861, 61.20000,     -0.27277, 87.06715,50.00000,20.00000,1.157784e-07,0.73956,4
350.24938, 61.80000,     -0.27429, 86.55596,50.00000,20.00000,1.158228e-07,0.73957,4
350.21887, 62.40000,     -0.26224, 86.01928,50.00000,20.00000,1.155472e-07,0.73960,4
350.19767, 63.00000,     -0.26614, 85.54550,50.00000,20.00000,1.160289e-07,0.73962,4
350.17062, 63.60000,     -0.26088, 85.04970,50.00000,20.00000,1.157651e-07,0.73965,4
350.15332, 64.20000,     -0.26323, 84.58982,50.00000,20.00000,1.156927e-07,0.73967,4
350.13748, 64.80000,     -0.26446, 84.06343,50.00000,20.00000,1.158728e-07,0.73968,4
350.13309, 65.40000,     -0.26532, 83.57519,50.00000,20.00000,1.155862e-07,0.73969,4
350.10914, 66.00000,     -0.26693, 83.05936,50.00000,20.00000,1.157939e-07,0.73971,4
350.09713, 66.60000,     -0.26337, 82.57682,50.00000,20.00000,1.157379e-07,0.73972,4
350.08854, 67.20000,     -0.26316, 82.10528,50.00000,20.00000,1.157752e-07,0.73973,4
350.08260, 67.80000,     -0.26232, 81.62422,50.00000,20.00000,1.157439e-07,0.73973,4
350.06206, 68.40000,     -0.26336, 81.11903,50.00000,20.00000,1.157615e-07,0.73975,4
350.06334, 69.00000,     -0.25730, 80.63606,50.00000,20.00000,1.158018e-07,0.73975,4
350.05230, 69.60000,     -0.26403, 80.18616,50.00000,20.00000,1.156134e-07,0.73976,4
350.06388, 70.20000,     -0.26354, 79.72236,50.00000,20.00000,1.157458e-07,0.73975,4
350.05356, 70.80000,     -0.26374, 79.26164,50.00000,20.00000,1.158485e-07,0.73976,4
350.05525, 71.40000,     -0.26262, 78.77542,50.00000,20.00000,1.159328e-07,0.73976,4
350.05399, 72.00000,     -0.26278, 78.27775,50.00000,20.00000,1.156647e-07,0.73976,4
350.03870, 72.60000,     -0.26433, 77.82300,50.00000,20.00000,1.156981e-07,0.73978,4
350.03579, 73.20000,     -0.26269, 77.34364,50.00000,20.00000,1.154205e-07,0.73978,4
350.02876, 73.80000,     -0.26453, 76.87902,50.00000,20.00000,1.156358e-07,0.73979,4
350.02695, 74.40000,     -0.26374, 76.40914,50.00000,20.00000,1.158500e-07,0.73979,4
350.03156, 75.00000,     -0.26112, 75.95998,50.00000,20.00000,1.157743e-07,0.73978,4
350.03900, 75.60000,     -0.26160, 75.45927,50.00000,20.00000,1.155943e-07,0.73978,4
350.04787, 76.20000,     -0.26422, 75.01092,50.00000,20.00000,1.155527e-07,0.73977,4
350.03102, 76.80000,     -0.26491, 74.54878,50.00000,20.00000,1.157404e-07,0.73978,4
350.03702, 77.40000,     -0.26649, 74.07679,50.00000,20.00000,1.155819e-07,0.73978,4
350.02064, 78.00000,     -0.26551, 73.58912,50.00000,20.00000,1.156378e-07,0.73979,4
350.02321, 78.60000,     -0.26558, 73.14600,50.00000,20.00000,1.155767e-07,0.73979,4
350.01889, 79.20000,     -0.26722, 72.68741,50.00000,20.00000,1.156316e-07,0.73979,4
350.02141, 79.80000,     -0.26625, 72.20054,50.00000,20.00000,1.155760e-07,0.73979,4
350.03700, 80.40000,     -0.26520, 71.77818,50.00000,20.00000,1.153005e-07,0.73978,4
350.02409, 81.00000,     -0.26614, 71.32334,50.00000,20.00000,1.155221e-07,0.73979,4
350.03236, 81.60000,     -0.26618, 70.88329,50.00000,20.00000,1.154022e-07,0.73978,4
350.04110, 82.20000,     -0.26552, 70.42293,50.00000,20.00000,1.156785e-07,0.73977,4
350.03812, 82.80000,     -0.26828, 69.98714,50.00000,20.00000,1.155704e-07,0.73978,4
350.02686, 83.40000,     -0.26782, 69.53473,50.00000,20.00000,1.153030e-07,0.73979,4
350.02305, 84.00000,     -0.26909, 69.08913,50.00000,20.00000,1.154344e-07,0.73979,4
350.01852, 84.60000,     -0.26935, 68.66114,50.00000,20.00000,1.156297e-07,0.73979,4
350.02309, 85.20000,     -0.26855, 68.22217,50.00000,20.00000,1.156106e-07,0.73979,4
350.02485, 85.80000,     -0.26834, 67.78098,50.00000,20.00000,1.152861e-07,0.73979,4
350.12774, 86.40000,     -0.26961, 67.34763,50.00000,20.00000,1.157103e-07,0.73969,4
350.02607, 87.00000,     -0.27072, 66.93335,50.00000,20.00000,1.155675e-07,0.73979,4
350.02454, 87.60000,     -0.26905, 66.49535,50.00000,20.00000,1.153153e-07,0.73979,4
350.03153, 88.20000,     -0.26669, 66.06453,50.00000,20.00000,1.155233e-07,0.73978,4
350.03455, 88.80000,     -0.26887, 65.64684,50.00000,20.00000,1.153346e-07,0.73978,4
350.03435, 89.40000,     -0.27110, 65.22802,50.00000,20.00000,1.155657e-07,0.73978,4
350.03522, 90.00000,     -0.27311, 64.83284,50.00000,20.00000,1.154813e-07,0.73978,4
350.02142, 90.60000,     -0.27047, 64.39390,50.00000,20.00000,1.152022e-07,0.73979,4
350.02951, 91.20000,     -0.26990, 63.98323,50.00000,20.00000,1.152961e-07,0.73978,4
350.02706, 91.80000,     -0.27253, 63.59104,50.00000,20.00000,1.152695e-07,0.73979,4
350.02063, 92.40000,     -0.27313, 63.17248,50.00000,20.00000,1.154922e-07,0.73979,4
350.01900, 93.00000,     -0.27271, 62.77491,50.00000,20.00000,1.152880e-07,0.73979,4
350.02870, 93.60000,     -0.27287, 62.36992,50.00000,20.00000,1.152336e-07,0.73979,4
350.00943, 94.20000,     -0.27409, 61.98174,50.00000,20.00000,1.154089e-07,0.73980,4
350.02191, 94.80000,     -0.27474, 61.57733,50.00000,20.00000,1.154055e-07,0.73979,4
350.03007, 95.40000,     -0.27428, 61.19607,50.00000,20.00000,1.154569e-07,0.73978,4
350.03849, 96.00000,     -0.27404, 60.78181,50.00000,20.00000,1.151798e-07,0.73978,4
350.03368, 96.60000,     -0.27451, 60.40103,50.00000,20.00000,1.151414e-07,0.73978,4
350.03191, 97.20000,     -0.27508, 60.02605,50.00000,20.00000,1.152805e-07,0.73978,4
350.03789, 97.80000,     -0.27571, 59.66280,50.00000,20.00000,1.153826e-07,0.73978,4
350.03148, 98.40000,     -0.27539, 59.25371,50.00000,20.00000,1.154435e-07,0.73978,4
350.02250, 99.00000,     -0.27561, 58.88456,50.00000,20.00000,1.153242e-07,0.73979,4
350.02915, 99.60000,     -0.27648, 58.52126,50.00000,20.00000,1.153174e-07,0.73978,4
350.03212,100.20000,     -0.27524, 58.16096,50.00000,20.00000,1.150407e-07,0.73978,4
350.02849,100.80000,     -0.27580, 57.78386,50.00000,20.00000,1.153978e-07,0.73979,4
350.02644,101.40000,     -0.27818, 57.41295,50.00000,20.00000,1.152829e-07,0.73979,4
350.02251,102.00000,     -0.27795, 57.06014,50.00000,20.00000,1.152970e-07,0.73979,4
350.03147,102.60000,     -0.27801, 56.70660,50.00000,20.00000,1.151383e-07,0.73978,4
350.02126,103.20000,     -0.27985, 56.35422,50.00000,20.00000,1.151537e-07,0.73979,4
350.02760,103.80000,     -0.27807, 56.00464,50.00000,20.00000,1.150303e-07,0.73979,4
350.02196,104.40000,     -0.27682, 55.64626,50.00000,20.00000,1.151764e-07,0.73979,4
350.03000,105.00000,     -0.27779, 55.29398,50.00000,20.00000,1.153325e-07,0.73978,4
350.03653,105.60000,     -0.27923, 54.94481,50.00000,20.00000,1.152161e-07,0.73978,4
350.03239,106.20000,     -0.27993, 54.60947,50.00000,20.00000,1.152856e-07,0.73978,4
350.02035,106.80000,     -0.28027, 54.25375,50.00000,20.00000,1.151021e-07,0.73979,4
350.02882,107.40000,     -0.27849, 53.94327,50.00000,20.00000,1.149721e-07,0.73979,4
350.02664,108.00000,     -0.27834, 53.60198,50.00000,20.00000,1.148650e-07,0.73979,4
350.03158,108.60000,     -0.27982, 53.28088,50.00000,20.00000,1.152274e-07,0.73978,4
350.04125,109.20000,     -0.27901, 52.95585,50.00000,20.00000,1.151064e-07,0.73977,4
350.03082,109.80000,     -0.28218, 52.62491,50.00000,20.00000,1.152284e-07,0.73978,4
350.02450,110.40000,     -0.28211, 52.30265,50.00000,20.00000,1.149250e-07,0.73979,4
350.03108,111.00000,     -0.28223, 51.98486,50.00000,20.00000,1.154922e-07,0.73978,4
350.02432,111.60000,     -0.28167, 51.67143,50.00000,20.00000,1.152756e-07,0.73979,4
350.01820,112.20000,     -0.28067, 51.33862,50.00000,20.00000,1.151490e-07,0.73980,4
350.02371,112.80000,     -0.27989, 51.04774,50.00000,20.00000,1.150898e-07,0.73979,4
350.02938,113.40000,     -0.28189, 50.74369,50.00000,20.00000,1.152157e-07,0.73978,4
350.02471,114.00000,     -0.28441, 50.42453,50.00000,20.00000,1.149893e-07,0.73979,4
350.02314,114.60000,     -0.28232, 50.12395,50.00000,20.00000,1.151156e-07,0.73979,4
350.02954,115.20000,     -0.28144, 49.81641,50.00000,20.00000,1.148572e-07,0.73978,4
350.02856,115.80000,     -0.28159, 49.51818,50.00000,20.00000,1.151690e-07,0.73979,4
350.03143,116.40000,     -0.28418, 49.22656,50.00000,20.00000,1.150616e-07,0.73978,4
350.02772,117.00000,     -0.28485, 48.93713,50.00000,20.00000,1.152171e-07,0.73979,4
350.01619,117.60000,     -0.28352, 48.63973,50.00000,20.00000,1.152447e-07,0.73980,4
350.02880,118.20000,     -0.28474, 48.35668,50.00000,20.00000,1.151734e-07,0.73979,4
350.03793,118.80000,     -0.28427, 48.04964,50.00000,20.00000,1.151797e-07,0.73978,4
350.02841,119.40000,     -0.28464, 47.76842,50.00000,20.00000,1.151592e-07,0.73979,4
350.02863,120.00000,     -0.28558, 47.49510,50.00000,20.00000,1.150409e-07,0.73979,4
350.02658,120.60000,     -0.28601, 47.19919,50.00000,20.00000,1.153198e-07,0.73979,4
350.03257,121.20000,     -0.28426, 46.91424,50.00000,20.00000,1.152088e-07,0.73978,4
350.02728,121.80000,     -0.28441, 46.64614,50.00000,20.00000,1.151234e-07,0.73979,4
350.02782,122.40000,     -0.28622, 46.38060,50.00000,20.00000,1.151861e-07,0.73979,4
350.02934,123.00000,     -0.28587, 46.09712,50.00000,20.00000,1.147197e-07,0.73978,4
350.03500,123.60000,     -0.28479, 45.85396,50.00000,20.00000,1.147598e-07,0.73978,4
350.02581,124.20000,     -0.28670, 45.58126,50.00000,20.00000,1.151896e-07,0.73979,4
350.02919,124.80000,     -0.28721, 45.30913,50.00000,20.00000,1.150416e-07,0.73978,4
350.03742,125.40000,     -0.28548, 45.04916,50.00000,20.00000,1.148711e-07,0.73978,4
350.03914,126.00000,     -0.28690, 44.79135,50.00000,20.00000,1.150997e-07,0.73978,4
350.03575,126.60000,     -0.28661, 44.51567,50.00000,20.00000,1.153695e-07,0.73978,4
350.02672,127.20000,     -0.28587, 44.27015,50.00000,20.00000,1.147461e-07,0.73979,4
350.04210,127.80000,     -0.28591, 44.01203,50.00000,20.00000,1.147825e-07,0.73977,4
350.04597,128.40000,     -0.28759, 43.76247,50.00000,20.00000,1.147354e-07,0.73977,4
350.04123,129.00000,     -0.28867, 43.51162,50.00000,20.00000,1.150504e-07,0.73977,4
350.03831,129.60000,     -0.28794, 43.26372,50.00000,20.00000,1.147755e-07,0.73978,4
350.04203,130.20000,     -0.28893, 43.01595,50.00000,20.00000,1.152323e-07,0.73977,4
350.02885,130.80000,     -0.28951, 42.77068,50.00000,20.00000,1.146725e-07,0.73979,4
350.03195,131.40000,     -0.28831, 42.54000,50.00000,20.00000,1.146624e-07,0.73978,4
350.02501,132.00000,     -0.28752, 42.28108,50.00000,20.00000,1.146659e-07,0.73979,4
350.03042,132.60000,     -0.28898, 42.05359,50.00000,20.00000,1.153573e-07,0.73978,4
350.02694,133.20000,     -0.29003, 41.81589,50.00000,20.00000,1.150612e-07,0.73979,4
350.02580,133.80000,     -0.29002, 41.59008,50.00000,20.00000,1.152681e-07,0.73979,4
350.01930,134.40000,     -0.28856, 41.34425,50.00000,20.00000,1.149582e-07,0.73979,4
350.02967,135.00000,     -0.28708, 41.12839,50.00000,20.00000,1.149956e-07,0.73978,4
350.02693,135.60000,     -0.28817, 40.89433,50.00000,20.00000,1.146452e-07,0.73979,4
350.02611,136.20000,     -0.28907, 40.66811,50.00000,20.00000,1.144370e-07,0.73979,4
350.03200,136.80000,     -0.28981, 40.44620,50.00000,20.00000,1.145723e-07,0.73978,4
350.03622,137.40000,     -0.28924, 40.21783,50.00000,20.00000,1.145849e-07,0.73978,4
350.02607,138.00000,     -0.29011, 40.00246,50.00000,20.00000,1.146150e-07,0.73979,4
350.03355,138.60000,     -0.29060, 39.78623,50.00000,20.00000,1.146430e-07,0.73978,4
350.03077,139.20000,     -0.29072, 39.56285,50.00000,20.00000,1.146279e-07,0.73978,4
350.03047,139.80000,     -0.28969, 39.35578,50.00000,20.00000,1.149850e-07,0.73978,4
350.01467,140.40000,     -0.29000, 39.13483,50.00000,20.00000,1.141468e-07,0.73980,4
350.03027,141.00000,     -0.28939, 38.91175,50.00000,20.00000,1.151047e-07,0.73978,4
350.03744,141.60000,     -0.28847, 38.70710,50.00000,20.00000,1.144686e-07,0.73978,4
350.04318,142.20000,     -0.28982, 38.49883,50.00000,20.00000,1.151932e-07,0.73977,4
350.02729,142.80000,     -0.28925, 38.28607,50.00000,20.00000,1.146324e-07,0.73979,4
350.02904,143.40000,     -0.28883, 38.08348,50.00000,20.00000,1.145334e-07,0.73978,4
350.03911,144.00000,     -0.28889, 37.87753,50.00000,20.00000,1.143463e-07,0.73978,4
350.04211,144.60000,     -0.28992, 37.68258,50.00000,20.00000,1.143313e-07,0.73977,4
350.02788,145.20000,     -0.29126, 37.47926,50.00000,20.00000,1.149376e-07,0.73979,4
350.03075,145.80000,     -0.29143, 37.27303,50.00000,20.00000,1.145464e-07,0.73978,4
350.02985,146.40000,     -0.28992, 37.07457,50.00000,20.00000,1.145106e-07,0.73978,4
350.02574,147.00000,     -0.29080, 36.89018,50.00000,20.00000,1.148052e-07,0.73979,4
350.02890,147.60000,     -0.29131, 36.68650,50.00000,20.00000,1.143436e-07,0.73978,4
350.02957,148.20000,     -0.29073, 36.48621,50.00000,20.00000,1.144327e-07,0.73978,4
350.01691,148.80000,     -0.28954, 36.29083,50.00000,20.00000,1.145937e-07,0.73980,4
350.02635,149.40000,     -0.29006, 36.10348,50.00000,20.00000,1.144769e-07,0.73979,4
350.02797,150.00000,     -0.28928, 35.90247,50.00000,20.00000,1.144189e-07,0.73979,4
350.03188,150.60000,     -0.28951, 35.73416,50.00000,20.00000,1.141710e-07,0.73978,4
350.04081,151.20000,     -0.29070, 35.53478,50.00000,20.00000,1.151735e-07,0.73977,4
350.03650,151.80000,     -0.29214, 35.36185,50.00000,20.00000,1.144699e-07,0.73978,4
350.03280,152.40000,     -0.29154, 35.17025,50.00000,20.00000,1.145177e-07,0.73978,4
350.02184,153.00000,     -0.29022, 34.99348,50.00000,20.00000,1.145734e-07,0.73979,4
350.03469,153.60000,     -0.29096, 34.79315,50.00000,20.00000,1.144890e-07,0.73978,4
350.02861,154.20000,     -0.29275, 34.61980,50.00000,20.00000,1.142543e-07,0.73979,4
350.03437,154.80000,     -0.29119, 34.44892,50.00000,20.00000,1.149061e-07,0.73978,4
350.02648,155.40000,     -0.29161, 34.26856,50.00000,20.00000,1.150668e-07,0.73979,4
350.02782,156.00000,     -0.29135, 34.09744,50.00000,20.00000,1.146506e-07,0.73979,4
350.03926,156.60000,     -0.29065, 33.91154,50.00000,20.00000,1.142536e-07,0.73978,4
350.03227,157.20000,     -0.29214, 33.73711,50.00000,20.00000,1.146578e-07,0.73978,4
350.03069,157.80000,     -0.29197, 33.58308,50.00000,20.00000,1.140048e-07,0.73978,4
350.03245,158.40000,     -0.29187, 33.41416,50.00000,20.00000,1.143998e-07,0.73978,4
350.02315,159.00000,     -0.29335, 33.22960,50.00000,20.00000,1.142738e-07,0.73979,4
350.02675,159.60000,     -0.29169, 33.07871,50.00000,20.00000,1.141010e-07,0.73979,4
350.02446,160.20000,     -0.29110, 32.90995,50.00000,20.00000,1.145851e-07,0.73979,4
350.03091,160.80000,     -0.29061, 32.73994,50.00000,20.00000,1.145845e-07,0.73978,4
350.03092,161.40000,     -0.29164, 32.58215,50.00000,20.00000,1.149632e-07,0.73978,4
350.03167,162.00000,     -0.29182, 32.41442,50.00000,20.00000,1.145338e-07,0.73978,4
350.02750,162.60000,     -0.29270, 32.25219,50.00000,20.00000,1.144052e-07,0.73979,4
350.02950,163.20000,     -0.29146, 32.10125,50.00000,20.00000,1.149916e-07,0.73978,4
350.03509,163.80000,     -0.29154, 31.94825,50.00000,20.00000,1.140730e-07,0.73978,4
350.03361,164.40000,     -0.29196, 31.78637,50.00000,20.00000,1.144688e-07,0.73978,4
350.03425,165.00000,     -0.29175, 31.63471,50.00000,20.00000,1.146763e-07,0.73978,4
350.03467,165.60000,     -0.29194, 31.47463,50.00000,20.00000,1.145036e-07,0.73978,4
350.02693,166.20000,     -0.29154, 31.32043,50.00000,20.00000,1.141831e-07,0.73979,4
350.03219,166.80000,     -0.29256, 31.16736,50.00000,20.00000,1.142298e-07,0.73978,4
350.04057,167.40000,     -0.29185, 31.01085,50.00000,20.00000,1.143277e-07,0.73977,4
350.03459,168.00000,     -0.29145, 30.86121,50.00000,20.00000,1.144834e-07,0.73978,4
350.02856,168.60000,     -0.29262, 30.71930,50.00000,20.00000,1.141169e-07,0.73979,4
350.02156,169.20000,     -0.29235, 30.55387,50.00000,20.00000,1.142844e-07,0.73979,4
350.04300,169.80000,     -0.29084, 30.41204,50.00000,20.00000,1.138828e-07,0.73977,4
350.03347,170.40000,     -0.29062, 30.25874,50.00000,20.00000,1.141590e-07,0.73978,4
350.03767,171.00000,     -0.29063, 30.12730,50.00000,20.00000,1.141110e-07,0.73978,4
350.03888,171.60000,     -0.29219, 29.97284,50.00000,20.00000,1.137297e-07,0.73978,4
350.04078,172.20000,     -0.29311, 29.82557,50.00000,20.00000,1.139115e-07,0.73977,4
350.03516,172.80000,     -0.29410, 29.69252,50.00000,20.00000,1.139234e-07,0.73978,4
350.02976,173.40000,     -0.29370, 29.54418,50.00000,20.00000,1.140966e-07,0.73978,4
350.02617,174.00000,     -0.29276, 29.40796,50.00000,20.00000,1.141919e-07,0.73979,4
350.03100,174.60000,     -0.29052, 29.27065,50.00000,20.00000,1.138643e-07,0.73978,4
350.03242,175.20000,     -0.29050, 29.13445,50.00000,20.00000,1.142438e-07,0.73978,4
350.03731,175.80000,     -0.29124, 28.99144,50.00000,20.00000,1.143679e-07,0.73978,4
350.03921,176.40000,     -0.29272, 28.87458,50.00000,20.00000,1.148527e-07,0.73978,4
350.03047,177.00000,     -0.29471, 28.72297,50.00000,20.00000,1.144736e-07,0.73978,4
350.01848,177.60000,     -0.29537, 28.58507,50.00000,20.00000,1.137276e-07,0.73979,4
350.03101,178.20000,     -0.29282, 28.44209,50.00000,20.00000,1.138620e-07,0.73978,4
350.02985,178.80000,     -0.29174, 28.33184,50.00000,20.00000,1.140393e-07,0.73978,4
350.01968,179.40000,     -0.29234, 28.18766,50.00000,20.00000,1.142225e-07,0.73979,4
350.02121,180.00000,     -0.29302, 28.06388,50.00000,20.00000,1.143317e-07,0.73979,4
350.02827,180.60000,     -0.29255, 27.94231,50.00000,20.00000,1.139538e-07,0.73979,4
350.02779,181.20000,     -0.29240, 27.80700,50.00000,20.00000,1.144420e-07,0.73979,4
350.02779,181.80000,     -0.29226, 27.67781,50.00000,20.00000,1.143306e-07,0.73979,4
350.02741,182.40000,     -0.29237, 27.55379,50.00000,20.00000,1.139600e-07,0.73979,4
350.03282,183.00000,     -0.29346, 27.42571,50.00000,20.00000,1.139900e-07,0.73978,4
350.02892,183.60000,     -0.29370, 27.29841,50.00000,20.00000,1.145217e-07,0.73978,4
350.02952,184.20000,     -0.29267, 27.18478,50.00000,20.00000,1.137798e-07,0.73978,4
350.03237,184.80000,     -0.29217, 27.05287,50.00000,20.00000,1.137423e-07,0.73978,4
350.02060,185.40000,     -0.29205, 26.92810,50.00000,20.00000,1.138936e-07,0.73979,4
350.02147,186.00000,     -0.29028, 26.79078,50.00000,20.00000,1.142578e-07,0.73979,4
350.03705,186.60000,     -0.29193, 26.68269,50.00000,20.00000,1.139402e-07,0.73978,4
350.03094,187.20000,     -0.29276, 26.56310,50.00000,20.00000,1.141369e-07,0.73978,4
350.03614,187.80000,     -0.29318, 26.44289,50.00000,20.00000,1.146518e-07,0.73978,4
350.03101,188.40000,     -0.29306, 26.33483,50.00000,20.00000,1.144496e-07,0.73978,4
350.03264,189.00000,     -0.29337, 26.20638,50.00000,20.00000,1.141615e-07,0.73978,4
350.03844,189.60000,     -0.29245, 26.08498,50.00000,20.00000,1.142975e-07,0.73978,4
350.03629,190.20000,     -0.29300, 25.95891,50.00000,20.00000,1.143171e-07,0.73978,4
350.03638,190.80000,     -0.29410, 25.84965,50.00000,20.00000,1.141713e-07,0.73978,4
350.03348,191.40000,     -0.29208, 25.74498,50.00000,20.00000,1.143669e-07,0.73978,4
350.03971,192.00000,     -0.29083, 25.62178,50.00000,20.00000,1.142848e-07,0.73977,4
350.04196,192.60000,     -0.29265, 25.51871,50.00000,20.00000,1.141743e-07,0.73977,4
350.04047,193.20000,     -0.29359, 25.42080,50.00000,20.00000,1.143575e-07,0.73977,4
350.03423,193.80000,     -0.29393, 25.29702,50.00000,20.00000,1.140536e-07,0.73978,4
350.04267,194.40000,     -0.29092, 25.18896,50.00000,20.00000,1.137628e-07,0.73977,4
350.04013,195.00000,     -0.28939, 25.06610,50.00000,20.00000,1.140494e-07,0.73977,4
350.04631,195.60000,     -0.29134, 24.96826,50.00000,20.00000,1.139275e-07,0.73977,4
350.03404,196.20000,     -0.29426, 24.84879,50.00000,20.00000,1.136175e-07,0.73978,4
350.04591,196.80000,     -0.29441, 24.73521,50.00000,20.00000,1.135186e-07,0.73977,4
350.03736,197.40000,     -0.29392, 24.64070,50.00000,20.00000,1.137334e-07,0.73978,4
350.02999,198.00000,     -0.29402, 24.53154,50.00000,20.00000,1.135787e-07,0.73978,4
350.03108,198.60000,     -0.29224, 24.43473,50.00000,20.00000,1.139331e-07,0.73978,4
350.02990,199.20000,     -0.29171, 24.30975,50.00000,20.00000,1.136302e-07,0.73978,4
350.13228,199.80000,     -0.29264, 24.21548,50.00000,20.00000,1.141885e-07,0.73969,4
350.02697,200.40000,     -0.29276, 24.10590,50.00000,20.00000,1.136865e-07,0.73979,4
350.04041,201.00000,     -0.28955, 24.01037,50.00000,20.00000,1.143051e-07,0.73977,4
350.02617,201.60000,     -0.29200, 23.89429,50.00000,20.00000,1.138441e-07,0.73979,4
350.04359,202.20000,     -0.29145, 23.79765,50.00000,20.00000,1.144272e-07,0.73977,4
350.03464,202.80000,     -0.29161, 23.70079,50.00000,20.00000,1.140488e-07,0.73978,4
350.04451,203.40000,     -0.29412, 23.60026,50.00000,20.00000,1.138349e-07,0.73977,4
350.02141,204.00000,     -0.29370, 23.49727,50.00000,20.00000,1.140961e-07,0.73979,4
350.03094,204.60000,     -0.29213, 23.40249,50.00000,20.00000,1.134948e-07,0.73978,4
350.03730,205.20000,     -0.29140, 23.30796,50.00000,20.00000,1.141163e-07,0.73978,4
350.04437,205.80000,     -0.29175, 23.20517,50.00000,20.00000,1.141953e-07,0.73977,4
350.03159,206.40000,     -0.29097, 23.10620,50.00000,20.00000,1.141058e-07,0.73978,4
350.03339,207.00000,     -0.29261, 23.01970,50.00000,20.00000,1.138513e-07,0.73978,4
350.04153,207.60000,     -0.29252, 22.91055,50.00000,20.00000,1.141597e-07,0.73977,4
350.03745,208.20000,     -0.29219, 22.81602,50.00000,20.00000,1.142544e-07,0.73978,4
350.04139,208.80000,     -0.29235, 22.72139,50.00000,20.00000,1.141883e-07,0.73977,4
350.02912,209.40000,     -0.29100, 22.63811,50.00000,20.00000,1.137705e-07,0.73978,4
350.03134,210.00000,     -0.29102, 22.53110,50.00000,20.00000,1.139333e-07,0.73978,4
350.02450,210.60000,     -0.29256, 22.44677,50.00000,20.00000,1.134065e-07,0.73979,4
350.02869,211.20000,     -0.29255, 22.36241,50.00000,20.00000,1.144203e-07,0.73979,4
350.02927,211.80000,     -0.29130, 22.26776,50.00000,20.00000,1.139475e-07,0.73978,4
350.02949,212.40000,     -0.29130, 22.17323,50.00000,20.00000,1.141440e-07,0.73978,4
350.03704,213.00000,     -0.29210, 22.07871,50.00000,20.00000,1.132816e-07,0.73978,4
350.02420,213.60000,     -0.29022, 21.98284,50.00000,20.00000,1.139442e-07,0.73979,4
350.01845,214.20000,     -0.28918, 21.91323,50.00000,20.00000,1.136743e-07,0.73979,4
350.03375,214.80000,     -0.28958, 21.81642,50.00000,20.00000,1.134623e-07,0.73978,4
350.02628,215.40000,     -0.29002, 21.73423,50.00000,20.00000,1.141571e-07,0.73979,4
350.02547,216.00000,     -0.29032, 21.65094,50.00000,20.00000,1.142563e-07,0.73979,4
350.03513,216.60000,     -0.29075, 21.55642,50.00000,20.00000,1.139740e-07,0.73978,4
350.01554,217.20000,     -0.29134, 21.47518,50.00000,20.00000,1.141882e-07,0.73980,4
350.02843,217.80000,     -0.29206, 21.38836,50.00000,20.00000,1.136854e-07,0.73979,4
350.02795,218.40000,     -0.29102, 21.29751,50.00000,20.00000,1.135585e-07,0.73979,4
350.01612,219.00000,     -0.29050, 21.21413,50.00000,20.00000,1.136129e-07,0.73980,4
350.02128,219.60000,     -0.28988, 21.13203,50.00000,20.00000,1.139001e-07,0.73979,4
350.02940,220.20000,     -0.29083, 21.04080,50.00000,20.00000,1.131935e-07,0.73978,4
350.03733,220.80000,     -0.29027, 20.96655,50.00000,20.00000,1.136443e-07,0.73978,4
350.02521,221.40000,     -0.29017, 20.88209,50.00000,20.00000,1.133230e-07,0.73979,4
350.03128,222.00000,     -0.28949, 20.81446,50.00000,20.00000,1.136868e-07,0.73978,4
350.03124,222.60000,     -0.29142, 20.72000,50.00000,20.00000,1.139344e-07,0.73978,4
350.03263,223.20000,     -0.29154, 20.63890,50.00000,20.00000,1.131627e-07,0.73978,4
350.02524,223.80000,     -0.29135, 20.56222,50.00000,20.00000,1.138877e-07,0.73979,4
350.02823,224.40000,     -0.29146, 20.47682,50.00000,20.00000,1.137795e-07,0.73979,4
350.02319,225.00000,     -0.29123, 20.40935,50.00000,20.00000,1.129529e-07,0.73979,4
350.03583,225.60000,     -0.29095, 20.32716,50.00000,20.00000,1.136626e-07,0.73978,4
350.02889,226.20000,     -0.28972, 20.24606,50.00000,20.00000,1.137202e-07,0.73978,4
350.03328,226.80000,     -0.28906, 20.15711,50.00000,20.00000,1.131167e-07,0.73978,4
350.02681,227.40000,     -0.29011, 20.08846,50.00000,20.00000,1.134295e-07,0.73979,4
350.02605,228.00000,     -0.28979, 20.01980,50.00000,20.00000,1.135627e-07,0.73979,4
350.02405,228.60000,     -0.28957, 19.95249,50.00000,20.00000,1.133376e-07,0.73979,4
350.04113,229.20000,     -0.29011, 19.85552,50.00000,20.00000,1.136759e-07,0.73977,4
350.03377,229.80000,     -0.29090, 19.78822,50.00000,20.00000,1.138713e-07,0.73978,4
350.04530,230.40000,     -0.29155, 19.72040,50.00000,20.00000,1.138218e-07,0.73977,4
350.03261,231.00000,     -0.29194, 19.63930,50.00000,20.00000,1.140115e-07,0.73978,4
350.02845,231.60000,     -0.29012, 19.55889,50.00000,20.00000,1.137020e-07,0.73979,4
350.03346,232.20000,     -0.28931, 19.49642,50.00000,20.00000,1.137014e-07,0.73978,4
350.03189,232.80000,     -0.28933, 19.41502,50.00000,20.00000,1.137564e-07,0.73978,4
350.03340,233.40000,     -0.29060, 19.33989,50.00000,20.00000,1.133040e-07,0.73978,4
350.02844,234.00000,     -0.29082, 19.27234,50.00000,20.00000,1.141338e-07,0.73979,4
350.02045,234.60000,     -0.29060, 19.20488,50.00000,20.00000,1.133925e-07,0.73979,4
350.03184,235.20000,     -0.29092, 19.13731,50.00000,20.00000,1.142706e-07,0.73978,4
350.02621,235.80000,     -0.29175, 19.05622,50.00000,20.00000,1.138968e-07,0.73979,4
350.03758,236.40000,     -0.28991, 18.99542,50.00000,20.00000,1.137358e-07,0.73978,4
350.02759,237.00000,     -0.29092, 18.90642,50.00000,20.00000,1.137045e-07,0.73979,4
350.02784,237.60000,     -0.29033, 18.84915,50.00000,20.00000,1.138193e-07,0.73979,4
350.03523,238.20000,     -0.29064, 18.79512,50.00000,20.00000,1.131330e-07,0.73978,4
350.03103,238.80000,     -0.29101, 18.72673,50.00000,20.00000,1.129651e-07,0.73978,4
350.03124,239.40000,     -0.28990, 18.65891,50.00000,20.00000,1.134855e-07,0.73978,4
350.02498,240.00000,     -0.28865, 18.57874,50.00000,20.00000,1.130398e-07,0.73979,4
350.03172,240.60000,     -0.28886, 18.50636,50.00000,20.00000,1.139915e-07,0.73978,4
350.03273,241.20000,     -0.28909, 18.43711,50.00000,20.00000,1.133050e-07,0.73978,4
350.04828,241.80000,     -0.28971, 18.38638,50.00000,20.00000,1.132871e-07,0.73977,4
350.02964,242.40000,     -0.29012, 18.30268,50.00000,20.00000,1.138980e-07,0.73978,4
350.03349,243.00000,     -0.29000, 18.24808,50.00000,20.00000,1.130844e-07,0.73978,4
350.04025,243.60000,     -0.29103, 18.18802,50.00000,20.00000,1.136947e-07,0.73977,4
350.02931,244.20000,     -0.29080, 18.11403,50.00000,20.00000,1.135400e-07,0.73978,4
350.02863,244.80000,     -0.29092, 18.05662,50.00000,20.00000,1.132998e-07,0.73979,4
350.02940,245.40000,     -0.29083, 17.97562,50.00000,20.00000,1.138542e-07,0.73978,4
350.03159,246.00000,     -0.28956, 17.92036,50.00000,20.00000,1.135296e-07,0.73978,4
350.02347,246.60000,     -0.28920, 17.87307,50.00000,20.00000,1.133840e-07,0.73979,4
350.02933,247.20000,     -0.29112, 17.78766,50.00000,20.00000,1.132889e-07,0.73978,4
350.03011,247.80000,     -0.29029, 17.73363,50.00000,20.00000,1.136785e-07,0.73978,4
350.03324,248.40000,     -0.28896, 17.66594,50.00000,20.00000,1.131784e-07,0.73978,4
350.02205,249.00000,     -0.28935, 17.59622,50.00000,20.00000,1.136272e-07,0.73979,4
350.04396,249.60000,     -0.28876, 17.54109,50.00000,20.00000,1.131504e-07,0.73977,4
350.02809,250.20000,     -0.28957, 17.48706,50.00000,20.00000,1.136798e-07,0.73979,4
350.03530,250.80000,     -0.29071, 17.42965,50.00000,20.00000,1.134860e-07,0.73978,4
350.02715,251.40000,     -0.29042, 17.36099,50.00000,20.00000,1.135895e-07,0.73979,4
350.03379,252.00000,     -0.28845, 17.29343,50.00000,20.00000,1.132448e-07,0.73978,4
350.02771,252.60000,     -0.28983, 17.23264,50.00000,20.00000,1.137240e-07,0.73979,4
350.02716,253.20000,     -0.29053, 17.17861,50.00000,20.00000,1.129229e-07,0.73979,4
350.02362,253.80000,     -0.29052, 17.11535,50.00000,20.00000,1.129608e-07,0.73979,4
350.03808,254.40000,     -0.28852, 17.06040,50.00000,20.00000,1.136846e-07,0.73978,4
350.03124,255.00000,     -0.28744, 16.98836,50.00000,20.00000,1.138007e-07,0.73978,4
350.03957,255.60000,     -0.28990, 16.94786,50.00000,20.00000,1.135279e-07,0.73977,4
350.04172,256.20000,     -0.29070, 16.88597,50.00000,20.00000,1.134394e-07,0.73977,4
350.03100,256.80000,     -0.29190, 16.82517,50.00000,20.00000,1.137634e-07,0.73978,4
350.03544,257.40000,     -0.28837, 16.77114,50.00000,20.00000,1.134296e-07,0.73978,4
350.04412,258.00000,     -0.29036, 16.71711,50.00000,20.00000,1.127967e-07,0.73977,4
350.04696,258.60000,     -0.29197, 16.64846,50.00000,20.00000,1.131263e-07,0.73977,4
350.02969,259.20000,     -0.29173, 16.59443,50.00000,20.00000,1.134190e-07,0.73978,4
350.02526,259.80000,     -0.29104, 16.54039,50.00000,20.00000,1.136641e-07,0.73979,4
350.03601,260.40000,     -0.28970, 16.49980,50.00000,20.00000,1.134156e-07,0.73978,4
350.02770,261.00000,     -0.29021, 16.43114,50.00000,20.00000,1.130155e-07,0.73979,4
350.03076,261.60000,     -0.29028, 16.37711,50.00000,20.00000,1.137569e-07,0.73978,4
350.02685,262.20000,     -0.28991, 16.32199,50.00000,20.00000,1.130416e-07,0.73979,4
350.02435,262.80000,     -0.28997, 16.27364,50.00000,20.00000,1.136132e-07,0.73979,4
350.02901,263.40000,     -0.28969, 16.21960,50.00000,20.00000,1.135557e-07,0.73978,4
350.02970,264.00000,     -0.28945, 16.16557,50.00000,20.00000,1.136426e-07,0.73978,4
350.02906,264.60000,     -0.29037, 16.09801,50.00000,20.00000,1.128036e-07,0.73978,4
350.02980,265.20000,     -0.29071, 16.04398,50.00000,20.00000,1.135841e-07,0.73978,4
350.03068,265.80000,     -0.28941, 16.00338,50.00000,20.00000,1.126962e-07,0.73978,4
350.02716,266.40000,     -0.29066, 15.94935,50.00000,20.00000,1.134311e-07,0.73979,4
350.03124,267.00000,     -0.29077, 15.89313,50.00000,20.00000,1.131468e-07,0.73978,4
350.02420,267.60000,     -0.29223, 15.83910,50.00000,20.00000,1.128011e-07,0.73979,4
350.04020,268.20000,     -0.28908, 15.79850,50.00000,20.00000,1.133008e-07,0.73977,4
350.04153,268.80000,     -0.28748, 15.74448,50.00000,20.00000,1.131267e-07,0.73977,4
350.03896,269.40000,     -0.28906, 15.69797,50.00000,20.00000,1.133430e-07,0.73978,4
350.03556,270.00000,     -0.28904, 15.64178,50.00000,20.00000,1.130962e-07,0.73978,4
350.03868,270.60000,     -0.28930, 15.58020,50.00000,20.00000,1.132912e-07,0.73978,4
350.04045,271.20000,     -0.28824, 15.52617,50.00000,20.00000,1.134241e-07,0.73977,4
350.05417,271.80000,     -0.29155, 15.48557,50.00000,20.00000,1.131289e-07,0.73976,4
350.03793,272.40000,     -0.29145, 15.42923,50.00000,20.00000,1.135351e-07,0.73978,4
350.04197,273.00000,     -0.28978, 15.39104,50.00000,20.00000,1.127047e-07,0.73977,4
350.02951,273.60000,     -0.28864, 15.32348,50.00000,20.00000,1.133382e-07,0.73978,4
350.04008,274.20000,     -0.28908, 15.28299,50.00000,20.00000,1.131260e-07,0.73977,4
350.03757,274.80000,     -0.29041, 15.24248,50.00000,20.00000,1.136246e-07,0.73978,4
350.02984,275.40000,     -0.29099, 15.17493,50.00000,20.00000,1.128031e-07,0.73978,4
350.03092,276.00000,     -0.29008, 15.13501,50.00000,20.00000,1.125386e-07,0.73978,4
350.03488,276.60000,     -0.28972, 15.09274,50.00000,20.00000,1.125666e-07,0.73978,4
350.03551,277.20000,     -0.29030, 15.05900,50.00000,20.00000,1.130984e-07,0.73978,4
350.03290,277.80000,     -0.29092, 14.99034,50.00000,20.00000,1.137491e-07,0.73978,4
350.03156,278.40000,     -0.28939, 14.96109,50.00000,20.00000,1.129242e-07,0.73978,4
350.03981,279.00000,     -0.28865, 14.90706,50.00000,20.00000,1.135350e-07,0.73977,4
350.03463,279.60000,     -0.29068, 14.85303,50.00000,20.00000,1.123710e-07,0.73978,4
350.03885,280.20000,     -0.28966, 14.81134,50.00000,20.00000,1.132459e-07,0.73978,4
350.04438,280.80000,     -0.29013, 14.77085,50.00000,20.00000,1.130616e-07,0.73977,4
350.04241,281.40000,     -0.28948, 14.71682,50.00000,20.00000,1.135830e-07,0.73977,4
350.04419,282.00000,     -0.28868, 14.67842,50.00000,20.00000,1.136125e-07,0.73977,4
350.04960,282.60000,     -0.29021, 14.63801,50.00000,20.00000,1.135312e-07,0.73977,4
350.26303,283.20000,     -0.19787, 14.58403,50.00000,20.00000,1.133550e-07,0.73956,5
354.33182,283.80000,      1.24239, 14.69169,50.00000,20.00000,1.125573e-07,0.73568,5
359.82518,284.40000,      1.91897, 14.80152,50.00000,20.00000,1.133762e-07,0.73044,5
364.73361,285.00000,      1.81096, 14.78689,50.00000,20.00000,1.128165e-07,0.72577,5
369.92428,285.60000,      1.90445, 14.75055,50.00000,20.00000,1.126753e-07,0.72083,5
375.73490,286.20000,      2.15674, 14.70975,50.00000,20.00000,1.127860e-07,0.71533,5
381.81741,286.80000,      2.30892, 14.62656,50.00000,20.00000,1.129134e-07,0.70958,5
387.98482,287.40000,      2.37068, 14.49838,50.00000,20.00000,1.128153e-07,0.70378,5
394.22328,288.00000,      2.41844, 14.30206,50.00000,20.00000,1.131843e-07,0.69794,5
400.51238,288.60000,      2.46031, 14.03141,50.00000,20.00000,1.134444e-07,0.69209,5
406.81735,289.20000,      2.48900, 13.65638,50.00000,20.00000,1.126216e-07,0.68626,5
413.10713,289.80000,      2.50368, 13.15495,50.00000,20.00000,1.126614e-07,0.68049,5
419.36009,290.40000,      2.51298, 12.53647,50.00000,20.00000,1.134133e-07,0.67479,5
425.60671,291.00000,      2.51359, 11.79222,50.00000,20.00000,1.133516e-07,0.66915,5
431.81399,291.60000,      2.49987, 11.01892,50.00000,20.00000,1.135475e-07,0.66359,5
437.99312,292.20000,      2.47390, 10.18880,50.00000,20.00000,1.131286e-07,0.65811,5
444.15475,292.80000,      2.42775,  9.45836,50.00000,20.00000,1.134573e-07,0.65269,5
450.29667,293.40000,      2.36740,  8.88174,50.00000,20.00000,1.130425e-07,0.64736,5
456.40715,294.00000,      2.29583,  8.47310,50.00000,20.00000,1.131831e-07,0.64210,5
462.50512,294.60000,      2.21680,  8.27456,50.00000,20.00000,1.140217e-07,0.63692,5
468.59578,295.20000,      2.14639,  8.23187,50.00000,20.00000,1.132263e-07,0.63180,5
474.65979,295.80000,      2.08231,  8.23568,50.00000,20.00000,1.140552e-07,0.62677,5
480.70405,296.40000,      2.02447,  8.24878,50.00000,20.00000,1.136837e-07,0.62182,5
486.74724,297.00000,      1.96271,  8.28937,50.00000,20.00000,1.136883e-07,0.61694,5
492.77657,297.60000,      1.90030,  8.30714,50.00000,20.00000,1.137461e-07,0.61213,5
498.78790,298.20000,      1.83269,  8.32696,50.00000,20.00000,1.142528e-07,0.60740,5
504.80467,298.80000,      1.76705,  8.36079,50.00000,20.00000,1.136309e-07,0.60274,5
510.82272,299.40000,      1.68901,  8.39606,50.00000,20.00000,1.137054e-07,0.59814,5
516.83106,300.00000,      1.61384,  8.40312,50.00000,20.00000,1.134167e-07,0.59362,5
522.82654,300.60000,      1.53325,  8.44478,50.00000,20.00000,1.135862e-07,0.58918,5
528.83865,301.20000,      1.45115,  8.45821,50.00000,20.00000,1.141115e-07,0.58479,5
534.83506,301.80000,      1.36115,  8.48523,50.00000,20.00000,1.141524e-07,0.58048,5
540.82479,302.40000,      1.26840,  8.50577,50.00000,20.00000,1.138036e-07,0.57625,5
546.81056,303.00000,      1.17582,  8.53279,50.00000,20.00000,1.136302e-07,0.57209,5
552.79997,303.60000,      1.07877,  8.56014,50.00000,20.00000,1.140493e-07,0.56800,5
558.79939,304.20000,      0.97147,  8.57003,50.00000,20.00000,1.146764e-07,0.56397,5
564.80543,304.80000,      0.86587,  8.59783,50.00000,20.00000,1.139242e-07,0.56000,5
570.77981,305.40000,      0.75876,  8.61423,50.00000,20.00000,1.141134e-07,0.55613,5
576.77725,306.00000,      0.64332,  8.63409,50.00000,20.00000,1.142605e-07,0.55230,5
582.76852,306.60000,      0.53007,  8.66304,50.00000,20.00000,1.145705e-07,0.54855,5
588.77651,307.20000,      0.41598,  8.68248,50.00000,20.00000,1.143629e-07,0.54485,5
594.77674,307.80000,      0.29632,  8.70295,50.00000,20.00000,1.145679e-07,0.54122,5
600.77454,308.40000,      0.17601,  8.73633,50.00000,20.00000,1.149315e-07,0.53765,5
606.76985,309.00000, 5.367021e-02,  8.75003,50.00000,20.00000,1.142659e-07,0.53415,5
612.77579,309.60000,-7.015160e-02,  8.77693,50.00000,20.00000,1.142063e-07,0.53071,5
618.77344,310.20000,     -0.19541,  8.79048,50.00000,20.00000,1.139834e-07,0.52733,5
624.77340,310.80000,     -0.31651,  8.83087,50.00000,20.00000,1.143300e-07,0.52401,5
630.78150,311.40000,     -0.44136,  8.85733,50.00000,20.00000,1.140719e-07,0.52074,5
636.78390,312.00000,     -0.56407,  8.85780,50.00000,20.00000,1.145496e-07,0.51753,5
642.79033,312.60000,     -0.68777,  8.88441,50.00000,20.00000,1.149743e-07,0.51437,5
648.78831,313.20000,     -0.80861,  8.89833,50.00000,20.00000,1.151361e-07,0.51127,5
654.79575,313.80000,     -0.93030,  8.92207,50.00000,20.00000,1.146836e-07,0.50822,5
660.80556,314.40000,     -1.05425,  8.93946,50.00000,20.00000,1.143140e-07,0.50522,5
666.79352,315.00000,     -1.17642,  8.96580,50.00000,20.00000,1.145682e-07,0.50227,5
672.81187,315.60000,     -1.29405,  8.98310,50.00000,20.00000,1.144693e-07,0.49936,5
678.81338,316.20000,     -1.41643,  9.01111,50.00000,20.00000,1.148313e-07,0.49649,5
684.81981,316.80000,     -1.53927,  9.01747,50.00000,20.00000,1.150776e-07,0.49367,5
690.82482,317.40000,     -1.65785,  9.02550,50.00000,20.00000,1.147332e-07,0.49089,5
696.83980,318.00000,     -1.78335,  9.06195,50.00000,20.00000,1.147592e-07,0.48814,5
702.84188,318.60000,     -1.90605,  9.07854,50.00000,20.00000,1.147280e-07,0.48543,5
708.85390,319.20000,     -2.03686,  9.09241,50.00000,20.00000,1.150886e-07,0.48275,5
714.87290,319.80000,     -2.17132,  9.12152,50.00000,20.00000,1.146539e-07,0.48010,5
720.87689,320.40000,     -2.31183,  9.12438,50.00000,20.00000,1.152390e-07,0.47749,5
726.88963,321.00000,     -2.46048,  9.14206,50.00000,20.00000,1.145818e-07,0.47490,5
732.90969,321.60000,     -2.61496,  9.15163,50.00000,20.00000,1.146809e-07,0.47234,5
738.92202,322.20000,     -2.77547,  9.17832,50.00000,20.00000,1.149714e-07,0.46980,5
744.92182,322.80000,     -2.93939,  9.18843,50.00000,20.00000,1.148949e-07,0.46729,5
750.93397,323.40000,     -3.10919,  9.19092,50.00000,20.00000,1.148887e-07,0.46479,5
756.94686,324.00000,     -3.28420,  9.19197,50.00000,20.00000,1.150778e-07,0.46231,5
762.95728,324.60000,     -3.45864,  9.20589,50.00000,20.00000,1.153521e-07,0.45984,5
768.97818,325.20000,     -3.63507,  9.22942,50.00000,20.00000,1.151486e-07,0.45739,5
774.98663,325.80000,     -3.81225,  9.23675,50.00000,20.00000,1.151254e-07,0.45495,5
780.99056,326.40000,     -3.98957,  9.27340,50.00000,20.00000,1.155033e-07,0.45253,5
786.98390,327.00000,     -4.16888,  9.25986,50.00000,20.00000,1.150243e-07,0.45011,5
792.99322,327.60000,     -4.34255,  9.29364,50.00000,20.00000,1.151475e-07,0.44770,5
793.99430,327.70000,     -4.37129,  9.29581,50.00000,20.00000,1.151475e-07,0.44729,5