File: pc_x_polymers/ExpDat_2024_01_19_SL_001G.csv
#EXPORTTYPE:                 ,DATA ALL
#FILE:                       ,2024_01_19_SL_001G.ngb-ss5
#FORMAT:                     ,NETZSCH5
#FTYPE:                      ,ASCII
#IDENTITY:                   ,polystyrene
#DECIMAL:                    ,POINT
#SEPARATOR:                  ,COMMA
#MTYPE:                      ,DSC
#INSTRUMENT:                 ,NETZSCH STA 449F5
#PROJECT:                    ,2024_01_08_SL_007B
#DATE/TIME:                  ,1/19/2024 9:10:06 AM (UTC-5)
#CORR. FILE:                 ,
#TEMPCAL:                    ,28-06-2023 13:26
#SENSITIVITY:                ,28-06-2023 13:53
#LABORATORY:                 ,Tran/AAG
#OPERATOR:                   ,Stanley
#REMARK:                     ,
#SAMPLE:                     ,001G
#SAMPLE MASS /mg:            ,15.23
#MATERIAL:                   ,
#REFERENCE:                  ,
#REFERENCE MASS /mg:         ,0
#TYPE OF CRUCIBLE:           ,Al2O3 85 ‘l, open
#SAMPLE CRUCIBLE MASS /mg:   ,0
#REFERENCE CRUCIBLE MASS /mg:,0
#DSC RANGE /‘V:              ,5000
#TG RANGE /mg:               ,35000
#TAU-R:                      ,---
#CORR. CODE:                 ,000
#EXO:                        ,-1
#RANGE:                      ,20›C....800›C/0.0....10.0K/min
#SEGMENT:                    ,S1-5/5
#SEG. 1:                     ,20›C/10.0(K/min)/100›C
#SEG. 2:                     ,100›C/00:10/100›C
#SEG. 3:                     ,100›C/10.0(K/min)/350›C
#SEG. 4:                     ,350›C/04:00/350›C
#SEG. 5:                     ,350›C/10.0(K/min)/800›C

##Temp./›C,Time/min,DSC/(mW/mg),Mass/%,Gas Flow(purge2)/(ml/min),Gas Flow(protective)/(ml/min),TIC(scan:1)/A,Sensit./(uV/mW),Segment
 29.78000,  0.00000, 2.299922e-02,100.00000,50.00000,20.00000,1.678584e-07,0.92351,1
 30.25600,  0.60000, 2.842085e-02, 99.96435,50.00000,20.00000,1.783152e-07,0.92360,1
 31.37100,  1.20000, 7.879109e-02,100.13966,50.00000,20.00000,1.833188e-07,0.92380,1
 33.13200,  1.80000,      0.13921,100.29041,50.00000,20.00000,1.853835e-07,0.92410,1
 35.35100,  2.40000,      0.18977,100.41372,50.00000,20.00000,1.853712e-07,0.92445,1
 38.04000,  3.00000,      0.24288,100.55706,50.00000,20.00000,1.845724e-07,0.92483,1
 41.34500,  3.60000,      0.31327,100.73979,50.00000,20.00000,1.832592e-07,0.92524,1
 45.42700,  4.20000,      0.40113,100.95076,50.00000,20.00000,1.815809e-07,0.92564,1
 50.26800,  4.80000,      0.49620,101.17137,50.00000,20.00000,1.796183e-07,0.92597,1
 55.77400,  5.40000,      0.58766,101.35338,50.00000,20.00000,1.776074e-07,0.92617,1
 61.84300,  6.00000,      0.67166,101.52127,50.00000,20.00000,1.756390e-07,0.92617,1
 68.35300,  6.60000,      0.74894,101.65870,50.00000,20.00000,1.733860e-07,0.92592,1
 75.21800,  7.20000,      0.81971,101.77236,50.00000,20.00000,1.715833e-07,0.92536,1
 82.37500,  7.80000,      0.88394,101.87485,50.00000,20.00000,1.700407e-07,0.92448,1
 89.55950,  8.40000,      0.90772,101.91036,50.00000,20.00000,1.672862e-07,0.92329,2
 95.58582,  9.00000,      0.78886,101.74813,50.00000,20.00000,1.657956e-07,0.92206,2
100.01455,  9.60000,      0.61320,101.47134,50.00000,20.00000,1.646809e-07,0.92102,2
103.13444, 10.20000,      0.47456,101.25790,50.00000,20.00000,1.635988e-07,0.92023,2
105.53212, 10.80000,      0.36982,101.07160,50.00000,20.00000,1.627574e-07,0.91958,2
107.45655, 11.40000,      0.27669,100.93218,50.00000,20.00000,1.616490e-07,0.91903,2
108.88046, 12.00000,      0.19732,100.79095,50.00000,20.00000,1.605936e-07,0.91861,2
109.77074, 12.60000,      0.12021,100.63081,50.00000,20.00000,1.597046e-07,0.91835,2
110.20886, 13.20000, 5.111838e-02,100.48655,50.00000,20.00000,1.591149e-07,0.91822,2
110.27396, 13.80000,-3.395545e-03,100.35931,50.00000,20.00000,1.581140e-07,0.91820,2
110.08106, 14.40000,-4.445420e-02,100.24602,50.00000,20.00000,1.574633e-07,0.91826,2
109.68785, 15.00000,-7.491345e-02,100.13062,50.00000,20.00000,1.564744e-07,0.91837,2
109.13820, 15.60000,-9.813010e-02,100.03878,50.00000,20.00000,1.557188e-07,0.91854,2
108.48808, 16.20000,     -0.11440, 99.94384,50.00000,20.00000,1.547595e-07,0.91873,2
107.76137, 16.80000,     -0.12543, 99.87131,50.00000,20.00000,1.539871e-07,0.91894,2
107.00888, 17.40000,     -0.13119, 99.80509,50.00000,20.00000,1.531084e-07,0.91916,2
106.25100, 18.00000,     -0.13322, 99.73552,50.00000,20.00000,1.521712e-07,0.91938,3
105.83000, 18.60000,-7.866997e-02, 99.77715,50.00000,20.00000,1.513649e-07,0.91949,3
106.90200, 19.20000,      0.11581,100.08838,50.00000,20.00000,1.504108e-07,0.91919,3
109.48100, 19.80000,      0.33506,100.39442,50.00000,20.00000,1.498240e-07,0.91844,3
112.96500, 20.40000,      0.49065,100.58976,50.00000,20.00000,1.490849e-07,0.91736,3
117.01200, 21.00000,      0.60839,100.73014,50.00000,20.00000,1.483591e-07,0.91602,3
121.78900, 21.60000,      0.73449,100.87873,50.00000,20.00000,1.475621e-07,0.91434,3
127.31300, 22.20000,      0.87148,101.02955,50.00000,20.00000,1.467294e-07,0.91224,3
133.48500, 22.80000,      0.99726,101.16028,50.00000,20.00000,1.460039e-07,0.90970,3
140.11301, 23.40000,      1.09871,101.25456,50.00000,20.00000,1.453117e-07,0.90677,3
147.02800, 24.00000,      1.17800,101.33775,50.00000,20.00000,1.446011e-07,0.90349,3
154.15700, 24.60000,      1.24131,101.39278,50.00000,20.00000,1.441070e-07,0.89986,3
161.38200, 25.20000,      1.28894,101.43880,50.00000,20.00000,1.434377e-07,0.89595,3
168.63100, 25.80000,      1.32124,101.47518,50.00000,20.00000,1.426789e-07,0.89180,3
175.86000, 26.40000,      1.33948,101.49448,50.00000,20.00000,1.431708e-07,0.88743,3
183.01700, 27.00000,      1.32672,101.51011,50.00000,20.00000,1.428001e-07,0.88290,3
190.10600, 27.60000,      1.28942,101.50118,50.00000,20.00000,1.422859e-07,0.87822,3
197.07300, 28.20000,      1.25696,101.49448,50.00000,20.00000,1.418237e-07,0.87343,3
203.91200, 28.80000,      1.23044,101.47446,50.00000,20.00000,1.414041e-07,0.86857,3
210.63300, 29.40000,      1.20672,101.47446,50.00000,20.00000,1.410133e-07,0.86363,3
217.21300, 30.00000,      1.18466,101.46553,50.00000,20.00000,1.405825e-07,0.85866,3
223.68500, 30.60000,      1.16410,101.45883,50.00000,20.00000,1.403723e-07,0.85364,3
230.05299, 31.20000,      1.14536,101.44104,50.00000,20.00000,1.397727e-07,0.84859,3
236.35400, 31.80000,      1.12771,101.42246,50.00000,20.00000,1.396147e-07,0.84347,3
242.57100, 32.40000,      1.11144,101.41576,50.00000,20.00000,1.390249e-07,0.83833,3
248.73199, 33.00000,      1.09606,101.41353,50.00000,20.00000,1.384857e-07,0.83314,3
254.84000, 33.60000,      1.08222,101.38680,50.00000,20.00000,1.382626e-07,0.82792,3
260.89401, 34.20000,      1.07014,101.35338,50.00000,20.00000,1.379920e-07,0.82266,3
266.94601, 34.80000,      1.06027,101.29842,50.00000,20.00000,1.374888e-07,0.81733,3
272.94400, 35.40000,      1.05238,101.22416,50.00000,20.00000,1.371126e-07,0.81198,3
278.93500, 36.00000,      1.04675,101.10972,50.00000,20.00000,1.369836e-07,0.80658,3
284.89001, 36.60000,      1.04195,100.94629,50.00000,20.00000,1.366909e-07,0.80116,3
290.84399, 37.20000,      1.03904,100.71976,50.00000,20.00000,1.364852e-07,0.79570,3
296.78299, 37.80000,      1.03631,100.44123,50.00000,20.00000,1.361434e-07,0.79020,3
302.73499, 38.40000,      1.03362,100.07722,50.00000,20.00000,1.359019e-07,0.78465,3
308.66501, 39.00000,      1.03154, 99.65607,50.00000,20.00000,1.358470e-07,0.77909,3
314.58801, 39.60000,      1.03128, 99.16211,50.00000,20.00000,1.356265e-07,0.77351,3
320.52100, 40.20000,      1.03588, 98.58641,50.00000,20.00000,1.352232e-07,0.76790,3
326.45901, 40.80000,      1.04505, 97.90007,50.00000,20.00000,1.349291e-07,0.76226,3
332.38199, 41.40000,      1.05787, 97.06139,50.00000,20.00000,1.349981e-07,0.75662,3
338.30301, 42.00000,      1.07516, 96.05489,50.00000,20.00000,1.347149e-07,0.75098,3
344.23999, 42.60000,      1.09799, 94.87754,50.00000,20.00000,1.346943e-07,0.74531,3
350.05499, 43.20000,      1.08984, 93.51005,50.00000,20.00000,1.346384e-07,0.73976,4
353.01801, 43.80000,      0.49147, 91.87216,50.00000,20.00000,1.346325e-07,0.73693,4
353.40900, 44.40000,-2.305592e-02, 90.23427,50.00000,20.00000,1.346942e-07,0.73656,4
353.85400, 45.00000,-9.561137e-02, 88.78056,50.00000,20.00000,1.347958e-07,0.73613,4
354.56400, 45.60000,-9.706170e-02, 87.38634,50.00000,20.00000,1.346861e-07,0.73546,4
354.81699, 46.20000,     -0.20332, 85.99054,50.00000,20.00000,1.345117e-07,0.73522,4
354.62799, 46.80000,     -0.31280, 84.64609,50.00000,20.00000,1.342054e-07,0.73540,4
354.32901, 47.40000,     -0.36545, 83.37288,50.00000,20.00000,1.340268e-07,0.73568,4
354.04901, 48.00000,     -0.39452, 82.15318,50.00000,20.00000,1.337233e-07,0.73595,4
353.72101, 48.60000,     -0.42436, 80.98851,50.00000,20.00000,1.340002e-07,0.73626,4
353.37601, 49.20000,     -0.45137, 79.86533,50.00000,20.00000,1.341188e-07,0.73659,4
353.02899, 49.80000,     -0.47007, 78.81202,50.00000,20.00000,1.345454e-07,0.73692,4
352.71500, 50.40000,     -0.48163, 77.78844,50.00000,20.00000,1.347792e-07,0.73722,4
352.41501, 51.00000,     -0.49089, 76.82357,50.00000,20.00000,1.345376e-07,0.73751,4
352.15100, 51.60000,     -0.49710, 75.88313,50.00000,20.00000,1.346867e-07,0.73776,4
351.90799, 52.20000,     -0.50190, 74.97840,50.00000,20.00000,1.346705e-07,0.73799,4
351.69199, 52.80000,     -0.50522, 74.11825,50.00000,20.00000,1.345904e-07,0.73820,4
351.49799, 53.40000,     -0.50883, 73.26921,50.00000,20.00000,1.349765e-07,0.73838,4
351.30899, 54.00000,     -0.51175, 72.45653,50.00000,20.00000,1.345681e-07,0.73856,4
351.14801, 54.60000,     -0.51328, 71.67288,50.00000,20.00000,1.345448e-07,0.73872,4
351.01199, 55.20000,     -0.51461, 70.90407,50.00000,20.00000,1.345196e-07,0.73885,4
350.89899, 55.80000,     -0.51738, 70.16645,50.00000,20.00000,1.345273e-07,0.73895,4
350.79599, 56.40000,     -0.51908, 69.44517,50.00000,20.00000,1.345612e-07,0.73905,4
350.68900, 57.00000,     -0.52063, 68.74399,50.00000,20.00000,1.339415e-07,0.73915,4
350.61200, 57.60000,     -0.52261, 68.06211,50.00000,20.00000,1.338668e-07,0.73923,4
350.54700, 58.20000,     -0.52467, 67.39206,50.00000,20.00000,1.341952e-07,0.73929,4
350.48401, 58.80000,     -0.52679, 66.73913,50.00000,20.00000,1.338464e-07,0.73935,4
350.42599, 59.40000,     -0.52831, 66.10552,50.00000,20.00000,1.338848e-07,0.73941,4
350.39200, 60.00000,     -0.53019, 65.48083,50.00000,20.00000,1.337848e-07,0.73944,4
350.34000, 60.60000,     -0.53164, 64.86428,50.00000,20.00000,1.337585e-07,0.73949,4
350.29599, 61.20000,     -0.53412, 64.27374,50.00000,20.00000,1.335166e-07,0.73953,4
350.27899, 61.80000,     -0.53695, 63.67800,50.00000,20.00000,1.333008e-07,0.73955,4
350.23999, 62.40000,     -0.53868, 63.10085,50.00000,20.00000,1.333943e-07,0.73958,4
350.23300, 63.00000,     -0.54017, 62.54524,50.00000,20.00000,1.333295e-07,0.73959,4
350.20001, 63.60000,     -0.54225, 61.99554,50.00000,20.00000,1.332587e-07,0.73962,4
350.17499, 64.20000,     -0.54392, 61.44590,50.00000,20.00000,1.329673e-07,0.73965,4
350.15799, 64.80000,     -0.54642, 60.91103,50.00000,20.00000,1.330221e-07,0.73966,4
350.14099, 65.40000,     -0.54830, 60.38588,50.00000,20.00000,1.328797e-07,0.73968,4
350.11401, 66.00000,     -0.54964, 59.87262,50.00000,20.00000,1.326204e-07,0.73970,4
350.11499, 66.60000,     -0.55106, 59.36231,50.00000,20.00000,1.327126e-07,0.73970,4
350.09698, 67.20000,     -0.55314, 58.86684,50.00000,20.00000,1.325525e-07,0.73972,4
350.08701, 67.80000,     -0.55415, 58.36993,50.00000,20.00000,1.324298e-07,0.73973,4
350.10199, 68.40000,     -0.55559, 57.88707,50.00000,20.00000,1.324674e-07,0.73972,4
350.07101, 69.00000,     -0.55827, 57.41983,50.00000,20.00000,1.323829e-07,0.73974,4
350.06500, 69.60000,     -0.55949, 56.95634,50.00000,20.00000,1.320690e-07,0.73975,4
350.06601, 70.20000,     -0.56057, 56.48536,50.00000,20.00000,1.318269e-07,0.73975,4
350.06799, 70.80000,     -0.56233, 56.02784,50.00000,20.00000,1.321159e-07,0.73975,4
350.04901, 71.40000,     -0.56286, 55.60440,50.00000,20.00000,1.318191e-07,0.73977,4
350.04700, 72.00000,     -0.56381, 55.14984,50.00000,20.00000,1.318706e-07,0.73977,4
350.15302, 72.60000,     -0.56592, 54.72640,50.00000,20.00000,1.317761e-07,0.73967,4
350.04401, 73.20000,     -0.56712, 54.29632,50.00000,20.00000,1.315149e-07,0.73977,4
350.04099, 73.80000,     -0.56766, 53.87735,50.00000,20.00000,1.311661e-07,0.73977,4
350.03400, 74.40000,     -0.56881, 53.45995,50.00000,20.00000,1.315052e-07,0.73978,4
350.01801, 75.00000,     -0.57069, 53.05062,50.00000,20.00000,1.312994e-07,0.73980,4
350.03299, 75.60000,     -0.57043, 52.64432,50.00000,20.00000,1.314112e-07,0.73978,4
350.03400, 76.20000,     -0.57084, 52.25804,50.00000,20.00000,1.312156e-07,0.73978,4
350.03101, 76.80000,     -0.57240, 51.86362,50.00000,20.00000,1.314396e-07,0.73978,4
350.04401, 77.40000,     -0.57457, 51.47065,50.00000,20.00000,1.310969e-07,0.73977,4
350.02600, 78.00000,     -0.57612, 51.09856,50.00000,20.00000,1.305454e-07,0.73979,4
350.02600, 78.60000,     -0.57646, 50.71372,50.00000,20.00000,1.308392e-07,0.73979,4
350.03000, 79.20000,     -0.57747, 50.34603,50.00000,20.00000,1.306156e-07,0.73978,4
350.03000, 79.80000,     -0.57842, 49.97019,50.00000,20.00000,1.308295e-07,0.73978,4
350.01901, 80.40000,     -0.57760, 49.61070,50.00000,20.00000,1.305878e-07,0.73979,4
350.02701, 81.00000,     -0.57781, 49.26303,50.00000,20.00000,1.305879e-07,0.73979,4
350.04199, 81.60000,     -0.57809, 48.89829,50.00000,20.00000,1.305319e-07,0.73977,4
350.04099, 82.20000,     -0.57972, 48.55141,50.00000,20.00000,1.305273e-07,0.73977,4
350.03601, 82.80000,     -0.58114, 48.20604,50.00000,20.00000,1.304610e-07,0.73978,4
350.02600, 83.40000,     -0.58201, 47.87026,50.00000,20.00000,1.300258e-07,0.73979,4
350.03101, 84.00000,     -0.58242, 47.52489,50.00000,20.00000,1.304305e-07,0.73978,4
350.03500, 84.60000,     -0.58344, 47.19357,50.00000,20.00000,1.303025e-07,0.73978,4
350.03000, 85.20000,     -0.58397, 46.86008,50.00000,20.00000,1.301498e-07,0.73978,4
350.03900, 85.80000,     -0.58466, 46.53618,50.00000,20.00000,1.300275e-07,0.73978,4
350.02600, 86.40000,     -0.58600, 46.20637,50.00000,20.00000,1.299927e-07,0.73979,4
350.02499, 87.00000,     -0.58621, 45.89291,50.00000,20.00000,1.297952e-07,0.73979,4
350.02701, 87.60000,     -0.58634, 45.57498,50.00000,20.00000,1.298852e-07,0.73979,4
350.02301, 88.20000,     -0.58729, 45.27708,50.00000,20.00000,1.296486e-07,0.73979,4
350.03201, 88.80000,     -0.58750, 44.96586,50.00000,20.00000,1.299674e-07,0.73978,4
350.03699, 89.40000,     -0.58777, 44.66284,50.00000,20.00000,1.297368e-07,0.73978,4
350.03201, 90.00000,     -0.58872, 44.35456,50.00000,20.00000,1.295178e-07,0.73978,4
350.02499, 90.60000,     -0.59007, 44.06710,50.00000,20.00000,1.297653e-07,0.73979,4
350.02899, 91.20000,     -0.58959, 43.76474,50.00000,20.00000,1.293723e-07,0.73978,4
350.03400, 91.80000,     -0.58994, 43.47728,50.00000,20.00000,1.297119e-07,0.73978,4
350.02802, 92.40000,     -0.59163, 43.18831,50.00000,20.00000,1.295541e-07,0.73979,4
350.02200, 93.00000,     -0.59108, 42.89941,50.00000,20.00000,1.295006e-07,0.73979,4
350.01599, 93.60000,     -0.58864, 42.62456,50.00000,20.00000,1.292859e-07,0.73980,4
350.03201, 94.20000,     -0.58885, 42.33933,50.00000,20.00000,1.292567e-07,0.73978,4
350.01700, 94.80000,     -0.58931, 42.07557,50.00000,20.00000,1.294448e-07,0.73980,4
350.01999, 95.40000,     -0.58945, 41.80302,50.00000,20.00000,1.293583e-07,0.73979,4
350.02802, 96.00000,     -0.58932, 41.52961,50.00000,20.00000,1.291147e-07,0.73979,4
350.03000, 96.60000,     -0.59095, 41.26967,50.00000,20.00000,1.291376e-07,0.73978,4
350.02600, 97.20000,     -0.59169, 40.99107,50.00000,20.00000,1.290896e-07,0.73979,4
350.02301, 97.80000,     -0.59223, 40.73185,50.00000,20.00000,1.290012e-07,0.73979,4
350.02701, 98.40000,     -0.59217, 40.47557,50.00000,20.00000,1.288476e-07,0.73979,4
350.03101, 99.00000,     -0.59258, 40.20821,50.00000,20.00000,1.291736e-07,0.73978,4
350.02899, 99.60000,     -0.59257, 39.95115,50.00000,20.00000,1.287519e-07,0.73978,4
350.02899,100.20000,     -0.59291, 39.71418,50.00000,20.00000,1.288677e-07,0.73978,4
350.03400,100.80000,     -0.59353, 39.45128,50.00000,20.00000,1.288100e-07,0.73978,4
350.02899,101.40000,     -0.59393, 39.20913,50.00000,20.00000,1.287386e-07,0.73978,4
350.03500,102.00000,     -0.59515, 38.96546,50.00000,20.00000,1.286725e-07,0.73978,4
350.03101,102.60000,     -0.59522, 38.71812,50.00000,20.00000,1.287071e-07,0.73978,4
350.03101,103.20000,     -0.59569, 38.47741,50.00000,20.00000,1.285971e-07,0.73978,4
350.03201,103.80000,     -0.59671, 38.24347,50.00000,20.00000,1.285048e-07,0.73978,4
350.03699,104.40000,     -0.59630, 37.99757,50.00000,20.00000,1.283672e-07,0.73978,4
350.03601,105.00000,     -0.59617, 37.76579,50.00000,20.00000,1.285446e-07,0.73978,4
350.03201,105.60000,     -0.59495, 37.52364,50.00000,20.00000,1.284581e-07,0.73978,4
350.04001,106.20000,     -0.59529, 37.30525,50.00000,20.00000,1.283744e-07,0.73977,4
350.04700,106.80000,     -0.59699, 37.08017,50.00000,20.00000,1.280992e-07,0.73977,4
350.02899,107.40000,     -0.59786, 36.84767,50.00000,20.00000,1.279137e-07,0.73978,4
350.03201,108.00000,     -0.59901, 36.63454,50.00000,20.00000,1.280081e-07,0.73978,4
350.03201,108.60000,     -0.59793, 36.41090,50.00000,20.00000,1.280324e-07,0.73978,4
350.04099,109.20000,     -0.59814, 36.18286,50.00000,20.00000,1.279897e-07,0.73977,4
350.03601,109.80000,     -0.59915, 35.96527,50.00000,20.00000,1.278462e-07,0.73978,4
350.03500,110.40000,     -0.59949, 35.75128,50.00000,20.00000,1.276156e-07,0.73978,4
350.03601,111.00000,     -0.59989, 35.52699,50.00000,20.00000,1.278066e-07,0.73978,4
350.04001,111.60000,     -0.59969, 35.33533,50.00000,20.00000,1.278301e-07,0.73977,4
350.03299,112.20000,     -0.60057, 35.11773,50.00000,20.00000,1.276829e-07,0.73978,4
350.03900,112.80000,     -0.60098, 34.91563,50.00000,20.00000,1.275679e-07,0.73978,4
350.03400,113.40000,     -0.60253, 34.70098,50.00000,20.00000,1.273971e-07,0.73978,4
350.03400,114.00000,     -0.60199, 34.50341,50.00000,20.00000,1.276663e-07,0.73978,4
350.02600,114.60000,     -0.60198, 34.29468,50.00000,20.00000,1.276064e-07,0.73979,4
350.03601,115.20000,     -0.60240, 34.10079,50.00000,20.00000,1.274431e-07,0.73978,4
350.03101,115.80000,     -0.60253, 33.90617,50.00000,20.00000,1.273400e-07,0.73978,4
350.03601,116.40000,     -0.60355, 33.70118,50.00000,20.00000,1.273982e-07,0.73978,4
350.03400,117.00000,     -0.60422, 33.51024,50.00000,20.00000,1.273923e-07,0.73978,4
350.02802,117.60000,     -0.60469, 33.30972,50.00000,20.00000,1.271310e-07,0.73979,4
350.02899,118.20000,     -0.60381, 33.11878,50.00000,20.00000,1.270033e-07,0.73978,4
350.03799,118.80000,     -0.60409, 32.93158,50.00000,20.00000,1.270976e-07,0.73978,4
350.03101,119.40000,     -0.60402, 32.73999,50.00000,20.00000,1.270528e-07,0.73978,4
350.02600,120.00000,     -0.60490, 32.55726,50.00000,20.00000,1.266814e-07,0.73979,4
350.03101,120.60000,     -0.60348, 32.37374,50.00000,20.00000,1.269753e-07,0.73978,4
350.02399,121.20000,     -0.60401, 32.18877,50.00000,20.00000,1.268075e-07,0.73979,4
350.02899,121.80000,     -0.60463, 32.00532,50.00000,20.00000,1.267552e-07,0.73978,4
350.02200,122.40000,     -0.60449, 31.81293,50.00000,20.00000,1.266132e-07,0.73979,4
350.02899,123.00000,     -0.60510, 31.63388,50.00000,20.00000,1.265965e-07,0.73978,4
350.03601,123.60000,     -0.60443, 31.46678,50.00000,20.00000,1.264707e-07,0.73978,4
350.03000,124.20000,     -0.60544, 31.29002,50.00000,20.00000,1.265255e-07,0.73978,4
350.03101,124.80000,     -0.60639, 31.11615,50.00000,20.00000,1.264083e-07,0.73978,4
350.03201,125.40000,     -0.60619, 30.94531,50.00000,20.00000,1.262957e-07,0.73978,4
350.02701,126.00000,     -0.60524, 30.76999,50.00000,20.00000,1.264065e-07,0.73979,4
350.03299,126.60000,     -0.60558, 30.60217,50.00000,20.00000,1.263296e-07,0.73978,4
350.02899,127.20000,     -0.60679, 30.43578,50.00000,20.00000,1.261440e-07,0.73978,4
350.03400,127.80000,     -0.60741, 30.26940,50.00000,20.00000,1.263161e-07,0.73978,4
350.02499,128.40000,     -0.60740, 30.10151,50.00000,20.00000,1.259189e-07,0.73979,4
350.03101,129.00000,     -0.60727, 29.92843,50.00000,20.00000,1.258891e-07,0.73978,4
350.02899,129.60000,     -0.60646, 29.75758,50.00000,20.00000,1.260888e-07,0.73978,4
350.03699,130.20000,     -0.60707, 29.61195,50.00000,20.00000,1.259676e-07,0.73978,4
350.03201,130.80000,     -0.60849, 29.44708,50.00000,20.00000,1.257964e-07,0.73978,4
350.02600,131.40000,     -0.60835, 29.28963,50.00000,20.00000,1.259025e-07,0.73979,4
350.01901,132.00000,     -0.60807, 29.13362,50.00000,20.00000,1.259408e-07,0.73979,4
350.03101,132.60000,     -0.60747, 28.97170,50.00000,20.00000,1.257482e-07,0.73978,4
350.03101,133.20000,     -0.60768, 28.81865,50.00000,20.00000,1.258108e-07,0.73978,4
350.02802,133.80000,     -0.60794, 28.66487,50.00000,20.00000,1.259743e-07,0.73979,4
350.03699,134.40000,     -0.60734, 28.51037,50.00000,20.00000,1.257014e-07,0.73978,4
350.04300,135.00000,     -0.60728, 28.35515,50.00000,20.00000,1.256309e-07,0.73977,4
350.02600,135.60000,     -0.60794, 28.21103,50.00000,20.00000,1.257501e-07,0.73979,4
350.04401,136.20000,     -0.60830, 28.05877,50.00000,20.00000,1.256119e-07,0.73977,4
350.03101,136.80000,     -0.60862, 27.90946,50.00000,20.00000,1.254974e-07,0.73978,4
350.03400,137.40000,     -0.60944, 27.76756,50.00000,20.00000,1.253951e-07,0.73978,4
350.02802,138.00000,     -0.60896, 27.61681,50.00000,20.00000,1.257094e-07,0.73979,4
350.02600,138.60000,     -0.60855, 27.48306,50.00000,20.00000,1.255925e-07,0.73979,4
350.02899,139.20000,     -0.60896, 27.32633,50.00000,20.00000,1.253679e-07,0.73978,4
350.03000,139.80000,     -0.60903, 27.19114,50.00000,20.00000,1.254082e-07,0.73978,4
350.03400,140.40000,     -0.60842, 27.05299,50.00000,20.00000,1.251693e-07,0.73978,4
350.02899,141.00000,     -0.60815, 26.90814,50.00000,20.00000,1.252203e-07,0.73978,4
350.03299,141.60000,     -0.60869, 26.77072,50.00000,20.00000,1.252203e-07,0.73978,4
350.01999,142.20000,     -0.60929, 26.63106,50.00000,20.00000,1.251922e-07,0.73979,4
350.02802,142.80000,     -0.60903, 26.50558,50.00000,20.00000,1.253488e-07,0.73979,4
350.02701,143.40000,     -0.60808, 26.36815,50.00000,20.00000,1.251545e-07,0.73979,4
350.02399,144.00000,     -0.60638, 26.23145,50.00000,20.00000,1.249948e-07,0.73979,4
350.02899,144.60000,     -0.60151, 26.09554,50.00000,20.00000,1.251528e-07,0.73978,4
350.02899,145.20000,     -0.60524, 25.96257,50.00000,20.00000,1.252526e-07,0.73978,4
350.02399,145.80000,     -0.60577, 25.83257,50.00000,20.00000,1.251784e-07,0.73979,4
350.02899,146.40000,     -0.60530, 25.70630,50.00000,20.00000,1.249985e-07,0.73978,4
350.03101,147.00000,     -0.60504, 25.56218,50.00000,20.00000,1.249919e-07,0.73978,4
350.03101,147.60000,     -0.60497, 25.44557,50.00000,20.00000,1.249811e-07,0.73978,4
350.02301,148.20000,     -0.60516, 25.31333,50.00000,20.00000,1.248640e-07,0.73979,4
350.02701,148.80000,     -0.60503, 25.19599,50.00000,20.00000,1.249915e-07,0.73979,4
350.02399,149.40000,     -0.60422, 25.06080,50.00000,20.00000,1.249463e-07,0.73979,4
350.02701,150.00000,     -0.60415, 24.94045,50.00000,20.00000,1.250429e-07,0.73979,4
350.02100,150.60000,     -0.60449, 24.81563,50.00000,20.00000,1.247412e-07,0.73979,4
350.01801,151.20000,     -0.60293, 24.68864,50.00000,20.00000,1.249991e-07,0.73980,4
350.03101,151.80000,     -0.60178, 24.56310,50.00000,20.00000,1.249246e-07,0.73978,4
350.04199,152.40000,     -0.60220, 24.45016,50.00000,20.00000,1.247141e-07,0.73977,4
350.03900,153.00000,     -0.60240, 24.32764,50.00000,20.00000,1.246403e-07,0.73978,4
350.03500,153.60000,     -0.60253, 24.20282,50.00000,20.00000,1.248447e-07,0.73978,4
350.04401,154.20000,     -0.60193, 24.08772,50.00000,20.00000,1.246260e-07,0.73977,4
350.03699,154.80000,     -0.60165, 23.97479,50.00000,20.00000,1.247695e-07,0.73978,4
350.03799,155.40000,     -0.60213, 23.85003,50.00000,20.00000,1.248474e-07,0.73978,4
350.03400,156.00000,     -0.60165, 23.74603,50.00000,20.00000,1.246975e-07,0.73978,4
350.03500,156.60000,     -0.59833, 23.61898,50.00000,20.00000,1.246917e-07,0.73978,4
350.03799,157.20000,     -0.59583, 23.50460,50.00000,20.00000,1.249280e-07,0.73978,4
350.03101,157.80000,     -0.59718, 23.39540,50.00000,20.00000,1.244002e-07,0.73978,4
350.03299,158.40000,     -0.59752, 23.28175,50.00000,20.00000,1.245352e-07,0.73978,4
350.03900,159.00000,     -0.59719, 23.17183,50.00000,20.00000,1.246050e-07,0.73978,4
350.02600,159.60000,     -0.59724, 23.07301,50.00000,20.00000,1.245162e-07,0.73979,4
350.03500,160.20000,     -0.59718, 22.95266,50.00000,20.00000,1.244121e-07,0.73978,4
350.02802,160.80000,     -0.59677, 22.83684,50.00000,20.00000,1.245193e-07,0.73979,4
350.03101,161.40000,     -0.59671, 22.73283,50.00000,20.00000,1.243309e-07,0.73978,4
350.03400,162.00000,     -0.59678, 22.62285,50.00000,20.00000,1.245167e-07,0.73978,4
350.02399,162.60000,     -0.59582, 22.51221,50.00000,20.00000,1.246260e-07,0.73979,4
350.03299,163.20000,     -0.59535, 22.40223,50.00000,20.00000,1.247133e-07,0.73978,4
350.03101,163.80000,     -0.59501, 22.29606,50.00000,20.00000,1.244056e-07,0.73978,4
350.02399,164.40000,     -0.59480, 22.19875,50.00000,20.00000,1.245823e-07,0.73979,4
350.03601,165.00000,     -0.59508, 22.08877,50.00000,20.00000,1.243625e-07,0.73978,4
350.01599,165.60000,     -0.59460, 21.98628,50.00000,20.00000,1.242816e-07,0.73980,4
350.02701,166.20000,     -0.59393, 21.88378,50.00000,20.00000,1.244551e-07,0.73979,4
350.03799,166.80000,     -0.59394, 21.79238,50.00000,20.00000,1.244899e-07,0.73978,4
350.03400,167.40000,     -0.59292, 21.68766,50.00000,20.00000,1.243017e-07,0.73978,4
350.03500,168.00000,     -0.59305, 21.58221,50.00000,20.00000,1.242460e-07,0.73978,4
350.04300,168.60000,     -0.59340, 21.48267,50.00000,20.00000,1.242996e-07,0.73977,4
350.03900,169.20000,     -0.59400, 21.38464,50.00000,20.00000,1.241861e-07,0.73978,4
350.03201,169.80000,     -0.59420, 21.28286,50.00000,20.00000,1.241463e-07,0.73978,4
350.02701,170.40000,     -0.59325, 21.17886,50.00000,20.00000,1.242561e-07,0.73979,4
350.03500,171.00000,     -0.59244, 21.08825,50.00000,20.00000,1.243061e-07,0.73978,4
350.03900,171.60000,     -0.59204, 20.98720,50.00000,20.00000,1.241536e-07,0.73978,4
350.04300,172.20000,     -0.59231, 20.89435,50.00000,20.00000,1.241403e-07,0.73977,4
350.03201,172.80000,     -0.59203, 20.80079,50.00000,20.00000,1.240941e-07,0.73978,4
350.02899,173.40000,     -0.59102, 20.69902,50.00000,20.00000,1.239806e-07,0.73978,4
350.03601,174.00000,     -0.59095, 20.60020,50.00000,20.00000,1.240530e-07,0.73978,4
350.04099,174.60000,     -0.59103, 20.51031,50.00000,20.00000,1.242868e-07,0.73977,4
350.04401,175.20000,     -0.57491, 20.41747,50.00000,20.00000,1.235825e-07,0.73977,4
350.04300,175.80000,     -0.58249, 20.32685,50.00000,20.00000,1.242515e-07,0.73977,4
350.03500,176.40000,     -0.58350, 20.23992,50.00000,20.00000,1.241477e-07,0.73978,4
350.02701,177.00000,     -0.58269, 20.14340,50.00000,20.00000,1.235917e-07,0.73979,4
350.03000,177.60000,     -0.58194, 20.05049,50.00000,20.00000,1.244189e-07,0.73978,4
350.03201,178.20000,     -0.58161, 19.96139,50.00000,20.00000,1.241351e-07,0.73978,4
350.02100,178.80000,     -0.58126, 19.87965,50.00000,20.00000,1.242134e-07,0.73979,4
350.01901,179.40000,     -0.57984, 19.79501,50.00000,20.00000,1.236340e-07,0.73979,4
350.01801,180.00000,     -0.57970, 19.70361,50.00000,20.00000,1.238357e-07,0.73980,4
350.02899,180.60000,     -0.58011, 19.61149,50.00000,20.00000,1.242334e-07,0.73978,4
350.03101,181.20000,     -0.57910, 19.52830,50.00000,20.00000,1.235410e-07,0.73978,4
350.01901,181.80000,     -0.57902, 19.43624,50.00000,20.00000,1.239981e-07,0.73979,4
350.02499,182.40000,     -0.57916, 19.35227,50.00000,20.00000,1.235289e-07,0.73979,4
350.02899,183.00000,     -0.57808, 19.27131,50.00000,20.00000,1.237513e-07,0.73978,4
350.03400,183.60000,     -0.57754, 19.18588,50.00000,20.00000,1.240024e-07,0.73978,4
350.03900,184.20000,     -0.57809, 19.10269,50.00000,20.00000,1.237070e-07,0.73978,4
350.03900,184.80000,     -0.57735, 19.01950,50.00000,20.00000,1.238705e-07,0.73978,4
350.03299,185.40000,     -0.57775, 18.93703,50.00000,20.00000,1.236299e-07,0.73978,4
350.02600,186.00000,     -0.57767, 18.85680,50.00000,20.00000,1.235782e-07,0.73979,4
350.01999,186.60000,     -0.57679, 18.77065,50.00000,20.00000,1.237468e-07,0.73979,4
350.02499,187.20000,     -0.57530, 18.69567,50.00000,20.00000,1.235796e-07,0.73979,4
350.03201,187.80000,     -0.57463, 18.61687,50.00000,20.00000,1.236159e-07,0.73978,4
350.03299,188.40000,     -0.57511, 18.53519,50.00000,20.00000,1.235136e-07,0.73978,4
350.02899,189.00000,     -0.57531, 18.44977,50.00000,20.00000,1.234603e-07,0.73978,4
350.03900,189.60000,     -0.57416, 18.37997,50.00000,20.00000,1.234008e-07,0.73978,4
350.03699,190.20000,     -0.57423, 18.29895,50.00000,20.00000,1.235424e-07,0.73978,4
350.02600,190.80000,     -0.57422, 18.22397,50.00000,20.00000,1.236900e-07,0.73979,4
350.03799,191.40000,     -0.57274, 18.14301,50.00000,20.00000,1.234650e-07,0.73978,4
350.03400,192.00000,     -0.57409, 18.07019,50.00000,20.00000,1.233966e-07,0.73978,4
350.04099,192.60000,     -0.57335, 17.99737,50.00000,20.00000,1.235607e-07,0.73977,4
350.02701,193.20000,     -0.57280, 17.92462,50.00000,20.00000,1.233971e-07,0.73979,4
350.02899,193.80000,     -0.57402, 17.83178,50.00000,20.00000,1.234078e-07,0.73978,4
350.03900,194.40000,     -0.57349, 17.77085,50.00000,20.00000,1.235292e-07,0.73978,4
350.02100,195.00000,     -0.57435, 17.69508,50.00000,20.00000,1.235067e-07,0.73979,4
350.02200,195.60000,     -0.57280, 17.62305,50.00000,20.00000,1.234633e-07,0.73979,4
350.03201,196.20000,     -0.57301, 17.55095,50.00000,20.00000,1.234078e-07,0.73978,4
350.03500,196.80000,     -0.57213, 17.47965,50.00000,20.00000,1.234093e-07,0.73978,4
350.03601,197.40000,     -0.57193, 17.40683,50.00000,20.00000,1.234920e-07,0.73978,4
350.03299,198.00000,     -0.57172, 17.32443,50.00000,20.00000,1.232958e-07,0.73978,4
350.02899,198.60000,     -0.57199, 17.26054,50.00000,20.00000,1.232881e-07,0.73978,4
350.02899,199.20000,     -0.57253, 17.18923,50.00000,20.00000,1.234355e-07,0.73978,4
350.08200,199.80000,     -0.57054, 17.11641,50.00000,20.00000,1.234617e-07,0.73973,4
350.04800,200.40000,     -0.57139, 17.05181,50.00000,20.00000,1.233088e-07,0.73977,4
350.03699,201.00000,     -0.57287, 16.97978,50.00000,20.00000,1.233089e-07,0.73978,4
350.03799,201.60000,     -0.57132, 16.90840,50.00000,20.00000,1.234890e-07,0.73978,4
350.04700,202.20000,     -0.57119, 16.84531,50.00000,20.00000,1.231423e-07,0.73977,4
350.04199,202.80000,     -0.56997, 16.77249,50.00000,20.00000,1.231623e-07,0.73977,4
350.03699,203.40000,     -0.57057, 16.70716,50.00000,20.00000,1.232876e-07,0.73978,4
350.03601,204.00000,     -0.57159, 16.64399,50.00000,20.00000,1.231323e-07,0.73978,4
350.03101,204.60000,     -0.56989, 16.57269,50.00000,20.00000,1.231383e-07,0.73978,4
350.02600,205.20000,     -0.57009, 16.50952,50.00000,20.00000,1.232200e-07,0.73979,4
350.02802,205.80000,     -0.56955, 16.43749,50.00000,20.00000,1.230276e-07,0.73979,4
350.03101,206.40000,     -0.56772, 16.36467,50.00000,20.00000,1.232486e-07,0.73978,4
350.01901,207.00000,     -0.56792, 16.31123,50.00000,20.00000,1.231057e-07,0.73979,4
350.02499,207.60000,     -0.56901, 16.23546,50.00000,20.00000,1.230391e-07,0.73979,4
350.02899,208.20000,     -0.56921, 16.18194,50.00000,20.00000,1.229288e-07,0.73978,4
350.03699,208.80000,     -0.56692, 16.11064,50.00000,20.00000,1.231602e-07,0.73978,4
350.03500,209.40000,     -0.56766, 16.04675,50.00000,20.00000,1.233204e-07,0.73978,4
350.03900,210.00000,     -0.56861, 15.97544,50.00000,20.00000,1.231099e-07,0.73978,4
350.03000,210.60000,     -0.56759, 15.92567,50.00000,20.00000,1.229848e-07,0.73978,4
350.03500,211.20000,     -0.56563, 15.85292,50.00000,20.00000,1.229428e-07,0.73978,4
350.03400,211.80000,     -0.56583, 15.78976,50.00000,20.00000,1.229959e-07,0.73978,4
350.04199,212.40000,     -0.56699, 15.73631,50.00000,20.00000,1.231217e-07,0.73977,4
350.02899,213.00000,     -0.56671, 15.66494,50.00000,20.00000,1.227715e-07,0.73978,4
350.03500,213.60000,     -0.56691, 15.60184,50.00000,20.00000,1.229121e-07,0.73978,4
350.03699,214.20000,     -0.56543, 15.54833,50.00000,20.00000,1.230482e-07,0.73978,4
350.02499,214.80000,     -0.56508, 15.48523,50.00000,20.00000,1.229361e-07,0.73979,4
350.02100,215.40000,     -0.56440, 15.43171,50.00000,20.00000,1.229698e-07,0.73979,4
350.02399,216.00000,     -0.56487, 15.35968,50.00000,20.00000,1.228039e-07,0.73979,4
350.02399,216.60000,     -0.56487, 15.30545,50.00000,20.00000,1.226334e-07,0.73979,4
350.02600,217.20000,     -0.56318, 15.25121,50.00000,20.00000,1.228887e-07,0.73979,4
350.02600,217.80000,     -0.56352, 15.18884,50.00000,20.00000,1.229344e-07,0.73979,4
350.02701,218.40000,     -0.56427, 15.12567,50.00000,20.00000,1.228228e-07,0.73979,4
350.04001,219.00000,     -0.56434, 15.07144,50.00000,20.00000,1.229730e-07,0.73977,4
350.01999,219.60000,     -0.56480, 15.02692,50.00000,20.00000,1.228600e-07,0.73979,4
350.02899,220.20000,     -0.56380, 14.96376,50.00000,20.00000,1.225610e-07,0.73978,4
350.03400,220.80000,     -0.56197, 14.90059,50.00000,20.00000,1.229053e-07,0.73978,4
350.01999,221.40000,     -0.56250, 14.84714,50.00000,20.00000,1.228684e-07,0.73979,4
350.02399,222.00000,     -0.56210, 14.79291,50.00000,20.00000,1.229548e-07,0.73979,4
350.02301,222.60000,     -0.56305, 14.72902,50.00000,20.00000,1.228889e-07,0.73979,4
350.03000,223.20000,     -0.56285, 14.68372,50.00000,20.00000,1.228139e-07,0.73978,4
350.03000,223.80000,     -0.56170, 14.62055,50.00000,20.00000,1.227078e-07,0.73978,4
350.03101,224.40000,     -0.56305, 14.56638,50.00000,20.00000,1.228009e-07,0.73978,4
350.03299,225.00000,     -0.56183, 14.51287,50.00000,20.00000,1.227529e-07,0.73978,4
350.01999,225.60000,     -0.56196, 14.45791,50.00000,20.00000,1.228448e-07,0.73979,4
350.02701,226.20000,     -0.56163, 14.39330,50.00000,20.00000,1.226518e-07,0.73979,4
350.03101,226.80000,     -0.56143, 14.33086,50.00000,20.00000,1.224639e-07,0.73978,4
350.02600,227.40000,     -0.56325, 14.29521,50.00000,20.00000,1.225708e-07,0.73979,4
350.03799,228.00000,     -0.56326, 14.23578,50.00000,20.00000,1.226659e-07,0.73978,4
350.02600,228.60000,     -0.56203, 14.18457,50.00000,20.00000,1.225899e-07,0.73979,4
350.01801,229.20000,     -0.55986, 14.12955,50.00000,20.00000,1.222956e-07,0.73980,4
350.03000,229.80000,     -0.55939, 14.07538,50.00000,20.00000,1.224945e-07,0.73978,4
350.02600,230.40000,     -0.56163, 14.02482,50.00000,20.00000,1.225290e-07,0.73979,4
350.03400,231.00000,     -0.56197, 13.97584,50.00000,20.00000,1.227697e-07,0.73978,4
350.03400,231.60000,     -0.56163, 13.92232,50.00000,20.00000,1.225918e-07,0.73978,4
350.03400,232.20000,     -0.56312, 13.87551,50.00000,20.00000,1.223243e-07,0.73978,4
350.04099,232.80000,     -0.55981, 13.81241,50.00000,20.00000,1.224626e-07,0.73977,4
350.03699,233.40000,     -0.55872, 13.76336,50.00000,20.00000,1.225145e-07,0.73978,4
350.04599,234.00000,     -0.55961, 13.72252,50.00000,20.00000,1.224874e-07,0.73977,4
350.04599,234.60000,     -0.55988, 13.67794,50.00000,20.00000,1.223155e-07,0.73977,4
350.04199,235.20000,     -0.56150, 13.62226,50.00000,20.00000,1.224089e-07,0.73977,4
350.03900,235.80000,     -0.56069, 13.56802,50.00000,20.00000,1.224164e-07,0.73978,4
350.04199,236.40000,     -0.56130, 13.52049,50.00000,20.00000,1.224180e-07,0.73977,4
350.03799,237.00000,     -0.56055, 13.46921,50.00000,20.00000,1.222846e-07,0.73978,4
350.02701,237.60000,     -0.55973, 13.41576,50.00000,20.00000,1.224613e-07,0.73979,4
350.02802,238.20000,     -0.55905, 13.37118,50.00000,20.00000,1.223172e-07,0.73979,4
350.03900,238.80000,     -0.55872, 13.31917,50.00000,20.00000,1.224417e-07,0.73978,4
350.04300,239.40000,     -0.56015, 13.26494,50.00000,20.00000,1.222898e-07,0.73977,4
350.03299,240.00000,     -0.56048, 13.22928,50.00000,20.00000,1.223985e-07,0.73978,4
350.03101,240.60000,     -0.56149, 13.17282,50.00000,20.00000,1.226051e-07,0.73978,4
350.03799,241.20000,     -0.55554, 13.12830,50.00000,20.00000,1.221242e-07,0.73978,4
350.03299,241.80000,     -0.55716, 13.08076,50.00000,20.00000,1.222664e-07,0.73978,4
350.01901,242.40000,     -0.55559, 13.02725,50.00000,20.00000,1.221802e-07,0.73979,4
350.02301,243.00000,     -0.55580, 12.98267,50.00000,20.00000,1.221485e-07,0.73979,4
350.03500,243.60000,     -0.55682, 12.93808,50.00000,20.00000,1.222241e-07,0.73978,4
350.02899,244.20000,     -0.55682, 12.89133,50.00000,20.00000,1.221235e-07,0.73978,4
350.02802,244.80000,     -0.55709, 12.84524,50.00000,20.00000,1.222866e-07,0.73979,4
350.03699,245.40000,     -0.55351, 12.80072,50.00000,20.00000,1.221463e-07,0.73978,4
350.02899,246.00000,     -0.55540, 12.75167,50.00000,20.00000,1.219381e-07,0.73978,4
350.03201,246.60000,     -0.55425, 12.70709,50.00000,20.00000,1.220696e-07,0.73978,4
350.02600,247.20000,     -0.55573, 12.66697,50.00000,20.00000,1.222910e-07,0.73979,4
350.02301,247.80000,     -0.55485, 12.62239,50.00000,20.00000,1.222259e-07,0.73979,4
350.02600,248.40000,     -0.55567, 12.57932,50.00000,20.00000,1.220638e-07,0.73979,4
350.03000,249.00000,     -0.55181, 12.53920,50.00000,20.00000,1.221004e-07,0.73978,4
350.02701,249.60000,     -0.55269, 12.49317,50.00000,20.00000,1.219730e-07,0.73979,4
350.03299,250.20000,     -0.55439, 12.43821,50.00000,20.00000,1.221949e-07,0.73978,4
350.02899,250.80000,     -0.55526, 12.40256,50.00000,20.00000,1.217142e-07,0.73978,4
350.01599,251.40000,     -0.55444, 12.35726,50.00000,20.00000,1.221522e-07,0.73980,4
350.01700,252.00000,     -0.55343, 12.31267,50.00000,20.00000,1.221033e-07,0.73980,4
350.02899,252.60000,     -0.54815, 12.27630,50.00000,20.00000,1.220098e-07,0.73978,4
350.02600,253.20000,     -0.55235, 12.23171,50.00000,20.00000,1.220348e-07,0.73979,4
350.02200,253.80000,     -0.55248, 12.17676,50.00000,20.00000,1.221263e-07,0.73979,4
350.02200,254.40000,     -0.55302, 12.14924,50.00000,20.00000,1.220628e-07,0.73979,4
350.02100,255.00000,     -0.55268, 12.09429,50.00000,20.00000,1.221041e-07,0.73979,4
350.01501,255.60000,     -0.55173, 12.05791,50.00000,20.00000,1.219009e-07,0.73980,4
350.03299,256.20000,     -0.55161, 12.02219,50.00000,20.00000,1.221934e-07,0.73978,4
350.01999,256.80000,     -0.55025, 11.97768,50.00000,20.00000,1.221245e-07,0.73979,4
350.03799,257.40000,     -0.55148, 11.93979,50.00000,20.00000,1.222481e-07,0.73978,4
350.02899,258.00000,     -0.54761, 11.89521,50.00000,20.00000,1.222107e-07,0.73978,4
350.03500,258.60000,     -0.54870, 11.85883,50.00000,20.00000,1.221669e-07,0.73978,4
350.02899,259.20000,     -0.55025, 11.81425,50.00000,20.00000,1.219145e-07,0.73978,4
350.03299,259.80000,     -0.55357, 11.76894,50.00000,20.00000,1.221605e-07,0.73978,4
350.02600,260.40000,     -0.54842, 11.73329,50.00000,20.00000,1.217249e-07,0.73979,4
350.02899,261.00000,     -0.54720, 11.68647,50.00000,20.00000,1.218676e-07,0.73978,4
350.03799,261.60000,     -0.54735, 11.65010,50.00000,20.00000,1.220640e-07,0.73978,4
350.03299,262.20000,     -0.55032, 11.61366,50.00000,20.00000,1.215051e-07,0.73978,4
350.03101,262.80000,     -0.54849, 11.57058,50.00000,20.00000,1.218285e-07,0.73978,4
350.03400,263.40000,     -0.54938, 11.53421,50.00000,20.00000,1.220343e-07,0.73978,4
350.04099,264.00000,     -0.54999, 11.49186,50.00000,20.00000,1.218664e-07,0.73977,4
350.03799,264.60000,     -0.55100, 11.44951,50.00000,20.00000,1.218279e-07,0.73978,4
350.03699,265.20000,     -0.54735, 11.40420,50.00000,20.00000,1.217153e-07,0.73978,4
350.04199,265.80000,     -0.54972, 11.37078,50.00000,20.00000,1.217016e-07,0.73977,4
350.03699,266.40000,     -0.55066, 11.34183,50.00000,20.00000,1.215217e-07,0.73978,4
350.03500,267.00000,     -0.55005, 11.29724,50.00000,20.00000,1.220090e-07,0.73978,4
350.04700,267.60000,     -0.54911, 11.26159,50.00000,20.00000,1.217408e-07,0.73977,4
350.03101,268.20000,     -0.54836, 11.22594,50.00000,20.00000,1.216640e-07,0.73978,4
350.02301,268.80000,     -0.54835, 11.18956,50.00000,20.00000,1.215480e-07,0.73979,4
350.04099,269.40000,     -0.54809, 11.14498,50.00000,20.00000,1.217136e-07,0.73977,4
350.03101,270.00000,     -0.54707, 11.11379,50.00000,20.00000,1.214650e-07,0.73978,4
350.04099,270.60000,     -0.54539, 11.08109,50.00000,20.00000,1.216165e-07,0.73977,4
350.03400,271.20000,     -0.54538, 11.03651,50.00000,20.00000,1.218944e-07,0.73978,4
350.03900,271.80000,     -0.54647, 11.00236,50.00000,20.00000,1.215163e-07,0.73978,4
350.04099,272.40000,     -0.54735, 10.97190,50.00000,20.00000,1.213939e-07,0.73977,4
350.04001,273.00000,     -0.54823, 10.93473,50.00000,20.00000,1.215580e-07,0.73977,4
350.03500,273.60000,     -0.54660, 10.89015,50.00000,20.00000,1.217743e-07,0.73978,4
350.03699,274.20000,     -0.54572, 10.86343,50.00000,20.00000,1.214581e-07,0.73978,4
350.02802,274.80000,     -0.54544, 10.82777,50.00000,20.00000,1.215751e-07,0.73979,4
350.02802,275.40000,     -0.54585, 10.79068,50.00000,20.00000,1.213859e-07,0.73979,4
350.02499,276.00000,     -0.54747, 10.75502,50.00000,20.00000,1.214681e-07,0.73979,4
350.02399,276.60000,     -0.54625, 10.72823,50.00000,20.00000,1.215703e-07,0.73979,4
350.03101,277.20000,     -0.54585, 10.67479,50.00000,20.00000,1.215311e-07,0.73978,4
350.02499,277.80000,     -0.54652, 10.64800,50.00000,20.00000,1.216333e-07,0.73979,4
350.02499,278.40000,     -0.54605, 10.62055,50.00000,20.00000,1.213609e-07,0.73979,4
350.03799,279.00000,     -0.54545, 10.58339,50.00000,20.00000,1.215197e-07,0.73978,4
350.03101,279.60000,     -0.54646, 10.54773,50.00000,20.00000,1.215771e-07,0.73978,4
350.04099,280.20000,     -0.54478, 10.50315,50.00000,20.00000,1.216044e-07,0.73977,4
350.03699,280.80000,     -0.54484, 10.47643,50.00000,20.00000,1.212692e-07,0.73978,4
350.03799,281.40000,     -0.54728, 10.44077,50.00000,20.00000,1.217796e-07,0.73978,4
350.02802,282.00000,     -0.54592, 10.40512,50.00000,20.00000,1.213188e-07,0.73979,4
350.02701,282.60000,     -0.54768, 10.36947,50.00000,20.00000,1.215056e-07,0.73979,4
350.13996,283.20000,     -0.50987, 10.34279,50.00000,20.00000,1.215021e-07,0.73968,5
353.25078,283.80000,      0.15136, 10.43830,50.00000,20.00000,1.214710e-07,0.73671,5
358.95068,284.40000,      0.59593, 10.51485,50.00000,20.00000,1.213486e-07,0.73127,5
364.17343,285.00000,      0.53810, 10.49624,50.00000,20.00000,1.211668e-07,0.72630,5
369.20173,285.60000,      0.51500, 10.45916,50.00000,20.00000,1.213444e-07,0.72152,5
374.89972,286.20000,      0.63837, 10.41266,50.00000,20.00000,1.213416e-07,0.71612,5
381.05878,286.80000,      0.72347, 10.31832,50.00000,20.00000,1.213261e-07,0.71030,5
387.27956,287.40000,      0.73459, 10.12843,50.00000,20.00000,1.213770e-07,0.70444,5
393.52057,288.00000,      0.73700,  9.85536,50.00000,20.00000,1.213342e-07,0.69860,5
399.83417,288.60000,      0.74951,  9.45191,50.00000,20.00000,1.213902e-07,0.69272,5
406.17322,289.20000,      0.75116,  8.87350,50.00000,20.00000,1.211920e-07,0.68685,5
412.48702,289.80000,      0.73550,  8.10409,50.00000,20.00000,1.214240e-07,0.68105,5
418.78971,290.40000,      0.69732,  7.15060,50.00000,20.00000,1.214913e-07,0.67531,5
425.04506,291.00000,      0.61912,  6.07528,50.00000,20.00000,1.216741e-07,0.66965,5
431.27279,291.60000,      0.51962,  4.99864,50.00000,20.00000,1.216508e-07,0.66407,5
437.49468,292.20000,      0.38385,  4.02677,50.00000,20.00000,1.219634e-07,0.65855,5
443.69163,292.80000,      0.24195,  3.27398,50.00000,20.00000,1.219858e-07,0.65310,5
449.85783,293.40000, 8.397410e-02,  2.73255,50.00000,20.00000,1.223379e-07,0.64774,5
456.00127,294.00000,-1.901702e-02,  2.36813,50.00000,20.00000,1.222474e-07,0.64245,5
462.13283,294.60000,     -0.10451,  2.09581,50.00000,20.00000,1.224380e-07,0.63723,5
468.22000,295.20000,     -0.19519,  1.90553,50.00000,20.00000,1.227915e-07,0.63212,5
474.30305,295.80000,     -0.28566,  1.81649,50.00000,20.00000,1.228096e-07,0.62707,5
480.37021,296.40000,     -0.36820,  1.78771,50.00000,20.00000,1.232870e-07,0.62210,5
486.42568,297.00000,     -0.43961,  1.79712,50.00000,20.00000,1.233078e-07,0.61720,5
492.46749,297.60000,     -0.50595,  1.83324,50.00000,20.00000,1.236042e-07,0.61237,5
498.50446,298.20000,     -0.57385,  1.86324,50.00000,20.00000,1.236010e-07,0.60762,5
504.52043,298.80000,     -0.64268,  1.87889,50.00000,20.00000,1.236707e-07,0.60296,5
510.54219,299.40000,     -0.71148,  1.91434,50.00000,20.00000,1.235213e-07,0.59835,5
516.54985,300.00000,     -0.78175,  1.93866,50.00000,20.00000,1.236922e-07,0.59383,5
522.56828,300.60000,     -0.85436,  1.96568,50.00000,20.00000,1.238165e-07,0.58937,5
528.57558,301.20000,     -0.92712,  1.99224,50.00000,20.00000,1.224356e-07,0.58498,5
534.59232,301.80000,     -0.99969,  2.01339,50.00000,20.00000,1.225799e-07,0.58066,5
540.58747,302.40000,     -1.07608,  2.04077,50.00000,20.00000,1.218201e-07,0.57642,5
546.59604,303.00000,     -1.15419,  2.05867,50.00000,20.00000,1.223712e-07,0.57224,5
552.60293,303.60000,     -1.23004,  2.08522,50.00000,20.00000,1.220431e-07,0.56814,5
558.60478,304.20000,     -1.30716,  2.10303,50.00000,20.00000,1.223600e-07,0.56410,5
564.62315,304.80000,     -1.38426,  2.12996,50.00000,20.00000,1.222070e-07,0.56012,5
570.62134,305.40000,     -1.46315,  2.14739,50.00000,20.00000,1.224280e-07,0.55623,5
576.62935,306.00000,     -1.54445,  2.16564,50.00000,20.00000,1.220271e-07,0.55239,5
582.62010,306.60000,     -1.61958,  2.18345,50.00000,20.00000,1.217041e-07,0.54864,5
588.64319,307.20000,     -1.69433,  2.20788,50.00000,20.00000,1.227560e-07,0.54493,5
594.65517,307.80000,     -1.77151,  2.21885,50.00000,20.00000,1.221309e-07,0.54129,5
600.67097,308.40000,     -1.84532,  2.22744,50.00000,20.00000,1.223230e-07,0.53771,5
606.68022,309.00000,     -1.91723,  2.25469,50.00000,20.00000,1.211507e-07,0.53421,5
612.67025,309.60000,     -1.98505,  2.26976,50.00000,20.00000,1.221603e-07,0.53077,5
618.70445,310.20000,     -2.05137,  2.28811,50.00000,20.00000,1.222077e-07,0.52737,5
624.69979,310.80000,     -2.11466,  2.29647,50.00000,20.00000,1.224796e-07,0.52405,5
630.71876,311.40000,     -2.17628,  2.30815,50.00000,20.00000,1.229876e-07,0.52077,5
636.72743,312.00000,     -2.23193,  2.33471,50.00000,20.00000,1.219102e-07,0.51756,5
642.74400,312.60000,     -2.28599,  2.35254,50.00000,20.00000,1.222227e-07,0.51440,5
648.75391,313.20000,     -2.33962,  2.36146,50.00000,20.00000,1.226285e-07,0.51129,5
654.76212,313.80000,     -2.38888,  2.36467,50.00000,20.00000,1.227555e-07,0.50824,5
660.76928,314.40000,     -2.43474,  2.39079,50.00000,20.00000,1.227662e-07,0.50523,5
666.78625,315.00000,     -2.47768,  2.40644,50.00000,20.00000,1.226414e-07,0.50227,5
672.79623,315.60000,     -2.51654,  2.41977,50.00000,20.00000,1.226899e-07,0.49936,5
678.81203,316.20000,     -2.55086,  2.42630,50.00000,20.00000,1.219078e-07,0.49649,5
684.81919,316.80000,     -2.58023,  2.43901,50.00000,20.00000,1.218224e-07,0.49367,5
690.84119,317.40000,     -2.60347,  2.44805,50.00000,20.00000,1.226405e-07,0.49088,5
696.86109,318.00000,     -2.62734,  2.45780,50.00000,20.00000,1.219851e-07,0.48813,5
702.87345,318.60000,     -2.64049,  2.47395,50.00000,20.00000,1.227050e-07,0.48541,5
708.90018,319.20000,     -2.65219,  2.48918,50.00000,20.00000,1.221056e-07,0.48273,5
714.91731,319.80000,     -2.66058,  2.50027,50.00000,20.00000,1.224889e-07,0.48008,5
720.93076,320.40000,     -2.66491,  2.50472,50.00000,20.00000,1.226625e-07,0.47747,5
726.94458,321.00000,     -2.66476,  2.52258,50.00000,20.00000,1.230920e-07,0.47488,5
732.94313,321.60000,     -2.66291,  2.53168,50.00000,20.00000,1.230837e-07,0.47232,5
738.94988,322.20000,     -2.66178,  2.55056,50.00000,20.00000,1.224722e-07,0.46979,5
744.96425,322.80000,     -2.66213,  2.55886,50.00000,20.00000,1.231293e-07,0.46727,5
750.97218,323.40000,     -2.66299,  2.57313,50.00000,20.00000,1.223230e-07,0.46477,5
756.97999,324.00000,     -2.66676,  2.57769,50.00000,20.00000,1.233096e-07,0.46229,5
762.96928,324.60000,     -2.67354,  2.58204,50.00000,20.00000,1.219800e-07,0.45984,5
768.98392,325.20000,     -2.68272,  2.59985,50.00000,20.00000,1.223697e-07,0.45739,5
774.99287,325.80000,     -2.69524,  2.61734,50.00000,20.00000,1.221392e-07,0.45495,5
780.99137,326.40000,     -2.71055,  2.63301,50.00000,20.00000,1.231210e-07,0.45253,5
786.99219,327.00000,     -2.72196,  2.63986,50.00000,20.00000,1.222129e-07,0.45011,5
793.01748,327.60000,     -2.74136,  2.66221,50.00000,20.00000,1.228183e-07,0.44769,5
794.02140,327.70000,     -2.74488,  2.66187,50.00000,20.00000,1.228183e-07,0.44728,5