File: pc_x_polymers/ExpDat_2024_01_20_SL_005P-TGA-dynamic.csv
#EXPORTTYPE:                 ,DATA ALL
#FILE:                       ,2024_01_20_SL_005P-TGA-dynamic.ngb-ss5
#FORMAT:                     ,NETZSCH5
#FTYPE:                      ,ASCII
#IDENTITY:                   ,PS-SCF3
#DECIMAL:                    ,POINT
#SEPARATOR:                  ,COMMA
#MTYPE:                      ,DSC
#INSTRUMENT:                 ,NETZSCH STA 449F5
#PROJECT:                    ,
#DATE/TIME:                  ,1/20/2024 9:21:35 PM (UTC-5)
#CORR. FILE:                 ,
#TEMPCAL:                    ,28-06-2023 13:26
#SENSITIVITY:                ,28-06-2023 13:53
#LABORATORY:                 ,Tran/AAG
#OPERATOR:                   ,Stanley
#REMARK:                     ,
#SAMPLE:                     ,005P
#SAMPLE MASS /mg:            ,6.84
#MATERIAL:                   ,
#REFERENCE:                  ,Empty Al2O3
#REFERENCE MASS /mg:         ,0
#TYPE OF CRUCIBLE:           ,Al2O3 85 ‘l, open
#SAMPLE CRUCIBLE MASS /mg:   ,0
#REFERENCE CRUCIBLE MASS /mg:,136.57
#DSC RANGE /‘V:              ,5000
#TG RANGE /mg:               ,35000
#TAU-R:                      ,---
#CORR. CODE:                 ,000
#EXO:                        ,-1
#RANGE:                      ,20›C....800›C/0.0....5.0K/min
#SEGMENT:                    ,S1-4/4
#SEG. 1:                     ,20›C/5.0(K/min)/100›C
#SEG. 2:                     ,100›C/00:05/100›C
#SEG. 3:                     ,100›C/1.0(K/min)/400›C
#SEG. 4:                     ,400›C/5.0(K/min)/800›C

##Temp./›C,Time/min,DSC/(mW/mg),Mass/%,Gas Flow(purge2)/(ml/min),Gas Flow(protective)/(ml/min),TIC(scan:1)/A,Sensit./(uV/mW),Segment
 32.03500,  0.00000,-5.010130e-02,100.00000,50.00000,20.00000,1.162193e-07,0.92392,1
 32.10879,  0.70000,-3.076119e-02,100.10355,50.00000,20.00000,1.163065e-07,0.92393,1
 32.40000,  1.40000,-4.828716e-04,100.28289,50.00000,20.00000,1.163897e-07,0.92398,1
 32.78427,  2.10000, 1.239915e-02,100.33605,50.00000,20.00000,1.163134e-07,0.92404,1
 33.25400,  2.80000, 3.065762e-02,100.47646,50.00000,20.00000,1.158043e-07,0.92412,1
 33.96370,  3.50000, 7.562708e-02,100.79444,50.00000,20.00000,1.161067e-07,0.92424,1
 35.14000,  4.20000,      0.14962,101.22558,50.00000,20.00000,1.157970e-07,0.92442,1
 36.80375,  4.90000,      0.23880,101.75679,50.00000,20.00000,1.155741e-07,0.92466,1
 38.96100,  5.60000,      0.33247,102.28743,50.00000,20.00000,1.153520e-07,0.92495,1
 41.57897,  6.30000,      0.42647,102.77729,50.00000,20.00000,1.148747e-07,0.92526,1
 44.64600,  7.00000,      0.51639,103.23348,50.00000,20.00000,1.149158e-07,0.92557,1
 48.10859,  7.70000,      0.60142,103.63296,50.00000,20.00000,1.147414e-07,0.92584,1
 51.85700,  8.40000,      0.67860,104.02749,50.00000,20.00000,1.145822e-07,0.92605,1
 55.86848,  9.10000,      0.74667,104.32138,50.00000,20.00000,1.144094e-07,0.92617,1
 60.07600,  9.80000,      0.80314,104.57646,50.00000,20.00000,1.140833e-07,0.92620,1
 64.38636, 10.50000,      0.84976,104.82296,50.00000,20.00000,1.142580e-07,0.92610,1
 68.79000, 11.20000,      0.88472,105.03143,50.00000,20.00000,1.142583e-07,0.92589,1
 73.20327, 11.90000,      0.91212,105.14521,50.00000,20.00000,1.136861e-07,0.92556,1
 77.57500, 12.60000,      0.93298,105.29269,50.00000,20.00000,1.138178e-07,0.92511,1
 81.92120, 13.30000,      0.94997,105.41637,50.00000,20.00000,1.136652e-07,0.92455,1
 86.22800, 14.00000,      0.96126,105.51096,50.00000,20.00000,1.136270e-07,0.92388,1
 90.47391, 14.70000,      0.96920,105.59018,50.00000,20.00000,1.135143e-07,0.92312,1
 94.63300, 15.40000,      0.97757,105.66477,50.00000,20.00000,1.132934e-07,0.92227,1
 98.69729, 16.10000,      0.98705,105.72049,50.00000,20.00000,1.130963e-07,0.92134,2
102.05211, 16.80000,      0.80737,105.54236,50.00000,20.00000,1.127591e-07,0.92051,2
104.30300, 17.50000,      0.54187,105.14574,50.00000,20.00000,1.129580e-07,0.91991,2
105.87557, 18.20000,      0.36940,104.85925,50.00000,20.00000,1.130654e-07,0.91948,2
107.01364, 18.90000,      0.26086,104.64257,50.00000,20.00000,1.123689e-07,0.91916,2
107.74945, 19.60000,      0.15848,104.44704,50.00000,20.00000,1.130516e-07,0.91895,2
108.05217, 20.30000, 5.863838e-02,104.23113,50.00000,20.00000,1.129608e-07,0.91886,2
108.01337, 21.00000,-2.388944e-02,104.02145,50.00000,20.00000,1.126455e-07,0.91887,3
107.80775, 21.70000,-6.002271e-02,103.87199,50.00000,20.00000,1.125669e-07,0.91893,3
107.61340, 22.40000,-5.792572e-02,103.81405,50.00000,20.00000,1.127593e-07,0.91899,3
107.44924, 23.10000,-5.431794e-02,103.77554,50.00000,20.00000,1.126568e-07,0.91903,3
107.23746, 23.80000,-5.135096e-02,103.74945,50.00000,20.00000,1.124322e-07,0.91909,3
107.08930, 24.50000,-4.046609e-02,103.72809,50.00000,20.00000,1.124312e-07,0.91914,3
107.00625, 25.20000,-2.189985e-02,103.73801,50.00000,20.00000,1.121059e-07,0.91916,3
107.00834, 25.90000, 4.729937e-04,103.73356,50.00000,20.00000,1.117513e-07,0.91916,3
107.11509, 26.60000, 2.385886e-02,103.77233,50.00000,20.00000,1.121461e-07,0.91913,3
107.30297, 27.30000, 4.618334e-02,103.78190,50.00000,20.00000,1.119489e-07,0.91908,3
107.57728, 28.00000, 6.682327e-02,103.81237,50.00000,20.00000,1.121006e-07,0.91900,3
107.93087, 28.70000, 8.646835e-02,103.81536,50.00000,20.00000,1.120376e-07,0.91889,3
108.35764, 29.40000,      0.10609,103.85655,50.00000,20.00000,1.119749e-07,0.91877,3
108.82730, 30.10000,      0.12290,103.89638,50.00000,20.00000,1.113649e-07,0.91863,3
109.36761, 30.80000,      0.13889,103.93124,50.00000,20.00000,1.114044e-07,0.91847,3
109.97109, 31.50000,      0.15159,103.94839,50.00000,20.00000,1.112652e-07,0.91829,3
110.56871, 32.20000,      0.16240,103.95165,50.00000,20.00000,1.116887e-07,0.91811,3
111.24859, 32.90000,      0.17115,103.96484,50.00000,20.00000,1.112770e-07,0.91790,3
111.93330, 33.60000,      0.17903,104.01625,50.00000,20.00000,1.114659e-07,0.91768,3
112.64213, 34.30000,      0.18697,104.00392,50.00000,20.00000,1.112810e-07,0.91746,3
113.35027, 35.00000,      0.19163,104.02566,50.00000,20.00000,1.112614e-07,0.91724,3
114.07954, 35.70000,      0.19637,104.02590,50.00000,20.00000,1.114284e-07,0.91700,3
114.82219, 36.40000,      0.20015,104.03074,50.00000,20.00000,1.108924e-07,0.91676,3
115.57916, 37.10000,      0.20410,104.05174,50.00000,20.00000,1.111553e-07,0.91651,3
116.30522, 37.80000,      0.20585,104.06053,50.00000,20.00000,1.109926e-07,0.91626,3
117.03568, 38.50000,      0.20800,104.05994,50.00000,20.00000,1.110086e-07,0.91602,3
117.77650, 39.20000,      0.20961,104.07047,50.00000,20.00000,1.109456e-07,0.91576,3
118.51654, 39.90000,      0.21009,104.09645,50.00000,20.00000,1.109611e-07,0.91551,3
119.24739, 40.60000,      0.21083,104.07542,50.00000,20.00000,1.109569e-07,0.91525,3
119.97828, 41.30000,      0.21177,104.09020,50.00000,20.00000,1.111463e-07,0.91499,3
120.68642, 42.00000,      0.21362,104.10009,50.00000,20.00000,1.109507e-07,0.91474,3
121.41806, 42.70000,      0.21419,104.09340,50.00000,20.00000,1.106376e-07,0.91447,3
122.13750, 43.40000,      0.21509,104.11633,50.00000,20.00000,1.107846e-07,0.91421,3
122.85481, 44.10000,      0.21500,104.09015,50.00000,20.00000,1.108279e-07,0.91394,3
123.55830, 44.80000,      0.21644,104.11667,50.00000,20.00000,1.107864e-07,0.91368,3
124.27303, 45.50000,      0.21657,104.12056,50.00000,20.00000,1.107012e-07,0.91341,3
124.98823, 46.20000,      0.21769,104.14279,50.00000,20.00000,1.105612e-07,0.91314,3
125.68949, 46.90000,      0.21922,104.14265,50.00000,20.00000,1.103522e-07,0.91287,3
126.38219, 47.60000,      0.22135,104.17670,50.00000,20.00000,1.103319e-07,0.91260,3
127.10445, 48.30000,      0.22171,104.18788,50.00000,20.00000,1.107073e-07,0.91232,3
127.79739, 49.00000,      0.22319,104.19603,50.00000,20.00000,1.106430e-07,0.91205,3
128.51694, 49.70000,      0.22394,104.19547,50.00000,20.00000,1.105391e-07,0.91176,3
129.21519, 50.40000,      0.22553,104.22061,50.00000,20.00000,1.105500e-07,0.91148,3
129.90846, 51.10000,      0.22696,104.23079,50.00000,20.00000,1.105385e-07,0.91120,3
130.61545, 51.80000,      0.22823,104.23254,50.00000,20.00000,1.106381e-07,0.91091,3
131.30646, 52.50000,      0.23005,104.25507,50.00000,20.00000,1.103615e-07,0.91062,3
132.00420, 53.20000,      0.23145,104.25245,50.00000,20.00000,1.103889e-07,0.91033,3
132.70388, 53.90000,      0.23222,104.27778,50.00000,20.00000,1.105553e-07,0.91004,3
133.40523, 54.60000,      0.23394,104.29571,50.00000,20.00000,1.103038e-07,0.90974,3
134.11129, 55.30000,      0.23482,104.28212,50.00000,20.00000,1.100494e-07,0.90944,3
134.80135, 56.00000,      0.23593,104.32055,50.00000,20.00000,1.100323e-07,0.90914,3
135.50965, 56.70000,      0.23651,104.32005,50.00000,20.00000,1.103310e-07,0.90883,3
136.20735, 57.40000,      0.23818,104.35004,50.00000,20.00000,1.102656e-07,0.90853,3
136.90227, 58.10000,      0.23963,104.35704,50.00000,20.00000,1.102345e-07,0.90822,3
137.60531, 58.80000,      0.24019,104.35946,50.00000,20.00000,1.101060e-07,0.90791,3
138.29627, 59.50000,      0.24128,104.37771,50.00000,20.00000,1.100481e-07,0.90760,3
138.99132, 60.20000,      0.24269,104.38265,50.00000,20.00000,1.102098e-07,0.90728,3
139.69356, 60.90000,      0.24417,104.41179,50.00000,20.00000,1.101393e-07,0.90696,3
140.39834, 61.60000,      0.24618,104.41777,50.00000,20.00000,1.099400e-07,0.90664,3
141.09049, 62.30000,      0.24676,104.43292,50.00000,20.00000,1.099473e-07,0.90632,3
141.78918, 63.00000,      0.24845,104.45216,50.00000,20.00000,1.101458e-07,0.90600,3
142.49988, 63.70000,      0.24890,104.44995,50.00000,20.00000,1.100646e-07,0.90566,3
143.19228, 64.40000,      0.25021,104.47245,50.00000,20.00000,1.098972e-07,0.90534,3
143.90199, 65.10000,      0.25074,104.48165,50.00000,20.00000,1.100539e-07,0.90500,3
144.61228, 65.80000,      0.25190,104.49219,50.00000,20.00000,1.099212e-07,0.90466,3
145.31155, 66.50000,      0.25340,104.50693,50.00000,20.00000,1.101449e-07,0.90432,3
146.01128, 67.20000,      0.25454,104.55214,50.00000,20.00000,1.099596e-07,0.90398,3
146.71380, 67.90000,      0.25562,104.52993,50.00000,20.00000,1.102302e-07,0.90364,3
147.40243, 68.60000,      0.25611,104.55173,50.00000,20.00000,1.101061e-07,0.90330,3
148.11310, 69.30000,      0.25661,104.56701,50.00000,20.00000,1.102066e-07,0.90295,3
148.80828, 70.00000,      0.25717,104.58145,50.00000,20.00000,1.101220e-07,0.90260,3
149.50674, 70.70000,      0.25942,104.59984,50.00000,20.00000,1.101154e-07,0.90225,3
150.20748, 71.40000,      0.26131,104.59958,50.00000,20.00000,1.100640e-07,0.90190,3
150.90294, 72.10000,      0.26224,104.60701,50.00000,20.00000,1.102118e-07,0.90154,3
151.61229, 72.80000,      0.26300,104.63436,50.00000,20.00000,1.100184e-07,0.90118,3
152.31502, 73.50000,      0.26340,104.64504,50.00000,20.00000,1.100949e-07,0.90082,3
153.01246, 74.20000,      0.26445,104.66926,50.00000,20.00000,1.097218e-07,0.90046,3
153.71190, 74.90000,      0.26521,104.68167,50.00000,20.00000,1.096779e-07,0.90009,3
154.40813, 75.60000,      0.26728,104.65945,50.00000,20.00000,1.099254e-07,0.89973,3
155.11329, 76.30000,      0.26755,104.68942,50.00000,20.00000,1.097045e-07,0.89936,3
155.82813, 77.00000,      0.26874,104.71838,50.00000,20.00000,1.098317e-07,0.89898,3
156.51907, 77.70000,      0.26950,104.72778,50.00000,20.00000,1.099545e-07,0.89861,3
157.21645, 78.40000,      0.27070,104.72865,50.00000,20.00000,1.100155e-07,0.89823,3
157.91748, 79.10000,      0.27209,104.75357,50.00000,20.00000,1.099496e-07,0.89785,3
158.62634, 79.80000,      0.27229,104.75833,50.00000,20.00000,1.099603e-07,0.89747,3
159.32441, 80.50000,      0.27368,104.79051,50.00000,20.00000,1.098924e-07,0.89709,3
160.02328, 81.20000,      0.27466,104.78830,50.00000,20.00000,1.100325e-07,0.89670,3
160.73853, 81.90000,      0.27584,104.77607,50.00000,20.00000,1.100598e-07,0.89631,3
161.42630, 82.60000,      0.27676,104.79810,50.00000,20.00000,1.096938e-07,0.89593,3
162.13146, 83.30000,      0.27749,104.81798,50.00000,20.00000,1.094925e-07,0.89553,3
162.82229, 84.00000,      0.27824,104.82777,50.00000,20.00000,1.097283e-07,0.89514,3
163.53186, 84.70000,      0.27955,104.84965,50.00000,20.00000,1.100650e-07,0.89474,3
164.22620, 85.40000,      0.27948,104.86777,50.00000,20.00000,1.095048e-07,0.89435,3
164.93488, 86.10000,      0.28124,104.87849,50.00000,20.00000,1.098848e-07,0.89394,3
165.62157, 86.80000,      0.28286,104.87924,50.00000,20.00000,1.098900e-07,0.89355,3
166.34136, 87.50000,      0.28313,104.89150,50.00000,20.00000,1.098177e-07,0.89313,3
167.03449, 88.20000,      0.28250,104.90393,50.00000,20.00000,1.100176e-07,0.89273,3
167.73363, 88.90000,      0.28238,104.90570,50.00000,20.00000,1.099259e-07,0.89232,3
168.43138, 89.60000,      0.28412,104.90608,50.00000,20.00000,1.097755e-07,0.89191,3
169.13466, 90.30000,      0.28435,104.92544,50.00000,20.00000,1.096976e-07,0.89150,3
169.82236, 91.00000,      0.28564,104.94036,50.00000,20.00000,1.098690e-07,0.89109,3
170.53062, 91.70000,      0.28596,104.94506,50.00000,20.00000,1.099430e-07,0.89067,3
171.22923, 92.40000,      0.28704,104.93015,50.00000,20.00000,1.100613e-07,0.89025,3
171.92529, 93.10000,      0.28585,104.98970,50.00000,20.00000,1.096699e-07,0.88983,3
172.63333, 93.80000,      0.28706,104.98830,50.00000,20.00000,1.099440e-07,0.88941,3
173.31671, 94.50000,      0.28760,105.00322,50.00000,20.00000,1.099502e-07,0.88899,3
174.02626, 95.20000,      0.28859,105.00322,50.00000,20.00000,1.098096e-07,0.88856,3
174.73337, 95.90000,      0.28932,105.01804,50.00000,20.00000,1.097929e-07,0.88813,3
175.43933, 96.60000,      0.28925,105.02813,50.00000,20.00000,1.096810e-07,0.88769,3
176.12911, 97.30000,      0.28977,105.04674,50.00000,20.00000,1.094842e-07,0.88726,3
176.82323, 98.00000,      0.28965,105.05794,50.00000,20.00000,1.099455e-07,0.88683,3
177.52829, 98.70000,      0.29142,105.07955,50.00000,20.00000,1.099770e-07,0.88639,3
178.23037, 99.40000,      0.29233,105.08757,50.00000,20.00000,1.097380e-07,0.88595,3
178.92912,100.10000,      0.29120,105.09236,50.00000,20.00000,1.097031e-07,0.88551,3
179.62237,100.80000,      0.29062,105.08757,50.00000,20.00000,1.098431e-07,0.88507,3
180.32208,101.50000,      0.29222,105.11715,50.00000,20.00000,1.097366e-07,0.88463,3
181.03992,102.20000,      0.29268,105.13754,50.00000,20.00000,1.098647e-07,0.88417,3
181.73873,102.90000,      0.29300,105.12735,50.00000,20.00000,1.098650e-07,0.88372,3
182.43012,103.60000,      0.29258,105.13401,50.00000,20.00000,1.097231e-07,0.88328,3
183.12533,104.30000,      0.29339,105.13754,50.00000,20.00000,1.098408e-07,0.88283,3
183.82432,105.00000,      0.29379,105.14892,50.00000,20.00000,1.095964e-07,0.88238,3
184.53462,105.70000,      0.29532,105.14693,50.00000,20.00000,1.095822e-07,0.88191,3
185.23540,106.40000,      0.29499,105.18812,50.00000,20.00000,1.099221e-07,0.88146,3
185.92683,107.10000,      0.29453,105.18864,50.00000,20.00000,1.094356e-07,0.88100,3
186.63119,107.80000,      0.29427,105.18876,50.00000,20.00000,1.097446e-07,0.88054,3
187.33256,108.50000,      0.29535,105.20529,50.00000,20.00000,1.093545e-07,0.88007,3
188.03635,109.20000,      0.29468,105.21859,50.00000,20.00000,1.097441e-07,0.87960,3
188.75314,109.90000,      0.29560,105.21532,50.00000,20.00000,1.097555e-07,0.87913,3
189.43942,110.60000,      0.29590,105.21829,50.00000,20.00000,1.099161e-07,0.87867,3
190.13093,111.30000,      0.29538,105.22102,50.00000,20.00000,1.094404e-07,0.87820,3
190.82121,112.00000,      0.29687,105.23814,50.00000,20.00000,1.097817e-07,0.87773,3
191.52630,112.70000,      0.29679,105.23414,50.00000,20.00000,1.097991e-07,0.87726,3
192.24131,113.40000,      0.29681,105.24808,50.00000,20.00000,1.092612e-07,0.87677,3
192.92192,114.10000,      0.29668,105.26789,50.00000,20.00000,1.092905e-07,0.87630,3
193.62107,114.80000,      0.29737,105.27773,50.00000,20.00000,1.095201e-07,0.87582,3
194.32627,115.50000,      0.29697,105.28754,50.00000,20.00000,1.095999e-07,0.87534,3
195.01735,116.20000,      0.29785,105.30224,50.00000,20.00000,1.093498e-07,0.87486,3
195.71880,116.90000,      0.29888,105.30263,50.00000,20.00000,1.092848e-07,0.87438,3
196.42638,117.60000,      0.30020,105.30425,50.00000,20.00000,1.097120e-07,0.87388,3
197.13460,118.30000,      0.29960,105.32174,50.00000,20.00000,1.100492e-07,0.87339,3
197.84513,119.00000,      0.29979,105.33404,50.00000,20.00000,1.098142e-07,0.87289,3
198.52542,119.70000,      0.29971,105.34395,50.00000,20.00000,1.095926e-07,0.87241,3
199.22031,120.40000,      0.30062,105.33368,50.00000,20.00000,1.094515e-07,0.87192,3
199.92977,121.10000,      0.30069,105.36332,50.00000,20.00000,1.093501e-07,0.87142,3
200.63305,121.80000,      0.29982,105.37417,50.00000,20.00000,1.094357e-07,0.87092,3
201.32394,122.50000,      0.30126,105.37921,50.00000,20.00000,1.096919e-07,0.87043,3
202.03350,123.20000,      0.30260,105.37744,50.00000,20.00000,1.091157e-07,0.86992,3
202.73353,123.90000,      0.30295,105.38113,50.00000,20.00000,1.097098e-07,0.86942,3
203.44357,124.60000,      0.30283,105.40190,50.00000,20.00000,1.096788e-07,0.86891,3
204.12615,125.30000,      0.30350,105.40255,50.00000,20.00000,1.094077e-07,0.86841,3
204.82517,126.00000,      0.30331,105.42174,50.00000,20.00000,1.094367e-07,0.86791,3
205.52873,126.70000,      0.30300,105.42755,50.00000,20.00000,1.097448e-07,0.86739,3
206.22840,127.40000,      0.30457,105.43185,50.00000,20.00000,1.098295e-07,0.86688,3
206.93388,128.10000,      0.30609,105.43284,50.00000,20.00000,1.094204e-07,0.86637,3
207.63762,128.80000,      0.30429,105.45063,50.00000,20.00000,1.098038e-07,0.86585,3
208.32891,129.50000,      0.30470,105.44731,50.00000,20.00000,1.097938e-07,0.86534,3
209.03016,130.20000,      0.30463,105.47453,50.00000,20.00000,1.098828e-07,0.86482,3
209.73160,130.90000,      0.30541,105.46908,50.00000,20.00000,1.094934e-07,0.86430,3
210.43357,131.60000,      0.30540,105.47962,50.00000,20.00000,1.095205e-07,0.86378,3
211.12173,132.30000,      0.30455,105.47746,50.00000,20.00000,1.096188e-07,0.86327,3
211.82846,133.00000,      0.30511,105.49943,50.00000,20.00000,1.096359e-07,0.86274,3
212.52677,133.70000,      0.30444,105.49495,50.00000,20.00000,1.095443e-07,0.86222,3
213.23136,134.40000,      0.30434,105.51928,50.00000,20.00000,1.096543e-07,0.86169,3
213.92359,135.10000,      0.30405,105.51903,50.00000,20.00000,1.093907e-07,0.86116,3
214.61931,135.80000,      0.30533,105.50429,50.00000,20.00000,1.091509e-07,0.86064,3
215.33756,136.50000,      0.30569,105.52167,50.00000,20.00000,1.093217e-07,0.86009,3
216.03802,137.20000,      0.30483,105.52916,50.00000,20.00000,1.096873e-07,0.85956,3
216.72811,137.90000,      0.30490,105.55066,50.00000,20.00000,1.094013e-07,0.85903,3
217.43046,138.60000,      0.30483,105.55364,50.00000,20.00000,1.095753e-07,0.85849,3
218.13317,139.30000,      0.30364,105.52832,50.00000,20.00000,1.095054e-07,0.85795,3
218.82347,140.00000,      0.30194,105.56267,50.00000,20.00000,1.094861e-07,0.85742,3
219.52812,140.70000,      0.30186,105.56498,50.00000,20.00000,1.093440e-07,0.85688,3
220.23025,141.40000,      0.30258,105.56887,50.00000,20.00000,1.092071e-07,0.85634,3
220.91819,142.10000,      0.30335,105.57081,50.00000,20.00000,1.094796e-07,0.85580,3
221.62955,142.80000,      0.30257,105.57032,50.00000,20.00000,1.094211e-07,0.85525,3
222.32841,143.50000,      0.30358,105.57937,50.00000,20.00000,1.093656e-07,0.85470,3
223.03643,144.20000,      0.30271,105.59035,50.00000,20.00000,1.094168e-07,0.85415,3
223.72208,144.90000,      0.30083,105.57043,50.00000,20.00000,1.093209e-07,0.85361,3
224.42346,145.60000,      0.30190,105.58499,50.00000,20.00000,1.093483e-07,0.85306,3
225.12983,146.30000,      0.30245,105.58556,50.00000,20.00000,1.097192e-07,0.85250,3
225.84239,147.00000,      0.30140,105.58536,50.00000,20.00000,1.094287e-07,0.85194,3
226.53207,147.70000,      0.29990,105.58547,50.00000,20.00000,1.095436e-07,0.85140,3
227.23763,148.40000,      0.29865,105.58543,50.00000,20.00000,1.092112e-07,0.85084,3
227.92237,149.10000,      0.29787,105.59041,50.00000,20.00000,1.090809e-07,0.85029,3
228.63012,149.80000,      0.29864,105.58538,50.00000,20.00000,1.096056e-07,0.84973,3
229.32919,150.50000,      0.29984,105.60057,50.00000,20.00000,1.092704e-07,0.84917,3
230.03336,151.20000,      0.29850,105.58080,50.00000,20.00000,1.092188e-07,0.84860,3
230.72556,151.90000,      0.29713,105.58880,50.00000,20.00000,1.094470e-07,0.84805,3
231.42536,152.60000,      0.29614,105.60037,50.00000,20.00000,1.090239e-07,0.84748,3
232.11462,153.30000,      0.29627,105.61069,50.00000,20.00000,1.094838e-07,0.84693,3
232.82718,154.00000,      0.29572,105.60037,50.00000,20.00000,1.091969e-07,0.84635,3
233.52228,154.70000,      0.29765,105.60544,50.00000,20.00000,1.090148e-07,0.84578,3
234.22357,155.40000,      0.29680,105.60686,50.00000,20.00000,1.094209e-07,0.84521,3
234.91865,156.10000,      0.29416,105.60285,50.00000,20.00000,1.092599e-07,0.84465,3
235.62125,156.80000,      0.29388,105.62714,50.00000,20.00000,1.088757e-07,0.84407,3
236.31914,157.50000,      0.29510,105.60720,50.00000,20.00000,1.092639e-07,0.84350,3
237.02544,158.20000,      0.29549,105.62636,50.00000,20.00000,1.087768e-07,0.84292,3
237.71537,158.90000,      0.29246,105.61188,50.00000,20.00000,1.092376e-07,0.84236,3
238.41927,159.60000,      0.29284,105.61174,50.00000,20.00000,1.090666e-07,0.84178,3
239.11465,160.30000,      0.29153,105.62041,50.00000,20.00000,1.089460e-07,0.84120,3
239.81013,161.00000,      0.29151,105.63167,50.00000,20.00000,1.094495e-07,0.84063,3
240.51716,161.70000,      0.29161,105.62552,50.00000,20.00000,1.093557e-07,0.84004,3
241.21765,162.40000,      0.29021,105.64491,50.00000,20.00000,1.086605e-07,0.83946,3
241.92074,163.10000,      0.28976,105.62116,50.00000,20.00000,1.091717e-07,0.83887,3
242.62240,163.80000,      0.28887,105.65023,50.00000,20.00000,1.096364e-07,0.83829,3
243.31981,164.50000,      0.28820,105.63509,50.00000,20.00000,1.089880e-07,0.83771,3
244.01529,165.20000,      0.28701,105.63997,50.00000,20.00000,1.093106e-07,0.83712,3
244.72520,165.90000,      0.28581,105.63405,50.00000,20.00000,1.089585e-07,0.83653,3
245.41653,166.60000,      0.28342,105.64006,50.00000,20.00000,1.089590e-07,0.83595,3
246.11935,167.30000,      0.28326,105.63074,50.00000,20.00000,1.091422e-07,0.83535,3
246.81054,168.00000,      0.28196,105.63561,50.00000,20.00000,1.092537e-07,0.83477,3
247.50899,168.70000,      0.28040,105.65705,50.00000,20.00000,1.091258e-07,0.83418,3
248.19747,169.40000,      0.28071,105.65330,50.00000,20.00000,1.091250e-07,0.83360,3
248.90842,170.10000,      0.28220,105.65018,50.00000,20.00000,1.087316e-07,0.83299,3
249.60411,170.80000,      0.28074,105.63022,50.00000,20.00000,1.091680e-07,0.83240,3
250.30699,171.50000,      0.28015,105.64795,50.00000,20.00000,1.090773e-07,0.83180,3
251.00722,172.20000,      0.27979,105.64491,50.00000,20.00000,1.088482e-07,0.83121,3
251.71369,172.90000,      0.27791,105.64476,50.00000,20.00000,1.090892e-07,0.83060,3
252.40668,173.60000,      0.27698,105.65979,50.00000,20.00000,1.092850e-07,0.83001,3
253.10584,174.30000,      0.27513,105.64475,50.00000,20.00000,1.091071e-07,0.82941,3
253.80541,175.00000,      0.27509,105.64006,50.00000,20.00000,1.088241e-07,0.82881,3
254.51324,175.70000,      0.27357,105.66268,50.00000,20.00000,1.091450e-07,0.82820,3
255.21028,176.40000,      0.27212,105.63511,50.00000,20.00000,1.091241e-07,0.82760,3
255.90752,177.10000,      0.27198,105.63250,50.00000,20.00000,1.091713e-07,0.82699,3
256.61300,177.80000,      0.27141,105.61490,50.00000,20.00000,1.093851e-07,0.82638,3
257.32319,178.50000,      0.27078,105.62838,50.00000,20.00000,1.090308e-07,0.82577,3
258.01333,179.20000,      0.26846,105.63004,50.00000,20.00000,1.087093e-07,0.82517,3
258.71671,179.90000,      0.26632,105.59360,50.00000,20.00000,1.089254e-07,0.82456,3
259.39321,180.60000,      0.26588,105.62365,50.00000,20.00000,1.092254e-07,0.82397,3
260.10470,181.30000,      0.26542,105.59726,50.00000,20.00000,1.091853e-07,0.82335,3
260.80322,182.00000,      0.26530,105.61392,50.00000,20.00000,1.091910e-07,0.82274,3
261.49917,182.70000,      0.26223,105.60944,50.00000,20.00000,1.091410e-07,0.82213,3
262.20131,183.40000,      0.26177,105.59869,50.00000,20.00000,1.085958e-07,0.82151,3
262.89966,184.10000,      0.26236,105.60187,50.00000,20.00000,1.091342e-07,0.82090,3
263.60429,184.80000,      0.25891,105.58379,50.00000,20.00000,1.089409e-07,0.82028,3
264.29875,185.50000,      0.25758,105.57411,50.00000,20.00000,1.091905e-07,0.81967,3
264.99626,186.20000,      0.25795,105.58388,50.00000,20.00000,1.084836e-07,0.81905,3
265.71334,186.90000,      0.25963,105.58404,50.00000,20.00000,1.090790e-07,0.81842,3
266.41531,187.60000,      0.25575,105.56191,50.00000,20.00000,1.089745e-07,0.81780,3
267.11680,188.30000,      0.25165,105.56934,50.00000,20.00000,1.092808e-07,0.81718,3
267.80125,189.00000,      0.25079,105.56206,50.00000,20.00000,1.087836e-07,0.81657,3
268.49744,189.70000,      0.25000,105.54862,50.00000,20.00000,1.085134e-07,0.81595,3
269.20539,190.40000,      0.24833,105.53749,50.00000,20.00000,1.085783e-07,0.81532,3
269.89412,191.10000,      0.24630,105.52857,50.00000,20.00000,1.089479e-07,0.81471,3
270.59427,191.80000,      0.24540,105.52720,50.00000,20.00000,1.087579e-07,0.81408,3
271.29343,192.50000,      0.24415,105.50480,50.00000,20.00000,1.090149e-07,0.81346,3
271.99320,193.20000,      0.24344,105.52787,50.00000,20.00000,1.089057e-07,0.81283,3
272.68820,193.90000,      0.24306,105.50774,50.00000,20.00000,1.091103e-07,0.81221,3
273.40217,194.60000,      0.24260,105.50781,50.00000,20.00000,1.089207e-07,0.81157,3
274.07959,195.30000,      0.24113,105.48785,50.00000,20.00000,1.092167e-07,0.81096,3
274.79839,196.00000,      0.24156,105.46795,50.00000,20.00000,1.090104e-07,0.81032,3
275.50732,196.70000,      0.23633,105.46426,50.00000,20.00000,1.088059e-07,0.80968,3
276.19843,197.40000,      0.23383,105.44810,50.00000,20.00000,1.085075e-07,0.80906,3
276.88688,198.10000,      0.23264,105.44821,50.00000,20.00000,1.087376e-07,0.80844,3
277.59414,198.80000,      0.23144,105.42871,50.00000,20.00000,1.086199e-07,0.80780,3
278.29004,199.50000,      0.23094,105.41357,50.00000,20.00000,1.092537e-07,0.80717,3
278.98947,200.20000,      0.22807,105.40847,50.00000,20.00000,1.090657e-07,0.80653,3
279.68097,200.90000,      0.22729,105.38462,50.00000,20.00000,1.087969e-07,0.80591,3
280.38946,201.60000,      0.22565,105.36864,50.00000,20.00000,1.087471e-07,0.80526,3
281.09382,202.30000,      0.22428,105.34886,50.00000,20.00000,1.088848e-07,0.80462,3
281.79723,203.00000,      0.22297,105.34867,50.00000,20.00000,1.088629e-07,0.80398,3
282.50288,203.70000,      0.22187,105.32586,50.00000,20.00000,1.084519e-07,0.80334,3
283.19455,204.40000,      0.21870,105.30910,50.00000,20.00000,1.091067e-07,0.80271,3
283.89065,205.10000,      0.21632,105.28724,50.00000,20.00000,1.090699e-07,0.80208,3
284.59420,205.80000,      0.21670,105.26781,50.00000,20.00000,1.087564e-07,0.80143,3
285.29913,206.50000,      0.21542,105.26572,50.00000,20.00000,1.088518e-07,0.80079,3
285.99347,207.20000,      0.21218,105.27241,50.00000,20.00000,1.087703e-07,0.80015,3
286.69703,207.90000,      0.21143,105.23105,50.00000,20.00000,1.084872e-07,0.79951,3
287.40532,208.60000,      0.20931,105.19184,50.00000,20.00000,1.086471e-07,0.79886,3
288.09690,209.30000,      0.20556,105.19400,50.00000,20.00000,1.083775e-07,0.79822,3
288.78833,210.00000,      0.20415,105.17195,50.00000,20.00000,1.086516e-07,0.79759,3
289.48800,210.70000,      0.20157,105.14053,50.00000,20.00000,1.086113e-07,0.79695,3
290.18152,211.40000,      0.19988,105.11364,50.00000,20.00000,1.087900e-07,0.79631,3
290.87295,212.10000,      0.19856,105.11597,50.00000,20.00000,1.083228e-07,0.79567,3
291.57457,212.80000,      0.19840,105.07940,50.00000,20.00000,1.087219e-07,0.79502,3
292.28230,213.50000,      0.19613,105.06413,50.00000,20.00000,1.087170e-07,0.79437,3
292.98524,214.20000,      0.19338,105.05490,50.00000,20.00000,1.090446e-07,0.79372,3
293.68284,214.90000,      0.19197,105.03041,50.00000,20.00000,1.088168e-07,0.79307,3
294.37123,215.60000,      0.18974,105.00011,50.00000,20.00000,1.086981e-07,0.79244,3
295.08276,216.30000,      0.18835,104.97960,50.00000,20.00000,1.083135e-07,0.79178,3
295.78243,217.00000,      0.18681,104.94037,50.00000,20.00000,1.087011e-07,0.79113,3
296.49110,217.70000,      0.18674,104.91126,50.00000,20.00000,1.086732e-07,0.79047,3
297.19153,218.40000,      0.18374,104.88076,50.00000,20.00000,1.087627e-07,0.78982,3
297.89468,219.10000,      0.17985,104.85841,50.00000,20.00000,1.085487e-07,0.78917,3
298.58540,219.80000,      0.17598,104.84124,50.00000,20.00000,1.086095e-07,0.78852,3
299.28183,220.50000,      0.17375,104.80625,50.00000,20.00000,1.085596e-07,0.78788,3
299.98043,221.20000,      0.17244,104.77338,50.00000,20.00000,1.084591e-07,0.78722,3
300.67871,221.90000,      0.17086,104.73754,50.00000,20.00000,1.086658e-07,0.78657,3
301.38029,222.60000,      0.16834,104.70879,50.00000,20.00000,1.084813e-07,0.78592,3
302.07754,223.30000,      0.16793,104.66710,50.00000,20.00000,1.085038e-07,0.78527,3
302.78347,224.00000,      0.16691,104.62948,50.00000,20.00000,1.084352e-07,0.78461,3
303.48595,224.70000,      0.16025,104.60223,50.00000,20.00000,1.089148e-07,0.78395,3
304.18430,225.40000,      0.15889,104.57520,50.00000,20.00000,1.084695e-07,0.78330,3
304.87194,226.10000,      0.15710,104.52090,50.00000,20.00000,1.085534e-07,0.78265,3
305.58844,226.80000,      0.15463,104.49537,50.00000,20.00000,1.085225e-07,0.78198,3
306.26530,227.50000,      0.15211,104.45583,50.00000,20.00000,1.086177e-07,0.78135,3
306.97353,228.20000,      0.14859,104.41609,50.00000,20.00000,1.091383e-07,0.78068,3
307.67263,228.90000,      0.14895,104.37328,50.00000,20.00000,1.086406e-07,0.78003,3
308.36740,229.60000,      0.14586,104.33500,50.00000,20.00000,1.086466e-07,0.77937,3
309.07036,230.30000,      0.14340,104.26429,50.00000,20.00000,1.087720e-07,0.77871,3
309.76634,231.00000,      0.14062,104.23228,50.00000,20.00000,1.089263e-07,0.77806,3
310.46663,231.70000,      0.13960,104.19497,50.00000,20.00000,1.086813e-07,0.77740,3
311.17037,232.40000,      0.13686,104.13326,50.00000,20.00000,1.086416e-07,0.77674,3
311.87538,233.10000,      0.13470,104.08939,50.00000,20.00000,1.086444e-07,0.77607,3
312.57233,233.80000,      0.13234,104.03085,50.00000,20.00000,1.087934e-07,0.77541,3
313.27480,234.50000,      0.12759,103.99059,50.00000,20.00000,1.086151e-07,0.77475,3
313.97633,235.20000,      0.12666,103.92166,50.00000,20.00000,1.085640e-07,0.77409,3
314.67597,235.90000,      0.12411,103.86199,50.00000,20.00000,1.087042e-07,0.77343,3
315.37149,236.60000,      0.12183,103.80212,50.00000,20.00000,1.081452e-07,0.77277,3
316.07241,237.30000,      0.12001,103.74153,50.00000,20.00000,1.086934e-07,0.77211,3
316.76357,238.00000,      0.11960,103.69391,50.00000,20.00000,1.084894e-07,0.77146,3
317.47534,238.70000,      0.11447,103.62724,50.00000,20.00000,1.089566e-07,0.77078,3
318.17449,239.40000,      0.11314,103.55473,50.00000,20.00000,1.085336e-07,0.77012,3
318.88334,240.10000,      0.11164,103.50205,50.00000,20.00000,1.086975e-07,0.76945,3
319.57962,240.80000,      0.10767,103.43065,50.00000,20.00000,1.089909e-07,0.76879,3
320.28703,241.50000,      0.10435,103.35050,50.00000,20.00000,1.085011e-07,0.76812,3
320.98455,242.20000,      0.10564,103.27143,50.00000,20.00000,1.085509e-07,0.76746,3
321.68635,242.90000,      0.10261,103.18259,50.00000,20.00000,1.089592e-07,0.76679,3
322.38236,243.60000, 9.798753e-02,103.09324,50.00000,20.00000,1.088170e-07,0.76613,3
323.07972,244.30000, 9.391209e-02,103.02547,50.00000,20.00000,1.083776e-07,0.76547,3
323.77945,245.00000, 9.174376e-02,102.93435,50.00000,20.00000,1.082025e-07,0.76481,3
324.47914,245.70000, 9.102757e-02,102.83357,50.00000,20.00000,1.086921e-07,0.76414,3
325.18411,246.40000, 8.897198e-02,102.73624,50.00000,20.00000,1.086261e-07,0.76347,3
325.88273,247.10000, 8.640276e-02,102.66857,50.00000,20.00000,1.082686e-07,0.76281,3
326.58821,247.80000, 8.211212e-02,102.55686,50.00000,20.00000,1.083388e-07,0.76214,3
327.27571,248.50000, 8.126456e-02,102.44945,50.00000,20.00000,1.083499e-07,0.76148,3
327.98530,249.20000, 7.990388e-02,102.35902,50.00000,20.00000,1.087628e-07,0.76081,3
328.68209,249.90000, 7.373135e-02,102.22679,50.00000,20.00000,1.086570e-07,0.76015,3
329.36245,250.60000, 7.106975e-02,102.11938,50.00000,20.00000,1.085404e-07,0.75950,3
330.07953,251.30000, 7.205332e-02,102.00274,50.00000,20.00000,1.087114e-07,0.75882,3
330.77831,252.00000, 6.783086e-02,101.88089,50.00000,20.00000,1.085365e-07,0.75815,3
331.47410,252.70000, 6.598786e-02,101.73061,50.00000,20.00000,1.083497e-07,0.75749,3
332.18340,253.40000, 6.706784e-02,101.60295,50.00000,20.00000,1.088812e-07,0.75681,3
332.89123,254.10000, 6.364002e-02,101.47038,50.00000,20.00000,1.083753e-07,0.75614,3
333.57115,254.80000, 5.830873e-02,101.31689,50.00000,20.00000,1.083851e-07,0.75549,3
334.27519,255.50000, 5.668523e-02,101.17026,50.00000,20.00000,1.084565e-07,0.75482,3
334.96412,256.20000, 5.605859e-02,100.99448,50.00000,20.00000,1.083140e-07,0.75416,3
335.66083,256.90000, 5.595405e-02,100.82393,50.00000,20.00000,1.083076e-07,0.75350,3
336.37429,257.60000, 5.662766e-02,100.65690,50.00000,20.00000,1.082781e-07,0.75282,3
337.07811,258.30000, 5.023245e-02,100.47263,50.00000,20.00000,1.085002e-07,0.75215,3
337.77654,259.00000, 4.705513e-02,100.27146,50.00000,20.00000,1.082540e-07,0.75148,3
338.47787,259.70000, 4.631188e-02,100.04007,50.00000,20.00000,1.084763e-07,0.75081,3
339.17212,260.40000, 4.536046e-02, 99.84815,50.00000,20.00000,1.087727e-07,0.75015,3
339.87257,261.10000, 4.320781e-02, 99.62147,50.00000,20.00000,1.083513e-07,0.74948,3
340.58216,261.80000, 4.019715e-02, 99.37565,50.00000,20.00000,1.082296e-07,0.74880,3
341.28325,262.50000, 4.119578e-02, 99.11264,50.00000,20.00000,1.084674e-07,0.74813,3
341.98934,263.20000, 3.628360e-02, 98.85926,50.00000,20.00000,1.090286e-07,0.74746,3
342.68285,263.90000, 3.498984e-02, 98.57908,50.00000,20.00000,1.084848e-07,0.74680,3
343.38917,264.60000, 3.170168e-02, 98.31212,50.00000,20.00000,1.089303e-07,0.74612,3
344.07417,265.30000, 2.275391e-02, 98.00281,50.00000,20.00000,1.085477e-07,0.74547,3
344.76945,266.00000, 2.994234e-02, 97.71532,50.00000,20.00000,1.085373e-07,0.74481,3
345.47134,266.70000, 2.674858e-02, 97.37663,50.00000,20.00000,1.086399e-07,0.74414,3
346.16947,267.40000, 2.101281e-02, 97.03896,50.00000,20.00000,1.084674e-07,0.74347,3
346.85421,268.10000, 1.884390e-02, 96.67977,50.00000,20.00000,1.082401e-07,0.74282,3
347.56140,268.80000, 1.758665e-02, 96.30914,50.00000,20.00000,1.083000e-07,0.74214,3
348.27482,269.50000, 2.474597e-02, 95.93814,50.00000,20.00000,1.086124e-07,0.74146,3
348.95420,270.20000, 1.628581e-02, 95.53213,50.00000,20.00000,1.091018e-07,0.74081,3
349.67691,270.90000, 1.028640e-02, 95.10525,50.00000,20.00000,1.081536e-07,0.74012,3
350.36657,271.60000, 6.709177e-03, 94.66940,50.00000,20.00000,1.088882e-07,0.73946,3
351.06826,272.30000, 1.601706e-02, 94.22188,50.00000,20.00000,1.085618e-07,0.73879,3
351.77230,273.00000, 1.255964e-02, 93.72448,50.00000,20.00000,1.081756e-07,0.73812,3
352.47426,273.70000, 1.573800e-03, 93.21086,50.00000,20.00000,1.089105e-07,0.73745,3
353.16939,274.40000, 6.044554e-03, 92.69634,50.00000,20.00000,1.089031e-07,0.73679,3
353.85966,275.10000, 7.430088e-03, 92.15591,50.00000,20.00000,1.081551e-07,0.73613,3
354.55745,275.80000, 2.885721e-03, 91.57082,50.00000,20.00000,1.091387e-07,0.73546,3
355.25975,276.50000, 9.811979e-03, 90.97417,50.00000,20.00000,1.081631e-07,0.73479,3
355.96845,277.20000,-1.602921e-03, 90.35634,50.00000,20.00000,1.087678e-07,0.73412,3
356.65913,277.90000, 1.727294e-03, 89.70218,50.00000,20.00000,1.088973e-07,0.73346,3
357.36036,278.60000,-9.864068e-03, 89.01468,50.00000,20.00000,1.085529e-07,0.73279,3
358.05507,279.30000,-5.198131e-03, 88.34426,50.00000,20.00000,1.092003e-07,0.73213,3
358.75616,280.00000,-2.097062e-03, 87.60069,50.00000,20.00000,1.088185e-07,0.73146,3
359.45748,280.70000,-1.095806e-02, 86.83304,50.00000,20.00000,1.089354e-07,0.73079,3
360.15452,281.40000,-7.502754e-03, 86.03873,50.00000,20.00000,1.088611e-07,0.73013,3
360.86107,282.10000,-1.606057e-02, 85.20078,50.00000,20.00000,1.087109e-07,0.72945,3
361.55340,282.80000,-5.802480e-03, 84.37330,50.00000,20.00000,1.090717e-07,0.72879,3
362.26535,283.50000,-1.628320e-02, 83.46891,50.00000,20.00000,1.085358e-07,0.72812,3
362.96221,284.20000,-1.160894e-02, 82.56936,50.00000,20.00000,1.089327e-07,0.72745,3
363.66744,284.90000,-1.769599e-02, 81.60130,50.00000,20.00000,1.089138e-07,0.72678,3
364.36317,285.60000,-1.239110e-02, 80.63940,50.00000,20.00000,1.092447e-07,0.72612,3
365.04813,286.30000,-2.982575e-02, 79.59186,50.00000,20.00000,1.089761e-07,0.72547,3
365.75567,287.00000,-5.019993e-02, 78.52414,50.00000,20.00000,1.092296e-07,0.72479,3
366.44978,287.70000,-6.948055e-02, 77.42661,50.00000,20.00000,1.088675e-07,0.72413,3
367.14917,288.40000,-8.706161e-02, 76.28352,50.00000,20.00000,1.086549e-07,0.72347,3
367.85089,289.10000,-3.585360e-02, 75.17501,50.00000,20.00000,1.090047e-07,0.72280,3
368.55432,289.80000,-1.936311e-02, 73.98145,50.00000,20.00000,1.092074e-07,0.72213,3
369.25945,290.50000,-1.916536e-02, 72.76204,50.00000,20.00000,1.095347e-07,0.72147,3
369.94535,291.20000,-2.279821e-02, 71.45918,50.00000,20.00000,1.087562e-07,0.72081,3
370.65224,291.90000,-3.004393e-02, 70.17703,50.00000,20.00000,1.088423e-07,0.72014,3
371.35733,292.60000,-2.846857e-02, 68.86107,50.00000,20.00000,1.091825e-07,0.71947,3
372.05295,293.30000,-4.089913e-02, 67.54472,50.00000,20.00000,1.095573e-07,0.71881,3
372.76128,294.00000,-3.329070e-02, 66.15845,50.00000,20.00000,1.090734e-07,0.71814,3
373.45789,294.70000,-6.006489e-02, 64.82696,50.00000,20.00000,1.090392e-07,0.71748,3
374.15125,295.40000,-6.059109e-02, 63.33539,50.00000,20.00000,1.092091e-07,0.71683,3
374.84365,296.10000,-6.838405e-02, 61.90539,50.00000,20.00000,1.092603e-07,0.71617,3
375.54536,296.80000,-7.695002e-02, 60.48852,50.00000,20.00000,1.091688e-07,0.71551,3
376.24573,297.50000,-8.749008e-02, 59.01857,50.00000,20.00000,1.095118e-07,0.71484,3
376.94707,298.20000,-9.820827e-02, 57.54686,50.00000,20.00000,1.097532e-07,0.71418,3
377.63775,298.90000,     -0.11009, 56.01922,50.00000,20.00000,1.092213e-07,0.71353,3
378.35167,299.60000,     -0.11998, 54.51153,50.00000,20.00000,1.091786e-07,0.71285,3
379.03750,300.30000,     -0.14071, 53.02860,50.00000,20.00000,1.092180e-07,0.71220,3
379.75464,301.00000,     -0.12457, 51.55120,50.00000,20.00000,1.094362e-07,0.71153,3
380.45392,301.70000,     -0.15025, 50.07229,50.00000,20.00000,1.090580e-07,0.71087,3
381.14734,302.40000,     -0.17804, 48.55972,50.00000,20.00000,1.095665e-07,0.71021,3
381.85560,303.10000,     -0.19630, 47.11981,50.00000,20.00000,1.095674e-07,0.70954,3
382.55545,303.80000,     -0.21601, 45.64156,50.00000,20.00000,1.094422e-07,0.70889,3
383.25804,304.50000,     -0.23287, 44.16227,50.00000,20.00000,1.095400e-07,0.70822,3
383.94222,305.20000,     -0.24198, 42.73541,50.00000,20.00000,1.097876e-07,0.70758,3
384.64697,305.90000,     -0.26905, 41.35113,50.00000,20.00000,1.097438e-07,0.70692,3
385.35449,306.60000,     -0.28060, 39.95327,50.00000,20.00000,1.095043e-07,0.70625,3
386.05229,307.30000,     -0.30201, 38.57453,50.00000,20.00000,1.092825e-07,0.70559,3
386.74827,308.00000,     -0.32240, 37.22451,50.00000,20.00000,1.096933e-07,0.70494,3
387.45446,308.70000,     -0.33993, 35.88578,50.00000,20.00000,1.094480e-07,0.70428,3
388.14829,309.40000,     -0.36060, 34.58106,50.00000,20.00000,1.099861e-07,0.70363,3
388.84867,310.10000,     -0.37916, 33.30682,50.00000,20.00000,1.094899e-07,0.70297,3
389.55346,310.80000,     -0.40082, 32.02602,50.00000,20.00000,1.093434e-07,0.70231,3
390.26072,311.50000,     -0.42084, 30.83979,50.00000,20.00000,1.093203e-07,0.70165,3
390.94622,312.20000,     -0.43929, 29.65059,50.00000,20.00000,1.096504e-07,0.70100,3
391.65122,312.90000,     -0.45713, 28.47538,50.00000,20.00000,1.098952e-07,0.70034,3
392.36043,313.60000,     -0.47899, 27.37972,50.00000,20.00000,1.094806e-07,0.69968,3
393.05416,314.30000,     -0.49466, 26.33930,50.00000,20.00000,1.094044e-07,0.69903,3
393.75113,315.00000,     -0.51391, 25.28079,50.00000,20.00000,1.094314e-07,0.69838,3
394.45388,315.70000,     -0.53152, 24.28515,50.00000,20.00000,1.095137e-07,0.69773,3
395.14533,316.40000,     -0.55233, 23.33699,50.00000,20.00000,1.094767e-07,0.69708,3
395.84523,317.10000,     -0.56720, 22.40829,50.00000,20.00000,1.095078e-07,0.69643,3
396.54835,317.80000,     -0.58685, 21.52014,50.00000,20.00000,1.096279e-07,0.69577,3
397.24633,318.50000,     -0.60411, 20.70670,50.00000,20.00000,1.099084e-07,0.69512,3
397.94657,319.20000,     -0.62636, 19.88264,50.00000,20.00000,1.098414e-07,0.69447,3
398.64587,319.90000,     -0.63964, 19.11522,50.00000,20.00000,1.097694e-07,0.69382,3
399.35630,320.60000,     -0.65635, 18.39892,50.00000,20.00000,1.094950e-07,0.69316,3
400.45343,321.30000,     -0.38832, 17.75424,50.00000,20.00000,1.097482e-07,0.69214,4
403.62816,322.00000,      0.57659, 17.20698,50.00000,20.00000,1.099103e-07,0.68920,4
406.75964,322.70000,      0.53125, 16.57127,50.00000,20.00000,1.098332e-07,0.68631,4
409.80002,323.40000,      0.49835, 15.88254,50.00000,20.00000,1.096992e-07,0.68352,4
413.16312,324.10000,      0.62840, 15.20567,50.00000,20.00000,1.099172e-07,0.68043,4
416.66065,324.80000,      0.67285, 14.50755,50.00000,20.00000,1.098993e-07,0.67724,4
420.18568,325.50000,      0.65537, 13.81284,50.00000,20.00000,1.094984e-07,0.67404,4
423.75477,326.20000,      0.62635, 13.16899,50.00000,20.00000,1.096326e-07,0.67081,4
427.34988,326.90000,      0.58483, 12.52072,50.00000,20.00000,1.093539e-07,0.66758,4
430.94599,327.60000,      0.51529, 11.99174,50.00000,20.00000,1.095763e-07,0.66436,4
434.52737,328.30000,      0.43568, 11.55096,50.00000,20.00000,1.096512e-07,0.66117,4
438.10382,329.00000,      0.36045, 11.16343,50.00000,20.00000,1.097271e-07,0.65801,4
441.68213,329.70000,      0.28729, 10.91290,50.00000,20.00000,1.095307e-07,0.65486,4
445.24438,330.40000,      0.21009, 10.75452,50.00000,20.00000,1.093989e-07,0.65174,4
448.81655,331.10000,      0.14075, 10.67529,50.00000,20.00000,1.093345e-07,0.64864,4
452.36420,331.80000, 8.032938e-02, 10.66535,50.00000,20.00000,1.097292e-07,0.64557,4
455.90817,332.50000, 2.170163e-02, 10.67621,50.00000,20.00000,1.094040e-07,0.64253,4
459.42567,333.20000,-2.934638e-02, 10.70994,50.00000,20.00000,1.100802e-07,0.63953,4
462.96373,333.90000,-8.416989e-02, 10.72982,50.00000,20.00000,1.096809e-07,0.63653,4
466.49188,334.60000,     -0.14228, 10.76936,50.00000,20.00000,1.096002e-07,0.63356,4
470.00935,335.30000,     -0.20087, 10.77778,50.00000,20.00000,1.095100e-07,0.63063,4
473.52812,336.00000,     -0.25708, 10.81738,50.00000,20.00000,1.092280e-07,0.62771,4
477.04558,336.70000,     -0.32026, 10.82251,50.00000,20.00000,1.096144e-07,0.62481,4
480.54816,337.40000,     -0.38590, 10.86213,50.00000,20.00000,1.093484e-07,0.62195,4
484.04761,338.10000,     -0.44606, 10.88202,50.00000,20.00000,1.094610e-07,0.61911,4
487.56621,338.80000,     -0.50742, 10.92164,50.00000,20.00000,1.089486e-07,0.61628,4
491.06238,339.50000,     -0.57409, 10.93992,50.00000,20.00000,1.089057e-07,0.61349,4
494.56043,340.20000,     -0.64292, 10.98131,50.00000,20.00000,1.092225e-07,0.61072,4
498.07320,340.90000,     -0.70794, 11.00102,50.00000,20.00000,1.093900e-07,0.60796,4
501.55539,341.60000,     -0.77855, 11.02091,50.00000,20.00000,1.091899e-07,0.60525,4
505.06363,342.30000,     -0.84448, 11.04079,50.00000,20.00000,1.091423e-07,0.60254,4
508.58067,343.00000,     -0.91342, 11.06067,50.00000,20.00000,1.091469e-07,0.59985,4
512.08194,343.70000,     -0.98774, 11.07061,50.00000,20.00000,1.090275e-07,0.59719,4
515.57210,344.40000,     -1.06487, 11.10019,50.00000,20.00000,1.090158e-07,0.59456,4
519.07090,345.10000,     -1.13117, 11.12018,50.00000,20.00000,1.092734e-07,0.59195,4
522.57389,345.80000,     -1.20127, 11.14007,50.00000,20.00000,1.090114e-07,0.58936,4
526.07108,346.50000,     -1.27549, 11.17968,50.00000,20.00000,1.094621e-07,0.58680,4
529.57982,347.20000,     -1.34802, 11.19961,50.00000,20.00000,1.090876e-07,0.58425,4
533.07324,347.90000,     -1.41858, 11.22944,50.00000,20.00000,1.091939e-07,0.58174,4
536.57695,348.60000,     -1.48815, 11.22939,50.00000,20.00000,1.092919e-07,0.57925,4
540.08337,349.30000,     -1.56756, 11.24912,50.00000,20.00000,1.093394e-07,0.57677,4
543.56861,350.00000,     -1.64015, 11.25906,50.00000,20.00000,1.091948e-07,0.57434,4
547.07491,350.70000,     -1.71326, 11.27899,50.00000,20.00000,1.094583e-07,0.57191,4
550.57034,351.40000,     -1.78279, 11.29883,50.00000,20.00000,1.092224e-07,0.56952,4
554.07558,352.10000,     -1.85525, 11.32851,50.00000,20.00000,1.091150e-07,0.56714,4
557.56565,352.80000,     -1.92597, 11.35336,50.00000,20.00000,1.089359e-07,0.56479,4
561.06275,353.50000,     -1.99649, 11.36330,50.00000,20.00000,1.092775e-07,0.56247,4
564.57269,354.20000,     -2.06968, 11.38320,50.00000,20.00000,1.093331e-07,0.56016,4
568.07113,354.90000,     -2.14496, 11.40385,50.00000,20.00000,1.095120e-07,0.55788,4
571.57326,355.60000,     -2.21190, 11.40307,50.00000,20.00000,1.094338e-07,0.55562,4
575.07253,356.30000,     -2.28533, 11.43865,50.00000,20.00000,1.092614e-07,0.55338,4
578.57646,357.00000,     -2.35666, 11.44269,50.00000,20.00000,1.095487e-07,0.55117,4
582.07169,357.70000,     -2.42366, 11.46257,50.00000,20.00000,1.092586e-07,0.54898,4
585.57808,358.40000,     -2.48720, 11.47251,50.00000,20.00000,1.094050e-07,0.54681,4
589.07941,359.10000,     -2.55898, 11.47524,50.00000,20.00000,1.095582e-07,0.54466,4
592.58914,359.80000,     -2.62658, 11.49228,50.00000,20.00000,1.091795e-07,0.54253,4
596.09185,360.50000,     -2.69428, 11.54180,50.00000,20.00000,1.093245e-07,0.54043,4
599.59102,361.20000,     -2.76051, 11.53699,50.00000,20.00000,1.094737e-07,0.53835,4
603.08370,361.90000,     -2.82453, 11.55687,50.00000,20.00000,1.098550e-07,0.53630,4
606.59349,362.60000,     -2.88610, 11.57661,50.00000,20.00000,1.094384e-07,0.53426,4
610.08969,363.30000,     -2.94978, 11.59647,50.00000,20.00000,1.094856e-07,0.53224,4
613.59563,364.00000,     -3.01364, 11.61671,50.00000,20.00000,1.096111e-07,0.53024,4
617.09833,364.70000,     -3.06794, 11.63129,50.00000,20.00000,1.089231e-07,0.52827,4
620.59318,365.40000,     -3.13236, 11.63626,50.00000,20.00000,1.099065e-07,0.52632,4
624.11172,366.10000,     -3.19157, 11.65599,50.00000,20.00000,1.094338e-07,0.52437,4
627.61423,366.80000,     -3.24867, 11.67588,50.00000,20.00000,1.089623e-07,0.52246,4
631.12834,367.50000,     -3.30316, 11.69079,50.00000,20.00000,1.098995e-07,0.52055,4
634.62468,368.20000,     -3.36375, 11.71068,50.00000,20.00000,1.097540e-07,0.51868,4
638.17803,368.90000,     -3.41389, 11.68581,50.00000,20.00000,1.098973e-07,0.51679,4
641.63123,369.60000,     -3.46895, 11.70572,50.00000,20.00000,1.095997e-07,0.51498,4
645.14550,370.30000,     -3.52340, 11.72062,50.00000,20.00000,1.096025e-07,0.51315,4
648.63473,371.00000,     -3.57409, 11.73056,50.00000,20.00000,1.092551e-07,0.51135,4
652.15183,371.70000,     -3.62053, 11.74035,50.00000,20.00000,1.094699e-07,0.50956,4
655.64842,372.40000,     -3.67762, 11.76026,50.00000,20.00000,1.101083e-07,0.50779,4
659.15856,373.10000,     -3.72202, 11.74074,50.00000,20.00000,1.093440e-07,0.50604,4
662.64832,373.80000,     -3.77132, 11.76025,50.00000,20.00000,1.091278e-07,0.50431,4
666.15613,374.50000,     -3.81538, 11.77514,50.00000,20.00000,1.089039e-07,0.50258,4
669.67120,375.20000,     -3.86093, 11.78348,50.00000,20.00000,1.096088e-07,0.50087,4
673.16291,375.90000,     -3.90525, 11.78826,50.00000,20.00000,1.088681e-07,0.49919,4
676.66979,376.60000,     -3.94669, 11.80312,50.00000,20.00000,1.091655e-07,0.49751,4
680.17747,377.30000,     -3.98482, 11.81316,50.00000,20.00000,1.096875e-07,0.49585,4
683.67781,378.00000,     -4.03167, 11.81307,50.00000,20.00000,1.092019e-07,0.49420,4
687.18694,378.70000,     -4.06913, 11.83304,50.00000,20.00000,1.099807e-07,0.49257,4
690.69287,379.40000,     -4.11036, 11.83304,50.00000,20.00000,1.096793e-07,0.49095,4
694.20669,380.10000,     -4.15139, 11.84528,50.00000,20.00000,1.086924e-07,0.48934,4
697.71540,380.80000,     -4.19564, 11.85789,50.00000,20.00000,1.094780e-07,0.48774,4
701.20433,381.50000,     -4.24188, 11.87763,50.00000,20.00000,1.098142e-07,0.48616,4
704.70619,382.20000,     -4.28529, 11.88260,50.00000,20.00000,1.092541e-07,0.48459,4
708.20812,382.90000,     -4.32631, 11.88252,50.00000,20.00000,1.101109e-07,0.48304,4
711.72130,383.60000,     -4.37537, 11.90746,50.00000,20.00000,1.096313e-07,0.48149,4
715.23080,384.30000,     -4.42550, 11.91243,50.00000,20.00000,1.095096e-07,0.47995,4
718.73450,385.00000,     -4.47924, 11.89254,50.00000,20.00000,1.092284e-07,0.47842,4
722.22969,385.70000,     -4.53618, 11.90756,50.00000,20.00000,1.097664e-07,0.47690,4
725.72678,386.40000,     -4.58917, 11.94728,50.00000,20.00000,1.101040e-07,0.47540,4
729.25493,387.10000,     -4.65099, 11.92733,50.00000,20.00000,1.096430e-07,0.47389,4
732.75348,387.80000,     -4.71755, 11.93231,50.00000,20.00000,1.090339e-07,0.47240,4
736.25291,388.50000,     -4.78627, 11.92520,50.00000,20.00000,1.100773e-07,0.47092,4
739.75370,389.20000,     -4.85550, 11.94722,50.00000,20.00000,1.095488e-07,0.46945,4
743.25948,389.90000,     -4.92479, 11.95701,50.00000,20.00000,1.094419e-07,0.46798,4
746.77023,390.60000,     -5.00502, 11.98683,50.00000,20.00000,1.099245e-07,0.46652,4
750.27320,391.30000,     -5.08508, 11.97690,50.00000,20.00000,1.095787e-07,0.46506,4
753.78720,392.00000,     -5.16909, 11.96696,50.00000,20.00000,1.099483e-07,0.46361,4
757.28823,392.70000,     -5.25385, 11.96619,50.00000,20.00000,1.099560e-07,0.46217,4
760.79137,393.40000,     -5.34414, 11.98680,50.00000,20.00000,1.101452e-07,0.46073,4
764.29237,394.10000,     -5.43383, 11.99678,50.00000,20.00000,1.101514e-07,0.45930,4
767.79168,394.80000,     -5.52627, 12.00673,50.00000,20.00000,1.102492e-07,0.45787,4
771.29728,395.50000,     -5.61733, 12.02661,50.00000,20.00000,1.095474e-07,0.45645,4
774.79458,396.20000,     -5.70861, 12.03015,50.00000,20.00000,1.098664e-07,0.45503,4
778.29436,396.90000,     -5.80178, 12.03373,50.00000,20.00000,1.096117e-07,0.45361,4
781.79437,397.60000,     -5.89747, 12.03515,50.00000,20.00000,1.094186e-07,0.45220,4
785.30908,398.30000,     -5.99494, 12.05630,50.00000,20.00000,1.099060e-07,0.45079,4
788.80098,399.00000,     -6.08582, 12.08617,50.00000,20.00000,1.100952e-07,0.44938,4
792.30110,399.70000,     -6.18277, 12.07121,50.00000,20.00000,1.101940e-07,0.44797,4
795.80965,400.40000,     -6.27992, 12.08611,50.00000,20.00000,1.102699e-07,0.44657,4
798.31808,400.90000,     -6.35075, 12.10599,50.00000,20.00000,1.103092e-07,0.44556,4