File: pc_x_polymers/ExpDat_2024_01_20_SL_001G-TGA-dynamic.csv
#EXPORTTYPE:                 ,DATA ALL
#FILE:                       ,2024_01_20_SL_001G-TGA-dynamic.ngb-ss5
#FORMAT:                     ,NETZSCH5
#FTYPE:                      ,ASCII
#IDENTITY:                   ,PS
#DECIMAL:                    ,POINT
#SEPARATOR:                  ,COMMA
#MTYPE:                      ,DSC
#INSTRUMENT:                 ,NETZSCH STA 449F5
#PROJECT:                    ,
#DATE/TIME:                  ,1/21/2024 5:46:09 AM (UTC-5)
#CORR. FILE:                 ,
#TEMPCAL:                    ,28-06-2023 13:26
#SENSITIVITY:                ,28-06-2023 13:53
#LABORATORY:                 ,Tran/AAG
#OPERATOR:                   ,Stanley
#REMARK:                     ,
#SAMPLE:                     ,001G
#SAMPLE MASS /mg:            ,6.81
#MATERIAL:                   ,
#REFERENCE:                  ,Empty Al2O3
#REFERENCE MASS /mg:         ,0
#TYPE OF CRUCIBLE:           ,Al2O3 85 ‘l, open
#SAMPLE CRUCIBLE MASS /mg:   ,0
#REFERENCE CRUCIBLE MASS /mg:,136.57
#DSC RANGE /‘V:              ,5000
#TG RANGE /mg:               ,35000
#TAU-R:                      ,---
#CORR. CODE:                 ,000
#EXO:                        ,-1
#RANGE:                      ,20›C....800›C/0.0....5.0K/min
#SEGMENT:                    ,S1-4/4
#SEG. 1:                     ,20›C/5.0(K/min)/100›C
#SEG. 2:                     ,100›C/00:05/100›C
#SEG. 3:                     ,100›C/1.0(K/min)/400›C
#SEG. 4:                     ,400›C/5.0(K/min)/800›C

##Temp./›C,Time/min,DSC/(mW/mg),Mass/%,Gas Flow(purge2)/(ml/min),Gas Flow(protective)/(ml/min),TIC(scan:1)/A,Sensit./(uV/mW),Segment
 31.98000,  0.00000,-6.099333e-02,100.00000,50.00000,20.00000,1.101954e-07,0.92391,1
 32.05671,  0.70000,-4.071787e-02,100.12985,50.00000,20.00000,1.102818e-07,0.92392,1
 32.33600,  1.40000,-8.002574e-03,100.32394,50.00000,20.00000,1.103129e-07,0.92397,1
 32.71886,  2.10000, 7.698292e-03,100.40360,50.00000,20.00000,1.101930e-07,0.92403,1
 33.18400,  2.80000, 2.642869e-02,100.54332,50.00000,20.00000,1.099060e-07,0.92411,1
 33.92559,  3.50000, 7.509458e-02,100.86813,50.00000,20.00000,1.096427e-07,0.92423,1
 35.11300,  4.20000,      0.15185,101.33730,50.00000,20.00000,1.095431e-07,0.92442,1
 36.78257,  4.90000,      0.24748,101.83519,50.00000,20.00000,1.092041e-07,0.92466,1
 38.94300,  5.60000,      0.34568,102.35565,50.00000,20.00000,1.092440e-07,0.92495,1
 41.58539,  6.30000,      0.44503,102.87179,50.00000,20.00000,1.085847e-07,0.92526,1
 44.65100,  7.00000,      0.53960,103.33245,50.00000,20.00000,1.088663e-07,0.92557,1
 48.10457,  7.70000,      0.63074,103.75218,50.00000,20.00000,1.085421e-07,0.92584,1
 51.85100,  8.40000,      0.71269,104.12658,50.00000,20.00000,1.085822e-07,0.92605,1
 55.86302,  9.10000,      0.78471,104.45399,50.00000,20.00000,1.082010e-07,0.92617,1
 60.07400,  9.80000,      0.84514,104.73451,50.00000,20.00000,1.083667e-07,0.92620,1
 64.41990, 10.50000,      0.89426,104.96743,50.00000,20.00000,1.080603e-07,0.92610,1
 68.80400, 11.20000,      0.93109,105.15653,50.00000,20.00000,1.077969e-07,0.92589,1
 73.18313, 11.90000,      0.96224,105.31893,50.00000,20.00000,1.077552e-07,0.92556,1
 77.57600, 12.60000,      0.98589,105.46050,50.00000,20.00000,1.077053e-07,0.92511,1
 81.91911, 13.30000,      1.00382,105.58328,50.00000,20.00000,1.073568e-07,0.92455,1
 86.21400, 14.00000,      1.01569,105.68150,50.00000,20.00000,1.076265e-07,0.92388,1
 90.44693, 14.70000,      1.02631,105.76127,50.00000,20.00000,1.075192e-07,0.92312,1
 94.61500, 15.40000,      1.03556,105.84258,50.00000,20.00000,1.071280e-07,0.92227,1
 98.67659, 16.10000,      1.04423,105.91320,50.00000,20.00000,1.072982e-07,0.92135,2
102.04238, 16.80000,      0.88095,105.71654,50.00000,20.00000,1.070723e-07,0.92051,2
104.29792, 17.50000,      0.62005,105.30609,50.00000,20.00000,1.070648e-07,0.91991,2
105.87501, 18.20000,      0.42205,104.99589,50.00000,20.00000,1.071648e-07,0.91948,2
107.01762, 18.90000,      0.30046,104.79218,50.00000,20.00000,1.069822e-07,0.91916,2
107.75851, 19.60000,      0.18869,104.56619,50.00000,20.00000,1.069755e-07,0.91894,2
108.07573, 20.30000, 8.030408e-02,104.32056,50.00000,20.00000,1.070627e-07,0.91885,2
108.04004, 21.00000,-8.568721e-03,104.11367,50.00000,20.00000,1.071497e-07,0.91886,3
107.83781, 21.70000,-5.289460e-02,103.98122,50.00000,20.00000,1.070319e-07,0.91892,3
107.62315, 22.40000,-5.437375e-02,103.89914,50.00000,20.00000,1.065100e-07,0.91898,3
107.44651, 23.10000,-5.154734e-02,103.86494,50.00000,20.00000,1.066564e-07,0.91903,3
107.25814, 23.80000,-4.961727e-02,103.81420,50.00000,20.00000,1.063228e-07,0.91909,3
107.10187, 24.50000,-3.932472e-02,103.78983,50.00000,20.00000,1.065403e-07,0.91913,3
107.02911, 25.20000,-2.086148e-02,103.77924,50.00000,20.00000,1.064073e-07,0.91915,3
107.03024, 25.90000, 2.713709e-03,103.80795,50.00000,20.00000,1.064635e-07,0.91915,3
107.13788, 26.60000, 2.629885e-02,103.81411,50.00000,20.00000,1.061825e-07,0.91912,3
107.31792, 27.30000, 5.003280e-02,103.83730,50.00000,20.00000,1.059766e-07,0.91907,3
107.59456, 28.00000, 7.215466e-02,103.86886,50.00000,20.00000,1.060144e-07,0.91899,3
107.92574, 28.70000, 9.402419e-02,103.88990,50.00000,20.00000,1.059404e-07,0.91890,3
108.34954, 29.40000,      0.11400,103.90900,50.00000,20.00000,1.059663e-07,0.91877,3
108.82494, 30.10000,      0.13199,103.94241,50.00000,20.00000,1.059282e-07,0.91863,3
109.38029, 30.80000,      0.14733,103.95052,50.00000,20.00000,1.058414e-07,0.91847,3
109.97833, 31.50000,      0.16052,103.96990,50.00000,20.00000,1.055785e-07,0.91829,3
110.58831, 32.20000,      0.17254,103.99031,50.00000,20.00000,1.056895e-07,0.91810,3
111.25490, 32.90000,      0.18336,104.00945,50.00000,20.00000,1.056627e-07,0.91790,3
111.93025, 33.60000,      0.19105,104.01020,50.00000,20.00000,1.058755e-07,0.91769,3
112.63907, 34.30000,      0.19692,104.02270,50.00000,20.00000,1.054823e-07,0.91746,3
113.35913, 35.00000,      0.20190,104.03516,50.00000,20.00000,1.057087e-07,0.91723,3
114.07989, 35.70000,      0.20563,104.04604,50.00000,20.00000,1.054430e-07,0.91700,3
114.82325, 36.40000,      0.20860,104.05018,50.00000,20.00000,1.052670e-07,0.91676,3
115.56481, 37.10000,      0.21074,104.05962,50.00000,20.00000,1.058363e-07,0.91651,3
116.29505, 37.80000,      0.21263,104.06025,50.00000,20.00000,1.054628e-07,0.91627,3
117.04104, 38.50000,      0.21450,104.06952,50.00000,20.00000,1.056379e-07,0.91601,3
117.78019, 39.20000,      0.21532,104.07005,50.00000,20.00000,1.051080e-07,0.91576,3
118.52200, 39.90000,      0.21668,104.08515,50.00000,20.00000,1.053821e-07,0.91550,3
119.24599, 40.60000,      0.21653,104.09996,50.00000,20.00000,1.051991e-07,0.91525,3
119.97859, 41.30000,      0.21729,104.09927,50.00000,20.00000,1.052530e-07,0.91499,3
120.70200, 42.00000,      0.21728,104.09965,50.00000,20.00000,1.051649e-07,0.91473,3
121.41641, 42.70000,      0.21845,104.10999,50.00000,20.00000,1.049876e-07,0.91447,3
122.13015, 43.40000,      0.21788,104.11004,50.00000,20.00000,1.052295e-07,0.91421,3
122.86005, 44.10000,      0.21836,104.11107,50.00000,20.00000,1.054815e-07,0.91394,3
123.56726, 44.80000,      0.21862,104.12980,50.00000,20.00000,1.048782e-07,0.91368,3
124.27822, 45.50000,      0.21903,104.12996,50.00000,20.00000,1.048620e-07,0.91341,3
124.96925, 46.20000,      0.21801,104.12985,50.00000,20.00000,1.050172e-07,0.91315,3
125.67410, 46.90000,      0.22011,104.15453,50.00000,20.00000,1.052054e-07,0.91288,3
126.38920, 47.60000,      0.22207,104.16980,50.00000,20.00000,1.051260e-07,0.91260,3
127.09955, 48.30000,      0.22293,104.18005,50.00000,20.00000,1.045674e-07,0.91232,3
127.80721, 49.00000,      0.22295,104.17956,50.00000,20.00000,1.047792e-07,0.91204,3
128.49610, 49.70000,      0.22314,104.19011,50.00000,20.00000,1.047055e-07,0.91177,3
129.20722, 50.40000,      0.22370,104.18958,50.00000,20.00000,1.049678e-07,0.91148,3
129.89118, 51.10000,      0.22463,104.20948,50.00000,20.00000,1.044913e-07,0.91120,3
130.59722, 51.80000,      0.22519,104.22457,50.00000,20.00000,1.046616e-07,0.91091,3
131.29696, 52.50000,      0.22713,104.21841,50.00000,20.00000,1.045887e-07,0.91062,3
132.01324, 53.20000,      0.22792,104.24130,50.00000,20.00000,1.048481e-07,0.91033,3
132.69754, 53.90000,      0.22826,104.25221,50.00000,20.00000,1.046894e-07,0.91004,3
133.38703, 54.60000,      0.22892,104.29100,50.00000,20.00000,1.049268e-07,0.90975,3
134.09818, 55.30000,      0.22985,104.29513,50.00000,20.00000,1.046721e-07,0.90944,3
134.79804, 56.00000,      0.23180,104.30099,50.00000,20.00000,1.046837e-07,0.90914,3
135.50143, 56.70000,      0.23208,104.31002,50.00000,20.00000,1.044907e-07,0.90884,3
136.18625, 57.40000,      0.23318,104.34088,50.00000,20.00000,1.045233e-07,0.90854,3
136.88938, 58.10000,      0.23394,104.34320,50.00000,20.00000,1.046389e-07,0.90823,3
137.58703, 58.80000,      0.23470,104.36740,50.00000,20.00000,1.047100e-07,0.90792,3
138.30077, 59.50000,      0.23461,104.39091,50.00000,20.00000,1.043959e-07,0.90760,3
138.99020, 60.20000,      0.23511,104.40728,50.00000,20.00000,1.044038e-07,0.90728,3
139.69748, 60.90000,      0.23703,104.39501,50.00000,20.00000,1.044033e-07,0.90696,3
140.39515, 61.60000,      0.23737,104.39896,50.00000,20.00000,1.042971e-07,0.90664,3
141.11785, 62.30000,      0.23809,104.44146,50.00000,20.00000,1.046713e-07,0.90631,3
141.79213, 63.00000,      0.23853,104.44552,50.00000,20.00000,1.044827e-07,0.90600,3
142.52865, 63.70000,      0.23890,104.46937,50.00000,20.00000,1.045381e-07,0.90565,3
143.21433, 64.40000,      0.23957,104.46543,50.00000,20.00000,1.044116e-07,0.90533,3
143.90564, 65.10000,      0.24049,104.48491,50.00000,20.00000,1.044244e-07,0.90500,3
144.60930, 65.80000,      0.24136,104.50529,50.00000,20.00000,1.042188e-07,0.90466,3
145.31774, 66.50000,      0.24243,104.50388,50.00000,20.00000,1.043403e-07,0.90432,3
146.00510, 67.20000,      0.24241,104.52492,50.00000,20.00000,1.046635e-07,0.90399,3
146.70823, 67.90000,      0.24287,104.55972,50.00000,20.00000,1.047369e-07,0.90364,3
147.39606, 68.60000,      0.24395,104.58164,50.00000,20.00000,1.044438e-07,0.90330,3
148.09647, 69.30000,      0.24352,104.58700,50.00000,20.00000,1.041891e-07,0.90296,3
148.80710, 70.00000,      0.24440,104.59681,50.00000,20.00000,1.044392e-07,0.90260,3
149.50126, 70.70000,      0.24490,104.61843,50.00000,20.00000,1.040944e-07,0.90226,3
150.20007, 71.40000,      0.24583,104.61660,50.00000,20.00000,1.045553e-07,0.90190,3
150.91254, 72.10000,      0.24581,104.64113,50.00000,20.00000,1.043267e-07,0.90154,3
151.61215, 72.80000,      0.24577,104.63817,50.00000,20.00000,1.045291e-07,0.90118,3
152.30908, 73.50000,      0.24788,104.64765,50.00000,20.00000,1.043047e-07,0.90082,3
153.02313, 74.20000,      0.24685,104.66318,50.00000,20.00000,1.041744e-07,0.90045,3
153.71417, 74.90000,      0.24682,104.68508,50.00000,20.00000,1.044435e-07,0.90009,3
154.41709, 75.60000,      0.24580,104.70301,50.00000,20.00000,1.040110e-07,0.89972,3
155.11176, 76.30000,      0.24647,104.71447,50.00000,20.00000,1.045311e-07,0.89936,3
155.82005, 77.00000,      0.24638,104.70793,50.00000,20.00000,1.043811e-07,0.89898,3
156.53137, 77.70000,      0.24671,104.73048,50.00000,20.00000,1.045554e-07,0.89860,3
157.21716, 78.40000,      0.24620,104.74787,50.00000,20.00000,1.048170e-07,0.89823,3
157.92225, 79.10000,      0.24597,104.77548,50.00000,20.00000,1.041859e-07,0.89785,3
158.62314, 79.80000,      0.24579,104.76264,50.00000,20.00000,1.042001e-07,0.89747,3
159.31790, 80.50000,      0.24495,104.79711,50.00000,20.00000,1.040479e-07,0.89709,3
160.02308, 81.20000,      0.24351,104.80768,50.00000,20.00000,1.041678e-07,0.89670,3
160.72916, 81.90000,      0.24209,104.83148,50.00000,20.00000,1.043923e-07,0.89631,3
161.42418, 82.60000,      0.24184,104.82746,50.00000,20.00000,1.041654e-07,0.89593,3
162.12341, 83.30000,      0.24168,104.84743,50.00000,20.00000,1.043070e-07,0.89554,3
162.82726, 84.00000,      0.24030,104.86755,50.00000,20.00000,1.043538e-07,0.89514,3
163.52893, 84.70000,      0.23887,104.86555,50.00000,20.00000,1.042538e-07,0.89474,3
164.22713, 85.40000,      0.23788,104.89728,50.00000,20.00000,1.042295e-07,0.89435,3
164.93031, 86.10000,      0.23708,104.91733,50.00000,20.00000,1.045780e-07,0.89394,3
165.63006, 86.80000,      0.23484,104.91734,50.00000,20.00000,1.042620e-07,0.89354,3
166.32681, 87.50000,      0.23389,104.92681,50.00000,20.00000,1.042133e-07,0.89314,3
167.03828, 88.20000,      0.23129,104.94229,50.00000,20.00000,1.045838e-07,0.89273,3
167.72410, 88.90000,      0.22918,104.95477,50.00000,20.00000,1.044600e-07,0.89233,3
168.42214, 89.60000,      0.22761,104.96212,50.00000,20.00000,1.040899e-07,0.89192,3
169.12632, 90.30000,      0.22618,104.99661,50.00000,20.00000,1.042385e-07,0.89150,3
169.82326, 91.00000,      0.22404,105.00202,50.00000,20.00000,1.040825e-07,0.89109,3
170.52609, 91.70000,      0.22309,105.00065,50.00000,20.00000,1.040306e-07,0.89067,3
171.25119, 92.40000,      0.22188,105.01703,50.00000,20.00000,1.045602e-07,0.89024,3
171.92564, 93.10000,      0.21974,105.02770,50.00000,20.00000,1.040069e-07,0.88983,3
172.63108, 93.80000,      0.21704,105.04684,50.00000,20.00000,1.044000e-07,0.88941,3
173.32694, 94.50000,      0.21585,105.05603,50.00000,20.00000,1.041631e-07,0.88898,3
174.01823, 95.20000,      0.21346,105.08677,50.00000,20.00000,1.039531e-07,0.88856,3
174.73119, 95.90000,      0.21113,105.09720,50.00000,20.00000,1.041479e-07,0.88813,3
175.42322, 96.60000,      0.20939,105.10680,50.00000,20.00000,1.041486e-07,0.88770,3
176.12782, 97.30000,      0.20669,105.10348,50.00000,20.00000,1.043717e-07,0.88727,3
176.83325, 98.00000,      0.20402,105.14803,50.00000,20.00000,1.042652e-07,0.88683,3
177.52566, 98.70000,      0.20294,105.14802,50.00000,20.00000,1.043994e-07,0.88639,3
178.22721, 99.40000,      0.20284,105.17303,50.00000,20.00000,1.043499e-07,0.88596,3
178.92780,100.10000,      0.20134,105.18782,50.00000,20.00000,1.042117e-07,0.88551,3
179.62729,100.80000,      0.19949,105.21135,50.00000,20.00000,1.042213e-07,0.88507,3
180.32692,101.50000,      0.19708,105.20873,50.00000,20.00000,1.040627e-07,0.88463,3
181.03013,102.20000,      0.19565,105.23112,50.00000,20.00000,1.043965e-07,0.88418,3
181.71518,102.90000,      0.19471,105.23128,50.00000,20.00000,1.044101e-07,0.88374,3
182.42317,103.60000,      0.19431,105.24611,50.00000,20.00000,1.042965e-07,0.88328,3
183.12298,104.30000,      0.19091,105.24435,50.00000,20.00000,1.041300e-07,0.88283,3
183.82206,105.00000,      0.18982,105.27601,50.00000,20.00000,1.043914e-07,0.88238,3
184.52556,105.70000,      0.18714,105.27627,50.00000,20.00000,1.041373e-07,0.88192,3
185.22405,106.40000,      0.18683,105.29602,50.00000,20.00000,1.041528e-07,0.88146,3
185.92702,107.10000,      0.18621,105.32126,50.00000,20.00000,1.042031e-07,0.88100,3
186.61502,107.80000,      0.18397,105.34584,50.00000,20.00000,1.044484e-07,0.88055,3
187.32073,108.50000,      0.18213,105.34753,50.00000,20.00000,1.045701e-07,0.88008,3
188.01027,109.20000,      0.18252,105.37071,50.00000,20.00000,1.043330e-07,0.87962,3
188.71885,109.90000,      0.18122,105.38179,50.00000,20.00000,1.042909e-07,0.87915,3
189.41314,110.60000,      0.18041,105.38066,50.00000,20.00000,1.041873e-07,0.87868,3
190.12709,111.30000,      0.17934,105.37677,50.00000,20.00000,1.046059e-07,0.87820,3
190.83612,112.00000,      0.17806,105.40234,50.00000,20.00000,1.043883e-07,0.87772,3
191.53014,112.70000,      0.17771,105.43445,50.00000,20.00000,1.038823e-07,0.87725,3
192.22219,113.40000,      0.17519,105.44374,50.00000,20.00000,1.045773e-07,0.87678,3
192.93101,114.10000,      0.17230,105.44336,50.00000,20.00000,1.043103e-07,0.87630,3
193.62819,114.80000,      0.17141,105.44875,50.00000,20.00000,1.039929e-07,0.87582,3
194.33076,115.50000,      0.17006,105.47133,50.00000,20.00000,1.046558e-07,0.87534,3
195.02116,116.20000,      0.16814,105.48372,50.00000,20.00000,1.043358e-07,0.87486,3
195.72677,116.90000,      0.16677,105.48888,50.00000,20.00000,1.046633e-07,0.87437,3
196.42707,117.60000,      0.16577,105.49369,50.00000,20.00000,1.042365e-07,0.87388,3
197.12479,118.30000,      0.16419,105.50826,50.00000,20.00000,1.043068e-07,0.87340,3
197.82213,119.00000,      0.16339,105.52873,50.00000,20.00000,1.042825e-07,0.87291,3
198.51887,119.70000,      0.16234,105.53876,50.00000,20.00000,1.044436e-07,0.87242,3
199.22023,120.40000,      0.16138,105.55350,50.00000,20.00000,1.041942e-07,0.87192,3
199.92089,121.10000,      0.16058,105.55710,50.00000,20.00000,1.042733e-07,0.87143,3
200.64407,121.80000,      0.15964,105.56874,50.00000,20.00000,1.041620e-07,0.87091,3
201.32804,122.50000,      0.15637,105.58704,50.00000,20.00000,1.043334e-07,0.87042,3
202.03518,123.20000,      0.15466,105.58839,50.00000,20.00000,1.043370e-07,0.86992,3
202.73445,123.90000,      0.15356,105.58689,50.00000,20.00000,1.039559e-07,0.86942,3
203.43125,124.60000,      0.15240,105.60852,50.00000,20.00000,1.042936e-07,0.86891,3
204.14448,125.30000,      0.15044,105.64025,50.00000,20.00000,1.042278e-07,0.86840,3
204.83316,126.00000,      0.14910,105.62842,50.00000,20.00000,1.043856e-07,0.86790,3
205.53737,126.70000,      0.14838,105.64426,50.00000,20.00000,1.045270e-07,0.86739,3
206.23609,127.40000,      0.14552,105.65344,50.00000,20.00000,1.041369e-07,0.86688,3
206.92895,128.10000,      0.14506,105.67323,50.00000,20.00000,1.041400e-07,0.86637,3
207.63518,128.80000,      0.14246,105.67313,50.00000,20.00000,1.040534e-07,0.86585,3
208.32213,129.50000,      0.14152,105.68320,50.00000,20.00000,1.045354e-07,0.86535,3
209.02109,130.20000,      0.14069,105.67811,50.00000,20.00000,1.042626e-07,0.86483,3
209.72891,130.90000,      0.13932,105.72175,50.00000,20.00000,1.040983e-07,0.86430,3
210.44208,131.60000,      0.13736,105.71964,50.00000,20.00000,1.042923e-07,0.86377,3
211.13995,132.30000,      0.13439,105.74178,50.00000,20.00000,1.039124e-07,0.86325,3
211.82711,133.00000,      0.13401,105.72449,50.00000,20.00000,1.041983e-07,0.86274,3
212.53901,133.70000,      0.13304,105.75666,50.00000,20.00000,1.041139e-07,0.86221,3
213.23608,134.40000,      0.13015,105.74465,50.00000,20.00000,1.042432e-07,0.86168,3
213.93203,135.10000,      0.13061,105.75244,50.00000,20.00000,1.040548e-07,0.86116,3
214.64830,135.80000,      0.12836,105.78453,50.00000,20.00000,1.038717e-07,0.86061,3
215.33492,136.50000,      0.12573,105.78340,50.00000,20.00000,1.044415e-07,0.86009,3
216.03212,137.20000,      0.12486,105.82436,50.00000,20.00000,1.042738e-07,0.85956,3
216.72775,137.90000,      0.12268,105.84144,50.00000,20.00000,1.043015e-07,0.85903,3
217.43325,138.60000,      0.12008,105.83935,50.00000,20.00000,1.041158e-07,0.85849,3
218.12521,139.30000,      0.11922,105.84426,50.00000,20.00000,1.041736e-07,0.85796,3
218.82628,140.00000,      0.11734,105.84434,50.00000,20.00000,1.042495e-07,0.85742,3
219.52641,140.70000,      0.11517,105.86512,50.00000,20.00000,1.040236e-07,0.85688,3
220.22010,141.40000,      0.11474,105.86410,50.00000,20.00000,1.041123e-07,0.85634,3
220.92264,142.10000,      0.11316,105.88860,50.00000,20.00000,1.043625e-07,0.85580,3
221.61929,142.80000,      0.11056,105.90930,50.00000,20.00000,1.037883e-07,0.85526,3
222.33142,143.50000,      0.10879,105.89448,50.00000,20.00000,1.039601e-07,0.85470,3
223.01606,144.20000,      0.10664,105.90917,50.00000,20.00000,1.040204e-07,0.85417,3
223.71756,144.90000,      0.10418,105.91388,50.00000,20.00000,1.040160e-07,0.85362,3
224.40910,145.60000,      0.10217,105.92897,50.00000,20.00000,1.040347e-07,0.85307,3
225.10790,146.30000,      0.10123,105.92757,50.00000,20.00000,1.042091e-07,0.85252,3
225.80315,147.00000,      0.10021,105.94397,50.00000,20.00000,1.041867e-07,0.85197,3
226.50872,147.70000, 9.918893e-02,105.94470,50.00000,20.00000,1.037400e-07,0.85141,3
227.19710,148.40000, 9.624837e-02,105.96870,50.00000,20.00000,1.045688e-07,0.85087,3
227.90577,149.10000, 9.513697e-02,105.96888,50.00000,20.00000,1.043649e-07,0.85030,3
228.61119,149.80000, 9.150619e-02,105.96873,50.00000,20.00000,1.040071e-07,0.84974,3
229.30124,150.50000, 9.077150e-02,105.98039,50.00000,20.00000,1.038544e-07,0.84919,3
230.01009,151.20000, 9.016876e-02,105.98372,50.00000,20.00000,1.042977e-07,0.84862,3
230.71730,151.90000, 8.841475e-02,105.97847,50.00000,20.00000,1.041479e-07,0.84805,3
231.40921,152.60000, 8.566402e-02,105.98881,50.00000,20.00000,1.043231e-07,0.84749,3
232.11508,153.30000, 8.466177e-02,106.00061,50.00000,20.00000,1.044157e-07,0.84692,3
232.82020,154.00000, 8.127807e-02,106.00390,50.00000,20.00000,1.040034e-07,0.84635,3
233.51027,154.70000, 7.898514e-02,105.99205,50.00000,20.00000,1.041197e-07,0.84579,3
234.21312,155.40000, 7.846239e-02,106.00382,50.00000,20.00000,1.039164e-07,0.84522,3
234.91878,156.10000, 7.514380e-02,106.00387,50.00000,20.00000,1.042101e-07,0.84465,3
235.62211,156.80000, 7.154950e-02,106.01881,50.00000,20.00000,1.041522e-07,0.84407,3
236.30357,157.50000, 6.863988e-02,106.00409,50.00000,20.00000,1.040349e-07,0.84352,3
237.01310,158.20000, 6.844757e-02,105.99367,50.00000,20.00000,1.040204e-07,0.84293,3
237.70535,158.90000, 6.642342e-02,106.00158,50.00000,20.00000,1.041011e-07,0.84237,3
238.41722,159.60000, 6.402101e-02,106.01381,50.00000,20.00000,1.043084e-07,0.84178,3
239.10386,160.30000, 6.314658e-02,106.00749,50.00000,20.00000,1.042960e-07,0.84121,3
239.81119,161.00000, 5.958423e-02,106.00382,50.00000,20.00000,1.039600e-07,0.84063,3
240.51183,161.70000, 5.633478e-02,105.99210,50.00000,20.00000,1.042757e-07,0.84005,3
241.20618,162.40000, 5.378303e-02,106.00380,50.00000,20.00000,1.043622e-07,0.83947,3
241.90618,163.10000, 5.433902e-02,106.00607,50.00000,20.00000,1.040771e-07,0.83889,3
242.61009,163.80000, 5.145941e-02,105.98368,50.00000,20.00000,1.040805e-07,0.83830,3
243.30627,164.50000, 4.766288e-02,105.98791,50.00000,20.00000,1.042725e-07,0.83772,3
244.00113,165.20000, 4.549583e-02,105.98547,50.00000,20.00000,1.040969e-07,0.83714,3
244.69966,165.90000, 4.352520e-02,105.94438,50.00000,20.00000,1.040818e-07,0.83655,3
245.40614,166.60000, 4.169203e-02,105.94538,50.00000,20.00000,1.043129e-07,0.83596,3
246.10419,167.30000, 3.928474e-02,105.93396,50.00000,20.00000,1.040592e-07,0.83537,3
246.79622,168.00000, 3.758346e-02,105.94049,50.00000,20.00000,1.040561e-07,0.83478,3
247.50380,168.70000, 3.486140e-02,105.92036,50.00000,20.00000,1.040718e-07,0.83418,3
248.19515,169.40000, 3.184041e-02,105.88571,50.00000,20.00000,1.039206e-07,0.83360,3
248.90089,170.10000, 2.928257e-02,105.86713,50.00000,20.00000,1.039232e-07,0.83300,3
249.59716,170.80000, 2.719197e-02,105.84093,50.00000,20.00000,1.039176e-07,0.83241,3
250.29688,171.50000, 2.371048e-02,105.84326,50.00000,20.00000,1.039085e-07,0.83181,3
251.00425,172.20000, 2.184795e-02,105.82112,50.00000,20.00000,1.038456e-07,0.83121,3
251.70293,172.90000, 2.003517e-02,105.78110,50.00000,20.00000,1.038323e-07,0.83061,3
252.40528,173.60000, 1.795755e-02,105.76109,50.00000,20.00000,1.041535e-07,0.83001,3
253.09969,174.30000, 1.541235e-02,105.73643,50.00000,20.00000,1.038741e-07,0.82941,3
253.79601,175.00000, 1.162768e-02,105.71626,50.00000,20.00000,1.038554e-07,0.82881,3
254.50042,175.70000, 8.890064e-03,105.66431,50.00000,20.00000,1.041996e-07,0.82821,3
255.19924,176.40000, 6.770270e-03,105.64655,50.00000,20.00000,1.038910e-07,0.82761,3
255.89956,177.10000, 5.120147e-03,105.60443,50.00000,20.00000,1.043908e-07,0.82700,3
256.60118,177.80000, 2.582984e-03,105.57514,50.00000,20.00000,1.039040e-07,0.82639,3
257.29977,178.50000,-9.323354e-04,105.54055,50.00000,20.00000,1.041774e-07,0.82579,3
257.99418,179.20000,-2.845400e-03,105.51538,50.00000,20.00000,1.040585e-07,0.82518,3
258.69606,179.90000,-5.511945e-03,105.47776,50.00000,20.00000,1.043315e-07,0.82457,3
259.39330,180.60000,-7.754896e-03,105.41571,50.00000,20.00000,1.039149e-07,0.82397,3
260.09404,181.30000,-1.003568e-02,105.37846,50.00000,20.00000,1.037778e-07,0.82336,3
260.79325,182.00000,-1.307699e-02,105.32912,50.00000,20.00000,1.039556e-07,0.82274,3
261.50615,182.70000,-1.538472e-02,105.29362,50.00000,20.00000,1.037248e-07,0.82212,3
262.20014,183.40000,-1.840360e-02,105.21486,50.00000,20.00000,1.040019e-07,0.82151,3
262.90489,184.10000,-2.080092e-02,105.17540,50.00000,20.00000,1.039647e-07,0.82089,3
263.59907,184.80000,-2.389852e-02,105.11493,50.00000,20.00000,1.037316e-07,0.82028,3
264.30064,185.50000,-2.631899e-02,105.07526,50.00000,20.00000,1.043404e-07,0.81967,3
265.00026,186.20000,-2.913164e-02,105.01545,50.00000,20.00000,1.040911e-07,0.81905,3
265.70516,186.90000,-3.172274e-02,104.97528,50.00000,20.00000,1.038553e-07,0.81843,3
266.39925,187.60000,-3.615754e-02,104.89590,50.00000,20.00000,1.038517e-07,0.81781,3
267.11133,188.30000,-3.836352e-02,104.83343,50.00000,20.00000,1.037333e-07,0.81718,3
267.80023,189.00000,-4.128986e-02,104.77594,50.00000,20.00000,1.040895e-07,0.81657,3
268.50402,189.70000,-4.416726e-02,104.69448,50.00000,20.00000,1.039744e-07,0.81595,3
269.18512,190.40000,-4.754731e-02,104.65671,50.00000,20.00000,1.038489e-07,0.81534,3
269.90037,191.10000,-4.915613e-02,104.57922,50.00000,20.00000,1.041081e-07,0.81470,3
270.59619,191.80000,-5.435217e-02,104.50202,50.00000,20.00000,1.036125e-07,0.81408,3
271.29013,192.50000,-5.656844e-02,104.43066,50.00000,20.00000,1.038900e-07,0.81346,3
271.97115,193.20000,-6.036270e-02,104.35749,50.00000,20.00000,1.039267e-07,0.81285,3
272.69874,193.90000,-6.092098e-02,104.27619,50.00000,20.00000,1.039998e-07,0.81220,3
273.40222,194.60000,-6.418466e-02,104.21794,50.00000,20.00000,1.038995e-07,0.81157,3
274.10436,195.30000,-6.939091e-02,104.14781,50.00000,20.00000,1.039901e-07,0.81094,3
274.79424,196.00000,-7.285240e-02,104.05838,50.00000,20.00000,1.040373e-07,0.81032,3
275.49213,196.70000,-7.595441e-02,103.96685,50.00000,20.00000,1.041452e-07,0.80969,3
276.18832,197.40000,-7.974849e-02,103.89910,50.00000,20.00000,1.038716e-07,0.80907,3
276.90534,198.10000,-8.262495e-02,103.83939,50.00000,20.00000,1.042115e-07,0.80842,3
277.59816,198.80000,-8.583667e-02,103.74324,50.00000,20.00000,1.038261e-07,0.80779,3
278.30126,199.50000,-8.866735e-02,103.67080,50.00000,20.00000,1.038563e-07,0.80716,3
278.99402,200.20000,-9.236909e-02,103.60323,50.00000,20.00000,1.039293e-07,0.80653,3
279.69377,200.90000,-9.596302e-02,103.51891,50.00000,20.00000,1.040599e-07,0.80590,3
280.39204,201.60000,-9.932991e-02,103.42068,50.00000,20.00000,1.040245e-07,0.80526,3
281.08988,202.30000,     -0.10386,103.34334,50.00000,20.00000,1.039974e-07,0.80463,3
281.77919,203.00000,     -0.10618,103.23963,50.00000,20.00000,1.039353e-07,0.80400,3
282.48129,203.70000,     -0.10909,103.17069,50.00000,20.00000,1.036357e-07,0.80336,3
283.18317,204.40000,     -0.11416,103.06017,50.00000,20.00000,1.038847e-07,0.80272,3
283.88880,205.10000,     -0.11594,103.00178,50.00000,20.00000,1.037214e-07,0.80208,3
284.59013,205.80000,     -0.11881,102.90076,50.00000,20.00000,1.039929e-07,0.80144,3
285.29033,206.50000,     -0.12261,102.78977,50.00000,20.00000,1.039907e-07,0.80080,3
285.97636,207.20000,     -0.12713,102.71985,50.00000,20.00000,1.036844e-07,0.80017,3
286.68116,207.90000,     -0.13007,102.62522,50.00000,20.00000,1.037570e-07,0.79952,3
287.37624,208.60000,     -0.13308,102.52363,50.00000,20.00000,1.037023e-07,0.79889,3
288.08587,209.30000,     -0.13503,102.41962,50.00000,20.00000,1.038193e-07,0.79823,3
288.79207,210.00000,     -0.13974,102.32112,50.00000,20.00000,1.036302e-07,0.79759,3
289.48769,210.70000,     -0.14493,102.22301,50.00000,20.00000,1.036240e-07,0.79695,3
290.18011,211.40000,     -0.14730,102.10157,50.00000,20.00000,1.035955e-07,0.79631,3
290.88822,212.10000,     -0.14970,101.99240,50.00000,20.00000,1.036734e-07,0.79566,3
291.58309,212.80000,     -0.15317,101.88236,50.00000,20.00000,1.036286e-07,0.79501,3
292.29303,213.50000,     -0.15667,101.76867,50.00000,20.00000,1.039590e-07,0.79436,3
292.97616,214.20000,     -0.15949,101.66118,50.00000,20.00000,1.036252e-07,0.79373,3
293.68074,214.90000,     -0.16414,101.51777,50.00000,20.00000,1.038341e-07,0.79308,3
294.38327,215.60000,     -0.16767,101.42237,50.00000,20.00000,1.037285e-07,0.79243,3
295.08050,216.30000,     -0.17134,101.28789,50.00000,20.00000,1.037673e-07,0.79178,3
295.78021,217.00000,     -0.17431,101.15971,50.00000,20.00000,1.037573e-07,0.79113,3
296.48654,217.70000,     -0.17885,101.03221,50.00000,20.00000,1.036358e-07,0.79047,3
297.17332,218.40000,     -0.18240,100.90719,50.00000,20.00000,1.038591e-07,0.78984,3
297.88408,219.10000,     -0.18647,100.76411,50.00000,20.00000,1.039090e-07,0.78918,3
298.57403,219.80000,     -0.19136,100.60503,50.00000,20.00000,1.040242e-07,0.78853,3
299.27168,220.50000,     -0.19391,100.51495,50.00000,20.00000,1.035048e-07,0.78788,3
299.97025,221.20000,     -0.19936,100.34262,50.00000,20.00000,1.037609e-07,0.78723,3
300.67248,221.90000,     -0.20449,100.20346,50.00000,20.00000,1.037223e-07,0.78658,3
301.36918,222.60000,     -0.20740,100.04174,50.00000,20.00000,1.038219e-07,0.78593,3
302.07361,223.30000,     -0.20956, 99.89489,50.00000,20.00000,1.038920e-07,0.78527,3
302.78010,224.00000,     -0.21503, 99.75268,50.00000,20.00000,1.036632e-07,0.78461,3
303.47271,224.70000,     -0.22068, 99.58912,50.00000,20.00000,1.039137e-07,0.78396,3
304.16425,225.40000,     -0.22455, 99.44857,50.00000,20.00000,1.035256e-07,0.78332,3
304.87190,226.10000,     -0.22695, 99.28535,50.00000,20.00000,1.037512e-07,0.78265,3
305.56521,226.80000,     -0.23294, 99.12315,50.00000,20.00000,1.038163e-07,0.78200,3
306.26769,227.50000,     -0.23654, 98.97851,50.00000,20.00000,1.037245e-07,0.78134,3
306.96808,228.20000,     -0.24093, 98.80900,50.00000,20.00000,1.034045e-07,0.78069,3
307.67552,228.90000,     -0.24501, 98.65797,50.00000,20.00000,1.036771e-07,0.78002,3
308.37412,229.60000,     -0.24811, 98.48363,50.00000,20.00000,1.038667e-07,0.77937,3
309.07562,230.30000,     -0.25202, 98.31906,50.00000,20.00000,1.039407e-07,0.77871,3
309.78511,231.00000,     -0.25860, 98.15119,50.00000,20.00000,1.038864e-07,0.77804,3
310.45944,231.70000,     -0.26305, 98.00441,50.00000,20.00000,1.039409e-07,0.77741,3
311.17513,232.40000,     -0.26798, 97.82891,50.00000,20.00000,1.037924e-07,0.77673,3
311.86601,233.10000,     -0.27188, 97.65557,50.00000,20.00000,1.037234e-07,0.77608,3
312.58313,233.80000,     -0.27552, 97.51676,50.00000,20.00000,1.036145e-07,0.77540,3
313.27364,234.50000,     -0.28135, 97.33027,50.00000,20.00000,1.036941e-07,0.77475,3
313.97108,235.20000,     -0.28424, 97.15951,50.00000,20.00000,1.035971e-07,0.77410,3
314.66816,235.90000,     -0.28888, 96.99367,50.00000,20.00000,1.036908e-07,0.77344,3
315.37222,236.60000,     -0.29357, 96.83226,50.00000,20.00000,1.037613e-07,0.77277,3
316.07989,237.30000,     -0.29841, 96.65383,50.00000,20.00000,1.037678e-07,0.77210,3
316.76509,238.00000,     -0.30467, 96.48347,50.00000,20.00000,1.035530e-07,0.77146,3
317.46482,238.70000,     -0.30934, 96.31357,50.00000,20.00000,1.039187e-07,0.77079,3
318.17316,239.40000,     -0.31247, 96.15441,50.00000,20.00000,1.038869e-07,0.77012,3
318.87334,240.10000,     -0.31752, 95.96464,50.00000,20.00000,1.037465e-07,0.76946,3
319.58016,240.80000,     -0.32177, 95.79054,50.00000,20.00000,1.037204e-07,0.76879,3
320.28295,241.50000,     -0.32662, 95.61698,50.00000,20.00000,1.036559e-07,0.76812,3
320.98125,242.20000,     -0.33253, 95.43339,50.00000,20.00000,1.034764e-07,0.76746,3
321.68072,242.90000,     -0.33726, 95.25399,50.00000,20.00000,1.037127e-07,0.76680,3
322.37826,243.60000,     -0.34202, 95.08464,50.00000,20.00000,1.036485e-07,0.76614,3
323.07933,244.30000,     -0.34636, 94.90906,50.00000,20.00000,1.038375e-07,0.76547,3
323.78422,245.00000,     -0.35068, 94.71771,50.00000,20.00000,1.034738e-07,0.76480,3
324.48554,245.70000,     -0.35747, 94.54679,50.00000,20.00000,1.038392e-07,0.76414,3
325.18515,246.40000,     -0.36464, 94.33695,50.00000,20.00000,1.036748e-07,0.76347,3
325.88440,247.10000,     -0.36588, 94.16203,50.00000,20.00000,1.037221e-07,0.76281,3
326.57424,247.80000,     -0.37233, 93.97320,50.00000,20.00000,1.037209e-07,0.76215,3
327.27912,248.50000,     -0.37558, 93.76317,50.00000,20.00000,1.035488e-07,0.76148,3
327.98325,249.20000,     -0.37902, 93.58275,50.00000,20.00000,1.033051e-07,0.76081,3
328.66861,249.90000,     -0.38449, 93.38909,50.00000,20.00000,1.036797e-07,0.76016,3
329.38310,250.60000,     -0.39030, 93.17261,50.00000,20.00000,1.037667e-07,0.75948,3
330.07079,251.30000,     -0.39333, 92.96084,50.00000,20.00000,1.038984e-07,0.75883,3
330.76437,252.00000,     -0.39911, 92.72382,50.00000,20.00000,1.039325e-07,0.75816,3
331.47618,252.70000,     -0.40207, 92.51188,50.00000,20.00000,1.036802e-07,0.75749,3
332.18016,253.40000,     -0.40753, 92.27914,50.00000,20.00000,1.035823e-07,0.75682,3
332.87547,254.10000,     -0.41121, 92.06545,50.00000,20.00000,1.035160e-07,0.75615,3
333.57927,254.80000,     -0.41536, 91.80233,50.00000,20.00000,1.035647e-07,0.75548,3
334.27897,255.50000,     -0.41955, 91.54517,50.00000,20.00000,1.036485e-07,0.75482,3
334.97019,256.20000,     -0.42589, 91.30219,50.00000,20.00000,1.036343e-07,0.75416,3
335.66953,256.90000,     -0.43308, 91.01993,50.00000,20.00000,1.036636e-07,0.75349,3
336.36910,257.60000,     -0.43499, 90.74905,50.00000,20.00000,9.840689e-08,0.75282,3
337.07897,258.30000,     -0.43726, 90.43318,50.00000,20.00000,1.040480e-07,0.75215,3
337.76705,259.00000,     -0.44292, 90.13909,50.00000,20.00000,1.035578e-07,0.75149,3
338.47381,259.70000,     -0.44690, 89.84489,50.00000,20.00000,1.036754e-07,0.75082,3
339.17012,260.40000,     -0.45116, 89.52299,50.00000,20.00000,1.036946e-07,0.75015,3
339.86136,261.10000,     -0.45530, 89.19287,50.00000,20.00000,1.038200e-07,0.74949,3
340.57312,261.80000,     -0.46006, 88.87064,50.00000,20.00000,1.037085e-07,0.74881,3
341.27715,262.50000,     -0.46282, 88.51225,50.00000,20.00000,1.036836e-07,0.74814,3
341.96923,263.20000,     -0.46972, 88.11935,50.00000,20.00000,1.037188e-07,0.74748,3
342.66487,263.90000,     -0.47420, 87.73948,50.00000,20.00000,1.038195e-07,0.74682,3
343.37615,264.60000,     -0.47716, 87.38148,50.00000,20.00000,1.034887e-07,0.74614,3
344.07871,265.30000,     -0.48054, 86.97070,50.00000,20.00000,1.034827e-07,0.74547,3
344.76514,266.00000,     -0.48404, 86.53804,50.00000,20.00000,1.034614e-07,0.74481,3
345.46941,266.70000,     -0.49077, 86.10649,50.00000,20.00000,1.035785e-07,0.74414,3
346.16206,267.40000,     -0.49756, 85.64410,50.00000,20.00000,1.036303e-07,0.74348,3
346.86495,268.10000,     -0.49922, 85.16511,50.00000,20.00000,1.038331e-07,0.74281,3
347.55626,268.80000,     -0.50375, 84.67054,50.00000,20.00000,1.037018e-07,0.74215,3
348.25292,269.50000,     -0.50778, 84.18315,50.00000,20.00000,1.037714e-07,0.74148,3
348.96226,270.20000,     -0.51207, 83.66232,50.00000,20.00000,1.037004e-07,0.74080,3
349.65819,270.90000,     -0.51619, 83.10779,50.00000,20.00000,1.037283e-07,0.74014,3
350.36530,271.60000,     -0.51891, 82.54302,50.00000,20.00000,1.036144e-07,0.73946,3
351.06943,272.30000,     -0.52425, 81.95890,50.00000,20.00000,1.037564e-07,0.73879,3
351.76415,273.00000,     -0.52743, 81.32896,50.00000,20.00000,1.033925e-07,0.73813,3
352.46785,273.70000,     -0.53310, 80.71413,50.00000,20.00000,1.036343e-07,0.73746,3
353.16611,274.40000,     -0.53949, 80.04946,50.00000,20.00000,1.036856e-07,0.73679,3
353.86838,275.10000,     -0.54155, 79.37485,50.00000,20.00000,1.037247e-07,0.73612,3
354.55117,275.80000,     -0.54563, 78.66742,50.00000,20.00000,1.037611e-07,0.73547,3
355.25475,276.50000,     -0.55270, 77.97805,50.00000,20.00000,1.036879e-07,0.73480,3
355.95316,277.20000,     -0.55456, 77.22417,50.00000,20.00000,1.036066e-07,0.73413,3
356.65850,277.90000,     -0.55796, 76.47550,50.00000,20.00000,1.039700e-07,0.73346,3
357.36223,278.60000,     -0.56306, 75.67068,50.00000,20.00000,9.993980e-08,0.73279,3
358.05751,279.30000,     -0.57053, 74.85798,50.00000,20.00000,1.044290e-07,0.73213,3
358.75207,280.00000,     -0.57434, 74.01451,50.00000,20.00000,1.044230e-07,0.73146,3
359.44277,280.70000,     -0.57914, 73.14169,50.00000,20.00000,1.037858e-07,0.73080,3
360.14016,281.40000,     -0.58321, 72.27502,50.00000,20.00000,1.038119e-07,0.73014,3
360.85339,282.10000,     -0.58487, 71.33919,50.00000,20.00000,1.037690e-07,0.72946,3
361.55223,282.80000,     -0.58875, 70.39468,50.00000,20.00000,1.039081e-07,0.72880,3
362.24572,283.50000,     -0.59781, 69.41672,50.00000,20.00000,1.041261e-07,0.72813,3
362.95213,284.20000,     -0.60231, 68.43441,50.00000,20.00000,1.038333e-07,0.72746,3
363.65004,284.90000,     -0.60595, 67.38753,50.00000,20.00000,1.039420e-07,0.72680,3
364.35824,285.60000,     -0.61160, 66.32167,50.00000,20.00000,1.039135e-07,0.72612,3
365.04839,286.30000,     -0.61864, 65.29393,50.00000,20.00000,1.039576e-07,0.72547,3
365.75524,287.00000,     -0.62338, 64.16011,50.00000,20.00000,1.041244e-07,0.72480,3
366.45093,287.70000,     -0.62852, 63.04613,50.00000,20.00000,1.038831e-07,0.72413,3
367.15011,288.40000,     -0.63553, 61.88623,50.00000,20.00000,1.041234e-07,0.72347,3
367.85329,289.10000,     -0.64279, 60.71884,50.00000,20.00000,1.040900e-07,0.72280,3
368.55227,289.80000,     -0.64816, 59.53028,50.00000,20.00000,1.046568e-07,0.72214,3
369.24952,290.50000,     -0.65485, 58.30092,50.00000,20.00000,1.042652e-07,0.72147,3
369.95113,291.20000,     -0.66085, 57.05326,50.00000,20.00000,1.035054e-07,0.72081,3
370.64263,291.90000,     -0.66982, 55.81631,50.00000,20.00000,1.047844e-07,0.72015,3
371.34312,292.60000,     -0.67563, 54.53530,50.00000,20.00000,1.034293e-07,0.71949,3
372.04458,293.30000,     -0.68194, 53.26129,50.00000,20.00000,1.041605e-07,0.71882,3
372.75016,294.00000,     -0.68811, 51.95198,50.00000,20.00000,1.040348e-07,0.71815,3
373.45028,294.70000,     -0.69923, 50.64329,50.00000,20.00000,1.024977e-07,0.71749,3
374.14727,295.40000,     -0.70858, 49.31574,50.00000,20.00000,1.032581e-07,0.71683,3
374.85168,296.10000,     -0.71857, 48.00068,50.00000,20.00000,1.045028e-07,0.71616,3
375.55004,296.80000,     -0.72667, 46.67449,50.00000,20.00000,1.050391e-07,0.71550,3
376.24330,297.50000,     -0.73669, 45.35285,50.00000,20.00000,1.036669e-07,0.71485,3
376.95218,298.20000,     -0.74559, 44.01280,50.00000,20.00000,1.047662e-07,0.71417,3
377.65218,298.90000,     -0.75870, 42.67995,50.00000,20.00000,1.026483e-07,0.71351,3
378.34421,299.60000,     -0.77070, 41.34511,50.00000,20.00000,1.056882e-07,0.71286,3
379.05347,300.30000,     -0.77923, 40.04834,50.00000,20.00000,1.039577e-07,0.71219,3
379.73226,301.00000,     -0.78912, 38.71365,50.00000,20.00000,1.044155e-07,0.71155,3
380.45032,301.70000,     -0.80404, 37.43826,50.00000,20.00000,1.045657e-07,0.71087,3
381.14120,302.40000,     -0.81693, 36.17522,50.00000,20.00000,1.044575e-07,0.71022,3
381.84134,303.10000,     -0.82698, 34.93373,50.00000,20.00000,1.044390e-07,0.70956,3
382.54621,303.80000,     -0.84201, 33.70867,50.00000,20.00000,1.043705e-07,0.70889,3
383.25467,304.50000,     -0.85423, 32.47751,50.00000,20.00000,1.046154e-07,0.70823,3
383.95116,305.20000,     -0.86527, 31.34591,50.00000,20.00000,1.044257e-07,0.70757,3
384.65447,305.90000,     -0.88375, 30.17316,50.00000,20.00000,1.044969e-07,0.70691,3
385.35306,306.60000,     -0.89845, 29.03209,50.00000,20.00000,1.044448e-07,0.70625,3
386.04866,307.30000,     -0.91170, 27.95390,50.00000,20.00000,1.044379e-07,0.70560,3
386.76412,308.00000,     -0.92383, 26.94371,50.00000,20.00000,1.043155e-07,0.70493,3
387.45677,308.70000,     -0.93947, 25.92951,50.00000,20.00000,1.042866e-07,0.70428,3
388.15817,309.40000,     -0.95373, 24.92181,50.00000,20.00000,1.044488e-07,0.70362,3
388.85649,310.10000,     -0.97133, 23.99049,50.00000,20.00000,1.044738e-07,0.70296,3
389.55816,310.80000,     -0.98584, 23.10595,50.00000,20.00000,1.045779e-07,0.70230,3
390.25298,311.50000,     -1.00014, 22.27013,50.00000,20.00000,1.044981e-07,0.70165,3
390.95325,312.20000,     -1.01738, 21.42970,50.00000,20.00000,1.043852e-07,0.70100,3
391.64465,312.90000,     -1.03260, 20.65318,50.00000,20.00000,1.042985e-07,0.70035,3
392.35603,313.60000,     -1.04475, 19.91610,50.00000,20.00000,1.043723e-07,0.69969,3
393.04797,314.30000,     -1.06025, 19.19636,50.00000,20.00000,1.046272e-07,0.69904,3
393.75117,315.00000,     -1.07493, 18.55073,50.00000,20.00000,1.042734e-07,0.69838,3
394.44641,315.70000,     -1.08907, 17.94627,50.00000,20.00000,9.980259e-08,0.69773,3
395.14607,316.40000,     -1.10281, 17.34264,50.00000,20.00000,1.043892e-07,0.69708,3
395.84177,317.10000,     -1.11436, 16.79563,50.00000,20.00000,1.040482e-07,0.69643,3
396.55616,317.80000,     -1.12583, 16.26958,50.00000,20.00000,1.043969e-07,0.69577,3
397.24981,318.50000,     -1.14289, 15.81650,50.00000,20.00000,1.043753e-07,0.69512,3
397.95010,319.20000,     -1.15874, 15.32398,50.00000,20.00000,1.042433e-07,0.69447,3
398.62833,319.90000,     -1.17337, 14.93080,50.00000,20.00000,1.042598e-07,0.69384,3
399.33225,320.60000,     -1.18144, 14.52332,50.00000,20.00000,1.044827e-07,0.69318,3
400.42726,321.30000,     -0.93436, 14.17718,50.00000,20.00000,1.050339e-07,0.69217,4
403.56498,322.00000, 2.505939e-02, 13.91566,50.00000,20.00000,1.027302e-07,0.68926,4
406.73281,322.70000, 2.678686e-03, 13.61071,50.00000,20.00000,1.032442e-07,0.68634,4
409.77432,323.40000,-4.322098e-02, 13.23393,50.00000,20.00000,1.028340e-07,0.68354,4
413.11410,324.10000, 8.257780e-02, 12.89036,50.00000,20.00000,1.049454e-07,0.68048,4
416.61709,324.80000,      0.12773, 12.52790,50.00000,20.00000,1.044996e-07,0.67728,4
420.14707,325.50000,      0.11040, 12.19492,50.00000,20.00000,1.037037e-07,0.67408,4
423.71173,326.20000, 9.568553e-02, 11.86060,50.00000,20.00000,1.038432e-07,0.67085,4
427.30978,326.90000, 6.912609e-02, 11.58905,50.00000,20.00000,1.039693e-07,0.66762,4
430.89791,327.60000, 2.473894e-02, 11.30869,50.00000,20.00000,1.041181e-07,0.66440,4
434.49577,328.30000,-2.082881e-02, 11.10978,50.00000,20.00000,1.035134e-07,0.66120,4
438.08091,329.00000,-7.335342e-02, 10.94358,50.00000,20.00000,1.034627e-07,0.65803,4
441.64790,329.70000,     -0.12891, 10.80320,50.00000,20.00000,1.040409e-07,0.65489,4
445.21542,330.40000,     -0.18898, 10.68385,50.00000,20.00000,1.042462e-07,0.65177,4
448.78089,331.10000,     -0.25133, 10.59756,50.00000,20.00000,1.036297e-07,0.64867,4
452.33982,331.80000,     -0.32113, 10.50290,50.00000,20.00000,1.044701e-07,0.64559,4
455.88061,332.50000,     -0.39263, 10.43300,50.00000,20.00000,1.038242e-07,0.64255,4
459.40811,333.20000,     -0.45977, 10.39809,50.00000,20.00000,1.040501e-07,0.63955,4
462.94163,333.90000,     -0.52475, 10.38150,50.00000,20.00000,1.039686e-07,0.63655,4
466.47393,334.60000,     -0.59272, 10.38150,50.00000,20.00000,1.039489e-07,0.63358,4
469.98367,335.30000,     -0.65888, 10.40631,50.00000,20.00000,1.039759e-07,0.63065,4
473.50006,336.00000,     -0.72576, 10.42129,50.00000,20.00000,1.039086e-07,0.62773,4
477.00628,336.70000,     -0.78670, 10.45624,50.00000,20.00000,1.038321e-07,0.62484,4
480.53207,337.40000,     -0.85998, 10.50104,50.00000,20.00000,1.038990e-07,0.62196,4
484.03433,338.10000,     -0.92897, 10.53098,50.00000,20.00000,1.036595e-07,0.61912,4
487.53556,338.80000,     -0.99840, 10.58078,50.00000,20.00000,1.032680e-07,0.61631,4
491.04639,339.50000,     -1.07043, 10.60052,50.00000,20.00000,1.040346e-07,0.61350,4
494.54857,340.20000,     -1.14087, 10.64227,50.00000,20.00000,1.033659e-07,0.61073,4
498.06781,340.90000,     -1.20923, 10.69868,50.00000,20.00000,1.037912e-07,0.60796,4
501.56550,341.60000,     -1.28809, 10.73281,50.00000,20.00000,1.038481e-07,0.60524,4
505.05621,342.30000,     -1.36569, 10.73571,50.00000,20.00000,1.076468e-07,0.60254,4
508.56599,343.00000,     -1.44175, 10.75865,50.00000,20.00000,1.034238e-07,0.59986,4
512.06870,343.70000,     -1.51564, 10.81674,50.00000,20.00000,1.039383e-07,0.59720,4
515.55888,344.40000,     -1.60053, 10.83656,50.00000,20.00000,1.036574e-07,0.59457,4
519.05741,345.10000,     -1.67566, 10.87151,50.00000,20.00000,1.044255e-07,0.59196,4
522.55181,345.80000,     -1.75510, 10.89649,50.00000,20.00000,1.040585e-07,0.58938,4
526.05808,346.50000,     -1.83604, 10.92305,50.00000,20.00000,1.038477e-07,0.58681,4
529.55965,347.20000,     -1.92294, 10.94235,50.00000,20.00000,1.040382e-07,0.58427,4
533.05306,347.90000,     -2.00767, 10.96784,50.00000,20.00000,1.040412e-07,0.58176,4
536.55796,348.60000,     -2.08459, 11.00279,50.00000,20.00000,1.043136e-07,0.57926,4
540.06742,349.30000,     -2.16904, 11.02472,50.00000,20.00000,1.038088e-07,0.57678,4
543.57046,350.00000,     -2.25688, 11.04758,50.00000,20.00000,1.039401e-07,0.57434,4
547.06401,350.70000,     -2.34275, 11.06759,50.00000,20.00000,1.040539e-07,0.57192,4
550.56584,351.40000,     -2.42954, 11.10734,50.00000,20.00000,1.039246e-07,0.56952,4
554.06736,352.10000,     -2.51932, 11.10735,50.00000,20.00000,1.038470e-07,0.56714,4
557.55804,352.80000,     -2.60869, 11.14634,50.00000,20.00000,1.043064e-07,0.56480,4
561.06777,353.50000,     -2.69463, 11.15565,50.00000,20.00000,1.040322e-07,0.56246,4
564.57559,354.20000,     -2.78613, 11.18572,50.00000,20.00000,1.038635e-07,0.56015,4
568.06593,354.90000,     -2.88099, 11.19545,50.00000,20.00000,1.037947e-07,0.55788,4
571.57286,355.60000,     -2.96514, 11.23539,50.00000,20.00000,1.037494e-07,0.55562,4
575.07053,356.30000,     -3.05555, 11.25521,50.00000,20.00000,1.045921e-07,0.55338,4
578.59182,357.00000,     -3.14567, 11.27970,50.00000,20.00000,1.037478e-07,0.55116,4
582.09340,357.70000,     -3.24194, 11.29565,50.00000,20.00000,1.038611e-07,0.54897,4
585.59091,358.40000,     -3.33788, 11.31512,50.00000,20.00000,1.040776e-07,0.54680,4
589.09123,359.10000,     -3.42723, 11.34493,50.00000,20.00000,1.040414e-07,0.54465,4
592.60454,359.80000,     -3.52043, 11.35492,50.00000,20.00000,1.038799e-07,0.54252,4
596.09401,360.50000,     -3.61982, 11.37489,50.00000,20.00000,1.040298e-07,0.54043,4
599.59507,361.20000,     -3.71210, 11.37651,50.00000,20.00000,1.044156e-07,0.53835,4
603.09688,361.90000,     -3.80545, 11.37651,50.00000,20.00000,1.041696e-07,0.53629,4
606.59405,362.60000,     -3.90510, 11.39648,50.00000,20.00000,1.038527e-07,0.53426,4
610.09705,363.30000,     -3.99516, 11.39523,50.00000,20.00000,1.042227e-07,0.53224,4
613.60002,364.00000,     -4.09023, 11.42144,50.00000,20.00000,1.041567e-07,0.53024,4
617.11091,364.70000,     -4.18702, 11.44255,50.00000,20.00000,1.041401e-07,0.52826,4
620.62083,365.40000,     -4.28017, 11.44302,50.00000,20.00000,1.041098e-07,0.52630,4
624.11411,366.10000,     -4.38126, 11.48282,50.00000,20.00000,1.040190e-07,0.52437,4
627.62650,366.80000,     -4.46793, 11.48305,50.00000,20.00000,1.040230e-07,0.52245,4
631.14304,367.50000,     -4.56182, 11.48781,50.00000,20.00000,1.040952e-07,0.52054,4
634.63739,368.20000,     -4.66509, 11.50778,50.00000,20.00000,1.041923e-07,0.51867,4
638.15596,368.90000,     -4.74913, 11.52776,50.00000,20.00000,1.041445e-07,0.51680,4
641.65090,369.60000,     -4.85170, 11.53275,50.00000,20.00000,1.040499e-07,0.51497,4
645.15740,370.30000,     -4.94296, 11.53275,50.00000,20.00000,1.039207e-07,0.51314,4
648.66772,371.00000,     -5.03358, 11.55257,50.00000,20.00000,1.042716e-07,0.51134,4
652.16146,371.70000,     -5.12742, 11.57241,50.00000,20.00000,1.042058e-07,0.50955,4
655.66385,372.40000,     -5.21517, 11.57258,50.00000,20.00000,1.044435e-07,0.50778,4
659.15597,373.10000,     -5.30397, 11.57753,50.00000,20.00000,1.041019e-07,0.50604,4
662.67790,373.80000,     -5.38371, 11.59750,50.00000,20.00000,1.037954e-07,0.50429,4
666.18577,374.50000,     -5.47141, 11.59899,50.00000,20.00000,1.041797e-07,0.50257,4
669.67886,375.20000,     -5.55630, 11.59841,50.00000,20.00000,1.040663e-07,0.50087,4
673.16748,375.90000,     -5.64002, 11.61908,50.00000,20.00000,1.043136e-07,0.49918,4
676.68059,376.60000,     -5.71409, 11.63906,50.00000,20.00000,1.042291e-07,0.49750,4
680.18915,377.30000,     -5.78959, 11.63906,50.00000,20.00000,1.039730e-07,0.49584,4
683.70765,378.00000,     -5.86219, 11.65888,50.00000,20.00000,1.044411e-07,0.49419,4
687.20498,378.70000,     -5.94062, 11.67909,50.00000,20.00000,1.039747e-07,0.49256,4
690.71146,379.40000,     -6.00956, 11.67382,50.00000,20.00000,1.037128e-07,0.49094,4
694.22005,380.10000,     -6.08063, 11.65069,50.00000,20.00000,1.044347e-07,0.48933,4
697.73039,380.80000,     -6.14785, 11.69545,50.00000,20.00000,1.043228e-07,0.48773,4
701.22893,381.50000,     -6.22163, 11.67835,50.00000,20.00000,1.043046e-07,0.48615,4
704.72891,382.20000,     -6.28633, 11.70044,50.00000,20.00000,1.038987e-07,0.48458,4
708.23329,382.90000,     -6.35094, 11.70044,50.00000,20.00000,1.042347e-07,0.48303,4
711.72257,383.60000,     -6.41454, 11.72041,50.00000,20.00000,1.051355e-07,0.48148,4
715.24811,384.30000,     -6.47064, 11.74038,50.00000,20.00000,1.045956e-07,0.47994,4
718.75975,385.00000,     -6.53707, 11.72041,50.00000,20.00000,1.042841e-07,0.47841,4
722.26156,385.70000,     -6.59975, 11.73037,50.00000,20.00000,1.045188e-07,0.47689,4
725.75642,386.40000,     -6.65914, 11.73028,50.00000,20.00000,1.040138e-07,0.47539,4
729.25850,387.10000,     -6.71919, 11.75037,50.00000,20.00000,1.038496e-07,0.47389,4
732.77236,387.80000,     -6.77271, 11.77019,50.00000,20.00000,1.040699e-07,0.47239,4
736.27579,388.50000,     -6.83996, 11.77018,50.00000,20.00000,1.043641e-07,0.47091,4
739.78461,389.20000,     -6.89470, 11.76053,50.00000,20.00000,1.041782e-07,0.46943,4
743.29469,389.90000,     -6.95714, 11.78056,50.00000,20.00000,1.043494e-07,0.46796,4
746.79424,390.60000,     -7.01578, 11.77947,50.00000,20.00000,9.973139e-08,0.46651,4
750.30230,391.30000,     -7.07629, 11.78869,50.00000,20.00000,1.045660e-07,0.46505,4
753.77984,392.00000,     -7.13859, 11.80675,50.00000,20.00000,1.043171e-07,0.46361,4
757.27788,392.70000,     -7.20036, 11.80675,50.00000,20.00000,1.043439e-07,0.46217,4
760.80225,393.40000,     -7.26276, 11.80675,50.00000,20.00000,1.046430e-07,0.46073,4
764.30156,394.10000,     -7.32656, 11.83009,50.00000,20.00000,1.036793e-07,0.45930,4
767.80796,394.80000,     -7.39062, 11.83010,50.00000,20.00000,1.039071e-07,0.45787,4
771.31949,395.50000,     -7.44921, 11.82867,50.00000,20.00000,1.042419e-07,0.45644,4
774.82663,396.20000,     -7.51357, 11.85977,50.00000,20.00000,1.055076e-07,0.45502,4
778.32942,396.90000,     -7.58046, 11.84993,50.00000,20.00000,1.046882e-07,0.45360,4
781.83354,397.60000,     -7.64778, 11.84994,50.00000,20.00000,1.045627e-07,0.45219,4
785.34015,398.30000,     -7.71367, 11.86490,50.00000,20.00000,1.044955e-07,0.45077,4
788.83847,399.00000,     -7.77946, 11.86490,50.00000,20.00000,1.046606e-07,0.44937,4
792.34413,399.70000,     -7.84986, 11.87023,50.00000,20.00000,1.038494e-07,0.44796,4
795.84366,400.40000,     -7.91627, 11.88987,50.00000,20.00000,1.045871e-07,0.44655,4
798.36099,400.90000,     -7.96482, 11.90486,50.00000,20.00000,1.051408e-07,0.44554,4