File: data/TGA/005c/ExpDat_2024_06_28_PS2439_6_1K_dynamic-0_1K_min.csv
#EXPORTTYPE:                 ,DATA ALL
#FILE:                       ,2024_06_28_PS2439_6_1K_dynamic-0_1K_min.ngb-ss5
#FORMAT:                     ,NETZSCH5
#FTYPE:                      ,ASCII
#IDENTITY:                   ,PS
#DECIMAL:                    ,POINT
#SEPARATOR:                  ,COMMA
#MTYPE:                      ,DSC
#INSTRUMENT:                 ,NETZSCH STA 449F5
#PROJECT:                    ,
#DATE/TIME:                  ,6/27/2024 3:39:51 PM (UTC-4)
#CORR. FILE:                 ,
#TEMPCAL:                    ,28-06-2023 13:26
#SENSITIVITY:                ,28-06-2023 13:53
#LABORATORY:                 ,
#OPERATOR:                   ,Stanley
#REMARK:                     ,
#SAMPLE:                     ,PS2439_6_1K
#SAMPLE MASS /mg:            ,5.00
#MATERIAL:                   ,
#REFERENCE:                  ,-----
#REFERENCE MASS /mg:         ,0
#TYPE OF CRUCIBLE:           ,Al2O3 85 ‘l, open
#SAMPLE CRUCIBLE MASS /mg:   ,0
#REFERENCE CRUCIBLE MASS /mg:,0
#DSC RANGE /‘V:              ,5000
#TG RANGE /mg:               ,35000
#TAU-R:                      ,---
#CORR. CODE:                 ,000
#EXO:                        ,-1
#RANGE:                      ,30›C....800›C/0.0....2.0K/min
#SEGMENT:                    ,S3/4
#SEG. 1:                     ,30›C/1.0(K/min)/100›C
#SEG. 2:                     ,100›C/00:20/100›C
#SEG. 3:                     ,100›C/0.1(K/min)/400›C
#SEG. 4:                     ,400›C/2.0(K/min)/800›C

##Temp./›C,Time/min,DSC/(mW/mg),Mass loss/mg,Gas Flow(purge2)/(ml/min),Gas Flow(protective)/(ml/min),TIC(scan:1)/A,Sensit./(uV/mW)
 99.94700,  90.10000, 6.958099e-03,-0.48239,50.00000,20.00000,5.533718e-08,0.92104
100.26300,  95.10000, 3.230820e-02,-0.48216,50.00000,20.00000,5.518416e-08,0.92096
100.89400, 100.10000, 3.629081e-02,-0.48284,50.00000,20.00000,5.507161e-08,0.92080
101.48200, 105.10000, 3.463931e-02,-0.48488,50.00000,20.00000,5.499275e-08,0.92066
101.98900, 110.10000, 3.265506e-02,-0.48544,50.00000,20.00000,5.486419e-08,0.92053
102.49400, 115.10000, 3.232814e-02,-0.48624,50.00000,20.00000,5.477895e-08,0.92039
102.98200, 120.10000, 3.117198e-02,-0.48703,50.00000,20.00000,5.471459e-08,0.92027
103.48600, 125.10000, 3.217150e-02,-0.48590,50.00000,20.00000,5.461460e-08,0.92013
103.99200, 130.10000, 3.267381e-02,-0.48624,50.00000,20.00000,5.451575e-08,0.92000
104.47000, 135.10000, 3.251252e-02,-0.48590,50.00000,20.00000,5.440970e-08,0.91987
104.97600, 140.10000, 3.351284e-02,-0.48533,50.00000,20.00000,5.442121e-08,0.91973
105.46200, 145.10000, 3.434738e-02,-0.48284,50.00000,20.00000,5.436781e-08,0.91960
105.97400, 150.10000, 3.368889e-02,-0.48443,50.00000,20.00000,5.436593e-08,0.91945
106.47900, 155.10000, 3.352812e-02,-0.48182,50.00000,20.00000,5.431464e-08,0.91931
106.98500, 160.10000, 3.369938e-02,-0.48081,50.00000,20.00000,5.429443e-08,0.91917
107.48600, 165.10000, 3.586309e-02,-0.48081,50.00000,20.00000,5.425191e-08,0.91902
107.98200, 170.10000, 3.354388e-02,-0.47888,50.00000,20.00000,5.415835e-08,0.91888
108.48700, 175.10000, 3.487796e-02,-0.47854,50.00000,20.00000,5.424113e-08,0.91873
108.99200, 180.10000, 3.504974e-02,-0.47764,50.00000,20.00000,5.419914e-08,0.91858
109.47900, 185.10000, 3.522143e-02,-0.47662,50.00000,20.00000,5.416127e-08,0.91844
109.98300, 190.10000, 3.522725e-02,-0.47764,50.00000,20.00000,5.410188e-08,0.91828
110.47400, 195.10000, 3.523297e-02,-0.47481,50.00000,20.00000,5.410039e-08,0.91814
110.97700, 200.10000, 3.407534e-02,-0.47605,50.00000,20.00000,5.402603e-08,0.91798
111.46400, 205.10000, 3.574341e-02,-0.47300,50.00000,20.00000,5.389284e-08,0.91783
111.97900, 210.10000, 3.458573e-02,-0.47176,50.00000,20.00000,5.391596e-08,0.91767
112.49700, 215.10000, 3.376034e-02,-0.47108,50.00000,20.00000,5.390474e-08,0.91751
112.98900, 220.10000, 3.576211e-02,-0.47028,50.00000,20.00000,5.393621e-08,0.91735
113.49200, 225.10000, 3.427111e-02,-0.46825,50.00000,20.00000,5.376565e-08,0.91719
113.98800, 230.10000, 3.377791e-02,-0.47017,50.00000,20.00000,5.382237e-08,0.91703
114.48100, 235.10000, 3.428310e-02,-0.46847,50.00000,20.00000,5.382772e-08,0.91687
114.98300, 240.10000, 3.495507e-02,-0.46768,50.00000,20.00000,5.377941e-08,0.91670
115.47900, 245.10000, 3.429540e-02,-0.46587,50.00000,20.00000,5.386417e-08,0.91654
116.00300, 250.10000, 3.463497e-02,-0.46666,50.00000,20.00000,5.376460e-08,0.91637
116.49500, 255.10000, 3.380851e-02,-0.46361,50.00000,20.00000,5.384601e-08,0.91620
116.97400, 260.10000, 3.281506e-02,-0.46361,50.00000,20.00000,5.368502e-08,0.91604
117.47300, 265.10000, 3.315437e-02,-0.46225,50.00000,20.00000,5.379721e-08,0.91587
117.98300, 270.10000, 3.232755e-02,-0.45988,50.00000,20.00000,5.374963e-08,0.91569
118.48800, 275.10000, 3.150039e-02,-0.45841,50.00000,20.00000,5.373168e-08,0.91552
118.97900, 280.10000, 3.200640e-02,-0.45852,50.00000,20.00000,5.371610e-08,0.91534
119.48300, 285.10000, 3.184588e-02,-0.45614,50.00000,20.00000,5.367879e-08,0.91517
119.98900, 290.10000, 2.951742e-02,-0.45558,50.00000,20.00000,5.370756e-08,0.91499
120.47000, 295.10000, 3.102414e-02,-0.45603,50.00000,20.00000,5.379875e-08,0.91482
120.98700, 300.10000, 2.986264e-02,-0.45558,50.00000,20.00000,5.374002e-08,0.91463
121.47100, 305.10000, 3.086955e-02,-0.45377,50.00000,20.00000,5.370724e-08,0.91445
121.98100, 310.10000, 2.920688e-02,-0.45309,50.00000,20.00000,5.371807e-08,0.91427
122.48900, 315.10000, 2.988058e-02,-0.45196,50.00000,20.00000,5.377107e-08,0.91408
122.98800, 320.10000, 2.788306e-02,-0.45230,50.00000,20.00000,5.371840e-08,0.91390
123.49900, 325.10000, 2.722088e-02,-0.45094,50.00000,20.00000,5.377620e-08,0.91370
123.99100, 330.10000, 2.538903e-02,-0.45015,50.00000,20.00000,5.373991e-08,0.91352
124.47600, 335.10000, 2.539414e-02,-0.44777,50.00000,20.00000,5.380715e-08,0.91334
124.98300, 340.10000, 2.573371e-02,-0.44709,50.00000,20.00000,5.380260e-08,0.91314
125.48400, 345.10000, 2.590627e-02,-0.44845,50.00000,20.00000,5.377462e-08,0.91295
125.98200, 350.10000, 2.624608e-02,-0.44596,50.00000,20.00000,5.385097e-08,0.91276
126.48200, 355.10000, 2.357634e-02,-0.44551,50.00000,20.00000,5.380990e-08,0.91256
126.97700, 360.10000, 2.257789e-02,-0.44449,50.00000,20.00000,5.390604e-08,0.91237
127.48900, 365.10000, 2.442297e-02,-0.44472,50.00000,20.00000,5.385873e-08,0.91217
127.99700, 370.10000, 2.141665e-02,-0.44268,50.00000,20.00000,5.387473e-08,0.91197
128.47200, 375.10000, 2.024964e-02,-0.44313,50.00000,20.00000,5.384015e-08,0.91178
128.98500, 380.10000, 2.058900e-02,-0.44234,50.00000,20.00000,5.377621e-08,0.91157
129.48700, 385.10000, 1.992387e-02,-0.44144,50.00000,20.00000,5.382968e-08,0.91137
130.00301, 390.10000, 1.942607e-02,-0.43985,50.00000,20.00000,5.379525e-08,0.91116
130.49600, 395.10000, 1.742033e-02,-0.44019,50.00000,20.00000,5.395112e-08,0.91096
130.99001, 400.10000, 1.558128e-02,-0.44042,50.00000,20.00000,5.384849e-08,0.91075
131.50101, 405.10000, 1.625522e-02,-0.43691,50.00000,20.00000,5.390591e-08,0.91054
131.96700, 410.10000, 1.441493e-02,-0.43849,50.00000,20.00000,5.392387e-08,0.91035
132.46800, 415.10000, 1.559183e-02,-0.43623,50.00000,20.00000,5.396604e-08,0.91014
132.98700, 420.10000, 1.375095e-02,-0.43510,50.00000,20.00000,5.388426e-08,0.90992
133.47800, 425.10000, 1.325090e-02,-0.43521,50.00000,20.00000,5.385920e-08,0.90971
133.99300, 430.10000, 1.124082e-02,-0.43578,50.00000,20.00000,5.386926e-08,0.90949
134.48100, 435.10000, 1.124342e-02,-0.43555,50.00000,20.00000,5.390279e-08,0.90928
134.98300, 440.10000, 1.023899e-02,-0.43510,50.00000,20.00000,5.392653e-08,0.90906
135.49600, 445.10000, 9.569924e-03,-0.43386,50.00000,20.00000,5.395600e-08,0.90884
135.99699, 450.10000, 8.732561e-03,-0.43114,50.00000,20.00000,5.388029e-08,0.90862
136.47400, 455.10000, 6.886878e-03,-0.43273,50.00000,20.00000,5.396263e-08,0.90841
136.98500, 460.10000, 6.048519e-03,-0.43125,50.00000,20.00000,5.397751e-08,0.90818
137.48500, 465.10000, 5.713888e-03,-0.42990,50.00000,20.00000,5.402585e-08,0.90796
137.98599, 470.10000, 3.698134e-03,-0.42865,50.00000,20.00000,5.400922e-08,0.90774
138.49200, 475.10000, 2.353948e-03,-0.42775,50.00000,20.00000,5.394127e-08,0.90751
138.99600, 480.10000, 2.018176e-03,-0.42696,50.00000,20.00000,5.403134e-08,0.90728
139.49699, 485.10000, 6.728942e-04,-0.42616,50.00000,20.00000,5.394687e-08,0.90705
139.97900, 490.10000,-6.730576e-04,-0.42515,50.00000,20.00000,5.396089e-08,0.90683
140.48900, 495.10000,-3.029542e-03,-0.42537,50.00000,20.00000,5.397178e-08,0.90660
140.98399, 500.10000,-1.683503e-03,-0.42435,50.00000,20.00000,5.403196e-08,0.90637
141.49699, 505.10000,-2.525918e-03,-0.42367,50.00000,20.00000,5.398635e-08,0.90613
141.98300, 510.10000,-3.368734e-03,-0.42209,50.00000,20.00000,5.407542e-08,0.90591
142.48000, 515.10000,-6.739202e-03,-0.42085,50.00000,20.00000,5.396686e-08,0.90567
142.99600, 520.10000,-5.561335e-03,-0.42107,50.00000,20.00000,5.410906e-08,0.90543
143.48599, 525.10000,-7.417016e-03,-0.41881,50.00000,20.00000,5.394592e-08,0.90520
143.98801, 530.10000,-7.924814e-03,-0.41972,50.00000,20.00000,5.406798e-08,0.90496
144.48199, 535.10000,-9.950770e-03,-0.41904,50.00000,20.00000,5.410122e-08,0.90472
144.98399, 540.10000,-1.012213e-02,-0.41836,50.00000,20.00000,5.408099e-08,0.90448
145.49300, 545.10000,-1.181236e-02,-0.41700,50.00000,20.00000,5.407335e-08,0.90424
145.99100, 550.10000,-1.333466e-02,-0.41576,50.00000,20.00000,5.402162e-08,0.90399
146.49001, 555.10000,-1.215639e-02,-0.41383,50.00000,20.00000,5.411727e-08,0.90375
146.99100, 560.10000,-1.469296e-02,-0.41440,50.00000,20.00000,5.414200e-08,0.90350
147.49400, 565.10000,-1.638630e-02,-0.41247,50.00000,20.00000,5.416265e-08,0.90326
147.97600, 570.10000,-1.824937e-02,-0.41214,50.00000,20.00000,5.411724e-08,0.90302
148.47701, 575.10000,-1.994463e-02,-0.41066,50.00000,20.00000,5.421286e-08,0.90277
148.99800, 580.10000,-1.944317e-02,-0.41010,50.00000,20.00000,5.428631e-08,0.90251
149.49400, 585.10000,-2.249266e-02,-0.40885,50.00000,20.00000,5.418239e-08,0.90226
149.99699, 590.10000,-2.452897e-02,-0.40693,50.00000,20.00000,5.425738e-08,0.90200
150.47200, 595.10000,-2.504315e-02,-0.40682,50.00000,20.00000,5.422324e-08,0.90176
150.98599, 600.10000,-2.674302e-02,-0.40648,50.00000,20.00000,5.429335e-08,0.90150
151.49699, 605.10000,-3.047557e-02,-0.40648,50.00000,20.00000,5.418172e-08,0.90124
151.99899, 610.10000,-3.014558e-02,-0.40614,50.00000,20.00000,5.429256e-08,0.90098
152.48700, 615.10000,-3.337270e-02,-0.40614,50.00000,20.00000,5.428494e-08,0.90073
152.99699, 620.10000,-3.422977e-02,-0.40422,50.00000,20.00000,5.431864e-08,0.90047
153.49300, 625.10000,-3.407009e-02,-0.40410,50.00000,20.00000,5.428294e-08,0.90021
153.98000, 630.10000,-3.407973e-02,-0.40376,50.00000,20.00000,5.428556e-08,0.89995
154.49699, 635.10000,-3.629484e-02,-0.40263,50.00000,20.00000,5.431908e-08,0.89968
154.99899, 640.10000,-3.885032e-02,-0.40037,50.00000,20.00000,5.438174e-08,0.89942
155.47701, 645.10000,-4.174616e-02,-0.39992,50.00000,20.00000,5.448435e-08,0.89916
155.96400, 650.10000,-4.141869e-02,-0.39924,50.00000,20.00000,5.447453e-08,0.89890
156.48900, 655.10000,-4.228063e-02,-0.39924,50.00000,20.00000,5.435044e-08,0.89862
156.98900, 660.10000,-4.619987e-02,-0.39924,50.00000,20.00000,5.458604e-08,0.89836
157.48599, 665.10000,-4.927191e-02,-0.39924,50.00000,20.00000,5.450157e-08,0.89809
157.98599, 670.10000,-5.115625e-02,-0.39958,50.00000,20.00000,5.448687e-08,0.89782
158.50301, 675.10000,-5.066224e-02,-0.39890,50.00000,20.00000,5.443933e-08,0.89754
159.00101, 680.10000,-5.390871e-02,-0.39652,50.00000,20.00000,5.452719e-08,0.89726
159.50000, 685.10000,-5.545614e-02,-0.39720,50.00000,20.00000,5.452193e-08,0.89699
159.99899, 690.10000,-5.768524e-02,-0.39551,50.00000,20.00000,5.462142e-08,0.89672
160.50700, 695.10000,-5.889481e-02,-0.39415,50.00000,20.00000,5.461619e-08,0.89644
161.00000, 700.10000,-6.146680e-02,-0.39381,50.00000,20.00000,5.460687e-08,0.89616
161.49100, 705.10000,-6.318875e-02,-0.39313,50.00000,20.00000,5.461472e-08,0.89589
161.98700, 710.10000,-6.440092e-02,-0.39245,50.00000,20.00000,5.447852e-08,0.89561
162.49001, 715.10000,-6.612549e-02,-0.39381,50.00000,20.00000,5.459172e-08,0.89533
162.99400, 720.10000,-6.785127e-02,-0.39279,50.00000,20.00000,5.455873e-08,0.89505
163.49500, 725.10000,-7.043077e-02,-0.39177,50.00000,20.00000,5.460519e-08,0.89476
164.01100, 730.10000,-7.181856e-02,-0.39109,50.00000,20.00000,5.465128e-08,0.89447
164.50700, 735.10000,-7.457158e-02,-0.39075,50.00000,20.00000,5.463282e-08,0.89419
165.00400, 740.10000,-7.561949e-02,-0.39075,50.00000,20.00000,5.470114e-08,0.89390
165.50000, 745.10000,-7.922941e-02,-0.38974,50.00000,20.00000,5.474385e-08,0.89362
165.97600, 750.10000,-8.164501e-02,-0.38872,50.00000,20.00000,5.471538e-08,0.89334
166.49600, 755.10000,-8.150165e-02,-0.38906,50.00000,20.00000,5.469168e-08,0.89304
167.00000, 760.10000,-8.255388e-02,-0.38872,50.00000,20.00000,5.468800e-08,0.89275
167.63100, 765.10000,-8.515276e-02,-0.38634,50.00000,20.00000,5.476333e-08,0.89238
167.99001, 770.10000,-8.773826e-02,-0.38464,50.00000,20.00000,5.479990e-08,0.89217
168.48500, 775.10000,-8.930661e-02,-0.38397,50.00000,20.00000,5.474277e-08,0.89188
168.99500, 780.10000,-9.036356e-02,-0.38397,50.00000,20.00000,5.475775e-08,0.89158
169.50301, 785.10000,-9.398923e-02,-0.38397,50.00000,20.00000,5.480321e-08,0.89128
170.00200, 790.10000,-9.573304e-02,-0.38295,50.00000,20.00000,5.479308e-08,0.89098
170.50500, 795.10000,-9.713576e-02,-0.38261,50.00000,20.00000,5.485014e-08,0.89068
171.00301, 800.10000,     -0.10248,-0.38363,50.00000,20.00000,5.477896e-08,0.89039
171.49300, 805.10000,     -0.10269,-0.38057,50.00000,20.00000,5.483882e-08,0.89009
171.99500, 810.10000,     -0.10598,-0.37955,50.00000,20.00000,5.474641e-08,0.88979
172.50200, 815.10000,     -0.10653,-0.37831,50.00000,20.00000,5.484690e-08,0.88949
172.99600, 820.10000,     -0.11068,-0.37831,50.00000,20.00000,5.479959e-08,0.88919
173.49899, 825.10000,     -0.11347,-0.37695,50.00000,20.00000,5.481637e-08,0.88888
174.00000, 830.10000,     -0.11574,-0.37593,50.00000,20.00000,5.493535e-08,0.88857
174.49500, 835.10000,     -0.11681,-0.37492,50.00000,20.00000,5.495786e-08,0.88827
174.98500, 840.10000,     -0.11943,-0.37446,50.00000,20.00000,5.499648e-08,0.88797
175.47200, 845.10000,     -0.11912,-0.37401,50.00000,20.00000,5.492967e-08,0.88767
175.99500, 850.10000,     -0.12295,-0.37186,50.00000,20.00000,5.490756e-08,0.88735
176.50000, 855.10000,     -0.12626,-0.37220,50.00000,20.00000,5.488916e-08,0.88703
176.99899, 860.10000,     -0.12889,-0.37130,50.00000,20.00000,5.497862e-08,0.88672
177.50200, 865.10000,     -0.13048,-0.37028,50.00000,20.00000,5.499079e-08,0.88641
177.98900, 870.10000,     -0.13225,-0.37050,50.00000,20.00000,5.499380e-08,0.88610
178.47900, 875.10000,     -0.13505,-0.36881,50.00000,20.00000,5.496650e-08,0.88580
178.99500, 880.10000,     -0.13648,-0.36892,50.00000,20.00000,5.486997e-08,0.88547
179.49500, 885.10000,     -0.13912,-0.36824,50.00000,20.00000,5.498309e-08,0.88516
179.99100, 890.10000,     -0.14210,-0.36553,50.00000,20.00000,5.505828e-08,0.88484
180.50101, 895.10000,     -0.14422,-0.36553,50.00000,20.00000,5.513740e-08,0.88452
180.98500, 900.10000,     -0.14686,-0.36620,50.00000,20.00000,5.517512e-08,0.88421
181.49800, 905.10000,     -0.14795,-0.36451,50.00000,20.00000,5.497641e-08,0.88388
181.99699, 910.10000,     -0.15232,-0.36428,50.00000,20.00000,5.509074e-08,0.88356
182.49001, 915.10000,     -0.15617,-0.36485,50.00000,20.00000,5.514592e-08,0.88324
182.99001, 920.10000,     -0.15606,-0.36213,50.00000,20.00000,5.523731e-08,0.88292
183.49699, 925.10000,     -0.15957,-0.36247,50.00000,20.00000,5.516634e-08,0.88259
183.98900, 930.10000,     -0.16309,-0.36213,50.00000,20.00000,5.515469e-08,0.88227
184.49699, 935.10000,     -0.16696,-0.36111,50.00000,20.00000,5.529459e-08,0.88194
184.98399, 940.10000,     -0.16771,-0.36213,50.00000,20.00000,5.522341e-08,0.88162
185.50301, 945.10000,     -0.17159,-0.36157,50.00000,20.00000,5.525485e-08,0.88128
186.00400, 950.10000,     -0.17355,-0.36044,50.00000,20.00000,5.532177e-08,0.88095
186.50200, 955.10000,     -0.17882,-0.35976,50.00000,20.00000,5.524077e-08,0.88062
186.98700, 960.10000,     -0.17958,-0.35829,50.00000,20.00000,5.535882e-08,0.88030
187.49200, 965.10000,     -0.18068,-0.35817,50.00000,20.00000,5.528412e-08,0.87997
187.99699, 970.10000,     -0.18422,-0.35659,50.00000,20.00000,5.541811e-08,0.87963
188.50900, 975.10000,     -0.18499,-0.35546,50.00000,20.00000,5.535925e-08,0.87929
188.99200, 980.10000,     -0.18992,-0.35421,50.00000,20.00000,5.542483e-08,0.87897
189.48900, 985.10000,     -0.19086,-0.35387,50.00000,20.00000,5.542790e-08,0.87863
190.01199, 990.10000,     -0.19563,-0.35387,50.00000,20.00000,5.544113e-08,0.87828
190.49500, 995.10000,     -0.19865,-0.35421,50.00000,20.00000,5.544100e-08,0.87795
190.99699,1000.10000,     -0.20203,-0.35410,50.00000,20.00000,5.539027e-08,0.87761
191.49800,1005.10000,     -0.20402,-0.35353,50.00000,20.00000,5.544774e-08,0.87728
191.97900,1010.10000,     -0.20601,-0.35455,50.00000,20.00000,5.546954e-08,0.87695
192.49699,1015.10000,     -0.21028,-0.35399,50.00000,20.00000,5.544777e-08,0.87659
193.00800,1020.10000,     -0.21245,-0.35105,50.00000,20.00000,5.553721e-08,0.87625
193.49400,1025.10000,     -0.21305,-0.35048,50.00000,20.00000,5.546276e-08,0.87591
193.99699,1030.10000,     -0.21767,-0.35218,50.00000,20.00000,5.553096e-08,0.87557
194.50400,1035.10000,     -0.21880,-0.34765,50.00000,20.00000,5.562870e-08,0.87522
194.99500,1040.10000,     -0.22534,-0.34743,50.00000,20.00000,5.560131e-08,0.87488
195.48199,1045.10000,     -0.22647,-0.34743,50.00000,20.00000,5.553784e-08,0.87454
196.00101,1050.10000,     -0.22831,-0.34799,50.00000,20.00000,5.561086e-08,0.87418
196.48900,1055.10000,     -0.23050,-0.34788,50.00000,20.00000,5.559873e-08,0.87384
196.98300,1060.10000,     -0.23670,-0.34776,50.00000,20.00000,5.554200e-08,0.87349
197.50400,1065.10000,     -0.23890,-0.34641,50.00000,20.00000,5.560733e-08,0.87313
197.99600,1070.10000,     -0.24126,-0.34629,50.00000,20.00000,5.567407e-08,0.87278
198.49500,1075.10000,     -0.24678,-0.34516,50.00000,20.00000,5.563539e-08,0.87243
198.98599,1080.10000,     -0.24636,-0.34539,50.00000,20.00000,5.575044e-08,0.87209
199.50200,1085.10000,     -0.25206,-0.34618,50.00000,20.00000,5.558453e-08,0.87172
199.99300,1090.10000,     -0.25514,-0.34505,50.00000,20.00000,5.564280e-08,0.87137
200.49500,1095.10000,     -0.25805,-0.34256,50.00000,20.00000,5.571431e-08,0.87102
201.00600,1100.10000,     -0.26131,-0.34211,50.00000,20.00000,5.572477e-08,0.87065
201.48801,1105.10000,     -0.26457,-0.34177,50.00000,20.00000,5.581061e-08,0.87031
201.98900,1110.10000,     -0.26713,-0.34143,50.00000,20.00000,5.568700e-08,0.86995
202.48900,1115.10000,     -0.26987,-0.34154,50.00000,20.00000,5.571411e-08,0.86959
202.99400,1120.10000,     -0.27315,-0.34109,50.00000,20.00000,5.566883e-08,0.86923
203.48900,1125.10000,     -0.27712,-0.34075,50.00000,20.00000,5.573511e-08,0.86887
203.99800,1130.10000,     -0.28005,-0.34154,50.00000,20.00000,5.571788e-08,0.86850
204.49800,1135.10000,     -0.28368,-0.33905,50.00000,20.00000,5.570643e-08,0.86814
204.99200,1140.10000,     -0.28626,-0.33917,50.00000,20.00000,5.581391e-08,0.86778
205.49899,1145.10000,     -0.29025,-0.33860,50.00000,20.00000,5.580421e-08,0.86742
205.97800,1150.10000,     -0.29442,-0.33736,50.00000,20.00000,5.574645e-08,0.86707
206.50101,1155.10000,     -0.29842,-0.33837,50.00000,20.00000,5.574256e-08,0.86668
206.99001,1160.10000,     -0.30189,-0.33860,50.00000,20.00000,5.565867e-08,0.86633
207.49200,1165.10000,     -0.30537,-0.33736,50.00000,20.00000,5.573860e-08,0.86596
207.99600,1170.10000,     -0.30902,-0.33623,50.00000,20.00000,5.584308e-08,0.86559
208.51300,1175.10000,     -0.31198,-0.33713,50.00000,20.00000,5.581789e-08,0.86520
208.99600,1180.10000,     -0.31511,-0.33521,50.00000,20.00000,5.581827e-08,0.86485
209.49300,1185.10000,     -0.32019,-0.33521,50.00000,20.00000,5.567643e-08,0.86448
209.98199,1190.10000,     -0.32297,-0.33453,50.00000,20.00000,5.584771e-08,0.86412
210.49200,1195.10000,     -0.32647,-0.33498,50.00000,20.00000,5.588272e-08,0.86374
210.99001,1200.10000,     -0.33085,-0.33385,50.00000,20.00000,5.575276e-08,0.86337
211.49500,1205.10000,     -0.33241,-0.33419,50.00000,20.00000,5.593796e-08,0.86299
212.00600,1210.10000,     -0.33592,-0.33487,50.00000,20.00000,5.587801e-08,0.86261
212.49699,1215.10000,     -0.33978,-0.33261,50.00000,20.00000,5.584773e-08,0.86224
212.98300,1220.10000,     -0.34559,-0.33351,50.00000,20.00000,5.588991e-08,0.86187
213.49100,1225.10000,     -0.34751,-0.33181,50.00000,20.00000,5.587985e-08,0.86149
213.98801,1230.10000,     -0.35245,-0.33272,50.00000,20.00000,5.593729e-08,0.86111
214.50101,1235.10000,     -0.35544,-0.33249,50.00000,20.00000,5.583168e-08,0.86073
214.98900,1240.10000,     -0.35879,-0.33215,50.00000,20.00000,5.590043e-08,0.86036
215.49899,1245.10000,     -0.36285,-0.33272,50.00000,20.00000,5.582627e-08,0.85997
215.99600,1250.10000,     -0.36426,-0.33136,50.00000,20.00000,5.583945e-08,0.85959
216.50600,1255.10000,     -0.36975,-0.33193,50.00000,20.00000,5.597763e-08,0.85920
217.00200,1260.10000,     -0.37275,-0.33159,50.00000,20.00000,5.586150e-08,0.85882
217.50400,1265.10000,     -0.37452,-0.33046,50.00000,20.00000,5.591144e-08,0.85844
218.00200,1270.10000,     -0.38038,-0.33170,50.00000,20.00000,5.586500e-08,0.85806
218.48500,1275.10000,     -0.38535,-0.33102,50.00000,20.00000,5.595063e-08,0.85768
218.99300,1280.10000,     -0.38695,-0.32932,50.00000,20.00000,5.600324e-08,0.85729
219.49300,1285.10000,     -0.38997,-0.32865,50.00000,20.00000,5.597002e-08,0.85691
220.00700,1290.10000,     -0.39336,-0.32966,50.00000,20.00000,5.598791e-08,0.85651
220.49500,1295.10000,     -0.40048,-0.32955,50.00000,20.00000,5.599968e-08,0.85613
220.99400,1300.10000,     -0.40298,-0.32989,50.00000,20.00000,5.601781e-08,0.85574
221.48100,1305.10000,     -0.40691,-0.32955,50.00000,20.00000,5.597414e-08,0.85536
222.00400,1310.10000,     -0.41049,-0.33057,50.00000,20.00000,5.594481e-08,0.85496
222.50500,1315.10000,     -0.41389,-0.33012,50.00000,20.00000,5.599901e-08,0.85457
222.99001,1320.10000,     -0.41640,-0.33147,50.00000,20.00000,5.597475e-08,0.85419
223.50301,1325.10000,     -0.42106,-0.33102,50.00000,20.00000,5.608143e-08,0.85378
223.99800,1330.10000,     -0.42698,-0.33034,50.00000,20.00000,5.605237e-08,0.85340
224.49400,1335.10000,     -0.43057,-0.33102,50.00000,20.00000,5.608711e-08,0.85301
224.98500,1340.10000,     -0.43596,-0.33012,50.00000,20.00000,5.604460e-08,0.85262
225.50600,1345.10000,     -0.44082,-0.33159,50.00000,20.00000,5.603102e-08,0.85221
225.99400,1350.10000,     -0.44335,-0.33012,50.00000,20.00000,5.607174e-08,0.85182
226.50500,1355.10000,     -0.44786,-0.33034,50.00000,20.00000,5.600056e-08,0.85142
227.00500,1360.10000,     -0.45453,-0.33057,50.00000,20.00000,5.610925e-08,0.85102
227.50000,1365.10000,     -0.45527,-0.33136,50.00000,20.00000,5.608230e-08,0.85063
227.99500,1370.10000,     -0.45907,-0.33113,50.00000,20.00000,5.604480e-08,0.85023
228.48801,1375.10000,     -0.46521,-0.33080,50.00000,20.00000,5.607725e-08,0.84984
228.99800,1380.10000,     -0.46885,-0.32978,50.00000,20.00000,5.611727e-08,0.84943
229.49699,1385.10000,     -0.47572,-0.33159,50.00000,20.00000,5.610381e-08,0.84903
229.98500,1390.10000,     -0.47630,-0.33068,50.00000,20.00000,5.612348e-08,0.84864
230.49899,1395.10000,     -0.48283,-0.32944,50.00000,20.00000,5.602517e-08,0.84823
230.99699,1400.10000,     -0.48701,-0.32966,50.00000,20.00000,5.609059e-08,0.84783
231.50101,1405.10000,     -0.49031,-0.32978,50.00000,20.00000,5.610972e-08,0.84742
231.99200,1410.10000,     -0.49486,-0.32932,50.00000,20.00000,5.623974e-08,0.84702
232.51601,1415.10000,     -0.49871,-0.32898,50.00000,20.00000,5.610916e-08,0.84660
232.98300,1420.10000,     -0.50218,-0.32966,50.00000,20.00000,5.622762e-08,0.84622
233.49600,1425.10000,     -0.51001,-0.32898,50.00000,20.00000,5.613500e-08,0.84581
233.99699,1430.10000,     -0.51404,-0.32898,50.00000,20.00000,5.617904e-08,0.84540
234.48399,1435.10000,     -0.51771,-0.33034,50.00000,20.00000,5.617203e-08,0.84500
235.00200,1440.10000,     -0.52177,-0.32865,50.00000,20.00000,5.613499e-08,0.84458
235.50101,1445.10000,     -0.52509,-0.33057,50.00000,20.00000,5.616158e-08,0.84417
236.00800,1450.10000,     -0.52951,-0.33034,50.00000,20.00000,5.617696e-08,0.84376
236.50101,1455.10000,     -0.53573,-0.32797,50.00000,20.00000,5.624672e-08,0.84335
236.99699,1460.10000,     -0.53907,-0.32842,50.00000,20.00000,5.626705e-08,0.84295
237.49100,1465.10000,     -0.54241,-0.32910,50.00000,20.00000,5.624544e-08,0.84254
237.99699,1470.10000,     -0.54974,-0.32910,50.00000,20.00000,5.629257e-08,0.84213
238.50000,1475.10000,     -0.55382,-0.33012,50.00000,20.00000,5.636809e-08,0.84171
238.99800,1480.10000,     -0.55736,-0.32898,50.00000,20.00000,5.630231e-08,0.84130
239.48199,1485.10000,     -0.56252,-0.33000,50.00000,20.00000,5.631007e-08,0.84090
239.99699,1490.10000,     -0.56771,-0.32932,50.00000,20.00000,5.631825e-08,0.84047
240.51100,1495.10000,     -0.57054,-0.32865,50.00000,20.00000,5.634462e-08,0.84005
240.99600,1500.10000,     -0.57699,-0.33046,50.00000,20.00000,5.635581e-08,0.83964
241.49899,1505.10000,     -0.58164,-0.33068,50.00000,20.00000,5.629915e-08,0.83923
242.00200,1510.10000,     -0.58412,-0.32978,50.00000,20.00000,5.634296e-08,0.83881
242.50400,1515.10000,     -0.59132,-0.33034,50.00000,20.00000,5.632191e-08,0.83839
242.99200,1520.10000,     -0.59580,-0.32842,50.00000,20.00000,5.636706e-08,0.83798
243.48599,1525.10000,     -0.60047,-0.33147,50.00000,20.00000,5.647751e-08,0.83757
243.99500,1530.10000,     -0.60770,-0.33159,50.00000,20.00000,5.636249e-08,0.83714
244.50500,1535.10000,     -0.61111,-0.33170,50.00000,20.00000,5.630049e-08,0.83671
244.98500,1540.10000,     -0.61688,-0.33272,50.00000,20.00000,5.637955e-08,0.83631
245.49899,1545.10000,     -0.62103,-0.33227,50.00000,20.00000,5.647500e-08,0.83588
246.00200,1550.10000,     -0.62737,-0.33170,50.00000,20.00000,5.642056e-08,0.83545
246.50101,1555.10000,     -0.63207,-0.33475,50.00000,20.00000,5.639006e-08,0.83503
247.01100,1560.10000,     -0.63624,-0.33442,50.00000,20.00000,5.645072e-08,0.83460
247.49800,1565.10000,     -0.64277,-0.33543,50.00000,20.00000,5.644564e-08,0.83419
248.00999,1570.10000,     -0.64549,-0.33396,50.00000,20.00000,5.648713e-08,0.83376
248.49200,1575.10000,     -0.65130,-0.33611,50.00000,20.00000,5.645015e-08,0.83335
248.99600,1580.10000,     -0.65474,-0.33509,50.00000,20.00000,5.658000e-08,0.83292
249.50000,1585.10000,     -0.66370,-0.33770,50.00000,20.00000,5.644739e-08,0.83249
249.98199,1590.10000,     -0.66677,-0.33690,50.00000,20.00000,5.645828e-08,0.83208
250.50101,1595.10000,     -0.67080,-0.33600,50.00000,20.00000,5.652294e-08,0.83164
250.99600,1600.10000,     -0.67701,-0.33724,50.00000,20.00000,5.649861e-08,0.83122
251.48599,1605.10000,     -0.67993,-0.33679,50.00000,20.00000,5.664399e-08,0.83080
251.98599,1610.10000,     -0.68708,-0.33713,50.00000,20.00000,5.656787e-08,0.83037
252.48500,1615.10000,     -0.69368,-0.33871,50.00000,20.00000,5.658577e-08,0.82994
253.00600,1620.10000,     -0.69626,-0.33962,50.00000,20.00000,5.655195e-08,0.82949
253.49300,1625.10000,     -0.70471,-0.33939,50.00000,20.00000,5.659865e-08,0.82908
253.99001,1630.10000,     -0.70857,-0.33905,50.00000,20.00000,5.657349e-08,0.82865
254.50500,1635.10000,     -0.71485,-0.34211,50.00000,20.00000,5.665663e-08,0.82820
254.99100,1640.10000,     -0.72019,-0.34199,50.00000,20.00000,5.660750e-08,0.82779
255.48801,1645.10000,     -0.72388,-0.34392,50.00000,20.00000,5.655938e-08,0.82736
255.99001,1650.10000,     -0.72943,-0.34505,50.00000,20.00000,5.654238e-08,0.82692
256.49399,1655.10000,     -0.73314,-0.34222,50.00000,20.00000,5.667288e-08,0.82649
256.98700,1660.10000,     -0.73739,-0.34313,50.00000,20.00000,5.668459e-08,0.82606
257.48300,1665.10000,     -0.74609,-0.34437,50.00000,20.00000,5.679944e-08,0.82563
257.98999,1670.10000,     -0.75260,-0.34539,50.00000,20.00000,5.671105e-08,0.82519
258.50299,1675.10000,     -0.76003,-0.34652,50.00000,20.00000,5.673757e-08,0.82474
258.99399,1680.10000,     -0.76172,-0.34743,50.00000,20.00000,5.666450e-08,0.82432
259.49301,1685.10000,     -0.76638,-0.34776,50.00000,20.00000,5.680864e-08,0.82388
259.99100,1690.10000,     -0.77402,-0.34754,50.00000,20.00000,5.678620e-08,0.82345
260.48801,1695.10000,     -0.77962,-0.35003,50.00000,20.00000,5.676125e-08,0.82301
260.99899,1700.10000,     -0.78449,-0.35105,50.00000,20.00000,5.686759e-08,0.82256
261.50201,1705.10000,     -0.78769,-0.35116,50.00000,20.00000,5.686599e-08,0.82212
261.98401,1710.10000,     -0.79404,-0.35195,50.00000,20.00000,5.676242e-08,0.82170
262.48999,1715.10000,     -0.79707,-0.35399,50.00000,20.00000,5.674925e-08,0.82126
262.99301,1720.10000,     -0.80642,-0.35410,50.00000,20.00000,5.681357e-08,0.82082
263.49701,1725.10000,     -0.80909,-0.35523,50.00000,20.00000,5.691660e-08,0.82037
263.98199,1730.10000,     -0.81900,-0.35625,50.00000,20.00000,5.694971e-08,0.81995
264.49899,1735.10000,     -0.82225,-0.35783,50.00000,20.00000,5.690458e-08,0.81949
264.99399,1740.10000,     -0.82921,-0.35942,50.00000,20.00000,5.688803e-08,0.81905
265.48999,1745.10000,     -0.83562,-0.36145,50.00000,20.00000,5.687431e-08,0.81862
265.99301,1750.10000,     -0.84055,-0.36077,50.00000,20.00000,5.698650e-08,0.81817
266.49701,1755.10000,     -0.84661,-0.36168,50.00000,20.00000,5.706272e-08,0.81773
266.99500,1760.10000,     -0.85266,-0.36304,50.00000,20.00000,5.705329e-08,0.81728
267.49799,1765.10000,     -0.85873,-0.36507,50.00000,20.00000,5.707921e-08,0.81684
267.98599,1770.10000,     -0.86386,-0.36575,50.00000,20.00000,5.708422e-08,0.81641
268.49500,1775.10000,     -0.86827,-0.36915,50.00000,20.00000,5.705785e-08,0.81595
268.98999,1780.10000,     -0.87697,-0.36949,50.00000,20.00000,5.705995e-08,0.81551
269.49100,1785.10000,     -0.88232,-0.37096,50.00000,20.00000,5.703250e-08,0.81507
269.98700,1790.10000,     -0.88823,-0.37254,50.00000,20.00000,5.699439e-08,0.81463
270.48901,1795.10000,     -0.89565,-0.37322,50.00000,20.00000,5.712071e-08,0.81418
271.00400,1800.10000,     -0.90197,-0.37514,50.00000,20.00000,5.708371e-08,0.81372
271.49399,1805.10000,     -0.90714,-0.37639,50.00000,20.00000,5.710868e-08,0.81328
272.00101,1810.10000,     -0.90972,-0.37740,50.00000,20.00000,5.705160e-08,0.81283
272.48099,1815.10000,     -0.91809,-0.37944,50.00000,20.00000,5.704346e-08,0.81240
272.99500,1820.10000,     -0.92218,-0.37888,50.00000,20.00000,5.717168e-08,0.81194
273.49399,1825.10000,     -0.93039,-0.38182,50.00000,20.00000,5.719072e-08,0.81149
274.01001,1830.10000,     -0.93318,-0.38238,50.00000,20.00000,5.726563e-08,0.81103
274.50800,1835.10000,     -0.93916,-0.38295,50.00000,20.00000,5.725729e-08,0.81058
274.98401,1840.10000,     -0.94700,-0.38306,50.00000,20.00000,5.725383e-08,0.81015
275.49701,1845.10000,     -0.95621,-0.38566,50.00000,20.00000,5.725332e-08,0.80969
275.98599,1850.10000,     -0.96295,-0.38951,50.00000,20.00000,5.740595e-08,0.80925
276.48300,1855.10000,     -0.97254,-0.39222,50.00000,20.00000,5.723959e-08,0.80880
277.00101,1860.10000,     -0.97348,-0.39313,50.00000,20.00000,5.733440e-08,0.80833
277.49301,1865.10000,     -0.97930,-0.39483,50.00000,20.00000,5.733468e-08,0.80789
277.98001,1870.10000,     -0.98796,-0.39765,50.00000,20.00000,5.730059e-08,0.80745
278.49500,1875.10000,     -0.99251,-0.39913,50.00000,20.00000,5.741704e-08,0.80698
278.99100,1880.10000,     -0.99911,-0.40116,50.00000,20.00000,5.742861e-08,0.80653
279.49301,1885.10000,     -1.00308,-0.40410,50.00000,20.00000,5.740720e-08,0.80608
279.99200,1890.10000,     -1.01463,-0.40580,50.00000,20.00000,5.746640e-08,0.80562
280.49701,1895.10000,     -1.01881,-0.40784,50.00000,20.00000,5.755205e-08,0.80517
280.99399,1900.10000,     -1.02659,-0.41078,50.00000,20.00000,5.747832e-08,0.80471
281.48300,1905.10000,     -1.02829,-0.41270,50.00000,20.00000,5.755811e-08,0.80427
282.00500,1910.10000,     -1.03782,-0.41598,50.00000,20.00000,5.754948e-08,0.80380
282.49100,1915.10000,     -1.04181,-0.41881,50.00000,20.00000,5.749766e-08,0.80335
282.98801,1920.10000,     -1.05038,-0.42232,50.00000,20.00000,5.751833e-08,0.80290
283.48599,1925.10000,     -1.05535,-0.42526,50.00000,20.00000,5.753561e-08,0.80245
284.01001,1930.10000,     -1.06188,-0.42605,50.00000,20.00000,5.757362e-08,0.80197
284.48901,1935.10000,     -1.07350,-0.42990,50.00000,20.00000,5.763065e-08,0.80153
284.98700,1940.10000,     -1.07583,-0.43420,50.00000,20.00000,5.763767e-08,0.80107
285.49799,1945.10000,     -1.08255,-0.43555,50.00000,20.00000,5.769098e-08,0.80061
285.99100,1950.10000,     -1.09003,-0.43816,50.00000,20.00000,5.768691e-08,0.80016
286.49799,1955.10000,     -1.09600,-0.44325,50.00000,20.00000,5.761268e-08,0.79969
286.98099,1960.10000,     -1.10310,-0.44426,50.00000,20.00000,5.769177e-08,0.79925
287.49701,1965.10000,     -1.11331,-0.44777,50.00000,20.00000,5.773824e-08,0.79877
287.98999,1970.10000,     -1.11795,-0.45184,50.00000,20.00000,5.780245e-08,0.79832
288.49100,1975.10000,     -1.12529,-0.45343,50.00000,20.00000,5.770374e-08,0.79786
288.98599,1980.10000,     -1.13091,-0.45795,50.00000,20.00000,5.778390e-08,0.79741
289.49100,1985.10000,     -1.13770,-0.45942,50.00000,20.00000,5.778248e-08,0.79694
289.98401,1990.10000,     -1.14390,-0.46576,50.00000,20.00000,5.781144e-08,0.79649
290.49100,1995.10000,     -1.15051,-0.46983,50.00000,20.00000,5.774929e-08,0.79602
290.99301,2000.10000,     -1.15655,-0.47187,50.00000,20.00000,5.773321e-08,0.79556
291.48801,2005.10000,     -1.16489,-0.47809,50.00000,20.00000,5.782549e-08,0.79510
291.98801,2010.10000,     -1.17018,-0.48069,50.00000,20.00000,5.791154e-08,0.79464
292.48499,2015.10000,     -1.17777,-0.48522,50.00000,20.00000,5.787611e-08,0.79418
293.00299,2020.10000,     -1.18502,-0.48997,50.00000,20.00000,5.788077e-08,0.79370
293.48001,2025.10000,     -1.19183,-0.49393,50.00000,20.00000,5.794354e-08,0.79326
293.99399,2030.10000,     -1.19717,-0.49721,50.00000,20.00000,5.800856e-08,0.79279
294.50101,2035.10000,     -1.20481,-0.50151,50.00000,20.00000,5.795194e-08,0.79232
294.97900,2040.10000,     -1.21319,-0.50716,50.00000,20.00000,5.794141e-08,0.79187
295.49200,2045.10000,     -1.21951,-0.51158,50.00000,20.00000,5.797112e-08,0.79140
295.98499,2050.10000,     -1.22832,-0.51497,50.00000,20.00000,5.802475e-08,0.79094
296.49500,2055.10000,     -1.23388,-0.52198,50.00000,20.00000,5.807754e-08,0.79047
296.99301,2060.10000,     -1.23963,-0.52708,50.00000,20.00000,5.809997e-08,0.79000
297.48700,2065.10000,     -1.24943,-0.53081,50.00000,20.00000,5.818434e-08,0.78955
297.99600,2070.10000,     -1.25598,-0.53828,50.00000,20.00000,5.814958e-08,0.78907
298.49301,2075.10000,     -1.26155,-0.54529,50.00000,20.00000,5.815406e-08,0.78861
298.98001,2080.10000,     -1.26828,-0.55004,50.00000,20.00000,5.820507e-08,0.78816
299.49399,2085.10000,     -1.27641,-0.55706,50.00000,20.00000,5.819002e-08,0.78768
299.99200,2090.10000,     -1.28453,-0.56328,50.00000,20.00000,5.823222e-08,0.78721
300.49399,2095.10000,     -1.29150,-0.57108,50.00000,20.00000,5.822076e-08,0.78675
300.98700,2100.10000,     -1.29730,-0.57482,50.00000,20.00000,5.830258e-08,0.78629
301.49399,2105.10000,     -1.30197,-0.58364,50.00000,20.00000,5.820875e-08,0.78581
301.99701,2110.10000,     -1.31266,-0.58975,50.00000,20.00000,5.827053e-08,0.78534
302.49899,2115.10000,     -1.32122,-0.59891,50.00000,20.00000,5.840643e-08,0.78487
302.98901,2120.10000,     -1.32724,-0.60751,50.00000,20.00000,5.833466e-08,0.78442
303.47800,2125.10000,     -1.33385,-0.61294,50.00000,20.00000,5.840986e-08,0.78396
303.99200,2130.10000,     -1.33720,-0.62075,50.00000,20.00000,5.840833e-08,0.78348
304.49100,2135.10000,     -1.34833,-0.63093,50.00000,20.00000,5.843148e-08,0.78301
304.99100,2140.10000,     -1.35713,-0.63975,50.00000,20.00000,5.852185e-08,0.78254
305.48199,2145.10000,     -1.36573,-0.64790,50.00000,20.00000,5.856207e-08,0.78208
305.99799,2150.10000,     -1.37107,-0.65740,50.00000,20.00000,5.849956e-08,0.78160
306.50000,2155.10000,     -1.37463,-0.66566,50.00000,20.00000,5.852161e-08,0.78113
307.00601,2160.10000,     -1.38641,-0.67788,50.00000,20.00000,5.847770e-08,0.78065
307.49600,2165.10000,     -1.39310,-0.68851,50.00000,20.00000,5.853832e-08,0.78019
307.98999,2170.10000,     -1.40175,-0.69937,50.00000,20.00000,5.855805e-08,0.77973
308.48999,2175.10000,     -1.40671,-0.70989,50.00000,20.00000,5.861373e-08,0.77926
308.98199,2180.10000,     -1.41636,-0.72155,50.00000,20.00000,5.862662e-08,0.77880
309.47800,2185.10000,     -1.42407,-0.73309,50.00000,20.00000,5.863222e-08,0.77833
309.99500,2190.10000,     -1.43065,-0.74632,50.00000,20.00000,5.867863e-08,0.77784
310.48401,2195.10000,     -1.43935,-0.75820,50.00000,20.00000,5.869488e-08,0.77738
310.98599,2200.10000,     -1.44651,-0.77381,50.00000,20.00000,5.866064e-08,0.77691
311.48499,2205.10000,     -1.45289,-0.78603,50.00000,20.00000,5.868622e-08,0.77644
311.99100,2210.10000,     -1.46381,-0.80096,50.00000,20.00000,5.871679e-08,0.77596
312.49899,2215.10000,     -1.47141,-0.81522,50.00000,20.00000,5.871837e-08,0.77548
312.99600,2220.10000,     -1.47781,-0.82981,50.00000,20.00000,5.875965e-08,0.77502
313.48999,2225.10000,     -1.48067,-0.84271,50.00000,20.00000,5.875796e-08,0.77455
313.98401,2230.10000,     -1.49615,-0.85968,50.00000,20.00000,5.885789e-08,0.77408
314.48999,2235.10000,     -1.50161,-0.87427,50.00000,20.00000,5.889894e-08,0.77361
314.98999,2240.10000,     -1.50588,-0.89192,50.00000,20.00000,5.895699e-08,0.77313
315.48999,2245.10000,     -1.51352,-0.90957,50.00000,20.00000,5.893082e-08,0.77266
315.98999,2250.10000,     -1.52452,-0.92722,50.00000,20.00000,5.897254e-08,0.77219
316.49399,2255.10000,     -1.52961,-0.94792,50.00000,20.00000,5.899445e-08,0.77171
317.01300,2260.10000,     -1.53949,-0.96670,50.00000,20.00000,5.905635e-08,0.77122
317.50900,2265.10000,     -1.54577,-0.98604,50.00000,20.00000,5.918837e-08,0.77075
318.01300,2270.10000,     -1.55465,-1.00652,50.00000,20.00000,5.916486e-08,0.77027
318.51401,2275.10000,     -1.56314,-1.02836,50.00000,20.00000,5.910167e-08,0.76980
319.01700,2280.10000,     -1.57224,-1.05211,50.00000,20.00000,5.911649e-08,0.76932
319.50601,2285.10000,     -1.58053,-1.07417,50.00000,20.00000,5.915750e-08,0.76886
319.99701,2290.10000,     -1.58765,-1.09816,50.00000,20.00000,5.914531e-08,0.76840
320.49500,2295.10000,     -1.59816,-1.12225,50.00000,20.00000,5.923100e-08,0.76792
321.00800,2300.10000,     -1.60554,-1.14839,50.00000,20.00000,5.927990e-08,0.76744
321.50201,2305.10000,     -1.61229,-1.17508,50.00000,20.00000,5.932727e-08,0.76697
321.99899,2310.10000,     -1.62164,-1.20077,50.00000,20.00000,5.940704e-08,0.76650
322.50601,2315.10000,     -1.62684,-1.22871,50.00000,20.00000,5.945044e-08,0.76602
323.00101,2320.10000,     -1.63780,-1.25518,50.00000,20.00000,5.943379e-08,0.76555
323.51099,2325.10000,     -1.64662,-1.28550,50.00000,20.00000,5.952275e-08,0.76506
324.01599,2330.10000,     -1.65543,-1.31627,50.00000,20.00000,5.951008e-08,0.76458
324.48999,2335.10000,     -1.66340,-1.34851,50.00000,20.00000,5.950779e-08,0.76413
325.01801,2340.10000,     -1.66769,-1.38076,50.00000,20.00000,5.959856e-08,0.76363
325.50699,2345.10000,     -1.67710,-1.41322,50.00000,20.00000,5.959602e-08,0.76317
326.00299,2350.10000,     -1.68834,-1.44841,50.00000,20.00000,5.972896e-08,0.76269
326.49899,2355.10000,     -1.69399,-1.48404,50.00000,20.00000,5.977799e-08,0.76222
327.00101,2360.10000,     -1.70507,-1.52126,50.00000,20.00000,5.992494e-08,0.76175
327.49701,2365.10000,     -1.71294,-1.55916,50.00000,20.00000,5.988295e-08,0.76127
328.01099,2370.10000,     -1.72387,-1.59842,50.00000,20.00000,5.993078e-08,0.76079
328.49200,2375.10000,     -1.73233,-1.63813,50.00000,20.00000,5.999059e-08,0.76033
329.01001,2380.10000,     -1.73868,-1.67919,50.00000,20.00000,6.000669e-08,0.75983
329.50400,2385.10000,     -1.74638,-1.72207,50.00000,20.00000,6.006479e-08,0.75936
330.00699,2390.10000,     -1.75633,-1.76732,50.00000,20.00000,6.002740e-08,0.75889
330.51001,2395.10000,     -1.76428,-1.81155,50.00000,20.00000,6.012144e-08,0.75841
331.00201,2400.10000,     -1.76980,-1.85873,50.00000,20.00000,6.017773e-08,0.75794
331.50900,2405.10000,     -1.78302,-1.90647,50.00000,20.00000,6.018504e-08,0.75746
331.99500,2410.10000,     -1.79278,-1.95636,50.00000,20.00000,6.023395e-08,0.75699
332.51099,2415.10000,     -1.79858,-2.00467,50.00000,20.00000,6.029430e-08,0.75650
332.99799,2420.10000,     -1.80816,-2.05693,50.00000,20.00000,6.034403e-08,0.75604
333.51001,2425.10000,     -1.81720,-2.11044,50.00000,20.00000,6.039759e-08,0.75555
334.00500,2430.10000,     -1.82622,-2.16441,50.00000,20.00000,6.039340e-08,0.75508
334.49899,2435.10000,     -1.84172,-2.21837,50.00000,20.00000,6.044866e-08,0.75461
335.00699,2440.10000,     -1.84937,-2.27448,50.00000,20.00000,6.063065e-08,0.75412
335.51099,2445.10000,     -1.86230,-2.33263,50.00000,20.00000,6.056631e-08,0.75364
336.00699,2450.10000,     -1.86914,-2.39112,50.00000,20.00000,6.063150e-08,0.75317
336.50299,2455.10000,     -1.87944,-2.45051,50.00000,20.00000,6.073645e-08,0.75270
337.01599,2460.10000,     -1.89202,-2.51104,50.00000,20.00000,6.070012e-08,0.75221
337.51401,2465.10000,     -1.90133,-2.57269,50.00000,20.00000,6.091900e-08,0.75173
338.00000,2470.10000,     -1.90779,-2.63740,50.00000,20.00000,6.085668e-08,0.75127
338.50201,2475.10000,     -1.92404,-2.69996,50.00000,20.00000,6.092502e-08,0.75079
339.01999,2480.10000,     -1.93304,-2.76660,50.00000,20.00000,6.108719e-08,0.75029
339.50000,2485.10000,     -1.94724,-2.83052,50.00000,20.00000,6.106286e-08,0.74984
340.00101,2490.10000,     -1.95561,-2.89647,50.00000,20.00000,6.113360e-08,0.74936
340.50299,2495.10000,     -1.96502,-2.96458,50.00000,20.00000,6.123434e-08,0.74888
341.01099,2500.10000,     -1.97791,-3.02997,50.00000,20.00000,6.127350e-08,0.74839
341.50101,2505.10000,     -1.99465,-3.09773,50.00000,20.00000,6.133531e-08,0.74793
341.99899,2510.10000,     -2.00449,-3.16606,50.00000,20.00000,6.140169e-08,0.74745
342.51099,2515.10000,     -2.01827,-3.23609,50.00000,20.00000,6.141809e-08,0.74696
342.99600,2520.10000,     -2.02872,-3.30419,50.00000,20.00000,6.156335e-08,0.74650
343.50699,2525.10000,     -2.04313,-3.37320,50.00000,20.00000,6.159769e-08,0.74601
344.00900,2530.10000,     -2.05734,-3.44221,50.00000,20.00000,6.166527e-08,0.74553
344.52499,2535.10000,     -2.07140,-3.51439,50.00000,20.00000,6.164907e-08,0.74504
344.99799,2540.10000,     -2.08577,-3.58193,50.00000,20.00000,6.170541e-08,0.74459
345.50699,2545.10000,     -2.09944,-3.64879,50.00000,20.00000,6.174780e-08,0.74410
346.00201,2550.10000,     -2.11267,-3.71723,50.00000,20.00000,6.190414e-08,0.74363
346.50800,2555.10000,     -2.12842,-3.78409,50.00000,20.00000,6.193216e-08,0.74315
347.00500,2560.10000,     -2.14293,-3.84925,50.00000,20.00000,6.207557e-08,0.74267
347.51599,2565.10000,     -2.15935,-3.91566,50.00000,20.00000,6.209967e-08,0.74218
347.99399,2570.10000,     -2.17425,-3.97901,50.00000,20.00000,6.217546e-08,0.74173
348.50299,2575.10000,     -2.18967,-4.04418,50.00000,20.00000,6.232386e-08,0.74124
349.00000,2580.10000,     -2.20776,-4.10470,50.00000,20.00000,6.237259e-08,0.74077
349.51901,2585.10000,     -2.22223,-4.16421,50.00000,20.00000,6.240471e-08,0.74027
350.00299,2590.10000,     -2.24383,-4.22462,50.00000,20.00000,6.252904e-08,0.73981
350.50201,2595.10000,     -2.26034,-4.28379,50.00000,20.00000,6.265187e-08,0.73933
351.01199,2600.10000,     -2.27856,-4.34114,50.00000,20.00000,6.267234e-08,0.73885
351.49399,2605.10000,     -2.29857,-4.39624,50.00000,20.00000,6.272463e-08,0.73839
352.00800,2610.10000,     -2.31520,-4.44590,50.00000,20.00000,6.280812e-08,0.73790
352.50101,2615.10000,     -2.33323,-4.49794,50.00000,20.00000,6.284927e-08,0.73743
353.00400,2620.10000,     -2.35338,-4.54704,50.00000,20.00000,6.290954e-08,0.73695
353.50400,2625.10000,     -2.37190,-4.59297,50.00000,20.00000,6.297804e-08,0.73647
354.01099,2630.10000,     -2.38921,-4.63619,50.00000,20.00000,6.311694e-08,0.73598
354.51001,2635.10000,     -2.40881,-4.67850,50.00000,20.00000,6.320306e-08,0.73551
355.00400,2640.10000,     -2.42800,-4.71866,50.00000,20.00000,6.318939e-08,0.73504
355.50201,2645.10000,     -2.44390,-4.75724,50.00000,20.00000,6.322952e-08,0.73456
356.00900,2650.10000,     -2.46692,-4.79174,50.00000,20.00000,6.330567e-08,0.73408
356.50400,2655.10000,     -2.48411,-4.82500,50.00000,20.00000,6.333348e-08,0.73361
357.02100,2660.10000,     -2.50638,-4.85656,50.00000,20.00000,6.350984e-08,0.73311
357.50699,2665.10000,     -2.52567,-4.88643,50.00000,20.00000,6.350452e-08,0.73265
358.00500,2670.10000,     -2.54523,-4.91234,50.00000,20.00000,6.360446e-08,0.73218
358.50601,2675.10000,     -2.56087,-4.93847,50.00000,20.00000,6.372949e-08,0.73170
359.00601,2680.10000,     -2.58465,-4.96257,50.00000,20.00000,6.372756e-08,0.73122
359.48901,2685.10000,     -2.60236,-4.98350,50.00000,20.00000,6.384622e-08,0.73076
360.01199,2690.10000,     -2.62670,-5.00431,50.00000,20.00000,6.394100e-08,0.73026
360.50101,2695.10000,     -2.64281,-5.02230,50.00000,20.00000,6.399825e-08,0.72980
361.00900,2700.10000,     -2.66151,-5.03916,50.00000,20.00000,6.393545e-08,0.72931
361.49600,2705.10000,     -2.68037,-5.05488,50.00000,20.00000,6.407075e-08,0.72885
362.00101,2710.10000,     -2.70288,-5.06755,50.00000,20.00000,6.412375e-08,0.72837
362.50601,2715.10000,     -2.71703,-5.07943,50.00000,20.00000,6.412103e-08,0.72789
363.00500,2720.10000,     -2.73601,-5.08916,50.00000,20.00000,6.413508e-08,0.72741
363.49799,2725.10000,     -2.75373,-5.10047,50.00000,20.00000,6.420710e-08,0.72694
364.00201,2730.10000,     -2.77256,-5.10930,50.00000,20.00000,6.425441e-08,0.72646
364.51700,2735.10000,     -2.78830,-5.11993,50.00000,20.00000,6.435152e-08,0.72597
365.01300,2740.10000,     -2.80841,-5.12536,50.00000,20.00000,6.442513e-08,0.72550
365.49600,2745.10000,     -2.81987,-5.13204,50.00000,20.00000,6.440732e-08,0.72504
366.00699,2750.10000,     -2.83356,-5.13780,50.00000,20.00000,6.452089e-08,0.72456
366.50101,2755.10000,     -2.85015,-5.14471,50.00000,20.00000,6.455107e-08,0.72409
367.01001,2760.10000,     -2.86091,-5.14878,50.00000,20.00000,6.462678e-08,0.72360
367.50500,2765.10000,     -2.87839,-5.15432,50.00000,20.00000,6.469389e-08,0.72313
368.00000,2770.10000,     -2.89504,-5.16032,50.00000,20.00000,6.469781e-08,0.72266
368.49100,2775.10000,     -2.90874,-5.16337,50.00000,20.00000,6.476939e-08,0.72219
369.00500,2780.10000,     -2.92065,-5.16665,50.00000,20.00000,6.487690e-08,0.72171
369.48700,2785.10000,     -2.93752,-5.16914,50.00000,20.00000,6.487333e-08,0.72125
369.99600,2790.10000,     -2.95156,-5.17208,50.00000,20.00000,6.498391e-08,0.72077
370.50400,2795.10000,     -2.96624,-5.17412,50.00000,20.00000,6.491202e-08,0.72028
371.00000,2800.10000,     -2.98027,-5.17819,50.00000,20.00000,6.498388e-08,0.71981
371.50800,2805.10000,     -2.99669,-5.18068,50.00000,20.00000,6.500183e-08,0.71933
371.99301,2810.10000,     -3.01495,-5.18102,50.00000,20.00000,6.508134e-08,0.71887
372.49899,2815.10000,     -3.02248,-5.18147,50.00000,20.00000,6.510124e-08,0.71839
373.00000,2820.10000,     -3.04361,-5.18419,50.00000,20.00000,6.515000e-08,0.71792
373.50699,2825.10000,     -3.05607,-5.18543,50.00000,20.00000,6.518775e-08,0.71744
374.01099,2830.10000,     -3.06811,-5.18724,50.00000,20.00000,6.520777e-08,0.71696
374.50000,2835.10000,     -3.08607,-5.18826,50.00000,20.00000,6.531112e-08,0.71650
374.99701,2840.10000,     -3.10131,-5.19075,50.00000,20.00000,6.532126e-08,0.71602
375.51300,2845.10000,     -3.11750,-5.19211,50.00000,20.00000,6.536057e-08,0.71554
376.00400,2850.10000,     -3.13702,-5.19380,50.00000,20.00000,6.531173e-08,0.71507
376.51401,2855.10000,     -3.15088,-5.19380,50.00000,20.00000,6.538404e-08,0.71459
377.00400,2860.10000,     -3.16874,-5.19516,50.00000,20.00000,6.542092e-08,0.71413
377.50000,2865.10000,     -3.18622,-5.19663,50.00000,20.00000,6.544494e-08,0.71366
377.99500,2870.10000,     -3.19965,-5.19754,50.00000,20.00000,6.554965e-08,0.71319
378.51199,2875.10000,     -3.21704,-5.19923,50.00000,20.00000,6.551741e-08,0.71270
379.00500,2880.10000,     -3.23286,-5.19844,50.00000,20.00000,6.560027e-08,0.71223
379.49701,2885.10000,     -3.25104,-5.19889,50.00000,20.00000,6.555738e-08,0.71177
379.99600,2890.10000,     -3.26500,-5.19969,50.00000,20.00000,6.562032e-08,0.71130
380.51901,2895.10000,     -3.28293,-5.19969,50.00000,20.00000,6.566720e-08,0.71081
380.99301,2900.10000,     -3.29703,-5.19889,50.00000,20.00000,6.575233e-08,0.71036
381.50000,2905.10000,     -3.31387,-5.19991,50.00000,20.00000,6.577612e-08,0.70988
381.99500,2910.10000,     -3.33067,-5.20195,50.00000,20.00000,6.579577e-08,0.70941
382.50299,2915.10000,     -3.34067,-5.20082,50.00000,20.00000,6.583079e-08,0.70893
383.01401,2920.10000,     -3.35306,-5.20093,50.00000,20.00000,6.580382e-08,0.70845
383.50500,2925.10000,     -3.37293,-5.20240,50.00000,20.00000,6.575820e-08,0.70799
384.00400,2930.10000,     -3.38358,-5.20263,50.00000,20.00000,6.589759e-08,0.70752
384.48999,2935.10000,     -3.39612,-5.20387,50.00000,20.00000,6.589618e-08,0.70706
384.99600,2940.10000,     -3.41094,-5.20433,50.00000,20.00000,6.591754e-08,0.70659
385.50299,2945.10000,     -3.42124,-5.20331,50.00000,20.00000,6.599164e-08,0.70611
385.99799,2950.10000,     -3.43560,-5.20342,50.00000,20.00000,6.592470e-08,0.70565
386.49100,2955.10000,     -3.45041,-5.20342,50.00000,20.00000,6.598921e-08,0.70518
387.00101,2960.10000,     -3.46639,-5.20229,50.00000,20.00000,6.595442e-08,0.70470
387.50299,2965.10000,     -3.47608,-5.20172,50.00000,20.00000,6.594327e-08,0.70423
388.00699,2970.10000,     -3.48882,-5.20218,50.00000,20.00000,6.603303e-08,0.70376
388.51001,2975.10000,     -3.50332,-5.20195,50.00000,20.00000,6.608151e-08,0.70329
389.00400,2980.10000,     -3.51605,-5.20082,50.00000,20.00000,6.611830e-08,0.70282
389.49799,2985.10000,     -3.52944,-5.20184,50.00000,20.00000,6.610141e-08,0.70236
390.01099,2990.10000,     -3.54382,-5.20161,50.00000,20.00000,6.616121e-08,0.70188
390.50101,2995.10000,     -3.55462,-5.20037,50.00000,20.00000,6.618452e-08,0.70142
391.00101,3000.10000,     -3.57071,-5.20127,50.00000,20.00000,6.618853e-08,0.70095
391.50000,3005.10000,     -3.58311,-5.19991,50.00000,20.00000,6.620765e-08,0.70049
392.00699,3010.10000,     -3.59709,-5.20025,50.00000,20.00000,6.623851e-08,0.70001
392.49200,3015.10000,     -3.60989,-5.19889,50.00000,20.00000,6.623445e-08,0.69956
392.99701,3020.10000,     -3.61931,-5.19969,50.00000,20.00000,6.633113e-08,0.69909
393.50800,3025.10000,     -3.63445,-5.19957,50.00000,20.00000,6.628755e-08,0.69861
393.99200,3030.10000,     -3.64752,-5.19878,50.00000,20.00000,6.629607e-08,0.69816
394.50601,3035.10000,     -3.66074,-5.19742,50.00000,20.00000,6.628386e-08,0.69768
394.99799,3040.10000,     -3.67409,-5.19652,50.00000,20.00000,6.633787e-08,0.69722
395.51199,3045.10000,     -3.69107,-5.19765,50.00000,20.00000,6.632110e-08,0.69674
395.99799,3050.10000,     -3.70180,-5.19697,50.00000,20.00000,6.635578e-08,0.69629
396.50101,3055.10000,     -3.71372,-5.19663,50.00000,20.00000,6.627675e-08,0.69582
397.00201,3060.10000,     -3.73245,-5.19731,50.00000,20.00000,6.633479e-08,0.69535
397.50101,3065.10000,     -3.74725,-5.19663,50.00000,20.00000,6.635277e-08,0.69489
397.98099,3070.10000,     -3.75998,-5.19663,50.00000,20.00000,6.633120e-08,0.69444
398.51001,3075.10000,     -3.77430,-5.19607,50.00000,20.00000,6.634988e-08,0.69395
399.00299,3080.10000,     -3.78692,-5.19618,50.00000,20.00000,6.642062e-08,0.69349
399.50000,3085.10000,     -3.79935,-5.19618,50.00000,20.00000,6.637816e-08,0.69303
399.99600,3090.00000,     -3.81223,-5.19550,50.00000,20.00000,6.633923e-08,0.69257