File: data/TGA/005c/ExpDat_2024_06_20_PS2439_6_1K_dynamic.csv
#EXPORTTYPE:                 ,DATA ALL
#FILE:                       ,2024_06_20_PS2439_6_1K_dynamic.ngb-ss5
#FORMAT:                     ,NETZSCH5
#FTYPE:                      ,ASCII
#IDENTITY:                   ,PS
#DECIMAL:                    ,POINT
#SEPARATOR:                  ,COMMA
#MTYPE:                      ,DSC
#INSTRUMENT:                 ,NETZSCH STA 449F5
#PROJECT:                    ,
#DATE/TIME:                  ,6/20/2024 12:36:34 PM (UTC-4)
#CORR. FILE:                 ,
#TEMPCAL:                    ,28-06-2023 13:26
#SENSITIVITY:                ,28-06-2023 13:53
#LABORATORY:                 ,
#OPERATOR:                   ,Stanley
#REMARK:                     ,
#SAMPLE:                     ,PS2439_6.1K
#SAMPLE MASS /mg:            ,5.02
#MATERIAL:                   ,
#REFERENCE:                  ,-----
#REFERENCE MASS /mg:         ,0
#TYPE OF CRUCIBLE:           ,Al2O3 85 ‘l, open
#SAMPLE CRUCIBLE MASS /mg:   ,0
#REFERENCE CRUCIBLE MASS /mg:,0
#DSC RANGE /‘V:              ,5000
#TG RANGE /mg:               ,35000
#TAU-R:                      ,---
#CORR. CODE:                 ,000
#EXO:                        ,-1
#RANGE:                      ,20›C....800›C/0.0....5.0K/min
#SEGMENT:                    ,S1-4/4
#SEG. 1:                     ,20›C/5.0(K/min)/100›C
#SEG. 2:                     ,100›C/00:05/100›C
#SEG. 3:                     ,100›C/1.0(K/min)/400›C
#SEG. 4:                     ,400›C/5.0(K/min)/800›C

##Temp./›C,Time/min,DSC/(mW/mg),Mass loss/mg,Gas Flow(purge2)/(ml/min),Gas Flow(protective)/(ml/min),TIC(scan:1)/A,Sensit./(uV/mW),Segment
 31.75000,  0.00000,-6.547260e-02, 0.000000e+00,50.00000,20.00000,6.081995e-08,0.92387,1
 31.89800,  0.80000,-3.487388e-02, 8.030000e-03,50.00000,20.00000,6.072812e-08,0.92389,1
 32.28600,  1.60000, 1.036272e-02, 2.002000e-02,50.00000,20.00000,6.054677e-08,0.92396,1
 32.80200,  2.40000, 3.305889e-02, 2.511000e-02,50.00000,20.00000,6.025906e-08,0.92405,1
 33.52100,  3.20000, 7.975876e-02, 4.265000e-02,50.00000,20.00000,6.019992e-08,0.92417,1
 34.75400,  4.00000,      0.17593, 7.579000e-02,50.00000,20.00000,5.996698e-08,0.92436,1
 36.58700,  4.80000,      0.30671,      0.11256,50.00000,20.00000,5.971196e-08,0.92463,1
 39.08500,  5.60000,      0.44725,      0.15216,50.00000,20.00000,5.963928e-08,0.92497,1
 42.16700,  6.40000,      0.58668,      0.19096,50.00000,20.00000,5.938511e-08,0.92532,1
 45.80000,  7.20000,      0.71699,      0.22264,50.00000,20.00000,5.929291e-08,0.92567,1
 49.87800,  8.00000,      0.83725,      0.25296,50.00000,20.00000,5.909826e-08,0.92595,1
 54.34000,  8.80000,      0.94309,      0.27943,50.00000,20.00000,5.908266e-08,0.92614,1
 59.06500,  9.60000,      1.03196,      0.30036,50.00000,20.00000,5.902468e-08,0.92620,1
 64.01100, 10.40000,      1.10196,      0.31733,50.00000,20.00000,5.893423e-08,0.92612,1
 68.98900, 11.20000,      1.15264,      0.33147,50.00000,20.00000,5.865656e-08,0.92588,1
 73.99000, 12.00000,      1.18992,      0.34335,50.00000,20.00000,5.874394e-08,0.92548,1
 78.96100, 12.80000,      1.21740,      0.35172,50.00000,20.00000,5.870229e-08,0.92494,1
 83.89300, 13.60000,      1.24115,      0.35986,50.00000,20.00000,5.851333e-08,0.92426,1
 88.72200, 14.40000,      1.27417,      0.36665,50.00000,20.00000,5.866477e-08,0.92345,1
 93.47900, 15.20000,      1.30000,      0.37208,50.00000,20.00000,5.856226e-08,0.92252,1
 98.12702, 16.00000,      1.28629,      0.37505,50.00000,20.00000,5.855147e-08,0.92148,2
102.06034, 16.80000,      1.06401,      0.36116,50.00000,20.00000,5.845129e-08,0.92051,2
104.60549, 17.60000,      0.69783,      0.32970,50.00000,20.00000,5.875047e-08,0.91983,2
106.25333, 18.40000,      0.46291,      0.30888,50.00000,20.00000,5.867770e-08,0.91937,2
107.38104, 19.20000,      0.30720,      0.29275,50.00000,20.00000,5.852776e-08,0.91905,2
107.95334, 20.00000,      0.15845,      0.27508,50.00000,20.00000,5.862134e-08,0.91889,2
108.03838, 20.80000, 2.356777e-02,      0.25756,50.00000,20.00000,5.838775e-08,0.91886,2
107.80137, 21.60000,-5.619896e-02,      0.24685,50.00000,20.00000,5.836045e-08,0.91893,3
107.55233, 22.40000,-6.268168e-02,      0.24141,50.00000,20.00000,5.842665e-08,0.91900,3
107.33812, 23.20000,-5.489376e-02,      0.23735,50.00000,20.00000,5.823259e-08,0.91907,3
107.13009, 24.00000,-4.878601e-02,      0.23463,50.00000,20.00000,5.841298e-08,0.91913,3
107.01203, 24.80000,-2.913181e-02,      0.23406,50.00000,20.00000,5.814041e-08,0.91916,3
106.94493, 25.60000, 8.033443e-04,      0.23271,50.00000,20.00000,5.824325e-08,0.91918,3
107.01586, 26.40000, 3.402696e-02,      0.23507,50.00000,20.00000,5.822549e-08,0.91916,3
107.21074, 27.20000, 6.775254e-02,      0.23712,50.00000,20.00000,5.791903e-08,0.91910,3
107.53769, 28.00000, 9.902336e-02,      0.23779,50.00000,20.00000,5.796030e-08,0.91901,3
107.93356, 28.80000,      0.13049,      0.24050,50.00000,20.00000,5.788666e-08,0.91889,3
108.44449, 29.60000,      0.15763,      0.24323,50.00000,20.00000,5.794683e-08,0.91874,3
109.01947, 30.40000,      0.18048,      0.24220,50.00000,20.00000,5.786950e-08,0.91857,3
109.68231, 31.20000,      0.20072,      0.24492,50.00000,20.00000,5.779604e-08,0.91838,3
110.39025, 32.00000,      0.21914,      0.24627,50.00000,20.00000,5.766839e-08,0.91816,3
111.13814, 32.80000,      0.23245,      0.24764,50.00000,20.00000,5.756207e-08,0.91793,3
111.93408, 33.60000,      0.24459,      0.24843,50.00000,20.00000,5.765879e-08,0.91768,3
112.74426, 34.40000,      0.25245,      0.24978,50.00000,20.00000,5.749874e-08,0.91743,3
113.56819, 35.20000,      0.25849,      0.24979,50.00000,20.00000,5.752920e-08,0.91717,3
114.41724, 36.00000,      0.26322,      0.24979,50.00000,20.00000,5.754542e-08,0.91689,3
115.24217, 36.80000,      0.26478,      0.25001,50.00000,20.00000,5.747183e-08,0.91662,3
116.09415, 37.60000,      0.26653,      0.24968,50.00000,20.00000,5.741586e-08,0.91633,3
116.93627, 38.40000,      0.26809,      0.25250,50.00000,20.00000,5.740099e-08,0.91605,3
117.78917, 39.20000,      0.26969,      0.25080,50.00000,20.00000,5.745988e-08,0.91576,3
118.62714, 40.00000,      0.26943,      0.25116,50.00000,20.00000,5.747895e-08,0.91547,3
119.45423, 40.80000,      0.26886,      0.25115,50.00000,20.00000,5.733097e-08,0.91518,3
120.27418, 41.60000,      0.26895,      0.25353,50.00000,20.00000,5.731095e-08,0.91489,3
121.09715, 42.40000,      0.26921,      0.25385,50.00000,20.00000,5.715588e-08,0.91459,3
121.92408, 43.20000,      0.26913,      0.25250,50.00000,20.00000,5.723675e-08,0.91429,3
122.74805, 44.00000,      0.26853,      0.25251,50.00000,20.00000,5.729533e-08,0.91398,3
123.56821, 44.80000,      0.26746,      0.25296,50.00000,20.00000,5.737557e-08,0.91368,3
124.36433, 45.60000,      0.26841,      0.25431,50.00000,20.00000,5.715198e-08,0.91338,3
125.17113, 46.40000,      0.26798,      0.25600,50.00000,20.00000,5.740919e-08,0.91307,3
125.98314, 47.20000,      0.26824,      0.25602,50.00000,20.00000,5.727993e-08,0.91276,3
126.79021, 48.00000,      0.26667,      0.25601,50.00000,20.00000,5.716862e-08,0.91244,3
127.58029, 48.80000,      0.26708,      0.25555,50.00000,20.00000,5.702608e-08,0.91213,3
128.38214, 49.60000,      0.26836,      0.25726,50.00000,20.00000,5.744678e-08,0.91181,3
129.18916, 50.40000,      0.26928,      0.25793,50.00000,20.00000,5.709121e-08,0.91149,3
129.97515, 51.20000,      0.26855,      0.25827,50.00000,20.00000,5.712721e-08,0.91117,3
130.78915, 52.00000,      0.27130,      0.25828,50.00000,20.00000,5.716177e-08,0.91083,3
131.59913, 52.80000,      0.27125,      0.25997,50.00000,20.00000,5.731895e-08,0.91050,3
132.39608, 53.60000,      0.27134,      0.25997,50.00000,20.00000,5.706628e-08,0.91017,3
133.20208, 54.40000,      0.27145,      0.26099,50.00000,20.00000,5.711354e-08,0.90983,3
133.99326, 55.20000,      0.26936,      0.26268,50.00000,20.00000,5.708184e-08,0.90949,3
134.80016, 56.00000,      0.26899,      0.26201,50.00000,20.00000,5.710772e-08,0.90914,3
135.58930, 56.80000,      0.26874,      0.26268,50.00000,20.00000,5.722678e-08,0.90880,3
136.38308, 57.60000,      0.27036,      0.26337,50.00000,20.00000,5.730781e-08,0.90845,3
137.19117, 58.40000,      0.27180,      0.26473,50.00000,20.00000,5.707638e-08,0.90809,3
137.98825, 59.20000,      0.27140,      0.26438,50.00000,20.00000,5.726133e-08,0.90774,3
138.78515, 60.00000,      0.26984,      0.26608,50.00000,20.00000,5.706356e-08,0.90738,3
139.59718, 60.80000,      0.27179,      0.26710,50.00000,20.00000,5.711767e-08,0.90701,3
140.39028, 61.60000,      0.27190,      0.26723,50.00000,20.00000,5.718506e-08,0.90665,3
141.18215, 62.40000,      0.27083,      0.26855,50.00000,20.00000,5.713775e-08,0.90628,3
141.98321, 63.20000,      0.27128,      0.26925,50.00000,20.00000,5.703666e-08,0.90591,3
142.78730, 64.00000,      0.27089,      0.27061,50.00000,20.00000,5.708990e-08,0.90553,3
143.57705, 64.80000,      0.27099,      0.27209,50.00000,20.00000,5.720759e-08,0.90515,3
144.39822, 65.60000,      0.27179,      0.27274,50.00000,20.00000,5.732656e-08,0.90476,3
145.20420, 66.40000,      0.27124,      0.27275,50.00000,20.00000,5.693655e-08,0.90438,3
145.99427, 67.20000,      0.26917,      0.27411,50.00000,20.00000,5.721107e-08,0.90399,3
146.80116, 68.00000,      0.26912,      0.27479,50.00000,20.00000,5.712586e-08,0.90360,3
147.59113, 68.80000,      0.27006,      0.27512,50.00000,20.00000,5.702362e-08,0.90321,3
148.40822, 69.60000,      0.26868,      0.27614,50.00000,20.00000,5.706477e-08,0.90280,3
149.19927, 70.40000,      0.26743,      0.27750,50.00000,20.00000,5.727429e-08,0.90241,3
150.01720, 71.20000,      0.26773,      0.27819,50.00000,20.00000,5.732673e-08,0.90199,3
150.80708, 72.00000,      0.26718,      0.27886,50.00000,20.00000,5.718923e-08,0.90159,3
151.61431, 72.80000,      0.26578,      0.28022,50.00000,20.00000,5.737957e-08,0.90118,3
152.41196, 73.60000,      0.26455,      0.28023,50.00000,20.00000,5.718333e-08,0.90077,3
153.21418, 74.40000,      0.26300,      0.28157,50.00000,20.00000,5.729305e-08,0.90035,3
154.01818, 75.20000,      0.26312,      0.28259,50.00000,20.00000,5.720269e-08,0.89993,3
154.80421, 76.00000,      0.26206,      0.28294,50.00000,20.00000,5.719571e-08,0.89952,3
155.60623, 76.80000,      0.25964,      0.28429,50.00000,20.00000,5.717138e-08,0.89910,3
156.39931, 77.60000,      0.25858,      0.28463,50.00000,20.00000,5.725305e-08,0.89867,3
157.20730, 78.40000,      0.25887,      0.28611,50.00000,20.00000,5.721512e-08,0.89824,3
158.00413, 79.20000,      0.25901,      0.28600,50.00000,20.00000,5.719787e-08,0.89781,3
158.80323, 80.00000,      0.25895,      0.28735,50.00000,20.00000,5.716409e-08,0.89737,3
159.60309, 80.80000,      0.25672,      0.28870,50.00000,20.00000,5.734077e-08,0.89693,3
160.39409, 81.60000,      0.25718,      0.28903,50.00000,20.00000,5.734967e-08,0.89650,3
161.20228, 82.40000,      0.25560,      0.29040,50.00000,20.00000,5.710848e-08,0.89605,3
162.01816, 83.20000,      0.25388,      0.29142,50.00000,20.00000,5.753406e-08,0.89559,3
162.80325, 84.00000,      0.25264,      0.29075,50.00000,20.00000,5.736549e-08,0.89515,3
163.61320, 84.80000,      0.25158,      0.29244,50.00000,20.00000,5.743191e-08,0.89470,3
164.40813, 85.60000,      0.24829,      0.29471,50.00000,20.00000,5.739364e-08,0.89424,3
165.20594, 86.40000,      0.24809,      0.29369,50.00000,20.00000,5.735061e-08,0.89379,3
166.01212, 87.20000,      0.24737,      0.29504,50.00000,20.00000,5.739282e-08,0.89332,3
166.80935, 88.00000,      0.24545,      0.29708,50.00000,20.00000,5.739576e-08,0.89286,3
167.60727, 88.80000,      0.24458,      0.29742,50.00000,20.00000,5.744545e-08,0.89240,3
168.41337, 89.60000,      0.24214,      0.29878,50.00000,20.00000,5.742312e-08,0.89192,3
169.22011, 90.40000,      0.24176,      0.29877,50.00000,20.00000,5.754503e-08,0.89145,3
170.02011, 91.20000,      0.23863,      0.29876,50.00000,20.00000,5.744900e-08,0.89097,3
170.82405, 92.00000,      0.23741,      0.30013,50.00000,20.00000,5.744612e-08,0.89049,3
171.62808, 92.80000,      0.23599,      0.30148,50.00000,20.00000,5.767910e-08,0.89001,3
172.42020, 93.60000,      0.23237,      0.30150,50.00000,20.00000,5.751655e-08,0.88953,3
173.21421, 94.40000,      0.23146,      0.30284,50.00000,20.00000,5.761382e-08,0.88905,3
174.02192, 95.20000,      0.22937,      0.30319,50.00000,20.00000,5.753059e-08,0.88856,3
174.82419, 96.00000,      0.22693,      0.30319,50.00000,20.00000,5.754337e-08,0.88807,3
175.61011, 96.80000,      0.22569,      0.30363,50.00000,20.00000,5.757083e-08,0.88759,3
176.41324, 97.60000,      0.22410,      0.30635,50.00000,20.00000,5.746134e-08,0.88709,3
177.22117, 98.40000,      0.22268,      0.30646,50.00000,20.00000,5.773210e-08,0.88659,3
178.01422, 99.20000,      0.22074,      0.30714,50.00000,20.00000,5.765585e-08,0.88609,3
178.81313,100.00000,      0.21761,      0.30748,50.00000,20.00000,5.776588e-08,0.88559,3
179.60221,100.80000,      0.21637,      0.30816,50.00000,20.00000,5.766861e-08,0.88509,3
180.40913,101.60000,      0.21425,      0.30918,50.00000,20.00000,5.757219e-08,0.88457,3
181.21517,102.40000,      0.21300,      0.31042,50.00000,20.00000,5.771332e-08,0.88406,3
182.00817,103.20000,      0.21054,      0.31110,50.00000,20.00000,5.769861e-08,0.88355,3
182.82006,104.00000,      0.20688,      0.31076,50.00000,20.00000,5.765696e-08,0.88303,3
183.62511,104.80000,      0.20477,      0.31211,50.00000,20.00000,5.784599e-08,0.88251,3
184.42017,105.60000,      0.20179,      0.31381,50.00000,20.00000,5.777698e-08,0.88199,3
185.21024,106.40000,      0.20051,      0.31417,50.00000,20.00000,5.773231e-08,0.88147,3
186.01212,107.20000,      0.19892,      0.31483,50.00000,20.00000,5.791436e-08,0.88095,3
186.80722,108.00000,      0.19679,      0.31754,50.00000,20.00000,5.778510e-08,0.88042,3
187.62018,108.80000,      0.19447,      0.31721,50.00000,20.00000,5.781620e-08,0.87988,3
188.40618,109.60000,      0.19115,      0.31824,50.00000,20.00000,5.784668e-08,0.87936,3
189.21614,110.40000,      0.18798,      0.31788,50.00000,20.00000,5.786299e-08,0.87882,3
190.01725,111.20000,      0.18585,      0.31958,50.00000,20.00000,5.775530e-08,0.87828,3
190.81022,112.00000,      0.18544,      0.32049,50.00000,20.00000,5.797094e-08,0.87774,3
191.62020,112.80000,      0.18192,      0.32117,50.00000,20.00000,5.789147e-08,0.87719,3
192.42208,113.60000,      0.17684,      0.32287,50.00000,20.00000,5.791126e-08,0.87665,3
193.21826,114.40000,      0.17416,      0.32287,50.00000,20.00000,5.789674e-08,0.87610,3
194.01925,115.20000,      0.17168,      0.32355,50.00000,20.00000,5.809407e-08,0.87555,3
194.82223,116.00000,      0.17058,      0.32524,50.00000,20.00000,5.784195e-08,0.87500,3
195.60234,116.80000,      0.16772,      0.32625,50.00000,20.00000,5.783140e-08,0.87446,3
196.41620,117.60000,      0.16677,      0.32694,50.00000,20.00000,5.812800e-08,0.87389,3
197.21829,118.40000,      0.16203,      0.32762,50.00000,20.00000,5.799024e-08,0.87333,3
198.02530,119.20000,      0.16107,      0.32797,50.00000,20.00000,5.819010e-08,0.87276,3
198.82719,120.00000,      0.15771,      0.32932,50.00000,20.00000,5.805226e-08,0.87220,3
199.62417,120.80000,      0.15518,      0.32931,50.00000,20.00000,5.818166e-08,0.87164,3
200.42316,121.60000,      0.15128,      0.33102,50.00000,20.00000,5.807612e-08,0.87107,3
201.21329,122.40000,      0.14892,      0.33135,50.00000,20.00000,5.819754e-08,0.87051,3
202.01412,123.20000,      0.14465,      0.33271,50.00000,20.00000,5.814895e-08,0.86993,3
202.81705,124.00000,      0.14213,      0.33270,50.00000,20.00000,5.815218e-08,0.86936,3
203.61730,124.80000,      0.14014,      0.33271,50.00000,20.00000,5.833466e-08,0.86878,3
204.42212,125.60000,      0.13620,      0.33545,50.00000,20.00000,5.832242e-08,0.86820,3
205.21402,126.40000,      0.13226,      0.33611,50.00000,20.00000,5.832972e-08,0.86762,3
206.00712,127.20000,      0.12919,      0.33611,50.00000,20.00000,5.815410e-08,0.86704,3
206.80725,128.00000,      0.12629,      0.33746,50.00000,20.00000,5.835808e-08,0.86646,3
207.61324,128.80000,      0.12358,      0.33848,50.00000,20.00000,5.816328e-08,0.86587,3
208.42520,129.60000,      0.12034,      0.33985,50.00000,20.00000,5.829586e-08,0.86527,3
209.22627,130.40000,      0.11811,      0.34152,50.00000,20.00000,5.846872e-08,0.86468,3
210.01820,131.20000,      0.11346,      0.34085,50.00000,20.00000,5.837537e-08,0.86409,3
210.81811,132.00000,      0.10825,      0.34154,50.00000,20.00000,5.826039e-08,0.86349,3
211.62424,132.80000,      0.10604,      0.34255,50.00000,20.00000,5.829817e-08,0.86289,3
212.42229,133.60000,      0.10240,      0.34323,50.00000,20.00000,5.830564e-08,0.86229,3
213.22221,134.40000, 9.895040e-02,      0.34390,50.00000,20.00000,5.830681e-08,0.86169,3
214.01801,135.20000, 9.337166e-02,      0.34324,50.00000,20.00000,5.839534e-08,0.86109,3
214.81315,136.00000, 9.167134e-02,      0.34458,50.00000,20.00000,5.847628e-08,0.86049,3
215.61902,136.80000, 8.855797e-02,      0.34596,50.00000,20.00000,5.857936e-08,0.85988,3
216.41920,137.60000, 8.400307e-02,      0.34663,50.00000,20.00000,5.855285e-08,0.85927,3
217.21915,138.40000, 8.176860e-02,      0.34708,50.00000,20.00000,5.843185e-08,0.85866,3
218.03122,139.20000, 7.881703e-02,      0.34844,50.00000,20.00000,5.839771e-08,0.85803,3
218.81515,140.00000, 7.285597e-02,      0.34843,50.00000,20.00000,5.848626e-08,0.85743,3
219.61016,140.80000, 6.953529e-02,      0.34946,50.00000,20.00000,5.852470e-08,0.85682,3
220.41422,141.60000, 6.551195e-02,      0.34947,50.00000,20.00000,5.856085e-08,0.85619,3
221.22209,142.40000, 6.218301e-02,      0.35081,50.00000,20.00000,5.858817e-08,0.85557,3
222.01222,143.20000, 5.759237e-02,      0.35117,50.00000,20.00000,5.848853e-08,0.85495,3
222.81201,144.00000, 5.372570e-02,      0.35205,50.00000,20.00000,5.867055e-08,0.85433,3
223.60604,144.80000, 4.967657e-02,      0.35342,50.00000,20.00000,5.852602e-08,0.85370,3
224.40614,145.60000, 4.650508e-02,      0.35476,50.00000,20.00000,5.867003e-08,0.85308,3
225.21710,146.40000, 4.367636e-02,      0.35477,50.00000,20.00000,5.872072e-08,0.85244,3
226.01022,147.20000, 4.175072e-02,      0.35466,50.00000,20.00000,5.872728e-08,0.85181,3
226.80419,148.00000, 3.625266e-02,      0.35568,50.00000,20.00000,5.886552e-08,0.85118,3
227.61209,148.80000, 3.216498e-02,      0.35736,50.00000,20.00000,5.862804e-08,0.85054,3
228.40907,149.60000, 2.807471e-02,      0.35602,50.00000,20.00000,5.876099e-08,0.84990,3
229.21910,150.40000, 2.469604e-02,      0.35705,50.00000,20.00000,5.874412e-08,0.84925,3
230.02204,151.20000, 1.970107e-02,      0.35805,50.00000,20.00000,5.886361e-08,0.84861,3
230.81521,152.00000, 1.397729e-02,      0.35975,50.00000,20.00000,5.875485e-08,0.84797,3
231.62016,152.80000, 9.685583e-03,      0.35943,50.00000,20.00000,5.880989e-08,0.84732,3
232.40812,153.60000, 5.925978e-03,      0.35906,50.00000,20.00000,5.887363e-08,0.84669,3
233.20428,154.40000, 2.149023e-03,      0.36043,50.00000,20.00000,5.891581e-08,0.84604,3
233.99024,155.20000,-1.252900e-03,      0.36179,50.00000,20.00000,5.899193e-08,0.84540,3
234.80011,156.00000,-3.421506e-03,      0.36212,50.00000,20.00000,5.899999e-08,0.84475,3
235.60215,156.80000,-7.932888e-03,      0.36348,50.00000,20.00000,5.896970e-08,0.84409,3
236.40923,157.60000,-1.062891e-02,      0.36314,50.00000,20.00000,5.900477e-08,0.84343,3
237.20417,158.40000,-1.751072e-02,      0.36348,50.00000,20.00000,5.905244e-08,0.84278,3
238.00227,159.20000,-1.768718e-02,      0.36415,50.00000,20.00000,5.886845e-08,0.84212,3
238.80324,160.00000,-2.112635e-02,      0.36518,50.00000,20.00000,5.899825e-08,0.84146,3
239.60012,160.80000,-2.494092e-02,      0.36551,50.00000,20.00000,5.896026e-08,0.84080,3
240.39897,161.60000,-3.020210e-02,      0.36688,50.00000,20.00000,5.908479e-08,0.84014,3
241.20726,162.40000,-3.584821e-02,      0.36655,50.00000,20.00000,5.905559e-08,0.83947,3
242.00416,163.20000,-3.932419e-02,      0.36689,50.00000,20.00000,5.911217e-08,0.83880,3
242.80215,164.00000,-3.953036e-02,      0.36721,50.00000,20.00000,5.917543e-08,0.83814,3
243.60113,164.80000,-4.299352e-02,      0.36858,50.00000,20.00000,5.908230e-08,0.83747,3
244.39615,165.60000,-4.631015e-02,      0.36892,50.00000,20.00000,5.909749e-08,0.83680,3
245.19723,166.40000,-4.923921e-02,      0.36891,50.00000,20.00000,5.909217e-08,0.83613,3
246.00123,167.20000,-5.348834e-02,      0.36925,50.00000,20.00000,5.925808e-08,0.83545,3
246.80719,168.00000,-5.661750e-02,      0.36924,50.00000,20.00000,5.908448e-08,0.83477,3
247.60612,168.80000,-5.903899e-02,      0.36994,50.00000,20.00000,5.920837e-08,0.83410,3
248.39891,169.60000,-6.200509e-02,      0.37096,50.00000,20.00000,5.922795e-08,0.83343,3
249.20524,170.40000,-6.349729e-02,      0.37129,50.00000,20.00000,5.923726e-08,0.83274,3
250.00115,171.20000,-6.812943e-02,      0.37232,50.00000,20.00000,5.928822e-08,0.83206,3
250.79819,172.00000,-7.201937e-02,      0.37230,50.00000,20.00000,5.933269e-08,0.83138,3
251.58810,172.80000,-7.261663e-02,      0.37219,50.00000,20.00000,5.939047e-08,0.83071,3
252.39219,173.60000,-7.726058e-02,      0.37287,50.00000,20.00000,5.952717e-08,0.83002,3
253.17818,174.40000,-8.355160e-02,      0.37287,50.00000,20.00000,5.936990e-08,0.82935,3
253.95716,175.20000,-7.744378e-02,      0.37355,50.00000,20.00000,5.950860e-08,0.82868,3
254.74122,176.00000,-7.800249e-02,      0.37389,50.00000,20.00000,5.953945e-08,0.82800,3
255.54221,176.80000,-7.769157e-02,      0.37626,50.00000,20.00000,5.958100e-08,0.82731,3
256.34216,177.60000,-7.447782e-02,      0.37484,50.00000,20.00000,5.960647e-08,0.82662,3
257.13706,178.40000,-7.048861e-02,      0.37138,50.00000,20.00000,5.971273e-08,0.82593,3
257.95719,179.20000,-6.778357e-02,      0.37343,50.00000,20.00000,5.973721e-08,0.82522,3
258.76027,180.00000,-7.225753e-02,      0.37615,50.00000,20.00000,5.973494e-08,0.82452,3
259.55410,180.80000,-7.580482e-02,      0.37616,50.00000,20.00000,5.990437e-08,0.82383,3
260.36531,181.60000,-7.755179e-02,      0.37659,50.00000,20.00000,5.986544e-08,0.82312,3
261.16323,182.40000,-7.617270e-02,      0.37695,50.00000,20.00000,5.993658e-08,0.82242,3
261.95923,183.20000,-8.046185e-02,      0.37784,50.00000,20.00000,5.994352e-08,0.82172,3
262.76326,184.00000,-8.143864e-02,      0.37853,50.00000,20.00000,6.007185e-08,0.82102,3
263.56807,184.80000,-8.561474e-02,      0.37853,50.00000,20.00000,6.008722e-08,0.82031,3
264.36718,185.60000,-8.844815e-02,      0.37854,50.00000,20.00000,6.003725e-08,0.81961,3
265.16507,186.40000,-8.983116e-02,      0.37955,50.00000,20.00000,6.016615e-08,0.81890,3
265.96805,187.20000,-9.046351e-02,      0.37958,50.00000,20.00000,6.031698e-08,0.81819,3
266.77917,188.00000,-9.110479e-02,      0.38023,50.00000,20.00000,6.026371e-08,0.81748,3
267.58023,188.80000,-9.377923e-02,      0.38160,50.00000,20.00000,6.026723e-08,0.81677,3
268.37215,189.60000,-9.720709e-02,      0.38000,50.00000,20.00000,6.019689e-08,0.81606,3
269.17518,190.40000,-9.636526e-02,      0.37977,50.00000,20.00000,6.019557e-08,0.81535,3
269.98032,191.20000,     -0.10465,      0.38147,50.00000,20.00000,6.030497e-08,0.81463,3
270.78117,192.00000,     -0.10773,      0.38136,50.00000,20.00000,6.029879e-08,0.81392,3
271.58215,192.80000,     -0.11064,      0.38147,50.00000,20.00000,6.043378e-08,0.81320,3
272.38206,193.60000,     -0.10756,      0.38147,50.00000,20.00000,6.041887e-08,0.81249,3
273.17515,194.40000,     -0.11364,      0.38148,50.00000,20.00000,6.043092e-08,0.81177,3
273.97809,195.20000,     -0.11674,      0.37944,50.00000,20.00000,6.050951e-08,0.81105,3
274.78017,196.00000,     -0.11891,      0.38077,50.00000,20.00000,6.062463e-08,0.81033,3
275.56414,196.80000,     -0.11807,      0.38148,50.00000,20.00000,6.057881e-08,0.80963,3
276.38622,197.60000,     -0.12081,      0.38079,50.00000,20.00000,6.067290e-08,0.80889,3
277.17614,198.40000,     -0.12469,      0.38078,50.00000,20.00000,6.067781e-08,0.80817,3
277.97630,199.20000,     -0.12517,      0.38182,50.00000,20.00000,6.076346e-08,0.80745,3
278.77920,200.00000,     -0.12979,      0.38147,50.00000,20.00000,6.061966e-08,0.80672,3
279.57915,200.80000,     -0.13086,      0.38146,50.00000,20.00000,6.069572e-08,0.80600,3
280.37912,201.60000,     -0.13530,      0.37978,50.00000,20.00000,6.063700e-08,0.80527,3
281.18412,202.40000,     -0.14224,      0.38625,50.00000,20.00000,6.082406e-08,0.80454,3
281.97323,203.20000,     -0.14162,      0.37977,50.00000,20.00000,6.090065e-08,0.80382,3
282.76821,204.00000,     -0.13701,      0.37910,50.00000,20.00000,6.081217e-08,0.80310,3
283.58313,204.80000,     -0.13732,      0.37967,50.00000,20.00000,6.075565e-08,0.80236,3
284.38026,205.60000,     -0.14277,      0.37966,50.00000,20.00000,6.091051e-08,0.80163,3
285.17112,206.40000,     -0.14555,      0.37898,50.00000,20.00000,6.105051e-08,0.80091,3
285.96505,207.20000,     -0.14454,      0.38035,50.00000,20.00000,6.101525e-08,0.80018,3
286.77415,208.00000,     -0.14525,      0.37966,50.00000,20.00000,6.106049e-08,0.79944,3
287.59410,208.80000,     -0.14348,      0.37909,50.00000,20.00000,6.108018e-08,0.79869,3
288.40118,209.60000,     -0.15160,      0.37909,50.00000,20.00000,6.098971e-08,0.79794,3
289.20327,210.40000,     -0.15422,      0.37671,50.00000,20.00000,6.099018e-08,0.79721,3
290.01618,211.20000,     -0.15819,      0.37876,50.00000,20.00000,6.093077e-08,0.79646,3
290.81803,212.00000,     -0.16386,      0.37740,50.00000,20.00000,6.101223e-08,0.79572,3
291.62617,212.80000,     -0.16556,      0.37604,50.00000,20.00000,6.098057e-08,0.79497,3
292.41411,213.60000,     -0.16841,      0.37604,50.00000,20.00000,6.111973e-08,0.79425,3
293.21627,214.40000,     -0.17103,      0.37603,50.00000,20.00000,6.100280e-08,0.79351,3
294.01017,215.20000,     -0.17483,      0.37469,50.00000,20.00000,6.093150e-08,0.79277,3
294.80813,216.00000,     -0.17576,      0.37332,50.00000,20.00000,6.109757e-08,0.79203,3
295.60404,216.80000,     -0.17767,      0.37198,50.00000,20.00000,6.107532e-08,0.79129,3
296.40928,217.60000,     -0.17629,      0.37049,50.00000,20.00000,6.093695e-08,0.79055,3
297.20916,218.40000,     -0.17934,      0.36983,50.00000,20.00000,6.112098e-08,0.78980,3
297.99602,219.20000,     -0.18837,      0.36947,50.00000,20.00000,6.098489e-08,0.78907,3
298.80202,220.00000,     -0.18778,      0.36779,50.00000,20.00000,6.094148e-08,0.78832,3
299.59522,220.80000,     -0.19316,      0.36494,50.00000,20.00000,6.098090e-08,0.78758,3
300.38223,221.60000,     -0.20222,      0.36125,50.00000,20.00000,6.118285e-08,0.78685,3
301.18014,222.40000,     -0.19934,      0.36180,50.00000,20.00000,6.098428e-08,0.78611,3
301.96718,223.20000,     -0.20048,      0.36282,50.00000,20.00000,6.122864e-08,0.78537,3
302.74732,224.00000,     -0.20261,      0.36145,50.00000,20.00000,6.127354e-08,0.78464,3
303.53219,224.80000,     -0.20008,      0.36010,50.00000,20.00000,6.121936e-08,0.78391,3
304.33321,225.60000,     -0.19698,      0.35873,50.00000,20.00000,6.125911e-08,0.78316,3
305.11902,226.40000,     -0.19346,      0.35736,50.00000,20.00000,6.126543e-08,0.78242,3
305.91508,227.20000,     -0.18724,      0.35670,50.00000,20.00000,6.124947e-08,0.78168,3
306.72716,228.00000,     -0.18703,      0.35671,50.00000,20.00000,6.137986e-08,0.78091,3
307.51721,228.80000,     -0.18837,      0.35500,50.00000,20.00000,6.141944e-08,0.78017,3
308.32822,229.60000,     -0.18117,      0.35433,50.00000,20.00000,6.144798e-08,0.77941,3
309.13514,230.40000,     -0.18094,      0.35228,50.00000,20.00000,6.166636e-08,0.77865,3
309.94509,231.20000,     -0.17936,      0.34957,50.00000,20.00000,6.140923e-08,0.77789,3
310.74427,232.00000,     -0.17365,      0.34821,50.00000,20.00000,6.158020e-08,0.77714,3
311.54822,232.80000,     -0.17266,      0.34684,50.00000,20.00000,6.175438e-08,0.77638,3
312.35513,233.60000,     -0.17382,      0.34516,50.00000,20.00000,6.184050e-08,0.77562,3
313.15321,234.40000,     -0.16788,      0.34413,50.00000,20.00000,6.188082e-08,0.77487,3
313.96417,235.20000,     -0.16747,      0.34245,50.00000,20.00000,6.188817e-08,0.77410,3
314.76221,236.00000,     -0.16137,      0.34155,50.00000,20.00000,6.185945e-08,0.77335,3
315.56229,236.80000,     -0.15718,      0.33882,50.00000,20.00000,6.198396e-08,0.77259,3
316.35715,237.60000,     -0.15340,      0.33680,50.00000,20.00000,6.193616e-08,0.77184,3
317.16315,238.40000,     -0.15177,      0.33473,50.00000,20.00000,6.197402e-08,0.77108,3
317.95506,239.20000,     -0.14639,      0.33135,50.00000,20.00000,6.201965e-08,0.77033,3
318.76012,240.00000,     -0.14200,      0.32932,50.00000,20.00000,6.199305e-08,0.76957,3
319.57019,240.80000,     -0.14114,      0.32526,50.00000,20.00000,6.210043e-08,0.76880,3
320.36937,241.60000,     -0.13002,      0.32389,50.00000,20.00000,6.215204e-08,0.76804,3
321.15830,242.40000,     -0.12579,      0.32084,50.00000,20.00000,6.212869e-08,0.76729,3
321.95422,243.20000,     -0.11541,      0.31666,50.00000,20.00000,6.220224e-08,0.76654,3
322.77112,244.00000,     -0.10757,      0.31507,50.00000,20.00000,6.225034e-08,0.76576,3
323.56816,244.80000,     -0.10888,      0.31065,50.00000,20.00000,6.230092e-08,0.76501,3
324.37622,245.60000,     -0.10302,      0.30658,50.00000,20.00000,6.228780e-08,0.76424,3
325.17904,246.40000,-9.873782e-02,      0.30105,50.00000,20.00000,6.232857e-08,0.76348,3
325.96710,247.20000,-9.882978e-02,      0.29822,50.00000,20.00000,6.223971e-08,0.76273,3
326.76430,248.00000,-9.613644e-02,      0.29415,50.00000,20.00000,6.249430e-08,0.76197,3
327.56514,248.80000,-8.586407e-02,      0.29006,50.00000,20.00000,6.239499e-08,0.76121,3
328.37502,249.60000,-8.513063e-02,      0.28599,50.00000,20.00000,6.255490e-08,0.76044,3
329.17311,250.40000,-8.741256e-02,      0.28047,50.00000,20.00000,6.241434e-08,0.75968,3
329.96413,251.20000,-8.151413e-02,      0.27504,50.00000,20.00000,6.257000e-08,0.75893,3
330.76912,252.00000,-8.079976e-02,      0.26858,50.00000,20.00000,6.254861e-08,0.75816,3
331.57908,252.80000,-7.264705e-02,      0.26315,50.00000,20.00000,6.261940e-08,0.75739,3
332.36211,253.60000,-7.069093e-02,      0.25739,50.00000,20.00000,6.268678e-08,0.75664,3
333.17611,254.40000,-7.138267e-02,      0.25059,50.00000,20.00000,6.265588e-08,0.75587,3
333.96122,255.20000,-6.822642e-02,      0.24470,50.00000,20.00000,6.264196e-08,0.75512,3
334.76602,256.00000,-6.568529e-02,      0.23587,50.00000,20.00000,6.276588e-08,0.75435,3
335.56114,256.80000,-5.950084e-02,      0.22730,50.00000,20.00000,6.280879e-08,0.75359,3
336.36921,257.60000,-5.773229e-02,      0.22218,50.00000,20.00000,6.282723e-08,0.75282,3
337.16516,258.40000,-5.436613e-02,      0.21112,50.00000,20.00000,6.284154e-08,0.75206,3
337.96795,259.20000,-5.521013e-02,      0.20173,50.00000,20.00000,6.279856e-08,0.75130,3
338.75419,260.00000,-4.963205e-02,      0.19729,50.00000,20.00000,6.287414e-08,0.75055,3
339.55314,260.80000,-3.710139e-02,      0.18633,50.00000,20.00000,6.304973e-08,0.74979,3
340.36114,261.60000,-2.901997e-02,      0.17388,50.00000,20.00000,6.292402e-08,0.74901,3
341.18208,262.40000,-2.884890e-02,      0.16303,50.00000,20.00000,6.308088e-08,0.74823,3
341.99214,263.20000,-3.007161e-02,      0.15137,50.00000,20.00000,6.311100e-08,0.74746,3
342.79316,264.00000,-2.726188e-02,      0.13939,50.00000,20.00000,6.298975e-08,0.74669,3
343.60211,264.80000,-2.690082e-02,      0.12582,50.00000,20.00000,6.294339e-08,0.74592,3
344.40708,265.60000,-2.526800e-02,      0.11076,50.00000,20.00000,6.296003e-08,0.74515,3
345.20412,266.40000,-2.469952e-02, 9.697147e-02,50.00000,20.00000,6.300637e-08,0.74439,3
346.01211,267.20000,-2.555077e-02, 8.080455e-02,50.00000,20.00000,6.303704e-08,0.74362,3
346.80407,268.00000,-2.128152e-02, 6.428251e-02,50.00000,20.00000,6.292270e-08,0.74286,3
347.60016,268.80000,-1.741566e-02, 4.685756e-02,50.00000,20.00000,6.300174e-08,0.74210,3
348.40807,269.60000,-1.517563e-02, 2.967055e-02,50.00000,20.00000,6.287519e-08,0.74133,3
349.19207,270.40000,-1.129405e-02, 9.192378e-03,50.00000,20.00000,6.310704e-08,0.74058,3
349.99104,271.20000,-9.676996e-03,-1.106835e-02,50.00000,20.00000,6.300670e-08,0.73982,3
350.78017,272.00000,-4.507598e-03,-3.222096e-02,50.00000,20.00000,6.310912e-08,0.73907,3
351.57807,272.80000,-4.117771e-03,-5.459957e-02,50.00000,20.00000,6.312916e-08,0.73831,3
352.37714,273.60000,-8.272878e-04,-7.736910e-02,50.00000,20.00000,6.300709e-08,0.73754,3
353.17424,274.40000, 5.984922e-03,     -0.10280,50.00000,20.00000,6.310742e-08,0.73678,3
353.97508,275.20000, 4.730023e-03,     -0.12872,50.00000,20.00000,6.314343e-08,0.73602,3
354.77007,276.00000, 5.513374e-03,     -0.15790,50.00000,20.00000,6.316497e-08,0.73526,3
355.56615,276.80000, 1.056277e-02,     -0.19139,50.00000,20.00000,6.327461e-08,0.73450,3
356.37326,277.60000, 9.278465e-03,     -0.22215,50.00000,20.00000,6.311988e-08,0.73373,3
357.16626,278.40000, 8.418656e-03,     -0.25678,50.00000,20.00000,6.327893e-08,0.73298,3
357.96222,279.20000, 4.425257e-03,     -0.29523,50.00000,20.00000,6.327052e-08,0.73222,3
358.75620,280.00000, 1.280183e-02,     -0.33402,50.00000,20.00000,6.324828e-08,0.73146,3
359.55611,280.80000, 2.826145e-03,     -0.37738,50.00000,20.00000,6.347815e-08,0.73070,3
360.35428,281.60000, 1.555708e-04,     -0.42421,50.00000,20.00000,6.340018e-08,0.72994,3
361.16022,282.40000,-1.159305e-02,     -0.47002,50.00000,20.00000,6.332208e-08,0.72917,3
361.94822,283.20000,-1.540752e-02,     -0.51957,50.00000,20.00000,6.337953e-08,0.72842,3
362.74711,284.00000,-2.010617e-02,     -0.57159,50.00000,20.00000,6.336028e-08,0.72766,3
363.54609,284.80000,-2.100061e-02,     -0.62543,50.00000,20.00000,6.362657e-08,0.72690,3
364.35513,285.60000,-4.193948e-02,     -0.68201,50.00000,20.00000,6.360026e-08,0.72613,3
365.15822,286.40000,-3.398981e-02,     -0.74082,50.00000,20.00000,6.351324e-08,0.72536,3
365.96511,287.20000,-4.210557e-02,     -0.80361,50.00000,20.00000,6.361238e-08,0.72460,3
366.75828,288.00000,-2.597449e-02,     -0.86753,50.00000,20.00000,6.369200e-08,0.72384,3
367.54623,288.80000,-5.262947e-02,     -0.93585,50.00000,20.00000,6.358956e-08,0.72309,3
368.34418,289.60000,-9.116012e-02,     -1.00318,50.00000,20.00000,6.367637e-08,0.72233,3
369.13315,290.40000,-8.631440e-02,     -1.07603,50.00000,20.00000,6.381692e-08,0.72159,3
369.94322,291.20000,-7.559640e-02,     -1.15362,50.00000,20.00000,6.393148e-08,0.72082,3
370.73509,292.00000,     -0.11908,     -1.23065,50.00000,20.00000,6.393913e-08,0.72006,3
371.54621,292.80000,-6.408891e-02,     -1.31516,50.00000,20.00000,6.396908e-08,0.71929,3
372.34913,293.60000,     -0.12242,     -1.40180,50.00000,20.00000,6.407340e-08,0.71853,3
373.14216,294.40000,-9.515316e-02,     -1.49267,50.00000,20.00000,6.414664e-08,0.71778,3
373.94808,295.20000,     -0.27666,     -1.58270,50.00000,20.00000,6.418331e-08,0.71702,3
374.75312,296.00000,     -0.28033,     -1.67151,50.00000,20.00000,6.433406e-08,0.71626,3
375.55122,296.80000,     -0.29038,     -1.76484,50.00000,20.00000,6.434853e-08,0.71550,3
376.34329,297.60000,     -0.31740,     -1.85797,50.00000,20.00000,6.444427e-08,0.71475,3
377.16421,298.40000,     -0.34499,     -1.95628,50.00000,20.00000,6.451995e-08,0.71397,3
377.94318,299.20000,     -0.36728,     -2.05333,50.00000,20.00000,6.449166e-08,0.71324,3
378.73921,300.00000,     -0.39989,     -2.15141,50.00000,20.00000,6.465444e-08,0.71249,3
379.54413,300.80000,     -0.44835,     -2.25141,50.00000,20.00000,6.479150e-08,0.71173,3
380.36008,301.60000,     -0.49181,     -2.35164,50.00000,20.00000,6.491799e-08,0.71096,3
381.13724,302.40000,     -0.52365,     -2.45099,50.00000,20.00000,6.494680e-08,0.71022,3
381.95209,303.20000,     -0.57400,     -2.55188,50.00000,20.00000,6.505779e-08,0.70945,3
382.74717,304.00000,     -0.63625,     -2.65155,50.00000,20.00000,6.529425e-08,0.70870,3
383.54418,304.80000,     -0.69328,     -2.75280,50.00000,20.00000,6.533830e-08,0.70795,3
384.33928,305.60000,     -0.75505,     -2.84909,50.00000,20.00000,6.543435e-08,0.70721,3
385.14508,306.40000,     -0.82053,     -2.94523,50.00000,20.00000,6.554261e-08,0.70645,3
385.93525,307.20000,     -0.89881,     -3.04255,50.00000,20.00000,6.562712e-08,0.70570,3
386.75422,308.00000,     -0.98052,     -3.13645,50.00000,20.00000,6.576161e-08,0.70494,3
387.54315,308.80000,     -1.05943,     -3.22524,50.00000,20.00000,6.568511e-08,0.70419,3
388.34715,309.60000,     -1.15657,     -3.31562,50.00000,20.00000,6.596283e-08,0.70344,3
389.15206,310.40000,     -1.27588,     -3.40062,50.00000,20.00000,6.600892e-08,0.70269,3
389.95121,311.20000,     -1.39913,     -3.48442,50.00000,20.00000,6.616372e-08,0.70194,3
390.75306,312.00000,     -1.53013,     -3.56498,50.00000,20.00000,6.635546e-08,0.70119,3
391.56517,312.80000,     -1.63234,     -3.64228,50.00000,20.00000,6.641495e-08,0.70043,3
392.35802,313.60000,     -1.75648,     -3.71334,50.00000,20.00000,6.638976e-08,0.69968,3
393.14020,314.40000,     -1.88062,     -3.78324,50.00000,20.00000,6.659022e-08,0.69895,3
393.94709,315.20000,     -2.00081,     -3.84761,50.00000,20.00000,6.668788e-08,0.69820,3
394.75111,316.00000,     -2.12207,     -3.90901,50.00000,20.00000,6.668514e-08,0.69745,3
395.54719,316.80000,     -2.24999,     -3.96764,50.00000,20.00000,6.684348e-08,0.69671,3
396.34402,317.60000,     -2.36358,     -4.02016,50.00000,20.00000,6.687214e-08,0.69596,3
397.15328,318.40000,     -2.44639,     -4.07082,50.00000,20.00000,6.698251e-08,0.69521,3
397.94615,319.20000,     -2.52121,     -4.11834,50.00000,20.00000,6.699109e-08,0.69447,3
398.75229,320.00000,     -2.59052,     -4.16203,50.00000,20.00000,6.719412e-08,0.69372,3
399.53426,320.80000,     -2.66168,     -4.20126,50.00000,20.00000,6.715223e-08,0.69300,3
401.49815,321.60000,     -1.93144,     -4.23162,50.00000,20.00000,6.724639e-08,0.69118,4
405.35007,322.40000,     -1.33760,     -4.26076,50.00000,20.00000,6.741330e-08,0.68761,4
408.80830,323.20000,     -1.55986,     -4.29471,50.00000,20.00000,6.743994e-08,0.68443,4
412.56076,324.00000,     -1.47418,     -4.32665,50.00000,20.00000,6.745868e-08,0.68099,4
416.56066,324.80000,     -1.45690,     -4.35974,50.00000,20.00000,6.745915e-08,0.67733,4
420.60794,325.60000,     -1.53227,     -4.38735,50.00000,20.00000,6.763110e-08,0.67366,4
424.70124,326.40000,     -1.60914,     -4.41402,50.00000,20.00000,6.779187e-08,0.66996,4
428.80379,327.20000,     -1.70606,     -4.43549,50.00000,20.00000,6.772086e-08,0.66628,4
432.91941,328.00000,     -1.81319,     -4.45211,50.00000,20.00000,6.789244e-08,0.66260,4
437.02788,328.80000,     -1.92876,     -4.46593,50.00000,20.00000,6.813898e-08,0.65896,4
441.12213,329.60000,     -2.04654,     -4.47407,50.00000,20.00000,6.819754e-08,0.65535,4
445.19687,330.40000,     -2.17194,     -4.47814,50.00000,20.00000,6.831190e-08,0.65178,4
449.27038,331.20000,     -2.30326,     -4.47949,50.00000,20.00000,6.846006e-08,0.64824,4
453.32298,332.00000,     -2.42782,     -4.47713,50.00000,20.00000,6.862023e-08,0.64475,4
457.36717,332.80000,     -2.54765,     -4.47407,50.00000,20.00000,6.876391e-08,0.64128,4
461.40488,333.60000,     -2.68070,     -4.47132,50.00000,20.00000,6.877879e-08,0.63785,4
465.43380,334.40000,     -2.80321,     -4.46727,50.00000,20.00000,6.912276e-08,0.63445,4
469.46606,335.20000,     -2.93165,     -4.46491,50.00000,20.00000,6.909826e-08,0.63108,4
473.48252,336.00000,     -3.06051,     -4.46275,50.00000,20.00000,6.931310e-08,0.62775,4
477.50307,336.80000,     -3.18870,     -4.45869,50.00000,20.00000,6.954086e-08,0.62444,4
481.51401,337.60000,     -3.32933,     -4.45642,50.00000,20.00000,6.968054e-08,0.62116,4
485.52958,338.40000,     -3.46272,     -4.45340,50.00000,20.00000,6.984244e-08,0.61792,4
489.54296,339.20000,     -3.60196,     -4.44931,50.00000,20.00000,7.014104e-08,0.61470,4
493.55100,340.00000,     -3.74205,     -4.44771,50.00000,20.00000,7.015966e-08,0.61152,4
497.55721,340.80000,     -3.88845,     -4.44488,50.00000,20.00000,7.041035e-08,0.60836,4
501.55494,341.60000,     -4.03465,     -4.44217,50.00000,20.00000,7.044549e-08,0.60525,4
505.55606,342.40000,     -4.17682,     -4.43810,50.00000,20.00000,7.074348e-08,0.60216,4
509.55809,343.20000,     -4.33017,     -4.43742,50.00000,20.00000,7.094998e-08,0.59910,4
513.56377,344.00000,     -4.48147,     -4.43470,50.00000,20.00000,7.119979e-08,0.59607,4
517.55049,344.80000,     -4.63937,     -4.43199,50.00000,20.00000,7.126327e-08,0.59308,4
521.55253,345.60000,     -4.79068,     -4.43199,50.00000,20.00000,7.146177e-08,0.59011,4
525.56247,346.40000,     -4.93974,     -4.42864,50.00000,20.00000,7.168549e-08,0.58717,4
529.56554,347.20000,     -5.09766,     -4.42622,50.00000,20.00000,7.183688e-08,0.58426,4
533.55980,348.00000,     -5.25335,     -4.42486,50.00000,20.00000,7.204361e-08,0.58139,4
537.55396,348.80000,     -5.40249,     -4.42213,50.00000,20.00000,7.211774e-08,0.57856,4
541.56971,349.60000,     -5.55846,     -4.41943,50.00000,20.00000,7.218436e-08,0.57573,4
545.57374,350.40000,     -5.71040,     -4.41943,50.00000,20.00000,7.243385e-08,0.57295,4
549.56636,351.20000,     -5.87255,     -4.41671,50.00000,20.00000,7.260228e-08,0.57020,4
553.56495,352.00000,     -6.01498,     -4.41431,50.00000,20.00000,7.283457e-08,0.56748,4
557.55713,352.80000,     -6.16457,     -4.41230,50.00000,20.00000,7.285440e-08,0.56480,4
561.56886,353.60000,     -6.31708,     -4.41060,50.00000,20.00000,7.306132e-08,0.56213,4
565.56411,354.40000,     -6.46305,     -4.40925,50.00000,20.00000,7.334136e-08,0.55951,4
569.56522,355.20000,     -6.59802,     -4.40789,50.00000,20.00000,7.340979e-08,0.55691,4
573.57789,356.00000,     -6.74075,     -4.40551,50.00000,20.00000,7.361247e-08,0.55433,4
577.57003,356.80000,     -6.87913,     -4.40380,50.00000,20.00000,7.389217e-08,0.55180,4
581.58288,357.60000,     -7.01553,     -4.40314,50.00000,20.00000,7.378524e-08,0.54928,4
585.57831,358.40000,     -7.14776,     -4.40178,50.00000,20.00000,7.401110e-08,0.54681,4
589.58410,359.20000,     -7.28164,     -4.39907,50.00000,20.00000,7.413927e-08,0.54435,4
593.58925,360.00000,     -7.41847,     -4.39884,50.00000,20.00000,7.437092e-08,0.54193,4
597.58489,360.80000,     -7.55218,     -4.39748,50.00000,20.00000,7.455428e-08,0.53954,4
601.59107,361.60000,     -7.68054,     -4.39581,50.00000,20.00000,7.464455e-08,0.53717,4
605.60084,362.40000,     -7.82117,     -4.39578,50.00000,20.00000,7.499142e-08,0.53483,4
609.58169,363.20000,     -7.94227,     -4.39347,50.00000,20.00000,7.504685e-08,0.53253,4
613.58470,364.00000,     -8.07465,     -4.39216,50.00000,20.00000,7.508883e-08,0.53025,4
617.59210,364.80000,     -8.20704,     -4.39178,50.00000,20.00000,7.547052e-08,0.52799,4
621.59735,365.60000,     -8.34038,     -4.39013,50.00000,20.00000,7.550073e-08,0.52576,4
625.62474,366.40000,     -8.47004,     -4.38911,50.00000,20.00000,7.556612e-08,0.52354,4
629.63591,367.20000,     -8.61144,     -4.38809,50.00000,20.00000,7.570427e-08,0.52136,4
633.63949,368.00000,     -8.75011,     -4.38662,50.00000,20.00000,7.593705e-08,0.51920,4
637.65037,368.80000,     -8.89402,     -4.38526,50.00000,20.00000,7.611136e-08,0.51707,4
641.65316,369.60000,     -9.02547,     -4.38554,50.00000,20.00000,7.623192e-08,0.51497,4
645.64415,370.40000,     -9.16577,     -4.38425,50.00000,20.00000,7.640908e-08,0.51289,4
649.68994,371.20000,     -9.31148,     -4.38086,50.00000,20.00000,7.645352e-08,0.51081,4
653.64869,372.00000,     -9.45023,     -4.38255,50.00000,20.00000,7.661113e-08,0.50880,4
657.66424,372.80000,     -9.59235,     -4.38119,50.00000,20.00000,7.671531e-08,0.50678,4
661.66430,373.60000,     -9.72971,     -4.38120,50.00000,20.00000,7.684130e-08,0.50479,4
665.67348,374.40000,     -9.85138,     -4.37972,50.00000,20.00000,7.702982e-08,0.50282,4
669.66602,375.20000,     -9.99249,     -4.37836,50.00000,20.00000,7.710664e-08,0.50087,4
673.68173,376.00000,    -10.14356,     -4.37701,50.00000,20.00000,7.710627e-08,0.49894,4
677.67698,376.80000,    -10.28739,     -4.37667,50.00000,20.00000,7.729045e-08,0.49703,4
681.68959,377.60000,    -10.43097,     -4.37429,50.00000,20.00000,7.738770e-08,0.49513,4
685.69560,378.40000,    -10.57233,     -4.37294,50.00000,20.00000,7.731307e-08,0.49326,4
689.70308,379.20000,    -10.71666,     -4.37158,50.00000,20.00000,7.756667e-08,0.49140,4
693.69762,380.00000,    -10.85273,     -4.37124,50.00000,20.00000,7.755620e-08,0.48957,4
697.70675,380.80000,    -10.99187,     -4.37124,50.00000,20.00000,7.776769e-08,0.48774,4
701.71714,381.60000,    -11.13287,     -4.36852,50.00000,20.00000,7.790147e-08,0.48593,4
705.72314,382.40000,    -11.27253,     -4.36581,50.00000,20.00000,7.806283e-08,0.48414,4
709.72564,383.20000,    -11.41742,     -4.36581,50.00000,20.00000,7.803742e-08,0.48237,4
713.72844,384.00000,    -11.55202,     -4.36581,50.00000,20.00000,7.808698e-08,0.48060,4
717.72963,384.80000,    -11.69582,     -4.36648,50.00000,20.00000,7.816465e-08,0.47886,4
721.75340,385.60000,    -11.83922,     -4.36443,50.00000,20.00000,7.837330e-08,0.47711,4
725.75788,386.40000,    -11.98335,     -4.36716,50.00000,20.00000,7.837198e-08,0.47539,4
729.75792,387.20000,    -12.12045,     -4.36445,50.00000,20.00000,7.848024e-08,0.47368,4
733.75889,388.00000,    -12.25218,     -4.36433,50.00000,20.00000,7.860074e-08,0.47198,4
737.77233,388.80000,    -12.38799,     -4.36298,50.00000,20.00000,7.846491e-08,0.47028,4
741.77909,389.60000,    -12.52501,     -4.36305,50.00000,20.00000,7.857436e-08,0.46860,4
745.77951,390.40000,    -12.66345,     -4.36173,50.00000,20.00000,7.869704e-08,0.46693,4
749.78336,391.20000,    -12.79941,     -4.36038,50.00000,20.00000,7.882375e-08,0.46526,4
753.80222,392.00000,    -12.93387,     -4.36039,50.00000,20.00000,7.881334e-08,0.46360,4
757.79210,392.80000,    -13.06912,     -4.35868,50.00000,20.00000,7.884622e-08,0.46196,4
761.80556,393.60000,    -13.20314,     -4.35868,50.00000,20.00000,7.894314e-08,0.46032,4
765.81194,394.40000,    -13.33940,     -4.35868,50.00000,20.00000,7.900742e-08,0.45868,4
769.81209,395.20000,    -13.47825,     -4.35936,50.00000,20.00000,7.898089e-08,0.45705,4
773.81775,396.00000,    -13.61034,     -4.35766,50.00000,20.00000,7.910807e-08,0.45543,4
777.82980,396.80000,    -13.74767,     -4.35766,50.00000,20.00000,7.927198e-08,0.45380,4
781.82374,397.60000,    -13.88573,     -4.35630,50.00000,20.00000,7.911742e-08,0.45219,4
785.84085,398.40000,    -14.01997,     -4.35630,50.00000,20.00000,7.917526e-08,0.45057,4
789.83885,399.20000,    -14.15928,     -4.35495,50.00000,20.00000,7.922717e-08,0.44896,4
793.83049,400.00000,    -14.29558,     -4.35664,50.00000,20.00000,7.925534e-08,0.44736,4
797.83344,400.80000,    -14.43445,     -4.35528,50.00000,20.00000,7.942425e-08,0.44575,4
798.33320,400.90000,    -14.44970,     -4.35528,50.00000,20.00000,7.942425e-08,0.44555,4