File: data/TGA/005c/ExpDat_2024_07_02_005c-B_260C_isotherm.csv
#EXPORTTYPE:                 ,DATA ALL
#FILE:                       ,2024_07_02_005c-B_260C_isotherm.ngb-ss5
#FORMAT:                     ,NETZSCH5
#FTYPE:                      ,ASCII
#IDENTITY:                   ,PS-SCF3
#DECIMAL:                    ,POINT
#SEPARATOR:                  ,COMMA
#MTYPE:                      ,DSC
#INSTRUMENT:                 ,NETZSCH STA 449F5
#PROJECT:                    ,
#DATE/TIME:                  ,7/2/2024 6:48:14 PM (UTC-4)
#CORR. FILE:                 ,
#TEMPCAL:                    ,28-06-2023 13:26
#SENSITIVITY:                ,28-06-2023 13:53
#LABORATORY:                 ,
#OPERATOR:                   ,PL
#REMARK:                     ,
#SAMPLE:                     ,005c-B
#SAMPLE MASS /mg:            ,4.39
#MATERIAL:                   ,
#REFERENCE:                  ,-----
#REFERENCE MASS /mg:         ,0
#TYPE OF CRUCIBLE:           ,Al2O3 85 ‘l, open
#SAMPLE CRUCIBLE MASS /mg:   ,0
#REFERENCE CRUCIBLE MASS /mg:,0
#DSC RANGE /‘V:              ,5000
#TG RANGE /mg:               ,35000
#TAU-R:                      ,---
#CORR. CODE:                 ,000
#EXO:                        ,-1
#RANGE:                      ,30›C....800›C/0.0....10.0K/min
#SEGMENT:                    ,S1-5/5
#SEG. 1:                     ,30›C/10.0(K/min)/100›C
#SEG. 2:                     ,100›C/00:25/100›C
#SEG. 3:                     ,100›C/1.0(K/min)/260›C
#SEG. 4:                     ,260›C/48:00/260›C
#SEG. 5:                     ,260›C/10.0(K/min)/800›C

##Temp./›C,Time/min,DSC/(mW/mg),Mass loss/mg,Gas Flow(purge2)/(ml/min),Gas Flow(protective)/(ml/min),TIC(scan:1)/A,Sensit./(uV/mW),Segment
 29.45200,   0.00000,      0.19930, 0.000000e+00,50.00000,20.00000,6.303949e-08,0.92345,1
 67.99400,   5.70000,      2.84916,-3.620000e-03,50.00000,20.00000,6.662168e-08,0.92594,1
109.26728,  11.40000,      0.57768,     -0.13804,50.00000,20.00000,6.285952e-08,0.91850,2
106.16692,  17.10000,     -0.41188,     -0.27005,50.00000,20.00000,6.022454e-08,0.91940,2
100.94959,  22.80000,     -0.21004,     -0.32933,50.00000,20.00000,5.794500e-08,0.92079,2
 99.64807,  28.50000,-5.168460e-02,     -0.36904,50.00000,20.00000,5.593092e-08,0.92111,2
100.51752,  34.20000,      0.13877,     -0.38691,50.00000,20.00000,5.436520e-08,0.92090,3
106.36804,  39.90000,      0.34557,     -0.37967,50.00000,20.00000,5.320932e-08,0.91934,3
113.05186,  45.60000,      0.32642,     -0.38070,50.00000,20.00000,5.244550e-08,0.91733,3
119.01976,  51.30000,      0.29182,     -0.38339,50.00000,20.00000,5.192082e-08,0.91533,3
124.73480,  57.00000,      0.28202,     -0.38046,50.00000,20.00000,5.149743e-08,0.91324,3
130.40777,  62.70000,      0.27680,     -0.37718,50.00000,20.00000,5.129192e-08,0.91099,3
136.10585,  68.40000,      0.26703,     -0.37444,50.00000,20.00000,5.122861e-08,0.90857,3
141.81274,  74.10000,      0.25148,     -0.37073,50.00000,20.00000,5.112164e-08,0.90599,3
147.52183,  79.80000,      0.24109,     -0.36700,50.00000,20.00000,5.107905e-08,0.90324,3
153.21195,  85.50000,      0.22235,     -0.36383,50.00000,20.00000,5.114390e-08,0.90035,3
158.93582,  91.20000,      0.20317,     -0.36159,50.00000,20.00000,5.116718e-08,0.89730,3
164.64575,  96.90000,      0.17785,     -0.36157,50.00000,20.00000,5.127459e-08,0.89411,3
170.33783, 102.60000,      0.15335,     -0.35976,50.00000,20.00000,5.133026e-08,0.89078,3
176.03979, 108.30000,      0.12612,     -0.35861,50.00000,20.00000,5.144349e-08,0.88732,3
181.73686, 114.00000, 9.458880e-02,     -0.35885,50.00000,20.00000,5.156468e-08,0.88373,3
187.42585, 119.70000, 5.984247e-02,     -0.35648,50.00000,20.00000,5.167070e-08,0.88001,3
193.13183, 125.40000, 2.499117e-02,     -0.35658,50.00000,20.00000,5.183536e-08,0.87616,3
198.82784, 131.10000,-1.215908e-02,     -0.35477,50.00000,20.00000,5.198698e-08,0.87220,3
204.52988, 136.80000,-4.964960e-02,     -0.35455,50.00000,20.00000,5.211121e-08,0.86812,3
210.23588, 142.50000,-9.232838e-02,     -0.35398,50.00000,20.00000,5.218417e-08,0.86393,3
215.93582, 148.20000,     -0.13364,     -0.35194,50.00000,20.00000,5.239486e-08,0.85964,3
221.62374, 153.90000,     -0.18452,     -0.35286,50.00000,20.00000,5.255737e-08,0.85525,3
227.32677, 159.60000,     -0.23614,     -0.35161,50.00000,20.00000,5.266461e-08,0.85076,3
233.01987, 165.30000,     -0.29206,     -0.35216,50.00000,20.00000,5.278960e-08,0.84619,3
238.70983, 171.00000,     -0.35026,     -0.35241,50.00000,20.00000,5.292420e-08,0.84154,3
244.41783, 176.70000,     -0.41270,     -0.35274,50.00000,20.00000,5.311566e-08,0.83679,3
250.10189, 182.40000,     -0.47879,     -0.35388,50.00000,20.00000,5.325817e-08,0.83198,3
255.82288, 188.10000,     -0.54382,     -0.35535,50.00000,20.00000,5.345225e-08,0.82707,3
260.55204, 193.80000,     -0.96285,     -0.36541,50.00000,20.00000,5.361453e-08,0.82296,4
260.47590, 199.50000,     -1.13795,     -0.38092,50.00000,20.00000,5.377695e-08,0.82302,4
260.13896, 205.20000,     -1.11579,     -0.39257,50.00000,20.00000,5.385408e-08,0.82332,4
260.04296, 210.90000,     -1.10490,     -0.40160,50.00000,20.00000,5.387205e-08,0.82340,4
260.01691, 216.60000,     -1.10299,     -0.41123,50.00000,20.00000,5.386315e-08,0.82342,4
260.01702, 222.30000,     -1.10678,     -0.41847,50.00000,20.00000,5.389928e-08,0.82342,4
260.02003, 228.00000,     -1.10003,     -0.42537,50.00000,20.00000,5.391863e-08,0.82342,4
260.01402, 233.70000,     -1.10404,     -0.43318,50.00000,20.00000,5.395570e-08,0.82343,4
260.02201, 239.40000,     -1.10152,     -0.43872,50.00000,20.00000,5.397141e-08,0.82342,4
260.00302, 245.10000,     -1.10572,     -0.44438,50.00000,20.00000,5.392631e-08,0.82344,4
260.01004, 250.80000,     -1.10530,     -0.44903,50.00000,20.00000,5.395711e-08,0.82343,4
260.01601, 256.50000,     -1.10510,     -0.45514,50.00000,20.00000,5.392817e-08,0.82342,4
260.02496, 262.20000,     -1.10405,     -0.45906,50.00000,20.00000,5.395729e-08,0.82342,4
260.00901, 267.90000,     -1.10657,     -0.46497,50.00000,20.00000,5.396467e-08,0.82343,4
260.01503, 273.60000,     -1.10447,     -0.46791,50.00000,20.00000,5.395891e-08,0.82342,4
260.01790, 279.30000,     -1.10701,     -0.47301,50.00000,20.00000,5.395474e-08,0.82342,4
260.03289, 285.00000,     -1.10492,     -0.47774,50.00000,20.00000,5.394964e-08,0.82341,4
260.02199, 290.70000,     -1.10721,     -0.48136,50.00000,20.00000,5.397407e-08,0.82342,4
260.01993, 296.40000,     -1.10763,     -0.48590,50.00000,20.00000,5.392786e-08,0.82342,4
260.02207, 302.10000,     -1.10320,     -0.48861,50.00000,20.00000,5.399447e-08,0.82342,4
260.01995, 307.80000,     -1.10469,     -0.49301,50.00000,20.00000,5.401771e-08,0.82342,4
260.01995, 313.50000,     -1.10616,     -0.49675,50.00000,20.00000,5.400328e-08,0.82342,4
260.00398, 319.20000,     -1.10614,     -0.50208,50.00000,20.00000,5.402893e-08,0.82343,4
260.00997, 324.90000,     -1.10763,     -0.50580,50.00000,20.00000,5.403685e-08,0.82343,4
260.00501, 330.60000,     -1.10805,     -0.51046,50.00000,20.00000,5.405130e-08,0.82343,4
260.01601, 336.30000,     -1.10657,     -0.51429,50.00000,20.00000,5.401228e-08,0.82342,4
260.00802, 342.00000,     -1.10762,     -0.51712,50.00000,20.00000,5.402502e-08,0.82343,4
260.01797, 347.70000,     -1.10890,     -0.52347,50.00000,20.00000,5.394720e-08,0.82342,4
260.02088, 353.40000,     -1.10743,     -0.52650,50.00000,20.00000,5.402666e-08,0.82342,4
260.01589, 359.10000,     -1.10700,     -0.52910,50.00000,20.00000,5.403397e-08,0.82342,4
260.01815, 364.80000,     -1.10469,     -0.53262,50.00000,20.00000,5.397339e-08,0.82342,4
260.02092, 370.50000,     -1.10912,     -0.53566,50.00000,20.00000,5.403508e-08,0.82342,4
260.02095, 376.20000,     -1.10594,     -0.53827,50.00000,20.00000,5.403175e-08,0.82342,4
260.02106, 381.90000,     -1.10722,     -0.54235,50.00000,20.00000,5.406504e-08,0.82342,4
260.01196, 387.60000,     -1.10552,     -0.54552,50.00000,20.00000,5.410451e-08,0.82343,4
260.02200, 393.30000,     -1.10447,     -0.54925,50.00000,20.00000,5.405309e-08,0.82342,4
260.00794, 399.00000,     -1.10847,     -0.55366,50.00000,20.00000,5.409640e-08,0.82343,4
259.99305, 404.70000,     -1.10803,     -0.55683,50.00000,20.00000,5.407007e-08,0.82344,4
260.02097, 410.40000,     -1.10364,     -0.56136,50.00000,20.00000,5.404954e-08,0.82342,4
260.01099, 416.10000,     -1.10868,     -0.56519,50.00000,20.00000,5.408299e-08,0.82343,4
260.00396, 421.80000,     -1.10762,     -0.56825,50.00000,20.00000,5.404363e-08,0.82343,4
260.01196, 427.50000,     -1.11164,     -0.57176,50.00000,20.00000,5.410078e-08,0.82343,4
260.00704, 433.20000,     -1.10889,     -0.57323,50.00000,20.00000,5.403017e-08,0.82343,4
260.03107, 438.90000,     -1.10914,     -0.57606,50.00000,20.00000,5.405894e-08,0.82341,4
260.02207, 444.60000,     -1.10869,     -0.58025,50.00000,20.00000,5.403083e-08,0.82342,4
260.02402, 450.30000,     -1.10743,     -0.58251,50.00000,20.00000,5.405538e-08,0.82342,4
260.00304, 456.00000,     -1.10720,     -0.58703,50.00000,20.00000,5.408038e-08,0.82344,4
260.02598, 461.70000,     -1.10490,     -0.59020,50.00000,20.00000,5.403209e-08,0.82342,4
260.01993, 467.40000,     -1.10511,     -0.59303,50.00000,20.00000,5.403730e-08,0.82342,4
260.03005, 473.10000,     -1.10849,     -0.59710,50.00000,20.00000,5.406656e-08,0.82341,4
260.02300, 478.80000,     -1.10617,     -0.59936,50.00000,20.00000,5.408695e-08,0.82342,4
260.00693, 484.50000,     -1.10762,     -0.60231,50.00000,20.00000,5.409703e-08,0.82343,4
260.02000, 490.20000,     -1.10491,     -0.60536,50.00000,20.00000,5.408785e-08,0.82342,4
260.01101, 495.90000,     -1.10804,     -0.60887,50.00000,20.00000,5.408596e-08,0.82343,4
260.01803, 501.60000,     -1.10828,     -0.61259,50.00000,20.00000,5.407871e-08,0.82342,4
260.01012, 507.30000,     -1.10867,     -0.61566,50.00000,20.00000,5.406532e-08,0.82343,4
260.02500, 513.00000,     -1.10849,     -0.61837,50.00000,20.00000,5.408259e-08,0.82342,4
260.01503, 518.70000,     -1.10699,     -0.62109,50.00000,20.00000,5.408372e-08,0.82342,4
260.00996, 524.40000,     -1.10889,     -0.62312,50.00000,20.00000,5.406045e-08,0.82343,4
260.01997, 530.10000,     -1.10553,     -0.62753,50.00000,20.00000,5.410490e-08,0.82342,4
260.02203, 535.80000,     -1.10617,     -0.63060,50.00000,20.00000,5.409129e-08,0.82342,4
260.00399, 541.50000,     -1.10888,     -0.63229,50.00000,20.00000,5.404809e-08,0.82343,4
260.03201, 547.20000,     -1.10913,     -0.63534,50.00000,20.00000,5.404914e-08,0.82341,4
260.01897, 552.90000,     -1.10573,     -0.63906,50.00000,20.00000,5.404864e-08,0.82342,4
260.01797, 558.60000,     -1.10912,     -0.64247,50.00000,20.00000,5.402585e-08,0.82342,4
260.02297, 564.30000,     -1.10848,     -0.64598,50.00000,20.00000,5.400927e-08,0.82342,4
260.01705, 570.00000,     -1.10616,     -0.64745,50.00000,20.00000,5.405223e-08,0.82342,4
260.01401, 575.70000,     -1.10425,     -0.65050,50.00000,20.00000,5.403120e-08,0.82343,4
260.00800, 581.40000,     -1.10846,     -0.65231,50.00000,20.00000,5.402664e-08,0.82343,4
260.01202, 587.10000,     -1.10656,     -0.65604,50.00000,20.00000,5.405851e-08,0.82343,4
260.00806, 592.80000,     -1.10846,     -0.65808,50.00000,20.00000,5.405709e-08,0.82343,4
260.01599, 598.50000,     -1.10763,     -0.65978,50.00000,20.00000,5.407615e-08,0.82342,4
260.01300, 604.20000,     -1.10531,     -0.66248,50.00000,20.00000,5.409602e-08,0.82343,4
260.01009, 609.90000,     -1.10467,     -0.66520,50.00000,20.00000,5.409589e-08,0.82343,4
260.02194, 615.60000,     -1.10426,     -0.66769,50.00000,20.00000,5.406431e-08,0.82342,4
260.01504, 621.30000,     -1.10320,     -0.67120,50.00000,20.00000,5.405631e-08,0.82342,4
260.01104, 627.00000,     -1.10551,     -0.67334,50.00000,20.00000,5.401801e-08,0.82343,4
260.02306, 632.70000,     -1.10511,     -0.67685,50.00000,20.00000,5.400318e-08,0.82342,4
260.02302, 638.40000,     -1.10469,     -0.67946,50.00000,20.00000,5.398942e-08,0.82342,4
260.01501, 644.10000,     -1.10637,     -0.68263,50.00000,20.00000,5.401661e-08,0.82342,4
260.02103, 649.80000,     -1.10785,     -0.68399,50.00000,20.00000,5.401980e-08,0.82342,4
260.02096, 655.50000,     -1.10617,     -0.68636,50.00000,20.00000,5.398485e-08,0.82342,4
260.02402, 661.20000,     -1.10659,     -0.68841,50.00000,20.00000,5.401783e-08,0.82342,4
260.01502, 666.90000,     -1.10700,     -0.69111,50.00000,20.00000,5.403544e-08,0.82342,4
260.02106, 672.60000,     -1.10679,     -0.69259,50.00000,20.00000,5.403316e-08,0.82342,4
260.02694, 678.30000,     -1.10618,     -0.69587,50.00000,20.00000,5.402840e-08,0.82341,4
260.00498, 684.00000,     -1.10362,     -0.69768,50.00000,20.00000,5.404682e-08,0.82343,4
260.01703, 689.70000,     -1.10616,     -0.70073,50.00000,20.00000,5.400645e-08,0.82342,4
260.01098, 695.40000,     -1.10742,     -0.70185,50.00000,20.00000,5.401664e-08,0.82343,4
260.01795, 701.10000,     -1.10531,     -0.70559,50.00000,20.00000,5.401834e-08,0.82342,4
260.01701, 706.80000,     -1.10511,     -0.70719,50.00000,20.00000,5.399650e-08,0.82342,4
260.00990, 712.50000,     -1.10489,     -0.70832,50.00000,20.00000,5.403317e-08,0.82343,4
260.00698, 718.20000,     -1.10402,     -0.71092,50.00000,20.00000,5.406803e-08,0.82343,4
260.01810, 723.90000,     -1.10593,     -0.71487,50.00000,20.00000,5.399585e-08,0.82342,4
260.02303, 729.60000,     -1.10680,     -0.71826,50.00000,20.00000,5.395840e-08,0.82342,4
260.01196, 735.30000,     -1.10403,     -0.72076,50.00000,20.00000,5.400620e-08,0.82343,4
260.02692, 741.00000,     -1.10722,     -0.72414,50.00000,20.00000,5.398281e-08,0.82341,4
260.01905, 746.70000,     -1.10193,     -0.72618,50.00000,20.00000,5.398437e-08,0.82342,4
260.02803, 752.40000,     -1.10680,     -0.72901,50.00000,20.00000,5.400667e-08,0.82341,4
260.01801, 758.10000,     -1.10616,     -0.73252,50.00000,20.00000,5.398186e-08,0.82342,4
260.01604, 763.80000,     -1.10636,     -0.73467,50.00000,20.00000,5.397202e-08,0.82342,4
260.00900, 769.50000,     -1.10762,     -0.73737,50.00000,20.00000,5.395547e-08,0.82343,4
260.01703, 775.20000,     -1.10679,     -0.73773,50.00000,20.00000,5.394849e-08,0.82342,4
260.00697, 780.90000,     -1.10911,     -0.74202,50.00000,20.00000,5.393903e-08,0.82343,4
260.01564, 786.60000,     -1.10763,     -0.74202,50.00000,20.00000,5.394804e-08,0.82342,4
259.99788, 792.30000,     -1.10529,     -0.74383,50.00000,20.00000,5.388462e-08,0.82344,4
260.01902, 798.00000,     -1.10595,     -0.74665,50.00000,20.00000,5.393049e-08,0.82342,4
260.03197, 803.70000,     -1.10913,     -0.74915,50.00000,20.00000,5.391765e-08,0.82341,4
260.01202, 809.40000,     -1.10552,     -0.74959,50.00000,20.00000,5.387568e-08,0.82343,4
260.01996, 815.10000,     -1.10784,     -0.75154,50.00000,20.00000,5.392832e-08,0.82342,4
260.02401, 820.80000,     -1.10807,     -0.75414,50.00000,20.00000,5.394346e-08,0.82342,4
260.01298, 826.50000,     -1.10721,     -0.75605,50.00000,20.00000,5.393576e-08,0.82343,4
260.00900, 832.20000,     -1.10657,     -0.75843,50.00000,20.00000,5.394566e-08,0.82343,4
260.01901, 837.90000,     -1.10553,     -0.76171,50.00000,20.00000,5.391684e-08,0.82342,4
260.01994, 843.60000,     -1.10510,     -0.76397,50.00000,20.00000,5.392208e-08,0.82342,4
260.01902, 849.30000,     -1.10405,     -0.76623,50.00000,20.00000,5.392333e-08,0.82342,4
260.02308, 855.00000,     -1.10680,     -0.76941,50.00000,20.00000,5.389676e-08,0.82342,4
260.02508, 860.70000,     -1.10701,     -0.77110,50.00000,20.00000,5.392895e-08,0.82342,4
260.01601, 866.40000,     -1.11143,     -0.77449,50.00000,20.00000,5.390202e-08,0.82342,4
260.01424, 872.10000,     -1.10553,     -0.77653,50.00000,20.00000,5.392919e-08,0.82343,4
260.02104, 877.80000,     -1.10975,     -0.77823,50.00000,20.00000,5.390789e-08,0.82342,4
260.02303, 883.50000,     -1.10849,     -0.77890,50.00000,20.00000,5.394559e-08,0.82342,4
260.02304, 889.20000,     -1.10827,     -0.78309,50.00000,20.00000,5.392150e-08,0.82342,4
260.01798, 894.90000,     -1.10763,     -0.78399,50.00000,20.00000,5.388691e-08,0.82342,4
260.01405, 900.60000,     -1.10868,     -0.78557,50.00000,20.00000,5.388688e-08,0.82343,4
260.01793, 906.30000,     -1.10955,     -0.78852,50.00000,20.00000,5.388190e-08,0.82342,4
260.01306, 912.00000,     -1.10763,     -0.79123,50.00000,20.00000,5.382542e-08,0.82343,4
260.01401, 917.70000,     -1.10637,     -0.79475,50.00000,20.00000,5.382790e-08,0.82343,4
260.01396, 923.40000,     -1.10848,     -0.79780,50.00000,20.00000,5.385208e-08,0.82343,4
260.02299, 929.10000,     -1.11017,     -0.79881,50.00000,20.00000,5.382661e-08,0.82342,4
260.00800, 934.80000,     -1.10615,     -0.80052,50.00000,20.00000,5.386058e-08,0.82343,4
260.01004, 940.50000,     -1.10678,     -0.80300,50.00000,20.00000,5.384898e-08,0.82343,4
260.00003, 946.20000,     -1.10931,     -0.80548,50.00000,20.00000,5.381704e-08,0.82344,4
260.01401, 951.90000,     -1.10847,     -0.80753,50.00000,20.00000,5.383110e-08,0.82343,4
260.01300, 957.60000,     -1.10868,     -0.81036,50.00000,20.00000,5.378357e-08,0.82343,4
260.01297, 963.30000,     -1.10889,     -0.81238,50.00000,20.00000,5.378270e-08,0.82343,4
260.00593, 969.00000,     -1.11058,     -0.81523,50.00000,20.00000,5.380309e-08,0.82343,4
260.01396, 974.70000,     -1.10806,     -0.81725,50.00000,20.00000,5.380529e-08,0.82343,4
260.02892, 980.40000,     -1.10849,     -0.81691,50.00000,20.00000,5.378786e-08,0.82341,4
260.02094, 986.10000,     -1.10699,     -0.82053,50.00000,20.00000,5.382611e-08,0.82342,4
260.01201, 991.80000,     -1.10931,     -0.82257,50.00000,20.00000,5.377601e-08,0.82343,4
260.02703, 997.50000,     -1.10595,     -0.82495,50.00000,20.00000,5.378617e-08,0.82341,4
260.01998,1003.20000,     -1.11060,     -0.82799,50.00000,20.00000,5.373906e-08,0.82342,4
260.00206,1008.90000,     -1.10804,     -0.83014,50.00000,20.00000,5.376065e-08,0.82344,4
260.02700,1014.60000,     -1.11081,     -0.83185,50.00000,20.00000,5.374173e-08,0.82341,4
260.01294,1020.30000,     -1.10319,     -0.83276,50.00000,20.00000,5.371624e-08,0.82343,4
260.02603,1026.00000,     -1.10680,     -0.83661,50.00000,20.00000,5.373919e-08,0.82342,4
260.02203,1031.70000,     -1.10532,     -0.83920,50.00000,20.00000,5.372144e-08,0.82342,4
260.01197,1037.40000,     -1.10995,     -0.83977,50.00000,20.00000,5.368192e-08,0.82343,4
260.00603,1043.10000,     -1.10931,     -0.84248,50.00000,20.00000,5.372067e-08,0.82343,4
260.02803,1048.80000,     -1.10828,     -0.84474,50.00000,20.00000,5.373512e-08,0.82341,4
260.01299,1054.50000,     -1.10532,     -0.84508,50.00000,20.00000,5.374613e-08,0.82343,4
260.00398,1060.20000,     -1.10720,     -0.84916,50.00000,20.00000,5.371263e-08,0.82343,4
260.01297,1065.90000,     -1.10720,     -0.85040,50.00000,20.00000,5.373518e-08,0.82343,4
260.02205,1071.60000,     -1.10808,     -0.85345,50.00000,20.00000,5.371711e-08,0.82342,4
260.01205,1077.30000,     -1.10404,     -0.85640,50.00000,20.00000,5.369259e-08,0.82343,4
260.01396,1083.00000,     -1.10616,     -0.85729,50.00000,20.00000,5.369446e-08,0.82343,4
260.02194,1088.70000,     -1.10469,     -0.86024,50.00000,20.00000,5.373144e-08,0.82342,4
260.01291,1094.40000,     -1.09940,     -0.86092,50.00000,20.00000,5.370402e-08,0.82343,4
260.02794,1100.10000,     -1.10174,     -0.86478,50.00000,20.00000,5.364884e-08,0.82341,4
259.95493,1105.80000,     -1.08664,     -0.87374,50.00000,20.00000,5.373441e-08,0.82348,4
260.00194,1111.50000,     -0.99154,     -0.86862,50.00000,20.00000,5.385613e-08,0.82344,4
260.06901,1117.20000,     -1.00386,     -0.86975,50.00000,20.00000,5.381183e-08,0.82338,4
260.03393,1122.90000,     -1.01268,     -0.87235,50.00000,20.00000,5.371155e-08,0.82341,4
260.03392,1128.60000,     -1.01543,     -0.87506,50.00000,20.00000,5.365922e-08,0.82341,4
260.00609,1134.30000,     -1.01454,     -0.87925,50.00000,20.00000,5.362409e-08,0.82343,4
260.02104,1140.00000,     -1.00717,     -0.88082,50.00000,20.00000,5.358756e-08,0.82342,4
260.02400,1145.70000,     -1.01119,     -0.88445,50.00000,20.00000,5.364420e-08,0.82342,4
260.01010,1151.40000,     -1.01055,     -0.88649,50.00000,20.00000,5.363337e-08,0.82343,4
260.01802,1157.10000,     -1.01330,     -0.88786,50.00000,20.00000,5.359989e-08,0.82342,4
260.00899,1162.80000,     -1.01244,     -0.88999,50.00000,20.00000,5.357707e-08,0.82343,4
260.01391,1168.50000,     -1.01328,     -0.89134,50.00000,20.00000,5.353646e-08,0.82343,4
260.00695,1174.20000,     -1.01160,     -0.89236,50.00000,20.00000,5.357216e-08,0.82343,4
260.00003,1179.90000,     -1.01137,     -0.89485,50.00000,20.00000,5.359904e-08,0.82344,4
260.01791,1185.60000,     -1.01267,     -0.89646,50.00000,20.00000,5.358301e-08,0.82342,4
260.01598,1191.30000,     -1.01436,     -0.89951,50.00000,20.00000,5.357868e-08,0.82342,4
260.00501,1197.00000,     -1.01328,     -0.90142,50.00000,20.00000,5.355757e-08,0.82343,4
259.99490,1202.70000,     -1.01032,     -0.90311,50.00000,20.00000,5.357838e-08,0.82344,4
260.00101,1208.40000,     -1.00990,     -0.90563,50.00000,20.00000,5.357921e-08,0.82344,4
260.00000,1214.10000,     -1.00905,     -0.90720,50.00000,20.00000,5.356667e-08,0.82344,4
260.03097,1219.80000,     -1.00802,     -0.90879,50.00000,20.00000,5.355689e-08,0.82341,4
260.01400,1225.50000,     -1.01054,     -0.91093,50.00000,20.00000,5.356241e-08,0.82343,4
260.00396,1231.20000,     -1.00947,     -0.91331,50.00000,20.00000,5.349700e-08,0.82343,4
260.01501,1236.90000,     -1.00464,     -0.91568,50.00000,20.00000,5.352181e-08,0.82342,4
260.00902,1242.60000,     -1.01223,     -0.91681,50.00000,20.00000,5.351372e-08,0.82343,4
260.02489,1248.30000,     -1.01224,     -0.92010,50.00000,20.00000,5.344325e-08,0.82342,4
260.03287,1254.00000,     -1.01268,     -0.92235,50.00000,20.00000,5.351504e-08,0.82341,4
260.01899,1259.70000,     -1.00802,     -0.92404,50.00000,20.00000,5.346763e-08,0.82342,4
260.00997,1265.40000,     -1.01139,     -0.92506,50.00000,20.00000,5.346461e-08,0.82343,4
260.02796,1271.10000,     -1.01351,     -0.92642,50.00000,20.00000,5.349420e-08,0.82341,4
260.01799,1276.80000,     -1.00908,     -0.92790,50.00000,20.00000,5.350709e-08,0.82342,4
260.01196,1282.50000,     -1.00928,     -0.93005,50.00000,20.00000,5.351916e-08,0.82343,4
260.00701,1288.20000,     -1.01096,     -0.93039,50.00000,20.00000,5.350641e-08,0.82343,4
260.01102,1293.90000,     -1.01075,     -0.93469,50.00000,20.00000,5.351074e-08,0.82343,4
260.01193,1299.60000,     -1.01371,     -0.93649,50.00000,20.00000,5.353094e-08,0.82343,4
260.01903,1305.30000,     -1.00971,     -0.93911,50.00000,20.00000,5.346908e-08,0.82342,4
260.01097,1311.00000,     -1.00971,     -0.94137,50.00000,20.00000,5.346215e-08,0.82343,4
260.01496,1316.70000,     -1.00674,     -0.94452,50.00000,20.00000,5.348891e-08,0.82342,4
260.02002,1322.40000,     -1.00824,     -0.94553,50.00000,20.00000,5.343734e-08,0.82342,4
260.01095,1328.10000,     -1.00948,     -0.94849,50.00000,20.00000,5.343091e-08,0.82343,4
260.01403,1333.80000,     -1.00864,     -0.94995,50.00000,20.00000,5.339905e-08,0.82343,4
260.01192,1339.50000,     -1.01096,     -0.95212,50.00000,20.00000,5.344100e-08,0.82343,4
260.02003,1345.20000,     -1.00697,     -0.95313,50.00000,20.00000,5.337569e-08,0.82342,4
260.01699,1350.90000,     -1.01055,     -0.95616,50.00000,20.00000,5.341826e-08,0.82342,4
260.01904,1356.60000,     -1.01055,     -0.95697,50.00000,20.00000,5.338297e-08,0.82342,4
260.01910,1362.30000,     -1.01075,     -0.95923,50.00000,20.00000,5.340377e-08,0.82342,4
260.02101,1368.00000,     -1.00886,     -0.96070,50.00000,20.00000,5.335821e-08,0.82342,4
260.01206,1373.70000,     -1.00885,     -0.96331,50.00000,20.00000,5.341947e-08,0.82343,4
260.01589,1379.40000,     -1.00843,     -0.96456,50.00000,20.00000,5.335708e-08,0.82342,4
260.01801,1385.10000,     -1.00992,     -0.96715,50.00000,20.00000,5.337837e-08,0.82342,4
260.02200,1390.80000,     -1.00719,     -0.96942,50.00000,20.00000,5.335671e-08,0.82342,4
260.01999,1396.50000,     -1.01013,     -0.97144,50.00000,20.00000,5.334299e-08,0.82342,4
260.01802,1402.20000,     -1.00464,     -0.97370,50.00000,20.00000,5.336046e-08,0.82342,4
260.01999,1407.90000,     -1.01160,     -0.97461,50.00000,20.00000,5.333724e-08,0.82342,4
260.01597,1413.60000,     -1.00590,     -0.97699,50.00000,20.00000,5.331396e-08,0.82342,4
260.01393,1419.30000,     -1.01202,     -0.97733,50.00000,20.00000,5.334598e-08,0.82343,4
260.02702,1425.00000,     -1.00992,     -0.98005,50.00000,20.00000,5.330972e-08,0.82341,4
260.02701,1430.70000,     -1.01034,     -0.98186,50.00000,20.00000,5.330709e-08,0.82341,4
260.02293,1436.40000,     -1.01267,     -0.98502,50.00000,20.00000,5.332058e-08,0.82342,4
260.01295,1442.10000,     -1.01201,     -0.98684,50.00000,20.00000,5.328672e-08,0.82343,4
260.00905,1447.80000,     -1.01118,     -0.98673,50.00000,20.00000,5.333360e-08,0.82343,4
260.01804,1453.50000,     -1.01140,     -0.98831,50.00000,20.00000,5.331735e-08,0.82342,4
260.00202,1459.20000,     -1.01117,     -0.99136,50.00000,20.00000,5.333032e-08,0.82344,4
260.01706,1464.90000,     -1.00970,     -0.99261,50.00000,20.00000,5.334685e-08,0.82342,4
260.02401,1470.60000,     -1.01034,     -0.99374,50.00000,20.00000,5.332999e-08,0.82342,4
260.02000,1476.30000,     -1.00971,     -0.99838,50.00000,20.00000,5.333851e-08,0.82342,4
260.02498,1482.00000,     -1.00887,     -0.99791,50.00000,20.00000,5.332989e-08,0.82342,4
260.01697,1487.70000,     -1.00675,     -1.00098,50.00000,20.00000,5.332094e-08,0.82342,4
260.01190,1493.40000,     -1.01033,     -1.00290,50.00000,20.00000,5.332425e-08,0.82343,4
260.02997,1499.10000,     -1.00719,     -1.00528,50.00000,20.00000,5.333008e-08,0.82341,4
260.02295,1504.80000,     -1.00696,     -1.00652,50.00000,20.00000,5.331803e-08,0.82342,4
260.00795,1510.50000,     -1.01095,     -1.00743,50.00000,20.00000,5.332445e-08,0.82343,4
260.01296,1516.20000,     -1.00970,     -1.01071,50.00000,20.00000,5.330991e-08,0.82343,4
260.01693,1521.90000,     -1.00823,     -1.01218,50.00000,20.00000,5.328981e-08,0.82342,4
260.02106,1527.60000,     -1.00971,     -1.01468,50.00000,20.00000,5.327742e-08,0.82342,4
260.01008,1533.30000,     -1.01137,     -1.01692,50.00000,20.00000,5.326221e-08,0.82343,4
260.00601,1539.00000,     -1.00948,     -1.01929,50.00000,20.00000,5.325356e-08,0.82343,4
260.02907,1544.70000,     -1.00592,     -1.02202,50.00000,20.00000,5.326395e-08,0.82341,4
260.01197,1550.40000,     -1.01224,     -1.02259,50.00000,20.00000,5.323327e-08,0.82343,4
260.01905,1556.10000,     -1.00866,     -1.02473,50.00000,20.00000,5.323958e-08,0.82342,4
260.02303,1561.80000,     -1.01140,     -1.02610,50.00000,20.00000,5.325415e-08,0.82342,4
260.02198,1567.50000,     -1.00929,     -1.02802,50.00000,20.00000,5.325153e-08,0.82342,4
260.01397,1573.20000,     -1.01139,     -1.02892,50.00000,20.00000,5.323779e-08,0.82343,4
260.01799,1578.90000,     -1.01456,     -1.03061,50.00000,20.00000,5.322653e-08,0.82342,4
260.01796,1584.60000,     -1.00655,     -1.03288,50.00000,20.00000,5.321169e-08,0.82342,4
260.02600,1590.30000,     -1.01245,     -1.03515,50.00000,20.00000,5.320036e-08,0.82342,4
260.00908,1596.00000,     -1.01160,     -1.03729,50.00000,20.00000,5.322999e-08,0.82343,4
260.01401,1601.70000,     -1.00969,     -1.03842,50.00000,20.00000,5.326144e-08,0.82343,4
260.01501,1607.40000,     -1.01076,     -1.03910,50.00000,20.00000,5.321794e-08,0.82342,4
260.02206,1613.10000,     -1.01097,     -1.04169,50.00000,20.00000,5.325039e-08,0.82342,4
260.01301,1618.80000,     -1.01243,     -1.04341,50.00000,20.00000,5.325240e-08,0.82343,4
260.01898,1624.50000,     -1.00970,     -1.04545,50.00000,20.00000,5.322863e-08,0.82342,4
260.02102,1630.20000,     -1.00865,     -1.04680,50.00000,20.00000,5.320787e-08,0.82342,4
260.01693,1635.90000,     -1.01096,     -1.04883,50.00000,20.00000,5.323013e-08,0.82342,4
260.02595,1641.60000,     -1.01140,     -1.05121,50.00000,20.00000,5.325891e-08,0.82342,4
260.00799,1647.30000,     -1.01181,     -1.05255,50.00000,20.00000,5.323557e-08,0.82343,4
260.00802,1653.00000,     -1.00737,     -1.05461,50.00000,20.00000,5.323992e-08,0.82343,4
260.01400,1658.70000,     -1.01118,     -1.05685,50.00000,20.00000,5.325361e-08,0.82343,4
260.01998,1664.40000,     -1.01013,     -1.05867,50.00000,20.00000,5.324800e-08,0.82342,4
260.00400,1670.10000,     -1.01201,     -1.05913,50.00000,20.00000,5.324848e-08,0.82343,4
260.01094,1675.80000,     -1.01223,     -1.06241,50.00000,20.00000,5.321078e-08,0.82343,4
260.01501,1681.50000,     -1.01244,     -1.06421,50.00000,20.00000,5.325801e-08,0.82342,4
260.01803,1687.20000,     -1.01139,     -1.06614,50.00000,20.00000,5.325285e-08,0.82342,4
260.01700,1692.90000,     -1.01350,     -1.06874,50.00000,20.00000,5.326190e-08,0.82342,4
260.01597,1698.60000,     -1.01434,     -1.06931,50.00000,20.00000,5.321843e-08,0.82342,4
260.01297,1704.30000,     -1.00928,     -1.07348,50.00000,20.00000,5.321071e-08,0.82343,4
260.01295,1710.00000,     -1.01287,     -1.07430,50.00000,20.00000,5.323387e-08,0.82343,4
260.01492,1715.70000,     -1.01244,     -1.07700,50.00000,20.00000,5.321983e-08,0.82342,4
260.00806,1721.40000,     -1.01054,     -1.07904,50.00000,20.00000,5.323738e-08,0.82343,4
260.02000,1727.10000,     -1.01329,     -1.08051,50.00000,20.00000,5.319158e-08,0.82342,4
260.01800,1732.80000,     -1.01372,     -1.08187,50.00000,20.00000,5.321472e-08,0.82342,4
260.01694,1738.50000,     -1.01519,     -1.08559,50.00000,20.00000,5.320366e-08,0.82342,4
260.02394,1744.20000,     -1.01562,     -1.08572,50.00000,20.00000,5.317888e-08,0.82342,4
260.00505,1749.90000,     -1.01476,     -1.08741,50.00000,20.00000,5.315941e-08,0.82343,4
260.01207,1755.60000,     -1.01328,     -1.08922,50.00000,20.00000,5.318988e-08,0.82343,4
260.00993,1761.30000,     -1.01580,     -1.09170,50.00000,20.00000,5.317377e-08,0.82343,4
260.01697,1767.00000,     -1.01392,     -1.09397,50.00000,20.00000,5.313424e-08,0.82342,4
260.00900,1772.70000,     -1.01076,     -1.09363,50.00000,20.00000,5.318074e-08,0.82343,4
260.00503,1778.40000,     -1.01434,     -1.09510,50.00000,20.00000,5.313208e-08,0.82343,4
260.00495,1784.10000,     -1.01581,     -1.09748,50.00000,20.00000,5.312122e-08,0.82343,4
260.01299,1789.80000,     -1.01224,     -1.09918,50.00000,20.00000,5.314127e-08,0.82343,4
260.01001,1795.50000,     -1.01222,     -1.10042,50.00000,20.00000,5.317775e-08,0.82343,4
260.02503,1801.20000,     -1.01373,     -1.10234,50.00000,20.00000,5.317127e-08,0.82342,4
260.02806,1806.90000,     -1.01437,     -1.10515,50.00000,20.00000,5.315692e-08,0.82341,4
260.01498,1812.60000,     -1.01751,     -1.10608,50.00000,20.00000,5.310777e-08,0.82342,4
260.01613,1818.30000,     -1.01181,     -1.10913,50.00000,20.00000,5.313711e-08,0.82342,4
260.01899,1824.00000,     -1.01498,     -1.10855,50.00000,20.00000,5.314515e-08,0.82342,4
260.01090,1829.70000,     -1.01413,     -1.11094,50.00000,20.00000,5.309470e-08,0.82343,4
260.01701,1835.40000,     -1.01562,     -1.11275,50.00000,20.00000,5.307128e-08,0.82342,4
260.02399,1841.10000,     -1.01518,     -1.11479,50.00000,20.00000,5.312351e-08,0.82342,4
260.01996,1846.80000,     -1.01667,     -1.11569,50.00000,20.00000,5.312392e-08,0.82342,4
260.01395,1852.50000,     -1.01687,     -1.11852,50.00000,20.00000,5.309473e-08,0.82343,4
260.01901,1858.20000,     -1.01732,     -1.11898,50.00000,20.00000,5.312596e-08,0.82342,4
260.01003,1863.90000,     -1.01687,     -1.12056,50.00000,20.00000,5.308727e-08,0.82343,4
260.00901,1869.60000,     -1.01561,     -1.12157,50.00000,20.00000,5.309480e-08,0.82343,4
260.01811,1875.30000,     -1.01541,     -1.12259,50.00000,20.00000,5.309597e-08,0.82342,4
260.01899,1881.00000,     -1.01518,     -1.12621,50.00000,20.00000,5.309592e-08,0.82342,4
260.01502,1886.70000,     -1.01751,     -1.12507,50.00000,20.00000,5.310713e-08,0.82342,4
260.00997,1892.40000,     -1.01771,     -1.13017,50.00000,20.00000,5.311693e-08,0.82343,4
260.01203,1898.10000,     -1.01624,     -1.13029,50.00000,20.00000,5.310173e-08,0.82343,4
260.02303,1903.80000,     -1.01879,     -1.13277,50.00000,20.00000,5.307907e-08,0.82342,4
259.99599,1909.50000,     -1.01496,     -1.13424,50.00000,20.00000,5.306707e-08,0.82344,4
260.02198,1915.20000,     -1.01520,     -1.13560,50.00000,20.00000,5.304508e-08,0.82342,4
260.02705,1920.90000,     -1.01542,     -1.13595,50.00000,20.00000,5.303568e-08,0.82341,4
260.01407,1926.60000,     -1.02004,     -1.13832,50.00000,20.00000,5.301595e-08,0.82343,4
260.01817,1932.30000,     -1.01541,     -1.14137,50.00000,20.00000,5.300488e-08,0.82342,4
260.01600,1938.00000,     -1.01581,     -1.14205,50.00000,20.00000,5.299683e-08,0.82342,4
260.00901,1943.70000,     -1.02026,     -1.14375,50.00000,20.00000,5.301729e-08,0.82343,4
260.02402,1949.40000,     -1.01688,     -1.14646,50.00000,20.00000,5.300006e-08,0.82342,4
260.00798,1955.10000,     -1.01770,     -1.14749,50.00000,20.00000,5.301465e-08,0.82343,4
260.01101,1960.80000,     -1.01645,     -1.14906,50.00000,20.00000,5.302471e-08,0.82343,4
260.02490,1966.50000,     -1.01774,     -1.14940,50.00000,20.00000,5.303507e-08,0.82342,4
260.01203,1972.20000,     -1.02024,     -1.15280,50.00000,20.00000,5.299460e-08,0.82343,4
260.01605,1977.90000,     -1.01964,     -1.15382,50.00000,20.00000,5.298212e-08,0.82342,4
260.02301,1983.60000,     -1.01879,     -1.15585,50.00000,20.00000,5.303216e-08,0.82342,4
260.02805,1989.30000,     -1.01542,     -1.15790,50.00000,20.00000,5.298722e-08,0.82341,4
260.02498,1995.00000,     -1.01859,     -1.15857,50.00000,20.00000,5.301047e-08,0.82342,4
260.00103,2000.70000,     -1.01939,     -1.16230,50.00000,20.00000,5.295903e-08,0.82344,4
260.02098,2006.40000,     -1.01794,     -1.16331,50.00000,20.00000,5.296239e-08,0.82342,4
260.01907,2012.10000,     -1.02005,     -1.16468,50.00000,20.00000,5.301629e-08,0.82342,4
260.00799,2017.80000,     -1.01707,     -1.16739,50.00000,20.00000,5.298173e-08,0.82343,4
260.00702,2023.50000,     -1.01540,     -1.16875,50.00000,20.00000,5.292641e-08,0.82343,4
260.01901,2029.20000,     -1.01689,     -1.17044,50.00000,20.00000,5.292445e-08,0.82342,4
260.01413,2034.90000,     -1.01709,     -1.17281,50.00000,20.00000,5.292645e-08,0.82343,4
260.03031,2040.60000,     -1.01732,     -1.17327,50.00000,20.00000,5.294200e-08,0.82341,4
260.04015,2046.30000,     -1.01755,     -1.17689,50.00000,20.00000,5.298546e-08,0.82340,4
260.01592,2052.00000,     -1.01667,     -1.17803,50.00000,20.00000,5.294211e-08,0.82342,4
260.01907,2057.70000,     -1.01750,     -1.17904,50.00000,20.00000,5.296344e-08,0.82342,4
260.01503,2063.40000,     -1.01455,     -1.18098,50.00000,20.00000,5.292265e-08,0.82342,4
260.01306,2069.10000,     -1.01898,     -1.18255,50.00000,20.00000,5.291211e-08,0.82343,4
260.00802,2074.80000,     -1.01772,     -1.18358,50.00000,20.00000,5.290631e-08,0.82343,4
260.04988,2080.50000,     -1.02071,     -1.18493,50.00000,20.00000,5.293975e-08,0.82339,4
260.02700,2086.20000,     -1.01731,     -1.18605,50.00000,20.00000,5.289382e-08,0.82341,4
260.02593,2091.90000,     -1.02067,     -1.19025,50.00000,20.00000,5.290834e-08,0.82342,4
260.02793,2097.60000,     -1.01921,     -1.19159,50.00000,20.00000,5.292205e-08,0.82341,4
260.03098,2103.30000,     -1.02027,     -1.19252,50.00000,20.00000,5.291058e-08,0.82341,4
260.02200,2109.00000,     -1.01879,     -1.19386,50.00000,20.00000,5.289421e-08,0.82342,4
260.02091,2114.70000,     -1.01667,     -1.19567,50.00000,20.00000,5.289616e-08,0.82342,4
260.01093,2120.40000,     -1.01836,     -1.19794,50.00000,20.00000,5.284775e-08,0.82343,4
260.00493,2126.10000,     -1.02087,     -1.19976,50.00000,20.00000,5.283790e-08,0.82343,4
260.02696,2131.80000,     -1.01521,     -1.20110,50.00000,20.00000,5.283361e-08,0.82341,4
260.01596,2137.50000,     -1.01814,     -1.20381,50.00000,20.00000,5.285460e-08,0.82342,4
260.01705,2143.20000,     -1.01836,     -1.20551,50.00000,20.00000,5.282066e-08,0.82342,4
260.02994,2148.90000,     -1.01543,     -1.20472,50.00000,20.00000,5.285887e-08,0.82341,4
260.02597,2154.60000,     -1.01985,     -1.21003,50.00000,20.00000,5.281984e-08,0.82342,4
260.01401,2160.30000,     -1.01626,     -1.21106,50.00000,20.00000,5.283554e-08,0.82343,4
260.02695,2166.00000,     -1.01816,     -1.21276,50.00000,20.00000,5.281459e-08,0.82341,4
260.01908,2171.70000,     -1.02089,     -1.21433,50.00000,20.00000,5.283795e-08,0.82342,4
260.02597,2177.40000,     -1.01877,     -1.21469,50.00000,20.00000,5.281691e-08,0.82342,4
260.01701,2183.10000,     -1.01413,     -1.21819,50.00000,20.00000,5.283912e-08,0.82342,4
260.03206,2188.80000,     -1.01880,     -1.21807,50.00000,20.00000,5.279747e-08,0.82341,4
260.00900,2194.50000,     -1.01624,     -1.22021,50.00000,20.00000,5.281085e-08,0.82343,4
260.03306,2200.20000,     -1.02047,     -1.22349,50.00000,20.00000,5.281656e-08,0.82341,4
259.98402,2205.90000,     -1.00882,     -1.22453,50.00000,20.00000,5.279455e-08,0.82345,4
260.05198,2211.60000,     -1.02324,     -1.22531,50.00000,20.00000,5.282019e-08,0.82339,4
260.02972,2217.30000,     -1.01562,     -1.22623,50.00000,20.00000,5.279908e-08,0.82341,4
260.02493,2223.00000,     -1.01837,     -1.23097,50.00000,20.00000,5.272823e-08,0.82342,4
260.05091,2228.70000,     -1.02093,     -1.23188,50.00000,20.00000,5.278679e-08,0.82339,4
260.02099,2234.40000,     -1.01710,     -1.23279,50.00000,20.00000,5.275055e-08,0.82342,4
260.01784,2240.10000,     -1.02046,     -1.23414,50.00000,20.00000,5.277015e-08,0.82342,4
260.01602,2245.80000,     -1.01773,     -1.23766,50.00000,20.00000,5.270550e-08,0.82342,4
260.01502,2251.50000,     -1.02109,     -1.24013,50.00000,20.00000,5.273868e-08,0.82342,4
260.01706,2257.20000,     -1.01856,     -1.24059,50.00000,20.00000,5.273615e-08,0.82342,4
260.01571,2262.90000,     -1.02005,     -1.24342,50.00000,20.00000,5.270020e-08,0.82342,4
260.03794,2268.60000,     -1.02112,     -1.24488,50.00000,20.00000,5.265720e-08,0.82340,4
260.02103,2274.30000,     -1.01793,     -1.24772,50.00000,20.00000,5.270317e-08,0.82342,4
259.99701,2280.00000,     -1.01726,     -1.24804,50.00000,20.00000,5.268388e-08,0.82344,4
260.01395,2285.70000,     -1.01792,     -1.24851,50.00000,20.00000,5.268907e-08,0.82343,4
260.01698,2291.40000,     -1.02005,     -1.25122,50.00000,20.00000,5.272900e-08,0.82342,4
260.01906,2297.10000,     -1.01710,     -1.25179,50.00000,20.00000,5.272257e-08,0.82342,4
260.02800,2302.80000,     -1.01838,     -1.25416,50.00000,20.00000,5.271502e-08,0.82341,4
260.02207,2308.50000,     -1.01858,     -1.25632,50.00000,20.00000,5.275612e-08,0.82342,4
260.01906,2314.20000,     -1.01540,     -1.25631,50.00000,20.00000,5.271701e-08,0.82342,4
260.00009,2319.90000,     -1.00801,     -1.26038,50.00000,20.00000,5.271673e-08,0.82344,4
260.01401,2325.60000,     -1.01645,     -1.26241,50.00000,20.00000,5.265673e-08,0.82343,4
260.02195,2331.30000,     -1.01773,     -1.26480,50.00000,20.00000,5.260982e-08,0.82342,4
260.02290,2337.00000,     -1.01942,     -1.26672,50.00000,20.00000,5.257939e-08,0.82342,4
260.01103,2342.70000,     -1.02362,     -1.26853,50.00000,20.00000,5.261505e-08,0.82343,4
260.03806,2348.40000,     -1.02070,     -1.27010,50.00000,20.00000,5.259538e-08,0.82340,4
260.01397,2354.10000,     -1.01836,     -1.26977,50.00000,20.00000,5.264078e-08,0.82343,4
260.01005,2359.80000,     -1.01834,     -1.27283,50.00000,20.00000,5.259825e-08,0.82343,4
260.01896,2365.50000,     -1.01963,     -1.27419,50.00000,20.00000,5.259888e-08,0.82342,4
260.02802,2371.20000,     -1.02154,     -1.27669,50.00000,20.00000,5.259036e-08,0.82341,4
260.01599,2376.90000,     -1.02046,     -1.27939,50.00000,20.00000,5.256805e-08,0.82342,4
260.02096,2382.60000,     -1.01900,     -1.27905,50.00000,20.00000,5.264685e-08,0.82342,4
260.01103,2388.30000,     -1.01836,     -1.28087,50.00000,20.00000,5.263072e-08,0.82343,4
260.03595,2394.00000,     -1.02661,     -1.28268,50.00000,20.00000,5.266233e-08,0.82341,4
260.00705,2399.70000,     -1.01834,     -1.28403,50.00000,20.00000,5.267104e-08,0.82343,4
260.02502,2405.40000,     -1.01752,     -1.28639,50.00000,20.00000,5.260563e-08,0.82342,4
259.99305,2411.10000,     -1.01622,     -1.28799,50.00000,20.00000,5.261782e-08,0.82344,4
260.00501,2416.80000,     -1.02046,     -1.28935,50.00000,20.00000,5.263774e-08,0.82343,4
260.01103,2422.50000,     -1.01709,     -1.29071,50.00000,20.00000,5.260496e-08,0.82343,4
260.00402,2428.20000,     -1.01750,     -1.29273,50.00000,20.00000,5.261444e-08,0.82343,4
260.00894,2433.90000,     -1.01814,     -1.29614,50.00000,20.00000,5.260954e-08,0.82343,4
260.01392,2439.60000,     -1.01815,     -1.29680,50.00000,20.00000,5.260508e-08,0.82343,4
260.01196,2445.30000,     -1.01687,     -1.30055,50.00000,20.00000,5.262188e-08,0.82343,4
260.02204,2451.00000,     -1.01668,     -1.30291,50.00000,20.00000,5.254405e-08,0.82342,4
260.02794,2456.70000,     -1.01879,     -1.30259,50.00000,20.00000,5.254099e-08,0.82341,4
260.01792,2462.40000,     -1.01687,     -1.30417,50.00000,20.00000,5.258811e-08,0.82342,4
260.02992,2468.10000,     -1.01372,     -1.30609,50.00000,20.00000,5.255062e-08,0.82341,4
260.03196,2473.80000,     -1.01457,     -1.30767,50.00000,20.00000,5.257831e-08,0.82341,4
260.02092,2479.50000,     -1.01646,     -1.30767,50.00000,20.00000,5.259186e-08,0.82342,4
260.01303,2485.20000,     -1.01602,     -1.30800,50.00000,20.00000,5.261713e-08,0.82343,4
260.01605,2490.90000,     -1.01667,     -1.31209,50.00000,20.00000,5.262966e-08,0.82342,4
260.03493,2496.60000,     -1.02596,     -1.31242,50.00000,20.00000,5.261414e-08,0.82341,4
260.02596,2502.30000,     -1.01732,     -1.31412,50.00000,20.00000,5.255150e-08,0.82342,4
260.02602,2508.00000,     -1.01943,     -1.31548,50.00000,20.00000,5.252382e-08,0.82342,4
260.01307,2513.70000,     -1.01730,     -1.31842,50.00000,20.00000,5.256355e-08,0.82343,4
260.01698,2519.40000,     -1.01477,     -1.32147,50.00000,20.00000,5.249203e-08,0.82342,4
260.00695,2525.10000,     -1.01582,     -1.32124,50.00000,20.00000,5.254375e-08,0.82343,4
260.01699,2530.80000,     -1.01729,     -1.32148,50.00000,20.00000,5.255609e-08,0.82342,4
260.00804,2536.50000,     -1.01602,     -1.32318,50.00000,20.00000,5.253434e-08,0.82343,4
260.01703,2542.20000,     -1.01710,     -1.32645,50.00000,20.00000,5.252392e-08,0.82342,4
260.02201,2547.90000,     -1.01541,     -1.32826,50.00000,20.00000,5.250580e-08,0.82342,4
260.00510,2553.60000,     -1.01687,     -1.32792,50.00000,20.00000,5.250293e-08,0.82343,4
260.02307,2559.30000,     -1.01520,     -1.33098,50.00000,20.00000,5.252364e-08,0.82342,4
259.95182,2565.00000,     -1.01131,     -1.33233,50.00000,20.00000,5.254319e-08,0.82348,4
259.99301,2570.70000,     -1.01263,     -1.33550,50.00000,20.00000,5.257655e-08,0.82344,4
260.01602,2576.40000,     -1.01520,     -1.33674,50.00000,20.00000,5.255374e-08,0.82342,4
260.02901,2582.10000,     -1.01395,     -1.33979,50.00000,20.00000,5.250880e-08,0.82341,4
260.00894,2587.80000,     -1.01688,     -1.34048,50.00000,20.00000,5.250460e-08,0.82343,4
260.01011,2593.50000,     -1.01624,     -1.34488,50.00000,20.00000,5.249173e-08,0.82343,4
260.01901,2599.20000,     -1.01287,     -1.34558,50.00000,20.00000,5.245220e-08,0.82342,4
260.00899,2604.90000,     -1.01412,     -1.34693,50.00000,20.00000,5.243710e-08,0.82343,4
260.01002,2610.60000,     -1.01414,     -1.34783,50.00000,20.00000,5.242953e-08,0.82343,4
260.01808,2616.30000,     -1.01457,     -1.35022,50.00000,20.00000,5.238797e-08,0.82342,4
260.01798,2622.00000,     -1.01814,     -1.35316,50.00000,20.00000,5.242440e-08,0.82342,4
260.00495,2627.70000,     -1.01856,     -1.35372,50.00000,20.00000,5.242975e-08,0.82343,4
260.01499,2633.40000,     -1.01667,     -1.35643,50.00000,20.00000,5.240847e-08,0.82342,4
260.01598,2639.10000,     -1.01772,     -1.35938,50.00000,20.00000,5.239495e-08,0.82342,4
260.02105,2644.80000,     -1.01542,     -1.35745,50.00000,20.00000,5.240885e-08,0.82342,4
260.02296,2650.50000,     -1.01646,     -1.36028,50.00000,20.00000,5.238827e-08,0.82342,4
260.01998,2656.20000,     -1.01498,     -1.36299,50.00000,20.00000,5.236931e-08,0.82342,4
260.13600,2661.90000,     -1.01511,     -1.36333,50.00000,20.00000,5.235020e-08,0.82332,4
260.00699,2667.60000,     -1.01582,     -1.36684,50.00000,20.00000,5.232986e-08,0.82343,4
260.02497,2673.30000,     -1.01668,     -1.36944,50.00000,20.00000,5.236850e-08,0.82342,4
260.01006,2679.00000,     -1.01835,     -1.36842,50.00000,20.00000,5.235756e-08,0.82343,4
260.00906,2684.70000,     -1.01266,     -1.37046,50.00000,20.00000,5.236696e-08,0.82343,4
260.00390,2690.40000,     -1.01708,     -1.37418,50.00000,20.00000,5.235585e-08,0.82343,4
260.02806,2696.10000,     -1.01584,     -1.37578,50.00000,20.00000,5.235206e-08,0.82341,4
260.01300,2701.80000,     -1.01455,     -1.37713,50.00000,20.00000,5.236179e-08,0.82343,4
260.00896,2707.50000,     -1.01350,     -1.38053,50.00000,20.00000,5.234296e-08,0.82343,4
260.00693,2713.20000,     -1.01413,     -1.38257,50.00000,20.00000,5.232598e-08,0.82343,4
260.01802,2718.90000,     -1.01604,     -1.38358,50.00000,20.00000,5.227239e-08,0.82342,4
260.01295,2724.60000,     -1.01814,     -1.38620,50.00000,20.00000,5.230214e-08,0.82343,4
260.03098,2730.30000,     -1.01458,     -1.38822,50.00000,20.00000,5.225682e-08,0.82341,4
260.01897,2736.00000,     -1.01182,     -1.39095,50.00000,20.00000,5.226814e-08,0.82342,4
260.01298,2741.70000,     -1.01307,     -1.39242,50.00000,20.00000,5.223523e-08,0.82343,4
260.00505,2747.40000,     -1.01538,     -1.39365,50.00000,20.00000,5.226459e-08,0.82343,4
260.02304,2753.10000,     -1.01562,     -1.39535,50.00000,20.00000,5.229265e-08,0.82342,4
260.01697,2758.80000,     -1.01667,     -1.39626,50.00000,20.00000,5.227623e-08,0.82342,4
260.01409,2764.50000,     -1.01561,     -1.39897,50.00000,20.00000,5.227985e-08,0.82343,4
260.00798,2770.20000,     -1.01433,     -1.39941,50.00000,20.00000,5.227997e-08,0.82343,4
260.01908,2775.90000,     -1.00803,     -1.40020,50.00000,20.00000,5.223620e-08,0.82342,4
260.02712,2781.60000,     -1.01225,     -1.40338,50.00000,20.00000,5.223825e-08,0.82341,4
260.03094,2787.30000,     -1.01478,     -1.40542,50.00000,20.00000,5.225251e-08,0.82341,4
260.00899,2793.00000,     -1.01159,     -1.40779,50.00000,20.00000,5.225115e-08,0.82343,4
260.00404,2798.70000,     -1.01159,     -1.40881,50.00000,20.00000,5.224916e-08,0.82343,4
260.01596,2804.40000,     -1.01014,     -1.40938,50.00000,20.00000,5.232243e-08,0.82342,4
260.01594,2810.10000,     -1.01118,     -1.41118,50.00000,20.00000,5.225174e-08,0.82342,4
260.01696,2815.80000,     -1.01182,     -1.41436,50.00000,20.00000,5.222678e-08,0.82342,4
260.00812,2821.50000,     -1.01033,     -1.41503,50.00000,20.00000,5.227733e-08,0.82343,4
260.02405,2827.20000,     -1.01309,     -1.41899,50.00000,20.00000,5.221832e-08,0.82342,4
260.01901,2832.90000,     -1.01117,     -1.41934,50.00000,20.00000,5.221046e-08,0.82342,4
260.00901,2838.60000,     -1.01329,     -1.42205,50.00000,20.00000,5.218511e-08,0.82343,4
259.99895,2844.30000,     -1.00990,     -1.42318,50.00000,20.00000,5.217137e-08,0.82344,4
260.02192,2850.00000,     -1.01350,     -1.42589,50.00000,20.00000,5.214080e-08,0.82342,4
260.01146,2855.70000,     -1.01728,     -1.42736,50.00000,20.00000,5.213454e-08,0.82343,4
260.01506,2861.40000,     -1.01392,     -1.42838,50.00000,20.00000,5.214987e-08,0.82342,4
260.03096,2867.10000,     -1.01034,     -1.42872,50.00000,20.00000,5.220037e-08,0.82341,4
260.02295,2872.80000,     -1.01182,     -1.43009,50.00000,20.00000,5.219155e-08,0.82342,4
260.02396,2878.50000,     -1.01351,     -1.43121,50.00000,20.00000,5.217509e-08,0.82342,4
260.01296,2884.20000,     -1.00991,     -1.43336,50.00000,20.00000,5.218532e-08,0.82343,4
260.00899,2889.90000,     -1.01140,     -1.43494,50.00000,20.00000,5.217552e-08,0.82343,4
260.02700,2895.60000,     -1.01055,     -1.43630,50.00000,20.00000,5.219330e-08,0.82341,4
260.01402,2901.30000,     -1.00948,     -1.43902,50.00000,20.00000,5.217115e-08,0.82343,4
260.01491,2907.00000,     -1.00948,     -1.44104,50.00000,20.00000,5.220919e-08,0.82342,4
260.02102,2912.70000,     -1.00992,     -1.44275,50.00000,20.00000,5.219205e-08,0.82342,4
260.02689,2918.40000,     -1.01330,     -1.44525,50.00000,20.00000,5.215911e-08,0.82341,4
260.03408,2924.10000,     -1.01247,     -1.44774,50.00000,20.00000,5.214981e-08,0.82341,4
260.00600,2929.80000,     -1.00990,     -1.44885,50.00000,20.00000,5.217931e-08,0.82343,4
260.01007,2935.50000,     -1.01329,     -1.45113,50.00000,20.00000,5.214696e-08,0.82343,4
260.01596,2941.20000,     -1.01371,     -1.45248,50.00000,20.00000,5.216648e-08,0.82342,4
260.00604,2946.90000,     -1.01159,     -1.45338,50.00000,20.00000,5.215119e-08,0.82343,4
260.00891,2952.60000,     -1.01413,     -1.45464,50.00000,20.00000,5.213896e-08,0.82343,4
260.01604,2958.30000,     -1.01224,     -1.45656,50.00000,20.00000,5.213231e-08,0.82342,4
260.02313,2964.00000,     -1.01646,     -1.45949,50.00000,20.00000,5.215094e-08,0.82342,4
260.02200,2969.70000,     -1.01540,     -1.46052,50.00000,20.00000,5.210160e-08,0.82342,4
260.00203,2975.40000,     -1.01559,     -1.46210,50.00000,20.00000,5.215811e-08,0.82344,4
260.01399,2981.10000,     -1.01645,     -1.46276,50.00000,20.00000,5.212335e-08,0.82343,4
260.01506,2986.80000,     -1.01286,     -1.46493,50.00000,20.00000,5.215895e-08,0.82342,4
260.01601,2992.50000,     -1.02026,     -1.46652,50.00000,20.00000,5.210418e-08,0.82342,4
260.02102,2998.20000,     -1.01666,     -1.46832,50.00000,20.00000,5.209583e-08,0.82342,4
260.01299,3003.90000,     -1.01371,     -1.46922,50.00000,20.00000,5.204784e-08,0.82343,4
260.02302,3009.60000,     -1.01562,     -1.47181,50.00000,20.00000,5.203733e-08,0.82342,4
260.00604,3015.30000,     -1.01370,     -1.47318,50.00000,20.00000,5.203612e-08,0.82343,4
260.01005,3021.00000,     -1.01391,     -1.47636,50.00000,20.00000,5.202870e-08,0.82343,4
260.01892,3026.70000,     -1.01625,     -1.47431,50.00000,20.00000,5.211069e-08,0.82342,4
260.01808,3032.40000,     -1.01225,     -1.47669,50.00000,20.00000,5.209268e-08,0.82342,4
260.01309,3038.10000,     -1.01562,     -1.47759,50.00000,20.00000,5.208465e-08,0.82343,4
260.01699,3043.80000,     -1.01266,     -1.47985,50.00000,20.00000,5.209490e-08,0.82342,4
260.01810,3049.50000,     -1.01350,     -1.48020,50.00000,20.00000,5.209177e-08,0.82342,4
260.03005,3055.20000,     -1.01035,     -1.48270,50.00000,20.00000,5.208403e-08,0.82341,4
260.02904,3060.90000,     -1.01519,     -1.48505,50.00000,20.00000,5.211143e-08,0.82341,4
260.01301,3066.60000,     -1.01603,     -1.48643,50.00000,20.00000,5.207272e-08,0.82343,4
260.21052,3072.30000,     -0.84324,     -1.48494,50.00000,20.00000,5.203954e-08,0.82325,5
312.73419,3078.00000,      4.28921,     -1.37012,50.00000,20.00000,5.218533e-08,0.77526,5
373.52813,3083.70000,      3.49179,     -1.62602,50.00000,20.00000,5.313846e-08,0.71742,5
431.03032,3089.40000,      3.15739,     -3.93848,50.00000,20.00000,5.479521e-08,0.66429,5
487.93234,3095.10000, 9.305066e-02,     -4.42928,50.00000,20.00000,5.683994e-08,0.61599,5
544.70032,3100.80000,     -2.10776,     -4.39137,50.00000,20.00000,5.830244e-08,0.57355,5
601.64149,3106.50000,     -4.48795,     -4.36848,50.00000,20.00000,5.939743e-08,0.53714,5
658.70335,3112.20000,     -6.82162,     -4.35212,50.00000,20.00000,6.046011e-08,0.50626,5
715.81736,3117.90000,     -9.16955,     -4.34131,50.00000,20.00000,6.127734e-08,0.47969,5
772.98938,3123.60000,    -11.78957,     -4.33072,50.00000,20.00000,6.200524e-08,0.45576,5
794.03442,3125.70000,    -12.87385,     -4.32835,50.00000,20.00000,6.204692e-08,0.44728,5