File: data/TGA/005c/ExpDat_2024_06_18_005c-B_350C_isotherm.csv
#EXPORTTYPE:                 ,DATA ALL
#FILE:                       ,2024_06_18_005c-B_350C_isotherm.ngb-ss5
#FORMAT:                     ,NETZSCH5
#FTYPE:                      ,ASCII
#IDENTITY:                   ,PS-SCF3
#DECIMAL:                    ,POINT
#SEPARATOR:                  ,COMMA
#MTYPE:                      ,DSC
#INSTRUMENT:                 ,NETZSCH STA 449F5
#PROJECT:                    ,
#DATE/TIME:                  ,6/18/2024 4:48:32 PM (UTC-4)
#CORR. FILE:                 ,
#TEMPCAL:                    ,28-06-2023 13:26
#SENSITIVITY:                ,28-06-2023 13:53
#LABORATORY:                 ,
#OPERATOR:                   ,Stanley
#REMARK:                     ,
#SAMPLE:                     ,005c-B_PS_6_1K-SCF3
#SAMPLE MASS /mg:            ,5.02
#MATERIAL:                   ,
#REFERENCE:                  ,
#REFERENCE MASS /mg:         ,0
#TYPE OF CRUCIBLE:           ,Al2O3 85 ‘l, open
#SAMPLE CRUCIBLE MASS /mg:   ,0
#REFERENCE CRUCIBLE MASS /mg:,0
#DSC RANGE /‘V:              ,5000
#TG RANGE /mg:               ,35000
#TAU-R:                      ,---
#CORR. CODE:                 ,000
#EXO:                        ,-1
#RANGE:                      ,30›C....800›C/0.0....10.0K/min
#SEGMENT:                    ,S1-5/5
#SEG. 1:                     ,30›C/10.0(K/min)/100›C
#SEG. 2:                     ,100›C/00:10/100›C
#SEG. 3:                     ,100›C/10.0(K/min)/350›C
#SEG. 4:                     ,350›C/04:00/350›C
#SEG. 5:                     ,350›C/10.0(K/min)/800›C

##Temp./›C,Time/min,DSC/(mW/mg),Mass loss/mg,Gas Flow(purge2)/(ml/min),Gas Flow(protective)/(ml/min),TIC(scan:1)/A,Sensit./(uV/mW),Segment
 33.34600,  0.00000,-6.413788e-02, 0.000000e+00,50.00000,20.00000,7.409280e-08,0.92414,1
 33.48900,  0.60000,-8.551502e-03, 4.530000e-03,50.00000,20.00000,7.374404e-08,0.92416,1
 34.54300,  1.20000,      0.22986, 5.261000e-02,50.00000,20.00000,7.347306e-08,0.92433,1
 36.62500,  1.80000,      0.54964,      0.10239,50.00000,20.00000,7.322016e-08,0.92464,1
 39.55200,  2.40000,      0.83578,      0.14628,50.00000,20.00000,7.282274e-08,0.92503,1
 43.15500,  3.00000,      1.09326,      0.18214,50.00000,20.00000,7.262615e-08,0.92543,1
 47.45000,  3.60000,      1.37075,      0.22151,50.00000,20.00000,7.239640e-08,0.92579,1
 52.53000,  4.20000,      1.68329,      0.25964,50.00000,20.00000,7.213852e-08,0.92608,1
 58.33900,  4.80000,      2.00058,      0.29211,50.00000,20.00000,7.184573e-08,0.92620,1
 64.75000,  5.40000,      2.28933,      0.32276,50.00000,20.00000,7.161300e-08,0.92609,1
 71.58500,  6.00000,      2.54183,      0.34562,50.00000,20.00000,7.142672e-08,0.92569,1
 78.74200,  6.60000,      2.76745,      0.36394,50.00000,20.00000,7.106102e-08,0.92497,1
 86.13075,  7.20000,      2.94452,      0.37763,50.00000,20.00000,7.106742e-08,0.92390,2
 92.66790,  7.80000,      2.64610,      0.36380,50.00000,20.00000,7.069378e-08,0.92268,2
 97.63516,  8.40000,      2.09023,      0.32838,50.00000,20.00000,7.055150e-08,0.92160,2
101.23718,  9.00000,      1.57097,      0.29353,50.00000,20.00000,7.037074e-08,0.92072,2
104.00241,  9.60000,      1.21313,      0.26835,50.00000,20.00000,7.023460e-08,0.91999,2
106.26808, 10.20000,      0.97594,      0.25434,50.00000,20.00000,6.986324e-08,0.91937,2
108.00848, 10.80000,      0.75938,      0.23426,50.00000,20.00000,6.989978e-08,0.91887,2
109.19614, 11.40000,      0.53080,      0.21488,50.00000,20.00000,6.960793e-08,0.91852,2
109.89530, 12.00000,      0.31650,      0.19489,50.00000,20.00000,6.945785e-08,0.91831,2
110.17885, 12.60000,      0.14107,      0.17736,50.00000,20.00000,6.937852e-08,0.91823,2
110.27390, 13.20000, 6.954716e-03,      0.16122,50.00000,20.00000,6.901735e-08,0.91820,2
109.88017, 13.80000,-9.710258e-02,      0.14826,50.00000,20.00000,6.885855e-08,0.91832,2
109.42502, 14.40000,     -0.17555,      0.13441,50.00000,20.00000,6.876436e-08,0.91845,2
108.84034, 15.00000,     -0.23568,      0.12339,50.00000,20.00000,6.844758e-08,0.91863,2
108.18139, 15.60000,     -0.27664,      0.11118,50.00000,20.00000,6.827533e-08,0.91882,2
107.44450, 16.20000,     -0.30183,      0.10306,50.00000,20.00000,6.809626e-08,0.91903,2
106.68998, 16.80000,     -0.31346, 9.488379e-02,50.00000,20.00000,6.794880e-08,0.91925,2
106.06031, 17.40000,     -0.25376, 9.162713e-02,50.00000,20.00000,6.750061e-08,0.91943,3
106.66664, 18.00000,      0.23930,      0.13171,50.00000,20.00000,6.743047e-08,0.91926,3
108.88959, 18.60000,      0.92953,      0.18016,50.00000,20.00000,6.711898e-08,0.91861,3
112.12562, 19.20000,      1.43788,      0.21692,50.00000,20.00000,6.701774e-08,0.91762,3
115.97320, 19.80000,      1.79185,      0.24154,50.00000,20.00000,6.679403e-08,0.91638,3
120.50533, 20.40000,      2.16217,      0.26552,50.00000,20.00000,6.651803e-08,0.91480,3
125.80820, 21.00000,      2.58687,      0.29198,50.00000,20.00000,6.618347e-08,0.91282,3
131.81316, 21.60000,      3.00118,      0.31392,50.00000,20.00000,6.617130e-08,0.91041,3
138.32165, 22.20000,      3.34670,      0.33135,50.00000,20.00000,6.585627e-08,0.90759,3
145.15876, 22.80000,      3.62676,      0.34482,50.00000,20.00000,6.567178e-08,0.90440,3
152.22609, 23.40000,      3.85146,      0.35601,50.00000,20.00000,6.558696e-08,0.90087,3
159.41347, 24.00000,      4.03179,      0.36417,50.00000,20.00000,6.547389e-08,0.89704,3
166.65567, 24.60000,      4.16189,      0.37096,50.00000,20.00000,6.530904e-08,0.89295,3
173.87160, 25.20000,      4.24412,      0.37503,50.00000,20.00000,6.507153e-08,0.88865,3
181.03391, 25.80000,      4.27692,      0.37910,50.00000,20.00000,6.522703e-08,0.88418,3
188.13324, 26.40000,      4.26363,      0.38182,50.00000,20.00000,6.505822e-08,0.87954,3
195.11736, 27.00000,      4.22251,      0.38453,50.00000,20.00000,6.500068e-08,0.87479,3
201.98058, 27.60000,      4.17937,      0.38453,50.00000,20.00000,6.479397e-08,0.86996,3
208.71816, 28.20000,      4.12377,      0.38453,50.00000,20.00000,6.470273e-08,0.86505,3
215.32611, 28.80000,      4.07476,      0.38521,50.00000,20.00000,6.470484e-08,0.86010,3
221.82995, 29.40000,      4.02881,      0.38487,50.00000,20.00000,6.464383e-08,0.85509,3
228.21497, 30.00000,      3.98316,      0.38487,50.00000,20.00000,6.464198e-08,0.85006,3
234.52271, 30.60000,      3.94886,      0.38490,50.00000,20.00000,6.469021e-08,0.84497,3
240.74373, 31.20000,      3.92006,      0.38521,50.00000,20.00000,6.457743e-08,0.83985,3
246.90876, 31.80000,      3.88864,      0.38759,50.00000,20.00000,6.447383e-08,0.83469,3
253.03865, 32.40000,      3.86201,      0.38759,50.00000,20.00000,6.456873e-08,0.82947,3
259.11212, 33.00000,      3.84215,      0.40822,50.00000,20.00000,6.461426e-08,0.82421,3
265.15477, 33.60000,      3.82066,      0.38702,50.00000,20.00000,6.465792e-08,0.81891,3
271.17891, 34.20000,      3.80822,      0.37620,50.00000,20.00000,6.462429e-08,0.81356,3
277.18591, 34.80000,      3.79489,      0.38759,50.00000,20.00000,6.464141e-08,0.80817,3
283.15347, 35.40000,      3.77425,      0.38487,50.00000,20.00000,6.462127e-08,0.80275,3
289.11134, 36.00000,      3.75557,      0.38057,50.00000,20.00000,6.473689e-08,0.79729,3
295.06085, 36.60000,      3.73895,      0.37650,50.00000,20.00000,6.470148e-08,0.79180,3
300.99360, 37.20000,      3.71826,      0.36949,50.00000,20.00000,6.483224e-08,0.78628,3
306.92436, 37.80000,      3.70196,      0.36236,50.00000,20.00000,6.480480e-08,0.78073,3
312.85921, 38.40000,      3.68361,      0.35139,50.00000,20.00000,6.485192e-08,0.77514,3
318.76791, 39.00000,      3.66007,      0.33589,50.00000,20.00000,6.489169e-08,0.76956,3
324.70834, 39.60000,      3.64231,      0.31518,50.00000,20.00000,6.497880e-08,0.76393,3
330.63448, 40.20000,      3.62720,      0.29239,50.00000,20.00000,6.489050e-08,0.75829,3
336.54894, 40.80000,      3.60717,      0.25856,50.00000,20.00000,6.514568e-08,0.75265,3
342.48408, 41.40000,      3.58745,      0.21750,50.00000,20.00000,6.509935e-08,0.74699,3
348.40393, 42.00000,      3.57569,      0.16358,50.00000,20.00000,6.527714e-08,0.74134,4
352.34332, 42.60000,      2.05315, 8.706336e-02,50.00000,20.00000,6.518485e-08,0.73758,4
353.09364, 43.20000,     -0.10662,-7.931932e-03,50.00000,20.00000,6.534663e-08,0.73686,4
353.55633, 43.80000,     -0.57670,-9.721044e-02,50.00000,20.00000,6.529006e-08,0.73642,4
354.30802, 44.40000,     -0.53290,     -0.18197,50.00000,20.00000,6.547778e-08,0.73570,4
354.65097, 45.00000,     -0.82532,     -0.27087,50.00000,20.00000,6.555897e-08,0.73537,4
354.56367, 45.60000,     -1.17378,     -0.35989,50.00000,20.00000,6.564860e-08,0.73546,4
354.30402, 46.20000,     -1.33184,     -0.44713,50.00000,20.00000,6.576260e-08,0.73571,4
354.04597, 46.80000,     -1.43845,     -0.53354,50.00000,20.00000,6.577896e-08,0.73595,4
353.74060, 47.40000,     -1.51419,     -0.61579,50.00000,20.00000,6.589971e-08,0.73624,4
353.40043, 48.00000,     -1.56844,     -0.68828,50.00000,20.00000,6.598994e-08,0.73657,4
353.06579, 48.60000,     -1.59211,     -0.78012,50.00000,20.00000,6.612570e-08,0.73689,4
352.75323, 49.20000,     -1.60062,     -0.84514,50.00000,20.00000,6.609873e-08,0.73718,4
352.46444, 49.80000,     -1.61036,     -0.91992,50.00000,20.00000,6.611079e-08,0.73746,4
352.18082, 50.40000,     -1.61528,     -0.98891,50.00000,20.00000,6.624851e-08,0.73773,4
351.92182, 51.00000,     -1.61274,     -1.05834,50.00000,20.00000,6.630413e-08,0.73798,4
351.70801, 51.60000,     -1.60654,     -1.12376,50.00000,20.00000,6.641425e-08,0.73818,4
351.49992, 52.20000,     -1.60192,     -1.18881,50.00000,20.00000,6.645778e-08,0.73838,4
351.32695, 52.80000,     -1.59274,     -1.25273,50.00000,20.00000,6.646233e-08,0.73855,4
351.15815, 53.40000,     -1.58906,     -1.31443,50.00000,20.00000,6.640012e-08,0.73871,4
351.02037, 54.00000,     -1.58386,     -1.37312,50.00000,20.00000,6.654717e-08,0.73884,4
350.91557, 54.60000,     -1.57911,     -1.43183,50.00000,20.00000,6.655128e-08,0.73894,4
350.79947, 55.20000,     -1.57501,     -1.48708,50.00000,20.00000,6.651853e-08,0.73905,4
350.72061, 55.80000,     -1.56762,     -1.54250,50.00000,20.00000,6.672281e-08,0.73912,4
350.63211, 56.40000,     -1.56888,     -1.59762,50.00000,20.00000,6.661025e-08,0.73921,4
350.56263, 57.00000,     -1.57085,     -1.65078,50.00000,20.00000,6.670293e-08,0.73928,4
350.49803, 57.60000,     -1.56968,     -1.70504,50.00000,20.00000,6.673760e-08,0.73934,4
350.44838, 58.20000,     -1.56930,     -1.75604,50.00000,20.00000,6.669401e-08,0.73938,4
350.39657, 58.80000,     -1.57194,     -1.80181,50.00000,20.00000,6.664073e-08,0.73943,4
350.34137, 59.40000,     -1.57391,     -1.86105,50.00000,20.00000,6.667844e-08,0.73949,4
350.29009, 60.00000,     -1.57265,     -1.90410,50.00000,20.00000,6.670932e-08,0.73954,4
350.26577, 60.60000,     -1.57391,     -1.94696,50.00000,20.00000,6.659419e-08,0.73956,4
350.22677, 61.20000,     -1.57568,     -1.99565,50.00000,20.00000,6.666164e-08,0.73960,4
350.19808, 61.80000,     -1.57604,     -2.04162,50.00000,20.00000,6.667584e-08,0.73962,4
350.15857, 62.40000,     -1.56775,     -2.08571,50.00000,20.00000,6.681305e-08,0.73966,4
350.15753, 63.00000,     -1.56693,     -2.12923,50.00000,20.00000,6.675974e-08,0.73966,4
350.14158, 63.60000,     -1.57455,     -2.17289,50.00000,20.00000,6.678972e-08,0.73968,4
350.11857, 64.20000,     -1.57548,     -2.21383,50.00000,20.00000,6.679701e-08,0.73970,4
350.08932, 64.80000,     -1.57506,     -2.25450,50.00000,20.00000,6.670562e-08,0.73973,4
350.08440, 65.40000,     -1.57005,     -2.29584,50.00000,20.00000,6.681142e-08,0.73973,4
350.08407, 66.00000,     -1.57033,     -2.33350,50.00000,20.00000,6.669551e-08,0.73973,4
350.08028, 66.60000,     -1.57291,     -2.37156,50.00000,20.00000,6.680019e-08,0.73974,4
350.06012, 67.20000,     -1.57389,     -2.40751,50.00000,20.00000,6.688341e-08,0.73976,4
350.06117, 67.80000,     -1.57458,     -2.44538,50.00000,20.00000,6.698164e-08,0.73975,4
350.06410, 68.40000,     -1.57543,     -2.48218,50.00000,20.00000,6.691679e-08,0.73975,4
350.04877, 69.00000,     -1.57411,     -2.51532,50.00000,20.00000,6.691243e-08,0.73977,4
350.04607, 69.60000,     -1.57863,     -2.54824,50.00000,20.00000,6.701336e-08,0.73977,4
350.03131, 70.20000,     -1.57674,     -2.58599,50.00000,20.00000,6.704512e-08,0.73978,4
350.03443, 70.80000,     -1.57094,     -2.61913,50.00000,20.00000,6.705297e-08,0.73978,4
350.04548, 71.40000,     -1.57064,     -2.64876,50.00000,20.00000,6.709284e-08,0.73977,4
350.04264, 72.00000,     -1.57130,     -2.68183,50.00000,20.00000,6.705451e-08,0.73977,4
350.04780, 72.60000,     -1.57096,     -2.71161,50.00000,20.00000,6.704069e-08,0.73977,4
350.04258, 73.20000,     -1.57353,     -2.74379,50.00000,20.00000,6.697618e-08,0.73977,4
350.04367, 73.80000,     -1.57859,     -2.77292,50.00000,20.00000,6.704914e-08,0.73977,4
350.04448, 74.40000,     -1.58262,     -2.80231,50.00000,20.00000,6.711235e-08,0.73977,4
350.03811, 75.00000,     -1.58232,     -2.83006,50.00000,20.00000,6.708991e-08,0.73978,4
350.02949, 75.60000,     -1.58288,     -2.85768,50.00000,20.00000,6.713810e-08,0.73978,4
350.01817, 76.20000,     -1.58299,     -2.88470,50.00000,20.00000,6.721246e-08,0.73980,4
350.01743, 76.80000,     -1.58128,     -2.91240,50.00000,20.00000,6.710415e-08,0.73980,4
350.02811, 77.40000,     -1.57655,     -2.93809,50.00000,20.00000,6.707163e-08,0.73979,4
350.04423, 78.00000,     -1.57382,     -2.96394,50.00000,20.00000,6.723608e-08,0.73977,4
350.05506, 78.60000,     -1.57882,     -2.98901,50.00000,20.00000,6.728165e-08,0.73976,4
350.05276, 79.20000,     -1.58322,     -3.01314,50.00000,20.00000,6.716576e-08,0.73976,4
350.05136, 79.80000,     -1.58519,     -3.03850,50.00000,20.00000,6.721167e-08,0.73976,4
350.05098, 80.40000,     -1.58827,     -3.06243,50.00000,20.00000,6.723804e-08,0.73976,4
350.04072, 81.00000,     -1.58802,     -3.08593,50.00000,20.00000,6.722803e-08,0.73977,4
350.04580, 81.60000,     -1.58964,     -3.10960,50.00000,20.00000,6.708510e-08,0.73977,4
350.05970, 82.20000,     -1.59203,     -3.13178,50.00000,20.00000,6.715597e-08,0.73976,4
350.05289, 82.80000,     -1.59279,     -3.15394,50.00000,20.00000,6.721151e-08,0.73976,4
350.04702, 83.40000,     -1.59408,     -3.17488,50.00000,20.00000,6.721879e-08,0.73977,4
350.04834, 84.00000,     -1.59711,     -3.19536,50.00000,20.00000,6.704838e-08,0.73977,4
350.04788, 84.60000,     -1.59669,     -3.21808,50.00000,20.00000,6.718923e-08,0.73977,4
350.04243, 85.20000,     -1.59793,     -3.23767,50.00000,20.00000,6.705223e-08,0.73977,4
350.03520, 85.80000,     -1.60033,     -3.25744,50.00000,20.00000,6.717628e-08,0.73978,4
350.03779, 86.40000,     -1.60089,     -3.27749,50.00000,20.00000,6.716672e-08,0.73978,4
350.04001, 87.00000,     -1.60094,     -3.29772,50.00000,20.00000,6.699156e-08,0.73977,4
350.03343, 87.60000,     -1.60118,     -3.31567,50.00000,20.00000,6.710245e-08,0.73978,4
350.04962, 88.20000,     -1.60187,     -3.33573,50.00000,20.00000,6.705063e-08,0.73977,4
350.04770, 88.80000,     -1.60702,     -3.35440,50.00000,20.00000,6.703399e-08,0.73977,4
350.04026, 89.40000,     -1.60557,     -3.37054,50.00000,20.00000,6.705382e-08,0.73977,4
350.04389, 90.00000,     -1.60964,     -3.38902,50.00000,20.00000,6.696627e-08,0.73977,4
350.03633, 90.60000,     -1.61101,     -3.40612,50.00000,20.00000,6.715595e-08,0.73978,4
350.03586, 91.20000,     -1.61287,     -3.42407,50.00000,20.00000,6.699742e-08,0.73978,4
350.03341, 91.80000,     -1.61208,     -3.43972,50.00000,20.00000,6.714833e-08,0.73978,4
350.03172, 92.40000,     -1.61077,     -3.45669,50.00000,20.00000,6.713894e-08,0.73978,4
350.03966, 93.00000,     -1.61089,     -3.47253,50.00000,20.00000,6.713581e-08,0.73977,4
350.03863, 93.60000,     -1.61166,     -3.48824,50.00000,20.00000,6.706185e-08,0.73978,4
350.04089, 94.20000,     -1.61359,     -3.50511,50.00000,20.00000,6.710341e-08,0.73977,4
350.03536, 94.80000,     -1.61722,     -3.51897,50.00000,20.00000,6.706011e-08,0.73978,4
350.03236, 95.40000,     -1.61617,     -3.53588,50.00000,20.00000,6.700978e-08,0.73978,4
350.03484, 96.00000,     -1.61325,     -3.55002,50.00000,20.00000,6.715388e-08,0.73978,4
350.03178, 96.60000,     -1.61667,     -3.56456,50.00000,20.00000,6.706337e-08,0.73978,4
350.02788, 97.20000,     -1.61886,     -3.57840,50.00000,20.00000,6.704186e-08,0.73979,4
350.03253, 97.80000,     -1.61766,     -3.59369,50.00000,20.00000,6.731012e-08,0.73978,4
350.02767, 98.40000,     -1.61805,     -3.60805,50.00000,20.00000,6.713783e-08,0.73979,4
350.02734, 99.00000,     -1.61840,     -3.62038,50.00000,20.00000,6.707406e-08,0.73979,4
350.02292, 99.60000,     -1.61822,     -3.63410,50.00000,20.00000,6.716136e-08,0.73979,4
350.02566,100.20000,     -1.61618,     -3.64674,50.00000,20.00000,6.722915e-08,0.73979,4
350.02882,100.80000,     -1.61780,     -3.66077,50.00000,20.00000,6.709135e-08,0.73979,4
350.03493,101.40000,     -1.62079,     -3.67367,50.00000,20.00000,6.718352e-08,0.73978,4
350.03127,102.00000,     -1.62021,     -3.68611,50.00000,20.00000,6.705876e-08,0.73978,4
350.03284,102.60000,     -1.62282,     -3.69878,50.00000,20.00000,6.727076e-08,0.73978,4
350.03500,103.20000,     -1.61939,     -3.71055,50.00000,20.00000,6.723833e-08,0.73978,4
350.04571,103.80000,     -1.62259,     -3.72217,50.00000,20.00000,6.714096e-08,0.73977,4
350.03991,104.40000,     -1.62608,     -3.73397,50.00000,20.00000,6.713318e-08,0.73977,4
350.02842,105.00000,     -1.62419,     -3.74654,50.00000,20.00000,6.730651e-08,0.73979,4
350.03683,105.60000,     -1.62316,     -3.75761,50.00000,20.00000,6.725348e-08,0.73978,4
350.03765,106.20000,     -1.62519,     -3.76870,50.00000,20.00000,6.734355e-08,0.73978,4
350.03290,106.80000,     -1.62809,     -3.77956,50.00000,20.00000,6.729996e-08,0.73978,4
350.02422,107.40000,     -1.62709,     -3.79181,50.00000,20.00000,6.725368e-08,0.73979,4
350.02417,108.00000,     -1.62557,     -3.80433,50.00000,20.00000,6.733836e-08,0.73979,4
350.03920,108.60000,     -1.62443,     -3.81271,50.00000,20.00000,6.736337e-08,0.73978,4
350.02946,109.20000,     -1.62564,     -3.82244,50.00000,20.00000,6.715273e-08,0.73978,4
350.02099,109.80000,     -1.62894,     -3.83363,50.00000,20.00000,6.737600e-08,0.73979,4
350.03185,110.40000,     -1.62459,     -3.84472,50.00000,20.00000,6.727151e-08,0.73978,4
350.03509,111.00000,     -1.62396,     -3.85448,50.00000,20.00000,6.744757e-08,0.73978,4
350.03299,111.60000,     -1.62709,     -3.86395,50.00000,20.00000,6.744912e-08,0.73978,4
350.03755,112.20000,     -1.62546,     -3.87380,50.00000,20.00000,6.731100e-08,0.73978,4
350.03922,112.80000,     -1.62990,     -3.88386,50.00000,20.00000,6.731238e-08,0.73978,4
350.03955,113.40000,     -1.63033,     -3.89337,50.00000,20.00000,6.732900e-08,0.73977,4
350.03596,114.00000,     -1.62893,     -3.90174,50.00000,20.00000,6.735834e-08,0.73978,4
350.04851,114.60000,     -1.62816,     -3.91124,50.00000,20.00000,6.749022e-08,0.73977,4
350.04113,115.20000,     -1.63038,     -3.92086,50.00000,20.00000,6.741965e-08,0.73977,4
350.03135,115.80000,     -1.63392,     -3.93059,50.00000,20.00000,6.738630e-08,0.73978,4
350.03821,116.40000,     -1.63411,     -3.94009,50.00000,20.00000,6.748380e-08,0.73978,4
350.02377,117.00000,     -1.63449,     -3.94824,50.00000,20.00000,6.744261e-08,0.73979,4
350.02585,117.60000,     -1.63610,     -3.95649,50.00000,20.00000,6.741503e-08,0.73979,4
350.02090,118.20000,     -1.63492,     -3.96475,50.00000,20.00000,6.756928e-08,0.73979,4
350.02571,118.80000,     -1.63461,     -3.97436,50.00000,20.00000,6.766401e-08,0.73979,4
350.03196,119.40000,     -1.63442,     -3.98122,50.00000,20.00000,6.758668e-08,0.73978,4
350.02906,120.00000,     -1.63593,     -3.99100,50.00000,20.00000,6.757681e-08,0.73978,4
350.02740,120.60000,     -1.63654,     -3.99801,50.00000,20.00000,6.764943e-08,0.73979,4
350.03364,121.20000,     -1.63562,     -4.00774,50.00000,20.00000,6.763821e-08,0.73978,4
350.04223,121.80000,     -1.63579,     -4.01476,50.00000,20.00000,6.761325e-08,0.73977,4
350.03598,122.40000,     -1.63463,     -4.02369,50.00000,20.00000,6.775436e-08,0.73978,4
350.03775,123.00000,     -1.63645,     -4.03160,50.00000,20.00000,6.758687e-08,0.73978,4
350.03950,123.60000,     -1.63965,     -4.03727,50.00000,20.00000,6.758031e-08,0.73977,4
350.02788,124.20000,     -1.64245,     -4.04756,50.00000,20.00000,6.783222e-08,0.73979,4
350.02796,124.80000,     -1.64230,     -4.05435,50.00000,20.00000,6.765514e-08,0.73979,4
350.02343,125.40000,     -1.64371,     -4.06249,50.00000,20.00000,6.766279e-08,0.73979,4
350.03095,126.00000,     -1.63963,     -4.06974,50.00000,20.00000,6.770038e-08,0.73978,4
350.03586,126.60000,     -1.63951,     -4.07653,50.00000,20.00000,6.776966e-08,0.73978,4
350.03770,127.20000,     -1.64316,     -4.08337,50.00000,20.00000,6.768437e-08,0.73978,4
350.03464,127.80000,     -1.64443,     -4.09133,50.00000,20.00000,6.794034e-08,0.73978,4
350.02549,128.40000,     -1.64509,     -4.09836,50.00000,20.00000,6.781295e-08,0.73979,4
350.03559,129.00000,     -1.64326,     -4.10243,50.00000,20.00000,6.780355e-08,0.73978,4
350.03301,129.60000,     -1.64535,     -4.11227,50.00000,20.00000,6.789226e-08,0.73978,4
350.03404,130.20000,     -1.64883,     -4.11846,50.00000,20.00000,6.786416e-08,0.73978,4
350.03175,130.80000,     -1.65188,     -4.12449,50.00000,20.00000,6.781088e-08,0.73978,4
350.03053,131.40000,     -1.65107,     -4.12992,50.00000,20.00000,6.772832e-08,0.73978,4
350.02884,132.00000,     -1.64928,     -4.13806,50.00000,20.00000,6.782665e-08,0.73979,4
350.02790,132.60000,     -1.64745,     -4.14486,50.00000,20.00000,6.781364e-08,0.73979,4
350.02822,133.20000,     -1.64671,     -4.15187,50.00000,20.00000,6.783038e-08,0.73979,4
350.03736,133.80000,     -1.64962,     -4.15866,50.00000,20.00000,6.796312e-08,0.73978,4
350.03162,134.40000,     -1.65167,     -4.16409,50.00000,20.00000,6.787159e-08,0.73978,4
350.03483,135.00000,     -1.65342,     -4.17088,50.00000,20.00000,6.791180e-08,0.73978,4
350.02591,135.60000,     -1.64965,     -4.17642,50.00000,20.00000,6.808228e-08,0.73979,4
350.02920,136.20000,     -1.64862,     -4.18423,50.00000,20.00000,6.792320e-08,0.73978,4
350.03106,136.80000,     -1.65133,     -4.18864,50.00000,20.00000,6.785726e-08,0.73978,4
350.02605,137.40000,     -1.65136,     -4.19407,50.00000,20.00000,6.796018e-08,0.73979,4
350.03008,138.00000,     -1.65371,     -4.19995,50.00000,20.00000,6.811692e-08,0.73978,4
350.02357,138.60000,     -1.65566,     -4.20538,50.00000,20.00000,6.797387e-08,0.73979,4
350.02641,139.20000,     -1.65502,     -4.21217,50.00000,20.00000,6.805979e-08,0.73979,4
350.03315,139.80000,     -1.65666,     -4.21910,50.00000,20.00000,6.797376e-08,0.73978,4
350.02461,140.40000,     -1.65412,     -4.22314,50.00000,20.00000,6.812437e-08,0.73979,4
350.04841,141.00000,     -1.65528,     -4.22993,50.00000,20.00000,6.803359e-08,0.73977,4
350.02851,141.60000,     -1.65699,     -4.23547,50.00000,20.00000,6.814948e-08,0.73979,4
350.03476,142.20000,     -1.65682,     -4.23977,50.00000,20.00000,6.814565e-08,0.73978,4
350.03446,142.80000,     -1.65937,     -4.24588,50.00000,20.00000,6.807886e-08,0.73978,4
350.02927,143.40000,     -1.66019,     -4.24882,50.00000,20.00000,6.813939e-08,0.73978,4
350.02965,144.00000,     -1.66104,     -4.25697,50.00000,20.00000,6.822226e-08,0.73978,4
350.02515,144.60000,     -1.66238,     -4.26104,50.00000,20.00000,6.821257e-08,0.73979,4
350.02671,145.20000,     -1.66077,     -4.26658,50.00000,20.00000,6.811740e-08,0.73979,4
350.03454,145.80000,     -1.66047,     -4.27201,50.00000,20.00000,6.810383e-08,0.73978,4
350.03409,146.40000,     -1.66280,     -4.27677,50.00000,20.00000,6.811571e-08,0.73978,4
350.03307,147.00000,     -1.66352,     -4.28174,50.00000,20.00000,6.817484e-08,0.73978,4
350.04233,147.60000,     -1.66350,     -4.28692,50.00000,20.00000,6.825273e-08,0.73977,4
350.03892,148.20000,     -1.66366,     -4.29057,50.00000,20.00000,6.834928e-08,0.73978,4
350.04272,148.80000,     -1.66590,     -4.29736,50.00000,20.00000,6.830156e-08,0.73977,4
350.03746,149.40000,     -1.66951,     -4.30143,50.00000,20.00000,6.830287e-08,0.73978,4
350.02704,150.00000,     -1.67414,     -4.30584,50.00000,20.00000,6.830022e-08,0.73979,4
350.02709,150.60000,     -1.67364,     -4.31138,50.00000,20.00000,6.816131e-08,0.73979,4
350.01964,151.20000,     -1.67039,     -4.31523,50.00000,20.00000,6.826948e-08,0.73979,4
350.03071,151.80000,     -1.66628,     -4.31828,50.00000,20.00000,6.841575e-08,0.73978,4
350.04418,152.40000,     -1.67057,     -4.32394,50.00000,20.00000,6.828792e-08,0.73977,4
350.03772,153.00000,     -1.67580,     -4.32801,50.00000,20.00000,6.836432e-08,0.73978,4
350.03348,153.60000,     -1.67868,     -4.33209,50.00000,20.00000,6.843632e-08,0.73978,4
350.03579,154.20000,     -1.67710,     -4.33718,50.00000,20.00000,6.843109e-08,0.73978,4
350.02998,154.80000,     -1.67805,     -4.34255,50.00000,20.00000,6.849102e-08,0.73978,4
350.03253,155.40000,     -1.68305,     -4.34600,50.00000,20.00000,6.839877e-08,0.73978,4
350.02912,156.00000,     -1.68584,     -4.34872,50.00000,20.00000,6.843327e-08,0.73978,4
350.03309,156.60000,     -1.68435,     -4.35302,50.00000,20.00000,6.840650e-08,0.73978,4
350.03264,157.20000,     -1.68465,     -4.35845,50.00000,20.00000,6.848548e-08,0.73978,4
350.02750,157.80000,     -1.68788,     -4.36122,50.00000,20.00000,6.859637e-08,0.73979,4
350.03234,158.40000,     -1.68894,     -4.36659,50.00000,20.00000,6.849231e-08,0.73978,4
350.03049,159.00000,     -1.69169,     -4.37042,50.00000,20.00000,6.845746e-08,0.73978,4
350.03218,159.60000,     -1.69487,     -4.37474,50.00000,20.00000,6.845106e-08,0.73978,4
350.03968,160.20000,     -1.69753,     -4.37627,50.00000,20.00000,6.843474e-08,0.73977,4
350.03343,160.80000,     -1.69999,     -4.38028,50.00000,20.00000,6.860694e-08,0.73978,4
350.02454,161.40000,     -1.70205,     -4.38571,50.00000,20.00000,6.854627e-08,0.73979,4
350.02630,162.00000,     -1.70405,     -4.38990,50.00000,20.00000,6.846907e-08,0.73979,4
350.03092,162.60000,     -1.70614,     -4.39261,50.00000,20.00000,6.865814e-08,0.73978,4
350.02075,163.20000,     -1.70834,     -4.39668,50.00000,20.00000,6.859102e-08,0.73979,4
350.02077,163.80000,     -1.70734,     -4.39940,50.00000,20.00000,6.861282e-08,0.73979,4
350.03471,164.40000,     -1.71027,     -4.40347,50.00000,20.00000,6.862291e-08,0.73978,4
350.04123,165.00000,     -1.71501,     -4.40709,50.00000,20.00000,6.871827e-08,0.73977,4
350.03411,165.60000,     -1.72138,     -4.41116,50.00000,20.00000,6.866819e-08,0.73978,4
350.03709,166.20000,     -1.72323,     -4.41659,50.00000,20.00000,6.870223e-08,0.73978,4
350.03231,166.80000,     -1.72257,     -4.41863,50.00000,20.00000,6.863304e-08,0.73978,4
350.02880,167.40000,     -1.72586,     -4.42236,50.00000,20.00000,6.860872e-08,0.73979,4
350.03215,168.00000,     -1.72750,     -4.42372,50.00000,20.00000,6.857557e-08,0.73978,4
350.03276,168.60000,     -1.73283,     -4.42644,50.00000,20.00000,6.855839e-08,0.73978,4
350.03582,169.20000,     -1.73579,     -4.42950,50.00000,20.00000,6.863649e-08,0.73978,4
350.02694,169.80000,     -1.73899,     -4.43470,50.00000,20.00000,6.863230e-08,0.73979,4
350.03203,170.40000,     -1.74069,     -4.43594,50.00000,20.00000,6.875243e-08,0.73978,4
350.02824,171.00000,     -1.74465,     -4.44001,50.00000,20.00000,6.866188e-08,0.73979,4
350.04419,171.60000,     -1.74730,     -4.44272,50.00000,20.00000,6.873128e-08,0.73977,4
350.03756,172.20000,     -1.74992,     -4.44635,50.00000,20.00000,6.874507e-08,0.73978,4
350.04563,172.80000,     -1.75329,     -4.45042,50.00000,20.00000,6.866475e-08,0.73977,4
350.04470,173.40000,     -1.75480,     -4.45349,50.00000,20.00000,6.878064e-08,0.73977,4
350.03350,174.00000,     -1.75982,     -4.45619,50.00000,20.00000,6.880757e-08,0.73978,4
350.03897,174.60000,     -1.76489,     -4.45755,50.00000,20.00000,6.878495e-08,0.73978,4
350.03184,175.20000,     -1.76563,     -4.46195,50.00000,20.00000,6.891730e-08,0.73978,4
350.03327,175.80000,     -1.76976,     -4.46332,50.00000,20.00000,6.872277e-08,0.73978,4
350.03325,176.40000,     -1.77301,     -4.46716,50.00000,20.00000,6.879198e-08,0.73978,4
350.01931,177.00000,     -1.77414,     -4.46851,50.00000,20.00000,6.879901e-08,0.73979,4
350.03621,177.60000,     -1.77319,     -4.47259,50.00000,20.00000,6.881863e-08,0.73978,4
350.03235,178.20000,     -1.77584,     -4.47486,50.00000,20.00000,6.879589e-08,0.73978,4
350.03821,178.80000,     -1.78045,     -4.47836,50.00000,20.00000,6.891120e-08,0.73978,4
350.02793,179.40000,     -1.78248,     -4.48142,50.00000,20.00000,6.883854e-08,0.73979,4
350.03267,180.00000,     -1.78337,     -4.48278,50.00000,20.00000,6.885316e-08,0.73978,4
350.02972,180.60000,     -1.78623,     -4.48515,50.00000,20.00000,6.880287e-08,0.73978,4
350.04229,181.20000,     -1.78821,     -4.48821,50.00000,20.00000,6.882538e-08,0.73977,4
350.03946,181.80000,     -1.79063,     -4.49228,50.00000,20.00000,6.885965e-08,0.73977,4
350.03054,182.40000,     -1.79256,     -4.49398,50.00000,20.00000,6.888605e-08,0.73978,4
350.03280,183.00000,     -1.79835,     -4.49398,50.00000,20.00000,6.888231e-08,0.73978,4
350.02873,183.60000,     -1.80004,     -4.49805,50.00000,20.00000,6.893128e-08,0.73979,4
350.02577,184.20000,     -1.80124,     -4.50102,50.00000,20.00000,6.890933e-08,0.73979,4
350.01880,184.80000,     -1.80638,     -4.50235,50.00000,20.00000,6.891395e-08,0.73979,4
350.02843,185.40000,     -1.80721,     -4.50642,50.00000,20.00000,6.891963e-08,0.73979,4
350.02382,186.00000,     -1.80670,     -4.50913,50.00000,20.00000,6.893871e-08,0.73979,4
350.02733,186.60000,     -1.80818,     -4.51083,50.00000,20.00000,6.900996e-08,0.73979,4
350.03075,187.20000,     -1.81130,     -4.51287,50.00000,20.00000,6.895676e-08,0.73978,4
350.02838,187.80000,     -1.81274,     -4.51558,50.00000,20.00000,6.898199e-08,0.73979,4
350.03418,188.40000,     -1.81751,     -4.51671,50.00000,20.00000,6.905513e-08,0.73978,4
350.02569,189.00000,     -1.81774,     -4.52011,50.00000,20.00000,6.902605e-08,0.73979,4
350.04346,189.60000,     -1.81711,     -4.52282,50.00000,20.00000,6.902355e-08,0.73977,4
350.03331,190.20000,     -1.82431,     -4.52418,50.00000,20.00000,6.901374e-08,0.73978,4
350.02707,190.80000,     -1.82617,     -4.52554,50.00000,20.00000,6.894737e-08,0.73979,4
350.02283,191.40000,     -1.83002,     -4.52824,50.00000,20.00000,6.902101e-08,0.73979,4
350.03473,192.00000,     -1.82987,     -4.53165,50.00000,20.00000,6.910844e-08,0.73978,4
350.03721,192.60000,     -1.83360,     -4.53436,50.00000,20.00000,6.900496e-08,0.73978,4
350.02978,193.20000,     -1.83667,     -4.53708,50.00000,20.00000,6.913425e-08,0.73978,4
350.03548,193.80000,     -1.84014,     -4.53844,50.00000,20.00000,6.914314e-08,0.73978,4
350.02282,194.40000,     -1.83898,     -4.53979,50.00000,20.00000,6.901693e-08,0.73979,4
350.01557,195.00000,     -1.83972,     -4.54183,50.00000,20.00000,6.909150e-08,0.73980,4
350.03185,195.60000,     -1.84306,     -4.54387,50.00000,20.00000,6.910160e-08,0.73978,4
350.02309,196.20000,     -1.84192,     -4.54522,50.00000,20.00000,6.913892e-08,0.73979,4
350.02794,196.80000,     -1.84504,     -4.54760,50.00000,20.00000,6.914303e-08,0.73979,4
350.03199,197.40000,     -1.84852,     -4.54930,50.00000,20.00000,6.916875e-08,0.73978,4
350.03715,198.00000,     -1.85401,     -4.55201,50.00000,20.00000,6.922930e-08,0.73978,4
350.03098,198.60000,     -1.85285,     -4.55337,50.00000,20.00000,6.918609e-08,0.73978,4
350.03916,199.20000,     -1.85483,     -4.55548,50.00000,20.00000,6.916003e-08,0.73978,4
350.02540,199.80000,     -1.85629,     -4.55608,50.00000,20.00000,6.915771e-08,0.73979,4
350.04067,200.40000,     -1.85760,     -4.55846,50.00000,20.00000,6.920480e-08,0.73977,4
350.04271,201.00000,     -1.85687,     -4.56016,50.00000,20.00000,6.913904e-08,0.73977,4
350.03513,201.60000,     -1.86217,     -4.56151,50.00000,20.00000,6.920255e-08,0.73978,4
350.03381,202.20000,     -1.86726,     -4.56389,50.00000,20.00000,6.915832e-08,0.73978,4
350.03482,202.80000,     -1.86667,     -4.56525,50.00000,20.00000,6.912803e-08,0.73978,4
350.03459,203.40000,     -1.86871,     -4.56625,50.00000,20.00000,6.918474e-08,0.73978,4
350.03819,204.00000,     -1.87077,     -4.56926,50.00000,20.00000,6.914402e-08,0.73978,4
350.04658,204.60000,     -1.87243,     -4.57074,50.00000,20.00000,6.921486e-08,0.73977,4
350.03155,205.20000,     -1.87437,     -4.57204,50.00000,20.00000,6.924629e-08,0.73978,4
350.03354,205.80000,     -1.87317,     -4.57339,50.00000,20.00000,6.924217e-08,0.73978,4
350.03612,206.40000,     -1.87669,     -4.57611,50.00000,20.00000,6.925630e-08,0.73978,4
350.02804,207.00000,     -1.87775,     -4.57679,50.00000,20.00000,6.925258e-08,0.73979,4
350.03608,207.60000,     -1.88037,     -4.57923,50.00000,20.00000,6.921549e-08,0.73978,4
350.02928,208.20000,     -1.88206,     -4.58086,50.00000,20.00000,6.916641e-08,0.73978,4
350.02817,208.80000,     -1.88208,     -4.58222,50.00000,20.00000,6.925650e-08,0.73979,4
350.02776,209.40000,     -1.88680,     -4.58357,50.00000,20.00000,6.927044e-08,0.73979,4
350.01837,210.00000,     -1.88755,     -4.58391,50.00000,20.00000,6.920185e-08,0.73979,4
350.03580,210.60000,     -1.88699,     -4.58459,50.00000,20.00000,6.923638e-08,0.73978,4
350.02571,211.20000,     -1.88756,     -4.58731,50.00000,20.00000,6.940372e-08,0.73979,4
350.03791,211.80000,     -1.88648,     -4.59002,50.00000,20.00000,6.921941e-08,0.73978,4
350.03104,212.40000,     -1.89131,     -4.59002,50.00000,20.00000,6.930177e-08,0.73978,4
350.04149,213.00000,     -1.89606,     -4.59104,50.00000,20.00000,6.926446e-08,0.73977,4
350.03582,213.60000,     -1.89622,     -4.59240,50.00000,20.00000,6.935885e-08,0.73978,4
350.02569,214.20000,     -1.89667,     -4.59376,50.00000,20.00000,6.934275e-08,0.73979,4
350.02724,214.80000,     -1.89683,     -4.59647,50.00000,20.00000,6.936008e-08,0.73979,4
350.03521,215.40000,     -1.89784,     -4.59783,50.00000,20.00000,6.923787e-08,0.73978,4
350.04323,216.00000,     -1.89934,     -4.60019,50.00000,20.00000,6.933450e-08,0.73977,4
350.02281,216.60000,     -1.90428,     -4.59987,50.00000,20.00000,6.933604e-08,0.73979,4
350.02879,217.20000,     -1.90240,     -4.60122,50.00000,20.00000,6.931733e-08,0.73979,4
350.03693,217.80000,     -1.90192,     -4.60360,50.00000,20.00000,6.914991e-08,0.73978,4
350.04479,218.40000,     -1.90523,     -4.60483,50.00000,20.00000,6.922187e-08,0.73977,4
350.02924,219.00000,     -1.90794,     -4.60484,50.00000,20.00000,6.934910e-08,0.73978,4
350.03777,219.60000,     -1.90714,     -4.60620,50.00000,20.00000,6.934739e-08,0.73978,4
350.05051,220.20000,     -1.90920,     -4.60756,50.00000,20.00000,6.935278e-08,0.73976,4
350.03895,220.80000,     -1.91243,     -4.60756,50.00000,20.00000,6.938051e-08,0.73978,4
350.03870,221.40000,     -1.91114,     -4.61027,50.00000,20.00000,6.933831e-08,0.73978,4
350.03406,222.00000,     -1.91285,     -4.61299,50.00000,20.00000,6.931219e-08,0.73978,4
350.03055,222.60000,     -1.91587,     -4.61231,50.00000,20.00000,6.932776e-08,0.73978,4
350.04094,223.20000,     -1.91478,     -4.61401,50.00000,20.00000,6.918758e-08,0.73977,4
350.03152,223.80000,     -1.91690,     -4.61548,50.00000,20.00000,6.948824e-08,0.73978,4
350.03099,224.40000,     -1.91833,     -4.61819,50.00000,20.00000,6.929542e-08,0.73978,4
350.03683,225.00000,     -1.91695,     -4.61921,50.00000,20.00000,6.934873e-08,0.73978,4
350.03299,225.60000,     -1.92062,     -4.61989,50.00000,20.00000,6.928445e-08,0.73978,4
350.03448,226.20000,     -1.92418,     -4.62260,50.00000,20.00000,6.941602e-08,0.73978,4
350.03672,226.80000,     -1.92326,     -4.62170,50.00000,20.00000,6.943179e-08,0.73978,4
350.04293,227.40000,     -1.92006,     -4.62306,50.00000,20.00000,6.941930e-08,0.73977,4
350.02739,228.00000,     -1.92452,     -4.62328,50.00000,20.00000,6.936215e-08,0.73979,4
350.03619,228.60000,     -1.92784,     -4.62328,50.00000,20.00000,6.944238e-08,0.73978,4
350.03090,229.20000,     -1.92920,     -4.62566,50.00000,20.00000,6.927849e-08,0.73978,4
350.02708,229.80000,     -1.92641,     -4.62601,50.00000,20.00000,6.938349e-08,0.73979,4
350.02689,230.40000,     -1.92763,     -4.62736,50.00000,20.00000,6.936359e-08,0.73979,4
350.02952,231.00000,     -1.92860,     -4.62939,50.00000,20.00000,6.937848e-08,0.73978,4
350.02671,231.60000,     -1.93006,     -4.62973,50.00000,20.00000,6.950305e-08,0.73979,4
350.02570,232.20000,     -1.92840,     -4.63041,50.00000,20.00000,6.934338e-08,0.73979,4
350.03125,232.80000,     -1.92779,     -4.63239,50.00000,20.00000,6.931545e-08,0.73978,4
350.01877,233.40000,     -1.93299,     -4.63245,50.00000,20.00000,6.939617e-08,0.73979,4
350.02285,234.00000,     -1.93004,     -4.63313,50.00000,20.00000,6.934266e-08,0.73979,4
350.02565,234.60000,     -1.93007,     -4.63448,50.00000,20.00000,6.938401e-08,0.73979,4
350.03048,235.20000,     -1.93254,     -4.63448,50.00000,20.00000,6.951578e-08,0.73978,4
350.03465,235.80000,     -1.93445,     -4.63618,50.00000,20.00000,6.952695e-08,0.73978,4
350.03748,236.40000,     -1.93463,     -4.63754,50.00000,20.00000,6.947479e-08,0.73978,4
350.02664,237.00000,     -1.93461,     -4.63888,50.00000,20.00000,6.951749e-08,0.73979,4
350.02863,237.60000,     -1.93473,     -4.63889,50.00000,20.00000,6.954341e-08,0.73979,4
350.03440,238.20000,     -1.93585,     -4.64025,50.00000,20.00000,6.944444e-08,0.73978,4
350.03450,238.80000,     -1.93744,     -4.64195,50.00000,20.00000,6.940838e-08,0.73978,4
350.03302,239.40000,     -1.93866,     -4.64059,50.00000,20.00000,6.947759e-08,0.73978,4
350.03821,240.00000,     -1.93975,     -4.64158,50.00000,20.00000,6.945399e-08,0.73978,4
350.03840,240.60000,     -1.93979,     -4.64322,50.00000,20.00000,6.951652e-08,0.73978,4
350.02993,241.20000,     -1.93766,     -4.64365,50.00000,20.00000,6.943286e-08,0.73978,4
350.02981,241.80000,     -1.93996,     -4.64365,50.00000,20.00000,6.944383e-08,0.73978,4
350.03422,242.40000,     -1.94143,     -4.64500,50.00000,20.00000,6.942790e-08,0.73978,4
350.03726,243.00000,     -1.94102,     -4.64636,50.00000,20.00000,6.950945e-08,0.73978,4
350.02752,243.60000,     -1.94111,     -4.64636,50.00000,20.00000,6.948827e-08,0.73979,4
350.02186,244.20000,     -1.94262,     -4.64918,50.00000,20.00000,6.947970e-08,0.73979,4
350.03227,244.80000,     -1.93929,     -4.64826,50.00000,20.00000,6.940501e-08,0.73978,4
350.03661,245.40000,     -1.93960,     -4.65055,50.00000,20.00000,6.950427e-08,0.73978,4
350.03513,246.00000,     -1.94268,     -4.65055,50.00000,20.00000,6.949783e-08,0.73978,4
350.02903,246.60000,     -1.94384,     -4.65157,50.00000,20.00000,6.941174e-08,0.73978,4
350.02628,247.20000,     -1.94467,     -4.65258,50.00000,20.00000,6.935975e-08,0.73979,4
350.02996,247.80000,     -1.94542,     -4.65258,50.00000,20.00000,6.948885e-08,0.73978,4
350.02309,248.40000,     -1.94486,     -4.65236,50.00000,20.00000,6.951772e-08,0.73979,4
350.02371,249.00000,     -1.94433,     -4.65338,50.00000,20.00000,6.943426e-08,0.73979,4
350.02362,249.60000,     -1.94493,     -4.65473,50.00000,20.00000,6.940432e-08,0.73979,4
350.03000,250.20000,     -1.94360,     -4.65473,50.00000,20.00000,6.947141e-08,0.73978,4
350.03458,250.80000,     -1.94526,     -4.65541,50.00000,20.00000,6.957900e-08,0.73978,4
350.03742,251.40000,     -1.94676,     -4.65541,50.00000,20.00000,6.948622e-08,0.73978,4
350.03634,252.00000,     -1.94490,     -4.65575,50.00000,20.00000,6.952787e-08,0.73978,4
350.04107,252.60000,     -1.94426,     -4.65711,50.00000,20.00000,6.955326e-08,0.73977,4
350.03332,253.20000,     -1.94671,     -4.65813,50.00000,20.00000,6.958112e-08,0.73978,4
350.02544,253.80000,     -1.94817,     -4.65813,50.00000,20.00000,6.951634e-08,0.73979,4
350.01517,254.40000,     -1.94691,     -4.65915,50.00000,20.00000,6.952421e-08,0.73980,4
350.03240,255.00000,     -1.94438,     -4.65847,50.00000,20.00000,6.949881e-08,0.73978,4
350.01963,255.60000,     -1.94549,     -4.65982,50.00000,20.00000,6.952438e-08,0.73979,4
350.03227,256.20000,     -1.94567,     -4.65853,50.00000,20.00000,6.943733e-08,0.73978,4
350.03321,256.80000,     -1.94344,     -4.65982,50.00000,20.00000,6.948977e-08,0.73978,4
350.03734,257.40000,     -1.94131,     -4.66005,50.00000,20.00000,6.952605e-08,0.73978,4
350.04962,258.00000,     -1.94418,     -4.66073,50.00000,20.00000,6.956605e-08,0.73977,4
350.04020,258.60000,     -1.94734,     -4.66175,50.00000,20.00000,6.948139e-08,0.73977,4
350.03968,259.20000,     -1.95173,     -4.66253,50.00000,20.00000,6.958157e-08,0.73977,4
350.02782,259.80000,     -1.95276,     -4.66277,50.00000,20.00000,6.947163e-08,0.73979,4
350.03650,260.40000,     -1.94593,     -4.66277,50.00000,20.00000,6.959735e-08,0.73978,4
350.02833,261.00000,     -1.94606,     -4.66277,50.00000,20.00000,6.951842e-08,0.73979,4
350.03190,261.60000,     -1.94977,     -4.66288,50.00000,20.00000,6.956102e-08,0.73978,4
350.02182,262.20000,     -1.94991,     -4.66415,50.00000,20.00000,6.963786e-08,0.73979,4
350.03053,262.80000,     -1.94387,     -4.66390,50.00000,20.00000,6.954324e-08,0.73978,4
350.03154,263.40000,     -1.94380,     -4.66525,50.00000,20.00000,6.967362e-08,0.73978,4
350.01915,264.00000,     -1.94858,     -4.66524,50.00000,20.00000,6.969693e-08,0.73979,4
350.02403,264.60000,     -1.95022,     -4.66482,50.00000,20.00000,6.960522e-08,0.73979,4
350.03448,265.20000,     -1.94716,     -4.66525,50.00000,20.00000,6.958114e-08,0.73978,4
350.02618,265.80000,     -1.94532,     -4.66525,50.00000,20.00000,6.970560e-08,0.73979,4
350.03586,266.40000,     -1.94458,     -4.66593,50.00000,20.00000,6.957641e-08,0.73978,4
350.03223,267.00000,     -1.94401,     -4.66446,50.00000,20.00000,6.961699e-08,0.73978,4
350.04074,267.60000,     -1.94738,     -4.66582,50.00000,20.00000,6.964523e-08,0.73977,4
350.02958,268.20000,     -1.94628,     -4.66571,50.00000,20.00000,6.970970e-08,0.73978,4
350.03204,268.80000,     -1.94909,     -4.66706,50.00000,20.00000,6.967625e-08,0.73978,4
350.02474,269.40000,     -1.94966,     -4.66706,50.00000,20.00000,6.973368e-08,0.73979,4
350.02214,270.00000,     -1.94718,     -4.66706,50.00000,20.00000,6.947715e-08,0.73979,4
350.02388,270.60000,     -1.94777,     -4.66820,50.00000,20.00000,6.974128e-08,0.73979,4
350.02722,271.20000,     -1.95103,     -4.66854,50.00000,20.00000,6.960100e-08,0.73979,4
350.02749,271.80000,     -1.95348,     -4.66820,50.00000,20.00000,6.971805e-08,0.73979,4
350.02047,272.40000,     -1.95124,     -4.66967,50.00000,20.00000,6.972277e-08,0.73979,4
350.03105,273.00000,     -1.94714,     -4.66820,50.00000,20.00000,6.976375e-08,0.73978,4
350.03534,273.60000,     -1.94451,     -4.66955,50.00000,20.00000,6.974709e-08,0.73978,4
350.04098,274.20000,     -1.94674,     -4.67001,50.00000,20.00000,6.954306e-08,0.73977,4
350.04076,274.80000,     -1.94925,     -4.66899,50.00000,20.00000,6.971795e-08,0.73977,4
350.03270,275.40000,     -1.94681,     -4.67021,50.00000,20.00000,6.967404e-08,0.73978,4
350.03633,276.00000,     -1.94807,     -4.67057,50.00000,20.00000,6.971560e-08,0.73978,4
350.03883,276.60000,     -1.95004,     -4.67057,50.00000,20.00000,6.957950e-08,0.73978,4
350.03241,277.20000,     -1.95211,     -4.67046,50.00000,20.00000,6.962320e-08,0.73978,4
350.02393,277.80000,     -1.95202,     -4.67182,50.00000,20.00000,6.970362e-08,0.73979,4
350.03082,278.40000,     -1.94759,     -4.67257,50.00000,20.00000,6.965129e-08,0.73978,4
350.02029,279.00000,     -1.94750,     -4.67226,50.00000,20.00000,6.957608e-08,0.73979,4
350.03066,279.60000,     -1.94715,     -4.67249,50.00000,20.00000,6.969000e-08,0.73978,4
350.03542,280.20000,     -1.94982,     -4.67216,50.00000,20.00000,6.962978e-08,0.73978,4
350.02685,280.80000,     -1.94979,     -4.67216,50.00000,20.00000,6.975656e-08,0.73979,4
350.03778,281.40000,     -1.94607,     -4.67148,50.00000,20.00000,6.980772e-08,0.73978,4
350.04367,282.00000,     -1.94756,     -4.67249,50.00000,20.00000,6.965578e-08,0.73977,4
352.08403,282.60000,     -0.28040,     -4.66388,50.00000,20.00000,6.969577e-08,0.73782,5
357.43484,283.20000,      2.12519,     -4.64385,50.00000,20.00000,6.968837e-08,0.73272,5
362.73386,283.80000,      2.32451,     -4.63595,50.00000,20.00000,6.960431e-08,0.72767,5
367.70721,284.40000,      2.14551,     -4.63188,50.00000,20.00000,6.971400e-08,0.72294,5
373.26421,285.00000,      2.52134,     -4.62508,50.00000,20.00000,6.962122e-08,0.71767,5
379.32657,285.60000,      2.89394,     -4.61830,50.00000,20.00000,6.969611e-08,0.71193,5
385.51760,286.20000,      2.98901,     -4.61151,50.00000,20.00000,6.969296e-08,0.70610,5
391.73964,286.80000,      2.98047,     -4.60698,50.00000,20.00000,6.965155e-08,0.70026,5
398.03275,287.40000,      2.97676,     -4.60189,50.00000,20.00000,6.976527e-08,0.69439,5
404.37677,288.00000,      2.93058,     -4.59680,50.00000,20.00000,6.972756e-08,0.68851,5
410.68873,288.60000,      2.84174,     -4.59375,50.00000,20.00000,6.989863e-08,0.68270,5
416.98573,289.20000,      2.72982,     -4.58832,50.00000,20.00000,7.001267e-08,0.67695,5
423.25071,289.80000,      2.60619,     -4.58537,50.00000,20.00000,7.004646e-08,0.67127,5
429.48867,290.40000,      2.47104,     -4.57994,50.00000,20.00000,7.007206e-08,0.66566,5
435.68661,291.00000,      2.32570,     -4.57587,50.00000,20.00000,7.009486e-08,0.66015,5
441.85453,291.60000,      2.17905,     -4.57169,50.00000,20.00000,7.021398e-08,0.65471,5
448.01253,292.20000,      2.02761,     -4.56705,50.00000,20.00000,7.039833e-08,0.64933,5
454.13853,292.80000,      1.86893,     -4.56297,50.00000,20.00000,7.047448e-08,0.64405,5
460.26148,293.40000,      1.70888,     -4.55993,50.00000,20.00000,7.067056e-08,0.63882,5
466.34145,294.00000,      1.53779,     -4.55597,50.00000,20.00000,7.077912e-08,0.63369,5
472.41644,294.60000,      1.36209,     -4.55212,50.00000,20.00000,7.088597e-08,0.62863,5
478.48342,295.20000,      1.18363,     -4.54770,50.00000,20.00000,7.106263e-08,0.62363,5
484.53338,295.80000,      0.99873,     -4.54340,50.00000,20.00000,7.124125e-08,0.61872,5
490.56738,296.40000,      0.81524,     -4.54103,50.00000,20.00000,7.139209e-08,0.61388,5
496.58643,297.00000,      0.62473,     -4.53560,50.00000,20.00000,7.142149e-08,0.60913,5
502.62043,297.60000,      0.43070,     -4.53141,50.00000,20.00000,7.158751e-08,0.60442,5
508.63933,298.20000,      0.22243,     -4.52734,50.00000,20.00000,7.181720e-08,0.59980,5
514.65433,298.80000, 2.321840e-02,     -4.52361,50.00000,20.00000,7.207869e-08,0.59525,5
520.66236,299.40000,     -0.19274,     -4.51920,50.00000,20.00000,7.219736e-08,0.59077,5
526.66738,300.00000,     -0.40436,     -4.51649,50.00000,20.00000,7.238076e-08,0.58637,5
532.67234,300.60000,     -0.61889,     -4.51321,50.00000,20.00000,7.255284e-08,0.58203,5
538.67533,301.20000,     -0.84786,     -4.50981,50.00000,20.00000,7.264829e-08,0.57776,5
544.68129,301.80000,     -1.08086,     -4.50665,50.00000,20.00000,7.290584e-08,0.57357,5
550.68438,302.40000,     -1.30675,     -4.50256,50.00000,20.00000,7.312672e-08,0.56944,5
556.68433,303.00000,     -1.55296,     -4.49849,50.00000,20.00000,7.324059e-08,0.56538,5
562.68733,303.60000,     -1.78597,     -4.49578,50.00000,20.00000,7.350106e-08,0.56140,5
568.68625,304.20000,     -2.03218,     -4.49306,50.00000,20.00000,7.364180e-08,0.55748,5
574.67327,304.80000,     -2.28452,     -4.49035,50.00000,20.00000,7.379429e-08,0.55364,5
580.67637,305.40000,     -2.52193,     -4.48696,50.00000,20.00000,7.404057e-08,0.54985,5
586.67732,306.00000,     -2.77122,     -4.48356,50.00000,20.00000,7.418710e-08,0.54613,5
592.68735,306.60000,     -3.02998,     -4.48051,50.00000,20.00000,7.438786e-08,0.54247,5
598.69236,307.20000,     -3.28624,     -4.47813,50.00000,20.00000,7.467892e-08,0.53888,5
604.69732,307.80000,     -3.55232,     -4.47542,50.00000,20.00000,7.474276e-08,0.53536,5
610.68939,308.40000,     -3.81742,     -4.47270,50.00000,20.00000,7.505538e-08,0.53190,5
616.69236,309.00000,     -4.07981,     -4.46999,50.00000,20.00000,7.515210e-08,0.52850,5
622.71530,309.60000,     -4.34262,     -4.46829,50.00000,20.00000,7.529528e-08,0.52514,5
628.70933,310.20000,     -4.62008,     -4.46558,50.00000,20.00000,7.547176e-08,0.52186,5
634.71733,310.80000,     -4.89649,     -4.46219,50.00000,20.00000,7.570217e-08,0.51863,5
640.72831,311.40000,     -5.17286,     -4.46083,50.00000,20.00000,7.593489e-08,0.51545,5
646.75129,312.00000,     -5.45040,     -4.45879,50.00000,20.00000,7.610358e-08,0.51232,5
652.75128,312.60000,     -5.75063,     -4.45742,50.00000,20.00000,7.618208e-08,0.50925,5
658.73935,313.20000,     -6.03877,     -4.45460,50.00000,20.00000,7.634375e-08,0.50624,5
664.75536,313.80000,     -6.32547,     -4.45325,50.00000,20.00000,7.649272e-08,0.50327,5
670.76134,314.40000,     -6.63155,     -4.45076,50.00000,20.00000,7.668343e-08,0.50034,5
676.77537,315.00000,     -6.93305,     -4.44803,50.00000,20.00000,7.687959e-08,0.49746,5
682.77734,315.60000,     -7.23337,     -4.44702,50.00000,20.00000,7.699795e-08,0.49462,5
688.78936,316.20000,     -7.54773,     -4.44590,50.00000,20.00000,7.711438e-08,0.49182,5
694.79331,316.80000,     -7.86059,     -4.44159,50.00000,20.00000,7.731680e-08,0.48907,5
700.80935,317.40000,     -8.17184,     -4.44194,50.00000,20.00000,7.736632e-08,0.48634,5
706.83534,318.00000,     -8.49361,     -4.44024,50.00000,20.00000,7.771875e-08,0.48365,5
712.83838,318.60000,     -8.81819,     -4.43888,50.00000,20.00000,7.779587e-08,0.48099,5
718.87037,319.20000,     -9.14729,     -4.43684,50.00000,20.00000,7.790414e-08,0.47836,5
724.86933,319.80000,     -9.47854,     -4.43651,50.00000,20.00000,7.817954e-08,0.47577,5
730.90341,320.40000,     -9.80229,     -4.43379,50.00000,20.00000,7.822631e-08,0.47319,5
736.92532,321.00000,    -10.15766,     -4.43243,50.00000,20.00000,7.833379e-08,0.47064,5
742.91336,321.60000,    -10.48585,     -4.43108,50.00000,20.00000,7.849599e-08,0.46812,5
748.92333,322.20000,    -10.83730,     -4.42972,50.00000,20.00000,7.865540e-08,0.46562,5
754.93132,322.80000,    -11.17005,     -4.42835,50.00000,20.00000,7.885675e-08,0.46314,5
760.94932,323.40000,    -11.49590,     -4.42699,50.00000,20.00000,7.895490e-08,0.46067,5
766.94836,324.00000,    -11.82666,     -4.42564,50.00000,20.00000,7.908365e-08,0.45822,5
772.97137,324.60000,    -12.15027,     -4.42497,50.00000,20.00000,7.922502e-08,0.45577,5
778.99132,325.20000,    -12.47299,     -4.42430,50.00000,20.00000,7.930124e-08,0.45333,5
784.99438,325.80000,    -12.78835,     -4.42293,50.00000,20.00000,7.942128e-08,0.45091,5
791.01336,326.40000,    -13.10204,     -4.42156,50.00000,20.00000,7.948832e-08,0.44849,5
794.01736,326.70000,    -13.25579,     -4.42125,50.00000,20.00000,7.955329e-08,0.44728,5