File: data/TGA/005c/ExpDat_2024_06_17_PS2439_6_1K_350C_isotherm.csv
#EXPORTTYPE:                 ,DATA ALL
#FILE:                       ,2024_06_17_PS2439_6_1K_350C_isotherm.ngb-ss5
#FORMAT:                     ,NETZSCH5
#FTYPE:                      ,ASCII
#IDENTITY:                   ,PS2934_6.1K
#DECIMAL:                    ,POINT
#SEPARATOR:                  ,COMMA
#MTYPE:                      ,DSC
#INSTRUMENT:                 ,NETZSCH STA 449F5
#PROJECT:                    ,
#DATE/TIME:                  ,6/17/2024 6:49:02 PM (UTC-4)
#CORR. FILE:                 ,
#TEMPCAL:                    ,28-06-2023 13:26
#SENSITIVITY:                ,28-06-2023 13:53
#LABORATORY:                 ,
#OPERATOR:                   ,Stanley
#REMARK:                     ,
#SAMPLE:                     ,PS2934_6.1K-high-vac
#SAMPLE MASS /mg:            ,5
#MATERIAL:                   ,
#REFERENCE:                  ,
#REFERENCE MASS /mg:         ,0
#TYPE OF CRUCIBLE:           ,Al2O3 85 ‘l, open
#SAMPLE CRUCIBLE MASS /mg:   ,0
#REFERENCE CRUCIBLE MASS /mg:,0
#DSC RANGE /‘V:              ,5000
#TG RANGE /mg:               ,35000
#TAU-R:                      ,---
#CORR. CODE:                 ,000
#EXO:                        ,-1
#RANGE:                      ,30›C....800›C/0.0....10.0K/min
#SEGMENT:                    ,S1-5/5
#SEG. 1:                     ,30›C/10.0(K/min)/100›C
#SEG. 2:                     ,100›C/00:10/100›C
#SEG. 3:                     ,100›C/10.0(K/min)/350›C
#SEG. 4:                     ,350›C/04:00/350›C
#SEG. 5:                     ,350›C/10.0(K/min)/800›C

##Temp./›C,Time/min,DSC/(mW/mg),Mass loss/mg,Gas Flow(purge2)/(ml/min),Gas Flow(protective)/(ml/min),TIC(scan:1)/A,Sensit./(uV/mW),Segment
 31.41100,  0.00000,-7.052871e-02, 0.000000e+00,50.00000,20.00000,5.266368e-08,0.92381,1
 31.62800,  0.60000,-2.295805e-02, 5.540000e-03,50.00000,20.00000,5.296126e-08,0.92385,1
 32.77300,  1.20000,      0.20394, 4.910000e-02,50.00000,20.00000,5.274261e-08,0.92404,1
 35.08600,  1.80000,      0.52359,      0.10001,50.00000,20.00000,5.244918e-08,0.92441,1
 38.30700,  2.40000,      0.81106,      0.14017,50.00000,20.00000,5.239183e-08,0.92487,1
 42.20800,  3.00000,      1.05553,      0.17807,50.00000,20.00000,5.221607e-08,0.92533,1
 46.80300,  3.60000,      1.30955,      0.21155,50.00000,20.00000,5.217060e-08,0.92575,1
 52.15000,  4.20000,      1.58971,      0.24640,50.00000,20.00000,5.189435e-08,0.92606,1
 58.18800,  4.80000,      1.87316,      0.27728,50.00000,20.00000,5.170491e-08,0.92620,1
 64.77400,  5.40000,      2.12911,      0.30115,50.00000,20.00000,5.165111e-08,0.92609,1
 71.77300,  6.00000,      2.35143,      0.32219,50.00000,20.00000,5.148973e-08,0.92568,1
 79.04800,  6.60000,      2.54767,      0.33950,50.00000,20.00000,5.154799e-08,0.92493,1
 86.51215,  7.20000,      2.70596,      0.35172,50.00000,20.00000,5.132222e-08,0.92383,2
 93.07594,  7.80000,      2.45860,      0.33617,50.00000,20.00000,5.115923e-08,0.92260,2
 98.01484,  8.40000,      1.91404,      0.29938,50.00000,20.00000,5.097982e-08,0.92151,2
101.55909,  9.00000,      1.39299,      0.26547,50.00000,20.00000,5.093591e-08,0.92064,2
104.27298,  9.60000,      1.06473,      0.24003,50.00000,20.00000,5.068545e-08,0.91992,2
106.46068, 10.20000,      0.85510,      0.22295,50.00000,20.00000,5.057396e-08,0.91932,2
108.16712, 10.80000,      0.66131,      0.20352,50.00000,20.00000,5.056028e-08,0.91882,2
109.30022, 11.40000,      0.45324,      0.18507,50.00000,20.00000,5.013123e-08,0.91849,2
109.95565, 12.00000,      0.25735,      0.16524,50.00000,20.00000,5.020535e-08,0.91829,2
110.18584, 12.60000, 9.816443e-02,      0.14702,50.00000,20.00000,4.989127e-08,0.91822,2
110.13077, 13.20000,-2.375822e-02,      0.13020,50.00000,20.00000,4.977059e-08,0.91824,2
109.82804, 13.80000,     -0.11656,      0.11603,50.00000,20.00000,4.967753e-08,0.91833,2
109.36824, 14.40000,     -0.18896,      0.10202,50.00000,20.00000,4.928335e-08,0.91847,2
108.77854, 15.00000,     -0.24258, 8.949392e-02,50.00000,20.00000,4.909122e-08,0.91865,2
108.08822, 15.60000,     -0.27869, 7.817067e-02,50.00000,20.00000,4.899054e-08,0.91885,2
107.36616, 16.20000,     -0.30220, 6.990612e-02,50.00000,20.00000,4.867624e-08,0.91906,2
106.61196, 16.80000,     -0.31091, 6.030308e-02,50.00000,20.00000,4.835156e-08,0.91927,2
105.97734, 17.40000,     -0.25170, 5.758000e-02,50.00000,20.00000,4.814508e-08,0.91945,3
106.58671, 18.00000,      0.22749, 9.433714e-02,50.00000,20.00000,4.790571e-08,0.91928,3
108.85654, 18.60000,      0.90167,      0.14106,50.00000,20.00000,4.756988e-08,0.91862,3
112.13167, 19.20000,      1.39542,      0.17595,50.00000,20.00000,4.736229e-08,0.91762,3
116.03426, 19.80000,      1.73735,      0.19934,50.00000,20.00000,4.702524e-08,0.91635,3
120.58662, 20.40000,      2.09499,      0.22308,50.00000,20.00000,4.689997e-08,0.91477,3
125.90681, 21.00000,      2.51523,      0.24606,50.00000,20.00000,4.659619e-08,0.91279,3
131.94035, 21.60000,      2.92646,      0.26902,50.00000,20.00000,4.642327e-08,0.91036,3
138.44839, 22.20000,      3.26212,      0.28611,50.00000,20.00000,4.626120e-08,0.90753,3
145.29010, 22.80000,      3.53274,      0.29719,50.00000,20.00000,4.605505e-08,0.90433,3
152.35033, 23.40000,      3.75664,      0.30760,50.00000,20.00000,4.574200e-08,0.90080,3
159.54402, 24.00000,      3.93993,      0.31575,50.00000,20.00000,4.554662e-08,0.89697,3
166.76947, 24.60000,      4.07145,      0.32118,50.00000,20.00000,4.560849e-08,0.89288,3
173.97665, 25.20000,      4.15077,      0.32321,50.00000,20.00000,4.531049e-08,0.88859,3
181.13469, 25.80000,      4.15488,      0.32740,50.00000,20.00000,4.534872e-08,0.88411,3
188.24069, 26.40000,      4.11024,      0.32876,50.00000,20.00000,4.526142e-08,0.87947,3
195.20358, 27.00000,      4.05623,      0.32944,50.00000,20.00000,4.499616e-08,0.87473,3
202.05274, 27.60000,      3.99898,      0.33113,50.00000,20.00000,4.491635e-08,0.86991,3
208.78048, 28.20000,      3.94866,      0.33046,50.00000,20.00000,4.492742e-08,0.86501,3
215.39006, 28.80000,      3.91090,      0.33317,50.00000,20.00000,4.475732e-08,0.86005,3
221.87860, 29.40000,      3.87364,      0.33453,50.00000,20.00000,4.496385e-08,0.85506,3
228.27799, 30.00000,      3.84242,      0.33724,50.00000,20.00000,4.472919e-08,0.85001,3
234.58732, 30.60000,      3.81337,      0.33713,50.00000,20.00000,4.466919e-08,0.84492,3
240.81040, 31.20000,      3.78599,      0.33984,50.00000,20.00000,4.490773e-08,0.83980,3
246.98670, 31.80000,      3.76481,      0.34109,50.00000,20.00000,4.464488e-08,0.83462,3
253.09647, 32.40000,      3.74284,      0.34312,50.00000,20.00000,4.474888e-08,0.82942,3
259.18075, 33.00000,      3.72709,      0.34250,50.00000,20.00000,4.476656e-08,0.82415,3
265.22157, 33.60000,      3.71452,      0.34244,50.00000,20.00000,4.462071e-08,0.81885,3
271.24540, 34.20000,      3.70036,      0.34143,50.00000,20.00000,4.462267e-08,0.81350,3
277.22922, 34.80000,      3.68878,      0.33973,50.00000,20.00000,4.473844e-08,0.80813,3
283.20387, 35.40000,      3.67996,      0.33566,50.00000,20.00000,4.480910e-08,0.80270,3
289.15775, 36.00000,      3.66975,      0.33023,50.00000,20.00000,4.466816e-08,0.79725,3
295.08967, 36.60000,      3.66161,      0.32132,50.00000,20.00000,4.467918e-08,0.79177,3
301.03140, 37.20000,      3.65776,      0.30931,50.00000,20.00000,4.466470e-08,0.78624,3
306.96798, 37.80000,      3.65579,      0.29313,50.00000,20.00000,4.484080e-08,0.78069,3
312.88615, 38.40000,      3.65347,      0.27186,50.00000,20.00000,4.493996e-08,0.77512,3
318.81469, 39.00000,      3.65467,      0.24527,50.00000,20.00000,4.497687e-08,0.76952,3
324.75799, 39.60000,      3.65688,      0.21122,50.00000,20.00000,4.509878e-08,0.76388,3
330.67461, 40.20000,      3.65698,      0.17092,50.00000,20.00000,4.537278e-08,0.75825,3
336.60029, 40.80000,      3.66011,      0.12158,50.00000,20.00000,4.561254e-08,0.75260,3
342.52774, 41.40000,      3.66611, 6.273254e-02,50.00000,20.00000,4.588721e-08,0.74695,3
348.45774, 42.00000,      3.67651,-7.888760e-03,50.00000,20.00000,4.606931e-08,0.74128,4
352.36494, 42.60000,      2.16958,-9.811230e-02,50.00000,20.00000,4.648119e-08,0.73756,4
353.09272, 43.20000, 5.784929e-02,     -0.20876,50.00000,20.00000,4.665244e-08,0.73686,4
353.54835, 43.80000,     -0.39669,     -0.30363,50.00000,20.00000,4.689818e-08,0.73643,4
354.29161, 44.40000,     -0.35445,     -0.39430,50.00000,20.00000,4.725792e-08,0.73572,4
354.65410, 45.00000,     -0.64077,     -0.48471,50.00000,20.00000,4.734783e-08,0.73537,4
354.55364, 45.60000,     -0.99169,     -0.57278,50.00000,20.00000,4.782700e-08,0.73547,4
354.29929, 46.20000,     -1.16093,     -0.65597,50.00000,20.00000,4.807288e-08,0.73571,4
354.03433, 46.80000,     -1.22645,     -0.73786,50.00000,20.00000,4.847050e-08,0.73596,4
353.72122, 47.40000,     -1.28801,     -0.81152,50.00000,20.00000,4.884427e-08,0.73626,4
353.38311, 48.00000,     -1.33743,     -0.88394,50.00000,20.00000,4.919263e-08,0.73658,4
353.05853, 48.60000,     -1.36281,     -0.95182,50.00000,20.00000,4.954296e-08,0.73689,4
352.74189, 49.20000,     -1.37244,     -1.01822,50.00000,20.00000,4.989891e-08,0.73720,4
352.44857, 49.80000,     -1.37822,     -1.08096,50.00000,20.00000,5.034994e-08,0.73748,4
352.16556, 50.40000,     -1.38193,     -1.13976,50.00000,20.00000,5.060423e-08,0.73775,4
351.92016, 51.00000,     -1.38173,     -1.19785,50.00000,20.00000,5.079198e-08,0.73798,4
351.70455, 51.60000,     -1.37687,     -1.25333,50.00000,20.00000,5.116506e-08,0.73819,4
351.50482, 52.20000,     -1.37357,     -1.30563,50.00000,20.00000,5.142420e-08,0.73838,4
351.32381, 52.80000,     -1.36458,     -1.35857,50.00000,20.00000,5.169192e-08,0.73855,4
351.15636, 53.40000,     -1.36244,     -1.40808,50.00000,20.00000,5.188156e-08,0.73871,4
351.02201, 54.00000,     -1.35805,     -1.45731,50.00000,20.00000,5.198766e-08,0.73884,4
350.89236, 54.60000,     -1.35127,     -1.50197,50.00000,20.00000,5.216669e-08,0.73896,4
350.78736, 55.20000,     -1.34671,     -1.54817,50.00000,20.00000,5.247971e-08,0.73906,4
350.69064, 55.80000,     -1.34616,     -1.59174,50.00000,20.00000,5.238499e-08,0.73915,4
350.61743, 56.40000,     -1.34244,     -1.63433,50.00000,20.00000,5.276345e-08,0.73922,4
350.53962, 57.00000,     -1.34000,     -1.67408,50.00000,20.00000,5.287142e-08,0.73930,4
350.48046, 57.60000,     -1.34024,     -1.71420,50.00000,20.00000,5.295877e-08,0.73935,4
350.43176, 58.20000,     -1.33974,     -1.75706,50.00000,20.00000,5.315113e-08,0.73940,4
350.37855, 58.80000,     -1.34035,     -1.79246,50.00000,20.00000,5.336240e-08,0.73945,4
350.34154, 59.40000,     -1.33887,     -1.83033,50.00000,20.00000,5.346914e-08,0.73949,4
350.29364, 60.00000,     -1.34298,     -1.86631,50.00000,20.00000,5.328767e-08,0.73953,4
350.25146, 60.60000,     -1.34048,     -1.90131,50.00000,20.00000,5.341445e-08,0.73957,4
350.22696, 61.20000,     -1.34097,     -1.93424,50.00000,20.00000,5.371097e-08,0.73960,4
350.20136, 61.80000,     -1.33778,     -1.97026,50.00000,20.00000,5.341790e-08,0.73962,4
350.18326, 62.40000,     -1.33348,     -2.00227,50.00000,20.00000,5.389146e-08,0.73964,4
350.16442, 63.00000,     -1.33540,     -2.03385,50.00000,20.00000,5.382253e-08,0.73966,4
350.14056, 63.60000,     -1.33235,     -2.06614,50.00000,20.00000,5.376046e-08,0.73968,4
350.12952, 64.20000,     -1.32877,     -2.09701,50.00000,20.00000,5.375503e-08,0.73969,4
350.11712, 64.80000,     -1.32661,     -2.12607,50.00000,20.00000,5.394309e-08,0.73970,4
350.09944, 65.40000,     -1.31358,     -2.15663,50.00000,20.00000,5.391161e-08,0.73972,4
350.09934, 66.00000,     -1.31592,     -2.18528,50.00000,20.00000,5.412523e-08,0.73972,4
350.08557, 66.60000,     -1.31645,     -2.21428,50.00000,20.00000,5.414977e-08,0.73973,4
350.07561, 67.20000,     -1.31153,     -2.24212,50.00000,20.00000,5.416297e-08,0.73974,4
350.07645, 67.80000,     -1.30906,     -2.26860,50.00000,20.00000,5.422193e-08,0.73974,4
350.07451, 68.40000,     -1.30536,     -2.29473,50.00000,20.00000,5.447412e-08,0.73974,4
350.06020, 69.00000,     -1.30278,     -2.32403,50.00000,20.00000,5.430434e-08,0.73976,4
350.05880, 69.60000,     -1.30318,     -2.34903,50.00000,20.00000,5.430944e-08,0.73976,4
350.06058, 70.20000,     -1.29968,     -2.37403,50.00000,20.00000,5.438551e-08,0.73975,4
350.05515, 70.80000,     -1.29469,     -2.39711,50.00000,20.00000,5.440912e-08,0.73976,4
350.04472, 71.40000,     -1.29227,     -2.42127,50.00000,20.00000,5.450114e-08,0.73977,4
350.04285, 72.00000,     -1.29066,     -2.44404,50.00000,20.00000,5.436102e-08,0.73977,4
350.03482, 72.60000,     -1.28707,     -2.46816,50.00000,20.00000,5.441687e-08,0.73978,4
350.02953, 73.20000,     -1.28025,     -2.49192,50.00000,20.00000,5.458961e-08,0.73978,4
350.03069, 73.80000,     -1.27800,     -2.51316,50.00000,20.00000,5.451635e-08,0.73978,4
350.03556, 74.40000,     -1.27676,     -2.53580,50.00000,20.00000,5.470568e-08,0.73978,4
350.03928, 75.00000,     -1.27117,     -2.55703,50.00000,20.00000,5.455971e-08,0.73978,4
350.02602, 75.60000,     -1.26789,     -2.57957,50.00000,20.00000,5.456903e-08,0.73979,4
350.02410, 76.20000,     -1.26461,     -2.60052,50.00000,20.00000,5.471149e-08,0.73979,4
350.02975, 76.80000,     -1.26040,     -2.62201,50.00000,20.00000,5.492477e-08,0.73978,4
350.03157, 77.40000,     -1.26088,     -2.64192,50.00000,20.00000,5.483605e-08,0.73978,4
350.01642, 78.00000,     -1.25666,     -2.66111,50.00000,20.00000,5.485080e-08,0.73980,4
350.01953, 78.60000,     -1.25273,     -2.68220,50.00000,20.00000,5.484517e-08,0.73979,4
350.03431, 79.20000,     -1.24681,     -2.70164,50.00000,20.00000,5.495187e-08,0.73978,4
350.02633, 79.80000,     -1.24455,     -2.72146,50.00000,20.00000,5.483461e-08,0.73979,4
350.01391, 80.40000,     -1.15564,     -2.74046,50.00000,20.00000,5.498851e-08,0.73980,4
350.01794, 81.00000,     -1.18950,     -2.75985,50.00000,20.00000,5.502369e-08,0.73980,4
350.02440, 81.60000,     -1.19636,     -2.77863,50.00000,20.00000,5.513743e-08,0.73979,4
350.03754, 82.20000,     -1.20024,     -2.79581,50.00000,20.00000,5.515721e-08,0.73978,4
350.02722, 82.80000,     -1.20369,     -2.81321,50.00000,20.00000,5.509846e-08,0.73979,4
350.03069, 83.40000,     -1.20211,     -2.83230,50.00000,20.00000,5.528278e-08,0.73978,4
350.02368, 84.00000,     -1.19935,     -2.85009,50.00000,20.00000,5.531534e-08,0.73979,4
350.02852, 84.60000,     -1.19925,     -2.86840,50.00000,20.00000,5.519735e-08,0.73979,4
350.02278, 85.20000,     -1.20091,     -2.88425,50.00000,20.00000,5.522718e-08,0.73979,4
350.03153, 85.80000,     -1.19939,     -2.90099,50.00000,20.00000,5.529920e-08,0.73978,4
350.03530, 86.40000,     -1.19974,     -2.91791,50.00000,20.00000,5.543089e-08,0.73978,4
350.01768, 87.00000,     -1.20044,     -2.93527,50.00000,20.00000,5.529586e-08,0.73980,4
350.03699, 87.60000,     -1.19793,     -2.95006,50.00000,20.00000,5.532678e-08,0.73978,4
350.03912, 88.20000,     -1.19555,     -2.96531,50.00000,20.00000,5.550499e-08,0.73978,4
350.03033, 88.80000,     -1.19645,     -2.98298,50.00000,20.00000,5.542239e-08,0.73978,4
350.03302, 89.40000,     -1.19499,     -2.99761,50.00000,20.00000,5.552842e-08,0.73978,4
350.02039, 90.00000,     -1.19073,     -3.01175,50.00000,20.00000,5.567277e-08,0.73979,4
350.02987, 90.60000,     -1.18602,     -3.02908,50.00000,20.00000,5.577902e-08,0.73978,4
350.02906, 91.20000,     -1.18805,     -3.04275,50.00000,20.00000,5.560271e-08,0.73978,4
350.02830, 91.80000,     -1.18809,     -3.05813,50.00000,20.00000,5.574047e-08,0.73979,4
350.03589, 92.40000,     -1.18823,     -3.07385,50.00000,20.00000,5.575674e-08,0.73978,4
350.02996, 93.00000,     -1.18542,     -3.08814,50.00000,20.00000,5.581742e-08,0.73978,4
350.03736, 93.60000,     -1.18254,     -3.10180,50.00000,20.00000,5.586318e-08,0.73978,4
350.03568, 94.20000,     -1.18145,     -3.11605,50.00000,20.00000,5.586941e-08,0.73978,4
350.02608, 94.80000,     -1.18099,     -3.13020,50.00000,20.00000,5.587410e-08,0.73979,4
350.03699, 95.40000,     -1.15629,     -3.14332,50.00000,20.00000,5.595337e-08,0.73978,4
350.03544, 96.00000,     -1.16944,     -3.15734,50.00000,20.00000,5.592858e-08,0.73978,4
350.01965, 96.60000,     -1.17012,     -3.17036,50.00000,20.00000,5.612732e-08,0.73979,4
350.02707, 97.20000,     -1.17197,     -3.18393,50.00000,20.00000,5.586294e-08,0.73979,4
350.02863, 97.80000,     -1.17099,     -3.19644,50.00000,20.00000,5.602594e-08,0.73979,4
350.03757, 98.40000,     -1.17008,     -3.21052,50.00000,20.00000,5.624225e-08,0.73978,4
350.02507, 99.00000,     -1.16945,     -3.22401,50.00000,20.00000,5.627842e-08,0.73979,4
350.02329, 99.60000,     -1.16944,     -3.23579,50.00000,20.00000,5.633008e-08,0.73979,4
350.01342,100.20000,     -1.16826,     -3.24856,50.00000,20.00000,5.640184e-08,0.73980,4
350.02333,100.80000,     -1.16621,     -3.25924,50.00000,20.00000,5.630176e-08,0.73979,4
350.01603,101.40000,     -1.16511,     -3.27297,50.00000,20.00000,5.638201e-08,0.73980,4
350.03723,102.00000,     -1.16464,     -3.28517,50.00000,20.00000,5.644413e-08,0.73978,4
350.02618,102.60000,     -1.16248,     -3.29740,50.00000,20.00000,5.656527e-08,0.73979,4
350.03097,103.20000,     -1.16307,     -3.30951,50.00000,20.00000,5.657565e-08,0.73978,4
350.02352,103.80000,     -1.16327,     -3.32109,50.00000,20.00000,5.650339e-08,0.73979,4
350.02506,104.40000,     -1.16228,     -3.33225,50.00000,20.00000,5.645259e-08,0.73979,4
350.02964,105.00000,     -1.16003,     -3.34492,50.00000,20.00000,5.679290e-08,0.73978,4
350.03863,105.60000,     -1.15434,     -3.35519,50.00000,20.00000,5.665364e-08,0.73978,4
350.03320,106.20000,     -1.15605,     -3.36866,50.00000,20.00000,5.685073e-08,0.73978,4
350.03724,106.80000,     -1.15571,     -3.37965,50.00000,20.00000,5.681740e-08,0.73978,4
350.02186,107.40000,     -1.15219,     -3.38925,50.00000,20.00000,5.666298e-08,0.73979,4
350.02228,108.00000,     -1.14845,     -3.40057,50.00000,20.00000,5.686044e-08,0.73979,4
350.02237,108.60000,     -1.14719,     -3.41291,50.00000,20.00000,5.704526e-08,0.73979,4
350.02527,109.20000,     -1.14965,     -3.42399,50.00000,20.00000,5.695105e-08,0.73979,4
350.02702,109.80000,     -1.14694,     -3.43350,50.00000,20.00000,5.721736e-08,0.73979,4
350.02890,110.40000,     -1.14061,     -3.44435,50.00000,20.00000,5.704972e-08,0.73978,4
350.02139,111.00000,     -1.14023,     -3.45397,50.00000,20.00000,5.716413e-08,0.73979,4
350.02046,111.60000,     -1.13005,     -3.46483,50.00000,20.00000,5.707937e-08,0.73979,4
350.03064,112.20000,     -1.13814,     -3.47581,50.00000,20.00000,5.709834e-08,0.73978,4
350.02543,112.80000,     -1.13738,     -3.48531,50.00000,20.00000,5.716378e-08,0.73979,4
350.03693,113.40000,     -1.13899,     -3.49515,50.00000,20.00000,5.725013e-08,0.73978,4
350.03144,114.00000,     -1.14056,     -3.50477,50.00000,20.00000,5.745944e-08,0.73978,4
350.01974,114.60000,     -1.13963,     -3.51439,50.00000,20.00000,5.745435e-08,0.73979,4
350.03689,115.20000,     -1.13719,     -3.52547,50.00000,20.00000,5.763768e-08,0.73978,4
350.04051,115.80000,     -1.13579,     -3.53384,50.00000,20.00000,5.754712e-08,0.73977,4
350.03142,116.40000,     -1.13754,     -3.54335,50.00000,20.00000,5.756356e-08,0.73978,4
350.02465,117.00000,     -1.13729,     -3.55319,50.00000,20.00000,5.770773e-08,0.73979,4
350.02136,117.60000,     -1.13564,     -3.56280,50.00000,20.00000,5.773601e-08,0.73979,4
350.02174,118.20000,     -1.13389,     -3.57118,50.00000,20.00000,5.762370e-08,0.73979,4
350.02503,118.80000,     -1.13275,     -3.58204,50.00000,20.00000,5.771275e-08,0.73979,4
350.02109,119.40000,     -1.13263,     -3.59007,50.00000,20.00000,5.785582e-08,0.73979,4
350.01872,120.00000,     -1.13035,     -3.59957,50.00000,20.00000,5.776139e-08,0.73979,4
350.02858,120.60000,     -1.12871,     -3.60806,50.00000,20.00000,5.777555e-08,0.73979,4
350.02857,121.20000,     -1.13032,     -3.61632,50.00000,20.00000,5.790573e-08,0.73979,4
350.03031,121.80000,     -1.13055,     -3.62659,50.00000,20.00000,5.795966e-08,0.73978,4
350.03052,122.40000,     -1.12896,     -3.63442,50.00000,20.00000,5.821235e-08,0.73978,4
350.02762,123.00000,     -1.12744,     -3.64256,50.00000,20.00000,5.816344e-08,0.73979,4
350.02312,123.60000,     -1.12603,     -3.65205,50.00000,20.00000,5.824172e-08,0.73979,4
350.02783,124.20000,     -1.12316,     -3.66032,50.00000,20.00000,5.825984e-08,0.73979,4
350.03150,124.80000,     -1.12223,     -3.66853,50.00000,20.00000,5.843521e-08,0.73978,4
350.04588,125.40000,     -1.12105,     -3.67532,50.00000,20.00000,5.835057e-08,0.73977,4
350.03003,126.00000,     -1.11859,     -3.68487,50.00000,20.00000,5.849833e-08,0.73978,4
350.04039,126.60000,     -1.11794,     -3.69308,50.00000,20.00000,5.860376e-08,0.73977,4
350.03729,127.20000,     -1.11846,     -3.70128,50.00000,20.00000,5.842396e-08,0.73978,4
350.02627,127.80000,     -1.12019,     -3.71044,50.00000,20.00000,5.851261e-08,0.73979,4
350.03752,128.40000,     -1.11792,     -3.71757,50.00000,20.00000,5.862473e-08,0.73978,4
350.02972,129.00000,     -1.10654,     -3.72511,50.00000,20.00000,5.864761e-08,0.73978,4
350.03413,129.60000,     -1.11686,     -3.73411,50.00000,20.00000,5.880344e-08,0.73978,4
350.03316,130.20000,     -1.11857,     -3.74087,50.00000,20.00000,5.889858e-08,0.73978,4
350.02841,130.80000,     -1.11839,     -3.74789,50.00000,20.00000,5.877308e-08,0.73979,4
350.02848,131.40000,     -1.11462,     -3.75547,50.00000,20.00000,5.891623e-08,0.73979,4
350.02087,132.00000,     -1.11762,     -3.76361,50.00000,20.00000,5.886374e-08,0.73979,4
350.02463,132.60000,     -1.11730,     -3.77040,50.00000,20.00000,5.911603e-08,0.73979,4
350.02607,133.20000,     -1.11381,     -3.77854,50.00000,20.00000,5.924530e-08,0.73979,4
350.01979,133.80000,     -1.11415,     -3.78409,50.00000,20.00000,5.907294e-08,0.73979,4
350.02892,134.40000,     -1.11150,     -3.79116,50.00000,20.00000,5.917791e-08,0.73978,4
350.02799,135.00000,     -1.10838,     -3.79979,50.00000,20.00000,5.926182e-08,0.73979,4
350.04399,135.60000,     -1.10888,     -3.80513,50.00000,20.00000,5.929278e-08,0.73977,4
350.02779,136.20000,     -1.11381,     -3.81327,50.00000,20.00000,5.937620e-08,0.73979,4
350.03698,136.80000,     -1.11532,     -3.82022,50.00000,20.00000,5.956816e-08,0.73978,4
350.03921,137.40000,     -1.11193,     -3.82742,50.00000,20.00000,5.945127e-08,0.73978,4
350.03468,138.00000,     -1.11180,     -3.83361,50.00000,20.00000,5.952716e-08,0.73978,4
350.03426,138.60000,     -1.11294,     -3.83962,50.00000,20.00000,5.945011e-08,0.73978,4
350.02643,139.20000,     -1.10964,     -3.84801,50.00000,20.00000,5.956523e-08,0.73979,4
350.02962,139.80000,     -1.10869,     -3.85344,50.00000,20.00000,5.975984e-08,0.73978,4
350.03790,140.40000,     -1.10658,     -3.86044,50.00000,20.00000,5.963448e-08,0.73978,4
350.04818,141.00000,     -1.10968,     -3.86588,50.00000,20.00000,5.977530e-08,0.73977,4
350.03027,141.60000,     -1.10796,     -3.87267,50.00000,20.00000,5.982478e-08,0.73978,4
350.03116,142.20000,     -1.11029,     -3.87945,50.00000,20.00000,5.973886e-08,0.73978,4
350.02311,142.80000,     -1.10655,     -3.88647,50.00000,20.00000,5.998025e-08,0.73979,4
350.02906,143.40000,     -1.10084,     -3.89190,50.00000,20.00000,5.983603e-08,0.73978,4
350.02441,144.00000,     -1.10225,     -3.89733,50.00000,20.00000,5.983366e-08,0.73979,4
350.02684,144.60000,     -1.10465,     -3.90412,50.00000,20.00000,6.000363e-08,0.73979,4
350.02718,145.20000,     -1.10110,     -3.90961,50.00000,20.00000,5.995662e-08,0.73979,4
350.03551,145.80000,     -1.09754,     -3.91611,50.00000,20.00000,6.004760e-08,0.73978,4
350.03820,146.40000,     -1.09839,     -3.92199,50.00000,20.00000,6.001874e-08,0.73978,4
350.04526,147.00000,     -1.09964,     -3.92878,50.00000,20.00000,6.014531e-08,0.73977,4
350.02166,147.60000,     -1.10057,     -3.93421,50.00000,20.00000,6.017863e-08,0.73979,4
350.03153,148.20000,     -1.09576,     -3.94051,50.00000,20.00000,6.013265e-08,0.73978,4
350.03159,148.80000,     -1.10214,     -3.94677,50.00000,20.00000,6.044349e-08,0.73978,4
350.03292,149.40000,     -1.10470,     -3.95220,50.00000,20.00000,6.028170e-08,0.73978,4
350.02600,150.00000,     -1.10503,     -3.95933,50.00000,20.00000,6.045765e-08,0.73979,4
350.02045,150.60000,     -1.10279,     -3.96204,50.00000,20.00000,6.048944e-08,0.73979,4
350.07214,151.20000,     -1.09869,     -3.96825,50.00000,20.00000,6.056055e-08,0.73974,4
350.02841,151.80000,     -1.10074,     -3.97409,50.00000,20.00000,6.048754e-08,0.73979,4
350.02395,152.40000,     -1.10181,     -3.97946,50.00000,20.00000,6.051233e-08,0.73979,4
350.02527,153.00000,     -1.10020,     -3.98489,50.00000,20.00000,6.060366e-08,0.73979,4
350.03837,153.60000,     -1.09756,     -3.99044,50.00000,20.00000,6.066203e-08,0.73978,4
350.03062,154.20000,     -1.09698,     -3.99530,50.00000,20.00000,6.075904e-08,0.73978,4
350.03960,154.80000,     -1.09658,     -4.00084,50.00000,20.00000,6.070401e-08,0.73977,4
350.03087,155.40000,     -1.09959,     -4.00514,50.00000,20.00000,6.076992e-08,0.73978,4
350.04019,156.00000,     -1.09976,     -4.00922,50.00000,20.00000,6.079783e-08,0.73977,4
350.02733,156.60000,     -1.09856,     -4.01482,50.00000,20.00000,6.082549e-08,0.73979,4
350.02675,157.20000,     -1.09897,     -4.01985,50.00000,20.00000,6.095164e-08,0.73979,4
350.02400,157.80000,     -1.09915,     -4.02528,50.00000,20.00000,6.097878e-08,0.73979,4
350.03790,158.40000,     -1.09681,     -4.03037,50.00000,20.00000,6.085518e-08,0.73978,4
350.02914,159.00000,     -1.09314,     -4.03637,50.00000,20.00000,6.118174e-08,0.73978,4
350.03626,159.60000,     -1.09738,     -4.03908,50.00000,20.00000,6.109783e-08,0.73978,4
350.02332,160.20000,     -1.10023,     -4.04451,50.00000,20.00000,6.117955e-08,0.73979,4
350.01972,160.80000,     -1.09483,     -4.04994,50.00000,20.00000,6.115986e-08,0.73979,4
350.02431,161.40000,     -1.09317,     -4.05402,50.00000,20.00000,6.108684e-08,0.73979,4
350.01715,162.00000,     -1.09607,     -4.05809,50.00000,20.00000,6.124990e-08,0.73980,4
350.02578,162.60000,     -1.09334,     -4.06239,50.00000,20.00000,6.123253e-08,0.73979,4
350.03593,163.20000,     -1.09191,     -4.06782,50.00000,20.00000,6.144552e-08,0.73978,4
350.03711,163.80000,     -1.09319,     -4.07195,50.00000,20.00000,6.139730e-08,0.73978,4
350.03382,164.40000,     -1.09376,     -4.07593,50.00000,20.00000,6.135443e-08,0.73978,4
350.03117,165.00000,     -1.09115,     -4.08105,50.00000,20.00000,6.141205e-08,0.73978,4
350.03547,165.60000,     -1.08886,     -4.08590,50.00000,20.00000,6.150085e-08,0.73978,4
350.02977,166.20000,     -1.08759,     -4.08954,50.00000,20.00000,6.133571e-08,0.73978,4
350.03392,166.80000,     -1.09014,     -4.09575,50.00000,20.00000,6.163656e-08,0.73978,4
350.03008,167.40000,     -1.08925,     -4.09983,50.00000,20.00000,6.169549e-08,0.73978,4
350.02484,168.00000,     -1.09031,     -4.10289,50.00000,20.00000,6.177200e-08,0.73979,4
350.02326,168.60000,     -1.08806,     -4.10831,50.00000,20.00000,6.165540e-08,0.73979,4
350.01594,169.20000,     -1.08760,     -4.11239,50.00000,20.00000,6.163325e-08,0.73980,4
350.01804,169.80000,     -1.08970,     -4.11646,50.00000,20.00000,6.171068e-08,0.73980,4
350.03002,170.40000,     -1.08826,     -4.12054,50.00000,20.00000,6.167360e-08,0.73978,4
350.03381,171.00000,     -1.09031,     -4.12325,50.00000,20.00000,6.183258e-08,0.73978,4
350.02886,171.60000,     -1.08855,     -4.12766,50.00000,20.00000,6.160968e-08,0.73979,4
350.04488,172.20000,     -1.08948,     -4.13038,50.00000,20.00000,6.172498e-08,0.73977,4
350.03506,172.80000,     -1.08961,     -4.13558,50.00000,20.00000,6.189699e-08,0.73978,4
350.03806,173.40000,     -1.09049,     -4.13864,50.00000,20.00000,6.203054e-08,0.73978,4
350.03198,174.00000,     -1.09029,     -4.14350,50.00000,20.00000,6.182286e-08,0.73978,4
350.03073,174.60000,     -1.09091,     -4.14690,50.00000,20.00000,6.205459e-08,0.73978,4
350.03063,175.20000,     -1.09234,     -4.15131,50.00000,20.00000,6.205576e-08,0.73978,4
350.03327,175.80000,     -1.09001,     -4.15538,50.00000,20.00000,6.221028e-08,0.73978,4
350.03012,176.40000,     -1.08863,     -4.15810,50.00000,20.00000,6.203159e-08,0.73978,4
350.03664,177.00000,     -1.08804,     -4.16092,50.00000,20.00000,6.200851e-08,0.73978,4
350.03718,177.60000,     -1.08953,     -4.16500,50.00000,20.00000,6.222990e-08,0.73978,4
350.02797,178.20000,     -1.08978,     -4.16907,50.00000,20.00000,6.216055e-08,0.73979,4
350.04005,178.80000,     -1.08717,     -4.17337,50.00000,20.00000,6.214104e-08,0.73977,4
350.02525,179.40000,     -1.09146,     -4.17608,50.00000,20.00000,6.220149e-08,0.73979,4
350.03873,180.00000,     -1.09076,     -4.17970,50.00000,20.00000,6.220438e-08,0.73978,4
350.02681,180.60000,     -1.08725,     -4.18513,50.00000,20.00000,6.228918e-08,0.73979,4
350.02839,181.20000,     -1.08758,     -4.18932,50.00000,20.00000,6.224031e-08,0.73979,4
350.02837,181.80000,     -1.08866,     -4.19237,50.00000,20.00000,6.228983e-08,0.73979,4
350.02355,182.40000,     -1.09006,     -4.19509,50.00000,20.00000,6.230368e-08,0.73979,4
350.02803,183.00000,     -1.08862,     -4.19803,50.00000,20.00000,6.234465e-08,0.73979,4
350.02118,183.60000,     -1.09002,     -4.20075,50.00000,20.00000,6.243099e-08,0.73979,4
350.02067,184.20000,     -1.08679,     -4.20504,50.00000,20.00000,6.241649e-08,0.73979,4
350.02601,184.80000,     -1.08359,     -4.20776,50.00000,20.00000,6.238262e-08,0.73979,4
350.02227,185.40000,     -1.08558,     -4.21047,50.00000,20.00000,6.246634e-08,0.73979,4
350.03165,186.00000,     -1.08333,     -4.21319,50.00000,20.00000,6.254506e-08,0.73978,4
350.02842,186.60000,     -1.08391,     -4.21692,50.00000,20.00000,6.246148e-08,0.73979,4
350.02279,187.20000,     -1.08402,     -4.22066,50.00000,20.00000,6.255701e-08,0.73979,4
350.01942,187.80000,     -1.08179,     -4.22275,50.00000,20.00000,6.254003e-08,0.73979,4
350.02617,188.40000,     -1.08154,     -4.22677,50.00000,20.00000,6.271705e-08,0.73979,4
350.02986,189.00000,     -1.08015,     -4.22846,50.00000,20.00000,6.254642e-08,0.73978,4
350.02016,189.60000,     -1.07892,     -4.23220,50.00000,20.00000,6.269673e-08,0.73979,4
350.03235,190.20000,     -1.08036,     -4.23525,50.00000,20.00000,6.270364e-08,0.73978,4
350.04199,190.80000,     -1.08242,     -4.23695,50.00000,20.00000,6.267961e-08,0.73977,4
350.03109,191.40000,     -1.08136,     -4.24102,50.00000,20.00000,6.279770e-08,0.73978,4
350.03178,192.00000,     -1.07830,     -4.24441,50.00000,20.00000,6.292608e-08,0.73978,4
350.02985,192.60000,     -1.08600,     -4.24566,50.00000,20.00000,6.279208e-08,0.73978,4
350.02686,193.20000,     -1.08654,     -4.24973,50.00000,20.00000,6.277983e-08,0.73979,4
350.02085,193.80000,     -1.08575,     -4.25109,50.00000,20.00000,6.288473e-08,0.73979,4
350.02427,194.40000,     -1.08569,     -4.25456,50.00000,20.00000,6.280086e-08,0.73979,4
350.03154,195.00000,     -1.08462,     -4.25788,50.00000,20.00000,6.283305e-08,0.73978,4
350.02441,195.60000,     -1.08568,     -4.26059,50.00000,20.00000,6.286565e-08,0.73979,4
350.02829,196.20000,     -1.08593,     -4.26263,50.00000,20.00000,6.280898e-08,0.73979,4
350.03897,196.80000,     -1.08712,     -4.26474,50.00000,20.00000,6.284992e-08,0.73978,4
350.03550,197.40000,     -1.08823,     -4.26746,50.00000,20.00000,6.291346e-08,0.73978,4
350.03966,198.00000,     -1.08629,     -4.27077,50.00000,20.00000,6.297965e-08,0.73977,4
350.03186,198.60000,     -1.08627,     -4.27485,50.00000,20.00000,6.304005e-08,0.73978,4
350.03770,199.20000,     -1.08767,     -4.27508,50.00000,20.00000,6.307483e-08,0.73978,4
350.02334,199.80000,     -1.08754,     -4.27858,50.00000,20.00000,6.316500e-08,0.73979,4
350.03671,200.40000,     -1.08610,     -4.28062,50.00000,20.00000,6.306717e-08,0.73978,4
350.02543,201.00000,     -1.08433,     -4.28411,50.00000,20.00000,6.312546e-08,0.73979,4
350.03158,201.60000,     -1.08703,     -4.28684,50.00000,20.00000,6.321884e-08,0.73978,4
350.02815,202.20000,     -1.08816,     -4.28955,50.00000,20.00000,6.297323e-08,0.73979,4
350.02282,202.80000,     -1.08716,     -4.29227,50.00000,20.00000,6.327669e-08,0.73979,4
350.02552,203.40000,     -1.08642,     -4.29363,50.00000,20.00000,6.315856e-08,0.73979,4
350.03268,204.00000,     -1.08580,     -4.29668,50.00000,20.00000,6.331001e-08,0.73978,4
350.03468,204.60000,     -1.08672,     -4.29804,50.00000,20.00000,6.330414e-08,0.73978,4
350.03446,205.20000,     -1.09080,     -4.30075,50.00000,20.00000,6.313858e-08,0.73978,4
350.02583,205.80000,     -1.09080,     -4.30313,50.00000,20.00000,6.330162e-08,0.73979,4
350.02654,206.40000,     -1.08817,     -4.30550,50.00000,20.00000,6.349261e-08,0.73979,4
350.03507,207.00000,     -1.09094,     -4.30686,50.00000,20.00000,6.340490e-08,0.73978,4
350.02456,207.60000,     -1.09527,     -4.31093,50.00000,20.00000,6.327736e-08,0.73979,4
350.02719,208.20000,     -1.09235,     -4.31229,50.00000,20.00000,6.341080e-08,0.73979,4
350.03442,208.80000,     -1.09349,     -4.31501,50.00000,20.00000,6.340398e-08,0.73978,4
350.02224,209.40000,     -1.09353,     -4.31772,50.00000,20.00000,6.349508e-08,0.73979,4
350.02468,210.00000,     -1.09610,     -4.31942,50.00000,20.00000,6.348441e-08,0.73979,4
350.02390,210.60000,     -1.09586,     -4.32213,50.00000,20.00000,6.359984e-08,0.73979,4
350.01690,211.20000,     -1.09445,     -4.32485,50.00000,20.00000,6.353848e-08,0.73980,4
350.02351,211.80000,     -1.09399,     -4.32451,50.00000,20.00000,6.363191e-08,0.73979,4
350.02285,212.40000,     -1.09472,     -4.32824,50.00000,20.00000,6.346521e-08,0.73979,4
350.03631,213.00000,     -1.09312,     -4.32960,50.00000,20.00000,6.361490e-08,0.73978,4
350.02971,213.60000,     -1.09589,     -4.33438,50.00000,20.00000,6.353333e-08,0.73978,4
350.03203,214.20000,     -1.10111,     -4.33582,50.00000,20.00000,6.352805e-08,0.73978,4
350.02402,214.80000,     -1.10272,     -4.33718,50.00000,20.00000,6.366111e-08,0.73979,4
350.02456,215.40000,     -1.09774,     -4.33990,50.00000,20.00000,6.365877e-08,0.73979,4
350.03715,216.00000,     -1.10125,     -4.34125,50.00000,20.00000,6.354352e-08,0.73978,4
350.03436,216.60000,     -1.10359,     -4.34261,50.00000,20.00000,6.379580e-08,0.73978,4
350.03812,217.20000,     -1.10394,     -4.34499,50.00000,20.00000,6.369945e-08,0.73978,4
350.03779,217.80000,     -1.10250,     -4.34804,50.00000,20.00000,6.374566e-08,0.73978,4
350.03837,218.40000,     -1.10497,     -4.34838,50.00000,20.00000,6.388186e-08,0.73978,4
350.02676,219.00000,     -1.10962,     -4.34974,50.00000,20.00000,6.360206e-08,0.73979,4
350.02905,219.60000,     -1.10885,     -4.35380,50.00000,20.00000,6.384712e-08,0.73978,4
350.04240,220.20000,     -1.10831,     -4.35381,50.00000,20.00000,6.391792e-08,0.73977,4
350.03427,220.80000,     -1.11009,     -4.35517,50.00000,20.00000,6.386903e-08,0.73978,4
350.03571,221.40000,     -1.11069,     -4.35651,50.00000,20.00000,6.399079e-08,0.73978,4
350.03384,222.00000,     -1.11529,     -4.36060,50.00000,20.00000,6.380442e-08,0.73978,4
350.04250,222.60000,     -1.12034,     -4.36196,50.00000,20.00000,6.386325e-08,0.73977,4
350.03258,223.20000,     -1.11975,     -4.36490,50.00000,20.00000,6.383275e-08,0.73978,4
350.02122,223.80000,     -1.11808,     -4.36625,50.00000,20.00000,6.381529e-08,0.73979,4
350.02809,224.40000,     -1.11785,     -4.36897,50.00000,20.00000,6.388283e-08,0.73979,4
350.02597,225.00000,     -1.12345,     -4.37067,50.00000,20.00000,6.373167e-08,0.73979,4
350.03840,225.60000,     -1.12253,     -4.37168,50.00000,20.00000,6.382154e-08,0.73978,4
350.02378,226.20000,     -1.12484,     -4.37541,50.00000,20.00000,6.400475e-08,0.73979,4
350.03564,226.80000,     -1.12548,     -4.37678,50.00000,20.00000,6.411555e-08,0.73978,4
350.02482,227.40000,     -1.12500,     -4.37712,50.00000,20.00000,6.409768e-08,0.73979,4
350.03335,228.00000,     -1.12598,     -4.37915,50.00000,20.00000,6.408368e-08,0.73978,4
350.04115,228.60000,     -1.12755,     -4.38211,50.00000,20.00000,6.414082e-08,0.73977,4
350.03835,229.20000,     -1.13012,     -4.38322,50.00000,20.00000,6.408423e-08,0.73978,4
350.03023,229.80000,     -1.13297,     -4.38594,50.00000,20.00000,6.413093e-08,0.73978,4
350.03258,230.40000,     -1.13524,     -4.38696,50.00000,20.00000,6.415394e-08,0.73978,4
350.02861,231.00000,     -1.13689,     -4.38932,50.00000,20.00000,6.423084e-08,0.73979,4
350.03113,231.60000,     -1.14046,     -4.38933,50.00000,20.00000,6.414192e-08,0.73978,4
350.04015,232.20000,     -1.14334,     -4.39013,50.00000,20.00000,6.398056e-08,0.73977,4
350.02220,232.80000,     -1.14535,     -4.39295,50.00000,20.00000,6.417996e-08,0.73979,4
350.02617,233.40000,     -1.14801,     -4.39454,50.00000,20.00000,6.408865e-08,0.73979,4
350.03023,234.00000,     -1.14499,     -4.39618,50.00000,20.00000,6.420704e-08,0.73978,4
350.02697,234.60000,     -1.14351,     -4.39872,50.00000,20.00000,6.426504e-08,0.73979,4
350.02728,235.20000,     -1.14619,     -4.39872,50.00000,20.00000,6.432030e-08,0.73979,4
350.03590,235.80000,     -1.14932,     -4.40212,50.00000,20.00000,6.414599e-08,0.73978,4
350.03454,236.40000,     -1.15386,     -4.40314,50.00000,20.00000,6.427363e-08,0.73978,4
350.02949,237.00000,     -1.15617,     -4.40393,50.00000,20.00000,6.422723e-08,0.73978,4
350.02238,237.60000,     -1.15707,     -4.40528,50.00000,20.00000,6.430293e-08,0.73979,4
350.02631,238.20000,     -1.15797,     -4.40664,50.00000,20.00000,6.432023e-08,0.73979,4
350.01863,238.80000,     -1.15839,     -4.40800,50.00000,20.00000,6.434037e-08,0.73979,4
350.02776,239.40000,     -1.16053,     -4.41026,50.00000,20.00000,6.433451e-08,0.73979,4
350.03231,240.00000,     -1.16334,     -4.41094,50.00000,20.00000,6.436425e-08,0.73978,4
350.03840,240.60000,     -1.16550,     -4.41467,50.00000,20.00000,6.427952e-08,0.73978,4
350.02912,241.20000,     -1.16600,     -4.41739,50.00000,20.00000,6.423261e-08,0.73978,4
350.03074,241.80000,     -1.16786,     -4.41739,50.00000,20.00000,6.441118e-08,0.73978,4
350.04139,242.40000,     -1.16847,     -4.41954,50.00000,20.00000,6.419116e-08,0.73977,4
350.03693,243.00000,     -1.17114,     -4.41954,50.00000,20.00000,6.430784e-08,0.73978,4
350.02302,243.60000,     -1.17422,     -4.42225,50.00000,20.00000,6.438409e-08,0.73979,4
350.05033,244.20000,     -1.17758,     -4.42497,50.00000,20.00000,6.439392e-08,0.73976,4
350.03836,244.80000,     -1.17776,     -4.42508,50.00000,20.00000,6.447316e-08,0.73978,4
350.04067,245.40000,     -1.17910,     -4.42667,50.00000,20.00000,6.427530e-08,0.73977,4
350.03615,246.00000,     -1.18176,     -4.42848,50.00000,20.00000,6.431242e-08,0.73978,4
350.03715,246.60000,     -1.18084,     -4.42882,50.00000,20.00000,6.445545e-08,0.73978,4
350.03338,247.20000,     -1.18493,     -4.43051,50.00000,20.00000,6.451706e-08,0.73978,4
350.04737,247.80000,     -1.18627,     -4.43050,50.00000,20.00000,6.446899e-08,0.73977,4
350.02415,248.40000,     -1.18797,     -4.43334,50.00000,20.00000,6.461630e-08,0.73979,4
350.02754,249.00000,     -1.18940,     -4.43471,50.00000,20.00000,6.455063e-08,0.73979,4
350.02977,249.60000,     -1.19112,     -4.43628,50.00000,20.00000,6.453220e-08,0.73978,4
350.03481,250.20000,     -1.19029,     -4.43627,50.00000,20.00000,6.453423e-08,0.73978,4
350.04225,250.80000,     -1.19324,     -4.43877,50.00000,20.00000,6.455759e-08,0.73977,4
350.03295,251.40000,     -1.19651,     -4.44013,50.00000,20.00000,6.453547e-08,0.73978,4
350.03591,252.00000,     -1.20007,     -4.44262,50.00000,20.00000,6.458702e-08,0.73978,4
350.02083,252.60000,     -1.19956,     -4.44397,50.00000,20.00000,6.442461e-08,0.73979,4
350.03859,253.20000,     -1.19756,     -4.44533,50.00000,20.00000,6.454147e-08,0.73978,4
350.04281,253.80000,     -1.20068,     -4.44669,50.00000,20.00000,6.469033e-08,0.73977,4
350.03286,254.40000,     -1.20442,     -4.44839,50.00000,20.00000,6.466502e-08,0.73978,4
350.02531,255.00000,     -1.20724,     -4.44793,50.00000,20.00000,6.474347e-08,0.73979,4
350.04143,255.60000,     -1.20680,     -4.44907,50.00000,20.00000,6.478073e-08,0.73977,4
350.04195,256.20000,     -1.20743,     -4.45178,50.00000,20.00000,6.462862e-08,0.73977,4
350.03697,256.80000,     -1.21259,     -4.45356,50.00000,20.00000,6.461413e-08,0.73978,4
350.02959,257.40000,     -1.21430,     -4.45554,50.00000,20.00000,6.456940e-08,0.73978,4
350.03386,258.00000,     -1.21397,     -4.45551,50.00000,20.00000,6.458842e-08,0.73978,4
350.03331,258.60000,     -1.21346,     -4.45540,50.00000,20.00000,6.465771e-08,0.73978,4
350.02678,259.20000,     -1.21733,     -4.45936,50.00000,20.00000,6.465043e-08,0.73979,4
350.04037,259.80000,     -1.21719,     -4.45823,50.00000,20.00000,6.467574e-08,0.73977,4
350.03698,260.40000,     -1.21965,     -4.46015,50.00000,20.00000,6.463847e-08,0.73978,4
350.02593,261.00000,     -1.22189,     -4.46151,50.00000,20.00000,6.461098e-08,0.73979,4
350.04729,261.60000,     -1.22200,     -4.46287,50.00000,20.00000,6.473840e-08,0.73977,4
350.04271,262.20000,     -1.22460,     -4.46287,50.00000,20.00000,6.461963e-08,0.73977,4
350.03888,262.80000,     -1.22866,     -4.46423,50.00000,20.00000,6.481701e-08,0.73978,4
350.03891,263.40000,     -1.22932,     -4.46558,50.00000,20.00000,6.484093e-08,0.73978,4
350.03977,264.00000,     -1.22906,     -4.46592,50.00000,20.00000,6.472611e-08,0.73977,4
350.03814,264.60000,     -1.23173,     -4.46864,50.00000,20.00000,6.476691e-08,0.73978,4
350.04657,265.20000,     -1.23501,     -4.47011,50.00000,20.00000,6.478359e-08,0.73977,4
350.03695,265.80000,     -1.23502,     -4.47011,50.00000,20.00000,6.461748e-08,0.73978,4
350.03141,266.40000,     -1.23601,     -4.47147,50.00000,20.00000,6.470631e-08,0.73978,4
350.03926,267.00000,     -1.23640,     -4.47282,50.00000,20.00000,6.493262e-08,0.73978,4
350.03333,267.60000,     -1.24166,     -4.47282,50.00000,20.00000,6.470156e-08,0.73978,4
350.02773,268.20000,     -1.24187,     -4.47554,50.00000,20.00000,6.486118e-08,0.73979,4
350.04080,268.80000,     -1.24231,     -4.47537,50.00000,20.00000,6.477660e-08,0.73977,4
350.03454,269.40000,     -1.24317,     -4.47633,50.00000,20.00000,6.488293e-08,0.73978,4
350.03798,270.00000,     -1.24880,     -4.47769,50.00000,20.00000,6.489796e-08,0.73978,4
350.03169,270.60000,     -1.24958,     -4.47905,50.00000,20.00000,6.492805e-08,0.73978,4
350.04048,271.20000,     -1.25189,     -4.48074,50.00000,20.00000,6.477036e-08,0.73977,4
350.03632,271.80000,     -1.25467,     -4.48244,50.00000,20.00000,6.485343e-08,0.73978,4
350.02842,272.40000,     -1.25458,     -4.48210,50.00000,20.00000,6.496464e-08,0.73979,4
350.03098,273.00000,     -1.25488,     -4.48278,50.00000,20.00000,6.498185e-08,0.73978,4
350.03620,273.60000,     -1.25778,     -4.48414,50.00000,20.00000,6.497928e-08,0.73978,4
350.03365,274.20000,     -1.26132,     -4.48561,50.00000,20.00000,6.492630e-08,0.73978,4
350.04034,274.80000,     -1.26121,     -4.48730,50.00000,20.00000,6.485630e-08,0.73977,4
350.03153,275.40000,     -1.26154,     -4.48696,50.00000,20.00000,6.494204e-08,0.73978,4
350.04479,276.00000,     -1.26468,     -4.48799,50.00000,20.00000,6.499522e-08,0.73977,4
350.03887,276.60000,     -1.27101,     -4.48968,50.00000,20.00000,6.486992e-08,0.73978,4
350.02827,277.20000,     -1.27337,     -4.49104,50.00000,20.00000,6.509782e-08,0.73979,4
350.03319,277.80000,     -1.27094,     -4.49206,50.00000,20.00000,6.494209e-08,0.73978,4
350.02955,278.40000,     -1.27061,     -4.49364,50.00000,20.00000,6.492654e-08,0.73978,4
350.03329,279.00000,     -1.27503,     -4.49440,50.00000,20.00000,6.508082e-08,0.73978,4
350.02300,279.60000,     -1.27303,     -4.49506,50.00000,20.00000,6.507790e-08,0.73979,4
350.02568,280.20000,     -1.27381,     -4.49635,50.00000,20.00000,6.497042e-08,0.73979,4
350.02315,280.80000,     -1.27783,     -4.49771,50.00000,20.00000,6.498210e-08,0.73979,4
350.02732,281.40000,     -1.27735,     -4.49941,50.00000,20.00000,6.495171e-08,0.73979,4
350.03435,282.00000,     -1.27593,     -4.49941,50.00000,20.00000,6.492167e-08,0.73978,4
352.10799,282.60000,      0.33601,     -4.49067,50.00000,20.00000,6.505002e-08,0.73780,5
357.48883,283.20000,      2.58415,     -4.47201,50.00000,20.00000,6.510484e-08,0.73267,5
362.77286,283.80000,      2.74078,     -4.46570,50.00000,20.00000,6.521351e-08,0.72763,5
367.77622,284.40000,      2.58703,     -4.46161,50.00000,20.00000,6.511854e-08,0.72287,5
373.34216,285.00000,      2.95650,     -4.45744,50.00000,20.00000,6.512408e-08,0.71759,5
379.38360,285.60000,      3.31576,     -4.45336,50.00000,20.00000,6.512484e-08,0.71188,5
385.57860,286.20000,      3.41551,     -4.45065,50.00000,20.00000,6.498438e-08,0.70604,5
391.80569,286.80000,      3.42371,     -4.45201,50.00000,20.00000,6.523866e-08,0.70020,5
398.10376,287.40000,      3.42783,     -4.45473,50.00000,20.00000,6.512908e-08,0.69433,5
404.43174,288.00000,      3.40334,     -4.46152,50.00000,20.00000,6.519258e-08,0.68846,5
410.72973,288.60000,      3.33228,     -4.46978,50.00000,20.00000,6.536297e-08,0.68266,5
417.02070,289.20000,      3.22889,     -4.48359,50.00000,20.00000,6.535688e-08,0.67692,5
423.29668,289.80000,      3.09438,     -4.50169,50.00000,20.00000,6.546756e-08,0.67123,5
429.51559,290.40000,      2.96196,     -4.52230,50.00000,20.00000,6.559460e-08,0.66564,5
435.72460,291.00000,      2.82933,     -4.54458,50.00000,20.00000,6.555252e-08,0.66011,5
441.89860,291.60000,      2.70468,     -4.56709,50.00000,20.00000,6.570452e-08,0.65467,5
448.04652,292.20000,      2.58552,     -4.58915,50.00000,20.00000,6.598254e-08,0.64931,5
454.17246,292.80000,      2.46249,     -4.60906,50.00000,20.00000,6.591800e-08,0.64402,5
460.27346,293.40000,      2.36481,     -4.62556,50.00000,20.00000,6.599463e-08,0.63881,5
466.37444,294.00000,      2.25927,     -4.63506,50.00000,20.00000,6.611477e-08,0.63366,5
472.45846,294.60000,      2.13568,     -4.63777,50.00000,20.00000,6.623214e-08,0.62859,5
478.51441,295.20000,      1.98315,     -4.63573,50.00000,20.00000,6.662731e-08,0.62361,5
484.56339,295.80000,      1.82260,     -4.63279,50.00000,20.00000,6.673103e-08,0.61870,5
490.59736,296.40000,      1.65772,     -4.62804,50.00000,20.00000,6.674550e-08,0.61386,5
496.61031,297.00000,      1.48953,     -4.62249,50.00000,20.00000,6.698686e-08,0.60911,5
502.63235,297.60000,      1.32161,     -4.61842,50.00000,20.00000,6.719886e-08,0.60441,5
508.65837,298.20000,      1.14301,     -4.61458,50.00000,20.00000,6.730572e-08,0.59979,5
514.66937,298.80000,      0.95129,     -4.61151,50.00000,20.00000,6.740200e-08,0.59524,5
520.67440,299.40000,      0.76942,     -4.60744,50.00000,20.00000,6.757523e-08,0.59076,5
526.68233,300.00000,      0.56780,     -4.60472,50.00000,20.00000,6.767551e-08,0.58635,5
532.68037,300.60000,      0.36755,     -4.59929,50.00000,20.00000,6.783953e-08,0.58202,5
538.67536,301.20000,      0.17033,     -4.59658,50.00000,20.00000,6.815065e-08,0.57776,5
544.68831,301.80000,-4.102036e-02,     -4.59250,50.00000,20.00000,6.826110e-08,0.57356,5
550.69236,302.40000,     -0.25969,     -4.58832,50.00000,20.00000,6.831529e-08,0.56943,5
556.68730,303.00000,     -0.48097,     -4.58425,50.00000,20.00000,6.849141e-08,0.56538,5
562.67735,303.60000,     -0.69855,     -4.58154,50.00000,20.00000,6.870851e-08,0.56140,5
568.68535,304.20000,     -0.91970,     -4.57746,50.00000,20.00000,6.889367e-08,0.55748,5
574.66733,304.80000,     -1.15676,     -4.57542,50.00000,20.00000,6.914717e-08,0.55364,5
580.67235,305.40000,     -1.38618,     -4.57271,50.00000,20.00000,6.928364e-08,0.54985,5
586.68630,306.00000,     -1.62279,     -4.56864,50.00000,20.00000,6.949790e-08,0.54613,5
592.68432,306.60000,     -1.87338,     -4.56593,50.00000,20.00000,6.972707e-08,0.54248,5
598.68032,307.20000,     -2.11602,     -4.56320,50.00000,20.00000,6.997946e-08,0.53889,5
604.69233,307.80000,     -2.35316,     -4.56050,50.00000,20.00000,7.011157e-08,0.53536,5
610.68936,308.40000,     -2.61433,     -4.55777,50.00000,20.00000,7.028457e-08,0.53190,5
616.69132,309.00000,     -2.86790,     -4.55507,50.00000,20.00000,7.055812e-08,0.52850,5
622.70633,309.60000,     -3.12737,     -4.55235,50.00000,20.00000,7.080636e-08,0.52515,5
628.69736,310.20000,     -3.39118,     -4.55100,50.00000,20.00000,7.097588e-08,0.52187,5
634.70633,310.80000,     -3.66652,     -4.54725,50.00000,20.00000,7.113899e-08,0.51864,5
640.70929,311.40000,     -3.94483,     -4.54557,50.00000,20.00000,7.143960e-08,0.51546,5
646.71033,312.00000,     -4.22142,     -4.54285,50.00000,20.00000,7.159365e-08,0.51234,5
652.71337,312.60000,     -4.50603,     -4.54115,50.00000,20.00000,7.178644e-08,0.50927,5
658.73036,313.20000,     -4.79157,     -4.53980,50.00000,20.00000,7.192830e-08,0.50625,5
664.73536,313.80000,     -5.09274,     -4.53673,50.00000,20.00000,7.227404e-08,0.50328,5
670.73538,314.40000,     -5.40091,     -4.53471,50.00000,20.00000,7.249823e-08,0.50036,5
676.75038,315.00000,     -5.72084,     -4.53403,50.00000,20.00000,7.252683e-08,0.49747,5
682.77337,315.60000,     -6.02770,     -4.53120,50.00000,20.00000,7.280422e-08,0.49463,5
688.78029,316.20000,     -6.35826,     -4.52848,50.00000,20.00000,7.308273e-08,0.49183,5
694.78939,316.80000,     -6.66211,     -4.52860,50.00000,20.00000,7.335775e-08,0.48907,5
700.80236,317.40000,     -6.99535,     -4.52713,50.00000,20.00000,7.346950e-08,0.48634,5
706.81232,318.00000,     -7.32667,     -4.52577,50.00000,20.00000,7.352490e-08,0.48366,5
712.83335,318.60000,     -7.65046,     -4.52441,50.00000,20.00000,7.374295e-08,0.48100,5
718.84531,319.20000,     -7.97475,     -4.52305,50.00000,20.00000,7.396044e-08,0.47837,5
724.85737,319.80000,     -8.30821,     -4.52170,50.00000,20.00000,7.422620e-08,0.47577,5
730.86031,320.40000,     -8.64414,     -4.51898,50.00000,20.00000,7.426872e-08,0.47321,5
736.87035,321.00000,     -8.96740,     -4.51898,50.00000,20.00000,7.438039e-08,0.47066,5
742.89337,321.60000,     -9.29063,     -4.51627,50.00000,20.00000,7.471919e-08,0.46813,5
748.91735,322.20000,     -9.61007,     -4.51627,50.00000,20.00000,7.476179e-08,0.46562,5
754.93832,322.80000,     -9.94303,     -4.51491,50.00000,20.00000,7.500126e-08,0.46313,5
760.94332,323.40000,    -10.24998,     -4.51287,50.00000,20.00000,7.518753e-08,0.46067,5
766.95231,324.00000,    -10.54963,     -4.51287,50.00000,20.00000,7.522997e-08,0.45821,5
772.97140,324.60000,    -10.86370,     -4.51083,50.00000,20.00000,7.538929e-08,0.45577,5
778.99038,325.20000,    -11.15394,     -4.51015,50.00000,20.00000,7.561674e-08,0.45333,5
785.00538,325.80000,    -11.44915,     -4.51015,50.00000,20.00000,7.567758e-08,0.45091,5
791.00934,326.40000,    -11.75573,     -4.50880,50.00000,20.00000,7.587909e-08,0.44849,5
794.01869,326.70000,    -11.89886,     -4.50859,50.00000,20.00000,7.590570e-08,0.44728,5