File: data/TGA/005c/ExpDat_2024_07_02_PS2439_6_1K_260C_isotherm.csv
#EXPORTTYPE:                 ,DATA ALL
#FILE:                       ,2024_07_02_PS2439_6_1K_260C_isotherm.ngb-ss5
#FORMAT:                     ,NETZSCH5
#FTYPE:                      ,ASCII
#IDENTITY:                   ,PS
#DECIMAL:                    ,POINT
#SEPARATOR:                  ,COMMA
#MTYPE:                      ,DSC
#INSTRUMENT:                 ,NETZSCH STA 449F5
#PROJECT:                    ,
#DATE/TIME:                  ,7/5/2024 12:13:39 AM (UTC-4)
#CORR. FILE:                 ,
#TEMPCAL:                    ,28-06-2023 13:26
#SENSITIVITY:                ,28-06-2023 13:53
#LABORATORY:                 ,
#OPERATOR:                   ,Stanley
#REMARK:                     ,
#SAMPLE:                     ,PS2439_6_1K
#SAMPLE MASS /mg:            ,5.03
#MATERIAL:                   ,
#REFERENCE:                  ,-----
#REFERENCE MASS /mg:         ,0
#TYPE OF CRUCIBLE:           ,Al2O3 85 ‘l, open
#SAMPLE CRUCIBLE MASS /mg:   ,0
#REFERENCE CRUCIBLE MASS /mg:,0
#DSC RANGE /‘V:              ,5000
#TG RANGE /mg:               ,35000
#TAU-R:                      ,---
#CORR. CODE:                 ,000
#EXO:                        ,-1
#RANGE:                      ,30›C....800›C/0.0....10.0K/min
#SEGMENT:                    ,S1-5/5
#SEG. 1:                     ,30›C/10.0(K/min)/100›C
#SEG. 2:                     ,100›C/00:25/100›C
#SEG. 3:                     ,100›C/1.0(K/min)/260›C
#SEG. 4:                     ,260›C/48:00/260›C
#SEG. 5:                     ,260›C/10.0(K/min)/800›C

##Temp./›C,Time/min,DSC/(mW/mg),Mass loss/mg,Gas Flow(purge2)/(ml/min),Gas Flow(protective)/(ml/min),TIC(scan:1)/A,Sensit./(uV/mW),Segment
 34.85900,   0.00000,-8.877085e-02, 0.000000e+00,50.00000,20.00000,6.026056e-08,0.92438,1
 68.13100,   5.70000,      2.21277,      0.36801,50.00000,20.00000,5.724664e-08,0.92593,1
109.18090,  11.40000,      0.52079,      0.25801,50.00000,20.00000,5.573560e-08,0.91853,2
106.38541,  17.10000,     -0.31080,      0.14416,50.00000,20.00000,5.444252e-08,0.91934,2
100.95977,  22.80000,     -0.14730,      0.11127,50.00000,20.00000,5.302844e-08,0.92079,2
 99.64550,  28.50000,-1.545048e-02, 9.057552e-02,50.00000,20.00000,5.189606e-08,0.92111,2
100.52817,  34.20000,      0.14158, 9.000303e-02,50.00000,20.00000,5.090257e-08,0.92090,3
106.39050,  39.90000,      0.30707,      0.10748,50.00000,20.00000,5.039508e-08,0.91934,3
113.08207,  45.60000,      0.29463,      0.11539,50.00000,20.00000,5.005338e-08,0.91732,3
119.04417,  51.30000,      0.27155,      0.12144,50.00000,20.00000,4.981790e-08,0.91532,3
124.73922,  57.00000,      0.27008,      0.12872,50.00000,20.00000,4.975126e-08,0.91324,3
130.42136,  62.70000,      0.26886,      0.13415,50.00000,20.00000,4.966128e-08,0.91099,3
136.11741,  68.40000,      0.26712,      0.14335,50.00000,20.00000,4.964055e-08,0.90857,3
141.82542,  74.10000,      0.26131,      0.15003,50.00000,20.00000,4.963735e-08,0.90598,3
147.54197,  79.80000,      0.25108,      0.15782,50.00000,20.00000,4.970897e-08,0.90323,3
153.21760,  85.50000,      0.24075,      0.16480,50.00000,20.00000,4.979923e-08,0.90035,3
158.93070,  91.20000,      0.22699,      0.16958,50.00000,20.00000,4.983993e-08,0.89730,3
164.64330,  96.90000,      0.21333,      0.17706,50.00000,20.00000,4.997986e-08,0.89411,3
170.35067, 102.60000,      0.19270,      0.18392,50.00000,20.00000,5.006773e-08,0.89078,3
176.05090, 108.30000,      0.17039,      0.18895,50.00000,20.00000,5.018694e-08,0.88731,3
181.74849, 114.00000,      0.14667,      0.19535,50.00000,20.00000,5.023760e-08,0.88372,3
187.44425, 119.70000,      0.11859,      0.20136,50.00000,20.00000,5.037767e-08,0.88000,3
193.15799, 125.40000, 8.915164e-02,      0.20798,50.00000,20.00000,5.045718e-08,0.87614,3
198.84992, 131.10000, 5.756155e-02,      0.21293,50.00000,20.00000,5.059171e-08,0.87218,3
204.54568, 136.80000, 2.326918e-02,      0.21917,50.00000,20.00000,5.072655e-08,0.86811,3
210.24166, 142.50000,-1.457607e-02,      0.22471,50.00000,20.00000,5.088221e-08,0.86392,3
215.94306, 148.20000,-5.264859e-02,      0.23150,50.00000,20.00000,5.101848e-08,0.85963,3
221.64054, 153.90000,-9.272938e-02,      0.23566,50.00000,20.00000,5.116997e-08,0.85524,3
227.34575, 159.60000,     -0.13518,      0.24063,50.00000,20.00000,5.134139e-08,0.85075,3
233.03360, 165.30000,     -0.18412,      0.24594,50.00000,20.00000,5.152713e-08,0.84618,3
238.73587, 171.00000,     -0.23544,      0.25033,50.00000,20.00000,5.164580e-08,0.84152,3
244.43047, 176.70000,     -0.29044,      0.25206,50.00000,20.00000,5.178998e-08,0.83678,3
250.12056, 182.40000,     -0.34692,      0.25450,50.00000,20.00000,5.191336e-08,0.83196,3
255.82012, 188.10000,     -0.40411,      0.25482,50.00000,20.00000,5.204477e-08,0.82707,3
260.55283, 193.80000,     -0.77740,      0.24805,50.00000,20.00000,5.221268e-08,0.82295,4
260.48068, 199.50000,     -0.92243,      0.23705,50.00000,20.00000,5.236985e-08,0.82302,4
260.14439, 205.20000,     -0.90219,      0.22795,50.00000,20.00000,5.240842e-08,0.82331,4
260.03762, 210.90000,     -0.89599,      0.21952,50.00000,20.00000,5.245060e-08,0.82341,4
260.04135, 216.60000,     -0.89178,      0.21191,50.00000,20.00000,5.247213e-08,0.82340,4
260.03350, 222.30000,     -0.89338,      0.20426,50.00000,20.00000,5.246808e-08,0.82341,4
260.00310, 228.00000,     -0.89388,      0.19755,50.00000,20.00000,5.248140e-08,0.82344,4
260.01155, 233.70000,     -0.89293,      0.19230,50.00000,20.00000,5.248022e-08,0.82343,4
260.01675, 239.40000,     -0.89355,      0.18651,50.00000,20.00000,5.246165e-08,0.82342,4
260.00701, 245.10000,     -0.89362,      0.17840,50.00000,20.00000,5.248203e-08,0.82343,4
260.02503, 250.80000,     -0.89247,      0.17363,50.00000,20.00000,5.250811e-08,0.82342,4
260.01237, 256.50000,     -0.89232,      0.16686,50.00000,20.00000,5.246445e-08,0.82343,4
260.00646, 262.20000,     -0.89534,      0.16154,50.00000,20.00000,5.246799e-08,0.82343,4
260.01809, 267.90000,     -0.89384,      0.15699,50.00000,20.00000,5.248872e-08,0.82342,4
260.01692, 273.60000,     -0.89558,      0.14990,50.00000,20.00000,5.250978e-08,0.82342,4
260.03756, 279.30000,     -0.89120,      0.14454,50.00000,20.00000,5.246803e-08,0.82341,4
260.01266, 285.00000,     -0.89598,      0.13853,50.00000,20.00000,5.248049e-08,0.82343,4
260.01598, 290.70000,     -0.89636,      0.13443,50.00000,20.00000,5.249016e-08,0.82342,4
260.01600, 296.40000,     -0.89739,      0.12882,50.00000,20.00000,5.247115e-08,0.82342,4
260.01399, 302.10000,     -0.89745,      0.12461,50.00000,20.00000,5.247012e-08,0.82343,4
260.02672, 307.80000,     -0.89507,      0.11813,50.00000,20.00000,5.252982e-08,0.82341,4
260.02477, 313.50000,     -0.89574,      0.11308,50.00000,20.00000,5.251556e-08,0.82342,4
260.01535, 319.20000,     -0.89570,      0.10905,50.00000,20.00000,5.254108e-08,0.82342,4
260.00957, 324.90000,     -0.89613,      0.10505,50.00000,20.00000,5.254336e-08,0.82343,4
260.01875, 330.60000,     -0.89642,      0.10008,50.00000,20.00000,5.257288e-08,0.82342,4
260.01872, 336.30000,     -0.89444, 9.367094e-02,50.00000,20.00000,5.247977e-08,0.82342,4
260.01614, 342.00000,     -0.89531, 9.059181e-02,50.00000,20.00000,5.255839e-08,0.82342,4
260.01409, 347.70000,     -0.89553, 8.520985e-02,50.00000,20.00000,5.257485e-08,0.82343,4
260.01806, 353.40000,     -0.89405, 8.092348e-02,50.00000,20.00000,5.258309e-08,0.82342,4
260.01448, 359.10000,     -0.89191, 7.457612e-02,50.00000,20.00000,5.258676e-08,0.82343,4
260.00497, 364.80000,     -0.89813, 7.167538e-02,50.00000,20.00000,5.259665e-08,0.82343,4
260.01750, 370.50000,     -0.89560, 6.756444e-02,50.00000,20.00000,5.256658e-08,0.82342,4
260.01149, 376.20000,     -0.89653, 6.127649e-02,50.00000,20.00000,5.254335e-08,0.82343,4
260.00864, 381.90000,     -0.89713, 5.628856e-02,50.00000,20.00000,5.255557e-08,0.82343,4
260.02351, 387.60000,     -0.89444, 5.229369e-02,50.00000,20.00000,5.253578e-08,0.82342,4
260.02420, 393.30000,     -0.89784, 4.735030e-02,50.00000,20.00000,5.253999e-08,0.82342,4
260.01530, 399.00000,     -0.89641, 4.149259e-02,50.00000,20.00000,5.252358e-08,0.82342,4
260.01828, 404.70000,     -0.89677, 3.852733e-02,50.00000,20.00000,5.251639e-08,0.82342,4
260.01803, 410.40000,     -0.89507, 3.327649e-02,50.00000,20.00000,5.257706e-08,0.82342,4
260.02007, 416.10000,     -0.89820, 2.995204e-02,50.00000,20.00000,5.258383e-08,0.82342,4
260.01395, 421.80000,     -0.89379, 2.567225e-02,50.00000,20.00000,5.254055e-08,0.82343,4
260.02017, 427.50000,     -0.89396, 2.233190e-02,50.00000,20.00000,5.257212e-08,0.82342,4
260.02004, 433.20000,     -0.89551, 1.775757e-02,50.00000,20.00000,5.259800e-08,0.82342,4
260.01374, 438.90000,     -0.89442, 1.403101e-02,50.00000,20.00000,5.261722e-08,0.82343,4
260.00823, 444.60000,     -0.89255, 8.980430e-03,50.00000,20.00000,5.260556e-08,0.82343,4
260.00491, 450.30000,     -0.89439, 3.695906e-03,50.00000,20.00000,5.256828e-08,0.82343,4
260.01778, 456.00000,     -0.89509, 3.606551e-04,50.00000,20.00000,5.258984e-08,0.82342,4
260.02836, 461.70000,     -0.89587,-4.988696e-03,50.00000,20.00000,5.254417e-08,0.82341,4
260.01625, 467.40000,     -0.89525,-7.825034e-03,50.00000,20.00000,5.260257e-08,0.82342,4
260.02250, 473.10000,     -0.89425,-1.168570e-02,50.00000,20.00000,5.257485e-08,0.82342,4
260.02226, 478.80000,     -0.89643,-1.652305e-02,50.00000,20.00000,5.259229e-08,0.82342,4
260.01042, 484.50000,     -0.89471,-2.105739e-02,50.00000,20.00000,5.255478e-08,0.82343,4
260.01006, 490.20000,     -0.89730,-2.382889e-02,50.00000,20.00000,5.254386e-08,0.82343,4
260.01769, 495.90000,     -0.89573,-3.007631e-02,50.00000,20.00000,5.253670e-08,0.82342,4
260.02427, 501.60000,     -0.89221,-3.123112e-02,50.00000,20.00000,5.256379e-08,0.82342,4
260.00599, 507.30000,     -0.89493,-3.405211e-02,50.00000,20.00000,5.259134e-08,0.82343,4
259.99931, 513.00000,     -0.89383,-3.736076e-02,50.00000,20.00000,5.259849e-08,0.82344,4
260.01089, 518.70000,     -0.89605,-4.428089e-02,50.00000,20.00000,5.256864e-08,0.82343,4
260.01705, 524.40000,     -0.89508,-4.565979e-02,50.00000,20.00000,5.261271e-08,0.82342,4
260.01059, 530.10000,     -0.89657,-4.917614e-02,50.00000,20.00000,5.255405e-08,0.82343,4
260.01808, 535.80000,     -0.89655,-5.378607e-02,50.00000,20.00000,5.257603e-08,0.82342,4
260.02688, 541.50000,     -0.89565,-5.598058e-02,50.00000,20.00000,5.257385e-08,0.82341,4
260.01908, 547.20000,     -0.89587,-6.041795e-02,50.00000,20.00000,5.255276e-08,0.82342,4
260.02299, 552.90000,     -0.89576,-6.327523e-02,50.00000,20.00000,5.255524e-08,0.82342,4
260.02205, 558.60000,     -0.89556,-6.732924e-02,50.00000,20.00000,5.254190e-08,0.82342,4
260.01987, 564.30000,     -0.89928,-7.007892e-02,50.00000,20.00000,5.254024e-08,0.82342,4
260.01304, 570.00000,     -0.89896,-7.538326e-02,50.00000,20.00000,5.254605e-08,0.82343,4
260.01224, 575.70000,     -0.89461,-7.871425e-02,50.00000,20.00000,5.251196e-08,0.82343,4
260.01817, 581.40000,     -0.89786,-8.156700e-02,50.00000,20.00000,5.249419e-08,0.82342,4
260.01410, 587.10000,     -0.89762,-8.485099e-02,50.00000,20.00000,5.252269e-08,0.82343,4
260.01384, 592.80000,     -0.89673,-8.863687e-02,50.00000,20.00000,5.245835e-08,0.82343,4
260.02881, 598.50000,     -0.89683,-9.150360e-02,50.00000,20.00000,5.248036e-08,0.82341,4
260.02521, 604.20000,     -0.89537,-9.435034e-02,50.00000,20.00000,5.249896e-08,0.82342,4
260.01732, 609.90000,     -0.89556,-9.857445e-02,50.00000,20.00000,5.249452e-08,0.82342,4
260.01122, 615.60000,     -0.89475,     -0.10153,50.00000,20.00000,5.248487e-08,0.82343,4
260.01744, 621.30000,     -0.90010,     -0.10583,50.00000,20.00000,5.249626e-08,0.82342,4
260.01822, 627.00000,     -0.89557,     -0.10878,50.00000,20.00000,5.244839e-08,0.82342,4
260.01187, 632.70000,     -0.89702,     -0.11105,50.00000,20.00000,5.248367e-08,0.82343,4
260.02419, 638.40000,     -0.89707,     -0.11371,50.00000,20.00000,5.250129e-08,0.82342,4
260.01446, 644.10000,     -0.89891,     -0.11788,50.00000,20.00000,5.249867e-08,0.82343,4
260.01529, 649.80000,     -0.89786,     -0.12292,50.00000,20.00000,5.243617e-08,0.82342,4
260.03037, 655.50000,     -0.89829,     -0.12581,50.00000,20.00000,5.245705e-08,0.82341,4
260.01564, 661.20000,     -0.89474,     -0.12692,50.00000,20.00000,5.242930e-08,0.82342,4
260.01341, 666.90000,     -0.89765,     -0.12951,50.00000,20.00000,5.247499e-08,0.82343,4
260.02026, 672.60000,     -0.89677,     -0.13244,50.00000,20.00000,5.250255e-08,0.82342,4
260.01703, 678.30000,     -0.89562,     -0.13505,50.00000,20.00000,5.246146e-08,0.82342,4
260.01302, 684.00000,     -0.89919,     -0.13778,50.00000,20.00000,5.247378e-08,0.82343,4
260.00630, 689.70000,     -0.89592,     -0.14284,50.00000,20.00000,5.245446e-08,0.82343,4
260.01079, 695.40000,     -0.89842,     -0.14551,50.00000,20.00000,5.240786e-08,0.82343,4
260.01793, 701.10000,     -0.89836,     -0.15116,50.00000,20.00000,5.240056e-08,0.82342,4
260.03186, 706.80000,     -0.89787,     -0.15260,50.00000,20.00000,5.240342e-08,0.82341,4
260.02195, 712.50000,     -0.89895,     -0.15579,50.00000,20.00000,5.242355e-08,0.82342,4
260.02570, 718.20000,     -0.89783,     -0.15675,50.00000,20.00000,5.239879e-08,0.82342,4
260.00739, 723.90000,     -0.89822,     -0.15996,50.00000,20.00000,5.244471e-08,0.82343,4
260.01653, 729.60000,     -0.89599,     -0.16436,50.00000,20.00000,5.242743e-08,0.82342,4
260.01460, 735.30000,     -0.89750,     -0.16475,50.00000,20.00000,5.241117e-08,0.82343,4
260.02301, 741.00000,     -0.89620,     -0.16779,50.00000,20.00000,5.242504e-08,0.82342,4
260.01723, 746.70000,     -0.89495,     -0.16957,50.00000,20.00000,5.242552e-08,0.82342,4
260.01933, 752.40000,     -0.89842,     -0.17361,50.00000,20.00000,5.242404e-08,0.82342,4
259.99805, 758.10000,     -0.89513,     -0.17642,50.00000,20.00000,5.240706e-08,0.82344,4
260.01995, 763.80000,     -0.89957,     -0.17929,50.00000,20.00000,5.234987e-08,0.82342,4
260.01565, 769.50000,     -0.89708,     -0.18293,50.00000,20.00000,5.232558e-08,0.82342,4
260.01715, 775.20000,     -0.90029,     -0.18461,50.00000,20.00000,5.236715e-08,0.82342,4
260.02618, 780.90000,     -0.89624,     -0.18665,50.00000,20.00000,5.236416e-08,0.82342,4
260.01733, 786.60000,     -0.89804,     -0.18655,50.00000,20.00000,5.240130e-08,0.82342,4
260.02674, 792.30000,     -0.89655,     -0.18948,50.00000,20.00000,5.239865e-08,0.82341,4
260.02185, 798.00000,     -0.89742,     -0.19307,50.00000,20.00000,5.241090e-08,0.82342,4
260.00421, 803.70000,     -0.89825,     -0.19463,50.00000,20.00000,5.239938e-08,0.82343,4
260.00845, 809.40000,     -0.89752,     -0.19786,50.00000,20.00000,5.239458e-08,0.82343,4
260.00818, 815.10000,     -0.89767,     -0.20063,50.00000,20.00000,5.239909e-08,0.82343,4
260.02678, 820.80000,     -0.90038,     -0.20407,50.00000,20.00000,5.238498e-08,0.82341,4
260.01123, 826.50000,     -0.89938,     -0.20746,50.00000,20.00000,5.234603e-08,0.82343,4
260.00060, 832.20000,     -0.89999,     -0.21081,50.00000,20.00000,5.233379e-08,0.82344,4
260.01808, 837.90000,     -0.89749,     -0.21275,50.00000,20.00000,5.234744e-08,0.82342,4
260.02252, 843.60000,     -0.89740,     -0.21423,50.00000,20.00000,5.237122e-08,0.82342,4
260.03011, 849.30000,     -0.89785,     -0.21850,50.00000,20.00000,5.234380e-08,0.82341,4
260.01483, 855.00000,     -0.89694,     -0.22002,50.00000,20.00000,5.236443e-08,0.82342,4
260.01059, 860.70000,     -0.89531,     -0.22116,50.00000,20.00000,5.239181e-08,0.82343,4
260.02444, 866.40000,     -0.89742,     -0.22453,50.00000,20.00000,5.236564e-08,0.82342,4
260.00041, 872.10000,     -0.89607,     -0.22694,50.00000,20.00000,5.238458e-08,0.82344,4
260.00888, 877.80000,     -0.89727,     -0.22997,50.00000,20.00000,5.236040e-08,0.82343,4
260.02705, 883.50000,     -0.89617,     -0.23222,50.00000,20.00000,5.239545e-08,0.82341,4
260.01781, 889.20000,     -0.89719,     -0.23531,50.00000,20.00000,5.232586e-08,0.82342,4
260.02025, 894.90000,     -0.89823,     -0.23742,50.00000,20.00000,5.234922e-08,0.82342,4
260.01615, 900.60000,     -0.90105,     -0.24148,50.00000,20.00000,5.234067e-08,0.82342,4
260.01936, 906.30000,     -0.89922,     -0.24479,50.00000,20.00000,5.231427e-08,0.82342,4
260.01595, 912.00000,     -0.90144,     -0.24622,50.00000,20.00000,5.231901e-08,0.82342,4
260.01140, 917.70000,     -0.90126,     -0.24809,50.00000,20.00000,5.230807e-08,0.82343,4
260.00836, 923.40000,     -0.90089,     -0.25287,50.00000,20.00000,5.228819e-08,0.82343,4
260.03053, 929.10000,     -0.89993,     -0.25437,50.00000,20.00000,5.231675e-08,0.82341,4
260.01745, 934.80000,     -0.90032,     -0.25673,50.00000,20.00000,5.218857e-08,0.82342,4
260.02106, 940.50000,     -0.89878,     -0.25513,50.00000,20.00000,5.226516e-08,0.82342,4
260.00896, 946.20000,     -0.89931,     -0.25936,50.00000,20.00000,5.228729e-08,0.82343,4
260.02044, 951.90000,     -0.89636,     -0.26055,50.00000,20.00000,5.223001e-08,0.82342,4
260.01081, 957.60000,     -0.89753,     -0.26278,50.00000,20.00000,5.224672e-08,0.82343,4
260.01816, 963.30000,     -0.89659,     -0.26695,50.00000,20.00000,5.224960e-08,0.82342,4
260.02457, 969.00000,     -0.89552,     -0.26948,50.00000,20.00000,5.222712e-08,0.82342,4
260.01362, 974.70000,     -0.89563,     -0.27207,50.00000,20.00000,5.217977e-08,0.82343,4
260.02104, 980.40000,     -0.89976,     -0.27628,50.00000,20.00000,5.223429e-08,0.82342,4
260.00824, 986.10000,     -0.89671,     -0.27712,50.00000,20.00000,5.219906e-08,0.82343,4
260.00778, 991.80000,     -0.89751,     -0.27932,50.00000,20.00000,5.221092e-08,0.82343,4
260.02498, 997.50000,     -0.89828,     -0.28195,50.00000,20.00000,5.216357e-08,0.82342,4
260.01719,1003.20000,     -0.89961,     -0.28389,50.00000,20.00000,5.214631e-08,0.82342,4
260.01786,1008.90000,     -0.89831,     -0.28688,50.00000,20.00000,5.212417e-08,0.82342,4
260.01909,1014.60000,     -0.89955,     -0.28967,50.00000,20.00000,5.214065e-08,0.82342,4
260.01461,1020.30000,     -0.89732,     -0.29001,50.00000,20.00000,5.217021e-08,0.82343,4
260.02158,1026.00000,     -0.89907,     -0.29418,50.00000,20.00000,5.216673e-08,0.82342,4
260.01252,1031.70000,     -0.89959,     -0.29528,50.00000,20.00000,5.211668e-08,0.82343,4
260.01625,1037.40000,     -0.89867,     -0.29737,50.00000,20.00000,5.211075e-08,0.82342,4
260.01418,1043.10000,     -0.89901,     -0.29830,50.00000,20.00000,5.208882e-08,0.82343,4
260.01931,1048.80000,     -0.89755,     -0.30061,50.00000,20.00000,5.213083e-08,0.82342,4
260.00970,1054.50000,     -0.89538,     -0.30246,50.00000,20.00000,5.219714e-08,0.82343,4
260.02333,1060.20000,     -0.89737,     -0.30422,50.00000,20.00000,5.218853e-08,0.82342,4
260.00577,1065.90000,     -0.89794,     -0.30674,50.00000,20.00000,5.215859e-08,0.82343,4
260.01838,1071.60000,     -0.89836,     -0.30795,50.00000,20.00000,5.220744e-08,0.82342,4
259.99399,1077.30000,     -0.89662,     -0.31058,50.00000,20.00000,5.219647e-08,0.82344,4
260.01183,1083.00000,     -0.90209,     -0.31468,50.00000,20.00000,5.221658e-08,0.82343,4
260.00964,1088.70000,     -0.89774,     -0.31531,50.00000,20.00000,5.222429e-08,0.82343,4
260.01668,1094.40000,     -0.89765,     -0.31674,50.00000,20.00000,5.218488e-08,0.82342,4
260.01465,1100.10000,     -0.90065,     -0.32103,50.00000,20.00000,5.214066e-08,0.82343,4
260.01186,1105.80000,     -0.90095,     -0.32132,50.00000,20.00000,5.213770e-08,0.82343,4
260.01502,1111.50000,     -0.89994,     -0.32422,50.00000,20.00000,5.212417e-08,0.82342,4
260.01519,1117.20000,     -0.90021,     -0.32874,50.00000,20.00000,5.213578e-08,0.82342,4
260.02073,1122.90000,     -0.89841,     -0.33147,50.00000,20.00000,5.211324e-08,0.82342,4
260.01142,1128.60000,     -0.89498,     -0.33289,50.00000,20.00000,5.212477e-08,0.82343,4
260.01624,1134.30000,     -0.89620,     -0.33680,50.00000,20.00000,5.207284e-08,0.82342,4
260.00678,1140.00000,     -0.89673,     -0.33797,50.00000,20.00000,5.211561e-08,0.82343,4
260.00445,1145.70000,     -0.89809,     -0.33950,50.00000,20.00000,5.208964e-08,0.82343,4
260.02172,1151.40000,     -0.89863,     -0.34248,50.00000,20.00000,5.208127e-08,0.82342,4
260.02169,1157.10000,     -0.89875,     -0.34570,50.00000,20.00000,5.211058e-08,0.82342,4
260.02087,1162.80000,     -0.89917,     -0.34800,50.00000,20.00000,5.209043e-08,0.82342,4
260.02806,1168.50000,     -0.89886,     -0.34826,50.00000,20.00000,5.208275e-08,0.82341,4
260.01459,1174.20000,     -0.90025,     -0.34950,50.00000,20.00000,5.203922e-08,0.82343,4
260.00101,1179.90000,     -0.89903,     -0.35079,50.00000,20.00000,5.203443e-08,0.82344,4
260.02633,1185.60000,     -0.89755,     -0.35099,50.00000,20.00000,5.210539e-08,0.82341,4
260.01223,1191.30000,     -0.89926,     -0.35298,50.00000,20.00000,5.210260e-08,0.82343,4
260.03208,1197.00000,     -0.89650,     -0.35550,50.00000,20.00000,5.207753e-08,0.82341,4
260.01314,1202.70000,     -0.89811,     -0.35836,50.00000,20.00000,5.208310e-08,0.82343,4
260.01116,1208.40000,     -0.89584,     -0.35982,50.00000,20.00000,5.206383e-08,0.82343,4
260.01572,1214.10000,     -0.89572,     -0.36243,50.00000,20.00000,5.208224e-08,0.82342,4
260.01339,1219.80000,     -0.89738,     -0.36587,50.00000,20.00000,5.204123e-08,0.82343,4
260.02144,1225.50000,     -0.89840,     -0.36815,50.00000,20.00000,5.199323e-08,0.82342,4
260.02439,1231.20000,     -0.89859,     -0.36978,50.00000,20.00000,5.202993e-08,0.82342,4
260.02644,1236.90000,     -0.89936,     -0.37214,50.00000,20.00000,5.203939e-08,0.82341,4
260.00589,1242.60000,     -0.89763,     -0.37497,50.00000,20.00000,5.200232e-08,0.82343,4
260.01204,1248.30000,     -0.89816,     -0.37539,50.00000,20.00000,5.204461e-08,0.82343,4
260.01300,1254.00000,     -0.89807,     -0.37732,50.00000,20.00000,5.207338e-08,0.82343,4
260.02502,1259.70000,     -0.89754,     -0.37878,50.00000,20.00000,5.202419e-08,0.82342,4
260.01384,1265.40000,     -0.89925,     -0.38303,50.00000,20.00000,5.201189e-08,0.82343,4
260.02746,1271.10000,     -0.89894,     -0.38231,50.00000,20.00000,5.197889e-08,0.82341,4
260.01936,1276.80000,     -0.90123,     -0.38405,50.00000,20.00000,5.201209e-08,0.82342,4
260.01167,1282.50000,     -0.90087,     -0.38630,50.00000,20.00000,5.203263e-08,0.82343,4
260.01574,1288.20000,     -0.89881,     -0.38721,50.00000,20.00000,5.206997e-08,0.82342,4
260.02465,1293.90000,     -0.89858,     -0.39139,50.00000,20.00000,5.211697e-08,0.82342,4
260.01965,1299.60000,     -0.89949,     -0.39167,50.00000,20.00000,5.207985e-08,0.82342,4
260.01681,1305.30000,     -0.89919,     -0.39267,50.00000,20.00000,5.214126e-08,0.82342,4
260.02119,1311.00000,     -0.89973,     -0.39410,50.00000,20.00000,5.214096e-08,0.82342,4
260.01181,1316.70000,     -0.89851,     -0.39672,50.00000,20.00000,5.210299e-08,0.82343,4
260.01112,1322.40000,     -0.90034,     -0.39733,50.00000,20.00000,5.208545e-08,0.82343,4
260.00841,1328.10000,     -0.89882,     -0.40082,50.00000,20.00000,5.208568e-08,0.82343,4
260.02698,1333.80000,     -0.90016,     -0.40329,50.00000,20.00000,5.202021e-08,0.82341,4
260.01804,1339.50000,     -0.90071,     -0.40502,50.00000,20.00000,5.206728e-08,0.82342,4
260.03312,1345.20000,     -0.90035,     -0.40635,50.00000,20.00000,5.204127e-08,0.82341,4
260.02293,1350.90000,     -0.90155,     -0.40875,50.00000,20.00000,5.204332e-08,0.82342,4
260.01360,1356.60000,     -0.89968,     -0.41063,50.00000,20.00000,5.202655e-08,0.82343,4
260.01463,1362.30000,     -0.90174,     -0.41203,50.00000,20.00000,5.206270e-08,0.82343,4
260.01651,1368.00000,     -0.90124,     -0.41424,50.00000,20.00000,5.202420e-08,0.82342,4
260.01469,1373.70000,     -0.90110,     -0.41588,50.00000,20.00000,5.202066e-08,0.82343,4
260.01335,1379.40000,     -0.89993,     -0.41941,50.00000,20.00000,5.199478e-08,0.82343,4
260.01668,1385.10000,     -0.89787,     -0.41986,50.00000,20.00000,5.201154e-08,0.82342,4
260.01190,1390.80000,     -0.89740,     -0.42307,50.00000,20.00000,5.200796e-08,0.82343,4
260.01369,1396.50000,     -0.89748,     -0.42300,50.00000,20.00000,5.202441e-08,0.82343,4
260.01334,1402.20000,     -0.89934,     -0.42409,50.00000,20.00000,5.204749e-08,0.82343,4
260.01178,1407.90000,     -0.89861,     -0.42764,50.00000,20.00000,5.199135e-08,0.82343,4
260.02068,1413.60000,     -0.89624,     -0.42978,50.00000,20.00000,5.200054e-08,0.82342,4
260.01929,1419.30000,     -0.89536,     -0.43116,50.00000,20.00000,5.204207e-08,0.82342,4
260.03230,1425.00000,     -0.89672,     -0.43230,50.00000,20.00000,5.197969e-08,0.82341,4
260.03018,1430.70000,     -0.89729,     -0.43622,50.00000,20.00000,5.195483e-08,0.82341,4
260.01992,1436.40000,     -0.89662,     -0.43686,50.00000,20.00000,5.195926e-08,0.82342,4
260.02081,1442.10000,     -0.89867,     -0.43907,50.00000,20.00000,5.199918e-08,0.82342,4
260.01323,1447.80000,     -0.90017,     -0.44101,50.00000,20.00000,5.195640e-08,0.82343,4
260.02437,1453.50000,     -0.89965,     -0.44315,50.00000,20.00000,5.193869e-08,0.82342,4
260.01671,1459.20000,     -0.89961,     -0.44559,50.00000,20.00000,5.193941e-08,0.82342,4
260.02807,1464.90000,     -0.89884,     -0.44674,50.00000,20.00000,5.195325e-08,0.82341,4
260.01619,1470.60000,     -0.90027,     -0.44818,50.00000,20.00000,5.194021e-08,0.82342,4
260.02312,1476.30000,     -0.89976,     -0.45120,50.00000,20.00000,5.193464e-08,0.82342,4
260.01765,1482.00000,     -0.90061,     -0.45326,50.00000,20.00000,5.194207e-08,0.82342,4
260.00913,1487.70000,     -0.89993,     -0.45536,50.00000,20.00000,5.191946e-08,0.82343,4
260.01430,1493.40000,     -0.89801,     -0.45838,50.00000,20.00000,5.192597e-08,0.82343,4
260.00701,1499.10000,     -0.90097,     -0.45983,50.00000,20.00000,5.194497e-08,0.82343,4
260.01735,1504.80000,     -0.89812,     -0.46103,50.00000,20.00000,5.196683e-08,0.82342,4
260.02821,1510.50000,     -0.89547,     -0.46337,50.00000,20.00000,5.193720e-08,0.82341,4
260.01664,1516.20000,     -0.89702,     -0.46488,50.00000,20.00000,5.191092e-08,0.82342,4
260.01872,1521.90000,     -0.89766,     -0.46625,50.00000,20.00000,5.191299e-08,0.82342,4
260.01713,1527.60000,     -0.89639,     -0.46927,50.00000,20.00000,5.191024e-08,0.82342,4
260.02747,1533.30000,     -0.89733,     -0.47093,50.00000,20.00000,5.184124e-08,0.82341,4
260.01156,1539.00000,     -0.89886,     -0.47297,50.00000,20.00000,5.185157e-08,0.82343,4
260.00751,1544.70000,     -0.90058,     -0.47615,50.00000,20.00000,5.181342e-08,0.82343,4
260.01946,1550.40000,     -0.89765,     -0.47748,50.00000,20.00000,5.181953e-08,0.82342,4
260.01718,1556.10000,     -0.89882,     -0.47869,50.00000,20.00000,5.183217e-08,0.82342,4
260.00154,1561.80000,     -0.89851,     -0.48072,50.00000,20.00000,5.183606e-08,0.82344,4
260.01985,1567.50000,     -0.89795,     -0.48104,50.00000,20.00000,5.185127e-08,0.82342,4
260.01135,1573.20000,     -0.89899,     -0.48472,50.00000,20.00000,5.179666e-08,0.82343,4
260.02336,1578.90000,     -0.89928,     -0.48533,50.00000,20.00000,5.183204e-08,0.82342,4
260.01884,1584.60000,     -0.89849,     -0.48726,50.00000,20.00000,5.178043e-08,0.82342,4
260.01736,1590.30000,     -0.89890,     -0.48766,50.00000,20.00000,5.178062e-08,0.82342,4
260.02099,1596.00000,     -0.89955,     -0.49127,50.00000,20.00000,5.178543e-08,0.82342,4
260.03091,1601.70000,     -0.90093,     -0.49322,50.00000,20.00000,5.179515e-08,0.82341,4
260.01289,1607.40000,     -0.89992,     -0.49583,50.00000,20.00000,5.173922e-08,0.82343,4
260.01322,1613.10000,     -0.89976,     -0.49619,50.00000,20.00000,5.178292e-08,0.82343,4
260.01430,1618.80000,     -0.90090,     -0.49914,50.00000,20.00000,5.175888e-08,0.82343,4
260.01517,1624.50000,     -0.90138,     -0.50100,50.00000,20.00000,5.175845e-08,0.82342,4
260.01376,1630.20000,     -0.89779,     -0.50077,50.00000,20.00000,5.176157e-08,0.82343,4
260.01092,1635.90000,     -0.90055,     -0.50287,50.00000,20.00000,5.177272e-08,0.82343,4
260.01889,1641.60000,     -0.89730,     -0.50501,50.00000,20.00000,5.174909e-08,0.82342,4
260.02494,1647.30000,     -0.89894,     -0.50549,50.00000,20.00000,5.174823e-08,0.82342,4
260.02626,1653.00000,     -0.89815,     -0.50879,50.00000,20.00000,5.170146e-08,0.82342,4
260.02229,1658.70000,     -0.89821,     -0.50954,50.00000,20.00000,5.174511e-08,0.82342,4
260.01351,1664.40000,     -0.90194,     -0.51103,50.00000,20.00000,5.173016e-08,0.82343,4
260.02014,1670.10000,     -0.90266,     -0.51286,50.00000,20.00000,5.175422e-08,0.82342,4
260.01018,1675.80000,     -0.90053,     -0.51494,50.00000,20.00000,5.174788e-08,0.82343,4
260.01671,1681.50000,     -0.89737,     -0.51611,50.00000,20.00000,5.172162e-08,0.82342,4
260.02408,1687.20000,     -0.89853,     -0.51815,50.00000,20.00000,5.173692e-08,0.82342,4
260.00995,1692.90000,     -0.89887,     -0.52155,50.00000,20.00000,5.173433e-08,0.82343,4
260.01379,1698.60000,     -0.90049,     -0.52186,50.00000,20.00000,5.167859e-08,0.82343,4
260.02209,1704.30000,     -0.89725,     -0.52501,50.00000,20.00000,5.169256e-08,0.82342,4
260.01279,1710.00000,     -0.89817,     -0.52737,50.00000,20.00000,5.168178e-08,0.82343,4
260.02707,1715.70000,     -0.89674,     -0.52925,50.00000,20.00000,5.169908e-08,0.82341,4
260.00553,1721.40000,     -0.89901,     -0.53172,50.00000,20.00000,5.165018e-08,0.82343,4
260.00713,1727.10000,     -0.89685,     -0.53159,50.00000,20.00000,5.168372e-08,0.82343,4
260.01308,1732.80000,     -0.90105,     -0.53377,50.00000,20.00000,5.166573e-08,0.82343,4
260.01651,1738.50000,     -0.89905,     -0.53610,50.00000,20.00000,5.164025e-08,0.82342,4
260.01695,1744.20000,     -0.89821,     -0.53665,50.00000,20.00000,5.167627e-08,0.82342,4
260.02185,1749.90000,     -0.89941,     -0.53952,50.00000,20.00000,5.162539e-08,0.82342,4
260.00612,1755.60000,     -0.89610,     -0.54188,50.00000,20.00000,5.167341e-08,0.82343,4
260.02428,1761.30000,     -0.89955,     -0.54276,50.00000,20.00000,5.164847e-08,0.82342,4
260.01716,1767.00000,     -0.90225,     -0.54421,50.00000,20.00000,5.165019e-08,0.82342,4
260.02252,1772.70000,     -0.89924,     -0.54544,50.00000,20.00000,5.163406e-08,0.82342,4
260.01435,1778.40000,     -0.89745,     -0.54640,50.00000,20.00000,5.160678e-08,0.82343,4
260.02499,1784.10000,     -0.89544,     -0.54837,50.00000,20.00000,5.161197e-08,0.82342,4
260.01603,1789.80000,     -0.89957,     -0.55030,50.00000,20.00000,5.163194e-08,0.82342,4
260.02103,1795.50000,     -0.89874,     -0.55269,50.00000,20.00000,5.161968e-08,0.82342,4
260.01688,1801.20000,     -0.89828,     -0.55222,50.00000,20.00000,5.162644e-08,0.82342,4
260.01141,1806.90000,     -0.89669,     -0.55331,50.00000,20.00000,5.161885e-08,0.82343,4
260.01586,1812.60000,     -0.89655,     -0.55660,50.00000,20.00000,5.163944e-08,0.82342,4
260.01667,1818.30000,     -0.89977,     -0.55736,50.00000,20.00000,5.158128e-08,0.82342,4
260.01803,1824.00000,     -0.89912,     -0.55968,50.00000,20.00000,5.153198e-08,0.82342,4
260.01338,1829.70000,     -0.89957,     -0.56245,50.00000,20.00000,5.153652e-08,0.82343,4
260.02123,1835.40000,     -0.90020,     -0.56368,50.00000,20.00000,5.154347e-08,0.82342,4
260.02113,1841.10000,     -0.90128,     -0.56406,50.00000,20.00000,5.155894e-08,0.82342,4
260.01230,1846.80000,     -0.90175,     -0.56610,50.00000,20.00000,5.156469e-08,0.82343,4
260.01707,1852.50000,     -0.90175,     -0.56700,50.00000,20.00000,5.155852e-08,0.82342,4
260.01936,1858.20000,     -0.90018,     -0.56771,50.00000,20.00000,5.156603e-08,0.82342,4
260.02142,1863.90000,     -0.89988,     -0.56998,50.00000,20.00000,5.156626e-08,0.82342,4
260.01672,1869.60000,     -0.89997,     -0.57035,50.00000,20.00000,5.159164e-08,0.82342,4
260.01490,1875.30000,     -0.90197,     -0.57195,50.00000,20.00000,5.159016e-08,0.82342,4
260.02194,1881.00000,     -0.90033,     -0.57437,50.00000,20.00000,5.158919e-08,0.82342,4
260.01570,1886.70000,     -0.89985,     -0.57636,50.00000,20.00000,5.155404e-08,0.82342,4
260.01981,1892.40000,     -0.89808,     -0.57653,50.00000,20.00000,5.153475e-08,0.82342,4
260.01503,1898.10000,     -0.89641,     -0.57974,50.00000,20.00000,5.159837e-08,0.82342,4
260.01253,1903.80000,     -0.89856,     -0.58033,50.00000,20.00000,5.158654e-08,0.82343,4
260.01718,1909.50000,     -0.90109,     -0.58327,50.00000,20.00000,5.154881e-08,0.82342,4
260.00252,1915.20000,     -0.90198,     -0.58552,50.00000,20.00000,5.155070e-08,0.82344,4
260.02745,1920.90000,     -0.89724,     -0.58658,50.00000,20.00000,5.155158e-08,0.82341,4
260.02895,1926.60000,     -0.90080,     -0.58976,50.00000,20.00000,5.156465e-08,0.82341,4
260.02704,1932.30000,     -0.90045,     -0.59107,50.00000,20.00000,5.148747e-08,0.82341,4
260.00131,1938.00000,     -0.90210,     -0.59219,50.00000,20.00000,5.150276e-08,0.82344,4
260.02309,1943.70000,     -0.90019,     -0.59305,50.00000,20.00000,5.152608e-08,0.82342,4
260.02911,1949.40000,     -0.89986,     -0.59556,50.00000,20.00000,5.150345e-08,0.82341,4
260.02634,1955.10000,     -0.90261,     -0.59753,50.00000,20.00000,5.155155e-08,0.82341,4
260.01931,1960.80000,     -0.90233,     -0.59994,50.00000,20.00000,5.156414e-08,0.82342,4
260.01980,1966.50000,     -0.89923,     -0.59851,50.00000,20.00000,5.155436e-08,0.82342,4
260.02226,1972.20000,     -0.90175,     -0.60041,50.00000,20.00000,5.154674e-08,0.82342,4
260.01356,1977.90000,     -0.90095,     -0.60115,50.00000,20.00000,5.157826e-08,0.82343,4
260.01536,1983.60000,     -0.89996,     -0.60347,50.00000,20.00000,5.157058e-08,0.82342,4
260.03158,1989.30000,     -0.90231,     -0.60530,50.00000,20.00000,5.154606e-08,0.82341,4
260.00680,1995.00000,     -0.90289,     -0.60747,50.00000,20.00000,5.155290e-08,0.82343,4
260.01531,2000.70000,     -0.90128,     -0.61013,50.00000,20.00000,5.149978e-08,0.82342,4
260.02060,2006.40000,     -0.90041,     -0.61066,50.00000,20.00000,5.152421e-08,0.82342,4
260.00705,2012.10000,     -0.90070,     -0.61214,50.00000,20.00000,5.152745e-08,0.82343,4
260.02471,2017.80000,     -0.90098,     -0.61274,50.00000,20.00000,5.152703e-08,0.82342,4
260.01996,2023.50000,     -0.90044,     -0.61653,50.00000,20.00000,5.150741e-08,0.82342,4
260.01806,2029.20000,     -0.89945,     -0.61900,50.00000,20.00000,5.146642e-08,0.82342,4
260.01740,2034.90000,     -0.89972,     -0.61922,50.00000,20.00000,5.145807e-08,0.82342,4
260.01190,2040.60000,     -0.90080,     -0.62104,50.00000,20.00000,5.143898e-08,0.82343,4
260.01649,2046.30000,     -0.89985,     -0.62259,50.00000,20.00000,5.144744e-08,0.82342,4
260.01411,2052.00000,     -0.89912,     -0.62427,50.00000,20.00000,5.145003e-08,0.82343,4
260.00547,2057.70000,     -0.90001,     -0.62529,50.00000,20.00000,5.147601e-08,0.82343,4
260.01446,2063.40000,     -0.90033,     -0.62830,50.00000,20.00000,5.144823e-08,0.82343,4
260.02830,2069.10000,     -0.89964,     -0.62884,50.00000,20.00000,5.144837e-08,0.82341,4
260.02495,2074.80000,     -0.89954,     -0.62909,50.00000,20.00000,5.149822e-08,0.82342,4
260.01734,2080.50000,     -0.89904,     -0.63035,50.00000,20.00000,5.149205e-08,0.82342,4
260.01687,2086.20000,     -0.89994,     -0.63161,50.00000,20.00000,5.147092e-08,0.82342,4
260.01689,2091.90000,     -0.90037,     -0.63477,50.00000,20.00000,5.148891e-08,0.82342,4
260.00995,2097.60000,     -0.89974,     -0.63681,50.00000,20.00000,5.151903e-08,0.82343,4
260.03004,2103.30000,     -0.89710,     -0.63987,50.00000,20.00000,5.148360e-08,0.82341,4
260.02308,2109.00000,     -0.90028,     -0.64050,50.00000,20.00000,5.148672e-08,0.82342,4
260.02686,2114.70000,     -0.89797,     -0.64214,50.00000,20.00000,5.145813e-08,0.82341,4
260.03055,2120.40000,     -0.89918,     -0.64647,50.00000,20.00000,5.141110e-08,0.82341,4
260.01800,2126.10000,     -0.90147,     -0.64804,50.00000,20.00000,5.137594e-08,0.82342,4
260.00524,2131.80000,     -0.90211,     -0.64937,50.00000,20.00000,5.136883e-08,0.82343,4
260.02971,2137.50000,     -0.89777,     -0.65006,50.00000,20.00000,5.138728e-08,0.82341,4
260.01464,2143.20000,     -0.90309,     -0.65027,50.00000,20.00000,5.138554e-08,0.82343,4
260.01893,2148.90000,     -0.90099,     -0.65230,50.00000,20.00000,5.136707e-08,0.82342,4
260.01464,2154.60000,     -0.90163,     -0.65431,50.00000,20.00000,5.139552e-08,0.82343,4
260.01251,2160.30000,     -0.90259,     -0.65428,50.00000,20.00000,5.133167e-08,0.82343,4
260.01255,2166.00000,     -0.90174,     -0.65616,50.00000,20.00000,5.141357e-08,0.82343,4
260.01981,2171.70000,     -0.90084,     -0.65888,50.00000,20.00000,5.138357e-08,0.82342,4
260.01925,2177.40000,     -0.90325,     -0.65952,50.00000,20.00000,5.139720e-08,0.82342,4
260.01788,2183.10000,     -0.90178,     -0.66126,50.00000,20.00000,5.137073e-08,0.82342,4
260.01016,2188.80000,     -0.89900,     -0.66189,50.00000,20.00000,5.133153e-08,0.82343,4
260.01114,2194.50000,     -0.90375,     -0.66400,50.00000,20.00000,5.133064e-08,0.82343,4
260.00413,2200.20000,     -0.90332,     -0.66423,50.00000,20.00000,5.134507e-08,0.82343,4
260.01128,2205.90000,     -0.90521,     -0.66485,50.00000,20.00000,5.136847e-08,0.82343,4
260.01635,2211.60000,     -0.90340,     -0.66641,50.00000,20.00000,5.139198e-08,0.82342,4
260.02945,2217.30000,     -0.90304,     -0.67125,50.00000,20.00000,5.139837e-08,0.82341,4
260.01077,2223.00000,     -0.89947,     -0.67110,50.00000,20.00000,5.139234e-08,0.82343,4
260.01994,2228.70000,     -0.90470,     -0.67266,50.00000,20.00000,5.138262e-08,0.82342,4
260.01755,2234.40000,     -0.90183,     -0.67472,50.00000,20.00000,5.142288e-08,0.82342,4
260.02209,2240.10000,     -0.90073,     -0.67787,50.00000,20.00000,5.133170e-08,0.82342,4
260.01250,2245.80000,     -0.89969,     -0.67988,50.00000,20.00000,5.136500e-08,0.82343,4
260.00691,2251.50000,     -0.89974,     -0.68077,50.00000,20.00000,5.135121e-08,0.82343,4
260.01334,2257.20000,     -0.90066,     -0.68309,50.00000,20.00000,5.136158e-08,0.82343,4
260.01559,2262.90000,     -0.90054,     -0.68336,50.00000,20.00000,5.129847e-08,0.82342,4
260.01443,2268.60000,     -0.90180,     -0.68352,50.00000,20.00000,5.130726e-08,0.82343,4
260.01924,2274.30000,     -0.90121,     -0.68796,50.00000,20.00000,5.131872e-08,0.82342,4
260.02113,2280.00000,     -0.90250,     -0.68851,50.00000,20.00000,5.132566e-08,0.82342,4
260.01985,2285.70000,     -0.90354,     -0.69194,50.00000,20.00000,5.129894e-08,0.82342,4
260.02366,2291.40000,     -0.90155,     -0.69142,50.00000,20.00000,5.129622e-08,0.82342,4
260.00250,2297.10000,     -0.90131,     -0.69377,50.00000,20.00000,5.132679e-08,0.82344,4
260.01232,2302.80000,     -0.89881,     -0.69581,50.00000,20.00000,5.123746e-08,0.82343,4
260.02637,2308.50000,     -0.90628,     -0.69714,50.00000,20.00000,5.121527e-08,0.82341,4
260.01194,2314.20000,     -0.90351,     -0.69737,50.00000,20.00000,5.122768e-08,0.82343,4
260.01630,2319.90000,     -0.90236,     -0.69896,50.00000,20.00000,5.125648e-08,0.82342,4
260.02836,2325.60000,     -0.90184,     -0.69976,50.00000,20.00000,5.129735e-08,0.82341,4
260.00795,2331.30000,     -0.90329,     -0.70226,50.00000,20.00000,5.123806e-08,0.82343,4
260.01621,2337.00000,     -0.90204,     -0.70306,50.00000,20.00000,5.122986e-08,0.82342,4
260.00355,2342.70000,     -0.90208,     -0.70308,50.00000,20.00000,5.127493e-08,0.82343,4
260.01699,2348.40000,     -0.90322,     -0.70699,50.00000,20.00000,5.123846e-08,0.82342,4
260.00732,2354.10000,     -0.90162,     -0.70885,50.00000,20.00000,5.123885e-08,0.82343,4
260.02704,2359.80000,     -0.90276,     -0.70973,50.00000,20.00000,5.122595e-08,0.82341,4
260.01856,2365.50000,     -0.90156,     -0.71253,50.00000,20.00000,5.127303e-08,0.82342,4
260.02394,2371.20000,     -0.90117,     -0.71260,50.00000,20.00000,5.120871e-08,0.82342,4
260.03139,2376.90000,     -0.90112,     -0.71536,50.00000,20.00000,5.124414e-08,0.82341,4
260.03266,2382.60000,     -0.90244,     -0.71750,50.00000,20.00000,5.124755e-08,0.82341,4
259.99982,2388.30000,     -0.90381,     -0.71960,50.00000,20.00000,5.120345e-08,0.82344,4
260.01358,2394.00000,     -0.90577,     -0.72046,50.00000,20.00000,5.116604e-08,0.82343,4
260.03117,2399.70000,     -0.90408,     -0.71945,50.00000,20.00000,5.117834e-08,0.82341,4
260.01077,2405.40000,     -0.90401,     -0.72295,50.00000,20.00000,5.120188e-08,0.82343,4
260.01723,2411.10000,     -0.90263,     -0.72383,50.00000,20.00000,5.118653e-08,0.82342,4
260.01282,2416.80000,     -0.90371,     -0.72629,50.00000,20.00000,5.117796e-08,0.82343,4
260.01966,2422.50000,     -0.90401,     -0.72685,50.00000,20.00000,5.117198e-08,0.82342,4
260.01478,2428.20000,     -0.90065,     -0.72806,50.00000,20.00000,5.117902e-08,0.82343,4
260.02376,2433.90000,     -0.90512,     -0.72932,50.00000,20.00000,5.118352e-08,0.82342,4
259.99970,2439.60000,     -0.90228,     -0.73017,50.00000,20.00000,5.118829e-08,0.82344,4
260.01572,2445.30000,     -0.90371,     -0.73257,50.00000,20.00000,5.116398e-08,0.82342,4
260.02458,2451.00000,     -0.90296,     -0.73517,50.00000,20.00000,5.118136e-08,0.82342,4
260.00981,2456.70000,     -0.90388,     -0.73605,50.00000,20.00000,5.120011e-08,0.82343,4
260.02461,2462.40000,     -0.90099,     -0.73773,50.00000,20.00000,5.118994e-08,0.82342,4
260.01132,2468.10000,     -0.90313,     -0.73866,50.00000,20.00000,5.118909e-08,0.82343,4
260.01492,2473.80000,     -0.90282,     -0.74103,50.00000,20.00000,5.115681e-08,0.82342,4
260.02401,2479.50000,     -0.90268,     -0.74214,50.00000,20.00000,5.114424e-08,0.82342,4
260.00841,2485.20000,     -0.90227,     -0.74485,50.00000,20.00000,5.111695e-08,0.82343,4
260.03075,2490.90000,     -0.90611,     -0.74465,50.00000,20.00000,5.108401e-08,0.82341,4
260.02829,2496.60000,     -0.90418,     -0.74793,50.00000,20.00000,5.109368e-08,0.82341,4
260.02602,2502.30000,     -0.90457,     -0.74802,50.00000,20.00000,5.110382e-08,0.82342,4
260.02306,2508.00000,     -0.90454,     -0.74937,50.00000,20.00000,5.110872e-08,0.82342,4
260.02194,2513.70000,     -0.90377,     -0.75059,50.00000,20.00000,5.113715e-08,0.82342,4
260.01265,2519.40000,     -0.90245,     -0.75225,50.00000,20.00000,5.112154e-08,0.82343,4
260.01105,2525.10000,     -0.90213,     -0.75235,50.00000,20.00000,5.112493e-08,0.82343,4
260.02176,2530.80000,     -0.89969,     -0.75444,50.00000,20.00000,5.114959e-08,0.82342,4
260.02379,2536.50000,     -0.90123,     -0.75693,50.00000,20.00000,5.114217e-08,0.82342,4
260.01028,2542.20000,     -0.90222,     -0.75780,50.00000,20.00000,5.111851e-08,0.82343,4
260.02131,2547.90000,     -0.90148,     -0.75916,50.00000,20.00000,5.110489e-08,0.82342,4
260.01663,2553.60000,     -0.90685,     -0.75949,50.00000,20.00000,5.108723e-08,0.82342,4
260.02229,2559.30000,     -0.90426,     -0.76179,50.00000,20.00000,5.110869e-08,0.82342,4
260.02059,2565.00000,     -0.90416,     -0.76427,50.00000,20.00000,5.109546e-08,0.82342,4
260.01632,2570.70000,     -0.90698,     -0.76528,50.00000,20.00000,5.104665e-08,0.82342,4
260.01581,2576.40000,     -0.90415,     -0.76687,50.00000,20.00000,5.108686e-08,0.82342,4
260.01239,2582.10000,     -0.90282,     -0.76633,50.00000,20.00000,5.112205e-08,0.82343,4
260.02582,2587.80000,     -0.90293,     -0.76778,50.00000,20.00000,5.114089e-08,0.82342,4
260.02613,2593.50000,     -0.90499,     -0.76977,50.00000,20.00000,5.113550e-08,0.82342,4
260.02290,2599.20000,     -0.90550,     -0.76872,50.00000,20.00000,5.111354e-08,0.82342,4
260.01122,2604.90000,     -0.90493,     -0.77112,50.00000,20.00000,5.109464e-08,0.82343,4
260.02064,2610.60000,     -0.90453,     -0.77298,50.00000,20.00000,5.112765e-08,0.82342,4
260.02250,2616.30000,     -0.90506,     -0.77513,50.00000,20.00000,5.111895e-08,0.82342,4
260.01834,2622.00000,     -0.90779,     -0.77545,50.00000,20.00000,5.109546e-08,0.82342,4
260.01022,2627.70000,     -0.90569,     -0.77788,50.00000,20.00000,5.109604e-08,0.82343,4
260.01982,2633.40000,     -0.90612,     -0.77886,50.00000,20.00000,5.110678e-08,0.82342,4
260.01498,2639.10000,     -0.90552,     -0.77932,50.00000,20.00000,5.113487e-08,0.82342,4
260.01992,2644.80000,     -0.90345,     -0.78255,50.00000,20.00000,5.106161e-08,0.82342,4
260.00918,2650.50000,     -0.90696,     -0.78406,50.00000,20.00000,5.105914e-08,0.82343,4
260.01115,2656.20000,     -0.90538,     -0.78416,50.00000,20.00000,5.108893e-08,0.82343,4
260.01575,2661.90000,     -0.90624,     -0.78585,50.00000,20.00000,5.111357e-08,0.82342,4
260.01776,2667.60000,     -0.90608,     -0.78662,50.00000,20.00000,5.108381e-08,0.82342,4
260.02067,2673.30000,     -0.90754,     -0.78913,50.00000,20.00000,5.107387e-08,0.82342,4
260.00889,2679.00000,     -0.90524,     -0.78988,50.00000,20.00000,5.103734e-08,0.82343,4
260.00740,2684.70000,     -0.90510,     -0.79131,50.00000,20.00000,5.110871e-08,0.82343,4
260.01992,2690.40000,     -0.90412,     -0.79191,50.00000,20.00000,5.109886e-08,0.82342,4
260.02881,2696.10000,     -0.90417,     -0.79203,50.00000,20.00000,5.111910e-08,0.82341,4
260.02255,2701.80000,     -0.90544,     -0.79203,50.00000,20.00000,5.114096e-08,0.82342,4
260.01448,2707.50000,     -0.90509,     -0.79320,50.00000,20.00000,5.110649e-08,0.82343,4
260.01045,2713.20000,     -0.90508,     -0.79667,50.00000,20.00000,5.108656e-08,0.82343,4
260.01401,2718.90000,     -0.90598,     -0.79808,50.00000,20.00000,5.108364e-08,0.82343,4
260.02275,2724.60000,     -0.90769,     -0.80012,50.00000,20.00000,5.100971e-08,0.82342,4
260.01173,2730.30000,     -0.90808,     -0.80164,50.00000,20.00000,5.104823e-08,0.82343,4
260.02381,2736.00000,     -0.90868,     -0.80354,50.00000,20.00000,5.107200e-08,0.82342,4
260.02267,2741.70000,     -0.90557,     -0.80281,50.00000,20.00000,5.107705e-08,0.82342,4
260.00273,2747.40000,     -0.90866,     -0.80436,50.00000,20.00000,5.103326e-08,0.82344,4
260.02519,2753.10000,     -0.90455,     -0.80660,50.00000,20.00000,5.107513e-08,0.82342,4
260.00980,2758.80000,     -0.90586,     -0.80689,50.00000,20.00000,5.110891e-08,0.82343,4
260.01595,2764.50000,     -0.90816,     -0.80941,50.00000,20.00000,5.108898e-08,0.82342,4
260.01559,2770.20000,     -0.90763,     -0.80952,50.00000,20.00000,5.107572e-08,0.82342,4
260.02034,2775.90000,     -0.90935,     -0.81104,50.00000,20.00000,5.108111e-08,0.82342,4
260.01901,2781.60000,     -0.90509,     -0.81353,50.00000,20.00000,5.106169e-08,0.82342,4
260.02098,2787.30000,     -0.90836,     -0.81448,50.00000,20.00000,5.109071e-08,0.82342,4
260.00494,2793.00000,     -0.90664,     -0.81647,50.00000,20.00000,5.112318e-08,0.82343,4
260.01577,2798.70000,     -0.90934,     -0.81744,50.00000,20.00000,5.105076e-08,0.82342,4
260.02457,2804.40000,     -0.90586,     -0.81816,50.00000,20.00000,5.108215e-08,0.82342,4
260.02248,2810.10000,     -0.90768,     -0.82129,50.00000,20.00000,5.101038e-08,0.82342,4
260.02671,2815.80000,     -0.91046,     -0.82128,50.00000,20.00000,5.099143e-08,0.82341,4
260.01109,2821.50000,     -0.90943,     -0.82348,50.00000,20.00000,5.105724e-08,0.82343,4
260.00943,2827.20000,     -0.90581,     -0.82405,50.00000,20.00000,5.103352e-08,0.82343,4
260.01398,2832.90000,     -0.90676,     -0.82492,50.00000,20.00000,5.105729e-08,0.82343,4
260.01616,2838.60000,     -0.90996,     -0.82558,50.00000,20.00000,5.112856e-08,0.82342,4
260.01999,2844.30000,     -0.90901,     -0.82637,50.00000,20.00000,5.110284e-08,0.82342,4
260.00687,2850.00000,     -0.91076,     -0.82797,50.00000,20.00000,5.111062e-08,0.82343,4
260.02001,2855.70000,     -0.91009,     -0.82915,50.00000,20.00000,5.109059e-08,0.82342,4
260.00872,2861.40000,     -0.91059,     -0.83342,50.00000,20.00000,5.102254e-08,0.82343,4
260.00733,2867.10000,     -0.90921,     -0.83344,50.00000,20.00000,5.106934e-08,0.82343,4
260.01077,2872.80000,     -0.90826,     -0.83460,50.00000,20.00000,5.104441e-08,0.82343,4
260.02369,2878.50000,     -0.90696,     -0.83477,50.00000,20.00000,5.107336e-08,0.82342,4
260.00961,2884.20000,     -0.90947,     -0.83639,50.00000,20.00000,5.105666e-08,0.82343,4
260.00406,2889.90000,     -0.90738,     -0.83841,50.00000,20.00000,5.111052e-08,0.82343,4
260.00748,2895.60000,     -0.90597,     -0.83874,50.00000,20.00000,5.106370e-08,0.82343,4
260.00684,2901.30000,     -0.90761,     -0.84197,50.00000,20.00000,5.113630e-08,0.82343,4
260.02073,2907.00000,     -0.90871,     -0.84337,50.00000,20.00000,5.110603e-08,0.82342,4
260.01023,2912.70000,     -0.90712,     -0.84350,50.00000,20.00000,5.107167e-08,0.82343,4
260.01283,2918.40000,     -0.90930,     -0.84708,50.00000,20.00000,5.106952e-08,0.82343,4
260.03587,2924.10000,     -0.91129,     -0.84867,50.00000,20.00000,5.103777e-08,0.82341,4
260.00633,2929.80000,     -0.90818,     -0.84865,50.00000,20.00000,5.109161e-08,0.82343,4
260.00796,2935.50000,     -0.91082,     -0.84959,50.00000,20.00000,5.104134e-08,0.82343,4
260.00688,2941.20000,     -0.91146,     -0.85099,50.00000,20.00000,5.105461e-08,0.82343,4
260.01557,2946.90000,     -0.90974,     -0.85246,50.00000,20.00000,5.107579e-08,0.82342,4
260.00195,2952.60000,     -0.90783,     -0.85495,50.00000,20.00000,5.106525e-08,0.82344,4
260.02583,2958.30000,     -0.91171,     -0.85524,50.00000,20.00000,5.108316e-08,0.82342,4
260.02260,2964.00000,     -0.90596,     -0.85578,50.00000,20.00000,5.110352e-08,0.82342,4
260.02253,2969.70000,     -0.90723,     -0.85765,50.00000,20.00000,5.108781e-08,0.82342,4
260.02382,2975.40000,     -0.90890,     -0.85930,50.00000,20.00000,5.107202e-08,0.82342,4
260.00903,2981.10000,     -0.91041,     -0.85914,50.00000,20.00000,5.110180e-08,0.82343,4
260.01182,2986.80000,     -0.90667,     -0.86210,50.00000,20.00000,5.109527e-08,0.82343,4
260.01783,2992.50000,     -0.90764,     -0.86129,50.00000,20.00000,5.111203e-08,0.82342,4
260.01434,2998.20000,     -0.90728,     -0.86420,50.00000,20.00000,5.105531e-08,0.82343,4
260.01484,3003.90000,     -0.90859,     -0.86488,50.00000,20.00000,5.108939e-08,0.82342,4
260.00276,3009.60000,     -0.90824,     -0.86509,50.00000,20.00000,5.108568e-08,0.82344,4
260.02204,3015.30000,     -0.90871,     -0.86735,50.00000,20.00000,5.106749e-08,0.82342,4
260.01565,3021.00000,     -0.90740,     -0.87096,50.00000,20.00000,5.109259e-08,0.82342,4
260.02575,3026.70000,     -0.90940,     -0.87097,50.00000,20.00000,5.109224e-08,0.82342,4
260.02200,3032.40000,     -0.90826,     -0.87260,50.00000,20.00000,5.101782e-08,0.82342,4
260.03355,3038.10000,     -0.90849,     -0.87450,50.00000,20.00000,5.108399e-08,0.82341,4
260.01388,3043.80000,     -0.90823,     -0.87474,50.00000,20.00000,5.102995e-08,0.82343,4
260.01643,3049.50000,     -0.91159,     -0.87525,50.00000,20.00000,5.105834e-08,0.82342,4
260.02451,3055.20000,     -0.91035,     -0.87750,50.00000,20.00000,5.103180e-08,0.82342,4
260.00724,3060.90000,     -0.90916,     -0.87985,50.00000,20.00000,5.103779e-08,0.82343,4
260.02295,3066.60000,     -0.91164,     -0.87897,50.00000,20.00000,5.100595e-08,0.82342,4
260.24816,3072.30000,     -0.74515,     -0.87951,50.00000,20.00000,5.102339e-08,0.82322,5
312.89951,3078.00000,      3.46276,     -0.75832,50.00000,20.00000,5.114936e-08,0.77511,5
373.67643,3083.70000,      2.67120,     -0.87570,50.00000,20.00000,5.205385e-08,0.71728,5
431.19349,3089.40000,      3.21182,     -3.63220,50.00000,20.00000,5.377391e-08,0.66414,5
488.11206,3095.10000,     -1.27335,     -4.53058,50.00000,20.00000,5.616314e-08,0.61584,5
544.86280,3100.80000,     -3.28229,     -4.49170,50.00000,20.00000,5.776530e-08,0.57344,5
601.83021,3106.50000,     -5.62606,     -4.46843,50.00000,20.00000,5.886359e-08,0.53703,5
658.88845,3112.20000,     -8.26494,     -4.44968,50.00000,20.00000,5.979903e-08,0.50617,5
716.01612,3117.90000,    -10.80392,     -4.43681,50.00000,20.00000,6.058975e-08,0.47960,5
773.15524,3123.60000,    -13.02705,     -4.42395,50.00000,20.00000,6.123807e-08,0.45569,5
794.20260,3125.70000,    -13.77794,     -4.42037,50.00000,20.00000,6.137704e-08,0.44721,5