File: data/TGA/005c/ExpDat_2024_06_20_005c-B_dynamic.csv
#EXPORTTYPE:                 ,DATA ALL
#FILE:                       ,2024_06_20_005c-B_dynamic.ngb-ss5
#FORMAT:                     ,NETZSCH5
#FTYPE:                      ,ASCII
#IDENTITY:                   ,PS-SCF3
#DECIMAL:                    ,POINT
#SEPARATOR:                  ,COMMA
#MTYPE:                      ,DSC
#INSTRUMENT:                 ,NETZSCH STA 449F5
#PROJECT:                    ,
#DATE/TIME:                  ,6/20/2024 9:01:28 PM (UTC-4)
#CORR. FILE:                 ,
#TEMPCAL:                    ,28-06-2023 13:26
#SENSITIVITY:                ,28-06-2023 13:53
#LABORATORY:                 ,
#OPERATOR:                   ,Stanley
#REMARK:                     ,
#SAMPLE:                     ,005c-B-2
#SAMPLE MASS /mg:            ,5.05
#MATERIAL:                   ,
#REFERENCE:                  ,-----
#REFERENCE MASS /mg:         ,0
#TYPE OF CRUCIBLE:           ,Al2O3 85 ‘l, open
#SAMPLE CRUCIBLE MASS /mg:   ,0
#REFERENCE CRUCIBLE MASS /mg:,0
#DSC RANGE /‘V:              ,5000
#TG RANGE /mg:               ,35000
#TAU-R:                      ,---
#CORR. CODE:                 ,000
#EXO:                        ,-1
#RANGE:                      ,20›C....800›C/0.0....5.0K/min
#SEGMENT:                    ,S1-4/4
#SEG. 1:                     ,20›C/5.0(K/min)/100›C
#SEG. 2:                     ,100›C/00:05/100›C
#SEG. 3:                     ,100›C/1.0(K/min)/400›C
#SEG. 4:                     ,400›C/5.0(K/min)/800›C

##Temp./›C,Time/min,DSC/(mW/mg),Mass loss/mg,Gas Flow(purge2)/(ml/min),Gas Flow(protective)/(ml/min),TIC(scan:1)/A,Sensit./(uV/mW),Segment
 32.38400,  0.00000,-5.199538e-02, 0.000000e+00,50.00000,20.00000,6.400667e-08,0.92398,1
 32.48000,  0.80000,-1.831252e-02, 1.030000e-02,50.00000,20.00000,6.410300e-08,0.92399,1
 32.84500,  1.60000, 2.926539e-02, 1.991000e-02,50.00000,20.00000,6.362465e-08,0.92405,1
 33.27100,  2.40000, 5.051573e-02, 2.693000e-02,50.00000,20.00000,6.360502e-08,0.92412,1
 33.89100,  3.20000, 9.938585e-02, 4.220000e-02,50.00000,20.00000,6.346980e-08,0.92423,1
 35.00500,  4.00000,      0.21001, 7.478000e-02,50.00000,20.00000,6.335343e-08,0.92440,1
 36.75700,  4.80000,      0.36092,      0.11562,50.00000,20.00000,6.329161e-08,0.92466,1
 39.16500,  5.60000,      0.52478,      0.15397,50.00000,20.00000,6.296008e-08,0.92498,1
 42.17400,  6.40000,      0.68687,      0.19243,50.00000,20.00000,6.305820e-08,0.92533,1
 45.73300,  7.20000,      0.84167,      0.22898,50.00000,20.00000,6.271544e-08,0.92566,1
 49.75600,  8.00000,      0.98418,      0.25941,50.00000,20.00000,6.264928e-08,0.92594,1
 54.17400,  8.80000,      1.11073,      0.28758,50.00000,20.00000,6.259792e-08,0.92613,1
 58.89700,  9.60000,      1.21651,      0.30873,50.00000,20.00000,6.280174e-08,0.92620,1
 63.80800, 10.40000,      1.29883,      0.32853,50.00000,20.00000,6.238615e-08,0.92612,1
 68.78100, 11.20000,      1.36084,      0.34233,50.00000,20.00000,6.244239e-08,0.92589,1
 73.77900, 12.00000,      1.40205,      0.35421,50.00000,20.00000,6.229864e-08,0.92550,1
 78.77800, 12.80000,      1.43325,      0.36575,50.00000,20.00000,6.237175e-08,0.92496,1
 83.69900, 13.60000,      1.45489,      0.37254,50.00000,20.00000,6.243329e-08,0.92429,1
 88.58000, 14.40000,      1.46714,      0.37933,50.00000,20.00000,6.235505e-08,0.92347,1
 93.36900, 15.20000,      1.47615,      0.38611,50.00000,20.00000,6.219973e-08,0.92254,1
 98.04769, 16.00000,      1.49063,      0.38905,50.00000,20.00000,6.227241e-08,0.92150,2
102.03501, 16.80000,      1.25221,      0.37296,50.00000,20.00000,6.220803e-08,0.92051,2
104.56203, 17.60000,      0.83344,      0.34015,50.00000,20.00000,6.232550e-08,0.91984,2
106.25607, 18.40000,      0.55622,      0.31822,50.00000,20.00000,6.233158e-08,0.91937,2
107.38642, 19.20000,      0.37291,      0.30121,50.00000,20.00000,6.237807e-08,0.91905,2
107.97891, 20.00000,      0.19844,      0.28394,50.00000,20.00000,6.237113e-08,0.91888,2
108.08033, 20.80000, 4.251515e-02,      0.26737,50.00000,20.00000,6.226464e-08,0.91885,2
107.84814, 21.60000,-5.058185e-02,      0.25668,50.00000,20.00000,6.240192e-08,0.91892,3
107.61723, 22.40000,-6.231282e-02,      0.25127,50.00000,20.00000,6.221646e-08,0.91898,3
107.38622, 23.20000,-5.623616e-02,      0.24697,50.00000,20.00000,6.221255e-08,0.91905,3
107.16903, 24.00000,-5.162145e-02,      0.24527,50.00000,20.00000,6.213268e-08,0.91911,3
107.02325, 24.80000,-3.025910e-02,      0.24323,50.00000,20.00000,6.227831e-08,0.91916,3
106.97102, 25.60000, 2.097631e-03,      0.24390,50.00000,20.00000,6.213265e-08,0.91917,3
107.05788, 26.40000, 4.006197e-02,      0.24549,50.00000,20.00000,6.211674e-08,0.91915,3
107.23586, 27.20000, 7.852958e-02,      0.24685,50.00000,20.00000,6.195250e-08,0.91909,3
107.54257, 28.00000,      0.11487,      0.24821,50.00000,20.00000,6.191549e-08,0.91901,3
107.96050, 28.80000,      0.14876,      0.25024,50.00000,20.00000,6.198371e-08,0.91889,3
108.45019, 29.60000,      0.17740,      0.25262,50.00000,20.00000,6.177677e-08,0.91874,3
109.04535, 30.40000,      0.20457,      0.25362,50.00000,20.00000,6.185328e-08,0.91857,3
109.68735, 31.20000,      0.22928,      0.25702,50.00000,20.00000,6.185102e-08,0.91837,3
110.39339, 32.00000,      0.24714,      0.25806,50.00000,20.00000,6.173953e-08,0.91816,3
111.14724, 32.80000,      0.26283,      0.25940,50.00000,20.00000,6.164097e-08,0.91793,3
111.92814, 33.60000,      0.27393,      0.26077,50.00000,20.00000,6.177957e-08,0.91769,3
112.72811, 34.40000,      0.28372,      0.26178,50.00000,20.00000,6.165540e-08,0.91743,3
113.56014, 35.20000,      0.29073,      0.26178,50.00000,20.00000,6.172678e-08,0.91717,3
114.41305, 36.00000,      0.29609,      0.26076,50.00000,20.00000,6.158226e-08,0.91689,3
115.24002, 36.80000,      0.29948,      0.26123,50.00000,20.00000,6.161045e-08,0.91662,3
116.10410, 37.60000,      0.30139,      0.26325,50.00000,20.00000,6.157569e-08,0.91633,3
116.93297, 38.40000,      0.30313,      0.26191,50.00000,20.00000,6.146435e-08,0.91605,3
117.77294, 39.20000,      0.30257,      0.26359,50.00000,20.00000,6.157386e-08,0.91576,3
118.61217, 40.00000,      0.30217,      0.26359,50.00000,20.00000,6.165230e-08,0.91547,3
119.45716, 40.80000,      0.30160,      0.26371,50.00000,20.00000,6.149368e-08,0.91518,3
120.27422, 41.60000,      0.30105,      0.26337,50.00000,20.00000,6.148351e-08,0.91489,3
121.10799, 42.40000,      0.29981,      0.26573,50.00000,20.00000,6.160085e-08,0.91459,3
121.93117, 43.20000,      0.30024,      0.26507,50.00000,20.00000,6.146858e-08,0.91429,3
122.73407, 44.00000,      0.29951,      0.26641,50.00000,20.00000,6.140574e-08,0.91399,3
123.55912, 44.80000,      0.29928,      0.26506,50.00000,20.00000,6.140869e-08,0.91368,3
124.37018, 45.60000,      0.29871,      0.26777,50.00000,20.00000,6.147378e-08,0.91338,3
125.18004, 46.40000,      0.29816,      0.26641,50.00000,20.00000,6.140700e-08,0.91307,3
125.98518, 47.20000,      0.30010,      0.26880,50.00000,20.00000,6.134358e-08,0.91276,3
126.78311, 48.00000,      0.29771,      0.26915,50.00000,20.00000,6.165167e-08,0.91245,3
127.58623, 48.80000,      0.29565,      0.26993,50.00000,20.00000,6.129867e-08,0.91213,3
128.38224, 49.60000,      0.29708,      0.26992,50.00000,20.00000,6.127795e-08,0.91181,3
129.18528, 50.40000,      0.29652,      0.27129,50.00000,20.00000,6.163618e-08,0.91149,3
129.99006, 51.20000,      0.29712,      0.27263,50.00000,20.00000,6.153083e-08,0.91116,3
130.78215, 52.00000,      0.29806,      0.27296,50.00000,20.00000,6.153449e-08,0.91084,3
131.58823, 52.80000,      0.29783,      0.27330,50.00000,20.00000,6.146559e-08,0.91050,3
132.39916, 53.60000,      0.29794,      0.27400,50.00000,20.00000,6.161916e-08,0.91016,3
133.19528, 54.40000,      0.29807,      0.27500,50.00000,20.00000,6.158384e-08,0.90983,3
133.98517, 55.20000,      0.29749,      0.27502,50.00000,20.00000,6.142032e-08,0.90949,3
134.78918, 56.00000,      0.29778,      0.27637,50.00000,20.00000,6.152145e-08,0.90915,3
135.58919, 56.80000,      0.29741,      0.27639,50.00000,20.00000,6.155871e-08,0.90880,3
136.39615, 57.60000,      0.29619,      0.27818,50.00000,20.00000,6.158006e-08,0.90844,3
137.19818, 58.40000,      0.29697,      0.27887,50.00000,20.00000,6.137477e-08,0.90809,3
138.00823, 59.20000,      0.29658,      0.27953,50.00000,20.00000,6.163001e-08,0.90773,3
138.79626, 60.00000,      0.29521,      0.28124,50.00000,20.00000,6.164233e-08,0.90737,3
139.59715, 60.80000,      0.29481,      0.28261,50.00000,20.00000,6.145955e-08,0.90701,3
140.39812, 61.60000,      0.29429,      0.28249,50.00000,20.00000,6.147776e-08,0.90664,3
141.19321, 62.40000,      0.29357,      0.28417,50.00000,20.00000,6.142629e-08,0.90627,3
142.00014, 63.20000,      0.29302,      0.28418,50.00000,20.00000,6.161861e-08,0.90590,3
142.79433, 64.00000,      0.29229,      0.28520,50.00000,20.00000,6.143431e-08,0.90553,3
143.59823, 64.80000,      0.29226,      0.28556,50.00000,20.00000,6.169623e-08,0.90514,3
144.39516, 65.60000,      0.29106,      0.28734,50.00000,20.00000,6.140680e-08,0.90476,3
145.19230, 66.40000,      0.29000,      0.28871,50.00000,20.00000,6.156395e-08,0.90438,3
145.99223, 67.20000,      0.29112,      0.28906,50.00000,20.00000,6.162604e-08,0.90399,3
146.81013, 68.00000,      0.28992,      0.28973,50.00000,20.00000,6.163587e-08,0.90359,3
147.60031, 68.80000,      0.28820,      0.29073,50.00000,20.00000,6.170751e-08,0.90320,3
148.40413, 69.60000,      0.28783,      0.29177,50.00000,20.00000,6.164922e-08,0.90280,3
149.18017, 70.40000,      0.28812,      0.29448,50.00000,20.00000,6.167154e-08,0.90242,3
150.00201, 71.20000,      0.28759,      0.29448,50.00000,20.00000,6.171872e-08,0.90200,3
150.80209, 72.00000,      0.28671,      0.29584,50.00000,20.00000,6.162571e-08,0.90160,3
151.61015, 72.80000,      0.28685,      0.29585,50.00000,20.00000,6.163621e-08,0.90118,3
152.39415, 73.60000,      0.28479,      0.29719,50.00000,20.00000,6.172526e-08,0.90078,3
153.20406, 74.40000,      0.28374,      0.29786,50.00000,20.00000,6.167608e-08,0.90036,3
154.00315, 75.20000,      0.28238,      0.29923,50.00000,20.00000,6.169374e-08,0.89994,3
154.80701, 76.00000,      0.27930,      0.29924,50.00000,20.00000,6.174358e-08,0.89952,3
155.60409, 76.80000,      0.27793,      0.30070,50.00000,20.00000,6.188684e-08,0.89910,3
156.40217, 77.60000,      0.27656,      0.30138,50.00000,20.00000,6.186878e-08,0.89867,3
157.20627, 78.40000,      0.27584,      0.30128,50.00000,20.00000,6.163591e-08,0.89824,3
158.00423, 79.20000,      0.27578,      0.30398,50.00000,20.00000,6.179831e-08,0.89781,3
158.80716, 80.00000,      0.27459,      0.30545,50.00000,20.00000,6.186582e-08,0.89737,3
159.62199, 80.80000,      0.27169,      0.30547,50.00000,20.00000,6.176926e-08,0.89692,3
160.42216, 81.60000,      0.27098,      0.30612,50.00000,20.00000,6.178083e-08,0.89648,3
161.21628, 82.40000,      0.26926,      0.30760,50.00000,20.00000,6.178068e-08,0.89604,3
162.02812, 83.20000,      0.26788,      0.30895,50.00000,20.00000,6.198518e-08,0.89559,3
162.82013, 84.00000,      0.26448,      0.30885,50.00000,20.00000,6.180766e-08,0.89514,3
163.62541, 84.80000,      0.26257,      0.31020,50.00000,20.00000,6.183576e-08,0.89469,3
164.42906, 85.60000,      0.26204,      0.31023,50.00000,20.00000,6.192373e-08,0.89423,3
165.22635, 86.40000,      0.25912,      0.31157,50.00000,20.00000,6.191874e-08,0.89377,3
166.02411, 87.20000,      0.25739,      0.31190,50.00000,20.00000,6.196414e-08,0.89332,3
166.82307, 88.00000,      0.25600,      0.31326,50.00000,20.00000,6.197918e-08,0.89285,3
167.61914, 88.80000,      0.25005,      0.31462,50.00000,20.00000,6.210479e-08,0.89239,3
168.40225, 89.60000,      0.24901,      0.31620,50.00000,20.00000,6.190212e-08,0.89193,3
169.20996, 90.40000,      0.24878,      0.31485,50.00000,20.00000,6.208967e-08,0.89145,3
170.02014, 91.20000,      0.24808,      0.31654,50.00000,20.00000,6.209450e-08,0.89097,3
170.81926, 92.00000,      0.24448,      0.31844,50.00000,20.00000,6.201679e-08,0.89050,3
171.61006, 92.80000,      0.24156,      0.31744,50.00000,20.00000,6.207504e-08,0.89002,3
172.41812, 93.60000,      0.23983,      0.31846,50.00000,20.00000,6.208138e-08,0.88954,3
173.21719, 94.40000,      0.23910,      0.31846,50.00000,20.00000,6.223217e-08,0.88905,3
174.01321, 95.20000,      0.23514,      0.31914,50.00000,20.00000,6.218655e-08,0.88857,3
174.81211, 96.00000,      0.23187,      0.32016,50.00000,20.00000,6.210088e-08,0.88808,3
175.61311, 96.80000,      0.22962,      0.31983,50.00000,20.00000,6.226974e-08,0.88758,3
176.41225, 97.60000,      0.22838,      0.32117,50.00000,20.00000,6.222199e-08,0.88709,3
177.21310, 98.40000,      0.22766,      0.32085,50.00000,20.00000,6.224804e-08,0.88659,3
178.00115, 99.20000,      0.22489,      0.32220,50.00000,20.00000,6.230821e-08,0.88610,3
178.81911,100.00000,      0.22092,      0.32354,50.00000,20.00000,6.235529e-08,0.88558,3
179.62214,100.80000,      0.21902,      0.32456,50.00000,20.00000,6.226110e-08,0.88507,3
180.40617,101.60000,      0.21452,      0.32468,50.00000,20.00000,6.224546e-08,0.88458,3
181.21120,102.40000,      0.21225,      0.32468,50.00000,20.00000,6.209725e-08,0.88406,3
182.00216,103.20000,      0.21049,      0.32604,50.00000,20.00000,6.228083e-08,0.88356,3
182.81122,104.00000,      0.20650,      0.32706,50.00000,20.00000,6.236596e-08,0.88303,3
183.60619,104.80000,      0.20355,      0.32740,50.00000,20.00000,6.237913e-08,0.88252,3
184.40701,105.60000,      0.20058,      0.32808,50.00000,20.00000,6.234437e-08,0.88200,3
185.21131,106.40000,      0.19866,      0.32808,50.00000,20.00000,6.223873e-08,0.88147,3
186.00607,107.20000,      0.19516,      0.32944,50.00000,20.00000,6.237000e-08,0.88095,3
186.82716,108.00000,      0.19288,      0.33057,50.00000,20.00000,6.239834e-08,0.88041,3
187.61113,108.80000,      0.18991,      0.32922,50.00000,20.00000,6.247707e-08,0.87989,3
188.41823,109.60000,      0.19105,      0.33193,50.00000,20.00000,6.245641e-08,0.87935,3
189.21418,110.40000,      0.18877,      0.33192,50.00000,20.00000,6.259127e-08,0.87882,3
190.01917,111.20000,      0.18646,      0.33192,50.00000,20.00000,6.255238e-08,0.87828,3
190.80621,112.00000,      0.18262,      0.33159,50.00000,20.00000,6.260435e-08,0.87774,3
191.62404,112.80000,      0.18067,      0.33260,50.00000,20.00000,6.270610e-08,0.87719,3
192.41813,113.60000,      0.17785,      0.33293,50.00000,20.00000,6.241686e-08,0.87665,3
193.21911,114.40000,      0.17452,      0.33396,50.00000,20.00000,6.265380e-08,0.87610,3
194.01725,115.20000,      0.16946,      0.33396,50.00000,20.00000,6.265306e-08,0.87555,3
194.81501,116.00000,      0.16714,      0.33532,50.00000,20.00000,6.267570e-08,0.87500,3
195.61907,116.80000,      0.16447,      0.33668,50.00000,20.00000,6.262283e-08,0.87444,3
196.42024,117.60000,      0.16044,      0.33668,50.00000,20.00000,6.264700e-08,0.87389,3
197.21118,118.40000,      0.15743,      0.33701,50.00000,20.00000,6.263837e-08,0.87334,3
198.02918,119.20000,      0.15337,      0.33668,50.00000,20.00000,6.276632e-08,0.87276,3
198.82318,120.00000,      0.14827,      0.33803,50.00000,20.00000,6.269097e-08,0.87220,3
199.62222,120.80000,      0.14301,      0.33939,50.00000,20.00000,6.272693e-08,0.87164,3
200.41719,121.60000,      0.14256,      0.33938,50.00000,20.00000,6.279533e-08,0.87107,3
201.22433,122.40000,      0.13763,      0.33895,50.00000,20.00000,6.279360e-08,0.87050,3
202.01821,123.20000,      0.13373,      0.34165,50.00000,20.00000,6.273342e-08,0.86993,3
202.81317,124.00000,      0.12982,      0.34164,50.00000,20.00000,6.284036e-08,0.86936,3
203.61632,124.80000,      0.12608,      0.34062,50.00000,20.00000,6.281206e-08,0.86878,3
204.40524,125.60000,      0.12268,      0.34199,50.00000,20.00000,6.293841e-08,0.86821,3
205.21518,126.40000,      0.11806,      0.34211,50.00000,20.00000,6.284332e-08,0.86762,3
206.00521,127.20000,      0.11554,      0.34279,50.00000,20.00000,6.292045e-08,0.86705,3
206.81516,128.00000,      0.11073,      0.34278,50.00000,20.00000,6.303066e-08,0.86645,3
207.62629,128.80000,      0.10575,      0.34278,50.00000,20.00000,6.294338e-08,0.86586,3
208.41324,129.60000,      0.10216,      0.34414,50.00000,20.00000,6.284444e-08,0.86528,3
209.20424,130.40000, 9.714470e-02,      0.34426,50.00000,20.00000,6.301516e-08,0.86469,3
210.01612,131.20000, 9.424506e-02,      0.34459,50.00000,20.00000,6.299640e-08,0.86409,3
210.81115,132.00000, 9.027686e-02,      0.34493,50.00000,20.00000,6.298272e-08,0.86350,3
211.61920,132.80000, 8.456545e-02,      0.34595,50.00000,20.00000,6.301634e-08,0.86290,3
212.41816,133.60000, 7.989496e-02,      0.34697,50.00000,20.00000,6.300632e-08,0.86230,3
213.22427,134.40000, 7.714543e-02,      0.34732,50.00000,20.00000,6.304077e-08,0.86169,3
214.02225,135.20000, 7.264229e-02,      0.34708,50.00000,20.00000,6.304346e-08,0.86109,3
214.83706,136.00000, 6.549128e-02,      0.34707,50.00000,20.00000,6.326959e-08,0.86047,3
215.61522,136.80000, 6.079995e-02,      0.34844,50.00000,20.00000,6.310949e-08,0.85988,3
216.41108,137.60000, 5.732186e-02,      0.34777,50.00000,20.00000,6.311651e-08,0.85927,3
217.20406,138.40000, 5.103755e-02,      0.34912,50.00000,20.00000,6.321858e-08,0.85867,3
218.02012,139.20000, 4.612924e-02,      0.35048,50.00000,20.00000,6.315021e-08,0.85804,3
218.80312,140.00000, 4.176445e-02,      0.35048,50.00000,20.00000,6.320473e-08,0.85744,3
219.61216,140.80000, 3.756063e-02,      0.35047,50.00000,20.00000,6.325991e-08,0.85681,3
220.40622,141.60000, 3.352053e-02,      0.34957,50.00000,20.00000,6.320650e-08,0.85620,3
221.21927,142.40000, 2.773546e-02,      0.34957,50.00000,20.00000,6.338372e-08,0.85557,3
222.00520,143.20000, 2.331592e-02,      0.35025,50.00000,20.00000,6.324273e-08,0.85496,3
222.80613,144.00000, 1.856848e-02,      0.35296,50.00000,20.00000,6.339845e-08,0.85433,3
223.61214,144.80000, 1.433080e-02,      0.35263,50.00000,20.00000,6.333699e-08,0.85370,3
224.40623,145.60000, 8.518029e-03,      0.35283,50.00000,20.00000,6.343710e-08,0.85308,3
225.20523,146.40000, 2.300675e-03,      0.35365,50.00000,20.00000,6.322505e-08,0.85245,3
226.00601,147.20000,-2.651025e-03,      0.35330,50.00000,20.00000,6.327887e-08,0.85181,3
226.80218,148.00000,-8.330457e-03,      0.35467,50.00000,20.00000,6.331875e-08,0.85118,3
227.60026,148.80000,-1.294137e-02,      0.35532,50.00000,20.00000,6.337750e-08,0.85055,3
228.40712,149.60000,-1.687386e-02,      0.35534,50.00000,20.00000,6.344197e-08,0.84990,3
229.20904,150.40000,-2.365006e-02,      0.35432,50.00000,20.00000,6.342991e-08,0.84926,3
230.01406,151.20000,-2.882953e-02,      0.35568,50.00000,20.00000,6.349248e-08,0.84862,3
230.79208,152.00000,-3.366480e-02,      0.35705,50.00000,20.00000,6.351538e-08,0.84799,3
231.60615,152.80000,-4.046845e-02,      0.35839,50.00000,20.00000,6.351596e-08,0.84734,3
232.41109,153.60000,-4.620538e-02,      0.35839,50.00000,20.00000,6.344973e-08,0.84669,3
233.20516,154.40000,-5.231953e-02,      0.35839,50.00000,20.00000,6.358938e-08,0.84604,3
234.00023,155.20000,-5.773349e-02,      0.35875,50.00000,20.00000,6.352864e-08,0.84540,3
234.80015,156.00000,-6.188047e-02,      0.36009,50.00000,20.00000,6.359573e-08,0.84474,3
235.60817,156.80000,-6.941988e-02,      0.35975,50.00000,20.00000,6.359853e-08,0.84409,3
236.39817,157.60000,-7.880671e-02,      0.35975,50.00000,20.00000,6.364187e-08,0.84344,3
237.20004,158.40000,-8.335671e-02,      0.36043,50.00000,20.00000,6.375512e-08,0.84278,3
237.99821,159.20000,-8.681340e-02,      0.36042,50.00000,20.00000,6.380679e-08,0.84212,3
238.80416,160.00000,-9.353405e-02,      0.36111,50.00000,20.00000,6.365151e-08,0.84146,3
239.59115,160.80000,     -0.10116,      0.36077,50.00000,20.00000,6.378779e-08,0.84081,3
240.40413,161.60000,     -0.10680,      0.36111,50.00000,20.00000,6.369859e-08,0.84014,3
241.20816,162.40000,     -0.11248,      0.36111,50.00000,20.00000,6.382291e-08,0.83947,3
242.01617,163.20000,     -0.12013,      0.36203,50.00000,20.00000,6.387291e-08,0.83879,3
242.82015,164.00000,     -0.12762,      0.36202,50.00000,20.00000,6.389578e-08,0.83812,3
243.61500,164.80000,     -0.13187,      0.36168,50.00000,20.00000,6.383220e-08,0.83746,3
244.40417,165.60000,     -0.13974,      0.36338,50.00000,20.00000,6.386042e-08,0.83680,3
245.19520,166.40000,     -0.14635,      0.36200,50.00000,20.00000,6.385480e-08,0.83613,3
246.00108,167.20000,     -0.15335,      0.36338,50.00000,20.00000,6.392471e-08,0.83545,3
246.79808,168.00000,     -0.16033,      0.36337,50.00000,20.00000,6.398149e-08,0.83478,3
247.59333,168.80000,     -0.16789,      0.36202,50.00000,20.00000,6.403326e-08,0.83411,3
248.39818,169.60000,     -0.17384,      0.36201,50.00000,20.00000,6.391158e-08,0.83343,3
249.19515,170.40000,     -0.18032,      0.36237,50.00000,20.00000,6.409513e-08,0.83275,3
249.99224,171.20000,     -0.18719,      0.36371,50.00000,20.00000,6.401695e-08,0.83207,3
250.79418,172.00000,     -0.19226,      0.36203,50.00000,20.00000,6.399610e-08,0.83139,3
251.59318,172.80000,     -0.20023,      0.36336,50.00000,20.00000,6.399337e-08,0.83070,3
252.39922,173.60000,     -0.20840,      0.36202,50.00000,20.00000,6.416020e-08,0.83001,3
253.19114,174.40000,     -0.21678,      0.36202,50.00000,20.00000,6.425950e-08,0.82933,3
253.99415,175.20000,     -0.22225,      0.36371,50.00000,20.00000,6.412608e-08,0.82864,3
254.78820,176.00000,     -0.22825,      0.36225,50.00000,20.00000,6.415741e-08,0.82796,3
255.58801,176.80000,     -0.23776,      0.36224,50.00000,20.00000,6.411614e-08,0.82727,3
256.39222,177.60000,     -0.24380,      0.36361,50.00000,20.00000,6.417934e-08,0.82657,3
257.19614,178.40000,     -0.25006,      0.36293,50.00000,20.00000,6.427136e-08,0.82588,3
257.97725,179.20000,     -0.25941,      0.36325,50.00000,20.00000,6.440465e-08,0.82520,3
258.78016,180.00000,     -0.26642,      0.36328,50.00000,20.00000,6.436868e-08,0.82450,3
259.58917,180.80000,     -0.27325,      0.36247,50.00000,20.00000,6.432467e-08,0.82380,3
260.39710,181.60000,     -0.28045,      0.36212,50.00000,20.00000,6.433370e-08,0.82309,3
261.18710,182.40000,     -0.28730,      0.36213,50.00000,20.00000,6.438429e-08,0.82240,3
261.98830,183.20000,     -0.29637,      0.36145,50.00000,20.00000,6.433523e-08,0.82170,3
262.77716,184.00000,     -0.30509,      0.36134,50.00000,20.00000,6.450740e-08,0.82101,3
263.58004,184.80000,     -0.31180,      0.36132,50.00000,20.00000,6.445977e-08,0.82030,3
264.39329,185.60000,     -0.31760,      0.35998,50.00000,20.00000,6.450305e-08,0.81958,3
265.18721,186.40000,     -0.32819,      0.35964,50.00000,20.00000,6.440257e-08,0.81888,3
265.99324,187.20000,     -0.33605,      0.35862,50.00000,20.00000,6.438170e-08,0.81817,3
266.79715,188.00000,     -0.34226,      0.35863,50.00000,20.00000,6.450693e-08,0.81746,3
267.58922,188.80000,     -0.35163,      0.35793,50.00000,20.00000,6.453982e-08,0.81676,3
268.38524,189.60000,     -0.35971,      0.35794,50.00000,20.00000,6.456654e-08,0.81605,3
269.17324,190.40000,     -0.36575,      0.35727,50.00000,20.00000,6.461940e-08,0.81535,3
269.97921,191.20000,     -0.37350,      0.35625,50.00000,20.00000,6.445335e-08,0.81463,3
270.78718,192.00000,     -0.38367,      0.35558,50.00000,20.00000,6.457292e-08,0.81391,3
271.58509,192.80000,     -0.38846,      0.35557,50.00000,20.00000,6.457700e-08,0.81320,3
272.38417,193.60000,     -0.39753,      0.35489,50.00000,20.00000,6.469960e-08,0.81248,3
273.18122,194.40000,     -0.40736,      0.35353,50.00000,20.00000,6.471340e-08,0.81177,3
273.98422,195.20000,     -0.41557,      0.35183,50.00000,20.00000,6.460795e-08,0.81105,3
274.78514,196.00000,     -0.42078,      0.35139,50.00000,20.00000,6.471775e-08,0.81033,3
275.58901,196.80000,     -0.42974,      0.35002,50.00000,20.00000,6.484997e-08,0.80961,3
276.38418,197.60000,     -0.44003,      0.34969,50.00000,20.00000,6.473713e-08,0.80889,3
277.18621,198.40000,     -0.44976,      0.34902,50.00000,20.00000,6.481876e-08,0.80816,3
277.98413,199.20000,     -0.45672,      0.34834,50.00000,20.00000,6.490373e-08,0.80744,3
278.79119,200.00000,     -0.46556,      0.34563,50.00000,20.00000,6.485787e-08,0.80671,3
279.58613,200.80000,     -0.47517,      0.34482,50.00000,20.00000,6.502685e-08,0.80599,3
280.38123,201.60000,     -0.48101,      0.34380,50.00000,20.00000,6.498351e-08,0.80527,3
281.19115,202.40000,     -0.49366,      0.34109,50.00000,20.00000,6.499604e-08,0.80454,3
281.98514,203.20000,     -0.50182,      0.34109,50.00000,20.00000,6.494797e-08,0.80381,3
282.77724,204.00000,     -0.51131,      0.33973,50.00000,20.00000,6.503485e-08,0.80309,3
283.58513,204.80000,     -0.51912,      0.33701,50.00000,20.00000,6.501180e-08,0.80236,3
284.37121,205.60000,     -0.52900,      0.33566,50.00000,20.00000,6.513274e-08,0.80164,3
285.18007,206.40000,     -0.53855,      0.33430,50.00000,20.00000,6.513619e-08,0.80090,3
285.97433,207.20000,     -0.54469,      0.33159,50.00000,20.00000,6.493468e-08,0.80017,3
286.78426,208.00000,     -0.55520,      0.32888,50.00000,20.00000,6.515654e-08,0.79943,3
287.56519,208.80000,     -0.56670,      0.32616,50.00000,20.00000,6.506682e-08,0.79871,3
288.36404,209.60000,     -0.57214,      0.32480,50.00000,20.00000,6.519804e-08,0.79798,3
289.17714,210.40000,     -0.58174,      0.32105,50.00000,20.00000,6.520033e-08,0.79723,3
289.97527,211.20000,     -0.59331,      0.32105,50.00000,20.00000,6.521416e-08,0.79650,3
290.76814,212.00000,     -0.60068,      0.31688,50.00000,20.00000,6.536045e-08,0.79577,3
291.57019,212.80000,     -0.61302,      0.31516,50.00000,20.00000,6.533850e-08,0.79503,3
292.38309,213.60000,     -0.61817,      0.31236,50.00000,20.00000,6.526133e-08,0.79428,3
293.17318,214.40000,     -0.62864,      0.30963,50.00000,20.00000,6.536595e-08,0.79355,3
293.97521,215.20000,     -0.64180,      0.30490,50.00000,20.00000,6.548450e-08,0.79280,3
294.77225,216.00000,     -0.65213,      0.30217,50.00000,20.00000,6.543461e-08,0.79206,3
295.57117,216.80000,     -0.65980,      0.29947,50.00000,20.00000,6.543867e-08,0.79132,3
296.37705,217.60000,     -0.67017,      0.29539,50.00000,20.00000,6.554513e-08,0.79058,3
297.16405,218.40000,     -0.67884,      0.29336,50.00000,20.00000,6.559151e-08,0.78985,3
297.97316,219.20000,     -0.68712,      0.28792,50.00000,20.00000,6.560681e-08,0.78909,3
298.76613,220.00000,     -0.69869,      0.28385,50.00000,20.00000,6.569877e-08,0.78836,3
299.55605,220.80000,     -0.70933,      0.27910,50.00000,20.00000,6.566049e-08,0.78762,3
300.36624,221.60000,     -0.71557,      0.27504,50.00000,20.00000,6.565255e-08,0.78686,3
301.17210,222.40000,     -0.72700,      0.27063,50.00000,20.00000,6.563964e-08,0.78611,3
301.97027,223.20000,     -0.73830,      0.26653,50.00000,20.00000,6.581747e-08,0.78537,3
302.76630,224.00000,     -0.74843,      0.26201,50.00000,20.00000,6.571677e-08,0.78462,3
303.56423,224.80000,     -0.75587,      0.25658,50.00000,20.00000,6.570142e-08,0.78388,3
304.37003,225.60000,     -0.76952,      0.25116,50.00000,20.00000,6.579327e-08,0.78312,3
305.16403,226.40000,     -0.77646,      0.24573,50.00000,20.00000,6.574746e-08,0.78238,3
305.97419,227.20000,     -0.78801,      0.23895,50.00000,20.00000,6.588909e-08,0.78162,3
306.78010,228.00000,     -0.79709,      0.23396,50.00000,20.00000,6.580113e-08,0.78086,3
307.57304,228.80000,     -0.80929,      0.22717,50.00000,20.00000,6.594609e-08,0.78012,3
308.36912,229.60000,     -0.81918,      0.22039,50.00000,20.00000,6.601381e-08,0.77937,3
309.16117,230.40000,     -0.82772,      0.21495,50.00000,20.00000,6.592599e-08,0.77863,3
309.94916,231.20000,     -0.84055,      0.20681,50.00000,20.00000,6.593253e-08,0.77789,3
310.75713,232.00000,     -0.85070,      0.20003,50.00000,20.00000,6.620709e-08,0.77713,3
311.55621,232.80000,     -0.85757,      0.19290,50.00000,20.00000,6.605021e-08,0.77637,3
312.34924,233.60000,     -0.86911,      0.18454,50.00000,20.00000,6.615503e-08,0.77563,3
313.15416,234.40000,     -0.87795,      0.17638,50.00000,20.00000,6.608510e-08,0.77487,3
313.96116,235.20000,     -0.88799,      0.16880,50.00000,20.00000,6.627714e-08,0.77410,3
314.76420,236.00000,     -0.90176,      0.15794,50.00000,20.00000,6.623891e-08,0.77335,3
315.56126,236.80000,     -0.91026,      0.15115,50.00000,20.00000,6.626875e-08,0.77259,3
316.36235,237.60000,     -0.91662,      0.14165,50.00000,20.00000,6.620838e-08,0.77184,3
317.15211,238.40000,     -0.92947,      0.13079,50.00000,20.00000,6.639402e-08,0.77109,3
317.95918,239.20000,     -0.94195,      0.12118,50.00000,20.00000,6.635006e-08,0.77033,3
318.75816,240.00000,     -0.95014,      0.11021,50.00000,20.00000,6.631023e-08,0.76957,3
319.56526,240.80000,     -0.96053, 9.763959e-02,50.00000,20.00000,6.639516e-08,0.76880,3
320.36413,241.60000,     -0.97112, 8.667807e-02,50.00000,20.00000,6.655881e-08,0.76805,3
321.17520,242.40000,     -0.98033, 7.525000e-02,50.00000,20.00000,6.645202e-08,0.76728,3
321.97615,243.20000,     -0.99375, 6.269005e-02,50.00000,20.00000,6.646726e-08,0.76652,3
322.77327,244.00000,     -1.00635, 4.740407e-02,50.00000,20.00000,6.655456e-08,0.76576,3
323.57402,244.80000,     -1.01586, 3.507575e-02,50.00000,20.00000,6.654491e-08,0.76500,3
324.36822,245.60000,     -1.02733, 1.980601e-02,50.00000,20.00000,6.660635e-08,0.76425,3
325.16807,246.40000,     -1.03707, 4.446349e-03,50.00000,20.00000,6.664280e-08,0.76349,3
325.97220,247.20000,     -1.04623,-1.196443e-02,50.00000,20.00000,6.661045e-08,0.76272,3
326.76711,248.00000,     -1.05738,-2.702043e-02,50.00000,20.00000,6.671088e-08,0.76197,3
327.57327,248.80000,     -1.06737,-4.614492e-02,50.00000,20.00000,6.647732e-08,0.76120,3
328.37209,249.60000,     -1.07796,-6.433951e-02,50.00000,20.00000,6.666901e-08,0.76044,3
329.15911,250.40000,     -1.09157,-8.356860e-02,50.00000,20.00000,6.669469e-08,0.75969,3
329.97416,251.20000,     -1.10004,     -0.10238,50.00000,20.00000,6.685201e-08,0.75892,3
330.77721,252.00000,     -1.11230,     -0.12476,50.00000,20.00000,6.677328e-08,0.75815,3
331.57435,252.80000,     -1.12559,     -0.14602,50.00000,20.00000,6.673285e-08,0.75739,3
332.36212,253.60000,     -1.13649,     -0.16910,50.00000,20.00000,6.687990e-08,0.75664,3
333.15607,254.40000,     -1.14722,     -0.19252,50.00000,20.00000,6.697372e-08,0.75589,3
333.95418,255.20000,     -1.12067,     -0.22712,50.00000,20.00000,6.697444e-08,0.75513,3
334.75202,256.00000,     -1.21101,     -0.25699,50.00000,20.00000,6.699268e-08,0.75436,3
335.55413,256.80000,     -1.23110,     -0.28459,50.00000,20.00000,6.687828e-08,0.75360,3
336.37317,257.60000,     -1.24542,     -0.31437,50.00000,20.00000,6.703844e-08,0.75282,3
337.16918,258.40000,     -1.25391,     -0.34626,50.00000,20.00000,6.714092e-08,0.75206,3
337.97716,259.20000,     -1.26164,     -0.37962,50.00000,20.00000,6.714602e-08,0.75129,3
338.77510,260.00000,     -1.26694,     -0.41390,50.00000,20.00000,6.721111e-08,0.75053,3
339.57114,260.80000,     -1.27528,     -0.44955,50.00000,20.00000,6.720726e-08,0.74977,3
340.36218,261.60000,     -1.28644,     -0.48731,50.00000,20.00000,6.719221e-08,0.74901,3
341.16416,262.40000,     -1.29343,     -0.52466,50.00000,20.00000,6.727765e-08,0.74825,3
341.96321,263.20000,     -1.29858,     -0.56595,50.00000,20.00000,6.716871e-08,0.74748,3
342.76103,264.00000,     -1.30476,     -0.60632,50.00000,20.00000,6.721233e-08,0.74672,3
343.55120,264.80000,     -1.31278,     -0.65134,50.00000,20.00000,6.734793e-08,0.74597,3
344.36021,265.60000,     -1.32000,     -0.69546,50.00000,20.00000,6.739902e-08,0.74520,3
345.15709,266.40000,     -1.32703,     -0.74278,50.00000,20.00000,6.744501e-08,0.74444,3
345.95721,267.20000,     -1.33550,     -0.79342,50.00000,20.00000,6.743178e-08,0.74367,3
346.74909,268.00000,     -1.34236,     -0.84332,50.00000,20.00000,6.735481e-08,0.74292,3
347.55809,268.80000,     -1.34964,     -0.89571,50.00000,20.00000,6.761103e-08,0.74214,3
348.34222,269.60000,     -1.35774,     -0.95069,50.00000,20.00000,6.752166e-08,0.74140,3
349.14916,270.40000,     -1.36426,     -1.00657,50.00000,20.00000,6.762181e-08,0.74062,3
349.94409,271.20000,     -1.37485,     -1.06471,50.00000,20.00000,6.760577e-08,0.73987,3
350.75220,272.00000,     -1.38220,     -1.12399,50.00000,20.00000,6.771534e-08,0.73909,3
351.54719,272.80000,     -1.39140,     -1.18500,50.00000,20.00000,6.774560e-08,0.73834,3
352.34904,273.60000,     -1.40144,     -1.24970,50.00000,20.00000,6.777376e-08,0.73757,3
353.15630,274.40000,     -1.41193,     -1.31247,50.00000,20.00000,6.784311e-08,0.73680,3
353.94721,275.20000,     -1.42322,     -1.38112,50.00000,20.00000,6.782804e-08,0.73605,3
354.75112,276.00000,     -1.43394,     -1.44733,50.00000,20.00000,6.784493e-08,0.73528,3
355.54922,276.80000,     -1.44736,     -1.51710,50.00000,20.00000,6.796529e-08,0.73452,3
356.34710,277.60000,     -1.45916,     -1.58816,50.00000,20.00000,6.795479e-08,0.73376,3
357.14512,278.40000,     -1.47079,     -1.66011,50.00000,20.00000,6.799861e-08,0.73300,3
357.96318,279.20000,     -1.48576,     -1.73352,50.00000,20.00000,6.809770e-08,0.73222,3
358.74217,280.00000,     -1.50006,     -1.80662,50.00000,20.00000,6.818930e-08,0.73147,3
359.54904,280.80000,     -1.51572,     -1.88263,50.00000,20.00000,6.818731e-08,0.73070,3
360.34007,281.60000,     -1.53157,     -1.95772,50.00000,20.00000,6.828996e-08,0.72995,3
361.15714,282.40000,     -1.54500,     -2.03321,50.00000,20.00000,6.838661e-08,0.72917,3
361.94508,283.20000,     -1.56465,     -2.11024,50.00000,20.00000,6.838535e-08,0.72842,3
362.75016,284.00000,     -1.58166,     -2.18730,50.00000,20.00000,6.854587e-08,0.72765,3
363.55412,284.80000,     -1.59640,     -2.26366,50.00000,20.00000,6.851136e-08,0.72689,3
364.36421,285.60000,     -1.61827,     -2.34101,50.00000,20.00000,6.849978e-08,0.72612,3
365.15116,286.40000,     -1.63913,     -2.41705,50.00000,20.00000,6.852825e-08,0.72537,3
365.94406,287.20000,     -1.65978,     -2.49332,50.00000,20.00000,6.867299e-08,0.72462,3
366.74913,288.00000,     -1.67617,     -2.56830,50.00000,20.00000,6.875024e-08,0.72385,3
367.54216,288.80000,     -1.69858,     -2.64410,50.00000,20.00000,6.882584e-08,0.72310,3
368.34625,289.60000,     -1.72193,     -2.71618,50.00000,20.00000,6.893280e-08,0.72233,3
369.14313,290.40000,     -1.74028,     -2.78913,50.00000,20.00000,6.897877e-08,0.72158,3
369.93812,291.20000,     -1.76244,     -2.85987,50.00000,20.00000,6.903867e-08,0.72082,3
370.73408,292.00000,     -1.78692,     -2.93055,50.00000,20.00000,6.904372e-08,0.72007,3
371.54620,292.80000,     -1.81028,     -3.00059,50.00000,20.00000,6.910883e-08,0.71929,3
372.33718,293.60000,     -1.83089,     -3.06802,50.00000,20.00000,6.920881e-08,0.71854,3
373.15014,294.40000,     -1.85368,     -3.13476,50.00000,20.00000,6.929793e-08,0.71777,3
373.95411,295.20000,     -1.87989,     -3.19823,50.00000,20.00000,6.951366e-08,0.71701,3
374.74801,296.00000,     -1.90000,     -3.26225,50.00000,20.00000,6.953987e-08,0.71626,3
375.55520,296.80000,     -1.92630,     -3.32326,50.00000,20.00000,6.942279e-08,0.71550,3
376.33122,297.60000,     -1.95344,     -3.38322,50.00000,20.00000,6.960907e-08,0.71476,3
377.13815,298.40000,     -1.97583,     -3.44180,50.00000,20.00000,6.960976e-08,0.71400,3
377.93829,299.20000,     -1.99615,     -3.49702,50.00000,20.00000,6.965791e-08,0.71324,3
378.75016,300.00000,     -2.02310,     -3.55515,50.00000,20.00000,6.974086e-08,0.71248,3
379.54521,300.80000,     -2.05386,     -3.60719,50.00000,20.00000,6.995336e-08,0.71172,3
380.33924,301.60000,     -2.07349,     -3.65870,50.00000,20.00000,6.998728e-08,0.71098,3
381.13921,302.40000,     -2.10121,     -3.70892,50.00000,20.00000,6.996376e-08,0.71022,3
381.94214,303.20000,     -2.12880,     -3.75914,50.00000,20.00000,7.008970e-08,0.70946,3
382.73717,304.00000,     -2.15323,     -3.80735,50.00000,20.00000,7.014376e-08,0.70871,3
383.55111,304.80000,     -2.17924,     -3.85475,50.00000,20.00000,7.018007e-08,0.70795,3
384.35015,305.60000,     -2.20612,     -3.89866,50.00000,20.00000,7.022621e-08,0.70720,3
385.14926,306.40000,     -2.23454,     -3.94218,50.00000,20.00000,7.038912e-08,0.70644,3
385.95111,307.20000,     -2.26522,     -3.98373,50.00000,20.00000,7.044677e-08,0.70569,3
386.74914,308.00000,     -2.29288,     -4.02456,50.00000,20.00000,7.053457e-08,0.70494,3
387.55120,308.80000,     -2.32453,     -4.06290,50.00000,20.00000,7.048769e-08,0.70419,3
388.35602,309.60000,     -2.35431,     -4.10126,50.00000,20.00000,7.048313e-08,0.70343,3
389.14622,310.40000,     -2.38537,     -4.13533,50.00000,20.00000,7.055607e-08,0.70269,3
389.94521,311.20000,     -2.41934,     -4.17063,50.00000,20.00000,7.065637e-08,0.70194,3
390.74708,312.00000,     -2.45553,     -4.20240,50.00000,20.00000,7.078884e-08,0.70119,3
391.54518,312.80000,     -2.49891,     -4.23228,50.00000,20.00000,7.076955e-08,0.70044,3
392.34524,313.60000,     -2.54241,     -4.26091,50.00000,20.00000,7.076429e-08,0.69970,3
393.14006,314.40000,     -2.58811,     -4.28940,50.00000,20.00000,7.082997e-08,0.69895,3
393.94106,315.20000,     -2.63717,     -4.31466,50.00000,20.00000,7.087110e-08,0.69821,3
394.74412,316.00000,     -2.68680,     -4.33851,50.00000,20.00000,7.099463e-08,0.69746,3
395.54708,316.80000,     -2.74215,     -4.36046,50.00000,20.00000,7.106206e-08,0.69671,3
396.33810,317.60000,     -2.79564,     -4.37992,50.00000,20.00000,7.114511e-08,0.69597,3
397.14118,318.40000,     -2.84365,     -4.39768,50.00000,20.00000,7.126260e-08,0.69522,3
397.94025,319.20000,     -2.89217,     -4.41398,50.00000,20.00000,7.126319e-08,0.69448,3
398.75219,320.00000,     -2.93474,     -4.42936,50.00000,20.00000,7.124131e-08,0.69372,3
399.54131,320.80000,     -2.97292,     -4.44032,50.00000,20.00000,7.125222e-08,0.69299,3
401.47863,321.60000,     -2.10993,     -4.44580,50.00000,20.00000,7.140452e-08,0.69119,4
405.32136,322.40000,     -1.30609,     -4.44816,50.00000,20.00000,7.147206e-08,0.68764,4
408.77945,323.20000,     -1.52182,     -4.45461,50.00000,20.00000,7.146049e-08,0.68445,4
412.52584,324.00000,     -1.40569,     -4.46004,50.00000,20.00000,7.152587e-08,0.68102,4
416.52201,324.80000,     -1.34017,     -4.46074,50.00000,20.00000,7.165396e-08,0.67737,4
420.56985,325.60000,     -1.38738,     -4.46174,50.00000,20.00000,7.172559e-08,0.67369,4
424.67798,326.40000,     -1.44738,     -4.45970,50.00000,20.00000,7.165681e-08,0.66998,4
428.78425,327.20000,     -1.52588,     -4.45766,50.00000,20.00000,7.177858e-08,0.66629,4
432.89676,328.00000,     -1.62402,     -4.45495,50.00000,20.00000,7.191942e-08,0.66262,4
436.99508,328.80000,     -1.72162,     -4.45089,50.00000,20.00000,7.200696e-08,0.65899,4
441.08880,329.60000,     -1.83285,     -4.44986,50.00000,20.00000,7.210488e-08,0.65538,4
445.17046,330.40000,     -1.94367,     -4.44612,50.00000,20.00000,7.221263e-08,0.65181,4
449.24046,331.20000,     -2.05469,     -4.44409,50.00000,20.00000,7.229504e-08,0.64827,4
453.30593,332.00000,     -2.18059,     -4.44002,50.00000,20.00000,7.235992e-08,0.64476,4
457.34700,332.80000,     -2.30475,     -4.43728,50.00000,20.00000,7.244473e-08,0.64130,4
461.39088,333.60000,     -2.42119,     -4.43461,50.00000,20.00000,7.271294e-08,0.63786,4
465.43422,334.40000,     -2.54675,     -4.43187,50.00000,20.00000,7.272120e-08,0.63445,4
469.46546,335.20000,     -2.67508,     -4.42915,50.00000,20.00000,7.285712e-08,0.63108,4
473.47242,336.00000,     -2.80636,     -4.42609,50.00000,20.00000,7.312251e-08,0.62775,4
477.50066,336.80000,     -2.93250,     -4.42305,50.00000,20.00000,7.320522e-08,0.62444,4
481.52365,337.60000,     -3.06294,     -4.42169,50.00000,20.00000,7.333050e-08,0.62116,4
485.53457,338.40000,     -3.20550,     -4.41762,50.00000,20.00000,7.352032e-08,0.61791,4
489.53259,339.20000,     -3.33972,     -4.41490,50.00000,20.00000,7.368511e-08,0.61471,4
493.53714,340.00000,     -3.47977,     -4.41219,50.00000,20.00000,7.375013e-08,0.61153,4
497.54262,340.80000,     -3.61654,     -4.41049,50.00000,20.00000,7.392283e-08,0.60838,4
501.54918,341.60000,     -3.75862,     -4.40811,50.00000,20.00000,7.404919e-08,0.60525,4
505.54406,342.40000,     -3.90596,     -4.40504,50.00000,20.00000,7.420424e-08,0.60217,4
509.54980,343.20000,     -4.04407,     -4.40302,50.00000,20.00000,7.437541e-08,0.59911,4
513.54471,344.00000,     -4.20076,     -4.40166,50.00000,20.00000,7.449327e-08,0.59608,4
517.54735,344.80000,     -4.34156,     -4.39827,50.00000,20.00000,7.458826e-08,0.59308,4
521.55109,345.60000,     -4.49448,     -4.39623,50.00000,20.00000,7.482738e-08,0.59012,4
525.55494,346.40000,     -4.64013,     -4.39352,50.00000,20.00000,7.501028e-08,0.58718,4
529.54772,347.20000,     -4.79638,     -4.39182,50.00000,20.00000,7.509764e-08,0.58428,4
533.55282,348.00000,     -4.94159,     -4.39103,50.00000,20.00000,7.527902e-08,0.58140,4
537.55509,348.80000,     -5.09338,     -4.38832,50.00000,20.00000,7.531156e-08,0.57855,4
541.54681,349.60000,     -5.24369,     -4.38560,50.00000,20.00000,7.555232e-08,0.57575,4
545.56033,350.40000,     -5.39562,     -4.38390,50.00000,20.00000,7.568711e-08,0.57296,4
549.55173,351.20000,     -5.55116,     -4.38221,50.00000,20.00000,7.597996e-08,0.57021,4
553.55062,352.00000,     -5.69591,     -4.37949,50.00000,20.00000,7.605209e-08,0.56749,4
557.56069,352.80000,     -5.85120,     -4.37915,50.00000,20.00000,7.621783e-08,0.56480,4
561.54647,353.60000,     -6.00352,     -4.37744,50.00000,20.00000,7.646198e-08,0.56215,4
565.55376,354.40000,     -6.14306,     -4.37372,50.00000,20.00000,7.657083e-08,0.55951,4
569.57551,355.20000,     -6.28922,     -4.37236,50.00000,20.00000,7.676514e-08,0.55690,4
573.57011,356.00000,     -6.44748,     -4.37168,50.00000,20.00000,7.691841e-08,0.55434,4
577.56708,356.80000,     -6.58882,     -4.37168,50.00000,20.00000,7.706650e-08,0.55180,4
581.57366,357.60000,     -6.73352,     -4.36897,50.00000,20.00000,7.718800e-08,0.54929,4
585.58271,358.40000,     -6.87488,     -4.36761,50.00000,20.00000,7.744799e-08,0.54681,4
589.57199,359.20000,     -7.01572,     -4.36625,50.00000,20.00000,7.757371e-08,0.54436,4
593.58865,360.00000,     -7.15942,     -4.36490,50.00000,20.00000,7.761708e-08,0.54193,4
597.60371,360.80000,     -7.29993,     -4.36354,50.00000,20.00000,7.791705e-08,0.53953,4
601.58782,361.60000,     -7.43368,     -4.36218,50.00000,20.00000,7.799836e-08,0.53717,4
605.58816,362.40000,     -7.57102,     -4.36082,50.00000,20.00000,7.818365e-08,0.53484,4
609.60590,363.20000,     -7.70975,     -4.35947,50.00000,20.00000,7.826462e-08,0.53252,4
613.60288,364.00000,     -7.84471,     -4.35947,50.00000,20.00000,7.849765e-08,0.53024,4
617.60586,364.80000,     -7.97296,     -4.35811,50.00000,20.00000,7.848555e-08,0.52798,4
621.60714,365.60000,     -8.10871,     -4.35743,50.00000,20.00000,7.861466e-08,0.52575,4
625.61795,366.40000,     -8.24107,     -4.35709,50.00000,20.00000,7.876308e-08,0.52355,4
629.62674,367.20000,     -8.38048,     -4.35607,50.00000,20.00000,7.889814e-08,0.52136,4
633.63772,368.00000,     -8.51771,     -4.35571,50.00000,20.00000,7.901184e-08,0.51921,4
637.62725,368.80000,     -8.65013,     -4.35438,50.00000,20.00000,7.902374e-08,0.51708,4
641.63922,369.60000,     -8.76628,     -4.35268,50.00000,20.00000,7.910749e-08,0.51497,4
645.65375,370.40000,     -8.90198,     -4.35265,50.00000,20.00000,7.922811e-08,0.51289,4
649.64495,371.20000,     -9.02710,     -4.35169,50.00000,20.00000,7.942728e-08,0.51084,4
653.64915,372.00000,     -9.16283,     -4.35132,50.00000,20.00000,7.942133e-08,0.50880,4
657.66295,372.80000,     -9.29597,     -4.34996,50.00000,20.00000,7.950656e-08,0.50678,4
661.66481,373.60000,     -9.42649,     -4.34996,50.00000,20.00000,7.968538e-08,0.50479,4
665.66699,374.40000,     -9.55634,     -4.34895,50.00000,20.00000,7.983447e-08,0.50282,4
669.67967,375.20000,     -9.69336,     -4.34894,50.00000,20.00000,7.995878e-08,0.50087,4
673.66908,376.00000,     -9.82528,     -4.34759,50.00000,20.00000,7.997804e-08,0.49894,4
677.67812,376.80000,     -9.96526,     -4.34691,50.00000,20.00000,8.011291e-08,0.49703,4
681.68636,377.60000,    -10.09606,     -4.34691,50.00000,20.00000,8.012074e-08,0.49514,4
685.68681,378.40000,    -10.22695,     -4.34687,50.00000,20.00000,8.014289e-08,0.49326,4
689.69372,379.20000,    -10.33431,     -4.34452,50.00000,20.00000,8.044769e-08,0.49141,4
693.70518,380.00000,    -10.47980,     -4.34487,50.00000,20.00000,8.036479e-08,0.48956,4
697.70687,380.80000,    -10.63120,     -4.34419,50.00000,20.00000,8.058413e-08,0.48774,4
701.71744,381.60000,    -10.78467,     -4.34352,50.00000,20.00000,8.060593e-08,0.48593,4
705.73135,382.40000,    -10.93333,     -4.34352,50.00000,20.00000,8.077523e-08,0.48414,4
709.73431,383.20000,    -11.08419,     -4.34216,50.00000,20.00000,8.079608e-08,0.48236,4
713.73449,384.00000,    -11.23443,     -4.34079,50.00000,20.00000,8.094504e-08,0.48060,4
717.74620,384.80000,    -11.39816,     -4.34216,50.00000,20.00000,8.080815e-08,0.47885,4
721.74985,385.60000,    -11.55258,     -4.34080,50.00000,20.00000,8.083679e-08,0.47711,4
725.76197,386.40000,    -11.70413,     -4.34080,50.00000,20.00000,8.102072e-08,0.47538,4
729.75433,387.20000,    -11.85316,     -4.34046,50.00000,20.00000,8.095317e-08,0.47368,4
733.77532,388.00000,    -11.99529,     -4.33910,50.00000,20.00000,8.111158e-08,0.47197,4
737.78992,388.80000,    -12.15133,     -4.34046,50.00000,20.00000,8.120089e-08,0.47027,4
741.78803,389.60000,    -12.27087,     -4.33943,50.00000,20.00000,8.120617e-08,0.46859,4
745.79832,390.40000,    -12.43525,     -4.33808,50.00000,20.00000,8.129371e-08,0.46692,4
749.79775,391.20000,    -12.59922,     -4.33860,50.00000,20.00000,8.132373e-08,0.46526,4
753.80453,392.00000,    -12.76191,     -4.33922,50.00000,20.00000,8.137462e-08,0.46360,4
757.80597,392.80000,    -12.91085,     -4.33924,50.00000,20.00000,8.140355e-08,0.46195,4
761.82147,393.60000,    -13.06508,     -4.33786,50.00000,20.00000,8.137914e-08,0.46031,4
765.81864,394.40000,    -13.22260,     -4.33820,50.00000,20.00000,8.153168e-08,0.45868,4
769.82535,395.20000,    -13.37696,     -4.33821,50.00000,20.00000,8.153221e-08,0.45705,4
773.81894,396.00000,    -13.53574,     -4.33684,50.00000,20.00000,8.170663e-08,0.45543,4
777.81856,396.80000,    -13.69185,     -4.33684,50.00000,20.00000,8.177409e-08,0.45381,4
781.82673,397.60000,    -13.84900,     -4.33548,50.00000,20.00000,8.175814e-08,0.45219,4
785.82781,398.40000,    -14.00122,     -4.33650,50.00000,20.00000,8.168103e-08,0.45058,4
789.82411,399.20000,    -14.14985,     -4.33650,50.00000,20.00000,8.179225e-08,0.44897,4
793.82831,400.00000,    -14.31445,     -4.33413,50.00000,20.00000,8.174925e-08,0.44736,4
797.83492,400.80000,    -14.48005,     -4.33413,50.00000,20.00000,8.181205e-08,0.44575,4
798.34540,400.90000,    -14.50145,     -4.33413,50.00000,20.00000,8.181205e-08,0.44555,4