File: data/TGA/005c/ExpDat_2024_06_23_PS2439_6_1K_dynamic-slow.csv
#EXPORTTYPE:                 ,DATA ALL
#FILE:                       ,2024_06_23_PS2439_6_1K_dynamic-slow.ngb-ss5
#FORMAT:                     ,NETZSCH5
#FTYPE:                      ,ASCII
#IDENTITY:                   ,PS
#DECIMAL:                    ,POINT
#SEPARATOR:                  ,COMMA
#MTYPE:                      ,DSC
#INSTRUMENT:                 ,NETZSCH STA 449F5
#PROJECT:                    ,
#DATE/TIME:                  ,6/23/2024 7:02:45 PM (UTC-4)
#CORR. FILE:                 ,
#TEMPCAL:                    ,28-06-2023 13:26
#SENSITIVITY:                ,28-06-2023 13:53
#LABORATORY:                 ,
#OPERATOR:                   ,Stanley
#REMARK:                     ,
#SAMPLE:                     ,PS2439_6.1K
#SAMPLE MASS /mg:            ,5.0
#MATERIAL:                   ,
#REFERENCE:                  ,-----
#REFERENCE MASS /mg:         ,0
#TYPE OF CRUCIBLE:           ,Al2O3 85 ‘l, open
#SAMPLE CRUCIBLE MASS /mg:   ,0
#REFERENCE CRUCIBLE MASS /mg:,0
#DSC RANGE /‘V:              ,5000
#TG RANGE /mg:               ,35000
#TAU-R:                      ,---
#CORR. CODE:                 ,000
#EXO:                        ,-1
#RANGE:                      ,20›C....800›C/0.0....5.0K/min
#SEGMENT:                    ,S1-5/5
#SEG. 1:                     ,20›C/5.0(K/min)/100›C
#SEG. 2:                     ,100›C/00:05/100›C
#SEG. 3:                     ,100›C/2.0(K/min)/225›C
#SEG. 4:                     ,225›C/0.1(K/min)/350›C
#SEG. 5:                     ,350›C/5.0(K/min)/800›C

##Temp./›C,Time/min,DSC/(mW/mg),Mass loss/mg,Gas Flow(purge2)/(ml/min),Gas Flow(protective)/(ml/min),TIC(scan:1)/A,Sensit./(uV/mW),Segment
 31.83600,   0.00000,-5.169488e-02, 0.000000e+00,50.00000,20.00000,6.527058e-08,0.92388,1
 33.05000,   2.60000, 4.970191e-02, 1.866000e-02,50.00000,20.00000,6.434674e-08,0.92409,1
 37.83600,   5.20000,      0.38048,      0.10951,50.00000,20.00000,6.369553e-08,0.92480,1
 48.89200,   7.80000,      0.80308,      0.20816,50.00000,20.00000,6.287668e-08,0.92589,1
 64.00400,  10.40000,      1.09335,      0.27219,50.00000,20.00000,6.233979e-08,0.92612,1
 80.13100,  13.00000,      1.22329,      0.30567,50.00000,20.00000,6.182850e-08,0.92479,1
 95.71900,  15.60000,      1.29910,      0.32061,50.00000,20.00000,6.156537e-08,0.92203,1
105.82400,  18.20000,      0.51572,      0.25994,50.00000,20.00000,6.133901e-08,0.91949,2
107.96394,  20.80000, 3.604791e-02,      0.20325,50.00000,20.00000,6.110673e-08,0.91888,2
108.14394,  23.40000,      0.10729,      0.19741,50.00000,20.00000,6.090757e-08,0.91883,3
110.14766,  26.00000,      0.28108,      0.21076,50.00000,20.00000,6.071388e-08,0.91823,3
114.06568,  28.60000,      0.43858,      0.22399,50.00000,20.00000,6.036016e-08,0.91700,3
119.08903,  31.20000,      0.53124,      0.23418,50.00000,20.00000,6.018124e-08,0.91531,3
124.53824,  33.80000,      0.57134,      0.24311,50.00000,20.00000,5.996378e-08,0.91331,3
130.06294,  36.40000,      0.58015,      0.24672,50.00000,20.00000,5.985532e-08,0.91113,3
135.47626,  39.00000,      0.58005,      0.25069,50.00000,20.00000,5.975137e-08,0.90885,3
140.81201,  41.60000,      0.57804,      0.25385,50.00000,20.00000,5.966682e-08,0.90645,3
146.04541,  44.20000,      0.57601,      0.25872,50.00000,20.00000,5.970798e-08,0.90397,3
151.28160,  46.80000,      0.57791,      0.26167,50.00000,20.00000,5.970086e-08,0.90135,3
156.48418,  49.40000,      0.57764,      0.26517,50.00000,20.00000,5.978386e-08,0.89863,3
161.67418,  52.00000,      0.57501,      0.26956,50.00000,20.00000,5.980948e-08,0.89579,3
166.87127,  54.60000,      0.57257,      0.27227,50.00000,20.00000,5.979189e-08,0.89282,3
172.07476,  57.20000,      0.56654,      0.27999,50.00000,20.00000,5.981829e-08,0.88974,3
177.26172,  59.80000,      0.55902,      0.28492,50.00000,20.00000,5.986879e-08,0.88656,3
182.46425,  62.40000,      0.54693,      0.28723,50.00000,20.00000,6.007548e-08,0.88326,3
187.67580,  65.00000,      0.53316,      0.29232,50.00000,20.00000,6.004002e-08,0.87984,3
192.87723,  67.60000,      0.51829,      0.29753,50.00000,20.00000,6.027700e-08,0.87633,3
198.06033,  70.20000,      0.50224,      0.30045,50.00000,20.00000,6.037093e-08,0.87274,3
203.26891,  72.80000,      0.48450,      0.30454,50.00000,20.00000,6.055465e-08,0.86903,3
208.46509,  75.40000,      0.46424,      0.30873,50.00000,20.00000,6.058410e-08,0.86524,3
213.65924,  78.00000,      0.44099,      0.31397,50.00000,20.00000,6.077851e-08,0.86136,3
218.85039,  80.60000,      0.41555,      0.31900,50.00000,20.00000,6.093049e-08,0.85740,3
224.04614,  83.20000,      0.39017,      0.32163,50.00000,20.00000,6.097750e-08,0.85336,3
226.63825,  85.80000,     -0.19308,      0.30913,50.00000,20.00000,6.118432e-08,0.85131,4
227.03395,  88.40000,     -0.39056,      0.30081,50.00000,20.00000,6.139432e-08,0.85100,4
226.78961,  91.00000,     -0.43066,      0.29527,50.00000,20.00000,6.144789e-08,0.85119,4
226.59590,  93.60000,     -0.41393,      0.29080,50.00000,20.00000,6.163150e-08,0.85135,4
226.56189,  96.20000,     -0.39776,      0.28725,50.00000,20.00000,6.167161e-08,0.85137,4
226.66102,  98.80000,     -0.38182,      0.28222,50.00000,20.00000,6.167292e-08,0.85129,4
226.84467, 101.40000,     -0.37924,      0.28045,50.00000,20.00000,6.154173e-08,0.85115,4
227.05467, 104.00000,     -0.37532,      0.27811,50.00000,20.00000,6.154449e-08,0.85098,4
227.30789, 106.60000,     -0.37586,      0.27421,50.00000,20.00000,6.172353e-08,0.85078,4
227.56066, 109.20000,     -0.37611,      0.27253,50.00000,20.00000,6.177156e-08,0.85058,4
227.82342, 111.80000,     -0.38077,      0.27038,50.00000,20.00000,6.164138e-08,0.85037,4
228.07451, 114.40000,     -0.38138,      0.26711,50.00000,20.00000,6.159416e-08,0.85017,4
228.33842, 117.00000,     -0.38579,      0.26585,50.00000,20.00000,6.174883e-08,0.84996,4
228.59633, 119.60000,     -0.38744,      0.26551,50.00000,20.00000,6.158735e-08,0.84975,4
228.85985, 122.20000,     -0.39126,      0.26382,50.00000,20.00000,6.173960e-08,0.84954,4
229.11515, 124.80000,     -0.39167,      0.26397,50.00000,20.00000,6.177984e-08,0.84934,4
229.37819, 127.40000,     -0.39253,      0.26194,50.00000,20.00000,6.174028e-08,0.84913,4
229.64651, 130.00000,     -0.39599,      0.25952,50.00000,20.00000,6.159428e-08,0.84891,4
229.89177, 132.60000,     -0.39913,      0.25983,50.00000,20.00000,6.189331e-08,0.84872,4
230.15073, 135.20000,     -0.40192,      0.25815,50.00000,20.00000,6.175510e-08,0.84851,4
230.42218, 137.80000,     -0.40069,      0.25703,50.00000,20.00000,6.180175e-08,0.84829,4
230.68111, 140.40000,     -0.40441,      0.25620,50.00000,20.00000,6.173147e-08,0.84808,4
230.94100, 143.00000,     -0.40562,      0.25634,50.00000,20.00000,6.176373e-08,0.84787,4
231.20246, 145.60000,     -0.40745,      0.25567,50.00000,20.00000,6.173009e-08,0.84766,4
231.46808, 148.20000,     -0.41181,      0.25466,50.00000,20.00000,6.185278e-08,0.84745,4
231.70772, 150.80000,     -0.41477,      0.25486,50.00000,20.00000,6.189489e-08,0.84725,4
231.97405, 153.40000,     -0.41567,      0.25273,50.00000,20.00000,6.192317e-08,0.84704,4
232.23306, 156.00000,     -0.41613,      0.25395,50.00000,20.00000,6.202806e-08,0.84683,4
232.50009, 158.60000,     -0.42195,      0.25146,50.00000,20.00000,6.191049e-08,0.84661,4
232.75697, 161.20000,     -0.42283,      0.25229,50.00000,20.00000,6.185211e-08,0.84641,4
233.04058, 163.80000,     -0.42462,      0.24826,50.00000,20.00000,6.193356e-08,0.84618,4
233.28039, 166.40000,     -0.42582,      0.24866,50.00000,20.00000,6.197490e-08,0.84598,4
233.53433, 169.00000,     -0.42794,      0.24773,50.00000,20.00000,6.187674e-08,0.84578,4
233.80966, 171.60000,     -0.42681,      0.24761,50.00000,20.00000,6.194974e-08,0.84555,4
234.06477, 174.20000,     -0.43197,      0.24700,50.00000,20.00000,6.198573e-08,0.84534,4
234.31880, 176.80000,     -0.43390,      0.24623,50.00000,20.00000,6.199500e-08,0.84514,4
234.57262, 179.40000,     -0.43787,      0.24562,50.00000,20.00000,6.193971e-08,0.84493,4
234.83912, 182.00000,     -0.43766,      0.24492,50.00000,20.00000,6.199825e-08,0.84471,4
235.09261, 184.60000,     -0.43850,      0.24408,50.00000,20.00000,6.188449e-08,0.84451,4
235.36104, 187.20000,     -0.44244,      0.24436,50.00000,20.00000,6.200555e-08,0.84429,4
235.62406, 189.80000,     -0.44575,      0.24236,50.00000,20.00000,6.203341e-08,0.84407,4
235.89509, 192.40000,     -0.44583,      0.24345,50.00000,20.00000,6.210386e-08,0.84385,4
236.13699, 195.00000,     -0.45041,      0.24334,50.00000,20.00000,6.209151e-08,0.84365,4
236.40645, 197.60000,     -0.45026,      0.24065,50.00000,20.00000,6.199992e-08,0.84343,4
236.65866, 200.20000,     -0.45432,      0.24030,50.00000,20.00000,6.197966e-08,0.84323,4
236.92635, 202.80000,     -0.45649,      0.23953,50.00000,20.00000,6.207740e-08,0.84301,4
237.18240, 205.40000,     -0.45537,      0.23722,50.00000,20.00000,6.213247e-08,0.84280,4
237.44361, 208.00000,     -0.46149,      0.23720,50.00000,20.00000,6.212191e-08,0.84258,4
237.70964, 210.60000,     -0.46256,      0.23828,50.00000,20.00000,6.216255e-08,0.84236,4
237.94219, 213.20000,     -0.46627,      0.23689,50.00000,20.00000,6.209583e-08,0.84217,4
238.21170, 215.80000,     -0.46864,      0.23807,50.00000,20.00000,6.218601e-08,0.84195,4
238.47650, 218.40000,     -0.46917,      0.23526,50.00000,20.00000,6.217469e-08,0.84173,4
238.74161, 221.00000,     -0.46920,      0.23416,50.00000,20.00000,6.209951e-08,0.84151,4
238.99113, 223.60000,     -0.47331,      0.23510,50.00000,20.00000,6.221055e-08,0.84131,4
239.26416, 226.20000,     -0.47434,      0.23257,50.00000,20.00000,6.219858e-08,0.84108,4
239.52638, 228.80000,     -0.47777,      0.23135,50.00000,20.00000,6.215341e-08,0.84086,4
239.77292, 231.40000,     -0.47861,      0.23157,50.00000,20.00000,6.225459e-08,0.84066,4
240.02656, 234.00000,     -0.48110,      0.23158,50.00000,20.00000,6.213106e-08,0.84045,4
240.28595, 236.60000,     -0.48245,      0.23070,50.00000,20.00000,6.220487e-08,0.84023,4
240.55359, 239.20000,     -0.48429,      0.22947,50.00000,20.00000,6.218396e-08,0.84001,4
240.82504, 241.80000,     -0.48635,      0.22995,50.00000,20.00000,6.221297e-08,0.83979,4
241.07015, 244.40000,     -0.48706,      0.22897,50.00000,20.00000,6.210505e-08,0.83958,4
241.33324, 247.00000,     -0.49058,      0.22811,50.00000,20.00000,6.230173e-08,0.83936,4
241.60600, 249.60000,     -0.49177,      0.22648,50.00000,20.00000,6.226575e-08,0.83914,4
241.85658, 252.20000,     -0.49430,      0.22659,50.00000,20.00000,6.226378e-08,0.83893,4
242.11296, 254.80000,     -0.49705,      0.22512,50.00000,20.00000,6.229257e-08,0.83871,4
242.38256, 257.40000,     -0.49799,      0.22364,50.00000,20.00000,6.227493e-08,0.83849,4
242.63060, 260.00000,     -0.49674,      0.22420,50.00000,20.00000,6.229211e-08,0.83828,4
242.89930, 262.60000,     -0.49829,      0.22356,50.00000,20.00000,6.230379e-08,0.83806,4
243.16136, 265.20000,     -0.49982,      0.22434,50.00000,20.00000,6.240813e-08,0.83784,4
243.41631, 267.80000,     -0.50272,      0.22214,50.00000,20.00000,6.238023e-08,0.83763,4
243.68216, 270.40000,     -0.50128,      0.22330,50.00000,20.00000,6.250994e-08,0.83740,4
243.94323, 273.00000,     -0.50335,      0.22173,50.00000,20.00000,6.242064e-08,0.83718,4
244.19838, 275.60000,     -0.50317,      0.22006,50.00000,20.00000,6.244182e-08,0.83697,4
244.46964, 278.20000,     -0.50461,      0.22037,50.00000,20.00000,6.245064e-08,0.83674,4
244.72258, 280.80000,     -0.50868,      0.21977,50.00000,20.00000,6.239954e-08,0.83653,4
244.98907, 283.40000,     -0.50724,      0.21822,50.00000,20.00000,6.243133e-08,0.83631,4
245.24653, 286.00000,     -0.51195,      0.21581,50.00000,20.00000,6.255176e-08,0.83609,4
245.50453, 288.60000,     -0.51274,      0.21460,50.00000,20.00000,6.249610e-08,0.83587,4
245.74824, 291.20000,     -0.51283,      0.21248,50.00000,20.00000,6.252583e-08,0.83567,4
246.00842, 293.80000,     -0.51598,      0.21110,50.00000,20.00000,6.251565e-08,0.83545,4
246.27813, 296.40000,     -0.51514,      0.20972,50.00000,20.00000,6.252263e-08,0.83522,4
246.54227, 299.00000,     -0.51541,      0.20985,50.00000,20.00000,6.249090e-08,0.83500,4
246.79629, 301.60000,     -0.52019,      0.21019,50.00000,20.00000,6.248744e-08,0.83478,4
247.05527, 304.20000,     -0.52079,      0.20772,50.00000,20.00000,6.252729e-08,0.83456,4
247.32863, 306.80000,     -0.51951,      0.20804,50.00000,20.00000,6.260359e-08,0.83433,4
247.57868, 309.40000,     -0.52112,      0.20401,50.00000,20.00000,6.251501e-08,0.83412,4
247.84270, 312.00000,     -0.52324,      0.20415,50.00000,20.00000,6.254338e-08,0.83390,4
248.10013, 314.60000,     -0.52358,      0.20374,50.00000,20.00000,6.259293e-08,0.83368,4
248.35502, 317.20000,     -0.52318,      0.20238,50.00000,20.00000,6.253510e-08,0.83346,4
248.62566, 319.80000,     -0.52072,      0.20185,50.00000,20.00000,6.267211e-08,0.83323,4
248.87758, 322.40000,     -0.52659,      0.20149,50.00000,20.00000,6.262540e-08,0.83302,4
249.14002, 325.00000,     -0.52587,      0.20012,50.00000,20.00000,6.268091e-08,0.83280,4
249.40303, 327.60000,     -0.52650,      0.19872,50.00000,20.00000,6.264247e-08,0.83257,4
249.66582, 330.20000,     -0.52848,      0.19967,50.00000,20.00000,6.260431e-08,0.83235,4
249.91986, 332.80000,     -0.52920,      0.19969,50.00000,20.00000,6.267930e-08,0.83213,4
250.16979, 335.40000,     -0.52811,      0.19732,50.00000,20.00000,6.259905e-08,0.83192,4
250.44907, 338.00000,     -0.52247,      0.19594,50.00000,20.00000,6.270153e-08,0.83168,4
250.69880, 340.60000,     -0.52450,      0.19461,50.00000,20.00000,6.260323e-08,0.83147,4
250.95480, 343.20000,     -0.52719,      0.19264,50.00000,20.00000,6.277171e-08,0.83125,4
251.22187, 345.80000,     -0.52925,      0.19176,50.00000,20.00000,6.273155e-08,0.83102,4
251.47223, 348.40000,     -0.52811,      0.19100,50.00000,20.00000,6.270698e-08,0.83081,4
251.73232, 351.00000,     -0.52829,      0.18949,50.00000,20.00000,6.268080e-08,0.83059,4
252.00297, 353.60000,     -0.53024,      0.18837,50.00000,20.00000,6.274908e-08,0.83035,4
252.25203, 356.20000,     -0.53064,      0.19015,50.00000,20.00000,6.279733e-08,0.83014,4
252.51335, 358.80000,     -0.52939,      0.18716,50.00000,20.00000,6.268232e-08,0.82992,4
252.76830, 361.40000,     -0.53277,      0.18716,50.00000,20.00000,6.279066e-08,0.82970,4
253.04301, 364.00000,     -0.53343,      0.18566,50.00000,20.00000,6.272635e-08,0.82946,4
253.29645, 366.60000,     -0.53391,      0.18504,50.00000,20.00000,6.278838e-08,0.82924,4
253.55594, 369.20000,     -0.53358,      0.18315,50.00000,20.00000,6.287713e-08,0.82902,4
253.82174, 371.80000,     -0.53339,      0.18123,50.00000,20.00000,6.277742e-08,0.82879,4
254.07155, 374.40000,     -0.53582,      0.17938,50.00000,20.00000,6.281472e-08,0.82858,4
254.34692, 377.00000,     -0.53423,      0.17864,50.00000,20.00000,6.283920e-08,0.82834,4
254.60449, 379.60000,     -0.53773,      0.17763,50.00000,20.00000,6.290384e-08,0.82812,4
254.85724, 382.20000,     -0.53478,      0.17907,50.00000,20.00000,6.285472e-08,0.82790,4
255.11127, 384.80000,     -0.53726,      0.17750,50.00000,20.00000,6.292126e-08,0.82768,4
255.37504, 387.40000,     -0.53915,      0.17693,50.00000,20.00000,6.286757e-08,0.82745,4
255.63610, 390.00000,     -0.54217,      0.17468,50.00000,20.00000,6.295278e-08,0.82723,4
255.90508, 392.60000,     -0.54173,      0.17433,50.00000,20.00000,6.296194e-08,0.82700,4
256.15821, 395.20000,     -0.54299,      0.17365,50.00000,20.00000,6.294893e-08,0.82678,4
256.41799, 397.80000,     -0.54687,      0.17266,50.00000,20.00000,6.296596e-08,0.82655,4
256.67832, 400.40000,     -0.54581,      0.16918,50.00000,20.00000,6.294328e-08,0.82633,4
256.93631, 403.00000,     -0.54657,      0.16935,50.00000,20.00000,6.288880e-08,0.82610,4
257.19095, 405.60000,     -0.55109,      0.16901,50.00000,20.00000,6.302228e-08,0.82588,4
257.45502, 408.20000,     -0.55052,      0.16747,50.00000,20.00000,6.285870e-08,0.82565,4
257.71763, 410.80000,     -0.55323,      0.16688,50.00000,20.00000,6.305178e-08,0.82543,4
257.97056, 413.40000,     -0.55406,      0.16572,50.00000,20.00000,6.310505e-08,0.82521,4
258.22648, 416.00000,     -0.55825,      0.16426,50.00000,20.00000,6.301700e-08,0.82498,4
258.48826, 418.60000,     -0.55893,      0.16302,50.00000,20.00000,6.302123e-08,0.82476,4
258.74312, 421.20000,     -0.56009,      0.16128,50.00000,20.00000,6.311426e-08,0.82453,4
259.01019, 423.80000,     -0.56082,      0.16110,50.00000,20.00000,6.313459e-08,0.82430,4
259.28261, 426.40000,     -0.56111,      0.15850,50.00000,20.00000,6.308254e-08,0.82406,4
259.54266, 429.00000,     -0.56310,      0.15910,50.00000,20.00000,6.307607e-08,0.82384,4
259.79159, 431.60000,     -0.56421,      0.15584,50.00000,20.00000,6.303176e-08,0.82362,4
260.05485, 434.20000,     -0.56730,      0.15593,50.00000,20.00000,6.307265e-08,0.82339,4
260.32000, 436.80000,     -0.56640,      0.15591,50.00000,20.00000,6.315975e-08,0.82316,4
260.58298, 439.40000,     -0.56950,      0.15403,50.00000,20.00000,6.316993e-08,0.82293,4
260.84364, 442.00000,     -0.56984,      0.15306,50.00000,20.00000,6.309361e-08,0.82270,4
261.09452, 444.60000,     -0.56900,      0.15293,50.00000,20.00000,6.310213e-08,0.82248,4
261.36917, 447.20000,     -0.57445,      0.15094,50.00000,20.00000,6.314109e-08,0.82224,4
261.62241, 449.80000,     -0.57570,      0.14819,50.00000,20.00000,6.321512e-08,0.82202,4
261.87543, 452.40000,     -0.57117,      0.14832,50.00000,20.00000,6.332213e-08,0.82180,4
262.13863, 455.00000,     -0.57562,      0.14725,50.00000,20.00000,6.312618e-08,0.82157,4
262.39724, 457.60000,     -0.57651,      0.14593,50.00000,20.00000,6.322718e-08,0.82134,4
262.65996, 460.20000,     -0.58063,      0.14475,50.00000,20.00000,6.323848e-08,0.82111,4
262.91785, 462.80000,     -0.57885,      0.14322,50.00000,20.00000,6.322835e-08,0.82088,4
263.17572, 465.40000,     -0.57977,      0.14152,50.00000,20.00000,6.318014e-08,0.82066,4
263.43292, 468.00000,     -0.58294,      0.14016,50.00000,20.00000,6.322156e-08,0.82043,4
263.69729, 470.60000,     -0.58325,      0.13886,50.00000,20.00000,6.317024e-08,0.82020,4
263.96217, 473.20000,     -0.58266,      0.13743,50.00000,20.00000,6.315927e-08,0.81996,4
264.22463, 475.80000,     -0.58548,      0.13614,50.00000,20.00000,6.324575e-08,0.81973,4
264.48338, 478.40000,     -0.58603,      0.13521,50.00000,20.00000,6.320175e-08,0.81950,4
264.73456, 481.00000,     -0.58603,      0.13372,50.00000,20.00000,6.326222e-08,0.81928,4
265.00193, 483.60000,     -0.58761,      0.13089,50.00000,20.00000,6.326528e-08,0.81905,4
265.26235, 486.20000,     -0.59079,      0.12963,50.00000,20.00000,6.330786e-08,0.81882,4
265.52700, 488.80000,     -0.58979,      0.12860,50.00000,20.00000,6.324998e-08,0.81858,4
265.76895, 491.40000,     -0.59174,      0.12626,50.00000,20.00000,6.328584e-08,0.81837,4
266.05546, 494.00000,     -0.59357,      0.12590,50.00000,20.00000,6.327250e-08,0.81812,4
266.29640, 496.60000,     -0.59558,      0.12690,50.00000,20.00000,6.336960e-08,0.81790,4
266.56335, 499.20000,     -0.59703,      0.12421,50.00000,20.00000,6.335623e-08,0.81767,4
266.82468, 501.80000,     -0.59709,      0.12388,50.00000,20.00000,6.339190e-08,0.81744,4
267.07227, 504.40000,     -0.59489,      0.12154,50.00000,20.00000,6.346938e-08,0.81722,4
267.33943, 507.00000,     -0.59993,      0.11996,50.00000,20.00000,6.341098e-08,0.81698,4
267.60350, 509.60000,     -0.59816,      0.11658,50.00000,20.00000,6.347546e-08,0.81675,4
267.85966, 512.20000,     -0.60125,      0.11595,50.00000,20.00000,6.347111e-08,0.81652,4
268.11548, 514.80000,     -0.60551,      0.11530,50.00000,20.00000,6.343882e-08,0.81629,4
268.36799, 517.40000,     -0.60700,      0.11427,50.00000,20.00000,6.336922e-08,0.81607,4
268.62277, 520.00000,     -0.60610,      0.11119,50.00000,20.00000,6.338154e-08,0.81584,4
268.89824, 522.60000,     -0.60792,      0.11117,50.00000,20.00000,6.350002e-08,0.81559,4
269.15808, 525.20000,     -0.60690,      0.11084,50.00000,20.00000,6.353720e-08,0.81536,4
269.41221, 527.80000,     -0.61012,      0.10951,50.00000,20.00000,6.348318e-08,0.81514,4
269.66962, 530.40000,     -0.60824,      0.10747,50.00000,20.00000,6.341109e-08,0.81491,4
269.93652, 533.00000,     -0.61117,      0.10606,50.00000,20.00000,6.338501e-08,0.81467,4
270.20501, 535.60000,     -0.61191,      0.10416,50.00000,20.00000,6.351611e-08,0.81443,4
270.46036, 538.20000,     -0.61529,      0.10192,50.00000,20.00000,6.348055e-08,0.81420,4
270.71790, 540.80000,     -0.61484,      0.10238,50.00000,20.00000,6.350077e-08,0.81397,4
270.97258, 543.40000,     -0.61297, 9.978081e-02,50.00000,20.00000,6.352047e-08,0.81375,4
271.24604, 546.00000,     -0.61498, 9.774101e-02,50.00000,20.00000,6.349351e-08,0.81350,4
271.50421, 548.60000,     -0.61787, 9.721183e-02,50.00000,20.00000,6.345287e-08,0.81327,4
271.75303, 551.20000,     -0.61715, 9.469000e-02,50.00000,20.00000,6.350412e-08,0.81305,4
272.01573, 553.80000,     -0.61902, 9.332287e-02,50.00000,20.00000,6.359156e-08,0.81281,4
272.27124, 556.40000,     -0.61728, 9.265024e-02,50.00000,20.00000,6.365763e-08,0.81258,4
272.53992, 559.00000,     -0.62103, 9.094953e-02,50.00000,20.00000,6.363147e-08,0.81234,4
272.79695, 561.60000,     -0.61839, 8.855190e-02,50.00000,20.00000,6.363665e-08,0.81211,4
273.05255, 564.20000,     -0.62355, 8.585946e-02,50.00000,20.00000,6.361580e-08,0.81188,4
273.32254, 566.80000,     -0.62424, 8.625202e-02,50.00000,20.00000,6.355608e-08,0.81164,4
273.57025, 569.40000,     -0.62660, 8.367952e-02,50.00000,20.00000,6.368165e-08,0.81142,4
273.82265, 572.00000,     -0.62288, 8.281000e-02,50.00000,20.00000,6.360446e-08,0.81119,4
274.09756, 574.60000,     -0.62514, 8.178939e-02,50.00000,20.00000,6.370225e-08,0.81095,4
274.36189, 577.20000,     -0.62317, 7.975804e-02,50.00000,20.00000,6.369649e-08,0.81071,4
274.61180, 579.80000,     -0.62499, 7.684751e-02,50.00000,20.00000,6.373719e-08,0.81048,4
274.88338, 582.40000,     -0.62288, 7.691989e-02,50.00000,20.00000,6.374222e-08,0.81024,4
275.13747, 585.00000,     -0.62425, 7.549581e-02,50.00000,20.00000,6.385130e-08,0.81001,4
275.40518, 587.60000,     -0.62605, 7.309509e-02,50.00000,20.00000,6.384623e-08,0.80977,4
275.67990, 590.20000,     -0.62984, 7.090509e-02,50.00000,20.00000,6.382812e-08,0.80952,4
275.90994, 592.80000,     -0.63008, 6.833018e-02,50.00000,20.00000,6.374219e-08,0.80932,4
276.16956, 595.40000,     -0.62755, 6.696861e-02,50.00000,20.00000,6.374139e-08,0.80908,4
276.43101, 598.00000,     -0.62842, 6.560623e-02,50.00000,20.00000,6.376620e-08,0.80885,4
276.69085, 600.60000,     -0.62997, 6.458995e-02,50.00000,20.00000,6.378193e-08,0.80861,4
276.95009, 603.20000,     -0.63148, 6.290001e-02,50.00000,20.00000,6.380735e-08,0.80838,4
277.21881, 605.80000,     -0.62844, 6.152505e-02,50.00000,20.00000,6.377509e-08,0.80814,4
277.48268, 608.40000,     -0.63231, 6.016749e-02,50.00000,20.00000,6.380162e-08,0.80790,4
277.74386, 611.00000,     -0.63214, 5.679754e-02,50.00000,20.00000,6.390182e-08,0.80766,4
278.00805, 613.60000,     -0.63417, 5.519955e-02,50.00000,20.00000,6.384278e-08,0.80742,4
278.24977, 616.20000,     -0.63446, 5.317009e-02,50.00000,20.00000,6.389875e-08,0.80720,4
278.51213, 618.80000,     -0.63472, 4.979701e-02,50.00000,20.00000,6.387434e-08,0.80697,4
278.78068, 621.40000,     -0.63780, 4.933147e-02,50.00000,20.00000,6.378761e-08,0.80672,4
279.03180, 624.00000,     -0.63648, 4.504131e-02,50.00000,20.00000,6.384319e-08,0.80650,4
279.30252, 626.60000,     -0.63412, 4.603787e-02,50.00000,20.00000,6.388800e-08,0.80625,4
279.56088, 629.20000,     -0.63527, 4.351712e-02,50.00000,20.00000,6.381686e-08,0.80602,4
279.80683, 631.80000,     -0.63530, 4.358081e-02,50.00000,20.00000,6.390673e-08,0.80579,4
280.06725, 634.40000,     -0.63679, 3.976898e-02,50.00000,20.00000,6.396567e-08,0.80556,4
280.33303, 637.00000,     -0.63612, 3.834807e-02,50.00000,20.00000,6.397868e-08,0.80532,4
280.60095, 639.60000,     -0.63647, 3.562970e-02,50.00000,20.00000,6.388826e-08,0.80507,4
280.86711, 642.20000,     -0.63317, 3.456881e-02,50.00000,20.00000,6.385520e-08,0.80483,4
281.13343, 644.80000,     -0.63157, 3.091817e-02,50.00000,20.00000,6.397606e-08,0.80459,4
281.38695, 647.40000,     -0.63727, 2.896261e-02,50.00000,20.00000,6.387016e-08,0.80436,4
281.64215, 650.00000,     -0.63561, 2.715001e-02,50.00000,20.00000,6.396176e-08,0.80413,4
281.89757, 652.60000,     -0.63575, 2.450484e-02,50.00000,20.00000,6.408589e-08,0.80389,4
282.16066, 655.20000,     -0.63763, 2.386988e-02,50.00000,20.00000,6.398666e-08,0.80365,4
282.41340, 657.80000,     -0.63485, 2.121620e-02,50.00000,20.00000,6.405450e-08,0.80342,4
282.67473, 660.40000,     -0.63544, 2.074977e-02,50.00000,20.00000,6.406550e-08,0.80319,4
282.94627, 663.00000,     -0.63900, 1.731207e-02,50.00000,20.00000,6.413340e-08,0.80294,4
283.19873, 665.60000,     -0.63617, 1.561045e-02,50.00000,20.00000,6.406134e-08,0.80271,4
283.46258, 668.20000,     -0.63438, 1.200851e-02,50.00000,20.00000,6.409694e-08,0.80247,4
283.71575, 670.80000,     -0.63458, 1.108020e-02,50.00000,20.00000,6.419477e-08,0.80224,4
283.97597, 673.40000,     -0.63513, 9.692342e-03,50.00000,20.00000,6.412884e-08,0.80200,4
284.23364, 676.00000,     -0.63644, 6.995308e-03,50.00000,20.00000,6.419693e-08,0.80176,4
284.49290, 678.60000,     -0.63465, 3.655613e-03,50.00000,20.00000,6.416726e-08,0.80153,4
284.75504, 681.20000,     -0.63542, 1.236656e-03,50.00000,20.00000,6.425411e-08,0.80129,4
285.01651, 683.80000,     -0.63601,-6.455703e-04,50.00000,20.00000,6.411491e-08,0.80105,4
285.27865, 686.40000,     -0.63292,-2.993355e-03,50.00000,20.00000,6.418549e-08,0.80081,4
285.52958, 689.00000,     -0.63433,-4.953848e-03,50.00000,20.00000,6.425581e-08,0.80058,4
285.78679, 691.60000,     -0.63588,-6.793751e-03,50.00000,20.00000,6.424792e-08,0.80034,4
286.06381, 694.20000,     -0.63435,-9.024646e-03,50.00000,20.00000,6.421676e-08,0.80009,4
286.31463, 696.80000,     -0.63618,-1.305267e-02,50.00000,20.00000,6.428680e-08,0.79986,4
286.55993, 699.40000,     -0.63104,-1.460728e-02,50.00000,20.00000,6.431126e-08,0.79963,4
286.83907, 702.00000,     -0.63138,-1.730978e-02,50.00000,20.00000,6.426901e-08,0.79938,4
287.09027, 704.60000,     -0.63120,-2.002986e-02,50.00000,20.00000,6.419205e-08,0.79915,4
287.36170, 707.20000,     -0.62903,-2.274229e-02,50.00000,20.00000,6.435974e-08,0.79890,4
287.62038, 709.80000,     -0.62942,-2.562511e-02,50.00000,20.00000,6.423569e-08,0.79866,4
287.87287, 712.40000,     -0.62915,-2.771963e-02,50.00000,20.00000,6.434568e-08,0.79843,4
288.13329, 715.00000,     -0.62819,-3.055205e-02,50.00000,20.00000,6.433023e-08,0.79819,4
288.40039, 717.60000,     -0.62916,-3.187455e-02,50.00000,20.00000,6.434171e-08,0.79795,4
288.66013, 720.20000,     -0.63027,-3.609656e-02,50.00000,20.00000,6.437516e-08,0.79771,4
288.91838, 722.80000,     -0.63250,-3.683346e-02,50.00000,20.00000,6.441570e-08,0.79747,4
289.16839, 725.40000,     -0.63169,-4.045714e-02,50.00000,20.00000,6.440618e-08,0.79724,4
289.43306, 728.00000,     -0.63167,-4.347216e-02,50.00000,20.00000,6.433731e-08,0.79700,4
289.68607, 730.60000,     -0.63111,-4.741126e-02,50.00000,20.00000,6.447804e-08,0.79676,4
289.95732, 733.20000,     -0.62776,-4.911642e-02,50.00000,20.00000,6.439549e-08,0.79651,4
290.21716, 735.80000,     -0.62749,-5.105079e-02,50.00000,20.00000,6.439283e-08,0.79627,4
290.47711, 738.40000,     -0.63043,-5.476566e-02,50.00000,20.00000,6.439383e-08,0.79603,4
290.73007, 741.00000,     -0.62478,-5.658282e-02,50.00000,20.00000,6.439592e-08,0.79580,4
291.00205, 743.60000,     -0.62559,-6.008037e-02,50.00000,20.00000,6.444265e-08,0.79555,4
291.25559, 746.20000,     -0.62458,-6.223180e-02,50.00000,20.00000,6.460841e-08,0.79532,4
291.52100, 748.80000,     -0.62439,-6.585223e-02,50.00000,20.00000,6.457764e-08,0.79507,4
291.77252, 751.40000,     -0.62525,-6.877427e-02,50.00000,20.00000,6.459374e-08,0.79484,4
292.02883, 754.00000,     -0.61978,-7.218379e-02,50.00000,20.00000,6.463738e-08,0.79460,4
292.29974, 756.60000,     -0.61639,-7.557000e-02,50.00000,20.00000,6.464229e-08,0.79435,4
292.56435, 759.20000,     -0.61585,-7.784080e-02,50.00000,20.00000,6.462349e-08,0.79411,4
292.81248, 761.80000,     -0.61184,-8.198174e-02,50.00000,20.00000,6.466121e-08,0.79388,4
293.07951, 764.40000,     -0.61509,-8.621354e-02,50.00000,20.00000,6.464280e-08,0.79363,4
293.33475, 767.00000,     -0.61123,-8.881083e-02,50.00000,20.00000,6.467841e-08,0.79340,4
293.59684, 769.60000,     -0.61079,-9.278050e-02,50.00000,20.00000,6.474413e-08,0.79315,4
293.85873, 772.20000,     -0.61143,-9.550248e-02,50.00000,20.00000,6.459397e-08,0.79291,4
294.11322, 774.80000,     -0.60996,-9.859683e-02,50.00000,20.00000,6.467237e-08,0.79268,4
294.38062, 777.40000,     -0.60779,     -0.10060,50.00000,20.00000,6.470945e-08,0.79243,4
294.64132, 780.00000,     -0.60632,     -0.10519,50.00000,20.00000,6.472204e-08,0.79219,4
294.90236, 782.60000,     -0.60681,     -0.10954,50.00000,20.00000,6.468379e-08,0.79194,4
295.15909, 785.20000,     -0.59893,     -0.11313,50.00000,20.00000,6.473775e-08,0.79171,4
295.41235, 787.80000,     -0.60124,     -0.11635,50.00000,20.00000,6.475576e-08,0.79147,4
295.67095, 790.40000,     -0.59432,     -0.11868,50.00000,20.00000,6.480319e-08,0.79123,4
295.93340, 793.00000,     -0.59532,     -0.12207,50.00000,20.00000,6.473406e-08,0.79099,4
296.19795, 795.60000,     -0.59328,     -0.12577,50.00000,20.00000,6.469530e-08,0.79074,4
296.45382, 798.20000,     -0.59195,     -0.12905,50.00000,20.00000,6.475513e-08,0.79051,4
296.71965, 800.80000,     -0.59317,     -0.13351,50.00000,20.00000,6.483502e-08,0.79026,4
296.97484, 803.40000,     -0.59008,     -0.13551,50.00000,20.00000,6.477573e-08,0.79002,4
297.23720, 806.00000,     -0.57005,     -0.14164,50.00000,20.00000,6.476426e-08,0.78978,4
297.49459, 808.60000,     -0.56892,     -0.14642,50.00000,20.00000,6.484561e-08,0.78954,4
297.75751, 811.20000,     -0.56812,     -0.14875,50.00000,20.00000,6.494597e-08,0.78929,4
298.01623, 813.80000,     -0.56462,     -0.15381,50.00000,20.00000,6.486956e-08,0.78905,4
298.27657, 816.40000,     -0.56261,     -0.15706,50.00000,20.00000,6.484305e-08,0.78881,4
298.52986, 819.00000,     -0.56190,     -0.15969,50.00000,20.00000,6.485243e-08,0.78858,4
298.78500, 821.60000,     -0.55749,     -0.16439,50.00000,20.00000,6.485186e-08,0.78834,4
299.06309, 824.20000,     -0.55389,     -0.16936,50.00000,20.00000,6.493615e-08,0.78808,4
299.32196, 826.80000,     -0.55231,     -0.17217,50.00000,20.00000,6.486850e-08,0.78784,4
299.56681, 829.40000,     -0.54945,     -0.17672,50.00000,20.00000,6.490133e-08,0.78761,4
299.84047, 832.00000,     -0.54259,     -0.18083,50.00000,20.00000,6.493696e-08,0.78735,4
300.10026, 834.60000,     -0.54415,     -0.18475,50.00000,20.00000,6.495330e-08,0.78711,4
300.36304, 837.20000,     -0.54114,     -0.18859,50.00000,20.00000,6.498507e-08,0.78687,4
300.61387, 839.80000,     -0.53939,     -0.19314,50.00000,20.00000,6.491886e-08,0.78663,4
300.87408, 842.40000,     -0.53757,     -0.19809,50.00000,20.00000,6.488627e-08,0.78639,4
301.14435, 845.00000,     -0.53363,     -0.20217,50.00000,20.00000,6.502046e-08,0.78614,4
301.39198, 847.60000,     -0.53208,     -0.20590,50.00000,20.00000,6.497089e-08,0.78591,4
301.66002, 850.20000,     -0.53226,     -0.21134,50.00000,20.00000,6.502432e-08,0.78566,4
301.91880, 852.80000,     -0.52384,     -0.21574,50.00000,20.00000,6.501431e-08,0.78542,4
302.18172, 855.40000,     -0.52356,     -0.21906,50.00000,20.00000,6.510025e-08,0.78517,4
302.43519, 858.00000,     -0.52265,     -0.22494,50.00000,20.00000,6.506009e-08,0.78493,4
302.68830, 860.60000,     -0.52097,     -0.22977,50.00000,20.00000,6.504955e-08,0.78470,4
302.95411, 863.20000,     -0.51772,     -0.23337,50.00000,20.00000,6.503719e-08,0.78445,4
303.21952, 865.80000,     -0.51207,     -0.23975,50.00000,20.00000,6.504829e-08,0.78420,4
303.47265, 868.40000,     -0.50906,     -0.24407,50.00000,20.00000,6.515124e-08,0.78396,4
303.74181, 871.00000,     -0.50313,     -0.24956,50.00000,20.00000,6.522980e-08,0.78371,4
303.98718, 873.60000,     -0.50526,     -0.25360,50.00000,20.00000,6.508007e-08,0.78348,4
304.25337, 876.20000,     -0.50223,     -0.25977,50.00000,20.00000,6.512350e-08,0.78323,4
304.51609, 878.80000,     -0.49864,     -0.26416,50.00000,20.00000,6.517939e-08,0.78299,4
304.77700, 881.40000,     -0.49886,     -0.26997,50.00000,20.00000,6.526984e-08,0.78274,4
305.03748, 884.00000,     -0.49661,     -0.27528,50.00000,20.00000,6.515999e-08,0.78250,4
305.29048, 886.60000,     -0.49357,     -0.27935,50.00000,20.00000,6.517915e-08,0.78226,4
305.55556, 889.20000,     -0.48838,     -0.28694,50.00000,20.00000,6.531100e-08,0.78201,4
305.80459, 891.80000,     -0.49045,     -0.29061,50.00000,20.00000,6.529981e-08,0.78178,4
306.07858, 894.40000,     -0.48779,     -0.29456,50.00000,20.00000,6.528253e-08,0.78152,4
306.34121, 897.00000,     -0.48944,     -0.30137,50.00000,20.00000,6.527703e-08,0.78128,4
306.59765, 899.60000,     -0.48415,     -0.30843,50.00000,20.00000,6.533315e-08,0.78104,4
306.85239, 902.20000,     -0.48486,     -0.31281,50.00000,20.00000,6.520468e-08,0.78080,4
307.11872, 904.80000,     -0.48350,     -0.31767,50.00000,20.00000,6.519588e-08,0.78055,4
307.38376, 907.40000,     -0.47964,     -0.32379,50.00000,20.00000,6.536115e-08,0.78030,4
307.63045, 910.00000,     -0.47712,     -0.32958,50.00000,20.00000,6.522019e-08,0.78007,4
307.90389, 912.60000,     -0.47905,     -0.33462,50.00000,20.00000,6.532113e-08,0.77981,4
308.15409, 915.20000,     -0.47599,     -0.34109,50.00000,20.00000,6.528024e-08,0.77957,4
308.41819, 917.80000,     -0.47201,     -0.34653,50.00000,20.00000,6.528035e-08,0.77933,4
308.68326, 920.40000,     -0.47275,     -0.35330,50.00000,20.00000,6.531647e-08,0.77908,4
308.92997, 923.00000,     -0.47452,     -0.35773,50.00000,20.00000,6.541047e-08,0.77884,4
309.19059, 925.60000,     -0.47056,     -0.36349,50.00000,20.00000,6.540752e-08,0.77860,4
309.45803, 928.20000,     -0.46962,     -0.37025,50.00000,20.00000,6.546100e-08,0.77835,4
309.71939, 930.80000,     -0.46967,     -0.37561,50.00000,20.00000,6.535520e-08,0.77810,4
309.97233, 933.40000,     -0.46712,     -0.38179,50.00000,20.00000,6.537928e-08,0.77786,4
310.23392, 936.00000,     -0.46744,     -0.38861,50.00000,20.00000,6.553569e-08,0.77762,4
310.50595, 938.60000,     -0.46678,     -0.39570,50.00000,20.00000,6.548326e-08,0.77736,4
310.75923, 941.20000,     -0.46696,     -0.40079,50.00000,20.00000,6.548661e-08,0.77712,4
311.01433, 943.80000,     -0.46582,     -0.40812,50.00000,20.00000,6.546506e-08,0.77688,4
311.27150, 946.40000,     -0.46345,     -0.41344,50.00000,20.00000,6.563131e-08,0.77664,4
311.54362, 949.00000,     -0.46791,     -0.42062,50.00000,20.00000,6.550579e-08,0.77638,4
311.79800, 951.60000,     -0.46723,     -0.42738,50.00000,20.00000,6.553867e-08,0.77614,4
312.04528, 954.20000,     -0.46674,     -0.43310,50.00000,20.00000,6.548306e-08,0.77591,4
312.31604, 956.80000,     -0.46801,     -0.44033,50.00000,20.00000,6.558723e-08,0.77566,4
312.57736, 959.40000,     -0.46591,     -0.44790,50.00000,20.00000,6.564012e-08,0.77541,4
312.83649, 962.00000,     -0.46923,     -0.45354,50.00000,20.00000,6.557744e-08,0.77517,4
313.09720, 964.60000,     -0.46923,     -0.45999,50.00000,20.00000,6.559592e-08,0.77492,4
313.36614, 967.20000,     -0.47220,     -0.46690,50.00000,20.00000,6.556917e-08,0.77467,4
313.60924, 969.80000,     -0.47691,     -0.47289,50.00000,20.00000,6.565615e-08,0.77444,4
313.87901, 972.40000,     -0.47913,     -0.47970,50.00000,20.00000,6.565625e-08,0.77418,4
314.15477, 975.00000,     -0.48463,     -0.48653,50.00000,20.00000,6.550800e-08,0.77392,4
314.39352, 977.60000,     -0.49968,     -0.49492,50.00000,20.00000,6.566744e-08,0.77370,4
314.65999, 980.20000,     -0.50333,     -0.50226,50.00000,20.00000,6.564603e-08,0.77344,4
314.91521, 982.80000,     -0.50324,     -0.51091,50.00000,20.00000,6.566951e-08,0.77320,4
315.17779, 985.40000,     -0.51022,     -0.51753,50.00000,20.00000,6.564888e-08,0.77296,4
315.43233, 988.00000,     -0.51228,     -0.52562,50.00000,20.00000,6.569348e-08,0.77272,4
315.69511, 990.60000,     -0.51195,     -0.53092,50.00000,20.00000,6.569541e-08,0.77247,4
315.94755, 993.20000,     -0.49959,     -0.53839,50.00000,20.00000,6.569644e-08,0.77223,4
316.20917, 995.80000,     -0.50236,     -0.54552,50.00000,20.00000,6.574933e-08,0.77198,4
316.47076, 998.40000,     -0.50196,     -0.55243,50.00000,20.00000,6.582246e-08,0.77173,4
316.74465,1001.00000,     -0.50210,     -0.56078,50.00000,20.00000,6.575731e-08,0.77147,4
317.01383,1003.60000,     -0.50866,     -0.56927,50.00000,20.00000,6.575246e-08,0.77122,4
317.28667,1006.20000,     -0.51212,     -0.57663,50.00000,20.00000,6.572665e-08,0.77096,4
317.52750,1008.80000,     -0.51382,     -0.58474,50.00000,20.00000,6.578806e-08,0.77073,4
317.78503,1011.40000,     -0.51480,     -0.59219,50.00000,20.00000,6.578165e-08,0.77049,4
318.04720,1014.00000,     -0.51875,     -0.60181,50.00000,20.00000,6.577723e-08,0.77024,4
318.30921,1016.60000,     -0.52239,     -0.60921,50.00000,20.00000,6.588693e-08,0.76999,4
318.56999,1019.20000,     -0.52316,     -0.61804,50.00000,20.00000,6.581945e-08,0.76975,4
318.81839,1021.80000,     -0.52720,     -0.62653,50.00000,20.00000,6.591609e-08,0.76951,4
319.09786,1024.40000,     -0.52835,     -0.63461,50.00000,20.00000,6.581020e-08,0.76925,4
319.35745,1027.00000,     -0.52720,     -0.64540,50.00000,20.00000,6.581043e-08,0.76900,4
319.60903,1029.60000,     -0.53327,     -0.65435,50.00000,20.00000,6.583319e-08,0.76876,4
319.87365,1032.20000,     -0.53776,     -0.66321,50.00000,20.00000,6.584530e-08,0.76851,4
320.14344,1034.80000,     -0.53955,     -0.67198,50.00000,20.00000,6.590098e-08,0.76826,4
320.38985,1037.40000,     -0.54712,     -0.68173,50.00000,20.00000,6.587127e-08,0.76802,4
320.65049,1040.00000,     -0.54594,     -0.69135,50.00000,20.00000,6.585464e-08,0.76778,4
320.91356,1042.60000,     -0.54775,     -0.69969,50.00000,20.00000,6.590636e-08,0.76753,4
321.17443,1045.20000,     -0.54890,     -0.70906,50.00000,20.00000,6.595430e-08,0.76728,4
321.43123,1047.80000,     -0.55694,     -0.71806,50.00000,20.00000,6.595339e-08,0.76704,4
321.67461,1050.40000,     -0.55802,     -0.72912,50.00000,20.00000,6.590303e-08,0.76680,4
321.95972,1053.00000,     -0.56177,     -0.73969,50.00000,20.00000,6.606693e-08,0.76653,4
322.20863,1055.60000,     -0.56413,     -0.74981,50.00000,20.00000,6.595771e-08,0.76630,4
322.46845,1058.20000,     -0.56879,     -0.75941,50.00000,20.00000,6.590015e-08,0.76605,4
322.71865,1060.80000,     -0.57447,     -0.76907,50.00000,20.00000,6.597079e-08,0.76581,4
322.98400,1063.40000,     -0.57552,     -0.78147,50.00000,20.00000,6.602016e-08,0.76556,4
323.24821,1066.00000,     -0.58219,     -0.79078,50.00000,20.00000,6.613940e-08,0.76531,4
323.50606,1068.60000,     -0.58552,     -0.80024,50.00000,20.00000,6.597533e-08,0.76507,4
323.76773,1071.20000,     -0.58728,     -0.81373,50.00000,20.00000,6.612503e-08,0.76482,4
324.03453,1073.80000,     -0.59254,     -0.82330,50.00000,20.00000,6.602313e-08,0.76457,4
324.28994,1076.40000,     -0.59520,     -0.83362,50.00000,20.00000,6.609566e-08,0.76432,4
324.54890,1079.00000,     -0.59962,     -0.84554,50.00000,20.00000,6.619718e-08,0.76408,4
324.80118,1081.60000,     -0.60454,     -0.85708,50.00000,20.00000,6.609901e-08,0.76384,4
325.06913,1084.20000,     -0.61142,     -0.86837,50.00000,20.00000,6.603143e-08,0.76358,4
325.32395,1086.80000,     -0.61803,     -0.87993,50.00000,20.00000,6.611306e-08,0.76334,4
325.55998,1089.40000,     -0.62088,     -0.89361,50.00000,20.00000,6.602992e-08,0.76312,4
325.83285,1092.00000,     -0.62494,     -0.90352,50.00000,20.00000,6.617710e-08,0.76286,4
326.11559,1094.60000,     -0.62637,     -0.91613,50.00000,20.00000,6.617522e-08,0.76259,4
326.37950,1097.20000,     -0.62761,     -0.92864,50.00000,20.00000,6.614722e-08,0.76234,4
326.64048,1099.80000,     -0.63502,     -0.94052,50.00000,20.00000,6.622574e-08,0.76209,4
326.89935,1102.40000,     -0.64290,     -0.95403,50.00000,20.00000,6.616560e-08,0.76184,4
327.15619,1105.00000,     -0.64631,     -0.96620,50.00000,20.00000,6.618263e-08,0.76160,4
327.41461,1107.60000,     -0.64863,     -0.97980,50.00000,20.00000,6.618073e-08,0.76135,4
327.68229,1110.20000,     -0.65647,     -0.99362,50.00000,20.00000,6.619361e-08,0.76110,4
327.94045,1112.80000,     -0.65877,     -1.00639,50.00000,20.00000,6.629264e-08,0.76085,4
328.19029,1115.40000,     -0.66550,     -1.02067,50.00000,20.00000,6.615297e-08,0.76061,4
328.45178,1118.00000,     -0.66763,     -1.03283,50.00000,20.00000,6.621794e-08,0.76037,4
328.71115,1120.60000,     -0.67314,     -1.04795,50.00000,20.00000,6.627721e-08,0.76012,4
328.96089,1123.20000,     -0.67861,     -1.06197,50.00000,20.00000,6.618134e-08,0.75988,4
329.23458,1125.80000,     -0.68260,     -1.07709,50.00000,20.00000,6.628937e-08,0.75962,4
329.50165,1128.40000,     -0.68912,     -1.09168,50.00000,20.00000,6.622658e-08,0.75937,4
329.76173,1131.00000,     -0.69122,     -1.10563,50.00000,20.00000,6.628813e-08,0.75912,4
330.00688,1133.60000,     -0.69606,     -1.12168,50.00000,20.00000,6.635610e-08,0.75889,4
330.27616,1136.20000,     -0.69711,     -1.13647,50.00000,20.00000,6.636746e-08,0.75863,4
330.52529,1138.80000,     -0.70191,     -1.15145,50.00000,20.00000,6.634438e-08,0.75839,4
330.79209,1141.40000,     -0.70777,     -1.16782,50.00000,20.00000,6.636307e-08,0.75814,4
331.05437,1144.00000,     -0.71281,     -1.18289,50.00000,20.00000,6.637222e-08,0.75789,4
331.31050,1146.60000,     -0.72135,     -1.19943,50.00000,20.00000,6.640100e-08,0.75764,4
331.56558,1149.20000,     -0.72749,     -1.21443,50.00000,20.00000,6.647262e-08,0.75740,4
331.82097,1151.80000,     -0.73194,     -1.23168,50.00000,20.00000,6.638785e-08,0.75716,4
332.08607,1154.40000,     -0.73378,     -1.24771,50.00000,20.00000,6.643705e-08,0.75691,4
332.35732,1157.00000,     -0.73306,     -1.26444,50.00000,20.00000,6.645312e-08,0.75665,4
332.61751,1159.60000,     -0.73140,     -1.28258,50.00000,20.00000,6.636926e-08,0.75640,4
332.87286,1162.20000,     -0.73718,     -1.30100,50.00000,20.00000,6.637818e-08,0.75616,4
333.13297,1164.80000,     -0.74083,     -1.31798,50.00000,20.00000,6.643127e-08,0.75591,4
333.38576,1167.40000,     -0.74566,     -1.33617,50.00000,20.00000,6.642450e-08,0.75567,4
333.64865,1170.00000,     -0.75138,     -1.35462,50.00000,20.00000,6.643707e-08,0.75542,4
333.90327,1172.60000,     -0.75586,     -1.37205,50.00000,20.00000,6.660113e-08,0.75517,4
334.16895,1175.20000,     -0.76235,     -1.39151,50.00000,20.00000,6.649555e-08,0.75492,4
334.42019,1177.80000,     -0.76962,     -1.41219,50.00000,20.00000,6.663689e-08,0.75468,4
334.69437,1180.40000,     -0.77332,     -1.43230,50.00000,20.00000,6.662529e-08,0.75442,4
334.96264,1183.00000,     -0.78106,     -1.45159,50.00000,20.00000,6.666555e-08,0.75416,4
335.21944,1185.60000,     -0.78878,     -1.47081,50.00000,20.00000,6.659019e-08,0.75392,4
335.46557,1188.20000,     -0.79315,     -1.49134,50.00000,20.00000,6.669585e-08,0.75368,4
335.73775,1190.80000,     -0.79799,     -1.51379,50.00000,20.00000,6.661863e-08,0.75342,4
335.98956,1193.40000,     -0.80954,     -1.53343,50.00000,20.00000,6.669171e-08,0.75318,4
336.25289,1196.00000,     -0.82069,     -1.55678,50.00000,20.00000,6.668738e-08,0.75293,4
336.50733,1198.60000,     -0.82701,     -1.57734,50.00000,20.00000,6.674079e-08,0.75269,4
336.76402,1201.20000,     -0.83503,     -1.59914,50.00000,20.00000,6.663422e-08,0.75245,4
337.01874,1203.80000,     -0.84220,     -1.62148,50.00000,20.00000,6.671374e-08,0.75220,4
337.28959,1206.40000,     -0.85050,     -1.64549,50.00000,20.00000,6.679523e-08,0.75194,4
337.55608,1209.00000,     -0.86013,     -1.66671,50.00000,20.00000,6.669472e-08,0.75169,4
337.80833,1211.60000,     -0.86922,     -1.69107,50.00000,20.00000,6.675485e-08,0.75145,4
338.07825,1214.20000,     -0.87319,     -1.71295,50.00000,20.00000,6.675642e-08,0.75119,4
338.33430,1216.80000,     -0.88700,     -1.73628,50.00000,20.00000,6.691504e-08,0.75095,4
338.59174,1219.40000,     -0.89817,     -1.76064,50.00000,20.00000,6.694674e-08,0.75070,4
338.85557,1222.00000,     -0.90210,     -1.78379,50.00000,20.00000,6.693781e-08,0.75045,4
339.09800,1224.60000,     -0.91758,     -1.80961,50.00000,20.00000,6.685343e-08,0.75022,4
339.37355,1227.20000,     -0.92604,     -1.83368,50.00000,20.00000,6.696436e-08,0.74996,4
339.62044,1229.80000,     -0.93799,     -1.85694,50.00000,20.00000,6.699025e-08,0.74972,4
339.88058,1232.40000,     -0.94438,     -1.88211,50.00000,20.00000,6.706682e-08,0.74947,4
340.13663,1235.00000,     -0.95299,     -1.90676,50.00000,20.00000,6.702891e-08,0.74923,4
340.40392,1237.60000,     -0.96811,     -1.93293,50.00000,20.00000,6.698256e-08,0.74897,4
340.67143,1240.20000,     -0.98050,     -1.95782,50.00000,20.00000,6.697247e-08,0.74872,4
340.92894,1242.80000,     -0.98923,     -1.98402,50.00000,20.00000,6.697898e-08,0.74847,4
341.18411,1245.40000,     -1.00072,     -2.00932,50.00000,20.00000,6.705309e-08,0.74823,4
341.44564,1248.00000,     -1.01616,     -2.03535,50.00000,20.00000,6.710357e-08,0.74798,4
341.71846,1250.60000,     -1.03019,     -2.06171,50.00000,20.00000,6.707713e-08,0.74772,4
341.98309,1253.20000,     -1.04229,     -2.08896,50.00000,20.00000,6.714902e-08,0.74747,4
342.21969,1255.80000,     -1.05350,     -2.11515,50.00000,20.00000,6.713927e-08,0.74724,4
342.48734,1258.40000,     -1.06879,     -2.14094,50.00000,20.00000,6.716428e-08,0.74698,4
342.74445,1261.00000,     -1.08371,     -2.16958,50.00000,20.00000,6.724738e-08,0.74674,4
343.01233,1263.60000,     -1.10054,     -2.19579,50.00000,20.00000,6.719934e-08,0.74648,4
343.27577,1266.20000,     -1.11446,     -2.22282,50.00000,20.00000,6.734433e-08,0.74623,4
343.53535,1268.80000,     -1.13321,     -2.24850,50.00000,20.00000,6.714731e-08,0.74598,4
343.80222,1271.40000,     -1.14664,     -2.27636,50.00000,20.00000,6.730184e-08,0.74573,4
344.04576,1274.00000,     -1.16722,     -2.30358,50.00000,20.00000,6.730273e-08,0.74550,4
344.30275,1276.60000,     -1.18028,     -2.33270,50.00000,20.00000,6.735048e-08,0.74525,4
344.67181,1279.20000,     -1.20144,     -2.36120,50.00000,20.00000,6.732718e-08,0.74490,4
344.83542,1281.80000,     -1.22208,     -2.38861,50.00000,20.00000,6.731301e-08,0.74474,4
345.08754,1284.40000,     -1.23642,     -2.41861,50.00000,20.00000,6.737807e-08,0.74450,4
345.35051,1287.00000,     -1.25521,     -2.44705,50.00000,20.00000,6.748774e-08,0.74425,4
345.61725,1289.60000,     -1.27661,     -2.47468,50.00000,20.00000,6.742896e-08,0.74400,4
345.86378,1292.20000,     -1.29503,     -2.50375,50.00000,20.00000,6.746460e-08,0.74376,4
346.12600,1294.80000,     -1.31118,     -2.53321,50.00000,20.00000,6.757920e-08,0.74351,4
346.38821,1297.40000,     -1.32997,     -2.56279,50.00000,20.00000,6.749874e-08,0.74326,4
346.63557,1300.00000,     -1.34669,     -2.59201,50.00000,20.00000,6.754521e-08,0.74302,4
346.89229,1302.60000,     -1.36633,     -2.62044,50.00000,20.00000,6.757148e-08,0.74278,4
347.16438,1305.20000,     -1.39111,     -2.65144,50.00000,20.00000,6.752954e-08,0.74252,4
347.42203,1307.80000,     -1.41471,     -2.68017,50.00000,20.00000,6.747046e-08,0.74227,4
347.68479,1310.40000,     -1.44426,     -2.71032,50.00000,20.00000,6.756242e-08,0.74202,4
347.94705,1313.00000,     -1.46235,     -2.74093,50.00000,20.00000,6.758371e-08,0.74177,4
348.20734,1315.60000,     -1.48805,     -2.77032,50.00000,20.00000,6.762324e-08,0.74152,4
348.46138,1318.20000,     -1.51512,     -2.80027,50.00000,20.00000,6.756478e-08,0.74128,4
348.73026,1320.80000,     -1.54258,     -2.82907,50.00000,20.00000,6.772441e-08,0.74102,4
348.99329,1323.40000,     -1.56426,     -2.85904,50.00000,20.00000,6.774341e-08,0.74077,4
349.24948,1326.00000,     -1.58714,     -2.89110,50.00000,20.00000,6.766839e-08,0.74053,4
349.50856,1328.60000,     -1.61201,     -2.91866,50.00000,20.00000,6.768947e-08,0.74028,4
349.76031,1331.20000,     -1.63469,     -2.94834,50.00000,20.00000,6.775361e-08,0.74004,4
350.25500,1333.80000,     -1.47436,     -2.97521,50.00000,20.00000,6.785377e-08,0.73957,5
361.12799,1336.40000,-4.080455e-02,     -2.98539,50.00000,20.00000,6.776552e-08,0.72920,5
374.43900,1339.00000,      0.17334,     -3.03902,50.00000,20.00000,6.792014e-08,0.71655,5
388.07001,1341.60000, 4.336732e-02,     -3.17330,50.00000,20.00000,6.805158e-08,0.70370,5
401.50101,1344.20000,     -0.36471,     -3.43429,50.00000,20.00000,6.825789e-08,0.69117,5
414.73499,1346.80000,     -1.11149,     -3.83161,50.00000,20.00000,6.867848e-08,0.67900,5
427.84299,1349.40000,     -1.79683,     -4.21263,50.00000,20.00000,6.901212e-08,0.66714,5
440.92001,1352.00000,     -2.36030,     -4.40461,50.00000,20.00000,6.957781e-08,0.65553,5
453.98901,1354.60000,     -2.93605,     -4.45054,50.00000,20.00000,7.001051e-08,0.64418,5
466.99200,1357.20000,     -3.44943,     -4.44330,50.00000,20.00000,7.047790e-08,0.63315,5
479.96600,1359.80000,     -3.94693,     -4.43312,50.00000,20.00000,7.073957e-08,0.62242,5
492.94699,1362.40000,     -4.47396,     -4.42475,50.00000,20.00000,7.122215e-08,0.61199,5
505.92200,1365.00000,     -5.01664,     -4.41671,50.00000,20.00000,7.160802e-08,0.60188,5
518.89801,1367.60000,     -5.58701,     -4.41162,50.00000,20.00000,7.217071e-08,0.59208,5
531.89697,1370.20000,     -6.13694,     -4.40529,50.00000,20.00000,7.250552e-08,0.58259,5
544.88098,1372.80000,     -6.66256,     -4.40020,50.00000,20.00000,7.281290e-08,0.57343,5
557.88098,1375.40000,     -7.12639,     -4.39567,50.00000,20.00000,7.320025e-08,0.56458,5
570.88397,1378.00000,     -7.51964,     -4.38956,50.00000,20.00000,7.369695e-08,0.55606,5
583.89697,1380.60000,     -7.87691,     -4.38674,50.00000,20.00000,7.403417e-08,0.54785,5
596.89697,1383.20000,     -8.22695,     -4.38312,50.00000,20.00000,7.439677e-08,0.53995,5
609.91498,1385.80000,     -8.59906,     -4.37995,50.00000,20.00000,7.468121e-08,0.53234,5
622.94702,1388.40000,     -8.99375,     -4.37621,50.00000,20.00000,7.481755e-08,0.52501,5
635.97198,1391.00000,     -9.41844,     -4.37384,50.00000,20.00000,7.505294e-08,0.51796,5
648.96997,1393.60000,     -9.85141,     -4.37124,50.00000,20.00000,7.534179e-08,0.51118,5
661.98700,1396.20000,    -10.29525,     -4.36886,50.00000,20.00000,7.534919e-08,0.50463,5
674.99402,1398.80000,    -10.74434,     -4.36581,50.00000,20.00000,7.545469e-08,0.49831,5
688.02301,1401.40000,    -11.17920,     -4.36377,50.00000,20.00000,7.559278e-08,0.49218,5
701.04700,1404.00000,    -11.61901,     -4.36173,50.00000,20.00000,7.564156e-08,0.48623,5
714.08398,1406.60000,    -12.06260,     -4.35902,50.00000,20.00000,7.563573e-08,0.48045,5
727.08197,1409.20000,    -12.48003,     -4.35800,50.00000,20.00000,7.568677e-08,0.47482,5
740.11798,1411.80000,    -12.89420,     -4.35664,50.00000,20.00000,7.574303e-08,0.46929,5
753.13202,1414.40000,    -13.31051,     -4.35449,50.00000,20.00000,7.580632e-08,0.46388,5
766.15302,1417.00000,    -13.73238,     -4.35065,50.00000,20.00000,7.578105e-08,0.45854,5
779.18103,1419.60000,    -14.14663,     -4.34929,50.00000,20.00000,7.579041e-08,0.45326,5
792.18298,1422.20000,    -14.56464,     -4.34759,50.00000,20.00000,7.572862e-08,0.44802,5
798.18701,1423.40000,    -14.74921,     -4.34623,50.00000,20.00000,7.574972e-08,0.44561,5