File: data/TGA/005c/ExpDat_2024_06_21_005c-B_300C_isotherm.csv
#EXPORTTYPE:                 ,DATA ALL
#FILE:                       ,2024_06_21_005c-B_300C_isotherm.ngb-ss5
#FORMAT:                     ,NETZSCH5
#FTYPE:                      ,ASCII
#IDENTITY:                   ,PS-SCF3
#DECIMAL:                    ,POINT
#SEPARATOR:                  ,COMMA
#MTYPE:                      ,DSC
#INSTRUMENT:                 ,NETZSCH STA 449F5
#PROJECT:                    ,
#DATE/TIME:                  ,6/21/2024 12:22:40 PM (UTC-4)
#CORR. FILE:                 ,
#TEMPCAL:                    ,28-06-2023 13:26
#SENSITIVITY:                ,28-06-2023 13:53
#LABORATORY:                 ,
#OPERATOR:                   ,Stanley
#REMARK:                     ,
#SAMPLE:                     ,005c-B-2
#SAMPLE MASS /mg:            ,5.0
#MATERIAL:                   ,
#REFERENCE:                  ,-----
#REFERENCE MASS /mg:         ,0
#TYPE OF CRUCIBLE:           ,Al2O3 85 ‘l, open
#SAMPLE CRUCIBLE MASS /mg:   ,0
#REFERENCE CRUCIBLE MASS /mg:,0
#DSC RANGE /‘V:              ,5000
#TG RANGE /mg:               ,35000
#TAU-R:                      ,---
#CORR. CODE:                 ,000
#EXO:                        ,-1
#RANGE:                      ,30›C....800›C/0.0....10.0K/min
#SEGMENT:                    ,S4/5
#SEG. 1:                     ,30›C/10.0(K/min)/100›C
#SEG. 2:                     ,100›C/00:10/100›C
#SEG. 3:                     ,100›C/5.0(K/min)/300›C
#SEG. 4:                     ,300›C/24:00/300›C
#SEG. 5:                     ,300›C/10.0(K/min)/800›C

##Temp./›C,Time/min,DSC/(mW/mg),Mass loss/mg,Gas Flow(purge2)/(ml/min),Gas Flow(protective)/(ml/min),TIC(scan:1)/A,Sensit./(uV/mW)
298.99500,  57.01083,      1.28031,-0.22829,50.00000,20.00000,6.666579e-08,0.78814
302.67001,  59.41083,     -0.81008,-0.28486,50.00000,20.00000,6.684411e-08,0.78471
302.67700,  61.81083,     -1.31177,-0.32943,50.00000,20.00000,6.708288e-08,0.78471
301.85699,  64.21083,     -1.38820,-0.36642,50.00000,20.00000,6.719862e-08,0.78547
301.14099,  66.61083,     -1.35790,-0.39957,50.00000,20.00000,6.728503e-08,0.78614
300.66800,  69.01083,     -1.32358,-0.43113,50.00000,20.00000,6.736973e-08,0.78658
300.38699,  71.41083,     -1.29754,-0.45693,50.00000,20.00000,6.733944e-08,0.78685
300.21301,  73.81083,     -1.28564,-0.48283,50.00000,20.00000,6.726075e-08,0.78701
300.12799,  76.21083,     -1.27931,-0.50637,50.00000,20.00000,6.740341e-08,0.78709
300.07599,  78.61083,     -1.27419,-0.53001,50.00000,20.00000,6.719029e-08,0.78714
300.03900,  81.01083,     -1.27220,-0.55286,50.00000,20.00000,6.718948e-08,0.78717
300.04001,  83.41083,     -1.27220,-0.57255,50.00000,20.00000,6.707219e-08,0.78717
300.01599,  85.81083,     -1.27565,-0.59257,50.00000,20.00000,6.718271e-08,0.78719
300.01501,  88.21083,     -1.27313,-0.61022,50.00000,20.00000,6.712012e-08,0.78719
300.02100,  90.61083,     -1.27198,-0.62798,50.00000,20.00000,6.712961e-08,0.78719
300.01401,  93.01083,     -1.27604,-0.64438,50.00000,20.00000,6.718329e-08,0.78719
300.00201,  95.41083,     -1.27214,-0.66067,50.00000,20.00000,6.710237e-08,0.78720
299.99899,  97.81083,     -1.27194,-0.67697,50.00000,20.00000,6.708991e-08,0.78721
300.00101, 100.21083,     -1.26923,-0.69292,50.00000,20.00000,6.707496e-08,0.78721
300.01199, 102.61083,     -1.27196,-0.70785,50.00000,20.00000,6.703042e-08,0.78719
300.01401, 105.01083,     -1.27177,-0.72154,50.00000,20.00000,6.704734e-08,0.78719
300.02399, 107.41083,     -1.27101,-0.73647,50.00000,20.00000,6.706672e-08,0.78718
300.00699, 109.81083,     -1.27428,-0.75027,50.00000,20.00000,6.715267e-08,0.78720
300.01199, 112.21083,     -1.27506,-0.76453,50.00000,20.00000,6.698465e-08,0.78719
300.01300, 114.61083,     -1.27545,-0.77799,50.00000,20.00000,6.693470e-08,0.78719
300.01199, 117.01083,     -1.27293,-0.79236,50.00000,20.00000,6.704654e-08,0.78719
300.02100, 119.41083,     -1.27236,-0.80492,50.00000,20.00000,6.701831e-08,0.78719
300.00900, 121.81083,     -1.27351,-0.81713,50.00000,20.00000,6.700565e-08,0.78720
300.01700, 124.21083,     -1.27158,-0.83071,50.00000,20.00000,6.709837e-08,0.78719
300.01300, 126.61083,     -1.27410,-0.84576,50.00000,20.00000,6.707578e-08,0.78719
300.00900, 129.01083,     -1.26983,-0.85775,50.00000,20.00000,6.696706e-08,0.78720
300.01401, 131.41083,     -1.26518,-0.87098,50.00000,20.00000,6.706003e-08,0.78719
300.01599, 133.81083,     -1.26654,-0.88196,50.00000,20.00000,6.712780e-08,0.78719
300.01700, 136.21083,     -1.26712,-0.89553,50.00000,20.00000,6.711338e-08,0.78719
300.01801, 138.61083,     -1.27178,-0.90707,50.00000,20.00000,6.715452e-08,0.78719
300.01300, 141.01083,     -1.26809,-0.91997,50.00000,20.00000,6.721547e-08,0.78719
300.01199, 143.41083,     -1.26557,-0.93219,50.00000,20.00000,6.711273e-08,0.78719
300.01999, 145.81083,     -1.26364,-0.94361,50.00000,20.00000,6.710282e-08,0.78719
300.01199, 148.21083,     -1.26828,-0.95549,50.00000,20.00000,6.711835e-08,0.78719
300.01901, 150.61083,     -1.26635,-0.96771,50.00000,20.00000,6.718215e-08,0.78719
300.01700, 153.01083,     -1.26519,-0.97959,50.00000,20.00000,6.708186e-08,0.78719
300.00699, 155.41083,     -1.26614,-0.99181,50.00000,20.00000,6.712487e-08,0.78720
300.01999, 157.81083,     -1.26364,-1.00470,50.00000,20.00000,6.726379e-08,0.78719
300.01401, 160.21083,     -1.26499,-1.01477,50.00000,20.00000,6.715800e-08,0.78719
300.00500, 162.61083,     -1.26749,-1.02948,50.00000,20.00000,6.721716e-08,0.78720
300.00601, 165.01083,     -1.26401,-1.03796,50.00000,20.00000,6.725743e-08,0.78720
300.01901, 167.41083,     -1.26344,-1.04747,50.00000,20.00000,6.726696e-08,0.78719
300.00400, 169.81083,     -1.26730,-1.06240,50.00000,20.00000,6.716503e-08,0.78720
300.00699, 172.21083,     -1.26459,-1.07303,50.00000,20.00000,6.735507e-08,0.78720
300.01501, 174.61083,     -1.26460,-1.08593,50.00000,20.00000,6.718436e-08,0.78719
300.01700, 177.01083,     -1.26208,-1.09792,50.00000,20.00000,6.719086e-08,0.78719
300.02399, 179.41083,     -1.26190,-1.11082,50.00000,20.00000,6.730136e-08,0.78718
300.02100, 181.81083,     -1.26131,-1.12213,50.00000,20.00000,6.725757e-08,0.78719
300.00699, 184.21083,     -1.26362,-1.13299,50.00000,20.00000,6.723361e-08,0.78720
300.01401, 186.61083,     -1.26596,-1.14385,50.00000,20.00000,6.730119e-08,0.78719
300.01700, 189.01083,     -1.26189,-1.15437,50.00000,20.00000,6.735434e-08,0.78719
300.01099, 191.41083,     -1.26149,-1.16659,50.00000,20.00000,6.728560e-08,0.78720
300.00900, 193.81083,     -1.26382,-1.17677,50.00000,20.00000,6.741043e-08,0.78720
300.01599, 196.21083,     -1.26228,-1.18899,50.00000,20.00000,6.736620e-08,0.78719
300.01401, 198.61083,     -1.26247,-1.20121,50.00000,20.00000,6.733595e-08,0.78719
300.01901, 201.01083,     -1.26112,-1.21207,50.00000,20.00000,6.735523e-08,0.78719
300.02499, 203.41083,     -1.26190,-1.22259,50.00000,20.00000,6.734726e-08,0.78718
300.01401, 205.81083,     -1.26111,-1.23447,50.00000,20.00000,6.743700e-08,0.78719
300.01300, 208.21083,     -1.26111,-1.24646,50.00000,20.00000,6.749668e-08,0.78719
300.02100, 210.61083,     -1.26170,-1.25732,50.00000,20.00000,6.733003e-08,0.78719
300.01999, 213.01083,     -1.26364,-1.26954,50.00000,20.00000,6.737568e-08,0.78719
300.02200, 215.41083,     -1.25918,-1.27904,50.00000,20.00000,6.745373e-08,0.78719
300.01599, 217.81083,     -1.25937,-1.28990,50.00000,20.00000,6.745601e-08,0.78719
300.01300, 220.21083,     -1.26033,-1.30122,50.00000,20.00000,6.737474e-08,0.78719
300.00201, 222.61083,     -1.26439,-1.31344,50.00000,20.00000,6.751255e-08,0.78720
300.01901, 225.01083,     -1.26151,-1.32350,50.00000,20.00000,6.751157e-08,0.78719
300.00500, 227.41083,     -1.25741,-1.33572,50.00000,20.00000,6.751303e-08,0.78720
300.00201, 229.81083,     -1.25818,-1.34613,50.00000,20.00000,6.752409e-08,0.78720
300.01999, 232.21083,     -1.25918,-1.35597,50.00000,20.00000,6.752371e-08,0.78719
300.02499, 234.61083,     -1.26035,-1.36808,50.00000,20.00000,6.754273e-08,0.78718
300.01300, 237.01083,     -1.26072,-1.37792,50.00000,20.00000,6.746245e-08,0.78719
300.02499, 239.41083,     -1.26287,-1.39014,50.00000,20.00000,6.763019e-08,0.78718
300.01099, 241.81083,     -1.25975,-1.40055,50.00000,20.00000,6.751025e-08,0.78720
300.01700, 244.21083,     -1.25995,-1.41073,50.00000,20.00000,6.761140e-08,0.78719
300.01901, 246.61083,     -1.25995,-1.42306,50.00000,20.00000,6.770692e-08,0.78719
300.02600, 249.01083,     -1.25667,-1.43290,50.00000,20.00000,6.761445e-08,0.78718
300.02301, 251.41083,     -1.25899,-1.44353,50.00000,20.00000,6.760816e-08,0.78718
300.01199, 253.81083,     -1.25839,-1.45440,50.00000,20.00000,6.766240e-08,0.78719
300.01001, 256.21083,     -1.25994,-1.46526,50.00000,20.00000,6.761807e-08,0.78720
300.00900, 258.61083,     -1.25975,-1.47578,50.00000,20.00000,6.763361e-08,0.78720
300.02701, 261.01083,     -1.25706,-1.48675,50.00000,20.00000,6.758143e-08,0.78718
300.02399, 263.41083,     -1.25783,-1.49671,50.00000,20.00000,6.771382e-08,0.78718
300.01199, 265.81083,     -1.25568,-1.50689,50.00000,20.00000,6.757281e-08,0.78719
300.01300, 268.21083,     -1.25917,-1.51911,50.00000,20.00000,6.759195e-08,0.78719
300.00500, 270.61083,     -1.25664,-1.52963,50.00000,20.00000,6.763608e-08,0.78720
300.02600, 273.01083,     -1.25570,-1.54015,50.00000,20.00000,6.761482e-08,0.78718
300.01300, 275.41083,     -1.25626,-1.54897,50.00000,20.00000,6.767846e-08,0.78719
300.02100, 277.81083,     -1.25317,-1.55983,50.00000,20.00000,6.774730e-08,0.78719
300.02701, 280.21083,     -1.25473,-1.56979,50.00000,20.00000,6.771690e-08,0.78718
300.02301, 282.61083,     -1.25395,-1.58031,50.00000,20.00000,6.780229e-08,0.78718
300.02600, 285.01083,     -1.25260,-1.59162,50.00000,20.00000,6.790363e-08,0.78718
300.00400, 287.41083,     -1.25334,-1.60135,50.00000,20.00000,6.787820e-08,0.78720
300.00601, 289.81083,     -1.25431,-1.61278,50.00000,20.00000,6.778562e-08,0.78720
300.02399, 292.21083,     -1.25318,-1.62296,50.00000,20.00000,6.787152e-08,0.78718
300.02301, 294.61083,     -1.25395,-1.63144,50.00000,20.00000,6.789252e-08,0.78718
300.00900, 297.01083,     -1.24928,-1.64366,50.00000,20.00000,6.782645e-08,0.78720
300.01199, 299.41083,     -1.24967,-1.65294,50.00000,20.00000,6.783547e-08,0.78719
300.02200, 301.81083,     -1.24794,-1.66425,50.00000,20.00000,6.792388e-08,0.78719
300.02200, 304.21083,     -1.25162,-1.67308,50.00000,20.00000,6.778377e-08,0.78719
300.01199, 306.61083,     -1.24967,-1.68258,50.00000,20.00000,6.788131e-08,0.78719
300.02100, 309.01083,     -1.24561,-1.69344,50.00000,20.00000,6.779404e-08,0.78719
300.01801, 311.41083,     -1.24735,-1.70294,50.00000,20.00000,6.792072e-08,0.78719
300.02100, 313.81083,     -1.24775,-1.71437,50.00000,20.00000,6.786706e-08,0.78719
300.01001, 316.21083,     -1.24773,-1.72489,50.00000,20.00000,6.788609e-08,0.78720
300.01099, 318.61083,     -1.24792,-1.73518,50.00000,20.00000,6.785098e-08,0.78720
300.00400, 321.01083,     -1.24888,-1.74480,50.00000,20.00000,6.791657e-08,0.78720
300.01999, 323.41083,     -1.24348,-1.75362,50.00000,20.00000,6.799421e-08,0.78719
300.00699, 325.81083,     -1.24598,-1.76471,50.00000,20.00000,6.793755e-08,0.78720
300.00900, 328.21083,     -1.24443,-1.77421,50.00000,20.00000,6.794730e-08,0.78720
300.01401, 330.61083,     -1.24522,-1.78372,50.00000,20.00000,6.818846e-08,0.78719
300.01099, 333.01083,     -1.24308,-1.79333,50.00000,20.00000,6.800040e-08,0.78720
300.01901, 335.41083,     -1.23960,-1.80431,50.00000,20.00000,6.797548e-08,0.78719
300.01099, 337.81083,     -1.23765,-1.81290,50.00000,20.00000,6.800909e-08,0.78720
300.03101, 340.21083,     -1.23923,-1.82309,50.00000,20.00000,6.805562e-08,0.78718
300.02399, 342.61083,     -1.23922,-1.83293,50.00000,20.00000,6.809181e-08,0.78718
300.01099, 345.01083,     -1.23688,-1.84345,50.00000,20.00000,6.795242e-08,0.78720
300.02600, 347.41083,     -1.24077,-1.85227,50.00000,20.00000,6.806618e-08,0.78718
300.01599, 349.81083,     -1.23998,-1.86178,50.00000,20.00000,6.800474e-08,0.78719
300.01599, 352.21083,     -1.23630,-1.87128,50.00000,20.00000,6.802852e-08,0.78719
300.01099, 354.61083,     -1.23455,-1.88090,50.00000,20.00000,6.800073e-08,0.78720
300.01901, 357.01083,     -1.23379,-1.89006,50.00000,20.00000,6.804603e-08,0.78719
300.01700, 359.41083,     -1.23456,-1.89990,50.00000,20.00000,6.816620e-08,0.78719
300.00400, 361.81083,     -1.23318,-1.90918,50.00000,20.00000,6.813233e-08,0.78720
300.01599, 364.21083,     -1.23049,-1.91891,50.00000,20.00000,6.810530e-08,0.78719
300.01999, 366.61083,     -1.23359,-1.92965,50.00000,20.00000,6.813991e-08,0.78719
300.01199, 369.01083,     -1.23455,-1.93690,50.00000,20.00000,6.824352e-08,0.78719
300.02100, 371.41083,     -1.23418,-1.94719,50.00000,20.00000,6.816502e-08,0.78719
300.02701, 373.81083,     -1.23341,-1.95635,50.00000,20.00000,6.819328e-08,0.78718
300.01599, 376.21083,     -1.23243,-1.96778,50.00000,20.00000,6.815688e-08,0.78719
300.01199, 378.61083,     -1.23436,-1.97592,50.00000,20.00000,6.813890e-08,0.78719
300.01300, 381.01083,     -1.23184,-1.98543,50.00000,20.00000,6.827478e-08,0.78719
300.01901, 383.41083,     -1.22855,-1.99493,50.00000,20.00000,6.818320e-08,0.78719
300.03000, 385.81083,     -1.22779,-2.00511,50.00000,20.00000,6.823171e-08,0.78718
300.01801, 388.21083,     -1.22778,-2.01563,50.00000,20.00000,6.827777e-08,0.78719
300.02802, 390.61083,     -1.22876,-2.02276,50.00000,20.00000,6.815992e-08,0.78718
300.01700, 393.01083,     -1.22739,-2.03147,50.00000,20.00000,6.824040e-08,0.78719
300.01401, 395.41083,     -1.22719,-2.04188,50.00000,20.00000,6.832764e-08,0.78719
300.01700, 397.81083,     -1.22855,-2.05070,50.00000,20.00000,6.823792e-08,0.78719
299.99799, 400.21083,     -1.22658,-2.05919,50.00000,20.00000,6.836124e-08,0.78721
300.00699, 402.61083,     -1.22815,-2.07016,50.00000,20.00000,6.824664e-08,0.78720
300.02100, 405.01083,     -1.22390,-2.07763,50.00000,20.00000,6.837385e-08,0.78719
300.00699, 407.41083,     -1.22660,-2.08679,50.00000,20.00000,6.841301e-08,0.78720
300.02499, 409.81083,     -1.22643,-2.09505,50.00000,20.00000,6.821318e-08,0.78718
300.01300, 412.21083,     -1.22409,-2.10569,50.00000,20.00000,6.828229e-08,0.78719
300.00400, 414.61083,     -1.22504,-2.11360,50.00000,20.00000,6.825691e-08,0.78720
300.02802, 417.01083,     -1.22469,-2.12164,50.00000,20.00000,6.834555e-08,0.78718
300.01401, 419.41083,     -1.22544,-2.12978,50.00000,20.00000,6.844275e-08,0.78719
300.03299, 421.81083,     -1.22159,-2.14064,50.00000,20.00000,6.838794e-08,0.78718
300.02499, 424.21083,     -1.22197,-2.14743,50.00000,20.00000,6.844582e-08,0.78718
300.02200, 426.61083,     -1.22468,-2.15829,50.00000,20.00000,6.835204e-08,0.78719
300.03000, 429.01083,     -1.22237,-2.16564,50.00000,20.00000,6.831784e-08,0.78718
300.00699, 431.41083,     -1.22466,-2.17605,50.00000,20.00000,6.839150e-08,0.78720
300.01401, 433.81083,     -1.22409,-2.18307,50.00000,20.00000,6.843420e-08,0.78719
300.01599, 436.21083,     -1.22390,-2.19121,50.00000,20.00000,6.845982e-08,0.78719
300.00800, 438.61083,     -1.22369,-2.20026,50.00000,20.00000,6.844372e-08,0.78720
300.03799, 441.01083,     -1.22277,-2.20931,50.00000,20.00000,6.852511e-08,0.78717
300.00900, 443.41083,     -1.22078,-2.21882,50.00000,20.00000,6.850815e-08,0.78720
300.01700, 445.81083,     -1.22293,-2.22866,50.00000,20.00000,6.838234e-08,0.78719
300.00601, 448.21083,     -1.21690,-2.23545,50.00000,20.00000,6.850345e-08,0.78720
300.01700, 450.61083,     -1.21866,-2.24359,50.00000,20.00000,6.841074e-08,0.78719
300.01300, 453.01083,     -1.21924,-2.25185,50.00000,20.00000,6.839496e-08,0.78719
300.00699, 455.41083,     -1.21942,-2.25988,50.00000,20.00000,6.839084e-08,0.78720
300.01401, 457.81083,     -1.21982,-2.26972,50.00000,20.00000,6.841839e-08,0.78719
300.02100, 460.21083,     -1.22022,-2.27787,50.00000,20.00000,6.848347e-08,0.78719
300.01001, 462.61083,     -1.21594,-2.28771,50.00000,20.00000,6.845762e-08,0.78720
300.01801, 465.01083,     -1.22060,-2.29450,50.00000,20.00000,6.843197e-08,0.78719
300.01801, 467.41083,     -1.21421,-2.30208,50.00000,20.00000,6.848368e-08,0.78719
300.01099, 469.81083,     -1.20761,-2.31158,50.00000,20.00000,6.852298e-08,0.78720
300.01401, 472.21083,     -1.20606,-2.31882,50.00000,20.00000,6.852412e-08,0.78719
300.01300, 474.61083,     -1.20587,-2.32844,50.00000,20.00000,6.848346e-08,0.78719
300.02301, 477.01083,     -1.20472,-2.33523,50.00000,20.00000,6.860609e-08,0.78718
300.01999, 479.41083,     -1.20471,-2.34405,50.00000,20.00000,6.848336e-08,0.78719
300.01599, 481.81083,     -1.20587,-2.35186,50.00000,20.00000,6.856936e-08,0.78719
300.01300, 484.21083,     -1.20567,-2.36023,50.00000,20.00000,6.857113e-08,0.78719
300.00400, 486.61083,     -1.20450,-2.36815,50.00000,20.00000,6.860096e-08,0.78720
300.01599, 489.01083,     -1.20839,-2.37561,50.00000,20.00000,6.865862e-08,0.78719
300.01801, 491.41083,     -1.20432,-2.38444,50.00000,20.00000,6.859315e-08,0.78719
300.01401, 493.81083,     -1.20335,-2.39258,50.00000,20.00000,6.853625e-08,0.78719
300.00500, 496.21083,     -1.20333,-2.40209,50.00000,20.00000,6.855059e-08,0.78720
300.01700, 498.61083,     -1.20277,-2.40887,50.00000,20.00000,6.883545e-08,0.78719
300.02600, 501.01083,     -1.20511,-2.41532,50.00000,20.00000,6.853811e-08,0.78718
300.02100, 503.41083,     -1.20278,-2.42403,50.00000,20.00000,6.867212e-08,0.78719
300.01401, 505.81083,     -1.20315,-2.43150,50.00000,20.00000,6.875209e-08,0.78719
300.00601, 508.21083,     -1.20334,-2.44123,50.00000,20.00000,6.873650e-08,0.78720
300.02200, 510.61083,     -1.20103,-2.44689,50.00000,20.00000,6.868927e-08,0.78719
300.01801, 513.01083,     -1.20355,-2.45650,50.00000,20.00000,6.864879e-08,0.78719
300.01001, 515.41083,     -1.20024,-2.46261,50.00000,20.00000,6.881400e-08,0.78720
300.01001, 517.81083,     -1.20198,-2.47076,50.00000,20.00000,6.872770e-08,0.78720
300.02100, 520.21083,     -1.19832,-2.47822,50.00000,20.00000,6.883703e-08,0.78719
300.01901, 522.61083,     -1.20200,-2.48671,50.00000,20.00000,6.867305e-08,0.78719
300.01199, 525.01083,     -1.20179,-2.49349,50.00000,20.00000,6.877390e-08,0.78719
300.02600, 527.41083,     -1.19794,-2.50243,50.00000,20.00000,6.873731e-08,0.78718
300.01501, 529.81083,     -1.20257,-2.50888,50.00000,20.00000,6.877475e-08,0.78719
300.02499, 532.21083,     -1.20084,-2.51567,50.00000,20.00000,6.874179e-08,0.78718
300.01700, 534.61083,     -1.19967,-2.52415,50.00000,20.00000,6.875421e-08,0.78719
300.01401, 537.01083,     -1.20218,-2.53264,50.00000,20.00000,6.881652e-08,0.78719
300.01001, 539.41083,     -1.19656,-2.54067,50.00000,20.00000,6.868483e-08,0.78720
300.02100, 541.81083,     -1.19696,-2.54814,50.00000,20.00000,6.875711e-08,0.78719
300.01999, 544.21083,     -1.20025,-2.55572,50.00000,20.00000,6.871762e-08,0.78719
300.02200, 546.61083,     -1.19851,-2.56183,50.00000,20.00000,6.875056e-08,0.78719
300.00500, 549.01083,     -1.19984,-2.57020,50.00000,20.00000,6.871468e-08,0.78720
300.02100, 551.41083,     -1.19909,-2.57698,50.00000,20.00000,6.884419e-08,0.78719
300.00601, 553.81083,     -1.19849,-2.58377,50.00000,20.00000,6.875472e-08,0.78720
300.02899, 556.21083,     -1.19852,-2.59226,50.00000,20.00000,6.874796e-08,0.78718
300.00900, 558.61083,     -1.19811,-2.60006,50.00000,20.00000,6.873143e-08,0.78720
300.01501, 561.01083,     -1.19676,-2.60538,50.00000,20.00000,6.874858e-08,0.78719
300.01401, 563.41083,     -1.19521,-2.61387,50.00000,20.00000,6.866456e-08,0.78719
300.01001, 565.81083,     -1.19733,-2.61930,50.00000,20.00000,6.877442e-08,0.78720
300.01599, 568.21083,     -1.19346,-2.62744,50.00000,20.00000,6.878664e-08,0.78719
300.02100, 570.61083,     -1.19366,-2.63559,50.00000,20.00000,6.878525e-08,0.78719
300.01501, 573.01083,     -1.19753,-2.64136,50.00000,20.00000,6.881249e-08,0.78719
300.00900, 575.41083,     -1.19500,-2.64916,50.00000,20.00000,6.886510e-08,0.78720
300.00400, 577.81083,     -1.19539,-2.65606,50.00000,20.00000,6.889741e-08,0.78720
300.01700, 580.21083,     -1.19250,-2.66342,50.00000,20.00000,6.899020e-08,0.78719
300.00400, 582.61083,     -1.19112,-2.66919,50.00000,20.00000,6.889151e-08,0.78720
300.01401, 585.01083,     -1.19365,-2.67677,50.00000,20.00000,6.883414e-08,0.78719
300.03000, 587.41083,     -1.19193,-2.68287,50.00000,20.00000,6.898623e-08,0.78718
300.01599, 589.81083,     -1.19056,-2.69034,50.00000,20.00000,6.901428e-08,0.78719
300.01501, 592.21083,     -1.19133,-2.69747,50.00000,20.00000,6.900794e-08,0.78719
300.01700, 594.61083,     -1.19191,-2.70471,50.00000,20.00000,6.891252e-08,0.78719
300.00400, 597.01083,     -1.19461,-2.71093,50.00000,20.00000,6.891663e-08,0.78720
300.01300, 599.41083,     -1.18978,-2.71964,50.00000,20.00000,6.896723e-08,0.78719
300.00699, 601.81083,     -1.19054,-2.72496,50.00000,20.00000,6.881586e-08,0.78720
300.02600, 604.21083,     -1.19406,-2.73175,50.00000,20.00000,6.891275e-08,0.78718
300.01300, 606.61083,     -1.19094,-2.73853,50.00000,20.00000,6.890898e-08,0.78719
300.01901, 609.01083,     -1.19230,-2.74532,50.00000,20.00000,6.886508e-08,0.78719
300.02499, 611.41083,     -1.19018,-2.75369,50.00000,20.00000,6.891481e-08,0.78718
300.02899, 613.81083,     -1.18980,-2.76037,50.00000,20.00000,6.886259e-08,0.78718
300.00900, 616.21083,     -1.18977,-2.76557,50.00000,20.00000,6.890991e-08,0.78720
300.01001, 618.61083,     -1.19074,-2.77225,50.00000,20.00000,6.893477e-08,0.78720
300.01401, 621.01083,     -1.18861,-2.77937,50.00000,20.00000,6.892186e-08,0.78719
300.03000, 623.41083,     -1.19096,-2.78582,50.00000,20.00000,6.887180e-08,0.78718
300.01999, 625.81083,     -1.18765,-2.79340,50.00000,20.00000,6.879575e-08,0.78719
300.01501, 628.21083,     -1.18610,-2.79974,50.00000,20.00000,6.892218e-08,0.78719
300.02100, 630.61083,     -1.18843,-2.80517,50.00000,20.00000,6.891390e-08,0.78719
300.01801, 633.01083,     -1.18610,-2.81218,50.00000,20.00000,6.892287e-08,0.78719
300.01401, 635.41083,     -1.18629,-2.81603,50.00000,20.00000,6.886572e-08,0.78719
300.02399, 637.81083,     -1.18805,-2.82497,50.00000,20.00000,6.883838e-08,0.78718
300.02100, 640.21083,     -1.18378,-2.83006,50.00000,20.00000,6.902746e-08,0.78719
300.01901, 642.61083,     -1.18513,-2.83764,50.00000,20.00000,6.894546e-08,0.78719
300.01001, 645.01083,     -1.18648,-2.84397,50.00000,20.00000,6.898056e-08,0.78720
300.01199, 647.41083,     -1.18629,-2.84963,50.00000,20.00000,6.903244e-08,0.78719
300.01599, 649.81083,     -1.17912,-2.85653,50.00000,20.00000,6.896796e-08,0.78719
300.01001, 652.21083,     -1.18590,-2.86275,50.00000,20.00000,6.898760e-08,0.78720
300.01199, 654.61083,     -1.18105,-2.86988,50.00000,20.00000,6.905002e-08,0.78719
300.01801, 657.01083,     -1.18455,-2.87497,50.00000,20.00000,6.892680e-08,0.78719
300.01199, 659.41083,     -1.18474,-2.88210,50.00000,20.00000,6.900704e-08,0.78719
300.01599, 661.81083,     -1.18261,-2.88855,50.00000,20.00000,6.907650e-08,0.78719
300.01401, 664.21083,     -1.18299,-2.89522,50.00000,20.00000,6.899306e-08,0.78719
300.01599, 666.61083,     -1.18106,-2.90133,50.00000,20.00000,6.889573e-08,0.78719
300.01999, 669.01083,     -1.18029,-2.90653,50.00000,20.00000,6.899998e-08,0.78719
300.01599, 671.41083,     -1.18067,-2.91366,50.00000,20.00000,6.905241e-08,0.78719
300.02499, 673.81083,     -1.17991,-2.91932,50.00000,20.00000,6.900455e-08,0.78718
300.01901, 676.21083,     -1.18164,-2.92543,50.00000,20.00000,6.896389e-08,0.78719
300.01300, 678.61083,     -1.18125,-2.93221,50.00000,20.00000,6.902336e-08,0.78719
300.02802, 681.01083,     -1.18011,-2.93764,50.00000,20.00000,6.891219e-08,0.78718
300.01999, 683.41083,     -1.18048,-2.94341,50.00000,20.00000,6.904763e-08,0.78719
300.01501, 685.81083,     -1.17951,-2.95099,50.00000,20.00000,6.910776e-08,0.78719
300.02399, 688.21083,     -1.18088,-2.95676,50.00000,20.00000,6.909773e-08,0.78718
300.01801, 690.61083,     -1.17990,-2.96265,50.00000,20.00000,6.911610e-08,0.78719
300.01901, 693.01083,     -1.17971,-2.96740,50.00000,20.00000,6.895361e-08,0.78719
300.01901, 695.41083,     -1.17971,-2.97452,50.00000,20.00000,6.899520e-08,0.78719
300.01599, 697.81083,     -1.17951,-2.97961,50.00000,20.00000,6.889385e-08,0.78719
300.00699, 700.21083,     -1.18124,-2.98505,50.00000,20.00000,6.901412e-08,0.78720
300.02301, 702.61083,     -1.17758,-2.99081,50.00000,20.00000,6.898480e-08,0.78718
300.01999, 705.01083,     -1.17835,-2.99624,50.00000,20.00000,6.905994e-08,0.78719
300.01801, 707.41083,     -1.17777,-3.00303,50.00000,20.00000,6.905164e-08,0.78719
300.02499, 709.81083,     -1.17933,-3.00824,50.00000,20.00000,6.910991e-08,0.78718
300.01599, 712.21083,     -1.17815,-3.01559,50.00000,20.00000,6.912487e-08,0.78719
300.02200, 714.61083,     -1.17700,-3.02113,50.00000,20.00000,6.914773e-08,0.78719
300.01801, 717.01083,     -1.17466,-3.02521,50.00000,20.00000,6.908540e-08,0.78719
300.02200, 719.41083,     -1.17583,-3.03301,50.00000,20.00000,6.910401e-08,0.78719
300.01901, 721.81083,     -1.17447,-3.03788,50.00000,20.00000,6.924120e-08,0.78719
300.01501, 724.21083,     -1.17369,-3.04353,50.00000,20.00000,6.910172e-08,0.78719
300.01001, 726.61083,     -1.17446,-3.04896,50.00000,20.00000,6.913787e-08,0.78720
300.01401, 729.01083,     -1.17350,-3.05439,50.00000,20.00000,6.909056e-08,0.78719
300.00601, 731.41083,     -1.17445,-3.06016,50.00000,20.00000,6.913860e-08,0.78720
300.01001, 733.81083,     -1.17175,-3.06525,50.00000,20.00000,6.917592e-08,0.78720
300.01999, 736.21083,     -1.17370,-3.07102,50.00000,20.00000,6.916952e-08,0.78719
300.02600, 738.61083,     -1.17526,-3.07645,50.00000,20.00000,6.917727e-08,0.78718
300.02301, 741.01083,     -1.17196,-3.08188,50.00000,20.00000,6.914876e-08,0.78718
300.01700, 743.41083,     -1.17408,-3.08731,50.00000,20.00000,6.912825e-08,0.78719
300.02100, 745.81083,     -1.17254,-3.09297,50.00000,20.00000,6.907187e-08,0.78719
300.02301, 748.21083,     -1.17312,-3.09999,50.00000,20.00000,6.909424e-08,0.78718
300.01999, 750.61083,     -1.17021,-3.10394,50.00000,20.00000,6.914131e-08,0.78719
300.01801, 753.01083,     -1.17021,-3.10904,50.00000,20.00000,6.917939e-08,0.78719
300.01901, 755.41083,     -1.17234,-3.11379,50.00000,20.00000,6.905268e-08,0.78719
300.01999, 757.81083,     -1.17176,-3.12057,50.00000,20.00000,6.909253e-08,0.78719
300.00800, 760.21083,     -1.17116,-3.12397,50.00000,20.00000,6.899718e-08,0.78720
300.01001, 762.61083,     -1.17213,-3.13098,50.00000,20.00000,6.912442e-08,0.78720
300.01801, 765.01083,     -1.17079,-3.13698,50.00000,20.00000,6.906095e-08,0.78719
300.01801, 767.41083,     -1.17098,-3.14094,50.00000,20.00000,6.901148e-08,0.78719
300.02899, 769.81083,     -1.17138,-3.14603,50.00000,20.00000,6.904427e-08,0.78718
300.01901, 772.21083,     -1.16943,-3.15044,50.00000,20.00000,6.906934e-08,0.78719
300.01401, 774.61083,     -1.16768,-3.15621,50.00000,20.00000,6.905080e-08,0.78719
300.01099, 777.01083,     -1.17020,-3.16175,50.00000,20.00000,6.913955e-08,0.78720
300.02100, 779.41083,     -1.16788,-3.16673,50.00000,20.00000,6.905181e-08,0.78719
300.01801, 781.81083,     -1.16885,-3.17126,50.00000,20.00000,6.906768e-08,0.78719
300.02100, 784.21083,     -1.16808,-3.17816,50.00000,20.00000,6.908124e-08,0.78719
300.01501, 786.61083,     -1.17059,-3.18200,50.00000,20.00000,6.912612e-08,0.78719
300.01501, 789.01083,     -1.16594,-3.18777,50.00000,20.00000,6.898058e-08,0.78719
300.00000, 791.41083,     -1.16456,-3.19253,50.00000,20.00000,6.904087e-08,0.78721
300.01401, 793.81083,     -1.16458,-3.19796,50.00000,20.00000,6.908029e-08,0.78719
300.01700, 796.21083,     -1.16555,-3.20282,50.00000,20.00000,6.899883e-08,0.78719
300.01901, 798.61083,     -1.16420,-3.20859,50.00000,20.00000,6.912753e-08,0.78719
300.01501, 801.01083,     -1.16632,-3.21402,50.00000,20.00000,6.904151e-08,0.78719
300.01999, 803.41083,     -1.16556,-3.21911,50.00000,20.00000,6.906957e-08,0.78719
300.01001, 805.81083,     -1.16612,-3.22352,50.00000,20.00000,6.912905e-08,0.78720
300.01099, 808.21083,     -1.16341,-3.22861,50.00000,20.00000,6.909209e-08,0.78720
300.01999, 810.61083,     -1.16478,-3.23371,50.00000,20.00000,6.906181e-08,0.78719
300.02100, 813.01083,     -1.16187,-3.23880,50.00000,20.00000,6.905407e-08,0.78719
300.01300, 815.41083,     -1.16516,-3.24457,50.00000,20.00000,6.906754e-08,0.78719
300.01901, 817.81083,     -1.16129,-3.25011,50.00000,20.00000,6.913228e-08,0.78719
300.01801, 820.21083,     -1.16206,-3.25554,50.00000,20.00000,6.914085e-08,0.78719
300.01199, 822.61083,     -1.16167,-3.25961,50.00000,20.00000,6.912961e-08,0.78719
300.01999, 825.01083,     -1.16245,-3.26335,50.00000,20.00000,6.909548e-08,0.78719
300.01801, 827.41083,     -1.16148,-3.26911,50.00000,20.00000,6.901411e-08,0.78719
300.01501, 829.81083,     -1.16206,-3.27421,50.00000,20.00000,6.916107e-08,0.78719
300.01300, 832.21083,     -1.16245,-3.27896,50.00000,20.00000,6.901051e-08,0.78719
300.01401, 834.61083,     -1.16322,-3.28405,50.00000,20.00000,6.899595e-08,0.78719
300.00601, 837.01083,     -1.15992,-3.28982,50.00000,20.00000,6.897699e-08,0.78720
300.01599, 839.41083,     -1.15605,-3.29434,50.00000,20.00000,6.899386e-08,0.78719
300.03101, 841.81083,     -1.15452,-3.29842,50.00000,20.00000,6.902432e-08,0.78718
300.02399, 844.21083,     -1.15490,-3.30452,50.00000,20.00000,6.905896e-08,0.78718
300.01199, 846.61083,     -1.15450,-3.31041,50.00000,20.00000,6.908973e-08,0.78719
300.01401, 849.01083,     -1.15605,-3.31380,50.00000,20.00000,6.899668e-08,0.78719
300.01599, 851.41083,     -1.15470,-3.31821,50.00000,20.00000,6.906027e-08,0.78719
300.01401, 853.81083,     -1.15760,-3.32229,50.00000,20.00000,6.905939e-08,0.78719
300.01401, 856.21083,     -1.15624,-3.32636,50.00000,20.00000,6.909033e-08,0.78719
300.01999, 858.61083,     -1.15315,-3.33111,50.00000,20.00000,6.902890e-08,0.78719
300.00699, 861.01083,     -1.15371,-3.33552,50.00000,20.00000,6.900483e-08,0.78720
300.02100, 863.41083,     -1.15664,-3.33926,50.00000,20.00000,6.911042e-08,0.78719
300.01999, 865.81083,     -1.15431,-3.34435,50.00000,20.00000,6.920104e-08,0.78719
300.01401, 868.21083,     -1.15159,-3.34944,50.00000,20.00000,6.912817e-08,0.78719
300.02200, 870.61083,     -1.15354,-3.35385,50.00000,20.00000,6.903957e-08,0.78719
300.00299, 873.01083,     -1.15371,-3.35758,50.00000,20.00000,6.914098e-08,0.78720
300.01999, 875.41083,     -1.15044,-3.36301,50.00000,20.00000,6.917014e-08,0.78719
300.02399, 877.81083,     -1.15296,-3.36607,50.00000,20.00000,6.907854e-08,0.78718
300.02200, 880.21083,     -1.15257,-3.37150,50.00000,20.00000,6.906125e-08,0.78719
300.02600, 882.61083,     -1.15103,-3.37557,50.00000,20.00000,6.904006e-08,0.78718
300.01999, 885.01083,     -1.14947,-3.37964,50.00000,20.00000,6.905746e-08,0.78719
300.01501, 887.41083,     -1.15082,-3.38485,50.00000,20.00000,6.911197e-08,0.78719
300.01999, 889.81083,     -1.14927,-3.38892,50.00000,20.00000,6.908010e-08,0.78719
300.00400, 892.21083,     -1.14751,-3.39231,50.00000,20.00000,6.917525e-08,0.78720
300.01199, 894.61083,     -1.14616,-3.39774,50.00000,20.00000,6.909453e-08,0.78719
300.01999, 897.01083,     -1.14792,-3.40148,50.00000,20.00000,6.917182e-08,0.78719
300.01801, 899.41083,     -1.14966,-3.40657,50.00000,20.00000,6.909223e-08,0.78719
300.01001, 901.81083,     -1.15004,-3.41132,50.00000,20.00000,6.916241e-08,0.78720
300.00900, 904.21083,     -1.14499,-3.41539,50.00000,20.00000,6.911072e-08,0.78720
300.01401, 906.61083,     -1.14868,-3.41946,50.00000,20.00000,6.910130e-08,0.78719
300.01700, 909.01083,     -1.14597,-3.42456,50.00000,20.00000,6.898296e-08,0.78719
300.01401, 911.41083,     -1.14461,-3.42761,50.00000,20.00000,6.901064e-08,0.78719
300.01401, 913.81083,     -1.14500,-3.43168,50.00000,20.00000,6.909859e-08,0.78719
300.02301, 916.21083,     -1.14560,-3.43745,50.00000,20.00000,6.908035e-08,0.78718
300.01401, 918.61083,     -1.14442,-3.44017,50.00000,20.00000,6.909260e-08,0.78719
300.01099, 921.01083,     -1.14480,-3.44560,50.00000,20.00000,6.910973e-08,0.78720
300.02100, 923.41083,     -1.14443,-3.44933,50.00000,20.00000,6.907212e-08,0.78719
300.02499, 925.81083,     -1.14405,-3.45374,50.00000,20.00000,6.914051e-08,0.78718
300.02301, 928.21083,     -1.14288,-3.45849,50.00000,20.00000,6.909948e-08,0.78718
300.02100, 930.61083,     -1.14307,-3.46155,50.00000,20.00000,6.900017e-08,0.78719
300.01599, 933.01083,     -1.14248,-3.46528,50.00000,20.00000,6.911944e-08,0.78719
300.01901, 935.41083,     -1.14307,-3.47037,50.00000,20.00000,6.908174e-08,0.78719
300.01801, 937.81083,     -1.14074,-3.47411,50.00000,20.00000,6.915441e-08,0.78719
300.02499, 940.21083,     -1.13939,-3.47886,50.00000,20.00000,6.917730e-08,0.78718
300.03201, 942.61083,     -1.14037,-3.48157,50.00000,20.00000,6.906046e-08,0.78718
300.01300, 945.01083,     -1.14112,-3.48599,50.00000,20.00000,6.917430e-08,0.78719
300.01099, 947.41083,     -1.13763,-3.48938,50.00000,20.00000,6.921496e-08,0.78720
300.01001, 949.81083,     -1.13550,-3.49447,50.00000,20.00000,6.914947e-08,0.78720
299.99600, 952.21083,     -1.13684,-3.49752,50.00000,20.00000,6.914177e-08,0.78721
300.02600, 954.61083,     -1.13649,-3.50295,50.00000,20.00000,6.904596e-08,0.78718
300.01599, 957.01083,     -1.13337,-3.50805,50.00000,20.00000,6.909114e-08,0.78719
300.01501, 959.41083,     -1.13492,-3.51144,50.00000,20.00000,6.905434e-08,0.78719
300.00400, 961.81083,     -1.13413,-3.51449,50.00000,20.00000,6.904552e-08,0.78720
300.00601, 964.21083,     -1.13220,-3.51755,50.00000,20.00000,6.911383e-08,0.78720
300.01099, 966.61083,     -1.13511,-3.52264,50.00000,20.00000,6.902174e-08,0.78720
300.01099, 969.01083,     -1.13279,-3.52739,50.00000,20.00000,6.900939e-08,0.78720
300.02499, 971.41083,     -1.13358,-3.53146,50.00000,20.00000,6.903176e-08,0.78718
300.01401, 973.81083,     -1.13318,-3.53418,50.00000,20.00000,6.915581e-08,0.78719
300.01801, 976.21083,     -1.13008,-3.53927,50.00000,20.00000,6.912543e-08,0.78719
300.01801, 978.61083,     -1.12931,-3.54232,50.00000,20.00000,6.902212e-08,0.78719
300.01801, 981.01083,     -1.12911,-3.54674,50.00000,20.00000,6.906531e-08,0.78719
300.01999, 983.41083,     -1.13163,-3.55183,50.00000,20.00000,6.907646e-08,0.78719
300.00500, 985.81083,     -1.12929,-3.55522,50.00000,20.00000,6.908242e-08,0.78720
300.01001, 988.21083,     -1.13046,-3.55997,50.00000,20.00000,6.897152e-08,0.78720
300.01501, 990.61083,     -1.12756,-3.56371,50.00000,20.00000,6.900258e-08,0.78719
300.01999, 993.01083,     -1.13067,-3.56812,50.00000,20.00000,6.903765e-08,0.78719
300.01700, 995.41083,     -1.12989,-3.57117,50.00000,20.00000,6.902665e-08,0.78719
300.01401, 997.81083,     -1.13182,-3.57524,50.00000,20.00000,6.897242e-08,0.78719
300.01999,1000.21083,     -1.12485,-3.57762,50.00000,20.00000,6.909312e-08,0.78719
300.01300,1002.61083,     -1.12562,-3.58203,50.00000,20.00000,6.895149e-08,0.78719
300.00601,1005.01083,     -1.12735,-3.58475,50.00000,20.00000,6.899275e-08,0.78720
300.01901,1007.41083,     -1.12737,-3.58916,50.00000,20.00000,6.902610e-08,0.78719
300.00800,1009.81083,     -1.12716,-3.59255,50.00000,20.00000,6.900049e-08,0.78720
300.01001,1012.21083,     -1.12716,-3.59493,50.00000,20.00000,6.899719e-08,0.78720
300.00800,1014.61083,     -1.12619,-3.59866,50.00000,20.00000,6.905378e-08,0.78720
300.01300,1017.01083,     -1.12659,-3.60104,50.00000,20.00000,6.914661e-08,0.78719
300.01199,1019.41083,     -1.12523,-3.60647,50.00000,20.00000,6.912547e-08,0.78719
300.00699,1021.81083,     -1.12600,-3.61020,50.00000,20.00000,6.900910e-08,0.78720
300.01700,1024.21083,     -1.12814,-3.61394,50.00000,20.00000,6.910479e-08,0.78719
300.01001,1026.61083,     -1.12678,-3.61767,50.00000,20.00000,6.906894e-08,0.78720
300.02301,1029.01083,     -1.12175,-3.62072,50.00000,20.00000,6.902070e-08,0.78718
300.02301,1031.41083,     -1.12505,-3.62412,50.00000,20.00000,6.887697e-08,0.78718
300.01401,1033.81083,     -1.12368,-3.62808,50.00000,20.00000,6.905724e-08,0.78719
300.02499,1036.21083,     -1.12408,-3.63181,50.00000,20.00000,6.913538e-08,0.78718
300.01501,1038.61083,     -1.12077,-3.63419,50.00000,20.00000,6.906089e-08,0.78719
300.01401,1041.01083,     -1.12174,-3.63758,50.00000,20.00000,6.908146e-08,0.78719
300.02499,1043.41083,     -1.12001,-3.64120,50.00000,20.00000,6.906225e-08,0.78718
300.02200,1045.81083,     -1.12253,-3.64572,50.00000,20.00000,6.916741e-08,0.78719
300.00900,1048.21083,     -1.12057,-3.64946,50.00000,20.00000,6.903799e-08,0.78720
300.01599,1050.61083,     -1.11515,-3.65319,50.00000,20.00000,6.908907e-08,0.78719
300.01501,1053.01083,     -1.11670,-3.65534,50.00000,20.00000,6.907778e-08,0.78719
300.00900,1055.41083,     -1.11941,-3.66247,50.00000,20.00000,6.906739e-08,0.78720
300.02499,1057.81083,     -1.11516,-3.66609,50.00000,20.00000,6.899183e-08,0.78718
300.02301,1060.21083,     -1.11691,-3.66779,50.00000,20.00000,6.916021e-08,0.78718
300.01401,1062.61083,     -1.11767,-3.67186,50.00000,20.00000,6.913292e-08,0.78719
300.02100,1065.01083,     -1.11690,-3.67627,50.00000,20.00000,6.906458e-08,0.78719
300.02100,1067.41083,     -1.11865,-3.67751,50.00000,20.00000,6.907910e-08,0.78719
300.00900,1069.81083,     -1.11534,-3.68181,50.00000,20.00000,6.901329e-08,0.78720
300.01300,1072.21083,     -1.11651,-3.68487,50.00000,20.00000,6.910494e-08,0.78719
300.01801,1074.61083,     -1.11593,-3.68939,50.00000,20.00000,6.901811e-08,0.78719
300.02899,1077.01083,     -1.11343,-3.69290,50.00000,20.00000,6.900329e-08,0.78718
300.02399,1079.41083,     -1.11439,-3.69595,50.00000,20.00000,6.894885e-08,0.78718
300.01199,1081.81083,     -1.11457,-3.69901,50.00000,20.00000,6.907619e-08,0.78719
300.01001,1084.21083,     -1.11515,-3.70172,50.00000,20.00000,6.905741e-08,0.78720
300.01901,1086.61083,     -1.11361,-3.70478,50.00000,20.00000,6.908262e-08,0.78719
300.00800,1089.01083,     -1.11262,-3.70806,50.00000,20.00000,6.899346e-08,0.78720
300.01501,1091.41083,     -1.11321,-3.71225,50.00000,20.00000,6.902687e-08,0.78719
300.01999,1093.81083,     -1.10954,-3.71496,50.00000,20.00000,6.904327e-08,0.78719
300.02701,1096.21083,     -1.11110,-3.71937,50.00000,20.00000,6.904696e-08,0.78718
300.01001,1098.61083,     -1.11127,-3.72209,50.00000,20.00000,6.898194e-08,0.78720
300.01599,1101.01083,     -1.10837,-3.72582,50.00000,20.00000,6.909148e-08,0.78719
300.01401,1103.41083,     -1.11030,-3.72888,50.00000,20.00000,6.905122e-08,0.78719
300.02100,1105.81083,     -1.11148,-3.73159,50.00000,20.00000,6.903273e-08,0.78719
300.01901,1108.21083,     -1.10992,-3.73476,50.00000,20.00000,6.901480e-08,0.78719
300.00900,1110.61083,     -1.10855,-3.73883,50.00000,20.00000,6.904138e-08,0.78720
300.00601,1113.01083,     -1.10719,-3.74155,50.00000,20.00000,6.897263e-08,0.78720
300.01801,1115.41083,     -1.10701,-3.74449,50.00000,20.00000,6.887578e-08,0.78719
300.01599,1117.81083,     -1.10856,-3.74856,50.00000,20.00000,6.903713e-08,0.78719
300.01901,1120.21083,     -1.10585,-3.75128,50.00000,20.00000,6.903612e-08,0.78719
300.02499,1122.61083,     -1.10877,-3.75365,50.00000,20.00000,6.898894e-08,0.78718
300.01801,1125.01083,     -1.10643,-3.75863,50.00000,20.00000,6.895279e-08,0.78719
300.02200,1127.41083,     -1.10644,-3.76123,50.00000,20.00000,6.896503e-08,0.78719
300.00900,1129.81083,     -1.10623,-3.76395,50.00000,20.00000,6.889608e-08,0.78720
300.06299,1132.21083,     -1.06229,-3.76813,50.00000,20.00000,6.890980e-08,0.78715
300.02701,1134.61083,     -1.10606,-3.77175,50.00000,20.00000,6.894666e-08,0.78718
300.01099,1137.01083,     -1.10642,-3.77515,50.00000,20.00000,6.899468e-08,0.78720
300.00900,1139.41083,     -1.10623,-3.77741,50.00000,20.00000,6.897368e-08,0.78720
300.01099,1141.81083,     -1.10080,-3.78148,50.00000,20.00000,6.894021e-08,0.78720
300.01001,1144.21083,     -1.10099,-3.78454,50.00000,20.00000,6.889105e-08,0.78720
300.01801,1146.61083,     -1.10120,-3.78906,50.00000,20.00000,6.896783e-08,0.78719
300.00400,1149.01083,     -1.10157,-3.79098,50.00000,20.00000,6.900917e-08,0.78720
300.02100,1151.41083,     -1.10062,-3.79336,50.00000,20.00000,6.898470e-08,0.78719
300.03900,1153.81083,     -1.10026,-3.79574,50.00000,20.00000,6.884833e-08,0.78717
300.01901,1156.21083,     -1.10411,-3.79947,50.00000,20.00000,6.900754e-08,0.78719
300.02301,1158.61083,     -1.10295,-3.80331,50.00000,20.00000,6.894851e-08,0.78718
300.02499,1161.01083,     -1.10295,-3.80524,50.00000,20.00000,6.895195e-08,0.78718
300.01401,1163.41083,     -1.10081,-3.80841,50.00000,20.00000,6.886227e-08,0.78719
300.01501,1165.81083,     -1.09829,-3.81338,50.00000,20.00000,6.893742e-08,0.78719
300.02100,1168.21083,     -1.09791,-3.81610,50.00000,20.00000,6.884744e-08,0.78719
300.01700,1170.61083,     -1.10469,-3.81847,50.00000,20.00000,6.885329e-08,0.78719
300.01501,1173.01083,     -1.10100,-3.82221,50.00000,20.00000,6.898127e-08,0.78719
300.01501,1175.41083,     -1.09868,-3.82504,50.00000,20.00000,6.893562e-08,0.78719
300.02200,1177.81083,     -1.09752,-3.82877,50.00000,20.00000,6.892813e-08,0.78719
300.01001,1180.21083,     -1.10061,-3.83103,50.00000,20.00000,6.889996e-08,0.78720
300.01501,1182.61083,     -1.09383,-3.83273,50.00000,20.00000,6.895974e-08,0.78719
300.01501,1185.01083,     -1.09712,-3.83533,50.00000,20.00000,6.874545e-08,0.78719
300.02200,1187.41083,     -1.09636,-3.83895,50.00000,20.00000,6.883716e-08,0.78719
300.01801,1189.81083,     -1.09364,-3.84336,50.00000,20.00000,6.885261e-08,0.78719
300.01199,1192.21083,     -1.09615,-3.84506,50.00000,20.00000,6.886420e-08,0.78719
300.01401,1194.61083,     -1.09286,-3.84744,50.00000,20.00000,6.893244e-08,0.78719
300.01099,1197.01083,     -1.09441,-3.85219,50.00000,20.00000,6.897199e-08,0.78720
300.00000,1199.41083,     -1.09226,-3.85592,50.00000,20.00000,6.889779e-08,0.78721
300.01999,1201.81083,     -1.09422,-3.85592,50.00000,20.00000,6.883659e-08,0.78719
300.01099,1204.21083,     -1.09072,-3.85875,50.00000,20.00000,6.900777e-08,0.78720
300.02100,1206.61083,     -1.09015,-3.86180,50.00000,20.00000,6.893810e-08,0.78719
300.01901,1209.01083,     -1.09093,-3.86588,50.00000,20.00000,6.896545e-08,0.78719
300.01099,1211.41083,     -1.09227,-3.86780,50.00000,20.00000,6.893578e-08,0.78720
300.02899,1213.81083,     -1.09094,-3.87142,50.00000,20.00000,6.887179e-08,0.78718
300.02600,1216.21083,     -1.09094,-3.87425,50.00000,20.00000,6.895058e-08,0.78718
300.01999,1218.61083,     -1.08880,-3.87640,50.00000,20.00000,6.897431e-08,0.78719
300.00800,1221.01083,     -1.09304,-3.87911,50.00000,20.00000,6.890290e-08,0.78720
300.02301,1223.41083,     -1.08919,-3.88217,50.00000,20.00000,6.884285e-08,0.78718
300.01901,1225.81083,     -1.08666,-3.88499,50.00000,20.00000,6.890104e-08,0.78719
300.02499,1228.21083,     -1.08861,-3.88794,50.00000,20.00000,6.892281e-08,0.78718
300.01099,1230.61083,     -1.08626,-3.89144,50.00000,20.00000,6.895129e-08,0.78720
300.00601,1233.01083,     -1.08432,-3.89280,50.00000,20.00000,6.894648e-08,0.78720
300.01901,1235.41083,     -1.08783,-3.89699,50.00000,20.00000,6.883164e-08,0.78719
300.00601,1237.81083,     -1.08800,-3.89970,50.00000,20.00000,6.886785e-08,0.78720
300.01401,1240.21083,     -1.08627,-3.90276,50.00000,20.00000,6.884585e-08,0.78719
300.01401,1242.61083,     -1.08685,-3.90672,50.00000,20.00000,6.892565e-08,0.78719
300.01599,1245.01083,     -1.08414,-3.90909,50.00000,20.00000,6.888192e-08,0.78719
300.01999,1247.41083,     -1.08725,-3.91203,50.00000,20.00000,6.883616e-08,0.78719
300.01700,1249.81083,     -1.08453,-3.91712,50.00000,20.00000,6.886193e-08,0.78719
300.01300,1252.21083,     -1.08413,-3.91712,50.00000,20.00000,6.900842e-08,0.78719
300.01501,1254.61083,     -1.08646,-3.92086,50.00000,20.00000,6.882475e-08,0.78719
300.02499,1257.01083,     -1.08570,-3.92289,50.00000,20.00000,6.890164e-08,0.78718
300.02100,1259.41083,     -1.08415,-3.92629,50.00000,20.00000,6.890906e-08,0.78719
300.02600,1261.81083,     -1.08202,-3.92764,50.00000,20.00000,6.875066e-08,0.78718
300.00800,1264.21083,     -1.08490,-3.93036,50.00000,20.00000,6.887633e-08,0.78720
300.01099,1266.61083,     -1.08161,-3.93443,50.00000,20.00000,6.876716e-08,0.78720
300.01099,1269.01083,     -1.08161,-3.93556,50.00000,20.00000,6.884503e-08,0.78720
300.02100,1271.41083,     -1.08085,-3.93918,50.00000,20.00000,6.878397e-08,0.78719
300.01501,1273.81083,     -1.08278,-3.94088,50.00000,20.00000,6.877425e-08,0.78719
300.01401,1276.21083,     -1.08123,-3.94529,50.00000,20.00000,6.873095e-08,0.78719
300.01501,1278.61083,     -1.08220,-3.94733,50.00000,20.00000,6.875326e-08,0.78719
300.01099,1281.01083,     -1.08026,-3.94971,50.00000,20.00000,6.887349e-08,0.78720
300.01199,1283.41083,     -1.08006,-3.95231,50.00000,20.00000,6.881769e-08,0.78719
300.00101,1285.81083,     -1.07772,-3.95581,50.00000,20.00000,6.872905e-08,0.78721
300.00900,1288.21083,     -1.08161,-3.95853,50.00000,20.00000,6.871594e-08,0.78720
299.99701,1290.61083,     -1.07966,-3.96124,50.00000,20.00000,6.870888e-08,0.78721
300.01199,1293.01083,     -1.07754,-3.96328,50.00000,20.00000,6.877150e-08,0.78719
300.01801,1295.41083,     -1.07794,-3.96566,50.00000,20.00000,6.876853e-08,0.78719
300.02100,1297.81083,     -1.07736,-3.96837,50.00000,20.00000,6.874896e-08,0.78719
300.01801,1300.21083,     -1.07697,-3.97131,50.00000,20.00000,6.870945e-08,0.78719
300.01700,1302.61083,     -1.07600,-3.97527,50.00000,20.00000,6.879046e-08,0.78719
300.01099,1305.01083,     -1.07774,-3.97663,50.00000,20.00000,6.882982e-08,0.78720
300.01300,1307.41083,     -1.08123,-3.97923,50.00000,20.00000,6.870081e-08,0.78719
300.01501,1309.81083,     -1.07541,-3.98149,50.00000,20.00000,6.875439e-08,0.78719
300.00699,1312.21083,     -1.07657,-3.98500,50.00000,20.00000,6.866243e-08,0.78720
300.01700,1314.61083,     -1.07619,-3.98806,50.00000,20.00000,6.874780e-08,0.78719
300.00900,1317.01083,     -1.07483,-3.99009,50.00000,20.00000,6.869039e-08,0.78720
300.01001,1319.41083,     -1.07735,-3.99269,50.00000,20.00000,6.863163e-08,0.78720
300.01999,1321.81083,     -1.07329,-3.99552,50.00000,20.00000,6.882121e-08,0.78719
300.01700,1324.21083,     -1.07484,-3.99824,50.00000,20.00000,6.878095e-08,0.78719
300.00800,1326.61083,     -1.07541,-4.00061,50.00000,20.00000,6.864269e-08,0.78720
300.01099,1329.01083,     -1.07367,-4.00401,50.00000,20.00000,6.874646e-08,0.78720
300.00500,1331.41083,     -1.07540,-4.00537,50.00000,20.00000,6.876011e-08,0.78720
300.01999,1333.81083,     -1.07174,-4.00876,50.00000,20.00000,6.873432e-08,0.78719
300.01700,1336.21083,     -1.07232,-4.01249,50.00000,20.00000,6.877578e-08,0.78719
300.03201,1338.61083,     -1.07427,-4.01351,50.00000,20.00000,6.873561e-08,0.78718
300.01901,1341.01083,     -1.07561,-4.01679,50.00000,20.00000,6.879085e-08,0.78719
300.02200,1343.41083,     -1.07678,-4.01849,50.00000,20.00000,6.874117e-08,0.78719
300.01401,1345.81083,     -1.07658,-4.02052,50.00000,20.00000,6.876443e-08,0.78719
300.01099,1348.21083,     -1.07037,-4.02482,50.00000,20.00000,6.865269e-08,0.78720
300.01999,1350.61083,     -1.07465,-4.02697,50.00000,20.00000,6.868876e-08,0.78719
300.01599,1353.01083,     -1.07154,-4.02924,50.00000,20.00000,6.872906e-08,0.78719
300.01901,1355.41083,     -1.07387,-4.03127,50.00000,20.00000,6.865353e-08,0.78719
300.02200,1357.81083,     -1.07116,-4.03467,50.00000,20.00000,6.876512e-08,0.78719
300.01801,1360.21083,     -1.07270,-4.03659,50.00000,20.00000,6.873608e-08,0.78719
300.02701,1362.61083,     -1.07117,-4.03964,50.00000,20.00000,6.864548e-08,0.78718
300.00500,1365.01083,     -1.07017,-4.04066,50.00000,20.00000,6.861250e-08,0.78720
300.01501,1367.41083,     -1.06921,-4.04338,50.00000,20.00000,6.876692e-08,0.78719
300.01801,1369.81083,     -1.07154,-4.04519,50.00000,20.00000,6.872168e-08,0.78719
300.02899,1372.21083,     -1.06807,-4.04949,50.00000,20.00000,6.870669e-08,0.78718
300.02200,1374.61083,     -1.07349,-4.05084,50.00000,20.00000,6.858888e-08,0.78719
300.01700,1377.01083,     -1.07173,-4.05378,50.00000,20.00000,6.871183e-08,0.78719
300.01501,1379.41083,     -1.06747,-4.05616,50.00000,20.00000,6.871031e-08,0.78719
300.01999,1381.81083,     -1.06476,-4.05820,50.00000,20.00000,6.859929e-08,0.78719
300.03000,1384.21083,     -1.06535,-4.06057,50.00000,20.00000,6.869374e-08,0.78718
300.01901,1386.61083,     -1.06573,-4.06374,50.00000,20.00000,6.867741e-08,0.78719
300.02100,1389.01083,     -1.06806,-4.06510,50.00000,20.00000,6.867070e-08,0.78719
300.02200,1391.41083,     -1.06573,-4.06883,50.00000,20.00000,6.867974e-08,0.78719
300.01401,1393.81083,     -1.06630,-4.07177,50.00000,20.00000,6.856438e-08,0.78719
300.01300,1396.21083,     -1.06630,-4.07449,50.00000,20.00000,6.869264e-08,0.78719
300.02100,1398.61083,     -1.06592,-4.07618,50.00000,20.00000,6.859270e-08,0.78719
300.00800,1401.01083,     -1.06591,-4.07856,50.00000,20.00000,6.856661e-08,0.78720
300.01300,1403.41083,     -1.06650,-4.08161,50.00000,20.00000,6.860693e-08,0.78719
300.00900,1405.81083,     -1.06358,-4.08422,50.00000,20.00000,6.865526e-08,0.78720
300.01501,1408.21083,     -1.06650,-4.08625,50.00000,20.00000,6.866319e-08,0.78719
300.00400,1410.61083,     -1.06222,-4.08897,50.00000,20.00000,6.863289e-08,0.78720
300.01099,1413.01083,     -1.06087,-4.09168,50.00000,20.00000,6.856654e-08,0.78720
300.00299,1415.41083,     -1.06028,-4.09202,50.00000,20.00000,6.856036e-08,0.78720
300.01099,1417.81083,     -1.06281,-4.09677,50.00000,20.00000,6.853899e-08,0.78720
300.01599,1420.21083,     -1.06165,-4.09813,50.00000,20.00000,6.856613e-08,0.78719
300.02301,1422.61083,     -1.06302,-4.10085,50.00000,20.00000,6.856621e-08,0.78718
300.00500,1425.01083,     -1.06338,-4.10390,50.00000,20.00000,6.860592e-08,0.78720
300.01599,1427.41083,     -1.06359,-4.10560,50.00000,20.00000,6.861320e-08,0.78719
300.02399,1429.81083,     -1.06263,-4.10865,50.00000,20.00000,6.856987e-08,0.78718
300.02200,1432.21083,     -1.06127,-4.10978,50.00000,20.00000,6.855547e-08,0.78719
300.01901,1434.61083,     -1.06088,-4.11250,50.00000,20.00000,6.850631e-08,0.78719
300.00699,1437.01083,     -1.06281,-4.11623,50.00000,20.00000,6.857973e-08,0.78720
300.00601,1439.41083,     -1.06048,-4.11759,50.00000,20.00000,6.855702e-08,0.78720
300.01801,1441.81083,     -1.05855,-4.12031,50.00000,20.00000,6.848734e-08,0.78719
300.00699,1444.21083,     -1.05893,-4.12234,50.00000,20.00000,6.852730e-08,0.78720
300.01801,1446.61083,     -1.05933,-4.12540,50.00000,20.00000,6.860137e-08,0.78719
300.02499,1449.01083,     -1.05914,-4.12709,50.00000,20.00000,6.852435e-08,0.78718
300.02802,1451.41083,     -1.05799,-4.13049,50.00000,20.00000,6.853186e-08,0.78718
300.01199,1453.81083,     -1.05777,-4.13151,50.00000,20.00000,6.850921e-08,0.78719
300.01199,1456.21083,     -1.05952,-4.13490,50.00000,20.00000,6.856468e-08,0.78719
300.01501,1458.61083,     -1.05487,-4.13727,50.00000,20.00000,6.849463e-08,0.78719
300.02899,1461.01083,     -1.05489,-4.13863,50.00000,20.00000,6.857796e-08,0.78718
300.00699,1463.41083,     -1.05389,-4.14146,50.00000,20.00000,6.854216e-08,0.78720
300.01999,1465.81083,     -1.05701,-4.14406,50.00000,20.00000,6.850474e-08,0.78719
300.02499,1468.21083,     -1.05682,-4.14746,50.00000,20.00000,6.836605e-08,0.78718
300.01700,1470.61083,     -1.05836,-4.15017,50.00000,20.00000,6.845759e-08,0.78719
300.01599,1473.01083,     -1.05681,-4.15164,50.00000,20.00000,6.842127e-08,0.78719
300.00299,1475.41083,     -1.05175,-4.15436,50.00000,20.00000,6.843806e-08,0.78720
300.00500,1477.81083,     -1.05234,-4.15651,50.00000,20.00000,6.841452e-08,0.78720
300.01001,1480.21083,     -1.05409,-4.15685,50.00000,20.00000,6.848598e-08,0.78720
300.00201,1482.61083,     -1.05563,-4.16047,50.00000,20.00000,6.848094e-08,0.78720
300.01599,1485.01083,     -1.05371,-4.16318,50.00000,20.00000,6.836445e-08,0.78719
300.02499,1487.41083,     -1.05818,-4.16556,50.00000,20.00000,6.841187e-08,0.78718
300.01599,1489.81083,     -1.05700,-4.16895,50.00000,20.00000,6.838209e-08,0.78719
300.01401,1492.21083,     -1.05874,-4.17201,50.00000,20.00000,6.843351e-08,0.78719
300.01501,1494.61083,     -1.05584,-4.17302,50.00000,20.00000,6.852165e-08,0.78719
300.01099,1497.01083,     -1.05409,-4.17540,50.00000,20.00000,6.847724e-08,0.78720