File: data/TGA/005c/ExpDat_2024_06_21_PS2439_6_1K_300C_isotherm.csv
#EXPORTTYPE:                 ,DATA ALL
#FILE:                       ,2024_06_21_PS2439_6_1K_300C_isotherm.ngb-ss5
#FORMAT:                     ,NETZSCH5
#FTYPE:                      ,ASCII
#IDENTITY:                   ,PS_6_1K
#DECIMAL:                    ,POINT
#SEPARATOR:                  ,COMMA
#MTYPE:                      ,DSC
#INSTRUMENT:                 ,NETZSCH STA 449F5
#PROJECT:                    ,
#DATE/TIME:                  ,6/22/2024 3:14:27 PM (UTC-4)
#CORR. FILE:                 ,
#TEMPCAL:                    ,28-06-2023 13:26
#SENSITIVITY:                ,28-06-2023 13:53
#LABORATORY:                 ,
#OPERATOR:                   ,Stanley
#REMARK:                     ,
#SAMPLE:                     ,PS2439_6_1K
#SAMPLE MASS /mg:            ,5.0
#MATERIAL:                   ,
#REFERENCE:                  ,-----
#REFERENCE MASS /mg:         ,0
#TYPE OF CRUCIBLE:           ,Al2O3 85 ‘l, open
#SAMPLE CRUCIBLE MASS /mg:   ,0
#REFERENCE CRUCIBLE MASS /mg:,0
#DSC RANGE /‘V:              ,5000
#TG RANGE /mg:               ,35000
#TAU-R:                      ,---
#CORR. CODE:                 ,000
#EXO:                        ,-1
#RANGE:                      ,30›C....800›C/0.0....10.0K/min
#SEGMENT:                    ,S1-5/5
#SEG. 1:                     ,30›C/10.0(K/min)/100›C
#SEG. 2:                     ,100›C/00:10/100›C
#SEG. 3:                     ,100›C/5.0(K/min)/300›C
#SEG. 4:                     ,300›C/24:00/300›C
#SEG. 5:                     ,300›C/10.0(K/min)/800›C

##Temp./›C,Time/min,DSC/(mW/mg),Mass loss/mg,Gas Flow(purge2)/(ml/min),Gas Flow(protective)/(ml/min),TIC(scan:1)/A,Sensit./(uV/mW),Segment
 33.95400,   0.00000,      0.58147, 0.000000e+00,50.00000,20.00000,6.826453e-08,0.92424,1
 44.95700,   2.80000,      0.79641,     -0.21076,50.00000,20.00000,8.022397e-08,0.92560,1
 67.65400,   5.60000,      1.94452,-8.892000e-02,50.00000,20.00000,8.079484e-08,0.92596,1
 96.76502,   8.40000,      1.81826,-7.926676e-02,50.00000,20.00000,7.854983e-08,0.92180,2
107.60854,  11.20000,      0.53699,     -0.16395,50.00000,20.00000,7.614519e-08,0.91899,2
108.71720,  14.00000,-9.699576e-02,     -0.23194,50.00000,20.00000,7.392098e-08,0.91866,2
106.07955,  16.80000,     -0.26384,     -0.27568,50.00000,20.00000,7.228783e-08,0.91942,2
108.45109,  19.60000,      0.61100,     -0.22190,50.00000,20.00000,7.086002e-08,0.91874,3
119.78528,  22.40000,      1.34376,     -0.16259,50.00000,20.00000,6.964182e-08,0.91506,3
135.53752,  25.20000,      1.72904,     -0.13406,50.00000,20.00000,6.855088e-08,0.90882,3
151.92925,  28.00000,      1.81686,     -0.12082,50.00000,20.00000,6.776266e-08,0.90102,3
167.48167,  30.80000,      1.78869,     -0.11517,50.00000,20.00000,6.715454e-08,0.89247,3
182.14397,  33.60000,      1.75234,     -0.10827,50.00000,20.00000,6.677376e-08,0.88346,3
196.35419,  36.40000,      1.73607,     -0.10276,50.00000,20.00000,6.625136e-08,0.87393,3
210.36944,  39.20000,      1.72988,-9.605121e-02,50.00000,20.00000,6.606646e-08,0.86383,3
224.29436,  42.00000,      1.71572,-8.971184e-02,50.00000,20.00000,6.590778e-08,0.85316,3
238.22100,  44.80000,      1.69525,-8.579567e-02,50.00000,20.00000,6.567923e-08,0.84194,3
252.14912,  47.60000,      1.65505,-8.519495e-02,50.00000,20.00000,6.565199e-08,0.83023,3
266.09028,  50.40000,      1.59948,-8.748594e-02,50.00000,20.00000,6.560018e-08,0.81809,3
280.01737,  53.20000,      1.53052,     -0.10046,50.00000,20.00000,6.589418e-08,0.80560,3
293.94886,  56.00000,      1.45189,     -0.12773,50.00000,20.00000,6.605179e-08,0.79283,3
302.25843,  58.80000,     -0.55367,     -0.19995,50.00000,20.00000,6.628740e-08,0.78510,4
302.76004,  61.60000,     -1.06532,     -0.27006,50.00000,20.00000,6.662121e-08,0.78463,4
301.79514,  64.40000,     -1.15005,     -0.33374,50.00000,20.00000,6.682710e-08,0.78553,4
301.00860,  67.20000,     -1.11528,     -0.38802,50.00000,20.00000,6.707601e-08,0.78627,4
300.51761,  70.00000,     -1.07122,     -0.43825,50.00000,20.00000,6.702866e-08,0.78672,4
300.28196,  72.80000,     -1.04914,     -0.48355,50.00000,20.00000,6.704405e-08,0.78694,4
300.14328,  75.60000,     -1.03495,     -0.52333,50.00000,20.00000,6.704910e-08,0.78707,4
300.08244,  78.40000,     -1.02603,     -0.56150,50.00000,20.00000,6.704357e-08,0.78713,4
300.04762,  81.20000,     -1.02068,     -0.59688,50.00000,20.00000,6.707919e-08,0.78716,4
300.02819,  84.00000,     -1.01649,     -0.62837,50.00000,20.00000,6.702826e-08,0.78718,4
300.01841,  86.80000,     -1.00850,     -0.65948,50.00000,20.00000,6.708254e-08,0.78719,4
300.00965,  89.60000,     -0.99837,     -0.69224,50.00000,20.00000,6.715780e-08,0.78720,4
300.00641,  92.40000,     -0.99178,     -0.71975,50.00000,20.00000,6.721797e-08,0.78720,4
300.00863,  95.20000,     -0.98417,     -0.74554,50.00000,20.00000,6.704899e-08,0.78720,4
300.02653,  98.00000,     -0.97533,     -0.77132,50.00000,20.00000,6.709258e-08,0.78718,4
300.01907, 100.80000,     -0.95850,     -0.79587,50.00000,20.00000,6.711054e-08,0.78719,4
300.01127, 103.60000,     -0.95007,     -0.81873,50.00000,20.00000,6.714407e-08,0.78720,4
300.01310, 106.40000,     -0.93796,     -0.84203,50.00000,20.00000,6.712565e-08,0.78719,4
300.00775, 109.20000,     -0.92657,     -0.86405,50.00000,20.00000,6.717652e-08,0.78720,4
300.00693, 112.00000,     -0.92113,     -0.88631,50.00000,20.00000,6.718556e-08,0.78720,4
300.02034, 114.80000,     -0.90980,     -0.90565,50.00000,20.00000,6.722727e-08,0.78719,4
300.01921, 117.60000,     -0.90884,     -0.92487,50.00000,20.00000,6.724318e-08,0.78719,4
300.01527, 120.40000,     -0.89993,     -0.94532,50.00000,20.00000,6.728618e-08,0.78719,4
300.01399, 123.20000,     -0.89444,     -0.96408,50.00000,20.00000,6.723294e-08,0.78719,4
300.01161, 126.00000,     -0.88394,     -0.98297,50.00000,20.00000,6.740447e-08,0.78720,4
300.00694, 128.80000,     -0.87703,     -1.00420,50.00000,20.00000,6.732802e-08,0.78720,4
300.01531, 131.60000,     -0.87239,     -1.02191,50.00000,20.00000,6.731056e-08,0.78719,4
300.01066, 134.40000,     -0.86451,     -1.04027,50.00000,20.00000,6.731282e-08,0.78720,4
300.01258, 137.20000,     -0.85906,     -1.05785,50.00000,20.00000,6.739404e-08,0.78719,4
300.01285, 140.00000,     -0.85408,     -1.07612,50.00000,20.00000,6.742528e-08,0.78719,4
300.00732, 142.80000,     -0.84501,     -1.09431,50.00000,20.00000,6.738657e-08,0.78720,4
300.01952, 145.60000,     -0.84216,     -1.10944,50.00000,20.00000,6.752777e-08,0.78719,4
300.02595, 148.40000,     -0.83737,     -1.12783,50.00000,20.00000,6.742397e-08,0.78718,4
300.02029, 151.20000,     -0.83222,     -1.14215,50.00000,20.00000,6.745623e-08,0.78719,4
300.02005, 154.00000,     -0.82689,     -1.15958,50.00000,20.00000,6.738036e-08,0.78719,4
300.02341, 156.80000,     -0.82169,     -1.17533,50.00000,20.00000,6.737927e-08,0.78718,4
300.01632, 159.60000,     -0.81614,     -1.19020,50.00000,20.00000,6.757205e-08,0.78719,4
300.00350, 162.40000,     -0.80827,     -1.20375,50.00000,20.00000,6.758715e-08,0.78720,4
300.01302, 165.20000,     -0.80288,     -1.22173,50.00000,20.00000,6.757261e-08,0.78719,4
300.01885, 168.00000,     -0.80280,     -1.23792,50.00000,20.00000,6.753907e-08,0.78719,4
300.01295, 170.80000,     -0.79857,     -1.25305,50.00000,20.00000,6.747994e-08,0.78719,4
300.01742, 173.60000,     -0.79139,     -1.26843,50.00000,20.00000,6.762613e-08,0.78719,4
300.01240, 176.40000,     -0.79085,     -1.28032,50.00000,20.00000,6.765910e-08,0.78719,4
300.01707, 179.20000,     -0.78931,     -1.29802,50.00000,20.00000,6.759906e-08,0.78719,4
300.01095, 182.00000,     -0.78093,     -1.31210,50.00000,20.00000,6.758189e-08,0.78720,4
300.02169, 184.80000,     -0.77543,     -1.32419,50.00000,20.00000,6.761340e-08,0.78719,4
300.01702, 187.60000,     -0.77268,     -1.33641,50.00000,20.00000,6.758497e-08,0.78719,4
300.01482, 190.40000,     -0.76904,     -1.35101,50.00000,20.00000,6.752118e-08,0.78719,4
300.01205, 193.20000,     -0.76341,     -1.36470,50.00000,20.00000,6.751760e-08,0.78719,4
299.99987, 196.00000,     -0.75431,     -1.37561,50.00000,20.00000,6.767726e-08,0.78721,4
300.01195, 198.80000,     -0.75028,     -1.38777,50.00000,20.00000,6.762749e-08,0.78719,4
300.01541, 201.60000,     -0.74446,     -1.40113,50.00000,20.00000,6.771031e-08,0.78719,4
300.01540, 204.40000,     -0.74146,     -1.41537,50.00000,20.00000,6.769109e-08,0.78719,4
300.02330, 207.20000,     -0.73733,     -1.42895,50.00000,20.00000,6.765375e-08,0.78718,4
300.01699, 210.00000,     -0.73309,     -1.44117,50.00000,20.00000,6.764289e-08,0.78719,4
300.01783, 212.80000,     -0.72347,     -1.45272,50.00000,20.00000,6.769909e-08,0.78719,4
300.01331, 215.60000,     -0.71891,     -1.46527,50.00000,20.00000,6.765702e-08,0.78719,4
300.01761, 218.40000,     -0.71495,     -1.47635,50.00000,20.00000,6.771846e-08,0.78719,4
300.01445, 221.20000,     -0.70915,     -1.48857,50.00000,20.00000,6.772393e-08,0.78719,4
300.02297, 224.00000,     -0.69668,     -1.50161,50.00000,20.00000,6.771422e-08,0.78718,4
300.02011, 226.80000,     -0.69015,     -1.51209,50.00000,20.00000,6.778266e-08,0.78719,4
300.01019, 229.60000,     -0.68165,     -1.52432,50.00000,20.00000,6.777827e-08,0.78720,4
300.01683, 232.40000,     -0.68034,     -1.53351,50.00000,20.00000,6.773175e-08,0.78719,4
300.02041, 235.20000,     -0.67326,     -1.54458,50.00000,20.00000,6.773875e-08,0.78719,4
300.01388, 238.00000,     -0.66958,     -1.55319,50.00000,20.00000,6.780818e-08,0.78719,4
300.02077, 240.80000,     -0.66735,     -1.56814,50.00000,20.00000,6.780061e-08,0.78719,4
300.02314, 243.60000,     -0.66309,     -1.57794,50.00000,20.00000,6.771994e-08,0.78718,4
300.02587, 246.40000,     -0.65686,     -1.58642,50.00000,20.00000,6.787936e-08,0.78718,4
300.01894, 249.20000,     -0.64872,     -1.59969,50.00000,20.00000,6.787899e-08,0.78719,4
300.02072, 252.00000,     -0.64337,     -1.61041,50.00000,20.00000,6.784814e-08,0.78719,4
300.01180, 254.80000,     -0.64135,     -1.61991,50.00000,20.00000,6.782109e-08,0.78719,4
300.02173, 257.60000,     -0.63493,     -1.63202,50.00000,20.00000,6.780833e-08,0.78719,4
300.00635, 260.40000,     -0.62730,     -1.64107,50.00000,20.00000,6.788065e-08,0.78720,4
300.01804, 263.20000,     -0.61668,     -1.65091,50.00000,20.00000,6.783560e-08,0.78719,4
300.00871, 266.00000,     -0.61581,     -1.66078,50.00000,20.00000,6.788173e-08,0.78720,4
300.03209, 268.80000,     -0.60927,     -1.66777,50.00000,20.00000,6.785445e-08,0.78718,4
300.03050, 271.60000,     -0.60279,     -1.68021,50.00000,20.00000,6.786112e-08,0.78718,4
300.00351, 274.40000,     -0.48345,     -1.69120,50.00000,20.00000,6.794216e-08,0.78720,4
300.01769, 277.20000,     -0.47409,     -1.69786,50.00000,20.00000,6.789038e-08,0.78719,4
300.00723, 280.00000,     -0.47170,     -1.70792,50.00000,20.00000,6.795048e-08,0.78720,4
300.01316, 282.80000,     -0.47078,     -1.71687,50.00000,20.00000,6.793738e-08,0.78719,4
300.01349, 285.60000,     -0.46359,     -1.72388,50.00000,20.00000,6.791657e-08,0.78719,4
300.00921, 288.40000,     -0.46151,     -1.73413,50.00000,20.00000,6.780287e-08,0.78720,4
300.00786, 291.20000,     -0.46120,     -1.74368,50.00000,20.00000,6.787901e-08,0.78720,4
300.01721, 294.00000,     -0.45587,     -1.75183,50.00000,20.00000,6.794893e-08,0.78719,4
300.01638, 296.80000,     -0.44973,     -1.75943,50.00000,20.00000,6.802515e-08,0.78719,4
300.00553, 299.60000,     -0.44907,     -1.77003,50.00000,20.00000,6.794187e-08,0.78720,4
300.01643, 302.40000,     -0.44808,     -1.77867,50.00000,20.00000,6.799512e-08,0.78719,4
300.02434, 305.20000,     -0.44458,     -1.78497,50.00000,20.00000,6.797018e-08,0.78718,4
300.00968, 308.00000,     -0.43904,     -1.79438,50.00000,20.00000,6.790653e-08,0.78720,4
300.01342, 310.80000,     -0.43789,     -1.80409,50.00000,20.00000,6.808312e-08,0.78719,4
300.01037, 313.60000,     -0.43620,     -1.81025,50.00000,20.00000,6.808186e-08,0.78720,4
300.01773, 316.40000,     -0.43154,     -1.81962,50.00000,20.00000,6.788474e-08,0.78719,4
300.00903, 319.20000,     -0.43396,     -1.82652,50.00000,20.00000,6.803538e-08,0.78720,4
300.01438, 322.00000,     -0.43223,     -1.83463,50.00000,20.00000,6.801474e-08,0.78719,4
300.02657, 324.80000,     -0.43099,     -1.84199,50.00000,20.00000,6.802561e-08,0.78718,4
300.01591, 327.60000,     -0.42518,     -1.85063,50.00000,20.00000,6.813919e-08,0.78719,4
300.01092, 330.40000,     -0.42016,     -1.85776,50.00000,20.00000,6.817050e-08,0.78720,4
300.01406, 333.20000,     -0.42178,     -1.86484,50.00000,20.00000,6.805936e-08,0.78719,4
300.01691, 336.00000,     -0.41566,     -1.87130,50.00000,20.00000,6.805369e-08,0.78719,4
300.00752, 338.80000,     -0.41657,     -1.87943,50.00000,20.00000,6.803172e-08,0.78720,4
300.02011, 341.60000,     -0.41048,     -1.88622,50.00000,20.00000,6.810040e-08,0.78719,4
300.02281, 344.40000,     -0.41138,     -1.89455,50.00000,20.00000,6.808370e-08,0.78718,4
300.02091, 347.20000,     -0.41115,     -1.90194,50.00000,20.00000,6.802124e-08,0.78719,4
300.08601, 350.00000,     -0.40476,     -1.90849,50.00000,20.00000,6.800624e-08,0.78713,4
300.01280, 352.80000,     -0.40619,     -1.91306,50.00000,20.00000,6.792811e-08,0.78719,4
300.00594, 355.60000,     -0.40588,     -1.92053,50.00000,20.00000,6.815862e-08,0.78720,4
300.00682, 358.40000,     -0.40331,     -1.92758,50.00000,20.00000,6.800978e-08,0.78720,4
300.02274, 361.20000,     -0.39933,     -1.93407,50.00000,20.00000,6.809518e-08,0.78718,4
300.01642, 364.00000,     -0.39862,     -1.93916,50.00000,20.00000,6.811587e-08,0.78719,4
300.01693, 366.80000,     -0.39927,     -1.94493,50.00000,20.00000,6.808574e-08,0.78719,4
300.02290, 369.60000,     -0.39833,     -1.95138,50.00000,20.00000,6.812757e-08,0.78718,4
300.01717, 372.40000,     -0.39579,     -1.95749,50.00000,20.00000,6.811248e-08,0.78719,4
300.01437, 375.20000,     -0.39449,     -1.96225,50.00000,20.00000,6.807610e-08,0.78719,4
300.02092, 378.00000,     -0.39587,     -1.96926,50.00000,20.00000,6.813196e-08,0.78719,4
300.00130, 380.80000,     -0.39307,     -1.97339,50.00000,20.00000,6.815256e-08,0.78720,4
300.01481, 383.60000,     -0.39295,     -1.97955,50.00000,20.00000,6.812058e-08,0.78719,4
300.02035, 386.40000,     -0.39191,     -1.98498,50.00000,20.00000,6.819264e-08,0.78719,4
300.01201, 389.20000,     -0.39791,     -1.99076,50.00000,20.00000,6.822503e-08,0.78719,4
300.01303, 392.00000,     -0.39659,     -1.99618,50.00000,20.00000,6.818651e-08,0.78719,4
300.02555, 394.80000,     -0.39480,     -2.00162,50.00000,20.00000,6.807950e-08,0.78718,4
300.01241, 397.60000,     -0.39552,     -2.00554,50.00000,20.00000,6.818274e-08,0.78719,4
300.01912, 400.40000,     -0.39579,     -2.01135,50.00000,20.00000,6.812400e-08,0.78719,4
300.02403, 403.20000,     -0.40204,     -2.01541,50.00000,20.00000,6.823106e-08,0.78718,4
300.02849, 406.00000,     -0.39678,     -2.02220,50.00000,20.00000,6.817586e-08,0.78718,4
300.01103, 408.80000,     -0.40036,     -2.02774,50.00000,20.00000,6.809821e-08,0.78720,4
300.01712, 411.60000,     -0.40524,     -2.03307,50.00000,20.00000,6.812222e-08,0.78719,4
300.00469, 414.40000,     -0.40626,     -2.03762,50.00000,20.00000,6.806992e-08,0.78720,4
300.01868, 417.20000,     -0.40631,     -2.04226,50.00000,20.00000,6.818350e-08,0.78719,4
300.01078, 420.00000,     -0.41025,     -2.04743,50.00000,20.00000,6.815121e-08,0.78720,4
300.01471, 422.80000,     -0.41278,     -2.05150,50.00000,20.00000,6.815261e-08,0.78719,4
300.01210, 425.60000,     -0.42440,     -2.05489,50.00000,20.00000,6.816734e-08,0.78719,4
300.01366, 428.40000,     -0.43325,     -2.06097,50.00000,20.00000,6.822742e-08,0.78719,4
300.01247, 431.20000,     -0.43655,     -2.06553,50.00000,20.00000,6.816487e-08,0.78719,4
300.00937, 434.00000,     -0.43682,     -2.07092,50.00000,20.00000,6.815541e-08,0.78720,4
300.02169, 436.80000,     -0.43965,     -2.07300,50.00000,20.00000,6.829482e-08,0.78719,4
300.00877, 439.60000,     -0.43844,     -2.07540,50.00000,20.00000,6.821776e-08,0.78720,4
300.02398, 442.40000,     -0.43995,     -2.08243,50.00000,20.00000,6.816360e-08,0.78718,4
300.02113, 445.20000,     -0.43995,     -2.08657,50.00000,20.00000,6.810542e-08,0.78719,4
300.02345, 448.00000,     -0.43807,     -2.09031,50.00000,20.00000,6.808074e-08,0.78718,4
300.02145, 450.80000,     -0.43903,     -2.09405,50.00000,20.00000,6.820235e-08,0.78719,4
300.02820, 453.60000,     -0.43923,     -2.09902,50.00000,20.00000,6.815550e-08,0.78718,4
300.02988, 456.40000,     -0.43918,     -2.10218,50.00000,20.00000,6.828023e-08,0.78718,4
300.00814, 459.20000,     -0.44091,     -2.10592,50.00000,20.00000,6.823179e-08,0.78720,4
300.01111, 462.00000,     -0.44077,     -2.11067,50.00000,20.00000,6.818264e-08,0.78720,4
300.01452, 464.80000,     -0.43848,     -2.11542,50.00000,20.00000,6.816150e-08,0.78719,4
300.02066, 467.60000,     -0.44270,     -2.12153,50.00000,20.00000,6.823116e-08,0.78719,4
300.02470, 470.40000,     -0.43674,     -2.12424,50.00000,20.00000,6.823804e-08,0.78718,4
300.01843, 473.20000,     -0.44083,     -2.12819,50.00000,20.00000,6.810480e-08,0.78719,4
300.01110, 476.00000,     -0.44228,     -2.13250,50.00000,20.00000,6.825040e-08,0.78720,4
300.02180, 478.80000,     -0.43899,     -2.13623,50.00000,20.00000,6.824610e-08,0.78719,4
300.03041, 481.60000,     -0.43929,     -2.14098,50.00000,20.00000,6.832813e-08,0.78718,4
300.01845, 484.40000,     -0.44146,     -2.14472,50.00000,20.00000,6.816307e-08,0.78719,4
300.01048, 487.20000,     -0.44180,     -2.14907,50.00000,20.00000,6.840284e-08,0.78720,4
300.01119, 490.00000,     -0.44234,     -2.15207,50.00000,20.00000,6.823487e-08,0.78720,4
300.00471, 492.80000,     -0.43960,     -2.15615,50.00000,20.00000,6.829285e-08,0.78720,4
300.01445, 495.60000,     -0.44413,     -2.16305,50.00000,20.00000,6.817298e-08,0.78719,4
300.00189, 498.40000,     -0.44210,     -2.16577,50.00000,20.00000,6.823192e-08,0.78720,4
300.01276, 501.20000,     -0.43973,     -2.17230,50.00000,20.00000,6.819897e-08,0.78719,4
300.01668, 504.00000,     -0.44195,     -2.17506,50.00000,20.00000,6.825864e-08,0.78719,4
300.02041, 506.80000,     -0.44399,     -2.18116,50.00000,20.00000,6.827666e-08,0.78719,4
300.01223, 509.60000,     -0.44241,     -2.18251,50.00000,20.00000,6.838630e-08,0.78719,4
300.02126, 512.40000,     -0.44133,     -2.18658,50.00000,20.00000,6.832617e-08,0.78719,4
300.01135, 515.20000,     -0.44060,     -2.18984,50.00000,20.00000,6.829399e-08,0.78720,4
300.00930, 518.00000,     -0.44376,     -2.19426,50.00000,20.00000,6.818696e-08,0.78720,4
300.02144, 520.80000,     -0.44362,     -2.19993,50.00000,20.00000,6.822588e-08,0.78719,4
300.00973, 523.60000,     -0.44595,     -2.20253,50.00000,20.00000,6.832122e-08,0.78720,4
300.01576, 526.40000,     -0.44394,     -2.20690,50.00000,20.00000,6.822509e-08,0.78719,4
300.02163, 529.20000,     -0.44421,     -2.21113,50.00000,20.00000,6.825354e-08,0.78719,4
300.00190, 532.00000,     -0.44598,     -2.21622,50.00000,20.00000,6.825685e-08,0.78720,4
300.01835, 534.80000,     -0.44570,     -2.21961,50.00000,20.00000,6.828464e-08,0.78719,4
300.02051, 537.60000,     -0.44376,     -2.22228,50.00000,20.00000,6.823783e-08,0.78719,4
300.01579, 540.40000,     -0.44323,     -2.22900,50.00000,20.00000,6.817411e-08,0.78719,4
300.00543, 543.20000,     -0.44819,     -2.23356,50.00000,20.00000,6.807744e-08,0.78720,4
300.01483, 546.00000,     -0.44785,     -2.23626,50.00000,20.00000,6.819737e-08,0.78719,4
300.01937, 548.80000,     -0.44657,     -2.23783,50.00000,20.00000,6.825284e-08,0.78719,4
300.01536, 551.60000,     -0.44618,     -2.24122,50.00000,20.00000,6.815021e-08,0.78719,4
300.02079, 554.40000,     -0.44264,     -2.24495,50.00000,20.00000,6.815175e-08,0.78719,4
300.00965, 557.20000,     -0.44737,     -2.25109,50.00000,20.00000,6.822012e-08,0.78720,4
300.02127, 560.00000,     -0.44517,     -2.25409,50.00000,20.00000,6.814020e-08,0.78719,4
300.01739, 562.80000,     -0.44649,     -2.25815,50.00000,20.00000,6.825247e-08,0.78719,4
300.01859, 565.60000,     -0.44473,     -2.26158,50.00000,20.00000,6.815371e-08,0.78719,4
300.01794, 568.40000,     -0.44666,     -2.26431,50.00000,20.00000,6.811225e-08,0.78719,4
300.02838, 571.20000,     -0.44107,     -2.26939,50.00000,20.00000,6.811666e-08,0.78718,4
300.02841, 574.00000,     -0.44582,     -2.27482,50.00000,20.00000,6.812933e-08,0.78718,4
300.02513, 576.80000,     -0.44751,     -2.27842,50.00000,20.00000,6.819329e-08,0.78718,4
300.01077, 579.60000,     -0.44522,     -2.28398,50.00000,20.00000,6.817003e-08,0.78720,4
300.01591, 582.40000,     -0.45016,     -2.28646,50.00000,20.00000,6.812005e-08,0.78719,4
300.00894, 585.20000,     -0.44803,     -2.29021,50.00000,20.00000,6.812949e-08,0.78720,4
300.00806, 588.00000,     -0.44674,     -2.29359,50.00000,20.00000,6.812918e-08,0.78720,4
300.01038, 590.80000,     -0.44868,     -2.29688,50.00000,20.00000,6.814579e-08,0.78720,4
300.01153, 593.60000,     -0.44689,     -2.30031,50.00000,20.00000,6.815628e-08,0.78720,4
300.01756, 596.40000,     -0.44715,     -2.30514,50.00000,20.00000,6.812532e-08,0.78719,4
300.01718, 599.20000,     -0.44961,     -2.31146,50.00000,20.00000,6.819904e-08,0.78719,4
300.02502, 602.00000,     -0.44824,     -2.31317,50.00000,20.00000,6.825453e-08,0.78718,4
300.01247, 604.80000,     -0.44790,     -2.31652,50.00000,20.00000,6.822145e-08,0.78719,4
300.01118, 607.60000,     -0.44796,     -2.32029,50.00000,20.00000,6.809115e-08,0.78720,4
300.00635, 610.40000,     -0.44969,     -2.32471,50.00000,20.00000,6.812597e-08,0.78720,4
300.00848, 613.20000,     -0.45070,     -2.32777,50.00000,20.00000,6.820829e-08,0.78720,4
300.01347, 616.00000,     -0.44873,     -2.33218,50.00000,20.00000,6.803350e-08,0.78719,4
300.03021, 618.80000,     -0.45024,     -2.33530,50.00000,20.00000,6.809998e-08,0.78718,4
300.01697, 621.60000,     -0.45248,     -2.33763,50.00000,20.00000,6.805071e-08,0.78719,4
300.01948, 624.40000,     -0.45016,     -2.34225,50.00000,20.00000,6.803853e-08,0.78719,4
300.01201, 627.20000,     -0.45261,     -2.34666,50.00000,20.00000,6.799980e-08,0.78719,4
300.01060, 630.00000,     -0.44930,     -2.35051,50.00000,20.00000,6.807886e-08,0.78720,4
300.01055, 632.80000,     -0.45213,     -2.35561,50.00000,20.00000,6.798953e-08,0.78720,4
300.01960, 635.60000,     -0.45379,     -2.35857,50.00000,20.00000,6.812757e-08,0.78719,4
300.00960, 638.40000,     -0.45430,     -2.36115,50.00000,20.00000,6.807652e-08,0.78720,4
300.02237, 641.20000,     -0.45135,     -2.36454,50.00000,20.00000,6.816799e-08,0.78719,4
300.02023, 644.00000,     -0.45245,     -2.36867,50.00000,20.00000,6.815220e-08,0.78719,4
300.01510, 646.80000,     -0.45207,     -2.37166,50.00000,20.00000,6.798246e-08,0.78719,4
300.01956, 649.60000,     -0.45447,     -2.37645,50.00000,20.00000,6.795462e-08,0.78719,4
300.01687, 652.40000,     -0.45469,     -2.37892,50.00000,20.00000,6.794203e-08,0.78719,4
300.02619, 655.20000,     -0.45803,     -2.38263,50.00000,20.00000,6.805582e-08,0.78718,4
300.03071, 658.00000,     -0.45561,     -2.38504,50.00000,20.00000,6.802874e-08,0.78718,4
300.01098, 660.80000,     -0.45380,     -2.39010,50.00000,20.00000,6.802099e-08,0.78720,4
300.02288, 663.60000,     -0.45455,     -2.39347,50.00000,20.00000,6.802336e-08,0.78718,4
300.01943, 666.40000,     -0.45550,     -2.39622,50.00000,20.00000,6.815881e-08,0.78719,4
300.01280, 669.20000,     -0.45784,     -2.40130,50.00000,20.00000,6.805714e-08,0.78719,4
300.01719, 672.00000,     -0.45717,     -2.40394,50.00000,20.00000,6.804377e-08,0.78719,4
300.02673, 674.80000,     -0.45955,     -2.40809,50.00000,20.00000,6.802962e-08,0.78718,4
300.01509, 677.60000,     -0.45582,     -2.41111,50.00000,20.00000,6.806661e-08,0.78719,4
300.02582, 680.40000,     -0.45860,     -2.41458,50.00000,20.00000,6.803735e-08,0.78718,4
300.01483, 683.20000,     -0.45748,     -2.41862,50.00000,20.00000,6.794416e-08,0.78719,4
300.01944, 686.00000,     -0.45653,     -2.42200,50.00000,20.00000,6.798808e-08,0.78719,4
300.02605, 688.80000,     -0.46039,     -2.42316,50.00000,20.00000,6.795377e-08,0.78718,4
300.01113, 691.60000,     -0.46242,     -2.42777,50.00000,20.00000,6.794396e-08,0.78720,4
300.01389, 694.40000,     -0.45912,     -2.43108,50.00000,20.00000,6.802866e-08,0.78719,4
300.00935, 697.20000,     -0.46013,     -2.43388,50.00000,20.00000,6.798604e-08,0.78720,4
300.02319, 700.00000,     -0.45986,     -2.43681,50.00000,20.00000,6.797240e-08,0.78718,4
300.01420, 702.80000,     -0.46006,     -2.44099,50.00000,20.00000,6.796211e-08,0.78719,4
300.02115, 705.60000,     -0.46063,     -2.44374,50.00000,20.00000,6.806004e-08,0.78719,4
300.00698, 708.40000,     -0.46182,     -2.44712,50.00000,20.00000,6.803354e-08,0.78720,4
300.01018, 711.20000,     -0.46157,     -2.45119,50.00000,20.00000,6.796993e-08,0.78720,4
300.01698, 714.00000,     -0.46105,     -2.45357,50.00000,20.00000,6.795278e-08,0.78719,4
300.02691, 716.80000,     -0.46002,     -2.45732,50.00000,20.00000,6.793643e-08,0.78718,4
300.02173, 719.60000,     -0.46138,     -2.46168,50.00000,20.00000,6.791946e-08,0.78719,4
300.02149, 722.40000,     -0.46109,     -2.46446,50.00000,20.00000,6.794143e-08,0.78719,4
300.01121, 725.20000,     -0.46304,     -2.46714,50.00000,20.00000,6.789364e-08,0.78720,4
300.00425, 728.00000,     -0.46068,     -2.47218,50.00000,20.00000,6.793233e-08,0.78720,4
300.02158, 730.80000,     -0.46218,     -2.47461,50.00000,20.00000,6.794714e-08,0.78719,4
300.01629, 733.60000,     -0.46571,     -2.47655,50.00000,20.00000,6.786859e-08,0.78719,4
300.01161, 736.40000,     -0.46425,     -2.48072,50.00000,20.00000,6.789609e-08,0.78720,4
300.01969, 739.20000,     -0.46164,     -2.48411,50.00000,20.00000,6.789778e-08,0.78719,4
300.01648, 742.00000,     -0.46862,     -2.48853,50.00000,20.00000,6.785816e-08,0.78719,4
300.01455, 744.80000,     -0.46329,     -2.49055,50.00000,20.00000,6.778446e-08,0.78719,4
300.01563, 747.60000,     -0.46509,     -2.49395,50.00000,20.00000,6.781177e-08,0.78719,4
300.02377, 750.40000,     -0.46666,     -2.49814,50.00000,20.00000,6.784626e-08,0.78718,4
300.01309, 753.20000,     -0.46400,     -2.50028,50.00000,20.00000,6.792200e-08,0.78719,4
300.01689, 756.00000,     -0.46472,     -2.50334,50.00000,20.00000,6.782841e-08,0.78719,4
300.01090, 758.80000,     -0.46688,     -2.50606,50.00000,20.00000,6.787436e-08,0.78720,4
300.01067, 761.60000,     -0.46844,     -2.50945,50.00000,20.00000,6.786656e-08,0.78720,4
300.01756, 764.40000,     -0.46759,     -2.51182,50.00000,20.00000,6.787380e-08,0.78719,4
300.00956, 767.20000,     -0.46957,     -2.51623,50.00000,20.00000,6.788084e-08,0.78720,4
300.01920, 770.00000,     -0.46844,     -2.51819,50.00000,20.00000,6.781064e-08,0.78719,4
300.01539, 772.80000,     -0.46925,     -2.52133,50.00000,20.00000,6.788925e-08,0.78719,4
300.01569, 775.60000,     -0.46798,     -2.52268,50.00000,20.00000,6.788485e-08,0.78719,4
300.02305, 778.40000,     -0.46738,     -2.52778,50.00000,20.00000,6.788009e-08,0.78718,4
300.01815, 781.20000,     -0.46935,     -2.53004,50.00000,20.00000,6.781758e-08,0.78719,4
300.00732, 784.00000,     -0.47090,     -2.53321,50.00000,20.00000,6.785844e-08,0.78720,4
300.00308, 786.80000,     -0.47016,     -2.53763,50.00000,20.00000,6.780931e-08,0.78720,4
300.02291, 789.60000,     -0.47272,     -2.54000,50.00000,20.00000,6.777478e-08,0.78718,4
300.00433, 792.40000,     -0.47214,     -2.54447,50.00000,20.00000,6.781753e-08,0.78720,4
300.01269, 795.20000,     -0.47354,     -2.54654,50.00000,20.00000,6.780164e-08,0.78719,4
300.02319, 798.00000,     -0.46821,     -2.54950,50.00000,20.00000,6.781879e-08,0.78718,4
300.01172, 800.80000,     -0.47514,     -2.55391,50.00000,20.00000,6.773568e-08,0.78720,4
300.01190, 803.60000,     -0.47477,     -2.55731,50.00000,20.00000,6.786670e-08,0.78719,4
300.02443, 806.40000,     -0.47329,     -2.55786,50.00000,20.00000,6.774832e-08,0.78718,4
300.02593, 809.20000,     -0.47331,     -2.56274,50.00000,20.00000,6.771797e-08,0.78718,4
300.01439, 812.00000,     -0.47388,     -2.56511,50.00000,20.00000,6.771907e-08,0.78719,4
300.01021, 814.80000,     -0.47374,     -2.56845,50.00000,20.00000,6.779186e-08,0.78720,4
300.02514, 817.60000,     -0.47485,     -2.57190,50.00000,20.00000,6.771993e-08,0.78718,4
300.02835, 820.40000,     -0.47868,     -2.57529,50.00000,20.00000,6.779272e-08,0.78718,4
300.01341, 823.20000,     -0.47838,     -2.57796,50.00000,20.00000,6.773808e-08,0.78719,4
300.01503, 826.00000,     -0.47956,     -2.58072,50.00000,20.00000,6.764541e-08,0.78719,4
300.02232, 828.80000,     -0.47379,     -2.58276,50.00000,20.00000,6.764078e-08,0.78719,4
300.01662, 831.60000,     -0.47647,     -2.58729,50.00000,20.00000,6.775274e-08,0.78719,4
300.01258, 834.40000,     -0.47617,     -2.58880,50.00000,20.00000,6.765579e-08,0.78719,4
300.01698, 837.20000,     -0.47663,     -2.59295,50.00000,20.00000,6.782484e-08,0.78719,4
300.00937, 840.00000,     -0.47907,     -2.59634,50.00000,20.00000,6.764440e-08,0.78720,4
300.02125, 842.80000,     -0.47755,     -2.59803,50.00000,20.00000,6.768571e-08,0.78719,4
300.02703, 845.60000,     -0.47692,     -2.60075,50.00000,20.00000,6.763713e-08,0.78718,4
300.01718, 848.40000,     -0.47759,     -2.60482,50.00000,20.00000,6.769104e-08,0.78719,4
300.00710, 851.20000,     -0.47609,     -2.60641,50.00000,20.00000,6.773037e-08,0.78720,4
300.01001, 854.00000,     -0.47840,     -2.60912,50.00000,20.00000,6.770160e-08,0.78720,4
300.01792, 856.80000,     -0.47846,     -2.61184,50.00000,20.00000,6.769201e-08,0.78719,4
300.01504, 859.60000,     -0.48124,     -2.61540,50.00000,20.00000,6.769908e-08,0.78719,4
300.01427, 862.40000,     -0.48200,     -2.61828,50.00000,20.00000,6.760961e-08,0.78719,4
300.02619, 865.20000,     -0.48164,     -2.62169,50.00000,20.00000,6.772820e-08,0.78718,4
300.02189, 868.00000,     -0.48388,     -2.62304,50.00000,20.00000,6.764449e-08,0.78719,4
300.01086, 870.80000,     -0.48201,     -2.62486,50.00000,20.00000,6.767770e-08,0.78720,4
300.01771, 873.60000,     -0.48307,     -2.62721,50.00000,20.00000,6.765873e-08,0.78719,4
300.01928, 876.40000,     -0.48157,     -2.63095,50.00000,20.00000,6.759081e-08,0.78719,4
300.01031, 879.20000,     -0.48323,     -2.63381,50.00000,20.00000,6.750160e-08,0.78720,4
300.01037, 882.00000,     -0.47933,     -2.63707,50.00000,20.00000,6.759711e-08,0.78720,4
300.01283, 884.80000,     -0.48358,     -2.63876,50.00000,20.00000,6.766125e-08,0.78719,4
300.01224, 887.60000,     -0.48712,     -2.64283,50.00000,20.00000,6.761081e-08,0.78719,4
300.02208, 890.40000,     -0.48717,     -2.64657,50.00000,20.00000,6.760589e-08,0.78719,4
300.00041, 893.20000,     -0.48449,     -2.64913,50.00000,20.00000,6.759879e-08,0.78721,4
300.01320, 896.00000,     -0.48397,     -2.65157,50.00000,20.00000,6.755274e-08,0.78719,4
300.01067, 898.80000,     -0.48570,     -2.65487,50.00000,20.00000,6.766577e-08,0.78720,4
300.00488, 901.60000,     -0.48932,     -2.65795,50.00000,20.00000,6.756889e-08,0.78720,4
300.01661, 904.40000,     -0.48523,     -2.65892,50.00000,20.00000,6.766745e-08,0.78719,4
300.01453, 907.20000,     -0.48814,     -2.66412,50.00000,20.00000,6.760141e-08,0.78719,4
300.02914, 910.00000,     -0.49021,     -2.66511,50.00000,20.00000,6.758108e-08,0.78718,4
300.02127, 912.80000,     -0.49228,     -2.66823,50.00000,20.00000,6.760513e-08,0.78719,4
300.01488, 915.60000,     -0.49035,     -2.67181,50.00000,20.00000,6.756865e-08,0.78719,4
300.00998, 918.40000,     -0.49305,     -2.67338,50.00000,20.00000,6.748637e-08,0.78720,4
300.01541, 921.20000,     -0.49043,     -2.67736,50.00000,20.00000,6.746233e-08,0.78719,4
300.02335, 924.00000,     -0.49116,     -2.67722,50.00000,20.00000,6.758368e-08,0.78718,4
300.01904, 926.80000,     -0.49304,     -2.67984,50.00000,20.00000,6.753143e-08,0.78719,4
300.02275, 929.60000,     -0.49070,     -2.68232,50.00000,20.00000,6.754825e-08,0.78718,4
300.02056, 932.40000,     -0.49304,     -2.68606,50.00000,20.00000,6.751484e-08,0.78719,4
300.01569, 935.20000,     -0.49076,     -2.68778,50.00000,20.00000,6.749928e-08,0.78719,4
300.01755, 938.00000,     -0.49316,     -2.69216,50.00000,20.00000,6.745057e-08,0.78719,4
300.01798, 940.80000,     -0.49252,     -2.69432,50.00000,20.00000,6.748981e-08,0.78719,4
300.01825, 943.60000,     -0.49562,     -2.69645,50.00000,20.00000,6.752097e-08,0.78719,4
300.02509, 946.40000,     -0.49393,     -2.70008,50.00000,20.00000,6.749305e-08,0.78718,4
300.01127, 949.20000,     -0.49496,     -2.70249,50.00000,20.00000,6.752388e-08,0.78720,4
300.01378, 952.00000,     -0.49632,     -2.70483,50.00000,20.00000,6.758805e-08,0.78719,4
300.02179, 954.80000,     -0.49658,     -2.70757,50.00000,20.00000,6.746197e-08,0.78719,4
300.01748, 957.60000,     -0.49542,     -2.71024,50.00000,20.00000,6.748403e-08,0.78719,4
300.01900, 960.40000,     -0.49677,     -2.71452,50.00000,20.00000,6.745951e-08,0.78719,4
300.01920, 963.20000,     -0.49723,     -2.71490,50.00000,20.00000,6.745676e-08,0.78719,4
300.02076, 966.00000,     -0.49542,     -2.71785,50.00000,20.00000,6.743624e-08,0.78719,4
300.00477, 968.80000,     -0.50022,     -2.72202,50.00000,20.00000,6.738751e-08,0.78720,4
300.00533, 971.60000,     -0.49757,     -2.72394,50.00000,20.00000,6.738478e-08,0.78720,4
300.02024, 974.40000,     -0.49826,     -2.72644,50.00000,20.00000,6.738112e-08,0.78719,4
300.01465, 977.20000,     -0.50161,     -2.72997,50.00000,20.00000,6.744073e-08,0.78719,4
299.99979, 980.00000,     -0.50371,     -2.73088,50.00000,20.00000,6.742639e-08,0.78721,4
300.02036, 982.80000,     -0.50175,     -2.73232,50.00000,20.00000,6.742435e-08,0.78719,4
300.01624, 985.60000,     -0.49790,     -2.73571,50.00000,20.00000,6.742099e-08,0.78719,4
300.01616, 988.40000,     -0.50145,     -2.73809,50.00000,20.00000,6.734829e-08,0.78719,4
300.01822, 991.20000,     -0.50438,     -2.73898,50.00000,20.00000,6.738644e-08,0.78719,4
300.01503, 994.00000,     -0.50391,     -2.74402,50.00000,20.00000,6.735098e-08,0.78719,4
300.01135, 996.80000,     -0.50457,     -2.74534,50.00000,20.00000,6.732280e-08,0.78720,4
300.02205, 999.60000,     -0.50258,     -2.74800,50.00000,20.00000,6.734929e-08,0.78719,4
300.01661,1002.40000,     -0.50543,     -2.75246,50.00000,20.00000,6.738322e-08,0.78719,4
300.01557,1005.20000,     -0.50470,     -2.75385,50.00000,20.00000,6.733895e-08,0.78719,4
300.01187,1008.00000,     -0.50494,     -2.75708,50.00000,20.00000,6.736121e-08,0.78719,4
300.00873,1010.80000,     -0.50651,     -2.75920,50.00000,20.00000,6.732452e-08,0.78720,4
300.00852,1013.60000,     -0.50654,     -2.76139,50.00000,20.00000,6.735739e-08,0.78720,4
300.01687,1016.40000,     -0.50469,     -2.76309,50.00000,20.00000,6.726551e-08,0.78719,4
300.02841,1019.20000,     -0.50651,     -2.76750,50.00000,20.00000,6.724008e-08,0.78718,4
300.01558,1022.00000,     -0.50965,     -2.76761,50.00000,20.00000,6.734305e-08,0.78719,4
300.02480,1024.80000,     -0.50633,     -2.77093,50.00000,20.00000,6.728303e-08,0.78718,4
300.02706,1027.60000,     -0.50482,     -2.77418,50.00000,20.00000,6.730082e-08,0.78718,4
300.03513,1030.40000,     -0.50628,     -2.77734,50.00000,20.00000,6.730699e-08,0.78717,4
300.02337,1033.20000,     -0.50959,     -2.77814,50.00000,20.00000,6.727487e-08,0.78718,4
300.01834,1036.00000,     -0.50772,     -2.78115,50.00000,20.00000,6.730439e-08,0.78719,4
300.01677,1038.80000,     -0.51034,     -2.78250,50.00000,20.00000,6.728730e-08,0.78719,4
300.01228,1041.60000,     -0.50876,     -2.78450,50.00000,20.00000,6.742796e-08,0.78719,4
300.02175,1044.40000,     -0.51062,     -2.78620,50.00000,20.00000,6.730430e-08,0.78719,4
300.01982,1047.20000,     -0.51117,     -2.78911,50.00000,20.00000,6.741222e-08,0.78719,4
300.01294,1050.00000,     -0.51106,     -2.79013,50.00000,20.00000,6.737196e-08,0.78719,4
300.01871,1052.80000,     -0.50891,     -2.79477,50.00000,20.00000,6.741106e-08,0.78719,4
300.01593,1055.60000,     -0.50958,     -2.79692,50.00000,20.00000,6.731921e-08,0.78719,4
300.02304,1058.40000,     -0.51307,     -2.79895,50.00000,20.00000,6.735291e-08,0.78718,4
300.00817,1061.20000,     -0.51238,     -2.80086,50.00000,20.00000,6.735543e-08,0.78720,4
300.01393,1064.00000,     -0.51233,     -2.80268,50.00000,20.00000,6.727888e-08,0.78719,4
300.01114,1066.80000,     -0.51180,     -2.80472,50.00000,20.00000,6.727317e-08,0.78720,4
300.01321,1069.60000,     -0.46713,     -2.80868,50.00000,20.00000,6.727012e-08,0.78719,4
300.02095,1072.40000,     -0.46731,     -2.81083,50.00000,20.00000,6.727646e-08,0.78719,4
300.02064,1075.20000,     -0.47123,     -2.81311,50.00000,20.00000,6.729416e-08,0.78719,4
300.01383,1078.00000,     -0.46968,     -2.81719,50.00000,20.00000,6.731671e-08,0.78719,4
300.01435,1080.80000,     -0.46835,     -2.82045,50.00000,20.00000,6.727641e-08,0.78719,4
300.00374,1083.60000,     -0.47091,     -2.82322,50.00000,20.00000,6.723389e-08,0.78720,4
300.01648,1086.40000,     -0.46925,     -2.82441,50.00000,20.00000,6.720388e-08,0.78719,4
300.02008,1089.20000,     -0.46947,     -2.82648,50.00000,20.00000,6.727308e-08,0.78719,4
300.00946,1092.00000,     -0.47070,     -2.83066,50.00000,20.00000,6.727720e-08,0.78720,4
300.02303,1094.80000,     -0.47296,     -2.83288,50.00000,20.00000,6.720413e-08,0.78718,4
300.00571,1097.60000,     -0.46855,     -2.83414,50.00000,20.00000,6.727688e-08,0.78720,4
300.02382,1100.40000,     -0.47145,     -2.83678,50.00000,20.00000,6.722739e-08,0.78718,4
300.01272,1103.20000,     -0.47110,     -2.83877,50.00000,20.00000,6.716484e-08,0.78719,4
300.01137,1106.00000,     -0.47333,     -2.84119,50.00000,20.00000,6.720298e-08,0.78720,4
300.01604,1108.80000,     -0.47408,     -2.84476,50.00000,20.00000,6.719696e-08,0.78719,4
300.02180,1111.60000,     -0.47459,     -2.84865,50.00000,20.00000,6.725096e-08,0.78719,4
300.00319,1114.40000,     -0.47311,     -2.84726,50.00000,20.00000,6.714497e-08,0.78720,4
300.00669,1117.20000,     -0.47252,     -2.84999,50.00000,20.00000,6.714334e-08,0.78720,4
300.02411,1120.00000,     -0.47088,     -2.84973,50.00000,20.00000,6.719027e-08,0.78718,4
300.02176,1122.80000,     -0.47339,     -2.85280,50.00000,20.00000,6.725825e-08,0.78719,4
300.02105,1125.60000,     -0.47243,     -2.85721,50.00000,20.00000,6.721976e-08,0.78719,4
300.00870,1128.40000,     -0.47420,     -2.86038,50.00000,20.00000,6.717886e-08,0.78720,4
300.01889,1131.20000,     -0.47297,     -2.86130,50.00000,20.00000,6.715279e-08,0.78719,4
300.01772,1134.00000,     -0.47529,     -2.86264,50.00000,20.00000,6.718109e-08,0.78719,4
300.02126,1136.80000,     -0.47337,     -2.86490,50.00000,20.00000,6.717465e-08,0.78719,4
300.01909,1139.60000,     -0.47289,     -2.86728,50.00000,20.00000,6.726957e-08,0.78719,4
300.01860,1142.40000,     -0.47421,     -2.86830,50.00000,20.00000,6.719429e-08,0.78719,4
300.01214,1145.20000,     -0.47497,     -2.87044,50.00000,20.00000,6.723628e-08,0.78719,4
300.02916,1148.00000,     -0.47695,     -2.87339,50.00000,20.00000,6.717997e-08,0.78718,4
300.00990,1150.80000,     -0.47720,     -2.87595,50.00000,20.00000,6.721253e-08,0.78720,4
300.01768,1153.60000,     -0.47300,     -2.87871,50.00000,20.00000,6.724290e-08,0.78719,4
300.00985,1156.40000,     -0.47649,     -2.88007,50.00000,20.00000,6.717467e-08,0.78720,4
300.02850,1159.20000,     -0.47717,     -2.88203,50.00000,20.00000,6.710950e-08,0.78718,4
300.02623,1162.00000,     -0.47220,     -2.88425,50.00000,20.00000,6.716142e-08,0.78718,4
300.02041,1164.80000,     -0.47535,     -2.88742,50.00000,20.00000,6.716286e-08,0.78719,4
300.01311,1167.60000,     -0.47620,     -2.88843,50.00000,20.00000,6.723150e-08,0.78719,4
300.02012,1170.40000,     -0.47450,     -2.89093,50.00000,20.00000,6.708898e-08,0.78719,4
300.00481,1173.20000,     -0.47944,     -2.89319,50.00000,20.00000,6.719964e-08,0.78720,4
300.01916,1176.00000,     -0.47917,     -2.89637,50.00000,20.00000,6.717581e-08,0.78719,4
300.01525,1178.80000,     -0.47730,     -2.89930,50.00000,20.00000,6.714053e-08,0.78719,4
300.03144,1181.60000,     -0.47798,     -2.90100,50.00000,20.00000,6.714266e-08,0.78718,4
300.02734,1184.40000,     -0.47949,     -2.90292,50.00000,20.00000,6.714457e-08,0.78718,4
300.00992,1187.20000,     -0.48015,     -2.90503,50.00000,20.00000,6.709025e-08,0.78720,4
300.01187,1190.00000,     -0.48053,     -2.90729,50.00000,20.00000,6.716314e-08,0.78719,4
300.01554,1192.80000,     -0.47985,     -2.91073,50.00000,20.00000,6.700340e-08,0.78719,4
300.01900,1195.60000,     -0.47858,     -2.91390,50.00000,20.00000,6.708087e-08,0.78719,4
300.01031,1198.40000,     -0.48146,     -2.91367,50.00000,20.00000,6.709190e-08,0.78720,4
300.01296,1201.20000,     -0.47954,     -2.91502,50.00000,20.00000,6.710370e-08,0.78719,4
300.01661,1204.00000,     -0.47957,     -2.91683,50.00000,20.00000,6.703194e-08,0.78719,4
300.01367,1206.80000,     -0.48311,     -2.92067,50.00000,20.00000,6.713018e-08,0.78719,4
300.02858,1209.60000,     -0.48200,     -2.92087,50.00000,20.00000,6.700209e-08,0.78718,4
300.00987,1212.40000,     -0.48350,     -2.92453,50.00000,20.00000,6.711969e-08,0.78720,4
300.01615,1215.20000,     -0.48457,     -2.92690,50.00000,20.00000,6.708706e-08,0.78719,4
300.01599,1218.00000,     -0.47925,     -2.92849,50.00000,20.00000,6.704290e-08,0.78719,4
300.01689,1220.80000,     -0.48160,     -2.93049,50.00000,20.00000,6.710286e-08,0.78719,4
300.01716,1223.60000,     -0.48150,     -2.93179,50.00000,20.00000,6.698332e-08,0.78719,4
300.00822,1226.40000,     -0.48233,     -2.93455,50.00000,20.00000,6.708154e-08,0.78720,4
300.00727,1229.20000,     -0.48292,     -2.93637,50.00000,20.00000,6.700543e-08,0.78720,4
300.00641,1232.00000,     -0.48414,     -2.94024,50.00000,20.00000,6.706618e-08,0.78720,4
300.01334,1234.80000,     -0.48419,     -2.94162,50.00000,20.00000,6.705216e-08,0.78719,4
300.02153,1237.60000,     -0.48054,     -2.94431,50.00000,20.00000,6.697169e-08,0.78719,4
300.02256,1240.40000,     -0.48511,     -2.94579,50.00000,20.00000,6.705418e-08,0.78718,4
300.01531,1243.20000,     -0.48618,     -2.94885,50.00000,20.00000,6.704879e-08,0.78719,4
300.02623,1246.00000,     -0.48629,     -2.95220,50.00000,20.00000,6.696915e-08,0.78718,4
300.01901,1248.80000,     -0.48799,     -2.95394,50.00000,20.00000,6.699698e-08,0.78719,4
300.00863,1251.60000,     -0.48495,     -2.95696,50.00000,20.00000,6.697544e-08,0.78720,4
299.99996,1254.40000,     -0.48553,     -2.95767,50.00000,20.00000,6.696676e-08,0.78721,4
300.02088,1257.20000,     -0.48699,     -2.96013,50.00000,20.00000,6.703084e-08,0.78719,4
300.01546,1260.00000,     -0.48971,     -2.96142,50.00000,20.00000,6.703258e-08,0.78719,4
300.01412,1262.80000,     -0.48671,     -2.96275,50.00000,20.00000,6.693172e-08,0.78719,4
300.02413,1265.60000,     -0.48963,     -2.96579,50.00000,20.00000,6.690918e-08,0.78718,4
300.02359,1268.40000,     -0.48729,     -2.96732,50.00000,20.00000,6.691743e-08,0.78718,4
300.01632,1271.20000,     -0.48929,     -2.96876,50.00000,20.00000,6.705070e-08,0.78719,4
300.02429,1274.00000,     -0.49017,     -2.97046,50.00000,20.00000,6.692891e-08,0.78718,4
300.01580,1276.80000,     -0.48679,     -2.97478,50.00000,20.00000,6.693473e-08,0.78719,4
300.00148,1279.60000,     -0.48930,     -2.97626,50.00000,20.00000,6.695763e-08,0.78720,4
300.00870,1282.40000,     -0.49275,     -2.97666,50.00000,20.00000,6.696911e-08,0.78720,4
300.02211,1285.20000,     -0.48973,     -2.97952,50.00000,20.00000,6.701772e-08,0.78719,4
300.02309,1288.00000,     -0.48960,     -2.98087,50.00000,20.00000,6.685212e-08,0.78718,4
300.01509,1290.80000,     -0.49405,     -2.98221,50.00000,20.00000,6.694117e-08,0.78719,4
300.01408,1293.60000,     -0.49219,     -2.98618,50.00000,20.00000,6.695755e-08,0.78719,4
300.01897,1296.40000,     -0.49196,     -2.98788,50.00000,20.00000,6.695788e-08,0.78719,4
300.01088,1299.20000,     -0.49162,     -2.99037,50.00000,20.00000,6.691454e-08,0.78720,4
300.01736,1302.00000,     -0.49035,     -2.99158,50.00000,20.00000,6.682223e-08,0.78719,4
300.02110,1304.80000,     -0.48892,     -2.99411,50.00000,20.00000,6.686162e-08,0.78719,4
300.01136,1307.60000,     -0.49496,     -2.99531,50.00000,20.00000,6.691218e-08,0.78720,4
300.01477,1310.40000,     -0.49843,     -2.99647,50.00000,20.00000,6.692851e-08,0.78719,4
300.01713,1313.20000,     -0.49293,     -2.99936,50.00000,20.00000,6.686040e-08,0.78719,4
300.01834,1316.00000,     -0.49476,     -3.00029,50.00000,20.00000,6.678304e-08,0.78719,4
300.01889,1318.80000,     -0.49593,     -3.00304,50.00000,20.00000,6.682814e-08,0.78719,4
300.00404,1321.60000,     -0.49669,     -3.00677,50.00000,20.00000,6.699315e-08,0.78720,4
300.01301,1324.40000,     -0.49603,     -3.00744,50.00000,20.00000,6.680231e-08,0.78719,4
300.01240,1327.20000,     -0.49570,     -3.01017,50.00000,20.00000,6.692466e-08,0.78719,4
300.01517,1330.00000,     -0.49511,     -3.01157,50.00000,20.00000,6.686226e-08,0.78719,4
300.02141,1332.80000,     -0.49578,     -3.01493,50.00000,20.00000,6.678246e-08,0.78719,4
300.02098,1335.60000,     -0.49642,     -3.01641,50.00000,20.00000,6.681140e-08,0.78719,4
300.02146,1338.40000,     -0.49781,     -3.01526,50.00000,20.00000,6.687455e-08,0.78719,4
300.01634,1341.20000,     -0.49782,     -3.01944,50.00000,20.00000,6.680807e-08,0.78719,4
300.01328,1344.00000,     -0.49800,     -3.02080,50.00000,20.00000,6.676361e-08,0.78719,4
300.02354,1346.80000,     -0.49552,     -3.02472,50.00000,20.00000,6.678332e-08,0.78718,4
300.01246,1349.60000,     -0.49716,     -3.02522,50.00000,20.00000,6.678007e-08,0.78719,4
300.01365,1352.40000,     -0.49932,     -3.02827,50.00000,20.00000,6.678835e-08,0.78719,4
300.00384,1355.20000,     -0.50103,     -3.02935,50.00000,20.00000,6.686209e-08,0.78720,4
300.01483,1358.00000,     -0.49960,     -3.03056,50.00000,20.00000,6.681429e-08,0.78719,4
300.01900,1360.80000,     -0.50111,     -3.03333,50.00000,20.00000,6.687577e-08,0.78719,4
300.02038,1363.60000,     -0.50055,     -3.03438,50.00000,20.00000,6.670074e-08,0.78719,4
300.00509,1366.40000,     -0.50053,     -3.03709,50.00000,20.00000,6.677899e-08,0.78720,4
300.02397,1369.20000,     -0.50140,     -3.03969,50.00000,20.00000,6.677630e-08,0.78718,4
300.01900,1372.00000,     -0.50179,     -3.04115,50.00000,20.00000,6.679646e-08,0.78719,4
300.01515,1374.80000,     -0.50059,     -3.04490,50.00000,20.00000,6.672501e-08,0.78719,4
300.00838,1377.60000,     -0.50290,     -3.04680,50.00000,20.00000,6.672502e-08,0.78720,4
300.01318,1380.40000,     -0.50132,     -3.04920,50.00000,20.00000,6.674646e-08,0.78719,4
300.01358,1383.20000,     -0.50004,     -3.04998,50.00000,20.00000,6.675321e-08,0.78719,4
300.01477,1386.00000,     -0.50237,     -3.05208,50.00000,20.00000,6.683787e-08,0.78719,4
300.01739,1388.80000,     -0.50333,     -3.05451,50.00000,20.00000,6.671643e-08,0.78719,4
300.02201,1391.60000,     -0.50384,     -3.05622,50.00000,20.00000,6.659427e-08,0.78719,4
300.01264,1394.40000,     -0.49667,     -3.05779,50.00000,20.00000,6.667695e-08,0.78719,4
300.01090,1397.20000,     -0.49897,     -3.05987,50.00000,20.00000,6.667063e-08,0.78720,4
300.03151,1400.00000,     -0.49738,     -3.06099,50.00000,20.00000,6.663822e-08,0.78718,4
300.01884,1402.80000,     -0.49857,     -3.06273,50.00000,20.00000,6.670907e-08,0.78719,4
300.01093,1405.60000,     -0.49904,     -3.06583,50.00000,20.00000,6.666250e-08,0.78720,4
300.01343,1408.40000,     -0.49816,     -3.06820,50.00000,20.00000,6.667146e-08,0.78719,4
300.01943,1411.20000,     -0.49786,     -3.06955,50.00000,20.00000,6.662525e-08,0.78719,4
300.01767,1414.00000,     -0.49926,     -3.07024,50.00000,20.00000,6.665426e-08,0.78719,4
300.01567,1416.80000,     -0.49946,     -3.07281,50.00000,20.00000,6.674145e-08,0.78719,4
300.01439,1419.60000,     -0.50027,     -3.07510,50.00000,20.00000,6.672233e-08,0.78719,4
300.01756,1422.40000,     -0.49987,     -3.07584,50.00000,20.00000,6.663735e-08,0.78719,4
300.01990,1425.20000,     -0.50058,     -3.07816,50.00000,20.00000,6.665827e-08,0.78719,4
300.01946,1428.00000,     -0.50237,     -3.07945,50.00000,20.00000,6.657946e-08,0.78719,4
300.01583,1430.80000,     -0.49991,     -3.08122,50.00000,20.00000,6.668468e-08,0.78719,4
300.02369,1433.60000,     -0.50233,     -3.08332,50.00000,20.00000,6.662866e-08,0.78718,4
300.02413,1436.40000,     -0.50453,     -3.08562,50.00000,20.00000,6.670270e-08,0.78718,4
300.01363,1439.20000,     -0.50438,     -3.08816,50.00000,20.00000,6.670553e-08,0.78719,4
299.99433,1442.00000,     -0.50061,     -3.08958,50.00000,20.00000,6.659411e-08,0.78721,4
300.01494,1444.80000,     -0.50410,     -3.09105,50.00000,20.00000,6.675316e-08,0.78719,4
300.02226,1447.60000,     -0.49895,     -3.09241,50.00000,20.00000,6.665431e-08,0.78719,4
300.01227,1450.40000,     -0.50497,     -3.09479,50.00000,20.00000,6.653024e-08,0.78719,4
300.01871,1453.20000,     -0.50609,     -3.09615,50.00000,20.00000,6.662165e-08,0.78719,4
300.01276,1456.00000,     -0.50333,     -3.09812,50.00000,20.00000,6.665773e-08,0.78719,4
300.01458,1458.80000,     -0.50334,     -3.09990,50.00000,20.00000,6.666641e-08,0.78719,4
300.01548,1461.60000,     -0.50524,     -3.10178,50.00000,20.00000,6.667088e-08,0.78719,4
300.01607,1464.40000,     -0.50421,     -3.10219,50.00000,20.00000,6.660706e-08,0.78719,4
300.01313,1467.20000,     -0.50612,     -3.10429,50.00000,20.00000,6.650030e-08,0.78719,4
300.02244,1470.00000,     -0.50564,     -3.10836,50.00000,20.00000,6.654526e-08,0.78719,4
300.01697,1472.80000,     -0.50733,     -3.10723,50.00000,20.00000,6.665325e-08,0.78719,4
300.01893,1475.60000,     -0.50743,     -3.11166,50.00000,20.00000,6.666743e-08,0.78719,4
300.01472,1478.40000,     -0.50850,     -3.11334,50.00000,20.00000,6.653251e-08,0.78719,4
300.01754,1481.20000,     -0.50656,     -3.11390,50.00000,20.00000,6.662707e-08,0.78719,4
300.01668,1484.00000,     -0.50947,     -3.11595,50.00000,20.00000,6.659942e-08,0.78719,4
300.01729,1486.80000,     -0.50874,     -3.11565,50.00000,20.00000,6.656183e-08,0.78719,4
300.02466,1489.60000,     -0.49578,     -3.12088,50.00000,20.00000,6.661940e-08,0.78718,4
300.03243,1492.40000,     -0.49605,     -3.12092,50.00000,20.00000,6.662765e-08,0.78718,4
300.00852,1495.20000,     -0.49361,     -3.12228,50.00000,20.00000,6.658926e-08,0.78720,4
304.56980,1498.00000,      2.17516,     -3.09128,50.00000,20.00000,6.656558e-08,0.78294,5
330.26552,1500.80000,      3.92872,     -3.05160,50.00000,20.00000,6.652869e-08,0.75864,5
360.20126,1503.60000,      4.09342,     -3.03400,50.00000,20.00000,6.676272e-08,0.73008,5
389.81842,1506.40000,      4.04752,     -3.15027,50.00000,20.00000,6.704652e-08,0.70206,5
418.58948,1509.20000,      3.80800,     -3.84587,50.00000,20.00000,6.761379e-08,0.67549,5
446.89741,1512.00000,      1.38157,     -4.80020,50.00000,20.00000,6.818906e-08,0.65030,5
475.00331,1514.80000,      0.23092,     -4.97271,50.00000,20.00000,6.884540e-08,0.62649,5
502.93045,1517.60000,     -0.77183,     -4.95282,50.00000,20.00000,6.952583e-08,0.60418,5
530.86320,1520.40000,     -1.87586,     -4.93455,50.00000,20.00000,7.020718e-08,0.58333,5
558.78201,1523.20000,     -3.12172,     -4.91962,50.00000,20.00000,7.094506e-08,0.56398,5
586.77549,1526.00000,     -4.45211,     -4.90596,50.00000,20.00000,7.160448e-08,0.54607,5
614.78692,1528.80000,     -5.83597,     -4.89522,50.00000,20.00000,7.232067e-08,0.52957,5
642.81185,1531.60000,     -7.27819,     -4.88638,50.00000,20.00000,7.280319e-08,0.51436,5
670.82470,1534.40000,     -8.70555,     -4.87528,50.00000,20.00000,7.330022e-08,0.50031,5
698.89115,1537.20000,    -10.05329,     -4.86817,50.00000,20.00000,7.396164e-08,0.48721,5
726.97713,1540.00000,    -11.30891,     -4.86329,50.00000,20.00000,7.446796e-08,0.47486,5
755.03295,1542.80000,    -12.52011,     -4.85640,50.00000,20.00000,7.483207e-08,0.46310,5
783.08601,1545.60000,    -13.68196,     -4.85098,50.00000,20.00000,7.515351e-08,0.45168,5
796.10638,1546.90000,    -14.20025,     -4.84720,50.00000,20.00000,7.525220e-08,0.44645,5