File: data/TGA/005c/ExpDat_2024_06_24_005c-B_dynamic-slow.csv
#EXPORTTYPE:                 ,DATA ALL
#FILE:                       ,2024_06_24_005c-B_dynamic-slow.ngb-ss5
#FORMAT:                     ,NETZSCH5
#FTYPE:                      ,ASCII
#IDENTITY:                   ,PS-SCF3
#DECIMAL:                    ,POINT
#SEPARATOR:                  ,COMMA
#MTYPE:                      ,DSC
#INSTRUMENT:                 ,NETZSCH STA 449F5
#PROJECT:                    ,
#DATE/TIME:                  ,6/24/2024 8:29:57 PM (UTC-4)
#CORR. FILE:                 ,
#TEMPCAL:                    ,28-06-2023 13:26
#SENSITIVITY:                ,28-06-2023 13:53
#LABORATORY:                 ,
#OPERATOR:                   ,Stanley
#REMARK:                     ,
#SAMPLE:                     ,005c-B-2
#SAMPLE MASS /mg:            ,5.0
#MATERIAL:                   ,
#REFERENCE:                  ,-----
#REFERENCE MASS /mg:         ,0
#TYPE OF CRUCIBLE:           ,Al2O3 85 ‘l, open
#SAMPLE CRUCIBLE MASS /mg:   ,0
#REFERENCE CRUCIBLE MASS /mg:,0
#DSC RANGE /‘V:              ,5000
#TG RANGE /mg:               ,35000
#TAU-R:                      ,---
#CORR. CODE:                 ,000
#EXO:                        ,-1
#RANGE:                      ,20›C....800›C/0.0....5.0K/min
#SEGMENT:                    ,S1-5/5
#SEG. 1:                     ,20›C/5.0(K/min)/100›C
#SEG. 2:                     ,100›C/00:05/100›C
#SEG. 3:                     ,100›C/2.0(K/min)/225›C
#SEG. 4:                     ,225›C/0.1(K/min)/350›C
#SEG. 5:                     ,350›C/5.0(K/min)/800›C

##Temp./›C,Time/min,DSC/(mW/mg),Mass loss/mg,Gas Flow(purge2)/(ml/min),Gas Flow(protective)/(ml/min),TIC(scan:1)/A,Sensit./(uV/mW),Segment
 32.13600,   0.00000,-5.301319e-02, 0.000000e+00,50.00000,20.00000,5.872216e-08,0.92393,1
 33.20200,   2.60000, 5.069127e-02, 3.201000e-02,50.00000,20.00000,5.857850e-08,0.92411,1
 37.76300,   5.20000,      0.39566,      0.13677,50.00000,20.00000,5.805826e-08,0.92480,1
 48.68200,   7.80000,      0.84791,      0.25567,50.00000,20.00000,5.793119e-08,0.92588,1
 63.78000,  10.40000,      1.16271,      0.33113,50.00000,20.00000,5.757226e-08,0.92612,1
 80.02500,  13.00000,      1.30230,      0.37118,50.00000,20.00000,5.752422e-08,0.92481,1
 95.72600,  15.60000,      1.34743,      0.39312,50.00000,20.00000,5.761809e-08,0.92203,1
105.92503,  18.20000,      0.54508,      0.32650,50.00000,20.00000,5.780036e-08,0.91947,2
108.10890,  20.80000, 3.273963e-02,      0.26690,50.00000,20.00000,5.770153e-08,0.91884,2
108.25640,  23.40000, 8.970952e-02,      0.26290,50.00000,20.00000,5.770901e-08,0.91880,3
110.20517,  26.00000,      0.26298,      0.27857,50.00000,20.00000,5.778922e-08,0.91822,3
114.06126,  28.60000,      0.42157,      0.29647,50.00000,20.00000,5.766463e-08,0.91701,3
119.07676,  31.20000,      0.51244,      0.30751,50.00000,20.00000,5.746304e-08,0.91531,3
124.53097,  33.80000,      0.55054,      0.31766,50.00000,20.00000,5.743998e-08,0.91331,3
130.05506,  36.40000,      0.55687,      0.32445,50.00000,20.00000,5.742331e-08,0.91114,3
135.47479,  39.00000,      0.55261,      0.32913,50.00000,20.00000,5.749438e-08,0.90885,3
140.80097,  41.60000,      0.54680,      0.33498,50.00000,20.00000,5.770039e-08,0.90646,3
146.05984,  44.20000,      0.54222,      0.33784,50.00000,20.00000,5.768166e-08,0.90396,3
151.28435,  46.80000,      0.54204,      0.34416,50.00000,20.00000,5.770671e-08,0.90135,3
156.48278,  49.40000,      0.54024,      0.34866,50.00000,20.00000,5.787722e-08,0.89863,3
161.67849,  52.00000,      0.53451,      0.35398,50.00000,20.00000,5.788704e-08,0.89578,3
166.87510,  54.60000,      0.52683,      0.35657,50.00000,20.00000,5.810107e-08,0.89282,3
172.08420,  57.20000,      0.52056,      0.36194,50.00000,20.00000,5.812253e-08,0.88974,3
177.28052,  59.80000,      0.50980,      0.36608,50.00000,20.00000,5.844383e-08,0.88655,3
182.47762,  62.40000,      0.49407,      0.36792,50.00000,20.00000,5.848138e-08,0.88325,3
187.65528,  65.00000,      0.47839,      0.37276,50.00000,20.00000,5.847300e-08,0.87986,3
192.86559,  67.60000,      0.46080,      0.37548,50.00000,20.00000,5.867323e-08,0.87634,3
198.06733,  70.20000,      0.43971,      0.37898,50.00000,20.00000,5.873279e-08,0.87273,3
203.25671,  72.80000,      0.41853,      0.38056,50.00000,20.00000,5.888518e-08,0.86904,3
208.45697,  75.40000,      0.39838,      0.38329,50.00000,20.00000,5.913707e-08,0.86525,3
213.65578,  78.00000,      0.37194,      0.38703,50.00000,20.00000,5.920770e-08,0.86137,3
218.83946,  80.60000,      0.34422,      0.38962,50.00000,20.00000,5.939129e-08,0.85741,3
224.04562,  83.20000,      0.31749,      0.39199,50.00000,20.00000,5.946994e-08,0.85336,3
226.64189,  85.80000,     -0.24035,      0.37730,50.00000,20.00000,5.967316e-08,0.85131,4
227.03429,  88.40000,     -0.43239,      0.36791,50.00000,20.00000,5.979014e-08,0.85100,4
226.81090,  91.00000,     -0.46853,      0.36224,50.00000,20.00000,5.998502e-08,0.85117,4
226.60855,  93.60000,     -0.45660,      0.35613,50.00000,20.00000,6.000195e-08,0.85133,4
226.55476,  96.20000,     -0.44033,      0.35191,50.00000,20.00000,6.021793e-08,0.85138,4
226.65877,  98.80000,     -0.42646,      0.34748,50.00000,20.00000,6.018079e-08,0.85130,4
226.83459, 101.40000,     -0.42072,      0.34315,50.00000,20.00000,6.012411e-08,0.85116,4
227.06783, 104.00000,     -0.41733,      0.33880,50.00000,20.00000,6.023261e-08,0.85097,4
227.30413, 106.60000,     -0.41939,      0.33769,50.00000,20.00000,6.024251e-08,0.85078,4
227.56274, 109.20000,     -0.42292,      0.33523,50.00000,20.00000,6.029025e-08,0.85058,4
227.81645, 111.80000,     -0.42307,      0.33253,50.00000,20.00000,6.029626e-08,0.85037,4
228.08780, 114.40000,     -0.42399,      0.33036,50.00000,20.00000,6.021644e-08,0.85016,4
228.34585, 117.00000,     -0.42748,      0.32798,50.00000,20.00000,6.029844e-08,0.84995,4
228.60518, 119.60000,     -0.43052,      0.32850,50.00000,20.00000,6.028344e-08,0.84975,4
228.86449, 122.20000,     -0.43202,      0.32742,50.00000,20.00000,6.034672e-08,0.84954,4
229.11725, 124.80000,     -0.43566,      0.32596,50.00000,20.00000,6.040914e-08,0.84934,4
229.37935, 127.40000,     -0.43634,      0.32407,50.00000,20.00000,6.043258e-08,0.84913,4
229.63554, 130.00000,     -0.43925,      0.32317,50.00000,20.00000,6.038739e-08,0.84892,4
229.89352, 132.60000,     -0.44110,      0.32081,50.00000,20.00000,6.031138e-08,0.84871,4
230.14559, 135.20000,     -0.44471,      0.32074,50.00000,20.00000,6.029830e-08,0.84851,4
230.40018, 137.80000,     -0.44705,      0.31751,50.00000,20.00000,6.036465e-08,0.84831,4
230.66389, 140.40000,     -0.44704,      0.31887,50.00000,20.00000,6.047331e-08,0.84810,4
230.93510, 143.00000,     -0.44867,      0.31768,50.00000,20.00000,6.031418e-08,0.84788,4
231.20160, 145.60000,     -0.45149,      0.31740,50.00000,20.00000,6.041923e-08,0.84766,4
231.44228, 148.20000,     -0.45411,      0.31697,50.00000,20.00000,6.044048e-08,0.84747,4
231.71343, 150.80000,     -0.45470,      0.31580,50.00000,20.00000,6.046957e-08,0.84725,4
231.98902, 153.40000,     -0.46098,      0.31711,50.00000,20.00000,6.049871e-08,0.84703,4
232.24397, 156.00000,     -0.46089,      0.31642,50.00000,20.00000,6.048761e-08,0.84682,4
232.50252, 158.60000,     -0.46344,      0.31851,50.00000,20.00000,6.045277e-08,0.84661,4
232.75581, 161.20000,     -0.46607,      0.31642,50.00000,20.00000,6.058598e-08,0.84641,4
233.02276, 163.80000,     -0.46630,      0.31540,50.00000,20.00000,6.046831e-08,0.84619,4
233.27658, 166.40000,     -0.47002,      0.31450,50.00000,20.00000,6.054204e-08,0.84598,4
233.55580, 169.00000,     -0.46803,      0.31402,50.00000,20.00000,6.059851e-08,0.84576,4
233.81186, 171.60000,     -0.47276,      0.31321,50.00000,20.00000,6.062567e-08,0.84555,4
234.05676, 174.20000,     -0.47576,      0.31269,50.00000,20.00000,6.052586e-08,0.84535,4
234.30683, 176.80000,     -0.47660,      0.31237,50.00000,20.00000,6.073346e-08,0.84515,4
234.57360, 179.40000,     -0.47964,      0.31121,50.00000,20.00000,6.063590e-08,0.84493,4
234.82548, 182.00000,     -0.48415,      0.30986,50.00000,20.00000,6.073134e-08,0.84472,4
235.10532, 184.60000,     -0.48293,      0.30955,50.00000,20.00000,6.065039e-08,0.84450,4
235.35491, 187.20000,     -0.48617,      0.30768,50.00000,20.00000,6.069889e-08,0.84429,4
235.62217, 189.80000,     -0.49023,      0.30850,50.00000,20.00000,6.074635e-08,0.84407,4
235.88127, 192.40000,     -0.49055,      0.30813,50.00000,20.00000,6.068538e-08,0.84386,4
236.13740, 195.00000,     -0.49294,      0.30748,50.00000,20.00000,6.065555e-08,0.84365,4
236.39557, 197.60000,     -0.49712,      0.30698,50.00000,20.00000,6.067066e-08,0.84344,4
236.66341, 200.20000,     -0.49639,      0.30650,50.00000,20.00000,6.076588e-08,0.84322,4
236.91441, 202.80000,     -0.50184,      0.30526,50.00000,20.00000,6.084136e-08,0.84302,4
237.17326, 205.40000,     -0.50250,      0.30475,50.00000,20.00000,6.075805e-08,0.84280,4
237.44090, 208.00000,     -0.50445,      0.30375,50.00000,20.00000,6.086345e-08,0.84258,4
237.69580, 210.60000,     -0.50765,      0.30459,50.00000,20.00000,6.082087e-08,0.84237,4
237.96119, 213.20000,     -0.51040,      0.30251,50.00000,20.00000,6.078475e-08,0.84215,4
238.21906, 215.80000,     -0.51227,      0.30303,50.00000,20.00000,6.080754e-08,0.84194,4
238.47800, 218.40000,     -0.51299,      0.30219,50.00000,20.00000,6.082011e-08,0.84173,4
238.73377, 221.00000,     -0.51522,      0.30197,50.00000,20.00000,6.085872e-08,0.84152,4
238.99913, 223.60000,     -0.51653,      0.30071,50.00000,20.00000,6.088302e-08,0.84130,4
239.26291, 226.20000,     -0.51870,      0.30062,50.00000,20.00000,6.093771e-08,0.84108,4
239.52891, 228.80000,     -0.51958,      0.30183,50.00000,20.00000,6.105200e-08,0.84086,4
239.79384, 231.40000,     -0.52547,      0.29811,50.00000,20.00000,6.096507e-08,0.84064,4
240.02884, 234.00000,     -0.52699,      0.29872,50.00000,20.00000,6.102057e-08,0.84045,4
240.30513, 236.60000,     -0.52739,      0.29855,50.00000,20.00000,6.102618e-08,0.84022,4
240.56494, 239.20000,     -0.53114,      0.29755,50.00000,20.00000,6.103684e-08,0.84000,4
240.82351, 241.80000,     -0.53428,      0.29609,50.00000,20.00000,6.099034e-08,0.83979,4
241.07729, 244.40000,     -0.53441,      0.29617,50.00000,20.00000,6.104021e-08,0.83958,4
241.34133, 247.00000,     -0.53497,      0.29681,50.00000,20.00000,6.107075e-08,0.83936,4
241.58587, 249.60000,     -0.53976,      0.29488,50.00000,20.00000,6.110090e-08,0.83915,4
241.84563, 252.20000,     -0.54108,      0.29394,50.00000,20.00000,6.108296e-08,0.83894,4
242.11849, 254.80000,     -0.54439,      0.29421,50.00000,20.00000,6.107185e-08,0.83871,4
242.36883, 257.40000,     -0.54447,      0.29391,50.00000,20.00000,6.100571e-08,0.83850,4
242.64886, 260.00000,     -0.54981,      0.29118,50.00000,20.00000,6.103301e-08,0.83827,4
242.88660, 262.60000,     -0.55168,      0.29221,50.00000,20.00000,6.101691e-08,0.83807,4
243.17398, 265.20000,     -0.55377,      0.29059,50.00000,20.00000,6.110138e-08,0.83783,4
243.43458, 267.80000,     -0.55645,      0.29049,50.00000,20.00000,6.114861e-08,0.83761,4
243.68791, 270.40000,     -0.55798,      0.29095,50.00000,20.00000,6.107972e-08,0.83740,4
243.93952, 273.00000,     -0.56086,      0.29088,50.00000,20.00000,6.111620e-08,0.83719,4
244.19771, 275.60000,     -0.56605,      0.28976,50.00000,20.00000,6.126305e-08,0.83697,4
244.45283, 278.20000,     -0.56583,      0.28945,50.00000,20.00000,6.114841e-08,0.83676,4
244.71554, 280.80000,     -0.56539,      0.28797,50.00000,20.00000,6.117438e-08,0.83654,4
244.97777, 283.40000,     -0.56968,      0.28708,50.00000,20.00000,6.115423e-08,0.83632,4
245.24765, 286.00000,     -0.57197,      0.28678,50.00000,20.00000,6.116550e-08,0.83609,4
245.49353, 288.60000,     -0.57364,      0.28621,50.00000,20.00000,6.115472e-08,0.83588,4
245.76457, 291.20000,     -0.57515,      0.28665,50.00000,20.00000,6.127579e-08,0.83565,4
246.01075, 293.80000,     -0.57789,      0.28780,50.00000,20.00000,6.126852e-08,0.83545,4
246.29060, 296.40000,     -0.57704,      0.28633,50.00000,20.00000,6.134891e-08,0.83521,4
246.53268, 299.00000,     -0.58127,      0.28520,50.00000,20.00000,6.118005e-08,0.83501,4
246.79768, 301.60000,     -0.58374,      0.28682,50.00000,20.00000,6.125178e-08,0.83478,4
247.04905, 304.20000,     -0.58587,      0.28374,50.00000,20.00000,6.133260e-08,0.83457,4
247.31474, 306.80000,     -0.58657,      0.28421,50.00000,20.00000,6.133905e-08,0.83434,4
247.58453, 309.40000,     -0.58945,      0.28432,50.00000,20.00000,6.138331e-08,0.83412,4
247.82510, 312.00000,     -0.58937,      0.28346,50.00000,20.00000,6.135498e-08,0.83391,4
248.10056, 314.60000,     -0.59215,      0.28213,50.00000,20.00000,6.141114e-08,0.83368,4
248.36740, 317.20000,     -0.59586,      0.28257,50.00000,20.00000,6.131391e-08,0.83345,4
248.62038, 319.80000,     -0.59908,      0.28135,50.00000,20.00000,6.145719e-08,0.83324,4
248.87493, 322.40000,     -0.60072,      0.28064,50.00000,20.00000,6.144426e-08,0.83302,4
249.13614, 325.00000,     -0.59932,      0.28045,50.00000,20.00000,6.151036e-08,0.83280,4
249.40167, 327.60000,     -0.60358,      0.27822,50.00000,20.00000,6.143803e-08,0.83257,4
249.65510, 330.20000,     -0.60637,      0.27683,50.00000,20.00000,6.159998e-08,0.83236,4
249.91443, 332.80000,     -0.60799,      0.27760,50.00000,20.00000,6.150726e-08,0.83214,4
250.17410, 335.40000,     -0.60856,      0.27682,50.00000,20.00000,6.143569e-08,0.83192,4
250.43918, 338.00000,     -0.61322,      0.27554,50.00000,20.00000,6.147016e-08,0.83169,4
250.71956, 340.60000,     -0.61508,      0.27456,50.00000,20.00000,6.159514e-08,0.83145,4
250.95864, 343.20000,     -0.61709,      0.27263,50.00000,20.00000,6.142741e-08,0.83125,4
251.21159, 345.80000,     -0.61889,      0.27331,50.00000,20.00000,6.153601e-08,0.83103,4
251.47170, 348.40000,     -0.61916,      0.27299,50.00000,20.00000,6.159895e-08,0.83081,4
251.71798, 351.00000,     -0.62222,      0.27118,50.00000,20.00000,6.145022e-08,0.83060,4
251.99240, 353.60000,     -0.62501,      0.27027,50.00000,20.00000,6.145792e-08,0.83036,4
252.25738, 356.20000,     -0.62787,      0.26928,50.00000,20.00000,6.147777e-08,0.83014,4
252.52045, 358.80000,     -0.62775,      0.26982,50.00000,20.00000,6.148336e-08,0.82991,4
252.77364, 361.40000,     -0.63085,      0.26710,50.00000,20.00000,6.162319e-08,0.82969,4
253.03143, 364.00000,     -0.63097,      0.26574,50.00000,20.00000,6.159246e-08,0.82947,4
253.30180, 366.60000,     -0.63341,      0.26482,50.00000,20.00000,6.158022e-08,0.82924,4
253.56381, 369.20000,     -0.63613,      0.26495,50.00000,20.00000,6.168533e-08,0.82901,4
253.81645, 371.80000,     -0.63844,      0.26291,50.00000,20.00000,6.155910e-08,0.82880,4
254.07967, 374.40000,     -0.64040,      0.26373,50.00000,20.00000,6.173493e-08,0.82857,4
254.33940, 377.00000,     -0.64241,      0.26146,50.00000,20.00000,6.177566e-08,0.82835,4
254.58669, 379.60000,     -0.64376,      0.26076,50.00000,20.00000,6.166356e-08,0.82813,4
254.85302, 382.20000,     -0.64450,      0.25973,50.00000,20.00000,6.171084e-08,0.82790,4
255.11429, 384.80000,     -0.64621,      0.25872,50.00000,20.00000,6.176334e-08,0.82768,4
255.38393, 387.40000,     -0.64910,      0.25719,50.00000,20.00000,6.164334e-08,0.82745,4
255.63916, 390.00000,     -0.65274,      0.25635,50.00000,20.00000,6.163812e-08,0.82723,4
255.89849, 392.60000,     -0.65374,      0.25499,50.00000,20.00000,6.168580e-08,0.82700,4
256.14969, 395.20000,     -0.65629,      0.25399,50.00000,20.00000,6.171418e-08,0.82678,4
256.42072, 397.80000,     -0.65750,      0.25253,50.00000,20.00000,6.177023e-08,0.82655,4
256.67955, 400.40000,     -0.65979,      0.25160,50.00000,20.00000,6.172524e-08,0.82633,4
256.93204, 403.00000,     -0.65979,      0.25092,50.00000,20.00000,6.162483e-08,0.82611,4
257.19677, 405.60000,     -0.66412,      0.24866,50.00000,20.00000,6.167576e-08,0.82588,4
257.44664, 408.20000,     -0.66492,      0.24671,50.00000,20.00000,6.169849e-08,0.82566,4
257.70798, 410.80000,     -0.66869,      0.24752,50.00000,20.00000,6.171382e-08,0.82543,4
257.97155, 413.40000,     -0.66760,      0.24566,50.00000,20.00000,6.173824e-08,0.82520,4
258.23370, 416.00000,     -0.66820,      0.24451,50.00000,20.00000,6.174353e-08,0.82498,4
258.49776, 418.60000,     -0.67463,      0.24413,50.00000,20.00000,6.173546e-08,0.82475,4
258.76273, 421.20000,     -0.67489,      0.24205,50.00000,20.00000,6.180073e-08,0.82452,4
259.00950, 423.80000,     -0.67464,      0.24175,50.00000,20.00000,6.180591e-08,0.82430,4
259.27597, 426.40000,     -0.67887,      0.23973,50.00000,20.00000,6.180781e-08,0.82407,4
259.53206, 429.00000,     -0.67883,      0.23914,50.00000,20.00000,6.184698e-08,0.82385,4
259.79816, 431.60000,     -0.68162,      0.23613,50.00000,20.00000,6.182413e-08,0.82361,4
260.05646, 434.20000,     -0.68204,      0.23527,50.00000,20.00000,6.184777e-08,0.82339,4
260.31710, 436.80000,     -0.68325,      0.23507,50.00000,20.00000,6.179506e-08,0.82316,4
260.56899, 439.40000,     -0.68665,      0.23287,50.00000,20.00000,6.190194e-08,0.82294,4
260.84501, 442.00000,     -0.68844,      0.23091,50.00000,20.00000,6.184659e-08,0.82270,4
261.10486, 444.60000,     -0.68794,      0.23022,50.00000,20.00000,6.179060e-08,0.82247,4
261.36043, 447.20000,     -0.69022,      0.23056,50.00000,20.00000,6.185865e-08,0.82225,4
261.61858, 449.80000,     -0.69246,      0.22784,50.00000,20.00000,6.182487e-08,0.82202,4
261.88204, 452.40000,     -0.69426,      0.22714,50.00000,20.00000,6.183714e-08,0.82179,4
262.13737, 455.00000,     -0.69615,      0.22482,50.00000,20.00000,6.185638e-08,0.82157,4
262.39188, 457.60000,     -0.69809,      0.22290,50.00000,20.00000,6.185590e-08,0.82134,4
262.65240, 460.20000,     -0.70253,      0.22216,50.00000,20.00000,6.188508e-08,0.82112,4
262.92421, 462.80000,     -0.70371,      0.21991,50.00000,20.00000,6.188857e-08,0.82088,4
263.18872, 465.40000,     -0.70354,      0.21822,50.00000,20.00000,6.187415e-08,0.82064,4
263.43395, 468.00000,     -0.70043,      0.21722,50.00000,20.00000,6.190631e-08,0.82043,4
263.69707, 470.60000,     -0.70137,      0.21517,50.00000,20.00000,6.192286e-08,0.82020,4
263.95124, 473.20000,     -0.70360,      0.21382,50.00000,20.00000,6.197035e-08,0.81997,4
264.22145, 475.80000,     -0.70269,      0.21143,50.00000,20.00000,6.176879e-08,0.81974,4
264.46681, 478.40000,     -0.70803,      0.20940,50.00000,20.00000,6.190480e-08,0.81952,4
264.72387, 481.00000,     -0.70640,      0.20840,50.00000,20.00000,6.199738e-08,0.81929,4
264.99561, 483.60000,     -0.71014,      0.20692,50.00000,20.00000,6.193968e-08,0.81905,4
265.24039, 486.20000,     -0.70889,      0.20514,50.00000,20.00000,6.201485e-08,0.81884,4
265.52045, 488.80000,     -0.71320,      0.20383,50.00000,20.00000,6.193826e-08,0.81859,4
265.78521, 491.40000,     -0.71262,      0.20081,50.00000,20.00000,6.200301e-08,0.81836,4
266.03899, 494.00000,     -0.71618,      0.19978,50.00000,20.00000,6.193190e-08,0.81813,4
266.28864, 496.60000,     -0.71399,      0.19875,50.00000,20.00000,6.189842e-08,0.81791,4
266.56606, 499.20000,     -0.71588,      0.19639,50.00000,20.00000,6.205327e-08,0.81766,4
266.81170, 501.80000,     -0.72011,      0.19467,50.00000,20.00000,6.186939e-08,0.81745,4
267.08486, 504.40000,     -0.72103,      0.19198,50.00000,20.00000,6.197976e-08,0.81721,4
267.32718, 507.00000,     -0.72112,      0.19186,50.00000,20.00000,6.206536e-08,0.81699,4
267.59134, 509.60000,     -0.71952,      0.18858,50.00000,20.00000,6.204436e-08,0.81676,4
267.85803, 512.20000,     -0.72269,      0.18655,50.00000,20.00000,6.195836e-08,0.81652,4
268.11447, 514.80000,     -0.72093,      0.18418,50.00000,20.00000,6.206926e-08,0.81629,4
268.37426, 517.40000,     -0.72027,      0.18345,50.00000,20.00000,6.198343e-08,0.81606,4
268.63628, 520.00000,     -0.72410,      0.18175,50.00000,20.00000,6.211070e-08,0.81583,4
268.90843, 522.60000,     -0.72575,      0.18100,50.00000,20.00000,6.208186e-08,0.81559,4
269.16783, 525.20000,     -0.72466,      0.17769,50.00000,20.00000,6.211149e-08,0.81536,4
269.41437, 527.80000,     -0.72430,      0.17440,50.00000,20.00000,6.211870e-08,0.81514,4
269.67839, 530.40000,     -0.72717,      0.17157,50.00000,20.00000,6.217746e-08,0.81490,4
269.92852, 533.00000,     -0.72759,      0.17026,50.00000,20.00000,6.201399e-08,0.81468,4
270.20757, 535.60000,     -0.72750,      0.16788,50.00000,20.00000,6.210406e-08,0.81443,4
270.45890, 538.20000,     -0.72874,      0.16520,50.00000,20.00000,6.208294e-08,0.81420,4
270.71986, 540.80000,     -0.72923,      0.16448,50.00000,20.00000,6.208218e-08,0.81397,4
270.96704, 543.40000,     -0.73182,      0.16119,50.00000,20.00000,6.211205e-08,0.81375,4
271.23721, 546.00000,     -0.73073,      0.15933,50.00000,20.00000,6.220180e-08,0.81351,4
271.48770, 548.60000,     -0.73273,      0.15623,50.00000,20.00000,6.209941e-08,0.81329,4
271.75544, 551.20000,     -0.73723,      0.15317,50.00000,20.00000,6.216904e-08,0.81305,4
272.02175, 553.80000,     -0.73519,      0.15024,50.00000,20.00000,6.214462e-08,0.81281,4
272.26137, 556.40000,     -0.73704,      0.14926,50.00000,20.00000,6.217094e-08,0.81259,4
272.52883, 559.00000,     -0.73891,      0.14658,50.00000,20.00000,6.215112e-08,0.81235,4
272.78546, 561.60000,     -0.73478,      0.14313,50.00000,20.00000,6.213420e-08,0.81212,4
273.06477, 564.20000,     -0.73510,      0.14274,50.00000,20.00000,6.211426e-08,0.81187,4
273.31201, 566.80000,     -0.73685,      0.13948,50.00000,20.00000,6.219479e-08,0.81165,4
273.58130, 569.40000,     -0.73902,      0.13844,50.00000,20.00000,6.218786e-08,0.81141,4
273.83541, 572.00000,     -0.74001,      0.13451,50.00000,20.00000,6.228118e-08,0.81118,4
274.09743, 574.60000,     -0.73787,      0.13160,50.00000,20.00000,6.214936e-08,0.81095,4
274.35937, 577.20000,     -0.73968,      0.12896,50.00000,20.00000,6.223912e-08,0.81071,4
274.61970, 579.80000,     -0.74128,      0.12510,50.00000,20.00000,6.226882e-08,0.81048,4
274.87399, 582.40000,     -0.73968,      0.12360,50.00000,20.00000,6.226859e-08,0.81025,4
275.12490, 585.00000,     -0.74227,      0.11993,50.00000,20.00000,6.228600e-08,0.81002,4
275.39350, 587.60000,     -0.74225,      0.11921,50.00000,20.00000,6.232559e-08,0.80978,4
275.66004, 590.20000,     -0.74221,      0.11630,50.00000,20.00000,6.221439e-08,0.80954,4
275.91007, 592.80000,     -0.73505,      0.11301,50.00000,20.00000,6.230767e-08,0.80932,4
276.18577, 595.40000,     -0.73897,      0.10996,50.00000,20.00000,6.231136e-08,0.80907,4
276.44205, 598.00000,     -0.73598,      0.10588,50.00000,20.00000,6.241066e-08,0.80884,4
276.69792, 600.60000,     -0.73903,      0.10430,50.00000,20.00000,6.225075e-08,0.80861,4
276.95965, 603.20000,     -0.73550,      0.10090,50.00000,20.00000,6.235351e-08,0.80837,4
277.21218, 605.80000,     -0.73561, 9.611219e-02,50.00000,20.00000,6.228835e-08,0.80814,4
277.47128, 608.40000,     -0.73310, 9.259103e-02,50.00000,20.00000,6.228357e-08,0.80791,4
277.74146, 611.00000,     -0.73263, 9.026283e-02,50.00000,20.00000,6.231384e-08,0.80766,4
278.00420, 613.60000,     -0.73124, 8.643297e-02,50.00000,20.00000,6.233634e-08,0.80743,4
278.26967, 616.20000,     -0.72923, 8.348407e-02,50.00000,20.00000,6.242885e-08,0.80719,4
278.51526, 618.80000,     -0.72970, 7.946664e-02,50.00000,20.00000,6.237452e-08,0.80696,4
278.78153, 621.40000,     -0.73008, 7.654621e-02,50.00000,20.00000,6.244189e-08,0.80672,4
279.03687, 624.00000,     -0.72945, 7.377277e-02,50.00000,20.00000,6.251316e-08,0.80649,4
279.28363, 626.60000,     -0.72995, 6.936020e-02,50.00000,20.00000,6.241783e-08,0.80627,4
279.54863, 629.20000,     -0.73320, 6.539590e-02,50.00000,20.00000,6.244866e-08,0.80603,4
279.81141, 631.80000,     -0.73456, 6.345302e-02,50.00000,20.00000,6.244445e-08,0.80579,4
280.05340, 634.40000,     -0.73516, 5.874931e-02,50.00000,20.00000,6.246759e-08,0.80557,4
280.32681, 637.00000,     -0.73341, 5.466703e-02,50.00000,20.00000,6.253304e-08,0.80532,4
280.59604, 639.60000,     -0.73243, 5.504659e-02,50.00000,20.00000,6.262298e-08,0.80508,4
280.85670, 642.20000,     -0.73238, 5.098165e-02,50.00000,20.00000,6.261833e-08,0.80484,4
281.11904, 644.80000,     -0.73137, 4.592997e-02,50.00000,20.00000,6.267990e-08,0.80460,4
281.36695, 647.40000,     -0.72872, 4.219847e-02,50.00000,20.00000,6.258425e-08,0.80438,4
281.65010, 650.00000,     -0.72985, 4.001441e-02,50.00000,20.00000,6.274580e-08,0.80412,4
281.90990, 652.60000,     -0.72479, 3.590037e-02,50.00000,20.00000,6.276268e-08,0.80388,4
282.15586, 655.20000,     -0.72359, 3.320766e-02,50.00000,20.00000,6.270581e-08,0.80366,4
282.42484, 657.80000,     -0.72604, 3.009000e-02,50.00000,20.00000,6.276495e-08,0.80341,4
282.68004, 660.40000,     -0.72249, 2.634996e-02,50.00000,20.00000,6.285263e-08,0.80318,4
282.93723, 663.00000,     -0.72282, 2.060177e-02,50.00000,20.00000,6.278346e-08,0.80295,4
283.17967, 665.60000,     -0.72553, 1.482081e-02,50.00000,20.00000,6.271524e-08,0.80273,4
283.46021, 668.20000,     -0.72217, 1.058880e-02,50.00000,20.00000,6.282605e-08,0.80247,4
283.71253, 670.80000,     -0.72236, 7.359131e-03,50.00000,20.00000,6.281698e-08,0.80224,4
283.97121, 673.40000,     -0.72402, 2.143163e-03,50.00000,20.00000,6.273133e-08,0.80200,4
284.24274, 676.00000,     -0.72092,-9.112822e-04,50.00000,20.00000,6.273891e-08,0.80175,4
284.48422, 678.60000,     -0.72166,-4.542909e-03,50.00000,20.00000,6.286252e-08,0.80153,4
284.75958, 681.20000,     -0.72182,-9.958409e-03,50.00000,20.00000,6.276447e-08,0.80128,4
285.02388, 683.80000,     -0.72179,-1.547562e-02,50.00000,20.00000,6.288323e-08,0.80104,4
285.27933, 686.40000,     -0.71966,-1.957307e-02,50.00000,20.00000,6.286385e-08,0.80081,4
285.53966, 689.00000,     -0.73135,-2.375711e-02,50.00000,20.00000,6.287689e-08,0.80057,4
285.79971, 691.60000,     -0.72965,-2.908864e-02,50.00000,20.00000,6.281268e-08,0.80033,4
286.05998, 694.20000,     -0.73115,-3.334678e-02,50.00000,20.00000,6.288634e-08,0.80009,4
286.31209, 696.80000,     -0.73276,-3.681731e-02,50.00000,20.00000,6.294078e-08,0.79986,4
286.56635, 699.40000,     -0.72935,-4.345049e-02,50.00000,20.00000,6.277828e-08,0.79963,4
286.83551, 702.00000,     -0.72484,-4.737449e-02,50.00000,20.00000,6.304723e-08,0.79938,4
287.10216, 704.60000,     -0.72787,-5.266788e-02,50.00000,20.00000,6.293049e-08,0.79914,4
287.36055, 707.20000,     -0.72865,-5.806141e-02,50.00000,20.00000,6.292773e-08,0.79890,4
287.61526, 709.80000,     -0.72590,-6.366196e-02,50.00000,20.00000,6.300002e-08,0.79867,4
287.86443, 712.40000,     -0.72633,-6.989845e-02,50.00000,20.00000,6.296643e-08,0.79844,4
288.12928, 715.00000,     -0.72898,-7.489999e-02,50.00000,20.00000,6.300681e-08,0.79819,4
288.39029, 717.60000,     -0.72944,-8.168658e-02,50.00000,20.00000,6.304329e-08,0.79795,4
288.65937, 720.20000,     -0.73100,-8.663430e-02,50.00000,20.00000,6.311877e-08,0.79771,4
288.90065, 722.80000,     -0.72759,-9.139362e-02,50.00000,20.00000,6.304152e-08,0.79749,4
289.18105, 725.40000,     -0.72617,-9.820519e-02,50.00000,20.00000,6.301188e-08,0.79723,4
289.44559, 728.00000,     -0.72935,     -0.10488,50.00000,20.00000,6.301867e-08,0.79698,4
289.69998, 730.60000,     -0.73023,     -0.10932,50.00000,20.00000,6.303076e-08,0.79675,4
289.95356, 733.20000,     -0.72781,     -0.11540,50.00000,20.00000,6.314604e-08,0.79652,4
290.21347, 735.80000,     -0.72800,     -0.12212,50.00000,20.00000,6.303152e-08,0.79628,4
290.47281, 738.40000,     -0.72418,     -0.12811,50.00000,20.00000,6.318794e-08,0.79604,4
290.71651, 741.00000,     -0.72245,     -0.13494,50.00000,20.00000,6.314358e-08,0.79581,4
290.99862, 743.60000,     -0.72088,     -0.14352,50.00000,20.00000,6.318728e-08,0.79555,4
291.26279, 746.20000,     -0.72031,     -0.14798,50.00000,20.00000,6.313693e-08,0.79531,4
291.50964, 748.80000,     -0.71990,     -0.15364,50.00000,20.00000,6.322058e-08,0.79508,4
291.77761, 751.40000,     -0.71728,     -0.16235,50.00000,20.00000,6.312801e-08,0.79483,4
292.04018, 754.00000,     -0.72405,     -0.16928,50.00000,20.00000,6.330545e-08,0.79459,4
292.29714, 756.60000,     -0.71962,     -0.17703,50.00000,20.00000,6.324278e-08,0.79435,4
292.56260, 759.20000,     -0.71747,     -0.18386,50.00000,20.00000,6.314932e-08,0.79411,4
292.81980, 761.80000,     -0.71821,     -0.19234,50.00000,20.00000,6.316718e-08,0.79387,4
293.07935, 764.40000,     -0.72712,     -0.19870,50.00000,20.00000,6.328365e-08,0.79363,4
293.33579, 767.00000,     -0.72407,     -0.20680,50.00000,20.00000,6.322281e-08,0.79339,4
293.59981, 769.60000,     -0.72027,     -0.21371,50.00000,20.00000,6.317563e-08,0.79315,4
293.86003, 772.20000,     -0.71689,     -0.22197,50.00000,20.00000,6.315865e-08,0.79291,4
294.10169, 774.80000,     -0.71458,     -0.22887,50.00000,20.00000,6.319335e-08,0.79269,4
294.37059, 777.40000,     -0.71336,     -0.23622,50.00000,20.00000,6.329529e-08,0.79244,4
294.63364, 780.00000,     -0.71224,     -0.24448,50.00000,20.00000,6.319684e-08,0.79219,4
294.91067, 782.60000,     -0.72190,     -0.25430,50.00000,20.00000,6.321380e-08,0.79194,4
295.14624, 785.20000,     -0.72094,     -0.26170,50.00000,20.00000,6.329165e-08,0.79172,4
295.41381, 787.80000,     -0.71713,     -0.26958,50.00000,20.00000,6.318080e-08,0.79147,4
295.68184, 790.40000,     -0.71478,     -0.27709,50.00000,20.00000,6.320804e-08,0.79122,4
295.93806, 793.00000,     -0.71756,     -0.28512,50.00000,20.00000,6.332215e-08,0.79098,4
296.19821, 795.60000,     -0.71652,     -0.29447,50.00000,20.00000,6.329773e-08,0.79074,4
296.45438, 798.20000,     -0.71634,     -0.30330,50.00000,20.00000,6.326554e-08,0.79050,4
296.71465, 800.80000,     -0.72059,     -0.31032,50.00000,20.00000,6.344159e-08,0.79026,4
296.97102, 803.40000,     -0.71937,     -0.32016,50.00000,20.00000,6.330466e-08,0.79002,4
297.24882, 806.00000,     -0.71526,     -0.32879,50.00000,20.00000,6.336554e-08,0.78977,4
297.49917, 808.60000,     -0.71155,     -0.33795,50.00000,20.00000,6.332201e-08,0.78953,4
297.76848, 811.20000,     -0.71007,     -0.34648,50.00000,20.00000,6.342624e-08,0.78928,4
298.01834, 813.80000,     -0.70979,     -0.35621,50.00000,20.00000,6.335951e-08,0.78905,4
298.27521, 816.40000,     -0.72001,     -0.36710,50.00000,20.00000,6.348459e-08,0.78881,4
298.54273, 819.00000,     -0.71418,     -0.37678,50.00000,20.00000,6.349615e-08,0.78856,4
298.78659, 821.60000,     -0.71076,     -0.38702,50.00000,20.00000,6.355124e-08,0.78834,4
299.05105, 824.20000,     -0.70784,     -0.39699,50.00000,20.00000,6.346118e-08,0.78809,4
299.32620, 826.80000,     -0.70932,     -0.40805,50.00000,20.00000,6.345587e-08,0.78783,4
299.55985, 829.40000,     -0.73037,     -0.41711,50.00000,20.00000,6.353504e-08,0.78762,4
299.81860, 832.00000,     -0.72392,     -0.42833,50.00000,20.00000,6.361582e-08,0.78738,4
300.08850, 834.60000,     -0.72459,     -0.43809,50.00000,20.00000,6.355321e-08,0.78712,4
300.35636, 837.20000,     -0.72341,     -0.44766,50.00000,20.00000,6.360166e-08,0.78687,4
300.61014, 839.80000,     -0.71301,     -0.46123,50.00000,20.00000,6.358824e-08,0.78664,4
300.87424, 842.40000,     -0.71249,     -0.47169,50.00000,20.00000,6.356707e-08,0.78639,4
301.13217, 845.00000,     -0.71005,     -0.48415,50.00000,20.00000,6.363188e-08,0.78615,4
301.38951, 847.60000,     -0.71108,     -0.49656,50.00000,20.00000,6.357380e-08,0.78591,4
301.64910, 850.20000,     -0.71227,     -0.50870,50.00000,20.00000,6.369104e-08,0.78567,4
301.91211, 852.80000,     -0.70660,     -0.52105,50.00000,20.00000,6.359373e-08,0.78542,4
302.17770, 855.40000,     -0.73044,     -0.53150,50.00000,20.00000,6.364843e-08,0.78517,4
302.44705, 858.00000,     -0.72120,     -0.54348,50.00000,20.00000,6.354162e-08,0.78492,4
302.70725, 860.60000,     -0.71345,     -0.55550,50.00000,20.00000,6.370863e-08,0.78468,4
302.96186, 863.20000,     -0.71576,     -0.56736,50.00000,20.00000,6.357797e-08,0.78444,4
303.21263, 865.80000,     -0.71110,     -0.58112,50.00000,20.00000,6.359416e-08,0.78421,4
303.46209, 868.40000,     -0.70894,     -0.59295,50.00000,20.00000,6.368541e-08,0.78397,4
303.73794, 871.00000,     -0.71248,     -0.60468,50.00000,20.00000,6.361117e-08,0.78371,4
304.00059, 873.60000,     -0.71155,     -0.61818,50.00000,20.00000,6.370855e-08,0.78347,4
304.24885, 876.20000,     -0.71116,     -0.63240,50.00000,20.00000,6.371989e-08,0.78324,4
304.50799, 878.80000,     -0.70263,     -0.64635,50.00000,20.00000,6.370922e-08,0.78299,4
304.75372, 881.40000,     -0.71897,     -0.65887,50.00000,20.00000,6.362611e-08,0.78276,4
305.02818, 884.00000,     -0.72494,     -0.67402,50.00000,20.00000,6.388616e-08,0.78251,4
305.29574, 886.60000,     -0.71965,     -0.68773,50.00000,20.00000,6.373614e-08,0.78226,4
305.57107, 889.20000,     -0.70959,     -0.70185,50.00000,20.00000,6.369900e-08,0.78200,4
305.82172, 891.80000,     -0.71598,     -0.71423,50.00000,20.00000,6.375911e-08,0.78176,4
306.08688, 894.40000,     -0.70980,     -0.72983,50.00000,20.00000,6.379207e-08,0.78151,4
306.34476, 897.00000,     -0.71288,     -0.74482,50.00000,20.00000,6.375435e-08,0.78127,4
306.59553, 899.60000,     -0.70765,     -0.75973,50.00000,20.00000,6.377074e-08,0.78104,4
306.84966, 902.20000,     -0.71812,     -0.77585,50.00000,20.00000,6.377761e-08,0.78080,4
307.10208, 904.80000,     -0.71243,     -0.78960,50.00000,20.00000,6.378309e-08,0.78056,4
307.36404, 907.40000,     -0.72637,     -0.80606,50.00000,20.00000,6.382642e-08,0.78032,4
307.62769, 910.00000,     -0.71913,     -0.81995,50.00000,20.00000,6.378800e-08,0.78007,4
307.89661, 912.60000,     -0.71686,     -0.83525,50.00000,20.00000,6.374587e-08,0.77982,4
308.16756, 915.20000,     -0.71846,     -0.85200,50.00000,20.00000,6.384879e-08,0.77956,4
308.43257, 917.80000,     -0.71976,     -0.86689,50.00000,20.00000,6.392601e-08,0.77931,4
308.69353, 920.40000,     -0.73135,     -0.88434,50.00000,20.00000,6.389033e-08,0.77907,4
308.94023, 923.00000,     -0.72985,     -0.90087,50.00000,20.00000,6.385899e-08,0.77883,4
309.20542, 925.60000,     -0.72390,     -0.91821,50.00000,20.00000,6.401081e-08,0.77859,4
309.46129, 928.20000,     -0.72287,     -0.93325,50.00000,20.00000,6.398188e-08,0.77834,4
309.71596, 930.80000,     -0.71990,     -0.95073,50.00000,20.00000,6.390050e-08,0.77811,4
309.96422, 933.40000,     -0.72260,     -0.96682,50.00000,20.00000,6.387261e-08,0.77787,4
310.23005, 936.00000,     -0.73175,     -0.98461,50.00000,20.00000,6.399629e-08,0.77762,4
310.48453, 938.60000,     -0.72632,     -1.00265,50.00000,20.00000,6.392473e-08,0.77738,4
310.74845, 941.20000,     -0.72419,     -1.01904,50.00000,20.00000,6.396334e-08,0.77713,4
310.99392, 943.80000,     -0.72291,     -1.03610,50.00000,20.00000,6.405280e-08,0.77690,4
311.25916, 946.40000,     -0.72575,     -1.05687,50.00000,20.00000,6.410336e-08,0.77665,4
311.52494, 949.00000,     -0.73751,     -1.07495,50.00000,20.00000,6.407347e-08,0.77640,4
311.80970, 951.60000,     -0.73343,     -1.09405,50.00000,20.00000,6.402364e-08,0.77613,4
312.05040, 954.20000,     -0.73336,     -1.11047,50.00000,20.00000,6.418502e-08,0.77591,4
312.31619, 956.80000,     -0.72501,     -1.13007,50.00000,20.00000,6.413354e-08,0.77566,4
312.58075, 959.40000,     -0.73732,     -1.15059,50.00000,20.00000,6.405840e-08,0.77541,4
312.83285, 962.00000,     -0.74655,     -1.17000,50.00000,20.00000,6.413483e-08,0.77517,4
313.09949, 964.60000,     -0.74218,     -1.18976,50.00000,20.00000,6.421420e-08,0.77492,4
313.34997, 967.20000,     -0.73584,     -1.21014,50.00000,20.00000,6.410633e-08,0.77468,4
313.62536, 969.80000,     -0.73704,     -1.22782,50.00000,20.00000,6.411685e-08,0.77442,4
313.87398, 972.40000,     -0.74037,     -1.24807,50.00000,20.00000,6.423796e-08,0.77419,4
314.12775, 975.00000,     -0.75149,     -1.26744,50.00000,20.00000,6.421182e-08,0.77395,4
314.39504, 977.60000,     -0.74054,     -1.28719,50.00000,20.00000,6.425759e-08,0.77369,4
314.64648, 980.20000,     -0.73643,     -1.30629,50.00000,20.00000,6.421227e-08,0.77346,4
314.91571, 982.80000,     -0.75309,     -1.32793,50.00000,20.00000,6.418827e-08,0.77320,4
315.16389, 985.40000,     -0.74804,     -1.35037,50.00000,20.00000,6.418671e-08,0.77297,4
315.43758, 988.00000,     -0.73764,     -1.37217,50.00000,20.00000,6.422794e-08,0.77271,4
315.70126, 990.60000,     -0.74038,     -1.39296,50.00000,20.00000,6.419943e-08,0.77246,4
315.95650, 993.20000,     -0.73590,     -1.41104,50.00000,20.00000,6.418113e-08,0.77222,4
316.19987, 995.80000,     -0.76048,     -1.43459,50.00000,20.00000,6.425874e-08,0.77199,4
316.46529, 998.40000,     -0.75407,     -1.45539,50.00000,20.00000,6.424974e-08,0.77174,4
316.74023,1001.00000,     -0.76311,     -1.47701,50.00000,20.00000,6.428111e-08,0.77148,4
317.00872,1003.60000,     -0.76055,     -1.49810,50.00000,20.00000,6.429079e-08,0.77122,4
317.26850,1006.20000,     -0.76202,     -1.52077,50.00000,20.00000,6.434650e-08,0.77098,4
317.52513,1008.80000,     -0.75960,     -1.54289,50.00000,20.00000,6.432233e-08,0.77074,4
317.79275,1011.40000,     -0.76418,     -1.56422,50.00000,20.00000,6.438447e-08,0.77048,4
318.05683,1014.00000,     -0.76296,     -1.58673,50.00000,20.00000,6.433970e-08,0.77023,4
318.30313,1016.60000,     -0.76400,     -1.60914,50.00000,20.00000,6.434769e-08,0.77000,4
318.57015,1019.20000,     -0.77515,     -1.63410,50.00000,20.00000,6.441330e-08,0.76975,4
318.82391,1021.80000,     -0.77360,     -1.65598,50.00000,20.00000,6.449756e-08,0.76951,4
319.09325,1024.40000,     -0.77464,     -1.67653,50.00000,20.00000,6.441295e-08,0.76925,4
319.34584,1027.00000,     -0.77552,     -1.70105,50.00000,20.00000,6.451051e-08,0.76901,4
319.60836,1029.60000,     -0.77771,     -1.72552,50.00000,20.00000,6.450048e-08,0.76876,4
319.86480,1032.20000,     -0.77153,     -1.74732,50.00000,20.00000,6.445581e-08,0.76852,4
320.12908,1034.80000,     -0.78699,     -1.77188,50.00000,20.00000,6.454209e-08,0.76827,4
320.39118,1037.40000,     -0.78768,     -1.79449,50.00000,20.00000,6.452374e-08,0.76802,4
320.65211,1040.00000,     -0.79235,     -1.81731,50.00000,20.00000,6.456957e-08,0.76777,4
320.89887,1042.60000,     -0.80629,     -1.84279,50.00000,20.00000,6.455084e-08,0.76754,4
321.17391,1045.20000,     -0.79544,     -1.86452,50.00000,20.00000,6.462813e-08,0.76728,4
321.42118,1047.80000,     -0.79762,     -1.88935,50.00000,20.00000,6.461509e-08,0.76705,4
321.67808,1050.40000,     -0.80244,     -1.91531,50.00000,20.00000,6.460251e-08,0.76680,4
321.95305,1053.00000,     -0.81101,     -1.93964,50.00000,20.00000,6.458069e-08,0.76654,4
322.20454,1055.60000,     -0.81681,     -1.96350,50.00000,20.00000,6.472660e-08,0.76630,4
322.46363,1058.20000,     -0.82646,     -1.98752,50.00000,20.00000,6.465807e-08,0.76606,4
322.73526,1060.80000,     -0.81631,     -2.00862,50.00000,20.00000,6.473332e-08,0.76580,4
323.00225,1063.40000,     -0.81746,     -2.03432,50.00000,20.00000,6.465384e-08,0.76555,4
323.25581,1066.00000,     -0.82874,     -2.06021,50.00000,20.00000,6.472765e-08,0.76530,4
323.51275,1068.60000,     -0.83239,     -2.08348,50.00000,20.00000,6.486528e-08,0.76506,4
323.75961,1071.20000,     -0.82787,     -2.11084,50.00000,20.00000,6.482179e-08,0.76483,4
324.02737,1073.80000,     -0.83778,     -2.13682,50.00000,20.00000,6.476187e-08,0.76457,4
324.28930,1076.40000,     -0.84046,     -2.16283,50.00000,20.00000,6.485458e-08,0.76432,4
324.54665,1079.00000,     -0.83730,     -2.18907,50.00000,20.00000,6.485588e-08,0.76408,4
324.80592,1081.60000,     -0.86321,     -2.21458,50.00000,20.00000,6.486271e-08,0.76383,4
325.07185,1084.20000,     -0.85234,     -2.23894,50.00000,20.00000,6.485956e-08,0.76358,4
325.33820,1086.80000,     -0.85992,     -2.26493,50.00000,20.00000,6.481835e-08,0.76333,4
325.58836,1089.40000,     -0.87465,     -2.29110,50.00000,20.00000,6.495981e-08,0.76309,4
325.84097,1092.00000,     -0.88204,     -2.31562,50.00000,20.00000,6.490214e-08,0.76285,4
326.10542,1094.60000,     -0.88341,     -2.33947,50.00000,20.00000,6.494492e-08,0.76260,4
326.36505,1097.20000,     -0.88997,     -2.36302,50.00000,20.00000,6.503921e-08,0.76235,4
326.62770,1099.80000,     -0.90466,     -2.38882,50.00000,20.00000,6.499803e-08,0.76210,4
326.87939,1102.40000,     -0.91748,     -2.41599,50.00000,20.00000,6.503888e-08,0.76186,4
327.15170,1105.00000,     -0.91656,     -2.44073,50.00000,20.00000,6.510376e-08,0.76160,4
327.41375,1107.60000,     -0.91927,     -2.46760,50.00000,20.00000,6.511251e-08,0.76135,4
327.67499,1110.20000,     -0.93043,     -2.49291,50.00000,20.00000,6.506457e-08,0.76111,4
327.92114,1112.80000,     -0.93727,     -2.51844,50.00000,20.00000,6.507569e-08,0.76087,4
328.18926,1115.40000,     -0.94133,     -2.54569,50.00000,20.00000,6.513160e-08,0.76062,4
328.44680,1118.00000,     -0.94673,     -2.57161,50.00000,20.00000,6.515501e-08,0.76037,4
328.71370,1120.60000,     -0.97813,     -2.59646,50.00000,20.00000,6.523290e-08,0.76012,4
328.96820,1123.20000,     -0.97778,     -2.62119,50.00000,20.00000,6.518577e-08,0.75987,4
329.23027,1125.80000,     -0.98065,     -2.64876,50.00000,20.00000,6.516661e-08,0.75963,4
329.49460,1128.40000,     -1.00977,     -2.67674,50.00000,20.00000,6.521336e-08,0.75937,4
329.74513,1131.00000,     -1.01106,     -2.70215,50.00000,20.00000,6.523941e-08,0.75913,4
329.99965,1133.60000,     -1.02066,     -2.72763,50.00000,20.00000,6.525408e-08,0.75889,4
330.26322,1136.20000,     -1.04665,     -2.75465,50.00000,20.00000,6.516538e-08,0.75864,4
330.52810,1138.80000,     -1.04265,     -2.78097,50.00000,20.00000,6.533381e-08,0.75839,4
330.78741,1141.40000,     -1.07548,     -2.80716,50.00000,20.00000,6.529224e-08,0.75814,4
331.04972,1144.00000,     -1.07671,     -2.83453,50.00000,20.00000,6.529429e-08,0.75789,4
331.32082,1146.60000,     -1.08136,     -2.85969,50.00000,20.00000,6.548345e-08,0.75763,4
331.57379,1149.20000,     -1.12934,     -2.88453,50.00000,20.00000,6.543732e-08,0.75739,4
331.82894,1151.80000,     -1.13545,     -2.91025,50.00000,20.00000,6.535898e-08,0.75715,4
332.08094,1154.40000,     -1.14609,     -2.93689,50.00000,20.00000,6.538807e-08,0.75691,4
332.34694,1157.00000,     -1.14600,     -2.96009,50.00000,20.00000,6.543402e-08,0.75666,4
332.61288,1159.60000,     -1.18158,     -2.98870,50.00000,20.00000,6.544428e-08,0.75640,4
332.87364,1162.20000,     -1.18687,     -3.01186,50.00000,20.00000,6.539695e-08,0.75616,4
333.13645,1164.80000,     -1.21824,     -3.03835,50.00000,20.00000,6.552655e-08,0.75590,4
333.39423,1167.40000,     -1.24092,     -3.06354,50.00000,20.00000,6.565284e-08,0.75566,4
333.65267,1170.00000,     -1.25544,     -3.08667,50.00000,20.00000,6.551457e-08,0.75541,4
333.91822,1172.60000,     -1.27835,     -3.11367,50.00000,20.00000,6.549825e-08,0.75516,4
334.16723,1175.20000,     -1.30652,     -3.13864,50.00000,20.00000,6.542692e-08,0.75492,4
334.41998,1177.80000,     -1.31820,     -3.16228,50.00000,20.00000,6.558603e-08,0.75468,4
334.68924,1180.40000,     -1.33851,     -3.18556,50.00000,20.00000,6.565459e-08,0.75442,4
334.95045,1183.00000,     -1.35714,     -3.20881,50.00000,20.00000,6.559663e-08,0.75418,4
335.20196,1185.60000,     -1.37372,     -3.23168,50.00000,20.00000,6.571067e-08,0.75394,4
335.46718,1188.20000,     -1.38879,     -3.25620,50.00000,20.00000,6.562843e-08,0.75368,4
335.72845,1190.80000,     -1.40845,     -3.27965,50.00000,20.00000,6.568895e-08,0.75343,4
335.99662,1193.40000,     -1.42295,     -3.30399,50.00000,20.00000,6.569530e-08,0.75318,4
336.25601,1196.00000,     -1.44168,     -3.32580,50.00000,20.00000,6.569709e-08,0.75293,4
336.51109,1198.60000,     -1.46090,     -3.34878,50.00000,20.00000,6.582756e-08,0.75269,4
336.77590,1201.20000,     -1.47927,     -3.37055,50.00000,20.00000,6.569673e-08,0.75243,4
337.03248,1203.80000,     -1.50109,     -3.39453,50.00000,20.00000,6.574848e-08,0.75219,4
337.28534,1206.40000,     -1.51927,     -3.41607,50.00000,20.00000,6.586522e-08,0.75195,4
337.54635,1209.00000,     -1.53313,     -3.43542,50.00000,20.00000,6.582985e-08,0.75170,4
337.80753,1211.60000,     -1.55768,     -3.45808,50.00000,20.00000,6.584930e-08,0.75145,4
338.07779,1214.20000,     -1.57972,     -3.48016,50.00000,20.00000,6.583904e-08,0.75119,4
338.33042,1216.80000,     -1.59897,     -3.50226,50.00000,20.00000,6.582203e-08,0.75095,4
338.58143,1219.40000,     -1.62264,     -3.52285,50.00000,20.00000,6.578204e-08,0.75071,4
338.85789,1222.00000,     -1.65235,     -3.54204,50.00000,20.00000,6.582967e-08,0.75045,4
339.10623,1224.60000,     -1.67825,     -3.56260,50.00000,20.00000,6.591324e-08,0.75021,4
339.36214,1227.20000,     -1.70098,     -3.58227,50.00000,20.00000,6.586675e-08,0.74997,4
339.61358,1229.80000,     -1.73287,     -3.60296,50.00000,20.00000,6.591912e-08,0.74973,4
339.89871,1232.40000,     -1.76142,     -3.62237,50.00000,20.00000,6.595916e-08,0.74946,4
340.15898,1235.00000,     -1.79679,     -3.64165,50.00000,20.00000,6.590911e-08,0.74921,4
340.40489,1237.60000,     -1.82872,     -3.66249,50.00000,20.00000,6.589684e-08,0.74897,4
340.66675,1240.20000,     -1.85639,     -3.67892,50.00000,20.00000,6.594362e-08,0.74872,4
340.93920,1242.80000,     -1.88097,     -3.69913,50.00000,20.00000,6.601140e-08,0.74846,4
341.18790,1245.40000,     -1.91086,     -3.71800,50.00000,20.00000,6.611510e-08,0.74822,4
341.45040,1248.00000,     -1.93665,     -3.73781,50.00000,20.00000,6.620336e-08,0.74797,4
341.71125,1250.60000,     -1.96974,     -3.75442,50.00000,20.00000,6.608491e-08,0.74773,4
341.97547,1253.20000,     -2.01142,     -3.77417,50.00000,20.00000,6.615103e-08,0.74747,4
342.23265,1255.80000,     -2.03837,     -3.79311,50.00000,20.00000,6.615327e-08,0.74723,4
342.48790,1258.40000,     -2.05754,     -3.81069,50.00000,20.00000,6.615893e-08,0.74698,4
342.74711,1261.00000,     -2.07571,     -3.82946,50.00000,20.00000,6.619997e-08,0.74674,4
342.99527,1263.60000,     -2.09019,     -3.84623,50.00000,20.00000,6.627461e-08,0.74650,4
343.26155,1266.20000,     -2.10509,     -3.86650,50.00000,20.00000,6.627219e-08,0.74625,4
343.52409,1268.80000,     -2.12012,     -3.88579,50.00000,20.00000,6.618825e-08,0.74599,4
343.78497,1271.40000,     -2.13303,     -3.90251,50.00000,20.00000,6.630284e-08,0.74575,4
344.06069,1274.00000,     -2.14909,     -3.92168,50.00000,20.00000,6.642007e-08,0.74548,4
344.31343,1276.60000,     -2.16412,     -3.93927,50.00000,20.00000,6.639816e-08,0.74524,4
344.57205,1279.20000,     -2.17636,     -3.95844,50.00000,20.00000,6.645014e-08,0.74499,4
344.83925,1281.80000,     -2.18818,     -3.97661,50.00000,20.00000,6.637074e-08,0.74474,4
345.09629,1284.40000,     -2.20414,     -3.99335,50.00000,20.00000,6.640562e-08,0.74449,4
345.34575,1287.00000,     -2.21475,     -4.01069,50.00000,20.00000,6.636432e-08,0.74426,4
345.60809,1289.60000,     -2.22463,     -4.02854,50.00000,20.00000,6.651268e-08,0.74401,4
345.85843,1292.20000,     -2.23472,     -4.04432,50.00000,20.00000,6.651631e-08,0.74377,4
346.13327,1294.80000,     -2.24958,     -4.06248,50.00000,20.00000,6.647053e-08,0.74350,4
346.39791,1297.40000,     -2.26173,     -4.07707,50.00000,20.00000,6.650059e-08,0.74325,4
346.64140,1300.00000,     -2.27146,     -4.09281,50.00000,20.00000,6.641836e-08,0.74302,4
346.90932,1302.60000,     -2.28377,     -4.10939,50.00000,20.00000,6.655276e-08,0.74276,4
347.16623,1305.20000,     -2.29644,     -4.12451,50.00000,20.00000,6.660717e-08,0.74252,4
347.41766,1307.80000,     -2.30368,     -4.14009,50.00000,20.00000,6.656198e-08,0.74228,4
347.68294,1310.40000,     -2.31613,     -4.15448,50.00000,20.00000,6.666806e-08,0.74202,4
347.94148,1313.00000,     -2.33015,     -4.16854,50.00000,20.00000,6.669323e-08,0.74178,4
348.20921,1315.60000,     -2.33848,     -4.18329,50.00000,20.00000,6.667546e-08,0.74152,4
348.46778,1318.20000,     -2.34816,     -4.19868,50.00000,20.00000,6.666465e-08,0.74128,4
348.71511,1320.80000,     -2.36110,     -4.21189,50.00000,20.00000,6.671641e-08,0.74104,4
348.98520,1323.40000,     -2.37148,     -4.22619,50.00000,20.00000,6.683660e-08,0.74078,4
349.23956,1326.00000,     -2.38109,     -4.23822,50.00000,20.00000,6.685520e-08,0.74054,4
349.51995,1328.60000,     -2.39220,     -4.25234,50.00000,20.00000,6.677828e-08,0.74027,4
349.78395,1331.20000,     -2.40227,     -4.26299,50.00000,20.00000,6.672518e-08,0.74002,4
350.24915,1333.80000,     -2.22537,     -4.27451,50.00000,20.00000,6.684610e-08,0.73957,5
361.09315,1336.40000,     -0.68393,     -4.26580,50.00000,20.00000,6.686562e-08,0.72923,5
374.40548,1339.00000,     -0.54815,     -4.27304,50.00000,20.00000,6.694948e-08,0.71658,5
388.05086,1341.60000,     -0.78595,     -4.30233,50.00000,20.00000,6.698278e-08,0.70372,5
401.48912,1344.20000,     -1.11120,     -4.34897,50.00000,20.00000,6.725981e-08,0.69118,5
414.73832,1346.80000,     -1.48824,     -4.39993,50.00000,20.00000,6.747851e-08,0.67900,5
427.86225,1349.40000,     -1.90979,     -4.41796,50.00000,20.00000,6.788038e-08,0.66712,5
440.92102,1352.00000,     -2.31847,     -4.41253,50.00000,20.00000,6.833521e-08,0.65553,5
453.93071,1354.60000,     -2.73724,     -4.40733,50.00000,20.00000,6.873265e-08,0.64423,5
466.92213,1357.20000,     -3.16850,     -4.40129,50.00000,20.00000,6.923205e-08,0.63320,5
479.92376,1359.80000,     -3.63306,     -4.39160,50.00000,20.00000,6.966140e-08,0.62246,5
492.91267,1362.40000,     -4.11098,     -4.38515,50.00000,20.00000,7.015788e-08,0.61202,5
505.89515,1365.00000,     -4.60184,     -4.37814,50.00000,20.00000,7.065019e-08,0.60190,5
518.89572,1367.60000,     -5.09459,     -4.37169,50.00000,20.00000,7.096216e-08,0.59208,5
531.88268,1370.20000,     -5.59761,     -4.36800,50.00000,20.00000,7.152882e-08,0.58260,5
544.87512,1372.80000,     -6.08730,     -4.36235,50.00000,20.00000,7.193129e-08,0.57343,5
557.86763,1375.40000,     -6.54812,     -4.35676,50.00000,20.00000,7.228823e-08,0.56459,5
570.88657,1378.00000,     -6.97321,     -4.35359,50.00000,20.00000,7.261991e-08,0.55606,5
583.89387,1380.60000,     -7.36403,     -4.34997,50.00000,20.00000,7.296170e-08,0.54785,5
596.90766,1383.20000,     -7.70840,     -4.34759,50.00000,20.00000,7.318878e-08,0.53994,5
609.91397,1385.80000,     -8.03899,     -4.34386,50.00000,20.00000,7.342286e-08,0.53234,5
622.93348,1388.40000,     -8.35445,     -4.34182,50.00000,20.00000,7.353383e-08,0.52502,5
635.97377,1391.00000,     -8.67679,     -4.33945,50.00000,20.00000,7.369252e-08,0.51796,5
648.98260,1393.60000,     -9.03062,     -4.33820,50.00000,20.00000,7.373317e-08,0.51118,5
662.00190,1396.20000,     -9.40598,     -4.33436,50.00000,20.00000,7.396189e-08,0.50462,5
675.01470,1398.80000,     -9.78420,     -4.33334,50.00000,20.00000,7.390515e-08,0.49830,5
688.00510,1401.40000,    -10.15340,     -4.33108,50.00000,20.00000,7.396972e-08,0.49219,5
701.03535,1404.00000,    -10.54150,     -4.32927,50.00000,20.00000,7.401424e-08,0.48624,5
714.06312,1406.60000,    -10.90871,     -4.32712,50.00000,20.00000,7.411025e-08,0.48046,5
727.09548,1409.20000,    -11.29526,     -4.32542,50.00000,20.00000,7.406558e-08,0.47481,5
740.11208,1411.80000,    -11.69600,     -4.32395,50.00000,20.00000,7.408489e-08,0.46930,5
753.12706,1414.40000,    -12.10645,     -4.32169,50.00000,20.00000,7.414167e-08,0.46388,5
766.14312,1417.00000,    -12.53849,     -4.32014,50.00000,20.00000,7.429137e-08,0.45854,5
779.15732,1419.60000,    -12.98414,     -4.31874,50.00000,20.00000,7.414773e-08,0.45327,5
792.17388,1422.20000,    -13.43699,     -4.31671,50.00000,20.00000,7.420306e-08,0.44803,5
798.18728,1423.40000,    -13.64302,     -4.31525,50.00000,20.00000,7.421871e-08,0.44561,5